[
,
{"timestamp": "1743938535077", "bids": [[122500000.0, 0.6978], [122499000.0, 0.0012], [122498000.0, 0.0053], [122497000.0, 0.0188], [122496000.0, 0.0098], [122495000.0, 0.0411], [122494000.0, 0.0017], [122493000.0, 0.0236], [122492000.0, 0.0038], [122491000.0, 0.0159]], "asks": [[122507000.0, 0.105], [122508000.0, 0.0049], [122516000.0, 0.0], [122533000.0, 0.0023], [122534000.0, 0.0008], [122545000.0, 0.0], [122547000.0, 0.0], [122551000.0, 0.1003], [122563000.0, 0.1605], [122564000.0, 0.0037]]},
{"timestamp": "1743938535478", "bids": [[122500000.0, 0.6978], [122499000.0, 0.0012], [122498000.0, 0.0053], [122497000.0, 0.0188], [122496000.0, 0.0098], [122495000.0, 0.0411], [122494000.0, 0.0017], [122493000.0, 0.0236], [122492000.0, 0.0038], [122491000.0, 0.0159]], "asks": [[122507000.0, 0.105], [122508000.0, 0.0049], [122516000.0, 0.0], [122533000.0, 0.0023], [122534000.0, 0.0008], [122545000.0, 0.0], [122547000.0, 0.0], [122550000.0, 0.1605], [122564000.0, 0.104], [122565000.0, 0.003]]},
{"timestamp": "1743938536030", "bids": [[122500000.0, 0.6978], [122499000.0, 0.0012], [122498000.0, 0.0053], [122497000.0, 0.0188], [122496000.0, 0.0098], [122495000.0, 0.0411], [122494000.0, 0.0017], [122493000.0, 0.0236], [122492000.0, 0.0038], [122491000.0, 0.0159]], "asks": [[122507000.0, 0.105], [122508000.0, 0.0049], [122516000.0, 0.0], [122533000.0, 0.0023], [122534000.0, 0.0008], [122545000.0, 0.0], [122547000.0, 0.0], [122549000.0, 0.1003], [122561000.0, 0.1605], [122564000.0, 0.0037]]},
{"timestamp": "1743938536551", "bids": [[122500000.0, 0.6978], [122499000.0, 0.0012], [122498000.0, 0.0053], [122497000.0, 0.0188], [122496000.0, 0.0098], [122495000.0, 0.0411], [122494000.0, 0.0017], [122493000.0, 0.0236], [122492000.0, 0.0038], [122491000.0, 0.0159]], "asks": [[122507000.0, 0.105], [122508000.0, 0.0049], [122516000.0, 0.0], [122533000.0, 0.0023], [122534000.0, 0.0008], [122545000.0, 0.0], [122547000.0, 0.0], [122548000.0, 0.1605], [122562000.0, 0.1003], [122564000.0, 0.0037]]},
{"timestamp": "1743938537049", "bids": [[122500000.0, 0.7182], [122499000.0, 0.0012], [122498000.0, 0.0053], [122497000.0, 0.0188], [122496000.0, 0.0098], [122495000.0, 0.0411], [122494000.0, 0.0017], [122493000.0, 0.0236], [122492000.0, 0.0038], [122491000.0, 0.0159]], "asks": [[122507000.0, 0.105], [122508000.0, 0.0049], [122516000.0, 0.0], [122533000.0, 0.0023], [122534000.0, 0.0008], [122545000.0, 0.0], [122546000.0, 0.1605], [122547000.0, 0.0], [122560000.0, 0.1003], [122564000.0, 0.0037]]},
{"timestamp": "1743938537530", "bids": [[122500000.0, 0.6382], [122499000.0, 0.0012], [122498000.0, 0.0053], [122497000.0, 0.0188], [122496000.0, 0.0098], [122495000.0, 0.0411], [122494000.0, 0.0017], [122493000.0, 0.0236], [122492000.0, 0.0038], [122491000.0, 0.0159]], "asks": [[122507000.0, 0.1034], [122508000.0, 0.0008], [122516000.0, 0.0], [122533000.0, 0.0023], [122534000.0, 0.0008], [122545000.0, 0.0], [122547000.0, 0.0], [122558000.0, 0.1003], [122559000.0, 0.1605], [122564000.0, 0.0037]]},
{"timestamp": "1743938538056", "bids": [[122500000.0, 0.6382], [122499000.0, 0.0012], [122498000.0, 0.0053], [122497000.0, 0.0188], [122496000.0, 0.0098], [122495000.0, 0.0411], [122494000.0, 0.0017], [122493000.0, 0.0236], [122492000.0, 0.0038], [122491000.0, 0.0159]], "asks": [[122507000.0, 0.1034], [122508000.0, 0.0008], [122516000.0, 0.0], [122534000.0, 0.0031], [122545000.0, 0.0], [122547000.0, 0.0], [122557000.0, 0.1605], [122558000.0, 0.1003], [122564000.0, 0.0075], [122565000.0, 0.003]]},
{"timestamp": "1743938538550", "bids": [[122500000.0, 0.6427], [122499000.0, 0.0012], [122498000.0, 0.0053], [122497000.0, 0.0188], [122496000.0, 0.0098], [122495000.0, 0.0411], [122494000.0, 0.0017], [122493000.0, 0.0236], [122492000.0, 0.0038], [122491000.0, 0.0159]], "asks": [[122507000.0, 0.1034], [122508000.0, 0.0008], [122516000.0, 0.0], [122534000.0, 0.0031], [122545000.0, 0.0], [122547000.0, 0.0], [122555000.0, 0.1621], [122556000.0, 0.1013], [122564000.0, 0.0037], [122565000.0, 0.003]]},
{"timestamp": "1743938539102", "bids": [[122500000.0, 0.6427], [122499000.0, 0.0012], [122498000.0, 0.0053], [122497000.0, 0.0188], [122496000.0, 0.0098], [122495000.0, 0.0411], [122494000.0, 0.0017], [122493000.0, 0.0236], [122492000.0, 0.0038], [122491000.0, 0.0159]], "asks": [[122507000.0, 0.1034], [122508000.0, 0.0008], [122516000.0, 0.0], [122534000.0, 0.0031], [122545000.0, 0.0], [122547000.0, 0.0], [122554000.0, 0.1013], [122555000.0, 0.1621], [122564000.0, 0.0037], [122565000.0, 0.003]]},
{"timestamp": "1743938539604", "bids": [[122500000.0, 0.6387], [122499000.0, 0.0012], [122498000.0, 0.0053], [122497000.0, 0.0188], [122496000.0, 0.0098], [122495000.0, 0.0411], [122494000.0, 0.0017], [122493000.0, 0.0236], [122492000.0, 0.0038], [122491000.0, 0.0159]], "asks": [[122507000.0, 0.1034], [122508000.0, 0.0008], [122516000.0, 0.0], [122534000.0, 0.0031], [122545000.0, 0.0], [122547000.0, 0.0], [122552000.0, 0.1013], [122553000.0, 0.1621], [122564000.0, 0.0037], [122565000.0, 0.003]]},
{"timestamp": "1743938540105", "bids": [[122500000.0, 0.6387], [122499000.0, 0.0012], [122498000.0, 0.0053], [122497000.0, 0.0188], [122496000.0, 0.0098], [122495000.0, 0.0411], [122494000.0, 0.0017], [122493000.0, 0.0236], [122492000.0, 0.0038], [122491000.0, 0.0159]], "asks": [[122507000.0, 0.1034], [122508000.0, 0.0008], [122516000.0, 0.0], [122534000.0, 0.0031], [122545000.0, 0.0], [122547000.0, 0.0], [122551000.0, 0.1621], [122564000.0, 0.0037], [122565000.0, 0.003], [122567000.0, 0.006]]},
{"timestamp": "1743938540677", "bids": [[122500000.0, 0.6387], [122499000.0, 0.0012], [122498000.0, 0.0053], [122497000.0, 0.0188], [122496000.0, 0.0098], [122495000.0, 0.0411], [122494000.0, 0.0017], [122493000.0, 0.0236], [122492000.0, 0.0038], [122491000.0, 0.0159]], "asks": [[122507000.0, 0.1034], [122508000.0, 0.0008], [122516000.0, 0.0], [122534000.0, 0.0031], [122545000.0, 0.0], [122547000.0, 0.0], [122549000.0, 0.1621], [122564000.0, 0.0037], [122565000.0, 0.003], [122566000.0, 0.1013]]},
{"timestamp": "1743938541142", "bids": [[122500000.0, 0.634], [122499000.0, 0.0012], [122498000.0, 0.0053], [122497000.0, 0.0188], [122496000.0, 0.0098], [122495000.0, 0.0411], [122494000.0, 0.0017], [122493000.0, 0.0236], [122492000.0, 0.0038], [122491000.0, 0.0159]], "asks": [[122507000.0, 0.1034], [122508000.0, 0.0008], [122516000.0, 0.0], [122533000.0, 0.0023], [122534000.0, 0.0008], [122545000.0, 0.0], [122547000.0, 0.0], [122563000.0, 0.0037], [122565000.0, 0.003], [122567000.0, 0.006]]},
{"timestamp": "1743938541643", "bids": [[122500000.0, 0.6328], [122499000.0, 0.0012], [122498000.0, 0.0053], [122497000.0, 0.0188], [122496000.0, 0.0098], [122495000.0, 0.0411], [122494000.0, 0.0017], [122493000.0, 0.0236], [122492000.0, 0.0038], [122491000.0, 0.0159]], "asks": [[122507000.0, 0.1034], [122508000.0, 0.0008], [122516000.0, 0.0], [122533000.0, 0.0023], [122534000.0, 0.0008], [122545000.0, 0.0], [122547000.0, 0.0], [122563000.0, 0.0037], [122565000.0, 0.003], [122566000.0, 0.1013]]},
{"timestamp": "1743938542166", "bids": [[122500000.0, 0.6328], [122499000.0, 0.0012], [122498000.0, 0.0053], [122497000.0, 0.0188], [122496000.0, 0.0098], [122495000.0, 0.0411], [122494000.0, 0.0017], [122493000.0, 0.0236], [122492000.0, 0.0038], [122491000.0, 0.0159]], "asks": [[122507000.0, 0.1034], [122508000.0, 0.0008], [122516000.0, 0.0], [122533000.0, 0.0023], [122534000.0, 0.0008], [122545000.0, 0.0], [122547000.0, 0.0], [122563000.0, 0.0037], [122564000.0, 0.1013], [122565000.0, 0.003]]},
{"timestamp": "1743938542664", "bids": [[122500000.0, 0.6328], [122499000.0, 0.0012], [122498000.0, 0.0053], [122497000.0, 0.0188], [122496000.0, 0.0098], [122495000.0, 0.0411], [122494000.0, 0.0017], [122493000.0, 0.0236], [122492000.0, 0.0038], [122491000.0, 0.0159]], "asks": [[122507000.0, 0.1034], [122508000.0, 0.0008], [122516000.0, 0.0], [122533000.0, 0.0023], [122534000.0, 0.0008], [122545000.0, 0.0], [122547000.0, 0.0], [122563000.0, 0.0037], [122565000.0, 0.003], [122567000.0, 0.006]]},
{"timestamp": "1743938543176", "bids": [[122500000.0, 0.6286], [122499000.0, 0.0012], [122498000.0, 0.0053], [122497000.0, 0.0188], [122496000.0, 0.0098], [122495000.0, 0.0411], [122494000.0, 0.0017], [122493000.0, 0.0236], [122492000.0, 0.0038], [122491000.0, 0.0159]], "asks": [[122507000.0, 0.1034], [122508000.0, 0.0008], [122516000.0, 0.0], [122533000.0, 0.0023], [122534000.0, 0.0008], [122545000.0, 0.0], [122547000.0, 0.0], [122563000.0, 0.0037], [122565000.0, 0.003], [122566000.0, 0.1013]]},
{"timestamp": "1743938543911", "bids": [[122500000.0, 0.5982], [122499000.0, 0.0012], [122498000.0, 0.0053], [122497000.0, 0.0188], [122496000.0, 0.0098], [122495000.0, 0.0411], [122494000.0, 0.0017], [122493000.0, 0.0236], [122492000.0, 0.0038], [122491000.0, 0.0159]], "asks": [[122507000.0, 0.1034], [122508000.0, 0.0008], [122516000.0, 0.0], [122533000.0, 0.0023], [122534000.0, 0.0008], [122545000.0, 0.0], [122547000.0, 0.0], [122563000.0, 0.0037], [122564000.0, 0.1013], [122565000.0, 0.1651]]},
{"timestamp": "1743938544177", "bids": [[122500000.0, 0.5982], [122499000.0, 0.0012], [122498000.0, 0.0053], [122497000.0, 0.0188], [122496000.0, 0.0098], [122495000.0, 0.0411], [122494000.0, 0.0017], [122493000.0, 0.0236], [122492000.0, 0.0038], [122491000.0, 0.0159]], "asks": [[122507000.0, 0.1034], [122508000.0, 0.0008], [122516000.0, 0.0], [122533000.0, 0.0023], [122534000.0, 0.0008], [122545000.0, 0.0], [122547000.0, 0.0], [122563000.0, 0.1658], [122564000.0, 0.1013], [122565000.0, 0.003]]},
{"timestamp": "1743938544693", "bids": [[122500000.0, 0.5982], [122499000.0, 0.0012], [122498000.0, 0.0053], [122497000.0, 0.0188], [122496000.0, 0.0098], [122495000.0, 0.0411], [122494000.0, 0.0017], [122493000.0, 0.0236], [122492000.0, 0.0038], [122491000.0, 0.0159]], "asks": [[122507000.0, 0.1034], [122508000.0, 0.0008], [122516000.0, 0.0], [122533000.0, 0.0023], [122534000.0, 0.0008], [122545000.0, 0.0], [122547000.0, 0.0], [122562000.0, 0.101], [122563000.0, 0.1658], [122565000.0, 0.003]]},
{"timestamp": "1743938545205", "bids": [[122500000.0, 0.5982], [122499000.0, 0.0012], [122498000.0, 0.0053], [122497000.0, 0.0188], [122496000.0, 0.0098], [122495000.0, 0.0411], [122494000.0, 0.0017], [122493000.0, 0.0236], [122492000.0, 0.0038], [122491000.0, 0.0159]], "asks": [[122507000.0, 0.1034], [122508000.0, 0.0008], [122516000.0, 0.0], [122533000.0, 0.0023], [122534000.0, 0.0008], [122545000.0, 0.0], [122547000.0, 0.0], [122561000.0, 0.1617], [122562000.0, 0.101], [122563000.0, 0.0037]]},
{"timestamp": "1743938545732", "bids": [[122500000.0, 0.5982], [122499000.0, 0.0012], [122498000.0, 0.0053], [122497000.0, 0.0188], [122496000.0, 0.0098], [122495000.0, 0.0411], [122494000.0, 0.0017], [122493000.0, 0.0236], [122492000.0, 0.0038], [122491000.0, 0.0159]], "asks": [[122507000.0, 0.1026], [122508000.0, 0.001], [122516000.0, 0.0], [122533000.0, 0.0023], [122534000.0, 0.0008], [122545000.0, 0.0], [122547000.0, 0.0], [122560000.0, 0.101], [122563000.0, 0.0037], [122565000.0, 0.003]]},
{"timestamp": "1743938546256", "bids": [[122500000.0, 0.5982], [122499000.0, 0.0012], [122498000.0, 0.0053], [122497000.0, 0.0188], [122496000.0, 0.0098], [122495000.0, 0.0411], [122494000.0, 0.0017], [122493000.0, 0.0236], [122492000.0, 0.0038], [122491000.0, 0.0159]], "asks": [[122507000.0, 0.1026], [122508000.0, 0.001], [122516000.0, 0.0], [122533000.0, 0.0023], [122534000.0, 0.0008], [122545000.0, 0.0], [122547000.0, 0.0], [122559000.0, 0.1617], [122563000.0, 0.0037], [122565000.0, 0.003]]},
{"timestamp": "1743938546792", "bids": [[122500000.0, 0.5982], [122499000.0, 0.0012], [122498000.0, 0.0053], [122497000.0, 0.0188], [122496000.0, 0.0098], [122495000.0, 0.0411], [122494000.0, 0.0017], [122493000.0, 0.0236], [122492000.0, 0.0038], [122491000.0, 0.0159]], "asks": [[122507000.0, 0.1026], [122508000.0, 0.001], [122516000.0, 0.0], [122533000.0, 0.0023], [122534000.0, 0.0008], [122545000.0, 0.0], [122547000.0, 0.0], [122557000.0, 0.1617], [122563000.0, 0.0037], [122564000.0, 0.101]]},
{"timestamp": "1743938547294", "bids": [[122500000.0, 0.5982], [122499000.0, 0.0012], [122498000.0, 0.0053], [122497000.0, 0.0188], [122496000.0, 0.0098], [122495000.0, 0.0411], [122494000.0, 0.0017], [122493000.0, 0.0236], [122492000.0, 0.0038], [122491000.0, 0.0159]], "asks": [[122507000.0, 0.1026], [122508000.0, 0.001], [122516000.0, 0.0], [122533000.0, 0.0023], [122534000.0, 0.0008], [122545000.0, 0.0], [122547000.0, 0.0], [122556000.0, 0.101], [122563000.0, 0.1654], [122565000.0, 0.003]]},
{"timestamp": "1743938547770", "bids": [[122500000.0, 0.5982], [122499000.0, 0.0012], [122498000.0, 0.0053], [122497000.0, 0.0188], [122496000.0, 0.0098], [122495000.0, 0.0411], [122494000.0, 0.0017], [122493000.0, 0.0236], [122492000.0, 0.0038], [122491000.0, 0.0159]], "asks": [[122507000.0, 0.1026], [122508000.0, 0.001], [122516000.0, 0.0], [122533000.0, 0.0023], [122534000.0, 0.0008], [122545000.0, 0.0], [122547000.0, 0.0], [122555000.0, 0.1617], [122562000.0, 0.101], [122563000.0, 0.0037]]},
{"timestamp": "1743938548305", "bids": [[122500000.0, 0.5935], [122499000.0, 0.0012], [122498000.0, 0.0053], [122497000.0, 0.0188], [122496000.0, 0.0098], [122495000.0, 0.0411], [122494000.0, 0.0017], [122493000.0, 0.0236], [122492000.0, 0.0038], [122491000.0, 0.0159]], "asks": [[122507000.0, 0.1026], [122508000.0, 0.001], [122516000.0, 0.0], [122533000.0, 0.0046], [122534000.0, 0.0008], [122545000.0, 0.0], [122547000.0, 0.0], [122553000.0, 0.1617], [122560000.0, 0.101], [122563000.0, 0.0075]]},
{"timestamp": "1743938548819", "bids": [[122500000.0, 0.5935], [122499000.0, 0.0012], [122498000.0, 0.0053], [122497000.0, 0.0188], [122496000.0, 0.0098], [122495000.0, 0.0411], [122494000.0, 0.0017], [122493000.0, 0.0236], [122492000.0, 0.0038], [122491000.0, 0.0159]], "asks": [[122507000.0, 0.1026], [122508000.0, 0.001], [122516000.0, 0.0], [122533000.0, 0.0023], [122534000.0, 0.0008], [122545000.0, 0.0], [122547000.0, 0.0], [122552000.0, 0.101], [122559000.0, 0.1617], [122563000.0, 0.0037]]},
{"timestamp": "1743938549318", "bids": [[122500000.0, 0.5935], [122499000.0, 0.0012], [122498000.0, 0.0053], [122497000.0, 0.0188], [122496000.0, 0.0098], [122495000.0, 0.0411], [122494000.0, 0.0017], [122493000.0, 0.0236], [122492000.0, 0.0038], [122491000.0, 0.0159]], "asks": [[122507000.0, 0.1026], [122508000.0, 0.001], [122516000.0, 0.0], [122533000.0, 0.0023], [122534000.0, 0.0008], [122545000.0, 0.0], [122547000.0, 0.0], [122563000.0, 0.0037], [122565000.0, 0.003], [122567000.0, 0.006]]},
{"timestamp": "1743938549861", "bids": [[122500000.0, 0.5935], [122499000.0, 0.0012], [122498000.0, 0.0053], [122497000.0, 0.0188], [122496000.0, 0.0098], [122495000.0, 0.0411], [122494000.0, 0.0017], [122493000.0, 0.0236], [122492000.0, 0.0038], [122491000.0, 0.0159]], "asks": [[122507000.0, 0.1026], [122508000.0, 0.001], [122516000.0, 0.0], [122533000.0, 0.0023], [122534000.0, 0.0008], [122545000.0, 0.0], [122547000.0, 0.0], [122556000.0, 0.101], [122563000.0, 0.0037], [122565000.0, 0.1647]]},
{"timestamp": "1743938550358", "bids": [[122500000.0, 0.5935], [122499000.0, 0.0012], [122498000.0, 0.0053], [122497000.0, 0.0188], [122496000.0, 0.0098], [122495000.0, 0.0411], [122494000.0, 0.0017], [122493000.0, 0.0236], [122492000.0, 0.0038], [122491000.0, 0.0159]], "asks": [[122507000.0, 0.1026], [122508000.0, 0.001], [122516000.0, 0.0], [122533000.0, 0.0023], [122534000.0, 0.0008], [122545000.0, 0.0], [122547000.0, 0.0], [122555000.0, 0.1617], [122563000.0, 0.0037], [122565000.0, 0.003]]},
{"timestamp": "1743938550846", "bids": [[122500000.0, 0.5935], [122499000.0, 0.0012], [122498000.0, 0.0053], [122497000.0, 0.0188], [122496000.0, 0.0098], [122495000.0, 0.0411], [122494000.0, 0.0017], [122493000.0, 0.0236], [122492000.0, 0.0038], [122491000.0, 0.0159]], "asks": [[122507000.0, 0.1026], [122508000.0, 0.001], [122516000.0, 0.0], [122533000.0, 0.0023], [122534000.0, 0.0008], [122545000.0, 0.0], [122547000.0, 0.0], [122554000.0, 0.101], [122563000.0, 0.1654], [122565000.0, 0.003]]},
{"timestamp": "1743938551380", "bids": [[122500000.0, 0.5926], [122499000.0, 0.0012], [122498000.0, 0.0053], [122497000.0, 0.0188], [122496000.0, 0.0098], [122495000.0, 0.0411], [122494000.0, 0.0017], [122493000.0, 0.0236], [122492000.0, 0.0038], [122491000.0, 0.0159]], "asks": [[122507000.0, 0.1026], [122508000.0, 0.001], [122516000.0, 0.0], [122533000.0, 0.0023], [122534000.0, 0.0008], [122545000.0, 0.0], [122547000.0, 0.0], [122552000.0, 0.101], [122561000.0, 0.1617], [122563000.0, 0.0037]]},
{"timestamp": "1743938551879", "bids": [[122500000.0, 0.5926], [122499000.0, 0.0012], [122498000.0, 0.0053], [122497000.0, 0.0188], [122496000.0, 0.0098], [122495000.0, 0.0411], [122494000.0, 0.0017], [122493000.0, 0.0236], [122492000.0, 0.0038], [122491000.0, 0.0159]], "asks": [[122507000.0, 0.1026], [122508000.0, 0.001], [122516000.0, 0.0], [122533000.0, 0.0023], [122534000.0, 0.0008], [122545000.0, 0.0], [122547000.0, 0.0], [122563000.0, 0.0037], [122565000.0, 0.003], [122568000.0, 0.1617]]},
{"timestamp": "1743938552376", "bids": [[122501000.0, 0.006], [122500000.0, 0.5926], [122499000.0, 0.0012], [122498000.0, 0.0053], [122497000.0, 0.0188], [122496000.0, 0.0098], [122495000.0, 0.0411], [122494000.0, 0.0017], [122493000.0, 0.0236], [122492000.0, 0.0038]], "asks": [[122507000.0, 0.1026], [122508000.0, 0.001], [122516000.0, 0.0], [122533000.0, 0.0023], [122534000.0, 0.0008], [122545000.0, 0.0], [122547000.0, 0.0], [122563000.0, 0.0037], [122565000.0, 0.003], [122567000.0, 0.101]]},
{"timestamp": "1743938552913", "bids": [[122504000.0, 0.027], [122503000.0, 0.0159], [122501000.0, 0.1051], [122500000.0, 0.5926], [122499000.0, 0.0012], [122498000.0, 0.0053], [122497000.0, 0.0032], [122496000.0, 0.0098], [122495000.0, 0.0411], [122494000.0, 0.0017]], "asks": [[122507000.0, 0.1026], [122508000.0, 0.001], [122516000.0, 0.0], [122533000.0, 0.0023], [122534000.0, 0.0008], [122545000.0, 0.0], [122547000.0, 0.0], [122563000.0, 0.0037], [122565000.0, 0.003], [122575000.0, 0.101]]},
{"timestamp": "1743938553402", "bids": [[122504000.0, 0.027], [122503000.0, 0.031], [122501000.0, 0.1051], [122500000.0, 0.5926], [122499000.0, 0.0012], [122498000.0, 0.0053], [122497000.0, 0.0032], [122496000.0, 0.0098], [122495000.0, 0.0411], [122494000.0, 0.0017]], "asks": [[122507000.0, 0.087], [122508000.0, 0.001], [122516000.0, 0.0], [122533000.0, 0.0023], [122534000.0, 0.0008], [122545000.0, 0.0], [122547000.0, 0.0], [122563000.0, 0.0037], [122565000.0, 0.003], [122566000.0, 0.1617]]},
{"timestamp": "1743938553930", "bids": [[122504000.0, 0.027], [122503000.0, 0.031], [122501000.0, 0.0152], [122500000.0, 0.5926], [122499000.0, 0.0012], [122498000.0, 0.0053], [122497000.0, 0.0032], [122496000.0, 0.0098], [122495000.0, 0.0411], [122494000.0, 0.0017]], "asks": [[122507000.0, 0.087], [122508000.0, 0.001], [122516000.0, 0.0], [122533000.0, 0.0023], [122534000.0, 0.0008], [122545000.0, 0.0], [122547000.0, 0.0], [122563000.0, 0.0037], [122565000.0, 0.104], [122569000.0, 0.0156]]},
{"timestamp": "1743938554446", "bids": [[122504000.0, 0.027], [122503000.0, 0.031], [122501000.0, 0.0152], [122500000.0, 0.5926], [122499000.0, 0.0012], [122498000.0, 0.0053], [122497000.0, 0.0032], [122496000.0, 0.0098], [122495000.0, 0.0411], [122494000.0, 0.0017]], "asks": [[122507000.0, 0.087], [122508000.0, 0.001], [122516000.0, 0.0], [122533000.0, 0.0023], [122534000.0, 0.0008], [122545000.0, 0.0], [122547000.0, 0.0], [122563000.0, 0.0037], [122565000.0, 0.003], [122569000.0, 0.0156]]},
{"timestamp": "1743938554970", "bids": [[122504000.0, 0.027], [122503000.0, 0.031], [122501000.0, 0.0152], [122500000.0, 0.5926], [122499000.0, 0.0012], [122498000.0, 0.0053], [122497000.0, 0.0032], [122496000.0, 0.0098], [122495000.0, 0.0411], [122494000.0, 0.0017]], "asks": [[122507000.0, 0.087], [122508000.0, 0.001], [122516000.0, 0.0], [122533000.0, 0.0023], [122534000.0, 0.0008], [122545000.0, 0.0], [122547000.0, 0.0], [122562000.0, 0.0037], [122564000.0, 0.1009], [122565000.0, 0.003]]},
{"timestamp": "1743938555499", "bids": [[122504000.0, 0.0218], [122503000.0, 0.031], [122501000.0, 0.1202], [122500000.0, 0.5926], [122499000.0, 0.0012], [122498000.0, 0.0053], [122497000.0, 0.0032], [122496000.0, 0.0098], [122495000.0, 0.0411], [122494000.0, 0.0017]], "asks": [[122507000.0, 0.087], [122508000.0, 0.001], [122516000.0, 0.0], [122533000.0, 0.0023], [122534000.0, 0.0008], [122545000.0, 0.0], [122547000.0, 0.0], [122562000.0, 0.0037], [122563000.0, 0.1615], [122565000.0, 0.003]]},
{"timestamp": "1743938556008", "bids": [[122504000.0, 0.0218], [122503000.0, 0.031], [122501000.0, 0.0152], [122500000.0, 0.5926], [122499000.0, 0.0012], [122498000.0, 0.0053], [122497000.0, 0.0032], [122496000.0, 0.0098], [122495000.0, 0.0411], [122494000.0, 0.0017]], "asks": [[122507000.0, 0.087], [122508000.0, 0.001], [122516000.0, 0.0], [122533000.0, 0.0023], [122534000.0, 0.0008], [122545000.0, 0.0], [122547000.0, 0.0], [122561000.0, 0.1609], [122562000.0, 0.0037], [122564000.0, 0.1005]]},
{"timestamp": "1743938556527", "bids": [[122504000.0, 0.0218], [122503000.0, 0.031], [122501000.0, 0.0152], [122500000.0, 0.5926], [122499000.0, 0.0012], [122498000.0, 0.0053], [122497000.0, 0.0032], [122496000.0, 0.0098], [122495000.0, 0.0411], [122494000.0, 0.0017]], "asks": [[122506000.0, 0.1602], [122507000.0, 0.087], [122508000.0, 0.001], [122516000.0, 0.0], [122533000.0, 0.0023], [122534000.0, 0.0008], [122545000.0, 0.0], [122547000.0, 0.0], [122560000.0, 0.1005], [122562000.0, 0.0037]]},
{"timestamp": "1743938557015", "bids": [[122504000.0, 0.0218], [122503000.0, 0.031], [122501000.0, 0.0152], [122500000.0, 0.5926], [122499000.0, 0.0012], [122498000.0, 0.0053], [122497000.0, 0.0032], [122496000.0, 0.0098], [122495000.0, 0.0411], [122494000.0, 0.0017]], "asks": [[122507000.0, 0.087], [122508000.0, 0.001], [122516000.0, 0.0], [122533000.0, 0.0023], [122534000.0, 0.0008], [122545000.0, 0.0], [122547000.0, 0.0], [122562000.0, 0.0037], [122565000.0, 0.003], [122569000.0, 0.0156]]},
{"timestamp": "1743938557527", "bids": [[122503000.0, 0.0151], [122501000.0, 0.1197], [122500000.0, 0.5926], [122499000.0, 0.0012], [122498000.0, 0.0053], [122497000.0, 0.0032], [122496000.0, 0.0098], [122495000.0, 0.0411], [122494000.0, 0.0017], [122493000.0, 0.0085]], "asks": [[122507000.0, 0.087], [122508000.0, 0.001], [122516000.0, 0.0], [122533000.0, 0.0023], [122534000.0, 0.0008], [122545000.0, 0.0], [122547000.0, 0.0], [122562000.0, 0.0037], [122565000.0, 0.003], [122568000.0, 0.2614]]},
{"timestamp": "1743938558020", "bids": [[122501000.0, 0.1045], [122500000.0, 0.5926], [122499000.0, 0.0205], [122498000.0, 0.0053], [122497000.0, 0.0032], [122496000.0, 0.0298], [122495000.0, 0.0413], [122494000.0, 0.0017], [122493000.0, 0.0333], [122492000.0, 0.0038]], "asks": [[122507000.0, 0.0832], [122508000.0, 0.001], [122516000.0, 0.0], [122533000.0, 0.0023], [122534000.0, 0.0008], [122545000.0, 0.0], [122547000.0, 0.0], [122562000.0, 0.0037], [122565000.0, 0.003], [122567000.0, 0.2614]]},
{"timestamp": "1743938558532", "bids": [[122500000.0, 0.5926], [122499000.0, 0.0012], [122498000.0, 0.0053], [122497000.0, 0.0032], [122496000.0, 0.0298], [122495000.0, 0.0689], [122494000.0, 0.0017], [122493000.0, 0.0085], [122492000.0, 0.0038], [122491000.0, 0.0007]], "asks": [[122507000.0, 0.0337], [122508000.0, 0.001], [122516000.0, 0.0], [122533000.0, 0.0023], [122534000.0, 0.0008], [122545000.0, 0.0], [122547000.0, 0.0], [122562000.0, 0.0037], [122565000.0, 0.1636], [122574000.0, 0.0151]]},
{"timestamp": "1743938559034", "bids": [[122501000.0, 0.1039], [122500000.0, 0.5911], [122499000.0, 0.0012], [122498000.0, 0.0053], [122497000.0, 0.0032], [122496000.0, 0.0298], [122495000.0, 0.0689], [122494000.0, 0.0017], [122493000.0, 0.0085], [122492000.0, 0.0038]], "asks": [[122507000.0, 0.0336], [122508000.0, 0.001], [122516000.0, 0.0], [122533000.0, 0.0023], [122534000.0, 0.0008], [122545000.0, 0.0], [122547000.0, 0.0], [122562000.0, 0.0037], [122564000.0, 0.1001], [122565000.0, 0.003]]},
{"timestamp": "1743938559570", "bids": [[122501000.0, 0.1039], [122500000.0, 0.5911], [122499000.0, 0.0012], [122498000.0, 0.0053], [122497000.0, 0.0032], [122496000.0, 0.0098], [122495000.0, 0.0413], [122494000.0, 0.0017], [122493000.0, 0.0085], [122492000.0, 0.0038]], "asks": [[122507000.0, 0.0143], [122508000.0, 0.001], [122516000.0, 0.0], [122533000.0, 0.0023], [122534000.0, 0.0008], [122545000.0, 0.0], [122547000.0, 0.0], [122562000.0, 0.0037], [122563000.0, 0.1601], [122565000.0, 0.003]]},
{"timestamp": "1743938560061", "bids": [[122505000.0, 0.02], [122504000.0, 0.0278], [122502000.0, 0.1039], [122500000.0, 0.5911], [122499000.0, 0.0012], [122498000.0, 0.0212], [122497000.0, 0.0032], [122496000.0, 0.026], [122495000.0, 0.0412], [122494000.0, 0.0017]], "asks": [[122507000.0, 0.0143], [122508000.0, 0.001], [122516000.0, 0.0], [122533000.0, 0.0023], [122534000.0, 0.0008], [122545000.0, 0.0], [122547000.0, 0.0], [122562000.0, 0.0037], [122565000.0, 0.003], [122571000.0, 0.1601]]},
{"timestamp": "1743938560575", "bids": [[122504000.0, 0.0278], [122500000.0, 0.5911], [122499000.0, 0.0012], [122498000.0, 0.0212], [122497000.0, 0.0032], [122496000.0, 0.026], [122495000.0, 0.0648], [122494000.0, 0.0017], [122493000.0, 0.045], [122492000.0, 0.0206]], "asks": [[122507000.0, 0.0143], [122508000.0, 0.001], [122516000.0, 0.0], [122533000.0, 0.0023], [122534000.0, 0.0008], [122545000.0, 0.0], [122547000.0, 0.0], [122562000.0, 0.0037], [122565000.0, 0.003], [122571000.0, 0.1601]]},
{"timestamp": "1743938561092", "bids": [[122504000.0, 0.0278], [122501000.0, 0.1039], [122500000.0, 0.5911], [122499000.0, 0.0012], [122498000.0, 0.0212], [122497000.0, 0.0032], [122496000.0, 0.026], [122495000.0, 0.0649], [122494000.0, 0.0017], [122493000.0, 0.045]], "asks": [[122507000.0, 0.0143], [122508000.0, 0.001], [122516000.0, 0.0], [122534000.0, 0.0031], [122545000.0, 0.0], [122547000.0, 0.0], [122562000.0, 0.0037], [122564000.0, 0.0037], [122565000.0, 0.003], [122570000.0, 0.1]]},
{"timestamp": "1743938561586", "bids": [[122505000.0, 0.1008], [122504000.0, 0.0278], [122501000.0, 0.0], [122500000.0, 0.5914], [122499000.0, 0.0012], [122498000.0, 0.0212], [122497000.0, 0.0032], [122496000.0, 0.026], [122495000.0, 0.0649], [122494000.0, 0.0017]], "asks": [[122507000.0, 0.0143], [122508000.0, 0.001], [122516000.0, 0.0], [122534000.0, 0.0031], [122545000.0, 0.0], [122547000.0, 0.0], [122564000.0, 0.0037], [122565000.0, 0.003], [122569000.0, 0.1601], [122574000.0, 0.1]]},
{"timestamp": "1743938562101", "bids": [[122504000.0, 0.0278], [122501000.0, 0.1008], [122500000.0, 0.5914], [122499000.0, 0.0012], [122498000.0, 0.0212], [122497000.0, 0.0032], [122496000.0, 0.026], [122495000.0, 0.0649], [122494000.0, 0.0017], [122493000.0, 0.045]], "asks": [[122507000.0, 0.0144], [122508000.0, 0.001], [122516000.0, 0.0], [122534000.0, 0.0031], [122545000.0, 0.0], [122547000.0, 0.0], [122564000.0, 0.0037], [122565000.0, 0.003], [122573000.0, 0.0143], [122576000.0, 0.0]]},
{"timestamp": "1743938562613", "bids": [[122501000.0, 0.1008], [122500000.0, 0.5914], [122499000.0, 0.0012], [122498000.0, 0.0212], [122497000.0, 0.0032], [122496000.0, 0.026], [122495000.0, 0.0649], [122494000.0, 0.0017], [122493000.0, 0.045], [122492000.0, 0.0206]], "asks": [[122507000.0, 0.0144], [122508000.0, 0.001], [122516000.0, 0.0], [122534000.0, 0.0031], [122545000.0, 0.0], [122547000.0, 0.0], [122564000.0, 0.0037], [122565000.0, 0.003], [122571000.0, 0.1601], [122572000.0, 0.1]]},
{"timestamp": "1743938563147", "bids": [[122501000.0, 0.0], [122500000.0, 0.5914], [122499000.0, 0.0012], [122498000.0, 0.0212], [122497000.0, 0.0032], [122496000.0, 0.026], [122495000.0, 0.0649], [122494000.0, 0.0017], [122493000.0, 0.045], [122492000.0, 0.0206]], "asks": [[122504000.0, 0.0057], [122507000.0, 0.0144], [122508000.0, 0.001], [122516000.0, 0.0], [122534000.0, 0.0031], [122545000.0, 0.0], [122547000.0, 0.0], [122564000.0, 0.0037], [122565000.0, 0.003], [122569000.0, 0.1604]]},
{"timestamp": "1743938563626", "bids": [[122501000.0, 0.0989], [122500000.0, 0.5914], [122499000.0, 0.0012], [122498000.0, 0.0212], [122497000.0, 0.0032], [122496000.0, 0.026], [122495000.0, 0.0649], [122494000.0, 0.0017], [122493000.0, 0.045], [122492000.0, 0.0206]], "asks": [[122504000.0, 0.0057], [122507000.0, 0.0144], [122508000.0, 0.001], [122516000.0, 0.0], [122534000.0, 0.0031], [122545000.0, 0.0], [122547000.0, 0.0], [122564000.0, 0.0037], [122565000.0, 0.003], [122568000.0, 0.1002]]},
{"timestamp": "1743938564165", "bids": [[122515000.0, 0.0248], [122514000.0, 0.0044], [122507000.0, 0.0168], [122506000.0, 0.0126], [122502000.0, 0.003], [122501000.0, 0.0989], [122500000.0, 0.6385], [122499000.0, 0.0429], [122498000.0, 0.0053], [122497000.0, 0.0032]], "asks": [[122516000.0, 0.0], [122531000.0, 0.0023], [122534000.0, 0.0031], [122545000.0, 0.0], [122547000.0, 0.0], [122560000.0, 0.0037], [122564000.0, 0.0037], [122565000.0, 0.003], [122567000.0, 0.1604], [122572000.0, 0.1002]]},
{"timestamp": "1743938564679", "bids": [[122515000.0, 0.0248], [122514000.0, 0.0044], [122507000.0, 0.0168], [122506000.0, 0.0126], [122504000.0, 0.0057], [122502000.0, 0.003], [122501000.0, 0.0213], [122500000.0, 0.6385], [122499000.0, 0.0429], [122498000.0, 0.0053]], "asks": [[122516000.0, 0.0], [122531000.0, 0.0023], [122534000.0, 0.0008], [122545000.0, 0.0], [122547000.0, 0.0], [122560000.0, 0.0037], [122565000.0, 0.003], [122571000.0, 0.1604], [122576000.0, 0.0], [122578000.0, 0.0]]},
{"timestamp": "1743938565164", "bids": [[122515000.0, 0.0209], [122514000.0, 0.0044], [122509000.0, 0.0159], [122508000.0, 0.0162], [122507000.0, 0.0168], [122506000.0, 0.0126], [122504000.0, 0.039], [122503000.0, 0.0254], [122501000.0, 0.0213], [122500000.0, 0.6385]], "asks": [[122516000.0, 0.0], [122531000.0, 0.0023], [122534000.0, 0.0008], [122545000.0, 0.0], [122547000.0, 0.0], [122560000.0, 0.0037], [122565000.0, 0.003], [122566000.0, 0.1002], [122571000.0, 0.1604], [122576000.0, 0.0]]},
{"timestamp": "1743938565686", "bids": [[122515000.0, 0.0171], [122514000.0, 0.0044], [122510000.0, 0.0989], [122509000.0, 0.0159], [122508000.0, 0.0162], [122507000.0, 0.0168], [122506000.0, 0.0126], [122504000.0, 0.039], [122503000.0, 0.0254], [122501000.0, 0.0213]], "asks": [[122516000.0, 0.0], [122531000.0, 0.0023], [122534000.0, 0.0008], [122545000.0, 0.0], [122547000.0, 0.0], [122560000.0, 0.0037], [122565000.0, 0.003], [122576000.0, 0.0], [122578000.0, 0.0], [122581000.0, 0.1645]]},
{"timestamp": "1743938566216", "bids": [[122515000.0, 0.0171], [122514000.0, 0.0044], [122510000.0, 0.0989], [122509000.0, 0.0159], [122508000.0, 0.0162], [122507000.0, 0.0168], [122506000.0, 0.0126], [122504000.0, 0.039], [122503000.0, 0.0254], [122501000.0, 0.0213]], "asks": [[122516000.0, 0.0], [122531000.0, 0.0023], [122534000.0, 0.0008], [122545000.0, 0.0], [122547000.0, 0.0], [122560000.0, 0.0037], [122565000.0, 0.003], [122576000.0, 0.0], [122578000.0, 0.0], [122581000.0, 0.1043]]},
{"timestamp": "1743938566735", "bids": [[122515000.0, 0.0171], [122514000.0, 0.0044], [122510000.0, 0.0989], [122509000.0, 0.0159], [122508000.0, 0.0162], [122507000.0, 0.0168], [122506000.0, 0.0126], [122504000.0, 0.039], [122503000.0, 0.0254], [122501000.0, 0.0213]], "asks": [[122516000.0, 0.0], [122531000.0, 0.0023], [122534000.0, 0.0008], [122545000.0, 0.0], [122547000.0, 0.0], [122560000.0, 0.0037], [122565000.0, 0.003], [122576000.0, 0.0], [122578000.0, 0.0], [122580000.0, 0.1591]]},
{"timestamp": "1743938567281", "bids": [[122514000.0, 0.0044], [122510000.0, 0.0989], [122509000.0, 0.0159], [122508000.0, 0.0162], [122507000.0, 0.0168], [122506000.0, 0.0126], [122504000.0, 0.039], [122503000.0, 0.0254], [122501000.0, 0.0213], [122500000.0, 0.6385]], "asks": [[122515000.0, 0.0068], [122516000.0, 0.0], [122531000.0, 0.0023], [122534000.0, 0.0008], [122545000.0, 0.0], [122547000.0, 0.0], [122560000.0, 0.0037], [122565000.0, 0.003], [122576000.0, 0.0], [122578000.0, 0.0]]},
{"timestamp": "1743938567759", "bids": [[122514000.0, 0.0044], [122510000.0, 0.0989], [122509000.0, 0.0159], [122508000.0, 0.0162], [122507000.0, 0.0168], [122506000.0, 0.0126], [122504000.0, 0.039], [122503000.0, 0.0254], [122501000.0, 0.0213], [122500000.0, 0.6385]], "asks": [[122515000.0, 0.0068], [122516000.0, 0.0], [122531000.0, 0.0023], [122534000.0, 0.0008], [122545000.0, 0.0], [122547000.0, 0.0], [122560000.0, 0.0037], [122565000.0, 0.003], [122576000.0, 0.0], [122578000.0, 0.0]]},
{"timestamp": "1743938568267", "bids": [[122514000.0, 0.0044], [122509000.0, 0.1143], [122508000.0, 0.0162], [122507000.0, 0.0168], [122506000.0, 0.0126], [122504000.0, 0.039], [122503000.0, 0.0254], [122501000.0, 0.0213], [122500000.0, 0.6385], [122499000.0, 0.0429]], "asks": [[122515000.0, 0.0068], [122516000.0, 0.0], [122534000.0, 0.0008], [122543000.0, 0.0023], [122545000.0, 0.0], [122547000.0, 0.0], [122565000.0, 0.003], [122572000.0, 0.0037], [122576000.0, 0.0], [122578000.0, 0.0]]},
{"timestamp": "1743938568778", "bids": [[122514000.0, 0.0044], [122509000.0, 0.1143], [122508000.0, 0.0162], [122507000.0, 0.0168], [122506000.0, 0.0126], [122504000.0, 0.039], [122503000.0, 0.0254], [122501000.0, 0.0213], [122500000.0, 0.6385], [122499000.0, 0.0429]], "asks": [[122515000.0, 0.0068], [122516000.0, 0.0], [122534000.0, 0.0008], [122543000.0, 0.0023], [122545000.0, 0.0], [122547000.0, 0.0], [122565000.0, 0.003], [122570000.0, 0.0068], [122572000.0, 0.0037], [122575000.0, 0.0993]]},
{"timestamp": "1743938569294", "bids": [[122514000.0, 0.0044], [122509000.0, 0.1143], [122508000.0, 0.0162], [122507000.0, 0.0168], [122506000.0, 0.0126], [122504000.0, 0.039], [122503000.0, 0.0254], [122501000.0, 0.0213], [122500000.0, 0.6385], [122499000.0, 0.0429]], "asks": [[122515000.0, 0.0068], [122516000.0, 0.0], [122534000.0, 0.0008], [122543000.0, 0.0023], [122545000.0, 0.0], [122547000.0, 0.0], [122565000.0, 0.003], [122570000.0, 0.0068], [122572000.0, 0.0037], [122576000.0, 0.0]]},
{"timestamp": "1743938569807", "bids": [[122514000.0, 0.0044], [122510000.0, 0.0983], [122509000.0, 0.0159], [122508000.0, 0.0162], [122507000.0, 0.0168], [122506000.0, 0.0126], [122504000.0, 0.039], [122503000.0, 0.0254], [122501000.0, 0.0213], [122500000.0, 0.6385]], "asks": [[122515000.0, 0.0068], [122516000.0, 0.0], [122534000.0, 0.0008], [122543000.0, 0.0023], [122545000.0, 0.0], [122547000.0, 0.0], [122565000.0, 0.003], [122570000.0, 0.0068], [122572000.0, 0.0037], [122576000.0, 0.0]]},
{"timestamp": "1743938570320", "bids": [[122510000.0, 0.0983], [122509000.0, 0.0159], [122508000.0, 0.0162], [122507000.0, 0.0168], [122506000.0, 0.0126], [122504000.0, 0.039], [122503000.0, 0.0254], [122501000.0, 0.0213], [122500000.0, 0.6385], [122499000.0, 0.0429]], "asks": [[122515000.0, 0.0068], [122516000.0, 0.0], [122534000.0, 0.0008], [122543000.0, 0.0023], [122545000.0, 0.0], [122547000.0, 0.0], [122565000.0, 0.003], [122570000.0, 0.159], [122572000.0, 0.0037], [122576000.0, 0.0]]},
{"timestamp": "1743938570825", "bids": [[122509000.0, 0.0], [122508000.0, 0.0983], [122501000.0, 0.0], [122500000.0, 0.5914], [122499000.0, 0.0012], [122498000.0, 0.0054], [122497000.0, 0.0032], [122496000.0, 0.0098], [122495000.0, 0.0411], [122494000.0, 0.0017]], "asks": [[122515000.0, 0.0067], [122516000.0, 0.0], [122534000.0, 0.0008], [122543000.0, 0.0023], [122545000.0, 0.0], [122547000.0, 0.0], [122565000.0, 0.003], [122569000.0, 0.0993], [122572000.0, 0.0037], [122573000.0, 0.0068]]},
{"timestamp": "1743938571318", "bids": [[122510000.0, 0.0002], [122509000.0, 0.0], [122505000.0, 0.0983], [122503000.0, 0.0002], [122501000.0, 0.0], [122500000.0, 0.5914], [122499000.0, 0.0012], [122498000.0, 0.0054], [122497000.0, 0.0032], [122496000.0, 0.0098]], "asks": [[122515000.0, 0.0067], [122516000.0, 0.0], [122534000.0, 0.0008], [122543000.0, 0.0023], [122545000.0, 0.0], [122547000.0, 0.0], [122565000.0, 0.003], [122572000.0, 0.0037], [122573000.0, 0.0068], [122576000.0, 0.0]]},
{"timestamp": "1743938571856", "bids": [[122515000.0, 0.0176], [122511000.0, 0.0059], [122510000.0, 0.0237], [122509000.0, 0.0], [122503000.0, 0.0181], [122501000.0, 0.0983], [122500000.0, 0.5914], [122499000.0, 0.0012], [122498000.0, 0.0054], [122497000.0, 0.0032]], "asks": [[122516000.0, 0.0], [122534000.0, 0.0008], [122543000.0, 0.0023], [122545000.0, 0.0], [122547000.0, 0.0], [122565000.0, 0.003], [122572000.0, 0.103], [122576000.0, 0.0], [122578000.0, 0.0], [122579000.0, 0.159]]},
{"timestamp": "1743938572342", "bids": [[122515000.0, 0.0176], [122510000.0, 0.0238], [122509000.0, 0.0], [122503000.0, 0.0181], [122501000.0, 0.0983], [122500000.0, 0.5914], [122499000.0, 0.0012], [122498000.0, 0.0054], [122497000.0, 0.0032], [122496000.0, 0.0098]], "asks": [[122516000.0, 0.0], [122534000.0, 0.0008], [122541000.0, 0.0023], [122545000.0, 0.0], [122547000.0, 0.0], [122565000.0, 0.003], [122570000.0, 0.0037], [122574000.0, 0.0067], [122576000.0, 0.0], [122578000.0, 0.099]]},
{"timestamp": "1743938572894", "bids": [[122515000.0, 0.0159], [122510000.0, 0.0238], [122509000.0, 0.0], [122504000.0, 0.0979], [122503000.0, 0.0181], [122501000.0, 0.0], [122500000.0, 0.5914], [122499000.0, 0.0012], [122498000.0, 0.0054], [122497000.0, 0.0032]], "asks": [[122516000.0, 0.0], [122534000.0, 0.0008], [122541000.0, 0.0023], [122545000.0, 0.0], [122547000.0, 0.0], [122565000.0, 0.003], [122570000.0, 0.0037], [122573000.0, 0.099], [122574000.0, 0.0067], [122576000.0, 0.0]]},
{"timestamp": "1743938573368", "bids": [[122515000.0, 0.0115], [122510000.0, 0.0238], [122509000.0, 0.0], [122504000.0, 0.0979], [122503000.0, 0.0181], [122501000.0, 0.0], [122500000.0, 0.5914], [122499000.0, 0.0012], [122498000.0, 0.0054], [122497000.0, 0.0032]], "asks": [[122516000.0, 0.0], [122534000.0, 0.0008], [122541000.0, 0.0023], [122545000.0, 0.0], [122547000.0, 0.0], [122565000.0, 0.003], [122570000.0, 0.0037], [122571000.0, 0.099], [122572000.0, 0.1585], [122573000.0, 0.0048]]},
{"timestamp": "1743938573890", "bids": [[122515000.0, 0.0115], [122510000.0, 0.0238], [122509000.0, 0.0], [122504000.0, 0.0979], [122503000.0, 0.0181], [122501000.0, 0.0], [122500000.0, 0.5914], [122499000.0, 0.0012], [122498000.0, 0.0054], [122497000.0, 0.0032]], "asks": [[122516000.0, 0.0], [122534000.0, 0.0008], [122541000.0, 0.0023], [122545000.0, 0.0], [122547000.0, 0.0], [122565000.0, 0.003], [122570000.0, 0.1622], [122573000.0, 0.0048], [122576000.0, 0.0], [122578000.0, 0.0]]},
{"timestamp": "1743938574387", "bids": [[122515000.0, 0.0104], [122510000.0, 0.0238], [122509000.0, 0.0], [122504000.0, 0.0979], [122503000.0, 0.0181], [122501000.0, 0.0], [122500000.0, 0.5914], [122499000.0, 0.0012], [122498000.0, 0.0054], [122497000.0, 0.0032]], "asks": [[122516000.0, 0.0], [122534000.0, 0.0008], [122541000.0, 0.0023], [122545000.0, 0.0], [122547000.0, 0.0], [122565000.0, 0.003], [122570000.0, 0.0037], [122573000.0, 0.0048], [122576000.0, 0.0], [122578000.0, 0.0]]},
{"timestamp": "1743938574902", "bids": [[122515000.0, 0.0047], [122510000.0, 0.0238], [122509000.0, 0.0], [122504000.0, 0.0979], [122503000.0, 0.0181], [122501000.0, 0.0], [122500000.0, 0.5914], [122499000.0, 0.0012], [122498000.0, 0.0054], [122497000.0, 0.0032]], "asks": [[122516000.0, 0.0], [122534000.0, 0.0008], [122541000.0, 0.0023], [122545000.0, 0.0], [122547000.0, 0.0], [122565000.0, 0.003], [122570000.0, 0.0037], [122573000.0, 0.0048], [122576000.0, 0.0], [122578000.0, 0.0]]},
{"timestamp": "1743938575422", "bids": [[122515000.0, 0.0047], [122510000.0, 0.0238], [122509000.0, 0.0], [122504000.0, 0.0979], [122503000.0, 0.0181], [122501000.0, 0.0], [122500000.0, 0.5914], [122499000.0, 0.0012], [122498000.0, 0.0054], [122497000.0, 0.0032]], "asks": [[122516000.0, 0.0], [122534000.0, 0.0008], [122541000.0, 0.0023], [122545000.0, 0.0], [122547000.0, 0.0], [122565000.0, 0.003], [122570000.0, 0.0037], [122573000.0, 0.0048], [122576000.0, 0.0], [122578000.0, 0.0]]},
{"timestamp": "1743938575954", "bids": [[122515000.0, 0.0047], [122510000.0, 0.0238], [122509000.0, 0.0], [122504000.0, 0.0979], [122503000.0, 0.0181], [122501000.0, 0.0025], [122500000.0, 0.5914], [122499000.0, 0.0012], [122498000.0, 0.0054], [122497000.0, 0.0032]], "asks": [[122516000.0, 0.0], [122534000.0, 0.0008], [122545000.0, 0.0], [122547000.0, 0.0], [122557000.0, 0.0023], [122565000.0, 0.003], [122570000.0, 0.0037], [122573000.0, 0.0048], [122576000.0, 0.0], [122578000.0, 0.0]]},
{"timestamp": "1743938576445", "bids": [[122510000.0, 0.0238], [122509000.0, 0.0], [122504000.0, 0.0979], [122503000.0, 0.0181], [122501000.0, 0.0025], [122500000.0, 0.5914], [122499000.0, 0.0012], [122498000.0, 0.0054], [122497000.0, 0.0032], [122496000.0, 0.0098]], "asks": [[122515000.0, 0.0016], [122516000.0, 0.0], [122534000.0, 0.0008], [122545000.0, 0.0], [122547000.0, 0.0], [122557000.0, 0.0023], [122565000.0, 0.003], [122573000.0, 0.0048], [122576000.0, 0.0], [122578000.0, 0.0987]]},
{"timestamp": "1743938576985", "bids": [[122510000.0, 0.0238], [122509000.0, 0.0], [122504000.0, 0.0979], [122503000.0, 0.0181], [122501000.0, 0.0025], [122500000.0, 0.5914], [122499000.0, 0.0012], [122498000.0, 0.0054], [122497000.0, 0.0032], [122496000.0, 0.0098]], "asks": [[122515000.0, 0.0016], [122516000.0, 0.0], [122534000.0, 0.0008], [122545000.0, 0.0], [122547000.0, 0.0], [122557000.0, 0.0023], [122565000.0, 0.003], [122573000.0, 0.0048], [122576000.0, 0.0], [122577000.0, 0.1579]]},
{"timestamp": "1743938577494", "bids": [[122510000.0, 0.0213], [122509000.0, 0.0], [122504000.0, 0.0979], [122503000.0, 0.0181], [122501000.0, 0.0025], [122500000.0, 0.5914], [122499000.0, 0.0012], [122498000.0, 0.0054], [122497000.0, 0.0032], [122496000.0, 0.0098]], "asks": [[122516000.0, 0.0], [122534000.0, 0.0008], [122545000.0, 0.0], [122547000.0, 0.0], [122557000.0, 0.0023], [122565000.0, 0.003], [122573000.0, 0.0048], [122576000.0, 0.0], [122578000.0, 0.0], [122579000.0, 0.1579]]},
{"timestamp": "1743938577988", "bids": [[122510000.0, 0.0205], [122509000.0, 0.0], [122504000.0, 0.0979], [122503000.0, 0.0181], [122501000.0, 0.0025], [122500000.0, 0.5914], [122499000.0, 0.0012], [122498000.0, 0.0054], [122497000.0, 0.0032], [122496000.0, 0.0098]], "asks": [[122516000.0, 0.0], [122534000.0, 0.0008], [122545000.0, 0.0], [122547000.0, 0.0], [122557000.0, 0.0023], [122565000.0, 0.003], [122576000.0, 0.0], [122578000.0, 0.0987], [122580000.0, 0.1579], [122581000.0, 0.0]]},
{"timestamp": "1743938578515", "bids": [[122511000.0, 0.0975], [122510000.0, 0.0205], [122509000.0, 0.0], [122503000.0, 0.0181], [122501000.0, 0.036], [122500000.0, 0.5914], [122499000.0, 0.0012], [122498000.0, 0.0054], [122497000.0, 0.0032], [122496000.0, 0.0098]], "asks": [[122516000.0, 0.0], [122534000.0, 0.0008], [122545000.0, 0.0], [122547000.0, 0.0], [122557000.0, 0.0023], [122565000.0, 0.003], [122576000.0, 0.0048], [122578000.0, 0.0], [122579000.0, 0.0987], [122581000.0, 0.1579]]},
{"timestamp": "1743938579029", "bids": [[122511000.0, 0.0975], [122510000.0, 0.0205], [122509000.0, 0.0], [122504000.0, 0.0335], [122503000.0, 0.0181], [122501000.0, 0.0025], [122500000.0, 0.5914], [122499000.0, 0.0012], [122498000.0, 0.0054], [122497000.0, 0.0032]], "asks": [[122516000.0, 0.0], [122534000.0, 0.0008], [122545000.0, 0.0], [122547000.0, 0.0], [122557000.0, 0.0023], [122565000.0, 0.003], [122576000.0, 0.1035], [122578000.0, 0.1579], [122581000.0, 0.0], [122583000.0, 0.377]]},
{"timestamp": "1743938579541", "bids": [[122511000.0, 0.096], [122510000.0, 0.0205], [122509000.0, 0.0], [122504000.0, 0.0335], [122503000.0, 0.0181], [122501000.0, 0.0025], [122500000.0, 0.6014], [122499000.0, 0.0012], [122498000.0, 0.0054], [122497000.0, 0.0032]], "asks": [[122516000.0, 0.0], [122534000.0, 0.0008], [122545000.0, 0.0], [122547000.0, 0.0], [122557000.0, 0.0023], [122565000.0, 0.003], [122576000.0, 0.0048], [122577000.0, 0.0987], [122578000.0, 0.0], [122581000.0, 0.0]]},
{"timestamp": "1743938580028", "bids": [[122511000.0, 0.096], [122510000.0, 0.0205], [122509000.0, 0.0], [122503000.0, 0.0181], [122501000.0, 0.0335], [122500000.0, 0.6014], [122499000.0, 0.0012], [122498000.0, 0.0054], [122497000.0, 0.0032], [122496000.0, 0.0098]], "asks": [[122516000.0, 0.0], [122534000.0, 0.0008], [122545000.0, 0.0], [122547000.0, 0.0], [122555000.0, 0.0023], [122557000.0, 0.0023], [122565000.0, 0.003], [122576000.0, 0.1627], [122578000.0, 0.0], [122581000.0, 0.1579]]},
{"timestamp": "1743938580568", "bids": [[122524000.0, 0.0168], [122519000.0, 0.0161], [122515000.0, 0.0152], [122514000.0, 0.0298], [122511000.0, 0.096], [122510000.0, 0.0205], [122509000.0, 0.0], [122504000.0, 0.0313], [122503000.0, 0.0472], [122501000.0, 0.0025]], "asks": [[122534000.0, 0.0008], [122545000.0, 0.0], [122547000.0, 0.0], [122555000.0, 0.0023], [122565000.0, 0.003], [122576000.0, 0.1579], [122578000.0, 0.0], [122581000.0, 0.0], [122586000.0, 0.0], [122588000.0, 0.0037]]},
{"timestamp": "1743938581080", "bids": [[122527000.0, 0.0001], [122524000.0, 0.0168], [122522000.0, 0.0001], [122521000.0, 0.0126], [122520000.0, 0.0159], [122519000.0, 0.0161], [122516000.0, 0.0461], [122515000.0, 0.0325], [122514000.0, 0.09], [122512000.0, 0.0314]], "asks": [[122534000.0, 0.0008], [122545000.0, 0.0], [122547000.0, 0.0], [122555000.0, 0.0023], [122565000.0, 0.003], [122576000.0, 0.0], [122578000.0, 0.0], [122581000.0, 0.0], [122585000.0, 0.0048], [122586000.0, 0.0]]},
{"timestamp": "1743938581564", "bids": [[122525000.0, 0.0968], [122520000.0, 0.0314], [122514000.0, 0.0001], [122509000.0, 0.0], [122508000.0, 0.0162], [122506000.0, 0.0174], [122501000.0, 0.0279], [122500000.0, 0.6014], [122499000.0, 0.0013], [122498000.0, 0.0054]], "asks": [[122534000.0, 0.0008], [122545000.0, 0.0], [122547000.0, 0.0], [122555000.0, 0.0023], [122565000.0, 0.003], [122576000.0, 0.0], [122578000.0, 0.0], [122581000.0, 0.0], [122585000.0, 0.0048], [122586000.0, 0.0]]},
{"timestamp": "1743938582098", "bids": [[122543000.0, 0.0001], [122539000.0, 0.0159], [122534000.0, 0.0162], [122532000.0, 0.0204], [122531000.0, 0.0249], [122530000.0, 0.0152], [122526000.0, 0.0121], [122525000.0, 0.0968], [122523000.0, 0.0172], [122522000.0, 0.0968]], "asks": [[122545000.0, 0.0], [122547000.0, 0.0], [122555000.0, 0.0023], [122565000.0, 0.003], [122576000.0, 0.0], [122578000.0, 0.0], [122581000.0, 0.0], [122586000.0, 0.0], [122588000.0, 0.0037], [122591000.0, 0.0]]},
{"timestamp": "1743938582611", "bids": [[122532000.0, 0.0001], [122531000.0, 0.0987], [122530000.0, 0.0152], [122526000.0, 0.0121], [122525000.0, 0.018], [122523000.0, 0.017], [122522000.0, 0.0968], [122519000.0, 0.0234], [122518000.0, 0.0237], [122517000.0, 0.0244]], "asks": [[122545000.0, 0.0], [122547000.0, 0.0], [122555000.0, 0.0023], [122565000.0, 0.003], [122576000.0, 0.0], [122578000.0, 0.0], [122581000.0, 0.0], [122586000.0, 0.0], [122588000.0, 0.0037], [122591000.0, 0.0]]},
{"timestamp": "1743938583107", "bids": [[122532000.0, 0.0001], [122531000.0, 0.0987], [122530000.0, 0.0152], [122527000.0, 0.0968], [122526000.0, 0.0121], [122525000.0, 0.0182], [122523000.0, 0.017], [122519000.0, 0.0234], [122518000.0, 0.0237], [122517000.0, 0.0244]], "asks": [[122545000.0, 0.0], [122547000.0, 0.0], [122555000.0, 0.0023], [122565000.0, 0.003], [122576000.0, 0.0], [122578000.0, 0.0], [122581000.0, 0.0], [122586000.0, 0.0], [122588000.0, 0.0037], [122591000.0, 0.0]]},
{"timestamp": "1743938583636", "bids": [[122531000.0, 0.0966], [122530000.0, 0.0152], [122526000.0, 0.1085], [122525000.0, 0.0182], [122523000.0, 0.017], [122519000.0, 0.0234], [122518000.0, 0.0237], [122517000.0, 0.0244], [122515000.0, 0.0162], [122514000.0, 0.0143]], "asks": [[122547000.0, 0.0], [122555000.0, 0.0023], [122565000.0, 0.003], [122576000.0, 0.0], [122578000.0, 0.0], [122581000.0, 0.0], [122586000.0, 0.0], [122588000.0, 0.0037], [122591000.0, 0.0], [122594000.0, 0.1574]]},
{"timestamp": "1743938584133", "bids": [[122531000.0, 0.193], [122530000.0, 0.0152], [122526000.0, 0.0121], [122525000.0, 0.0182], [122523000.0, 0.017], [122519000.0, 0.0234], [122518000.0, 0.0237], [122517000.0, 0.0244], [122515000.0, 0.0162], [122514000.0, 0.0143]], "asks": [[122547000.0, 0.0], [122565000.0, 0.003], [122576000.0, 0.0], [122578000.0, 0.0], [122579000.0, 0.0023], [122581000.0, 0.0], [122586000.0, 0.0], [122590000.0, 0.0983], [122591000.0, 0.0], [122593000.0, 0.0983]]},
{"timestamp": "1743938584647", "bids": [[122531000.0, 0.0966], [122530000.0, 0.0152], [122527000.0, 0.0964], [122526000.0, 0.0121], [122525000.0, 0.0182], [122523000.0, 0.017], [122519000.0, 0.0234], [122518000.0, 0.0237], [122517000.0, 0.0244], [122515000.0, 0.0162]], "asks": [[122547000.0, 0.0], [122565000.0, 0.003], [122576000.0, 0.0], [122578000.0, 0.0], [122579000.0, 0.0023], [122581000.0, 0.0], [122586000.0, 0.0], [122589000.0, 0.1574], [122591000.0, 0.0], [122593000.0, 0.0983]]},
{"timestamp": "1743938585174", "bids": [[122531000.0, 0.0754], [122530000.0, 0.0152], [122527000.0, 0.0964], [122526000.0, 0.0121], [122525000.0, 0.0001], [122523000.0, 0.017], [122519000.0, 0.0234], [122518000.0, 0.0237], [122517000.0, 0.0244], [122514000.0, 0.0143]], "asks": [[122547000.0, 0.0], [122565000.0, 0.003], [122576000.0, 0.0], [122578000.0, 0.0], [122579000.0, 0.0023], [122581000.0, 0.0], [122586000.0, 0.0], [122591000.0, 0.0983], [122592000.0, 0.1574], [122596000.0, 0.0698]]},
{"timestamp": "1743938585697", "bids": [[122547000.0, 0.0], [122531000.0, 0.0754], [122530000.0, 0.0152], [122527000.0, 0.0964], [122526000.0, 0.0121], [122525000.0, 0.0001], [122523000.0, 0.017], [122519000.0, 0.0234], [122518000.0, 0.0237], [122517000.0, 0.0244]], "asks": [[122565000.0, 0.003], [122576000.0, 0.0], [122578000.0, 0.0], [122579000.0, 0.0023], [122581000.0, 0.0], [122586000.0, 0.0], [122590000.0, 0.1574], [122591000.0, 0.0], [122594000.0, 0.0983], [122596000.0, 0.0698]]},
{"timestamp": "1743938586204", "bids": [[122547000.0, 0.0], [122531000.0, 0.1718], [122530000.0, 0.0152], [122527000.0, 0.0], [122526000.0, 0.0121], [122525000.0, 0.0001], [122523000.0, 0.017], [122519000.0, 0.0234], [122518000.0, 0.0237], [122517000.0, 0.0244]], "asks": [[122565000.0, 0.003], [122576000.0, 0.0], [122578000.0, 0.0], [122579000.0, 0.0023], [122581000.0, 0.0], [122586000.0, 0.0], [122591000.0, 0.0], [122593000.0, 0.1574], [122596000.0, 0.0698], [122601000.0, 0.0]]},
{"timestamp": "1743938586701", "bids": [[122547000.0, 0.0], [122532000.0, 0.0964], [122531000.0, 0.0754], [122530000.0, 0.0152], [122527000.0, 0.0], [122526000.0, 0.0121], [122525000.0, 0.0001], [122523000.0, 0.017], [122519000.0, 0.0234], [122518000.0, 0.0237]], "asks": [[122565000.0, 0.003], [122576000.0, 0.0], [122578000.0, 0.0], [122579000.0, 0.0023], [122581000.0, 0.0], [122586000.0, 0.0], [122591000.0, 0.0], [122592000.0, 0.0984], [122595000.0, 0.1574], [122596000.0, 0.0698]]},
{"timestamp": "1743938587234", "bids": [[122547000.0, 0.0], [122531000.0, 0.0754], [122530000.0, 0.0152], [122527000.0, 0.0964], [122526000.0, 0.0121], [122525000.0, 0.0001], [122523000.0, 0.017], [122519000.0, 0.0234], [122518000.0, 0.0237], [122517000.0, 0.0244]], "asks": [[122565000.0, 0.003], [122576000.0, 0.0], [122578000.0, 0.0], [122579000.0, 0.0023], [122581000.0, 0.0], [122586000.0, 0.0], [122591000.0, 0.0], [122593000.0, 0.1574], [122596000.0, 0.0698], [122601000.0, 0.0]]},
{"timestamp": "1743938587734", "bids": [[122547000.0, 0.0], [122531000.0, 0.0752], [122530000.0, 0.0152], [122527000.0, 0.0], [122526000.0, 0.0121], [122525000.0, 0.0001], [122523000.0, 0.017], [122520000.0, 0.0964], [122519000.0, 0.0234], [122518000.0, 0.0237]], "asks": [[122565000.0, 0.003], [122576000.0, 0.0], [122578000.0, 0.0], [122579000.0, 0.0023], [122581000.0, 0.0], [122586000.0, 0.0], [122591000.0, 0.0], [122592000.0, 0.0984], [122596000.0, 0.0698], [122601000.0, 0.0]]},
{"timestamp": "1743938588250", "bids": [[122547000.0, 0.0], [122531000.0, 0.0752], [122530000.0, 0.0152], [122527000.0, 0.0], [122526000.0, 0.0121], [122525000.0, 0.0001], [122524000.0, 0.0964], [122523000.0, 0.017], [122519000.0, 0.0234], [122518000.0, 0.0237]], "asks": [[122565000.0, 0.003], [122576000.0, 0.0], [122578000.0, 0.0], [122581000.0, 0.0], [122583000.0, 0.0023], [122586000.0, 0.0], [122591000.0, 0.1574], [122595000.0, 0.0984], [122596000.0, 0.0698], [122601000.0, 0.0]]},
{"timestamp": "1743938588741", "bids": [[122531000.0, 0.066], [122530000.0, 0.0152], [122527000.0, 0.0964], [122526000.0, 0.0121], [122525000.0, 0.0001], [122523000.0, 0.017], [122519000.0, 0.0234], [122518000.0, 0.0237], [122517000.0, 0.0244], [122514000.0, 0.0143]], "asks": [[122590000.0, 0.0839], [122591000.0, 0.0], [122593000.0, 0.157], [122596000.0, 0.0698], [122601000.0, 0.0], [122604000.0, 0.0152], [122605000.0, 0.0152], [122606000.0, 0.0], [122607000.0, 0.0204], [122608000.0, 0.0]]},
{"timestamp": "1743938589227", "bids": [[122531000.0, 0.066], [122530000.0, 0.0152], [122527000.0, 0.0964], [122526000.0, 0.0121], [122525000.0, 0.0001], [122523000.0, 0.017], [122519000.0, 0.0234], [122518000.0, 0.0237], [122517000.0, 0.0244], [122514000.0, 0.0143]], "asks": [[122589000.0, 0.157], [122591000.0, 0.0], [122592000.0, 0.0981], [122596000.0, 0.0698], [122601000.0, 0.0], [122604000.0, 0.0152], [122605000.0, 0.0152], [122606000.0, 0.0], [122607000.0, 0.0204], [122608000.0, 0.0]]},
{"timestamp": "1743938589762", "bids": [[122532000.0, 0.096], [122531000.0, 0.066], [122530000.0, 0.0152], [122527000.0, 0.0], [122526000.0, 0.0121], [122525000.0, 0.0001], [122523000.0, 0.017], [122519000.0, 0.0234], [122518000.0, 0.0237], [122517000.0, 0.0244]], "asks": [[122591000.0, 0.0], [122595000.0, 0.1568], [122596000.0, 0.0698], [122601000.0, 0.0], [122604000.0, 0.0152], [122605000.0, 0.0152], [122606000.0, 0.0], [122607000.0, 0.0204], [122608000.0, 0.0], [122609000.0, 0.0031]]},
{"timestamp": "1743938590255", "bids": [[122532000.0, 0.096], [122531000.0, 0.066], [122530000.0, 0.0152], [122527000.0, 0.0001], [122526000.0, 0.0121], [122525000.0, 0.0001], [122523000.0, 0.017], [122519000.0, 0.0234], [122518000.0, 0.0237], [122517000.0, 0.0244]], "asks": [[122591000.0, 0.0], [122595000.0, 0.1568], [122596000.0, 0.0698], [122601000.0, 0.0], [122604000.0, 0.0152], [122605000.0, 0.0152], [122606000.0, 0.0], [122607000.0, 0.0204], [122608000.0, 0.0], [122609000.0, 0.0031]]},
{"timestamp": "1743938590804", "bids": [[122532000.0, 0.096], [122531000.0, 0.066], [122530000.0, 0.0152], [122527000.0, 0.0001], [122526000.0, 0.0121], [122525000.0, 0.0001], [122523000.0, 0.017], [122519000.0, 0.0234], [122518000.0, 0.0237], [122517000.0, 0.0244]], "asks": [[122591000.0, 0.0], [122595000.0, 0.1568], [122596000.0, 0.0698], [122601000.0, 0.0], [122604000.0, 0.0152], [122605000.0, 0.0152], [122606000.0, 0.0], [122607000.0, 0.0204], [122608000.0, 0.0], [122609000.0, 0.0031]]},
{"timestamp": "1743938591315", "bids": [[122532000.0, 0.096], [122531000.0, 0.066], [122530000.0, 0.0152], [122527000.0, 0.0001], [122526000.0, 0.0121], [122525000.0, 0.0001], [122523000.0, 0.017], [122519000.0, 0.0234], [122518000.0, 0.0237], [122517000.0, 0.0244]], "asks": [[122591000.0, 0.0], [122595000.0, 0.1568], [122596000.0, 0.0698], [122601000.0, 0.0], [122604000.0, 0.0152], [122605000.0, 0.0152], [122606000.0, 0.0], [122607000.0, 0.0204], [122608000.0, 0.0], [122609000.0, 0.0031]]},
{"timestamp": "1743938591824", "bids": [[122532000.0, 0.096], [122531000.0, 0.066], [122530000.0, 0.0152], [122527000.0, 0.0001], [122526000.0, 0.0121], [122525000.0, 0.0001], [122523000.0, 0.017], [122519000.0, 0.0234], [122518000.0, 0.0237], [122517000.0, 0.0244]], "asks": [[122591000.0, 0.0], [122595000.0, 0.1568], [122596000.0, 0.0698], [122601000.0, 0.0], [122604000.0, 0.0152], [122605000.0, 0.0152], [122606000.0, 0.0], [122607000.0, 0.0204], [122608000.0, 0.0], [122609000.0, 0.0031]]},
{"timestamp": "1743938592327", "bids": [[122591000.0, 0.0], [122532000.0, 0.096], [122531000.0, 0.066], [122530000.0, 0.0152], [122527000.0, 0.0001], [122526000.0, 0.0121], [122525000.0, 0.0001], [122523000.0, 0.017], [122519000.0, 0.0234], [122518000.0, 0.0237]], "asks": [[122594000.0, 0.098], [122596000.0, 0.0698], [122601000.0, 0.0], [122604000.0, 0.0152], [122605000.0, 0.0152], [122606000.0, 0.0], [122607000.0, 0.0204], [122608000.0, 0.0], [122609000.0, 0.0031], [122610000.0, 0.0081]]},
{"timestamp": "1743938592892", "bids": [[122591000.0, 0.0], [122532000.0, 0.0959], [122531000.0, 0.066], [122530000.0, 0.0152], [122527000.0, 0.0001], [122526000.0, 0.0121], [122525000.0, 0.0001], [122523000.0, 0.017], [122519000.0, 0.0234], [122518000.0, 0.0237]], "asks": [[122594000.0, 0.1568], [122595000.0, 0.098], [122596000.0, 0.0698], [122601000.0, 0.0], [122604000.0, 0.0152], [122605000.0, 0.0152], [122606000.0, 0.0], [122607000.0, 0.0204], [122608000.0, 0.0], [122609000.0, 0.0031]]},
{"timestamp": "1743938593326", "bids": [[122591000.0, 0.0], [122531000.0, 0.066], [122530000.0, 0.0152], [122527000.0, 0.096], [122526000.0, 0.0121], [122525000.0, 0.0001], [122523000.0, 0.017], [122519000.0, 0.0234], [122518000.0, 0.0237], [122517000.0, 0.0244]], "asks": [[122593000.0, 0.098], [122594000.0, 0.1568], [122596000.0, 0.0698], [122601000.0, 0.0], [122604000.0, 0.0152], [122605000.0, 0.0152], [122606000.0, 0.0], [122607000.0, 0.0204], [122608000.0, 0.0], [122609000.0, 0.0031]]},
{"timestamp": "1743938593869", "bids": [[122591000.0, 0.0001], [122531000.0, 0.1619], [122530000.0, 0.0152], [122527000.0, 0.0001], [122526000.0, 0.0121], [122525000.0, 0.0001], [122523000.0, 0.017], [122519000.0, 0.0234], [122518000.0, 0.0237], [122517000.0, 0.0244]], "asks": [[122593000.0, 0.098], [122594000.0, 0.1568], [122596000.0, 0.0698], [122601000.0, 0.0], [122604000.0, 0.0152], [122605000.0, 0.0152], [122606000.0, 0.0], [122607000.0, 0.0204], [122608000.0, 0.0], [122609000.0, 0.0031]]},
{"timestamp": "1743938594444", "bids": [[122591000.0, 0.0001], [122532000.0, 0.0959], [122531000.0, 0.066], [122530000.0, 0.0152], [122527000.0, 0.0001], [122526000.0, 0.0121], [122525000.0, 0.0001], [122523000.0, 0.017], [122519000.0, 0.0234], [122518000.0, 0.0237]], "asks": [[122595000.0, 0.1568], [122596000.0, 0.0698], [122601000.0, 0.0], [122604000.0, 0.0152], [122605000.0, 0.0152], [122606000.0, 0.0], [122607000.0, 0.0204], [122608000.0, 0.0], [122609000.0, 0.0031], [122610000.0, 0.0081]]},
{"timestamp": "1743938594901", "bids": [[122591000.0, 0.0], [122532000.0, 0.0959], [122531000.0, 0.066], [122530000.0, 0.0152], [122527000.0, 0.0001], [122526000.0, 0.0121], [122525000.0, 0.0001], [122523000.0, 0.017], [122519000.0, 0.0234], [122518000.0, 0.0237]], "asks": [[122595000.0, 0.2548], [122596000.0, 0.0698], [122601000.0, 0.0], [122604000.0, 0.0152], [122605000.0, 0.0152], [122606000.0, 0.0], [122607000.0, 0.0204], [122608000.0, 0.0], [122609000.0, 0.0031], [122610000.0, 0.0081]]}
]