{"timestamp": "1743933191579", "bids": [[122960000.0, 0.1511], [122956000.0, 0.0], [122950000.0, 0.0057], [122949000.0, 0.0002], [122944000.0, 0.003], [122940000.0, 0.0], [122931000.0, 0.0], [122930000.0, 0.0], [122926000.0, 0.0024], [122918000.0, 0.0]], "asks": [[122968000.0, 0.0], [122970000.0, 0.0004], [122973000.0, 0.0152], [122978000.0, 0.0203], [122980000.0, 0.0004], [122996000.0, 0.1368], [122998000.0, 0.0855], [123000000.0, 0.1072], [123001000.0, 0.0001], [123003000.0, 0.0081]]},
{"timestamp": "1743933192037", "bids": [[122960000.0, 0.1511], [122956000.0, 0.0], [122950000.0, 0.0057], [122949000.0, 0.0002], [122944000.0, 0.003], [122940000.0, 0.0], [122931000.0, 0.0], [122930000.0, 0.0], [122926000.0, 0.0024], [122918000.0, 0.0]], "asks": [[122968000.0, 0.0], [122970000.0, 0.0004], [122973000.0, 0.0152], [122978000.0, 0.0203], [122980000.0, 0.0004], [122995000.0, 0.0855], [122997000.0, 0.1368], [123000000.0, 0.1072], [123001000.0, 0.0001], [123003000.0, 0.0081]]},
{"timestamp": "1743933192553", "bids": [[122960000.0, 0.1511], [122956000.0, 0.0], [122950000.0, 0.0057], [122949000.0, 0.0002], [122944000.0, 0.003], [122940000.0, 0.0], [122931000.0, 0.0], [122930000.0, 0.0], [122926000.0, 0.0024], [122918000.0, 0.0]], "asks": [[122968000.0, 0.0], [122970000.0, 0.0004], [122973000.0, 0.0152], [122978000.0, 0.0203], [122980000.0, 0.0004], [122993000.0, 0.0855], [122995000.0, 0.1368], [123000000.0, 0.1072], [123001000.0, 0.0001], [123003000.0, 0.0081]]},
{"timestamp": "1743933193047", "bids": [[122960000.0, 0.1511], [122956000.0, 0.0], [122950000.0, 0.0057], [122949000.0, 0.0002], [122944000.0, 0.003], [122940000.0, 0.0], [122931000.0, 0.0], [122930000.0, 0.0], [122926000.0, 0.0024], [122918000.0, 0.0]], "asks": [[122968000.0, 0.0], [122970000.0, 0.0004], [122973000.0, 0.0152], [122978000.0, 0.0203], [122980000.0, 0.0004], [123000000.0, 0.1072], [123001000.0, 0.0001], [123003000.0, 0.0081], [123004000.0, 0.0001], [123007000.0, 0.0001]]},
{"timestamp": "1743933193733", "bids": [[122960000.0, 0.1511], [122956000.0, 0.0], [122950000.0, 0.0057], [122949000.0, 0.0002], [122944000.0, 0.003], [122940000.0, 0.0], [122931000.0, 0.0], [122930000.0, 0.0], [122926000.0, 0.0024], [122918000.0, 0.0]], "asks": [[122968000.0, 0.0], [122970000.0, 0.0004], [122973000.0, 0.0152], [122978000.0, 0.0203], [122980000.0, 0.0004], [122997000.0, 0.1368], [123000000.0, 0.1072], [123001000.0, 0.0001], [123003000.0, 0.0081], [123004000.0, 0.0001]]},
{"timestamp": "1743933194106", "bids": [[122960000.0, 0.1511], [122956000.0, 0.0], [122950000.0, 0.0057], [122949000.0, 0.0002], [122944000.0, 0.003], [122940000.0, 0.0], [122931000.0, 0.0], [122930000.0, 0.0], [122926000.0, 0.0024], [122918000.0, 0.0]], "asks": [[122968000.0, 0.0], [122970000.0, 0.0004], [122973000.0, 0.0152], [122978000.0, 0.0203], [122980000.0, 0.0004], [122997000.0, 0.0855], [123000000.0, 0.1072], [123001000.0, 0.0001], [123003000.0, 0.0081], [123004000.0, 0.0001]]},
{"timestamp": "1743933194542", "bids": [[122960000.0, 0.1511], [122956000.0, 0.0], [122950000.0, 0.0057], [122949000.0, 0.0002], [122944000.0, 0.003], [122940000.0, 0.0], [122931000.0, 0.0], [122930000.0, 0.0], [122926000.0, 0.0024], [122918000.0, 0.0]], "asks": [[122968000.0, 0.0], [122970000.0, 0.0004], [122973000.0, 0.0152], [122978000.0, 0.0203], [122980000.0, 0.0004], [122996000.0, 0.1368], [122999000.0, 0.0878], [123000000.0, 0.1072], [123001000.0, 0.0001], [123003000.0, 0.0081]]},
{"timestamp": "1743933195138", "bids": [[122960000.0, 0.1511], [122956000.0, 0.0], [122950000.0, 0.0057], [122949000.0, 0.0002], [122944000.0, 0.003], [122940000.0, 0.0], [122931000.0, 0.0], [122930000.0, 0.0], [122926000.0, 0.0024], [122918000.0, 0.0]], "asks": [[122968000.0, 0.0], [122970000.0, 0.0004], [122973000.0, 0.0152], [122978000.0, 0.0203], [122980000.0, 0.0004], [122998000.0, 0.0855], [122999000.0, 0.1391], [123000000.0, 0.1049], [123001000.0, 0.0001], [123003000.0, 0.0081]]},
{"timestamp": "1743933195561", "bids": [[122960000.0, 0.1511], [122956000.0, 0.0], [122950000.0, 0.0057], [122949000.0, 0.0002], [122944000.0, 0.003], [122940000.0, 0.0], [122931000.0, 0.0], [122930000.0, 0.0], [122926000.0, 0.0024], [122918000.0, 0.0]], "asks": [[122968000.0, 0.0], [122970000.0, 0.0004], [122973000.0, 0.0152], [122978000.0, 0.0203], [122980000.0, 0.0004], [122994000.0, 0.1368], [122997000.0, 0.0855], [122999000.0, 0.0023], [123000000.0, 0.1049], [123001000.0, 0.0001]]},
{"timestamp": "1743933196076", "bids": [[122960000.0, 0.1511], [122956000.0, 0.0], [122950000.0, 0.0057], [122949000.0, 0.0002], [122944000.0, 0.003], [122940000.0, 0.0], [122931000.0, 0.0], [122930000.0, 0.0], [122926000.0, 0.0024], [122918000.0, 0.0]], "asks": [[122968000.0, 0.0], [122970000.0, 0.0004], [122973000.0, 0.0152], [122978000.0, 0.0203], [122980000.0, 0.0004], [122996000.0, 0.1368], [122999000.0, 0.0023], [123000000.0, 0.1049], [123001000.0, 0.0001], [123003000.0, 0.0081]]},
{"timestamp": "1743933196601", "bids": [[122960000.0, 0.1511], [122956000.0, 0.0], [122950000.0, 0.0057], [122949000.0, 0.0002], [122944000.0, 0.003], [122940000.0, 0.0], [122931000.0, 0.0], [122930000.0, 0.0], [122926000.0, 0.0024], [122918000.0, 0.0]], "asks": [[122968000.0, 0.0], [122970000.0, 0.0004], [122973000.0, 0.0152], [122978000.0, 0.0203], [122980000.0, 0.0004], [122995000.0, 0.0855], [122999000.0, 0.0023], [123000000.0, 0.1049], [123001000.0, 0.0001], [123003000.0, 0.0081]]},
{"timestamp": "1743933197124", "bids": [[122960000.0, 0.1511], [122956000.0, 0.0], [122950000.0, 0.0057], [122949000.0, 0.0002], [122944000.0, 0.003], [122940000.0, 0.0], [122931000.0, 0.0], [122930000.0, 0.0], [122926000.0, 0.0024], [122918000.0, 0.0]], "asks": [[122968000.0, 0.0], [122970000.0, 0.0004], [122973000.0, 0.0152], [122978000.0, 0.0203], [122980000.0, 0.0004], [122994000.0, 0.1368], [122999000.0, 0.0878], [123000000.0, 0.1049], [123001000.0, 0.0001], [123003000.0, 0.0081]]},
{"timestamp": "1743933197600", "bids": [[122960000.0, 0.1511], [122956000.0, 0.0], [122950000.0, 0.0057], [122949000.0, 0.0002], [122944000.0, 0.003], [122940000.0, 0.0], [122931000.0, 0.0], [122930000.0, 0.0], [122926000.0, 0.0024], [122918000.0, 0.0]], "asks": [[122968000.0, 0.0], [122970000.0, 0.0004], [122973000.0, 0.0152], [122978000.0, 0.0203], [122980000.0, 0.0004], [122993000.0, 0.0855], [122998000.0, 0.1368], [122999000.0, 0.0023], [123000000.0, 0.1049], [123001000.0, 0.0001]]},
{"timestamp": "1743933198150", "bids": [[122960000.0, 0.1511], [122956000.0, 0.0], [122950000.0, 0.0057], [122949000.0, 0.0002], [122944000.0, 0.003], [122940000.0, 0.0], [122931000.0, 0.0], [122930000.0, 0.0], [122926000.0, 0.0024], [122918000.0, 0.0]], "asks": [[122968000.0, 0.0], [122970000.0, 0.0004], [122973000.0, 0.0152], [122978000.0, 0.0203], [122980000.0, 0.0004], [122997000.0, 0.0855], [122999000.0, 0.0023], [123000000.0, 0.1049], [123001000.0, 0.0001], [123003000.0, 0.0081]]},
{"timestamp": "1743933198644", "bids": [[122960000.0, 0.1511], [122956000.0, 0.0], [122950000.0, 0.0057], [122949000.0, 0.0002], [122944000.0, 0.003], [122940000.0, 0.0], [122931000.0, 0.0], [122930000.0, 0.0], [122926000.0, 0.0024], [122918000.0, 0.0]], "asks": [[122968000.0, 0.0], [122970000.0, 0.0004], [122973000.0, 0.0152], [122978000.0, 0.0203], [122980000.0, 0.0004], [122995000.0, 0.0855], [122996000.0, 0.1368], [122999000.0, 0.0023], [123000000.0, 0.1049], [123001000.0, 0.0001]]},
{"timestamp": "1743933199158", "bids": [[122960000.0, 0.1511], [122956000.0, 0.0], [122950000.0, 0.0057], [122949000.0, 0.0002], [122944000.0, 0.003], [122940000.0, 0.0], [122931000.0, 0.0], [122930000.0, 0.0], [122926000.0, 0.0024], [122918000.0, 0.0]], "asks": [[122968000.0, 0.0], [122970000.0, 0.0004], [122973000.0, 0.0152], [122978000.0, 0.0203], [122980000.0, 0.0004], [122986000.0, 0.1368], [122995000.0, 0.0855], [122999000.0, 0.0023], [123000000.0, 0.1049], [123001000.0, 0.0001]]},
{"timestamp": "1743933199662", "bids": [[122960000.0, 0.1511], [122956000.0, 0.0], [122950000.0, 0.0057], [122949000.0, 0.0002], [122944000.0, 0.003], [122940000.0, 0.0], [122931000.0, 0.0], [122930000.0, 0.0], [122926000.0, 0.0024], [122918000.0, 0.0]], "asks": [[122968000.0, 0.0], [122970000.0, 0.0004], [122973000.0, 0.0152], [122978000.0, 0.0203], [122980000.0, 0.0004], [122985000.0, 0.0855], [122999000.0, 0.0023], [123000000.0, 0.1049], [123001000.0, 0.0001], [123003000.0, 0.0081]]},
{"timestamp": "1743933200149", "bids": [[122960000.0, 0.1511], [122956000.0, 0.0], [122950000.0, 0.0057], [122949000.0, 0.0002], [122944000.0, 0.003], [122940000.0, 0.0], [122931000.0, 0.0], [122930000.0, 0.0], [122926000.0, 0.0024], [122918000.0, 0.0]], "asks": [[122968000.0, 0.0], [122970000.0, 0.0004], [122973000.0, 0.0152], [122978000.0, 0.0203], [122980000.0, 0.0004], [122999000.0, 0.0878], [123000000.0, 0.1049], [123001000.0, 0.0001], [123003000.0, 0.0081], [123004000.0, 0.0001]]},
{"timestamp": "1743933200664", "bids": [[122960000.0, 0.1511], [122956000.0, 0.0], [122950000.0, 0.0057], [122949000.0, 0.0002], [122944000.0, 0.003], [122940000.0, 0.0], [122931000.0, 0.0], [122930000.0, 0.0], [122926000.0, 0.0024], [122918000.0, 0.0]], "asks": [[122968000.0, 0.0], [122970000.0, 0.0004], [122973000.0, 0.0152], [122978000.0, 0.0203], [122980000.0, 0.0004], [122991000.0, 0.0855], [122999000.0, 0.0023], [123000000.0, 0.1049], [123001000.0, 0.0001], [123003000.0, 0.0081]]},
{"timestamp": "1743933201200", "bids": [[122960000.0, 0.1511], [122956000.0, 0.0], [122950000.0, 0.0057], [122949000.0, 0.0002], [122944000.0, 0.003], [122940000.0, 0.0], [122931000.0, 0.0], [122930000.0, 0.0], [122926000.0, 0.0024], [122918000.0, 0.0]], "asks": [[122968000.0, 0.0], [122970000.0, 0.0004], [122973000.0, 0.0152], [122978000.0, 0.0203], [122980000.0, 0.0004], [122990000.0, 0.1368], [122999000.0, 0.0878], [123000000.0, 0.1049], [123001000.0, 0.0001], [123003000.0, 0.0081]]},
{"timestamp": "1743933201703", "bids": [[122960000.0, 0.1511], [122956000.0, 0.0], [122950000.0, 0.0057], [122949000.0, 0.0002], [122944000.0, 0.003], [122940000.0, 0.0], [122931000.0, 0.0], [122930000.0, 0.0], [122926000.0, 0.0024], [122918000.0, 0.0]], "asks": [[122968000.0, 0.0], [122970000.0, 0.0004], [122973000.0, 0.0152], [122978000.0, 0.0203], [122980000.0, 0.0004], [122988000.0, 0.1368], [122997000.0, 0.0855], [122999000.0, 0.0023], [123000000.0, 0.1049], [123001000.0, 0.0001]]},
{"timestamp": "1743933202200", "bids": [[122960000.0, 0.1511], [122956000.0, 0.0], [122950000.0, 0.0057], [122949000.0, 0.0002], [122944000.0, 0.003], [122940000.0, 0.0], [122931000.0, 0.0], [122930000.0, 0.0], [122926000.0, 0.0024], [122918000.0, 0.0]], "asks": [[122968000.0, 0.0], [122970000.0, 0.0004], [122973000.0, 0.0152], [122978000.0, 0.0203], [122980000.0, 0.0004], [122987000.0, 0.0855], [122996000.0, 0.1368], [122999000.0, 0.0023], [123000000.0, 0.1049], [123001000.0, 0.0001]]},
{"timestamp": "1743933202730", "bids": [[122960000.0, 0.1511], [122956000.0, 0.0], [122950000.0, 0.0057], [122949000.0, 0.0002], [122944000.0, 0.003], [122940000.0, 0.0], [122931000.0, 0.0], [122930000.0, 0.0], [122926000.0, 0.0024], [122918000.0, 0.0]], "asks": [[122968000.0, 0.0], [122970000.0, 0.0004], [122973000.0, 0.0152], [122978000.0, 0.0203], [122980000.0, 0.0004], [122986000.0, 0.1368], [122995000.0, 0.0855], [122999000.0, 0.0023], [123000000.0, 0.1049], [123001000.0, 0.0001]]},
{"timestamp": "1743933203243", "bids": [[122960000.0, 0.1511], [122956000.0, 0.0], [122950000.0, 0.0057], [122949000.0, 0.0002], [122944000.0, 0.003], [122940000.0, 0.0], [122931000.0, 0.0], [122930000.0, 0.0], [122926000.0, 0.0024], [122918000.0, 0.0]], "asks": [[122968000.0, 0.0], [122970000.0, 0.0004], [122973000.0, 0.0152], [122978000.0, 0.0203], [122980000.0, 0.0004], [122994000.0, 0.1368], [122999000.0, 0.0023], [123000000.0, 0.1049], [123001000.0, 0.0001], [123003000.0, 0.0081]]},
{"timestamp": "1743933203769", "bids": [[122960000.0, 0.1511], [122956000.0, 0.0], [122950000.0, 0.0057], [122949000.0, 0.0002], [122944000.0, 0.003], [122940000.0, 0.0], [122931000.0, 0.0], [122930000.0, 0.0], [122926000.0, 0.0024], [122918000.0, 0.0]], "asks": [[122973000.0, 0.01], [122978000.0, 0.0203], [122980000.0, 0.0004], [122992000.0, 0.1368], [122998000.0, 0.0855], [122999000.0, 0.0023], [123000000.0, 0.1049], [123001000.0, 0.0001], [123003000.0, 0.0081], [123004000.0, 0.0001]]},
{"timestamp": "1743933204247", "bids": [[122960000.0, 0.1511], [122956000.0, 0.0], [122950000.0, 0.0057], [122949000.0, 0.0002], [122944000.0, 0.003], [122940000.0, 0.0], [122931000.0, 0.0], [122930000.0, 0.0], [122926000.0, 0.0024], [122918000.0, 0.0]], "asks": [[122973000.0, 0.01], [122978000.0, 0.0203], [122980000.0, 0.0004], [122991000.0, 0.0852], [122997000.0, 0.1363], [122999000.0, 0.0023], [123000000.0, 0.1049], [123001000.0, 0.0001], [123003000.0, 0.0081], [123004000.0, 0.0001]]},
{"timestamp": "1743933204747", "bids": [[122960000.0, 0.1511], [122956000.0, 0.0], [122950000.0, 0.0057], [122949000.0, 0.0002], [122944000.0, 0.003], [122940000.0, 0.0], [122931000.0, 0.0], [122930000.0, 0.0], [122926000.0, 0.0024], [122918000.0, 0.0]], "asks": [[122973000.0, 0.01], [122978000.0, 0.0203], [122980000.0, 0.0004], [122990000.0, 0.1363], [122996000.0, 0.0852], [122999000.0, 0.0023], [123000000.0, 0.1049], [123001000.0, 0.0001], [123003000.0, 0.0081], [123004000.0, 0.0001]]},
{"timestamp": "1743933205267", "bids": [[122960000.0, 0.1511], [122956000.0, 0.0], [122950000.0, 0.0057], [122949000.0, 0.0002], [122944000.0, 0.003], [122940000.0, 0.0], [122931000.0, 0.0], [122930000.0, 0.0], [122926000.0, 0.0024], [122918000.0, 0.0]], "asks": [[122973000.0, 0.01], [122978000.0, 0.0203], [122980000.0, 0.0004], [122989000.0, 0.0852], [122995000.0, 0.1363], [122999000.0, 0.0023], [123000000.0, 0.1049], [123001000.0, 0.0001], [123003000.0, 0.0081], [123004000.0, 0.0001]]},
{"timestamp": "1743933205787", "bids": [[122960000.0, 0.1511], [122956000.0, 0.0], [122950000.0, 0.0057], [122949000.0, 0.0002], [122944000.0, 0.003], [122940000.0, 0.0], [122931000.0, 0.0], [122930000.0, 0.0], [122926000.0, 0.0024], [122918000.0, 0.0]], "asks": [[122973000.0, 0.01], [122978000.0, 0.0203], [122980000.0, 0.0004], [122988000.0, 0.1363], [122994000.0, 0.0852], [122999000.0, 0.0023], [123000000.0, 0.1049], [123001000.0, 0.0001], [123003000.0, 0.0081], [123004000.0, 0.0001]]},
{"timestamp": "1743933206322", "bids": [[122960000.0, 0.1511], [122956000.0, 0.0], [122950000.0, 0.0057], [122949000.0, 0.0002], [122944000.0, 0.003], [122940000.0, 0.0], [122931000.0, 0.0], [122930000.0, 0.0], [122926000.0, 0.0024], [122918000.0, 0.0]], "asks": [[122973000.0, 0.01], [122978000.0, 0.0203], [122980000.0, 0.0004], [122992000.0, 0.0852], [122999000.0, 0.1386], [123000000.0, 0.1049], [123001000.0, 0.0001], [123003000.0, 0.0081], [123004000.0, 0.0001], [123007000.0, 0.0001]]},
{"timestamp": "1743933206815", "bids": [[122960000.0, 0.1511], [122956000.0, 0.0], [122950000.0, 0.0057], [122949000.0, 0.0002], [122944000.0, 0.003], [122940000.0, 0.0], [122931000.0, 0.0], [122930000.0, 0.0], [122926000.0, 0.0024], [122918000.0, 0.0]], "asks": [[122973000.0, 0.01], [122978000.0, 0.0203], [122980000.0, 0.0004], [122991000.0, 0.1363], [122998000.0, 0.0852], [122999000.0, 0.0046], [123000000.0, 0.1049], [123001000.0, 0.0001], [123003000.0, 0.0081], [123004000.0, 0.0001]]},
{"timestamp": "1743933207311", "bids": [[122960000.0, 0.1511], [122956000.0, 0.0], [122950000.0, 0.0057], [122949000.0, 0.0002], [122944000.0, 0.003], [122940000.0, 0.0], [122931000.0, 0.0], [122930000.0, 0.0], [122926000.0, 0.0024], [122918000.0, 0.0]], "asks": [[122973000.0, 0.01], [122978000.0, 0.0203], [122980000.0, 0.0004], [122990000.0, 0.0852], [122999000.0, 0.0023], [123000000.0, 0.1049], [123001000.0, 0.0001], [123003000.0, 0.0081], [123004000.0, 0.0001], [123007000.0, 0.0001]]},
{"timestamp": "1743933207841", "bids": [[122960000.0, 0.1511], [122956000.0, 0.0], [122950000.0, 0.0057], [122949000.0, 0.0002], [122944000.0, 0.003], [122940000.0, 0.0], [122931000.0, 0.0], [122930000.0, 0.0], [122926000.0, 0.0024], [122918000.0, 0.0]], "asks": [[122973000.0, 0.01], [122978000.0, 0.0203], [122980000.0, 0.0004], [122995000.0, 0.1363], [122999000.0, 0.0875], [123000000.0, 0.1049], [123001000.0, 0.0001], [123003000.0, 0.0081], [123004000.0, 0.0001], [123007000.0, 0.0001]]},
{"timestamp": "1743933208348", "bids": [[122960000.0, 0.1511], [122956000.0, 0.0], [122950000.0, 0.0057], [122949000.0, 0.0002], [122944000.0, 0.003], [122940000.0, 0.0], [122931000.0, 0.0], [122930000.0, 0.0], [122926000.0, 0.0024], [122918000.0, 0.0]], "asks": [[122973000.0, 0.01], [122978000.0, 0.0203], [122980000.0, 0.0004], [122994000.0, 0.0852], [122998000.0, 0.1363], [122999000.0, 0.0023], [123000000.0, 0.1049], [123001000.0, 0.0001], [123003000.0, 0.0081], [123004000.0, 0.0001]]},
{"timestamp": "1743933208865", "bids": [[122960000.0, 0.1511], [122956000.0, 0.0], [122950000.0, 0.0057], [122949000.0, 0.0002], [122944000.0, 0.003], [122940000.0, 0.0], [122931000.0, 0.0], [122930000.0, 0.0], [122926000.0, 0.0024], [122918000.0, 0.0]], "asks": [[122973000.0, 0.01], [122978000.0, 0.0203], [122980000.0, 0.0004], [122993000.0, 0.1363], [122999000.0, 0.0023], [123000000.0, 0.1049], [123001000.0, 0.0001], [123003000.0, 0.0081], [123004000.0, 0.0001], [123007000.0, 0.0001]]},
{"timestamp": "1743933209375", "bids": [[122960000.0, 0.1511], [122956000.0, 0.0], [122950000.0, 0.0057], [122949000.0, 0.0002], [122944000.0, 0.003], [122940000.0, 0.0], [122931000.0, 0.0], [122930000.0, 0.0], [122926000.0, 0.0024], [122918000.0, 0.0]], "asks": [[122973000.0, 0.01], [122978000.0, 0.0203], [122980000.0, 0.0004], [122995000.0, 0.0852], [122999000.0, 0.1386], [123000000.0, 0.1049], [123001000.0, 0.0001], [123003000.0, 0.0081], [123004000.0, 0.0001], [123007000.0, 0.0001]]},
{"timestamp": "1743933209871", "bids": [[122960000.0, 0.1511], [122956000.0, 0.0], [122950000.0, 0.0057], [122949000.0, 0.0002], [122944000.0, 0.003], [122940000.0, 0.0], [122931000.0, 0.0], [122930000.0, 0.0], [122926000.0, 0.0024], [122918000.0, 0.0]], "asks": [[122973000.0, 0.01], [122978000.0, 0.0203], [122980000.0, 0.0004], [122994000.0, 0.1363], [122998000.0, 0.0852], [122999000.0, 0.0023], [123000000.0, 0.1049], [123001000.0, 0.0001], [123003000.0, 0.0081], [123004000.0, 0.0001]]},
{"timestamp": "1743933210375", "bids": [[122960000.0, 0.1511], [122956000.0, 0.0], [122950000.0, 0.0057], [122949000.0, 0.0002], [122944000.0, 0.003], [122940000.0, 0.0], [122931000.0, 0.0], [122930000.0, 0.0], [122926000.0, 0.0024], [122918000.0, 0.0]], "asks": [[122973000.0, 0.01], [122978000.0, 0.0203], [122980000.0, 0.0004], [122993000.0, 0.0852], [122997000.0, 0.1363], [122999000.0, 0.0023], [123000000.0, 0.1049], [123001000.0, 0.0001], [123003000.0, 0.0081], [123004000.0, 0.0001]]},
{"timestamp": "1743933210905", "bids": [[122960000.0, 0.1511], [122956000.0, 0.0], [122950000.0, 0.0057], [122949000.0, 0.0002], [122944000.0, 0.003], [122940000.0, 0.0], [122931000.0, 0.0], [122930000.0, 0.0], [122926000.0, 0.0024], [122918000.0, 0.0]], "asks": [[122973000.0, 0.01], [122978000.0, 0.0203], [122980000.0, 0.0004], [122992000.0, 0.1363], [122996000.0, 0.0852], [122999000.0, 0.0023], [123000000.0, 0.1049], [123001000.0, 0.0001], [123003000.0, 0.0081], [123004000.0, 0.0001]]},
{"timestamp": "1743933211400", "bids": [[122960000.0, 0.1511], [122956000.0, 0.0], [122950000.0, 0.0057], [122949000.0, 0.0002], [122944000.0, 0.003], [122940000.0, 0.0], [122931000.0, 0.0], [122930000.0, 0.0], [122926000.0, 0.0024], [122918000.0, 0.0]], "asks": [[122973000.0, 0.01], [122978000.0, 0.0203], [122980000.0, 0.0004], [122991000.0, 0.0852], [122995000.0, 0.1363], [122999000.0, 0.0023], [123000000.0, 0.1049], [123001000.0, 0.0001], [123003000.0, 0.0081], [123004000.0, 0.0001]]},
{"timestamp": "1743933211921", "bids": [[122960000.0, 0.1511], [122956000.0, 0.0], [122950000.0, 0.0057], [122949000.0, 0.0002], [122944000.0, 0.003], [122940000.0, 0.0], [122931000.0, 0.0], [122930000.0, 0.0], [122926000.0, 0.0024], [122918000.0, 0.0]], "asks": [[122973000.0, 0.01], [122978000.0, 0.0203], [122980000.0, 0.0004], [122990000.0, 0.1363], [122994000.0, 0.0852], [122999000.0, 0.0023], [123000000.0, 0.1049], [123001000.0, 0.0001], [123003000.0, 0.0081], [123004000.0, 0.0001]]},
{"timestamp": "1743933212464", "bids": [[122960000.0, 0.1511], [122956000.0, 0.0], [122950000.0, 0.0057], [122949000.0, 0.0002], [122944000.0, 0.003], [122940000.0, 0.0], [122931000.0, 0.0], [122930000.0, 0.0], [122926000.0, 0.0024], [122918000.0, 0.0]], "asks": [[122973000.0, 0.01], [122978000.0, 0.0203], [122980000.0, 0.0004], [122988000.0, 0.1363], [122992000.0, 0.0852], [122999000.0, 0.0023], [123000000.0, 0.1049], [123001000.0, 0.0001], [123003000.0, 0.0081], [123004000.0, 0.0001]]},
{"timestamp": "1743933212963", "bids": [[122960000.0, 0.1511], [122956000.0, 0.0], [122950000.0, 0.0057], [122949000.0, 0.0002], [122944000.0, 0.003], [122940000.0, 0.0], [122931000.0, 0.0], [122930000.0, 0.0], [122926000.0, 0.0024], [122918000.0, 0.0]], "asks": [[122973000.0, 0.01], [122978000.0, 0.0203], [122980000.0, 0.0004], [122991000.0, 0.1363], [122999000.0, 0.0023], [123000000.0, 0.1049], [123001000.0, 0.0001], [123003000.0, 0.0081], [123004000.0, 0.0001], [123007000.0, 0.0001]]},
{"timestamp": "1743933213483", "bids": [[122960000.0, 0.1511], [122956000.0, 0.0], [122950000.0, 0.0057], [122949000.0, 0.0002], [122944000.0, 0.003], [122940000.0, 0.0], [122931000.0, 0.0], [122930000.0, 0.0], [122926000.0, 0.0024], [122918000.0, 0.0]], "asks": [[122973000.0, 0.01], [122978000.0, 0.0203], [122980000.0, 0.0004], [122989000.0, 0.1363], [122998000.0, 0.0852], [123000000.0, 0.1072], [123001000.0, 0.0001], [123003000.0, 0.0081], [123004000.0, 0.0001], [123007000.0, 0.0001]]},
{"timestamp": "1743933213980", "bids": [[122960000.0, 0.1511], [122956000.0, 0.0], [122950000.0, 0.0057], [122949000.0, 0.0002], [122944000.0, 0.003], [122940000.0, 0.0], [122931000.0, 0.0], [122930000.0, 0.0], [122926000.0, 0.0024], [122918000.0, 0.0]], "asks": [[122973000.0, 0.01], [122978000.0, 0.0203], [122980000.0, 0.0004], [122988000.0, 0.0852], [122997000.0, 0.1363], [123000000.0, 0.1072], [123001000.0, 0.0001], [123003000.0, 0.0081], [123004000.0, 0.0001], [123007000.0, 0.0001]]},
{"timestamp": "1743933214498", "bids": [[122960000.0, 0.1511], [122956000.0, 0.0], [122950000.0, 0.0057], [122949000.0, 0.0002], [122944000.0, 0.003], [122940000.0, 0.0], [122931000.0, 0.0], [122930000.0, 0.0], [122926000.0, 0.0024], [122918000.0, 0.0]], "asks": [[122973000.0, 0.01], [122978000.0, 0.0203], [122980000.0, 0.0004], [122987000.0, 0.1363], [122996000.0, 0.0852], [123000000.0, 0.1072], [123001000.0, 0.0001], [123003000.0, 0.0081], [123004000.0, 0.0001], [123007000.0, 0.0001]]},
{"timestamp": "1743933214989", "bids": [[122960000.0, 0.1511], [122956000.0, 0.0], [122950000.0, 0.0057], [122949000.0, 0.0002], [122944000.0, 0.003], [122940000.0, 0.0], [122931000.0, 0.0], [122930000.0, 0.0], [122926000.0, 0.0024], [122918000.0, 0.0]], "asks": [[122973000.0, 0.01], [122978000.0, 0.0203], [122980000.0, 0.0004], [122995000.0, 0.1363], [123000000.0, 0.1072], [123001000.0, 0.0001], [123003000.0, 0.0081], [123004000.0, 0.0001], [123007000.0, 0.0001], [123008000.0, 0.0081]]},
{"timestamp": "1743933215524", "bids": [[122960000.0, 0.1511], [122956000.0, 0.0], [122950000.0, 0.0057], [122949000.0, 0.0002], [122944000.0, 0.003], [122940000.0, 0.0], [122931000.0, 0.0], [122930000.0, 0.0], [122926000.0, 0.0024], [122918000.0, 0.0]], "asks": [[122973000.0, 0.01], [122978000.0, 0.0203], [122980000.0, 0.0004], [122994000.0, 0.0852], [122999000.0, 0.1363], [123000000.0, 0.1072], [123001000.0, 0.0001], [123003000.0, 0.0081], [123004000.0, 0.0001], [123007000.0, 0.0001]]},
{"timestamp": "1743933216003", "bids": [[122960000.0, 0.1511], [122956000.0, 0.0], [122950000.0, 0.0057], [122949000.0, 0.0002], [122944000.0, 0.003], [122940000.0, 0.0], [122931000.0, 0.0], [122930000.0, 0.0], [122926000.0, 0.0024], [122918000.0, 0.0]], "asks": [[122973000.0, 0.01], [122978000.0, 0.0203], [122980000.0, 0.0004], [122993000.0, 0.1363], [122998000.0, 0.0852], [123000000.0, 0.1072], [123001000.0, 0.0001], [123003000.0, 0.0081], [123004000.0, 0.0001], [123007000.0, 0.0001]]},
{"timestamp": "1743933216532", "bids": [[122960000.0, 0.1511], [122956000.0, 0.0], [122950000.0, 0.0057], [122949000.0, 0.0002], [122944000.0, 0.003], [122940000.0, 0.0], [122931000.0, 0.0], [122930000.0, 0.0], [122926000.0, 0.0024], [122918000.0, 0.0]], "asks": [[122973000.0, 0.01], [122978000.0, 0.0203], [122980000.0, 0.0004], [122991000.0, 0.1363], [122995000.0, 0.0852], [122999000.0, 0.0023], [123000000.0, 0.1049], [123001000.0, 0.0001], [123003000.0, 0.0081], [123004000.0, 0.0001]]},
{"timestamp": "1743933217057", "bids": [[122960000.0, 0.1511], [122956000.0, 0.0], [122950000.0, 0.0057], [122949000.0, 0.0002], [122944000.0, 0.003], [122940000.0, 0.0], [122931000.0, 0.0], [122930000.0, 0.0], [122926000.0, 0.0024], [122918000.0, 0.0]], "asks": [[122973000.0, 0.01], [122978000.0, 0.0203], [122980000.0, 0.0004], [122994000.0, 0.1363], [122996000.0, 0.0852], [122999000.0, 0.0023], [123000000.0, 0.1049], [123001000.0, 0.0001], [123003000.0, 0.0081], [123004000.0, 0.0001]]},
{"timestamp": "1743933217567", "bids": [[122960000.0, 0.1511], [122956000.0, 0.0], [122950000.0, 0.0057], [122949000.0, 0.0002], [122944000.0, 0.003], [122940000.0, 0.0], [122931000.0, 0.0], [122930000.0, 0.0], [122926000.0, 0.0024], [122918000.0, 0.0]], "asks": [[122973000.0, 0.01], [122978000.0, 0.0203], [122980000.0, 0.0004], [122989000.0, 0.1363], [122993000.0, 0.0852], [122999000.0, 0.0023], [123000000.0, 0.1049], [123001000.0, 0.0001], [123003000.0, 0.0081], [123004000.0, 0.0001]]},
{"timestamp": "1743933218091", "bids": [[122960000.0, 0.1511], [122956000.0, 0.0], [122950000.0, 0.0057], [122949000.0, 0.0002], [122944000.0, 0.003], [122940000.0, 0.0], [122931000.0, 0.0], [122930000.0, 0.0], [122926000.0, 0.0024], [122918000.0, 0.0]], "asks": [[122973000.0, 0.01], [122978000.0, 0.0203], [122980000.0, 0.0004], [122988000.0, 0.0852], [122993000.0, 0.1363], [122999000.0, 0.0023], [123000000.0, 0.1049], [123001000.0, 0.0001], [123003000.0, 0.0081], [123004000.0, 0.0001]]},
{"timestamp": "1743933218598", "bids": [[122960000.0, 0.1511], [122956000.0, 0.0], [122950000.0, 0.0057], [122949000.0, 0.0002], [122944000.0, 0.003], [122940000.0, 0.0], [122931000.0, 0.0], [122930000.0, 0.0], [122926000.0, 0.0024], [122918000.0, 0.0]], "asks": [[122973000.0, 0.0087], [122978000.0, 0.0203], [122980000.0, 0.0004], [122992000.0, 0.0852], [122999000.0, 0.0023], [123000000.0, 0.1049], [123001000.0, 0.0001], [123003000.0, 0.0081], [123004000.0, 0.0001], [123007000.0, 0.0001]]},
{"timestamp": "1743933219089", "bids": [[122960000.0, 0.1511], [122956000.0, 0.0], [122950000.0, 0.0057], [122949000.0, 0.0002], [122944000.0, 0.003], [122940000.0, 0.0], [122931000.0, 0.0], [122930000.0, 0.0], [122926000.0, 0.0024], [122918000.0, 0.0]], "asks": [[122973000.0, 0.0087], [122978000.0, 0.0203], [122980000.0, 0.0004], [122991000.0, 0.1363], [122999000.0, 0.0875], [123000000.0, 0.1049], [123001000.0, 0.0001], [123003000.0, 0.0081], [123004000.0, 0.0001], [123007000.0, 0.0001]]},
{"timestamp": "1743933219628", "bids": [[122960000.0, 0.1511], [122956000.0, 0.0], [122950000.0, 0.0057], [122949000.0, 0.0002], [122944000.0, 0.003], [122940000.0, 0.0], [122931000.0, 0.0], [122930000.0, 0.0], [122926000.0, 0.0024], [122918000.0, 0.0]], "asks": [[122973000.0, 0.0087], [122978000.0, 0.0203], [122980000.0, 0.0004], [122990000.0, 0.0852], [122998000.0, 0.1363], [122999000.0, 0.0023], [123000000.0, 0.1049], [123001000.0, 0.0001], [123003000.0, 0.0081], [123004000.0, 0.0001]]},
{"timestamp": "1743933220113", "bids": [[122960000.0, 0.1511], [122956000.0, 0.0], [122950000.0, 0.0057], [122949000.0, 0.0002], [122944000.0, 0.003], [122940000.0, 0.0], [122931000.0, 0.0], [122930000.0, 0.0], [122926000.0, 0.0024], [122918000.0, 0.0]], "asks": [[122973000.0, 0.0087], [122978000.0, 0.0203], [122980000.0, 0.0004], [122987000.0, 0.0852], [122997000.0, 0.1363], [122999000.0, 0.0023], [123000000.0, 0.1049], [123001000.0, 0.0001], [123003000.0, 0.0081], [123004000.0, 0.0001]]},
{"timestamp": "1743933220640", "bids": [[122960000.0, 0.1511], [122956000.0, 0.0], [122950000.0, 0.0057], [122949000.0, 0.0002], [122944000.0, 0.003], [122940000.0, 0.0], [122931000.0, 0.0], [122930000.0, 0.0], [122926000.0, 0.0024], [122918000.0, 0.0]], "asks": [[122973000.0, 0.0087], [122978000.0, 0.0203], [122980000.0, 0.0004], [122986000.0, 0.1363], [122988000.0, 0.0852], [122999000.0, 0.0023], [123000000.0, 0.1049], [123001000.0, 0.0001], [123003000.0, 0.0081], [123004000.0, 0.0001]]},
{"timestamp": "1743933221163", "bids": [[122960000.0, 0.1511], [122956000.0, 0.0], [122950000.0, 0.0057], [122949000.0, 0.0002], [122944000.0, 0.003], [122940000.0, 0.0], [122931000.0, 0.0], [122930000.0, 0.0], [122926000.0, 0.0024], [122918000.0, 0.0]], "asks": [[122973000.0, 0.0087], [122978000.0, 0.0203], [122980000.0, 0.0004], [122998000.0, 0.0852], [122999000.0, 0.0023], [123000000.0, 0.1049], [123001000.0, 0.0001], [123003000.0, 0.0081], [123004000.0, 0.0001], [123007000.0, 0.0001]]},
{"timestamp": "1743933221665", "bids": [[122960000.0, 0.1511], [122956000.0, 0.0], [122950000.0, 0.0057], [122949000.0, 0.0002], [122944000.0, 0.003], [122940000.0, 0.0], [122931000.0, 0.0], [122930000.0, 0.0], [122926000.0, 0.0024], [122918000.0, 0.0]], "asks": [[122973000.0, 0.0087], [122978000.0, 0.0203], [122980000.0, 0.0004], [122997000.0, 0.1363], [122999000.0, 0.0875], [123000000.0, 0.1049], [123001000.0, 0.0001], [123003000.0, 0.0081], [123004000.0, 0.0001], [123007000.0, 0.0001]]},
{"timestamp": "1743933222175", "bids": [[122960000.0, 0.1511], [122956000.0, 0.0], [122950000.0, 0.0057], [122949000.0, 0.0002], [122944000.0, 0.003], [122940000.0, 0.0], [122931000.0, 0.0], [122930000.0, 0.0], [122926000.0, 0.0024], [122918000.0, 0.0]], "asks": [[122973000.0, 0.0087], [122978000.0, 0.0203], [122980000.0, 0.0004], [122996000.0, 0.0852], [122998000.0, 0.1363], [122999000.0, 0.0023], [123000000.0, 0.1049], [123001000.0, 0.0001], [123003000.0, 0.0081], [123004000.0, 0.0001]]},
{"timestamp": "1743933222667", "bids": [[122960000.0, 0.1511], [122956000.0, 0.0], [122950000.0, 0.0057], [122949000.0, 0.0002], [122944000.0, 0.003], [122940000.0, 0.0], [122931000.0, 0.0], [122930000.0, 0.0], [122926000.0, 0.0024], [122918000.0, 0.0]], "asks": [[122973000.0, 0.0087], [122978000.0, 0.0203], [122980000.0, 0.0004], [122995000.0, 0.1363], [122999000.0, 0.0023], [123000000.0, 0.1049], [123001000.0, 0.0001], [123003000.0, 0.0081], [123004000.0, 0.0001], [123007000.0, 0.0001]]},
{"timestamp": "1743933223198", "bids": [[122960000.0, 0.1511], [122956000.0, 0.0], [122950000.0, 0.0057], [122949000.0, 0.0002], [122944000.0, 0.003], [122940000.0, 0.0], [122931000.0, 0.0], [122930000.0, 0.0], [122926000.0, 0.0024], [122918000.0, 0.0]], "asks": [[122973000.0, 0.0087], [122978000.0, 0.0203], [122980000.0, 0.0004], [122994000.0, 0.0852], [122999000.0, 0.1386], [123000000.0, 0.1049], [123001000.0, 0.0001], [123003000.0, 0.0081], [123004000.0, 0.0001], [123007000.0, 0.0001]]},
{"timestamp": "1743933223696", "bids": [[122960000.0, 0.1511], [122956000.0, 0.0], [122950000.0, 0.0057], [122949000.0, 0.0002], [122944000.0, 0.003], [122940000.0, 0.0], [122931000.0, 0.0], [122930000.0, 0.0], [122926000.0, 0.0024], [122918000.0, 0.0]], "asks": [[122973000.0, 0.0087], [122978000.0, 0.0203], [122980000.0, 0.0004], [122993000.0, 0.1363], [122998000.0, 0.0852], [122999000.0, 0.0023], [123000000.0, 0.1049], [123001000.0, 0.0001], [123003000.0, 0.0081], [123004000.0, 0.0001]]},
{"timestamp": "1743933224199", "bids": [[122960000.0, 0.1511], [122956000.0, 0.0], [122950000.0, 0.0057], [122949000.0, 0.0002], [122944000.0, 0.003], [122940000.0, 0.0], [122931000.0, 0.0], [122930000.0, 0.0], [122926000.0, 0.0024], [122918000.0, 0.0]], "asks": [[122973000.0, 0.0085], [122978000.0, 0.0203], [122980000.0, 0.0004], [122992000.0, 0.0852], [122997000.0, 0.1363], [122999000.0, 0.0023], [123000000.0, 0.1049], [123001000.0, 0.0001], [123003000.0, 0.0081], [123004000.0, 0.0001]]},
{"timestamp": "1743933224729", "bids": [[122960000.0, 0.1511], [122956000.0, 0.0], [122950000.0, 0.0057], [122949000.0, 0.0002], [122944000.0, 0.003], [122940000.0, 0.0], [122931000.0, 0.0], [122930000.0, 0.0], [122926000.0, 0.0024], [122918000.0, 0.0]], "asks": [[122973000.0, 0.0085], [122978000.0, 0.0203], [122980000.0, 0.0004], [122993000.0, 0.1363], [122996000.0, 0.0852], [122999000.0, 0.0023], [123000000.0, 0.1049], [123001000.0, 0.0001], [123003000.0, 0.0081], [123004000.0, 0.0001]]},
{"timestamp": "1743933225245", "bids": [[122960000.0, 0.1511], [122956000.0, 0.0], [122950000.0, 0.0057], [122949000.0, 0.0002], [122944000.0, 0.003], [122940000.0, 0.0], [122931000.0, 0.0], [122930000.0, 0.0], [122926000.0, 0.0024], [122918000.0, 0.0]], "asks": [[122973000.0, 0.0085], [122978000.0, 0.0203], [122980000.0, 0.0004], [122989000.0, 0.1363], [122992000.0, 0.0852], [122999000.0, 0.0023], [123000000.0, 0.1049], [123001000.0, 0.0001], [123003000.0, 0.0081], [123004000.0, 0.0001]]},
{"timestamp": "1743933225729", "bids": [[122960000.0, 0.1511], [122956000.0, 0.0], [122950000.0, 0.0057], [122949000.0, 0.0002], [122944000.0, 0.003], [122940000.0, 0.0], [122931000.0, 0.0], [122930000.0, 0.0], [122926000.0, 0.0024], [122918000.0, 0.0]], "asks": [[122973000.0, 0.0085], [122978000.0, 0.0203], [122980000.0, 0.0004], [122988000.0, 0.0852], [122991000.0, 0.1363], [122999000.0, 0.0023], [123000000.0, 0.1049], [123001000.0, 0.0001], [123003000.0, 0.0081], [123004000.0, 0.0001]]},
{"timestamp": "1743933226255", "bids": [[122960000.0, 0.1511], [122956000.0, 0.0], [122950000.0, 0.0057], [122949000.0, 0.0002], [122944000.0, 0.003], [122940000.0, 0.0], [122931000.0, 0.0], [122930000.0, 0.0], [122926000.0, 0.0024], [122918000.0, 0.0]], "asks": [[122973000.0, 0.0085], [122978000.0, 0.0203], [122980000.0, 0.0004], [122999000.0, 0.0023], [123000000.0, 0.1049], [123001000.0, 0.0001], [123003000.0, 0.0081], [123004000.0, 0.0001], [123007000.0, 0.0001], [123008000.0, 0.0081]]},
{"timestamp": "1743933226746", "bids": [[122960000.0, 0.1511], [122956000.0, 0.0], [122950000.0, 0.0057], [122949000.0, 0.0002], [122944000.0, 0.003], [122940000.0, 0.0], [122931000.0, 0.0], [122930000.0, 0.0], [122926000.0, 0.0024], [122918000.0, 0.0]], "asks": [[122973000.0, 0.0085], [122978000.0, 0.0203], [122980000.0, 0.0004], [122999000.0, 0.2238], [123000000.0, 0.1049], [123001000.0, 0.0001], [123003000.0, 0.0081], [123004000.0, 0.0001], [123007000.0, 0.0001], [123008000.0, 0.0081]]},
{"timestamp": "1743933227285", "bids": [[122960000.0, 0.1511], [122956000.0, 0.0], [122950000.0, 0.0057], [122949000.0, 0.0002], [122944000.0, 0.003], [122940000.0, 0.0], [122931000.0, 0.0], [122930000.0, 0.0], [122926000.0, 0.0024], [122918000.0, 0.0]], "asks": [[122973000.0, 0.0085], [122978000.0, 0.0203], [122980000.0, 0.0004], [122987000.0, 0.1363], [122998000.0, 0.0852], [122999000.0, 0.0023], [123000000.0, 0.1049], [123001000.0, 0.0001], [123003000.0, 0.0081], [123004000.0, 0.0001]]},
{"timestamp": "1743933227801", "bids": [[122960000.0, 0.1511], [122956000.0, 0.0], [122950000.0, 0.0057], [122949000.0, 0.0002], [122944000.0, 0.003], [122940000.0, 0.0], [122931000.0, 0.0], [122930000.0, 0.0], [122926000.0, 0.0024], [122918000.0, 0.0]], "asks": [[122973000.0, 0.0085], [122978000.0, 0.0203], [122980000.0, 0.0004], [122997000.0, 0.1363], [122999000.0, 0.0875], [123000000.0, 0.1049], [123001000.0, 0.0001], [123003000.0, 0.0081], [123004000.0, 0.0001], [123007000.0, 0.0001]]},
{"timestamp": "1743933228327", "bids": [[122960000.0, 0.1511], [122956000.0, 0.0], [122950000.0, 0.0057], [122949000.0, 0.0002], [122944000.0, 0.003], [122940000.0, 0.0], [122931000.0, 0.0], [122930000.0, 0.0], [122926000.0, 0.0024], [122918000.0, 0.0]], "asks": [[122973000.0, 0.0085], [122978000.0, 0.0203], [122980000.0, 0.0004], [122995000.0, 0.0852], [122999000.0, 0.1386], [123000000.0, 0.1049], [123001000.0, 0.0001], [123003000.0, 0.0081], [123004000.0, 0.0001], [123007000.0, 0.0001]]},
{"timestamp": "1743933228802", "bids": [[122960000.0, 0.1511], [122956000.0, 0.0], [122950000.0, 0.0057], [122949000.0, 0.0002], [122944000.0, 0.003], [122940000.0, 0.0], [122931000.0, 0.0], [122930000.0, 0.0], [122926000.0, 0.0024], [122918000.0, 0.0]], "asks": [[122973000.0, 0.0085], [122978000.0, 0.0203], [122980000.0, 0.0004], [122994000.0, 0.1363], [122999000.0, 0.0023], [123000000.0, 0.1049], [123001000.0, 0.0001], [123003000.0, 0.0081], [123004000.0, 0.0001], [123007000.0, 0.0001]]},
{"timestamp": "1743933229335", "bids": [[122960000.0, 0.1511], [122956000.0, 0.0], [122950000.0, 0.0057], [122949000.0, 0.0002], [122944000.0, 0.003], [122940000.0, 0.0], [122931000.0, 0.0], [122930000.0, 0.0], [122926000.0, 0.0024], [122918000.0, 0.0]], "asks": [[122973000.0, 0.0085], [122978000.0, 0.0203], [122980000.0, 0.0004], [122993000.0, 0.0852], [122999000.0, 0.1386], [123000000.0, 0.1049], [123001000.0, 0.0001], [123003000.0, 0.0081], [123004000.0, 0.0001], [123007000.0, 0.0001]]},
{"timestamp": "1743933229856", "bids": [[122960000.0, 0.1511], [122956000.0, 0.0], [122950000.0, 0.0057], [122949000.0, 0.0002], [122944000.0, 0.003], [122940000.0, 0.0], [122931000.0, 0.0], [122930000.0, 0.0], [122926000.0, 0.0024], [122918000.0, 0.0]], "asks": [[122973000.0, 0.0085], [122978000.0, 0.0203], [122980000.0, 0.0004], [122992000.0, 0.1363], [122998000.0, 0.0852], [122999000.0, 0.0023], [123000000.0, 0.1049], [123001000.0, 0.0001], [123003000.0, 0.0081], [123004000.0, 0.0001]]},
{"timestamp": "1743933230354", "bids": [[122960000.0, 0.1511], [122956000.0, 0.0], [122950000.0, 0.0057], [122949000.0, 0.0002], [122944000.0, 0.003], [122940000.0, 0.0], [122931000.0, 0.0], [122930000.0, 0.0], [122926000.0, 0.0024], [122918000.0, 0.0]], "asks": [[122973000.0, 0.008], [122978000.0, 0.0203], [122980000.0, 0.0004], [122991000.0, 0.0852], [122997000.0, 0.1363], [122999000.0, 0.0023], [123000000.0, 0.1049], [123001000.0, 0.0001], [123003000.0, 0.0081], [123004000.0, 0.0001]]},
{"timestamp": "1743933230873", "bids": [[122968000.0, 0.0001], [122960000.0, 0.1511], [122956000.0, 0.0], [122950000.0, 0.0057], [122949000.0, 0.0002], [122944000.0, 0.003], [122940000.0, 0.0], [122931000.0, 0.0], [122930000.0, 0.0], [122926000.0, 0.0024]], "asks": [[122973000.0, 0.008], [122978000.0, 0.0203], [122980000.0, 0.0004], [122999000.0, 0.2238], [123000000.0, 0.1049], [123001000.0, 0.0001], [123003000.0, 0.0081], [123004000.0, 0.0001], [123007000.0, 0.0001], [123008000.0, 0.0081]]},
{"timestamp": "1743933231387", "bids": [[122968000.0, 0.0001], [122960000.0, 0.1511], [122956000.0, 0.0], [122950000.0, 0.0057], [122949000.0, 0.0002], [122944000.0, 0.003], [122940000.0, 0.0], [122931000.0, 0.0], [122930000.0, 0.0], [122926000.0, 0.0024]], "asks": [[122973000.0, 0.008], [122978000.0, 0.0203], [122980000.0, 0.0004], [122998000.0, 0.2215], [122999000.0, 0.0023], [123000000.0, 0.1049], [123001000.0, 0.0001], [123003000.0, 0.0081], [123004000.0, 0.0001], [123007000.0, 0.0001]]},
{"timestamp": "1743933231905", "bids": [[122968000.0, 0.0001], [122960000.0, 0.1511], [122956000.0, 0.0], [122950000.0, 0.0057], [122949000.0, 0.0002], [122944000.0, 0.003], [122940000.0, 0.0], [122931000.0, 0.0], [122930000.0, 0.0], [122926000.0, 0.0024]], "asks": [[122973000.0, 0.008], [122978000.0, 0.0203], [122980000.0, 0.0004], [122997000.0, 0.2215], [122999000.0, 0.0023], [123000000.0, 0.1049], [123001000.0, 0.0001], [123003000.0, 0.0081], [123004000.0, 0.0001], [123007000.0, 0.0001]]},
{"timestamp": "1743933232398", "bids": [[122968000.0, 0.0001], [122960000.0, 0.1511], [122956000.0, 0.0], [122950000.0, 0.0057], [122949000.0, 0.0002], [122944000.0, 0.003], [122940000.0, 0.0], [122931000.0, 0.0], [122930000.0, 0.0], [122926000.0, 0.0024]], "asks": [[122973000.0, 0.008], [122978000.0, 0.0203], [122980000.0, 0.0004], [122996000.0, 0.2215], [122999000.0, 0.0023], [123000000.0, 0.1049], [123001000.0, 0.0001], [123003000.0, 0.0081], [123004000.0, 0.0001], [123007000.0, 0.0001]]},
{"timestamp": "1743933232939", "bids": [[122968000.0, 0.0001], [122960000.0, 0.1511], [122956000.0, 0.0], [122950000.0, 0.0057], [122949000.0, 0.0002], [122944000.0, 0.003], [122940000.0, 0.0], [122931000.0, 0.0], [122930000.0, 0.0], [122926000.0, 0.0024]], "asks": [[122973000.0, 0.008], [122978000.0, 0.0203], [122980000.0, 0.0004], [122995000.0, 0.2215], [122999000.0, 0.0023], [123000000.0, 0.1049], [123001000.0, 0.0001], [123003000.0, 0.0081], [123004000.0, 0.0001], [123007000.0, 0.0001]]},
{"timestamp": "1743933233418", "bids": [[122968000.0, 0.0001], [122960000.0, 0.1511], [122956000.0, 0.0], [122950000.0, 0.0057], [122949000.0, 0.0002], [122944000.0, 0.003], [122940000.0, 0.0], [122931000.0, 0.0], [122930000.0, 0.0], [122926000.0, 0.0024]], "asks": [[122973000.0, 0.008], [122978000.0, 0.0203], [122980000.0, 0.0004], [122994000.0, 0.2215], [122999000.0, 0.0023], [123000000.0, 0.1049], [123001000.0, 0.0001], [123003000.0, 0.0081], [123004000.0, 0.0001], [123007000.0, 0.0001]]},
{"timestamp": "1743933233950", "bids": [[122968000.0, 0.0001], [122960000.0, 0.1511], [122956000.0, 0.0], [122950000.0, 0.0057], [122949000.0, 0.0002], [122944000.0, 0.003], [122940000.0, 0.0], [122931000.0, 0.0], [122930000.0, 0.0], [122926000.0, 0.0024]], "asks": [[122973000.0, 0.008], [122978000.0, 0.0203], [122980000.0, 0.0004], [122999000.0, 0.0023], [123000000.0, 0.1049], [123001000.0, 0.0001], [123003000.0, 0.0081], [123004000.0, 0.0001], [123007000.0, 0.0001], [123008000.0, 0.0081]]},
{"timestamp": "1743933234433", "bids": [[122968000.0, 0.0001], [122960000.0, 0.1511], [122956000.0, 0.0], [122950000.0, 0.0057], [122949000.0, 0.0002], [122944000.0, 0.003], [122940000.0, 0.0], [122931000.0, 0.0], [122930000.0, 0.0], [122926000.0, 0.0024]], "asks": [[122973000.0, 0.008], [122978000.0, 0.0203], [122980000.0, 0.0004], [122999000.0, 0.0875], [123000000.0, 0.1049], [123001000.0, 0.0001], [123003000.0, 0.0081], [123004000.0, 0.0001], [123007000.0, 0.0001], [123008000.0, 0.0081]]},
{"timestamp": "1743933234964", "bids": [[122968000.0, 0.0001], [122960000.0, 0.1511], [122956000.0, 0.0], [122950000.0, 0.0057], [122949000.0, 0.0002], [122944000.0, 0.003], [122940000.0, 0.0], [122931000.0, 0.0], [122930000.0, 0.0], [122926000.0, 0.0024]], "asks": [[122973000.0, 0.008], [122978000.0, 0.0203], [122980000.0, 0.0004], [122997000.0, 0.0852], [123000000.0, 0.1049], [123001000.0, 0.0001], [123002000.0, 0.0023], [123003000.0, 0.0081], [123004000.0, 0.0001], [123007000.0, 0.0001]]},
{"timestamp": "1743933235471", "bids": [[122968000.0, 0.0001], [122960000.0, 0.1511], [122956000.0, 0.0], [122950000.0, 0.0057], [122949000.0, 0.0002], [122944000.0, 0.003], [122940000.0, 0.0], [122931000.0, 0.0], [122930000.0, 0.0], [122926000.0, 0.0024]], "asks": [[122973000.0, 0.008], [122978000.0, 0.0203], [122980000.0, 0.0004], [122996000.0, 0.1363], [122999000.0, 0.0852], [123000000.0, 0.1049], [123001000.0, 0.0001], [123002000.0, 0.0023], [123003000.0, 0.0081], [123004000.0, 0.0001]]},
{"timestamp": "1743933235984", "bids": [[122968000.0, 0.0001], [122960000.0, 0.1511], [122956000.0, 0.0], [122950000.0, 0.0057], [122949000.0, 0.0002], [122944000.0, 0.003], [122940000.0, 0.0], [122931000.0, 0.0], [122930000.0, 0.0], [122926000.0, 0.0024]], "asks": [[122973000.0, 0.008], [122978000.0, 0.0203], [122980000.0, 0.0004], [122998000.0, 0.1363], [123000000.0, 0.1049], [123001000.0, 0.0001], [123002000.0, 0.0023], [123003000.0, 0.0081], [123004000.0, 0.0001], [123007000.0, 0.0001]]},
{"timestamp": "1743933236472", "bids": [[122968000.0, 0.0001], [122960000.0, 0.1511], [122956000.0, 0.0], [122950000.0, 0.0057], [122949000.0, 0.0002], [122944000.0, 0.003], [122940000.0, 0.0], [122931000.0, 0.0], [122930000.0, 0.0], [122926000.0, 0.0024]], "asks": [[122973000.0, 0.0073], [122978000.0, 0.0203], [122980000.0, 0.0004], [122997000.0, 0.0852], [123000000.0, 0.1049], [123001000.0, 0.0001], [123002000.0, 0.0023], [123003000.0, 0.0081], [123004000.0, 0.0001], [123007000.0, 0.0001]]},
{"timestamp": "1743933237018", "bids": [[122968000.0, 0.0001], [122960000.0, 0.1511], [122956000.0, 0.0], [122950000.0, 0.0057], [122949000.0, 0.0002], [122944000.0, 0.003], [122940000.0, 0.0], [122931000.0, 0.0], [122930000.0, 0.0], [122926000.0, 0.0024]], "asks": [[122973000.0, 0.0073], [122978000.0, 0.0203], [122980000.0, 0.0004], [122999000.0, 0.1363], [123000000.0, 0.1049], [123001000.0, 0.0001], [123002000.0, 0.0023], [123003000.0, 0.0081], [123004000.0, 0.0001], [123007000.0, 0.0082]]},
{"timestamp": "1743933237565", "bids": [[122968000.0, 0.0001], [122960000.0, 0.1511], [122956000.0, 0.0], [122950000.0, 0.0057], [122949000.0, 0.0002], [122944000.0, 0.003], [122940000.0, 0.0], [122931000.0, 0.0], [122930000.0, 0.0], [122926000.0, 0.0024]], "asks": [[122973000.0, 0.0073], [122978000.0, 0.0203], [122980000.0, 0.0004], [122998000.0, 0.0852], [123000000.0, 0.1049], [123001000.0, 0.0001], [123002000.0, 0.0023], [123003000.0, 0.0081], [123004000.0, 0.0001], [123007000.0, 0.0082]]},
{"timestamp": "1743933238064", "bids": [[122968000.0, 0.0001], [122960000.0, 0.1511], [122956000.0, 0.0], [122950000.0, 0.0057], [122949000.0, 0.0002], [122944000.0, 0.003], [122940000.0, 0.0], [122931000.0, 0.0], [122930000.0, 0.0], [122926000.0, 0.0024]], "asks": [[122973000.0, 0.0073], [122978000.0, 0.0203], [122980000.0, 0.0004], [122997000.0, 0.1363], [122999000.0, 0.0852], [123000000.0, 0.1049], [123001000.0, 0.0001], [123002000.0, 0.0023], [123003000.0, 0.0081], [123004000.0, 0.0001]]},
{"timestamp": "1743933238568", "bids": [[122968000.0, 0.0001], [122960000.0, 0.1511], [122956000.0, 0.0], [122950000.0, 0.0057], [122949000.0, 0.0002], [122944000.0, 0.003], [122940000.0, 0.0], [122931000.0, 0.0], [122930000.0, 0.0], [122926000.0, 0.0024]], "asks": [[122973000.0, 0.0073], [122978000.0, 0.0203], [122980000.0, 0.0004], [122996000.0, 0.0852], [123000000.0, 0.1049], [123001000.0, 0.0001], [123002000.0, 0.0023], [123003000.0, 0.0081], [123004000.0, 0.0001], [123007000.0, 0.0082]]},
{"timestamp": "1743933239092", "bids": [[122968000.0, 0.0001], [122960000.0, 0.1511], [122956000.0, 0.0], [122950000.0, 0.0057], [122949000.0, 0.0002], [122944000.0, 0.003], [122940000.0, 0.0], [122931000.0, 0.0], [122930000.0, 0.0], [122926000.0, 0.0024]], "asks": [[122973000.0, 0.0073], [122978000.0, 0.0203], [122980000.0, 0.0004], [122996000.0, 0.1363], [122999000.0, 0.0852], [123000000.0, 0.1049], [123001000.0, 0.0001], [123002000.0, 0.0023], [123003000.0, 0.0081], [123004000.0, 0.0001]]},
{"timestamp": "1743933239615", "bids": [[122968000.0, 0.0001], [122960000.0, 0.1511], [122956000.0, 0.0], [122950000.0, 0.0057], [122949000.0, 0.0002], [122944000.0, 0.003], [122940000.0, 0.0], [122931000.0, 0.0], [122930000.0, 0.0], [122926000.0, 0.0024]], "asks": [[122973000.0, 0.0073], [122978000.0, 0.0203], [122980000.0, 0.0004], [122995000.0, 0.0852], [123000000.0, 0.1049], [123001000.0, 0.0001], [123002000.0, 0.0023], [123003000.0, 0.0081], [123004000.0, 0.0001], [123007000.0, 0.0082]]},
{"timestamp": "1743933240066", "bids": [[122968000.0, 0.0001], [122960000.0, 0.1511], [122956000.0, 0.0], [122950000.0, 0.0057], [122949000.0, 0.0002], [122944000.0, 0.003], [122940000.0, 0.0], [122931000.0, 0.0], [122930000.0, 0.0], [122926000.0, 0.0024]], "asks": [[122973000.0, 0.0073], [122978000.0, 0.0203], [122980000.0, 0.0004], [122999000.0, 0.0852], [123000000.0, 0.1049], [123001000.0, 0.0001], [123002000.0, 0.0023], [123003000.0, 0.0081], [123004000.0, 0.0001], [123007000.0, 0.0082]]},
{"timestamp": "1743933240614", "bids": [[122968000.0, 0.0001], [122960000.0, 0.1511], [122956000.0, 0.0], [122950000.0, 0.0057], [122949000.0, 0.0002], [122944000.0, 0.003], [122940000.0, 0.0], [122931000.0, 0.0], [122930000.0, 0.0], [122926000.0, 0.0024]], "asks": [[122973000.0, 0.0073], [122978000.0, 0.0203], [122980000.0, 0.0004], [122998000.0, 0.1363], [122999000.0, 0.0852], [123000000.0, 0.1049], [123001000.0, 0.0001], [123002000.0, 0.0023], [123003000.0, 0.0081], [123004000.0, 0.0001]]},
{"timestamp": "1743933241152", "bids": [[122968000.0, 0.0001], [122960000.0, 0.1511], [122956000.0, 0.0], [122950000.0, 0.0057], [122949000.0, 0.0002], [122944000.0, 0.003], [122940000.0, 0.0], [122931000.0, 0.0], [122930000.0, 0.0], [122926000.0, 0.0024]], "asks": [[122973000.0, 0.0073], [122978000.0, 0.0203], [122980000.0, 0.0004], [122996000.0, 0.1363], [122997000.0, 0.0852], [123000000.0, 0.1049], [123001000.0, 0.0001], [123002000.0, 0.0023], [123003000.0, 0.0081], [123004000.0, 0.0001]]},
{"timestamp": "1743933241673", "bids": [[122968000.0, 0.0001], [122960000.0, 0.1511], [122956000.0, 0.0], [122950000.0, 0.0057], [122949000.0, 0.0002], [122944000.0, 0.003], [122940000.0, 0.0], [122931000.0, 0.0], [122930000.0, 0.0], [122926000.0, 0.0024]], "asks": [[122973000.0, 0.0073], [122978000.0, 0.0203], [122980000.0, 0.0004], [122995000.0, 0.0852], [122996000.0, 0.1363], [123000000.0, 0.1049], [123001000.0, 0.0001], [123002000.0, 0.0023], [123003000.0, 0.0081], [123004000.0, 0.0001]]},
{"timestamp": "1743933242121", "bids": [[122968000.0, 0.0001], [122960000.0, 0.1511], [122956000.0, 0.0], [122950000.0, 0.0057], [122949000.0, 0.0002], [122944000.0, 0.003], [122940000.0, 0.0], [122931000.0, 0.0], [122930000.0, 0.0], [122926000.0, 0.0024]], "asks": [[122973000.0, 0.0073], [122978000.0, 0.0203], [122980000.0, 0.0004], [122994000.0, 0.1363], [122995000.0, 0.0852], [123000000.0, 0.1049], [123001000.0, 0.0001], [123002000.0, 0.0023], [123003000.0, 0.0081], [123004000.0, 0.0001]]},
{"timestamp": "1743933242624", "bids": [[122968000.0, 0.0001], [122960000.0, 0.1511], [122956000.0, 0.0], [122950000.0, 0.0057], [122949000.0, 0.0002], [122944000.0, 0.003], [122940000.0, 0.0], [122931000.0, 0.0], [122930000.0, 0.0], [122926000.0, 0.0024]], "asks": [[122973000.0, 0.0073], [122978000.0, 0.0203], [122980000.0, 0.0004], [122993000.0, 0.0852], [122994000.0, 0.1363], [123000000.0, 0.1049], [123001000.0, 0.0001], [123002000.0, 0.0023], [123003000.0, 0.0081], [123004000.0, 0.0001]]},
{"timestamp": "1743933243151", "bids": [[122968000.0, 0.0001], [122960000.0, 0.1511], [122956000.0, 0.0], [122950000.0, 0.0057], [122949000.0, 0.0002], [122944000.0, 0.003], [122940000.0, 0.0], [122931000.0, 0.0], [122930000.0, 0.0], [122926000.0, 0.0024]], "asks": [[122973000.0, 0.0073], [122978000.0, 0.0203], [122980000.0, 0.0004], [122992000.0, 0.1363], [122993000.0, 0.0852], [123000000.0, 0.1049], [123001000.0, 0.0001], [123002000.0, 0.0023], [123003000.0, 0.0081], [123004000.0, 0.0001]]},
{"timestamp": "1743933243655", "bids": [[122968000.0, 0.0001], [122960000.0, 0.1511], [122956000.0, 0.0], [122950000.0, 0.0057], [122949000.0, 0.0002], [122944000.0, 0.003], [122940000.0, 0.0], [122931000.0, 0.0], [122930000.0, 0.0], [122926000.0, 0.0024]], "asks": [[122973000.0, 0.0073], [122978000.0, 0.0203], [122980000.0, 0.0004], [122992000.0, 0.1363], [123000000.0, 0.1049], [123001000.0, 0.0001], [123002000.0, 0.0023], [123003000.0, 0.0081], [123004000.0, 0.0001], [123007000.0, 0.0082]]},
{"timestamp": "1743933244150", "bids": [[122968000.0, 0.0001], [122960000.0, 0.1511], [122956000.0, 0.0], [122950000.0, 0.0057], [122949000.0, 0.0002], [122944000.0, 0.003], [122940000.0, 0.0], [122931000.0, 0.0], [122930000.0, 0.0], [122926000.0, 0.0024]], "asks": [[122973000.0, 0.0073], [122978000.0, 0.0203], [122980000.0, 0.0004], [122999000.0, 0.1363], [123000000.0, 0.1049], [123001000.0, 0.0001], [123002000.0, 0.0023], [123003000.0, 0.0081], [123004000.0, 0.0001], [123007000.0, 0.0082]]},
{"timestamp": "1743933244656", "bids": [[122968000.0, 0.0001], [122960000.0, 0.1511], [122956000.0, 0.0], [122950000.0, 0.0057], [122949000.0, 0.0002], [122944000.0, 0.003], [122940000.0, 0.0], [122931000.0, 0.0], [122930000.0, 0.0], [122926000.0, 0.0024]], "asks": [[122973000.0, 0.0073], [122978000.0, 0.0203], [122980000.0, 0.0004], [122998000.0, 0.0852], [122999000.0, 0.1363], [123000000.0, 0.1049], [123001000.0, 0.0001], [123002000.0, 0.0023], [123003000.0, 0.0081], [123004000.0, 0.0001]]},
{"timestamp": "1743933245169", "bids": [[122968000.0, 0.0001], [122960000.0, 0.1511], [122956000.0, 0.0], [122950000.0, 0.0057], [122949000.0, 0.0002], [122944000.0, 0.003], [122940000.0, 0.0], [122931000.0, 0.0], [122930000.0, 0.0], [122926000.0, 0.0024]], "asks": [[122973000.0, 0.0073], [122980000.0, 0.0004], [122996000.0, 0.0852], [122997000.0, 0.1363], [123000000.0, 0.1049], [123001000.0, 0.0001], [123002000.0, 0.0023], [123003000.0, 0.0081], [123004000.0, 0.0001], [123007000.0, 0.0082]]},
{"timestamp": "1743933245701", "bids": [[122968000.0, 0.0001], [122960000.0, 0.1511], [122956000.0, 0.0], [122950000.0, 0.0057], [122949000.0, 0.0002], [122944000.0, 0.003], [122940000.0, 0.0], [122931000.0, 0.0], [122930000.0, 0.0], [122926000.0, 0.0024]], "asks": [[122973000.0, 0.0073], [122980000.0, 0.0004], [122992000.0, 0.0203], [122995000.0, 0.1363], [122999000.0, 0.0852], [123000000.0, 0.1049], [123001000.0, 0.0001], [123002000.0, 0.0023], [123003000.0, 0.0081], [123004000.0, 0.0001]]},
{"timestamp": "1743933246191", "bids": [[122968000.0, 0.0001], [122960000.0, 0.1511], [122956000.0, 0.0], [122950000.0, 0.0057], [122949000.0, 0.0002], [122944000.0, 0.003], [122940000.0, 0.0], [122931000.0, 0.0], [122930000.0, 0.0], [122926000.0, 0.0024]], "asks": [[122973000.0, 0.0073], [122980000.0, 0.0004], [122991000.0, 0.1363], [122992000.0, 0.0203], [123000000.0, 0.1049], [123001000.0, 0.0001], [123002000.0, 0.0023], [123003000.0, 0.0081], [123004000.0, 0.0001], [123007000.0, 0.0082]]},
{"timestamp": "1743933246731", "bids": [[122968000.0, 0.0001], [122960000.0, 0.1511], [122956000.0, 0.0], [122950000.0, 0.0057], [122949000.0, 0.0002], [122944000.0, 0.003], [122940000.0, 0.0], [122931000.0, 0.0], [122930000.0, 0.0], [122926000.0, 0.0024]], "asks": [[122973000.0, 0.0073], [122980000.0, 0.0004], [122991000.0, 0.1363], [122992000.0, 0.0203], [123000000.0, 0.1049], [123001000.0, 0.0001], [123002000.0, 0.0023], [123003000.0, 0.0081], [123004000.0, 0.0001], [123007000.0, 0.0082]]},
{"timestamp": "1743933247233", "bids": [[122968000.0, 0.0001], [122960000.0, 0.1511], [122956000.0, 0.0], [122950000.0, 0.0057], [122949000.0, 0.0002], [122944000.0, 0.003], [122940000.0, 0.0], [122931000.0, 0.0], [122930000.0, 0.0], [122926000.0, 0.0024]], "asks": [[122973000.0, 0.0073], [122980000.0, 0.0004], [122991000.0, 0.1363], [122992000.0, 0.0203], [123000000.0, 0.1049], [123001000.0, 0.0001], [123002000.0, 0.0023], [123003000.0, 0.0081], [123004000.0, 0.0001], [123007000.0, 0.0082]]},
{"timestamp": "1743933247733", "bids": [[122968000.0, 0.0001], [122960000.0, 0.1511], [122956000.0, 0.0], [122950000.0, 0.0057], [122949000.0, 0.0002], [122944000.0, 0.003], [122940000.0, 0.0], [122931000.0, 0.0], [122930000.0, 0.0], [122926000.0, 0.0024]], "asks": [[122973000.0, 0.0073], [122980000.0, 0.0004], [122991000.0, 0.1363], [122992000.0, 0.0203], [123000000.0, 0.1049], [123001000.0, 0.0001], [123002000.0, 0.0023], [123003000.0, 0.0081], [123004000.0, 0.0001], [123007000.0, 0.0082]]},
{"timestamp": "1743933248240", "bids": [[122968000.0, 0.0001], [122960000.0, 0.1511], [122956000.0, 0.0], [122950000.0, 0.0057], [122949000.0, 0.0002], [122944000.0, 0.003], [122940000.0, 0.0], [122931000.0, 0.0], [122930000.0, 0.0], [122926000.0, 0.0024]], "asks": [[122973000.0, 0.0073], [122980000.0, 0.0004], [122991000.0, 0.1363], [122992000.0, 0.0203], [123000000.0, 0.1049], [123001000.0, 0.0001], [123002000.0, 0.0023], [123003000.0, 0.0081], [123004000.0, 0.0001], [123007000.0, 0.0082]]},
{"timestamp": "1743933248771", "bids": [[122968000.0, 0.0001], [122960000.0, 0.1511], [122956000.0, 0.0], [122950000.0, 0.0057], [122949000.0, 0.0002], [122944000.0, 0.003], [122940000.0, 0.0], [122931000.0, 0.0], [122930000.0, 0.0], [122926000.0, 0.0024]], "asks": [[122973000.0, 0.0079], [122980000.0, 0.0004], [122991000.0, 0.1363], [122992000.0, 0.0203], [123000000.0, 0.1049], [123001000.0, 0.0001], [123002000.0, 0.0023], [123003000.0, 0.0081], [123004000.0, 0.0001], [123007000.0, 0.0082]]},
{"timestamp": "1743933249265", "bids": [[122968000.0, 0.0001], [122960000.0, 0.1511], [122956000.0, 0.0], [122950000.0, 0.0057], [122949000.0, 0.0002], [122944000.0, 0.003], [122940000.0, 0.0], [122931000.0, 0.0], [122930000.0, 0.0], [122926000.0, 0.0024]], "asks": [[122973000.0, 0.0079], [122980000.0, 0.0004], [122991000.0, 0.1363], [122992000.0, 0.0203], [123000000.0, 0.1049], [123001000.0, 0.0001], [123002000.0, 0.0023], [123003000.0, 0.0081], [123004000.0, 0.0001], [123007000.0, 0.0082]]},
{"timestamp": "1743933249779", "bids": [[122968000.0, 0.0001], [122960000.0, 0.1511], [122956000.0, 0.0], [122950000.0, 0.0057], [122949000.0, 0.0002], [122944000.0, 0.003], [122940000.0, 0.0], [122931000.0, 0.0], [122930000.0, 0.0], [122926000.0, 0.0024]], "asks": [[122973000.0, 0.0079], [122980000.0, 0.0004], [122991000.0, 0.1363], [122992000.0, 0.0203], [123000000.0, 0.1049], [123001000.0, 0.0001], [123002000.0, 0.0023], [123003000.0, 0.0081], [123004000.0, 0.0001], [123007000.0, 0.0082]]},
{"timestamp": "1743933250301", "bids": [[122968000.0, 0.0001], [122960000.0, 0.1511], [122956000.0, 0.0], [122950000.0, 0.0057], [122949000.0, 0.0002], [122944000.0, 0.003], [122940000.0, 0.0], [122931000.0, 0.0], [122930000.0, 0.0], [122926000.0, 0.0024]], "asks": [[122973000.0, 0.0079], [122980000.0, 0.0004], [122991000.0, 0.1363], [122992000.0, 0.0203], [123000000.0, 0.1049], [123001000.0, 0.0001], [123002000.0, 0.0023], [123003000.0, 0.0081], [123004000.0, 0.0001], [123007000.0, 0.0082]]},
{"timestamp": "1743933250804", "bids": [[122968000.0, 0.0001], [122960000.0, 0.1511], [122956000.0, 0.0], [122950000.0, 0.0057], [122949000.0, 0.0002], [122944000.0, 0.003], [122940000.0, 0.0], [122931000.0, 0.0], [122930000.0, 0.0], [122926000.0, 0.0024]], "asks": [[122973000.0, 0.0079], [122980000.0, 0.0004], [122991000.0, 0.1363], [122992000.0, 0.0203], [123000000.0, 0.1049], [123001000.0, 0.0001], [123002000.0, 0.0023], [123003000.0, 0.0081], [123004000.0, 0.0001], [123007000.0, 0.0082]]},
{"timestamp": "1743933251319", "bids": [[122968000.0, 0.0001], [122960000.0, 0.1511], [122956000.0, 0.0], [122950000.0, 0.0057], [122949000.0, 0.0002], [122944000.0, 0.003], [122940000.0, 0.0], [122931000.0, 0.0], [122930000.0, 0.0], [122926000.0, 0.0024]], "asks": [[122973000.0, 0.0079], [122980000.0, 0.0004], [122991000.0, 0.1363], [122992000.0, 0.0203], [123000000.0, 0.1049], [123001000.0, 0.0001], [123002000.0, 0.0023], [123003000.0, 0.0081], [123004000.0, 0.0001], [123006000.0, 0.0081]]},
{"timestamp": "1743933251851", "bids": [[122968000.0, 0.0001], [122960000.0, 0.1511], [122956000.0, 0.0], [122950000.0, 0.0057], [122949000.0, 0.0002], [122944000.0, 0.003], [122940000.0, 0.0], [122931000.0, 0.0], [122930000.0, 0.0], [122926000.0, 0.0024]], "asks": [[122973000.0, 0.0079], [122980000.0, 0.0004], [122991000.0, 0.1363], [122992000.0, 0.0203], [123000000.0, 0.1049], [123001000.0, 0.0001], [123002000.0, 0.0023], [123003000.0, 0.0081], [123004000.0, 0.0001], [123006000.0, 0.0081]]},
{"timestamp": "1743933252342", "bids": [[122968000.0, 0.0001], [122960000.0, 0.1511], [122956000.0, 0.0], [122950000.0, 0.0057], [122949000.0, 0.0002], [122944000.0, 0.003], [122940000.0, 0.0], [122931000.0, 0.0], [122930000.0, 0.0], [122926000.0, 0.0024]], "asks": [[122973000.0, 0.0079], [122980000.0, 0.0004], [122991000.0, 0.1363], [122992000.0, 0.0203], [123000000.0, 0.1049], [123001000.0, 0.0001], [123002000.0, 0.0023], [123003000.0, 0.0081], [123004000.0, 0.0001], [123006000.0, 0.0081]]},
{"timestamp": "1743933252881", "bids": [[122968000.0, 0.0001], [122960000.0, 0.1511], [122956000.0, 0.0], [122950000.0, 0.0057], [122949000.0, 0.0002], [122944000.0, 0.003], [122940000.0, 0.0], [122931000.0, 0.0], [122930000.0, 0.0], [122926000.0, 0.0024]], "asks": [[122973000.0, 0.0079], [122980000.0, 0.0004], [122991000.0, 0.1363], [122992000.0, 0.0203], [123000000.0, 0.1049], [123001000.0, 0.0001], [123002000.0, 0.0023], [123003000.0, 0.0081], [123004000.0, 0.0001], [123006000.0, 0.0081]]},
{"timestamp": "1743933253389", "bids": [[122968000.0, 0.0001], [122960000.0, 0.1511], [122956000.0, 0.0], [122950000.0, 0.0057], [122949000.0, 0.0002], [122944000.0, 0.003], [122940000.0, 0.0], [122931000.0, 0.0], [122930000.0, 0.0], [122926000.0, 0.0024]], "asks": [[122973000.0, 0.0079], [122980000.0, 0.0004], [122990000.0, 0.0852], [122991000.0, 0.1363], [122992000.0, 0.0203], [123000000.0, 0.1049], [123001000.0, 0.0001], [123002000.0, 0.0023], [123003000.0, 0.0081], [123004000.0, 0.0001]]},
{"timestamp": "1743933253905", "bids": [[122968000.0, 0.0001], [122960000.0, 0.1511], [122956000.0, 0.0], [122950000.0, 0.0057], [122949000.0, 0.0002], [122944000.0, 0.003], [122940000.0, 0.0], [122931000.0, 0.0], [122930000.0, 0.0], [122926000.0, 0.0024]], "asks": [[122973000.0, 0.0079], [122980000.0, 0.0004], [122988000.0, 0.0852], [122989000.0, 0.1363], [122992000.0, 0.0203], [123000000.0, 0.1049], [123001000.0, 0.0001], [123002000.0, 0.0023], [123003000.0, 0.0081], [123004000.0, 0.0001]]},
{"timestamp": "1743933254417", "bids": [[122968000.0, 0.0001], [122960000.0, 0.1511], [122956000.0, 0.0], [122950000.0, 0.0057], [122949000.0, 0.0002], [122944000.0, 0.003], [122940000.0, 0.0], [122931000.0, 0.0], [122930000.0, 0.0], [122926000.0, 0.0024]], "asks": [[122973000.0, 0.0079], [122980000.0, 0.0004], [122987000.0, 0.1363], [122988000.0, 0.0852], [122992000.0, 0.0203], [123000000.0, 0.1049], [123001000.0, 0.0001], [123002000.0, 0.0023], [123003000.0, 0.0081], [123004000.0, 0.0001]]},
{"timestamp": "1743933254935", "bids": [[122968000.0, 0.0001], [122960000.0, 0.1511], [122956000.0, 0.0], [122950000.0, 0.0057], [122949000.0, 0.0002], [122944000.0, 0.003], [122940000.0, 0.0], [122931000.0, 0.0], [122930000.0, 0.0], [122926000.0, 0.0024]], "asks": [[122973000.0, 0.0079], [122980000.0, 0.0004], [122990000.0, 0.1363], [122992000.0, 0.0203], [123000000.0, 0.1049], [123001000.0, 0.0001], [123002000.0, 0.0023], [123003000.0, 0.0081], [123004000.0, 0.0001], [123006000.0, 0.0081]]},
{"timestamp": "1743933255411", "bids": [[122968000.0, 0.0001], [122960000.0, 0.1511], [122956000.0, 0.0], [122950000.0, 0.0057], [122949000.0, 0.0002], [122944000.0, 0.003], [122940000.0, 0.0], [122931000.0, 0.0], [122930000.0, 0.0], [122926000.0, 0.0024]], "asks": [[122973000.0, 0.0079], [122980000.0, 0.0004], [122992000.0, 0.0203], [123000000.0, 0.1049], [123001000.0, 0.0001], [123002000.0, 0.0023], [123003000.0, 0.0081], [123004000.0, 0.0001], [123006000.0, 0.0081], [123007000.0, 0.0082]]},
{"timestamp": "1743933255951", "bids": [[122968000.0, 0.0001], [122960000.0, 0.1515], [122956000.0, 0.0], [122950000.0, 0.0057], [122949000.0, 0.0002], [122944000.0, 0.003], [122940000.0, 0.0], [122931000.0, 0.0], [122930000.0, 0.0], [122926000.0, 0.0024]], "asks": [[122973000.0, 0.0079], [122980000.0, 0.0004], [122991000.0, 0.2215], [122992000.0, 0.0203], [123000000.0, 0.1049], [123001000.0, 0.0001], [123002000.0, 0.0023], [123003000.0, 0.0081], [123004000.0, 0.0001], [123006000.0, 0.0081]]},
{"timestamp": "1743933256466", "bids": [[122968000.0, 0.0001], [122960000.0, 0.1515], [122956000.0, 0.0], [122950000.0, 0.0057], [122949000.0, 0.0002], [122944000.0, 0.003], [122940000.0, 0.0], [122931000.0, 0.0], [122930000.0, 0.0], [122926000.0, 0.0024]], "asks": [[122973000.0, 0.0079], [122980000.0, 0.0004], [122989000.0, 0.2215], [122992000.0, 0.0203], [123000000.0, 0.1049], [123001000.0, 0.0001], [123002000.0, 0.0023], [123003000.0, 0.0081], [123004000.0, 0.0001], [123006000.0, 0.0081]]},
{"timestamp": "1743933256961", "bids": [[122968000.0, 0.0001], [122960000.0, 0.1515], [122956000.0, 0.0], [122950000.0, 0.0057], [122949000.0, 0.0002], [122944000.0, 0.003], [122940000.0, 0.0], [122931000.0, 0.0], [122930000.0, 0.0], [122926000.0, 0.0024]], "asks": [[122973000.0, 0.0079], [122980000.0, 0.0004], [122988000.0, 0.0852], [122992000.0, 0.0203], [123000000.0, 0.1049], [123001000.0, 0.0001], [123002000.0, 0.0023], [123003000.0, 0.0081], [123004000.0, 0.0001], [123006000.0, 0.0081]]},
{"timestamp": "1743933257504", "bids": [[122968000.0, 0.0001], [122960000.0, 0.1515], [122956000.0, 0.0], [122950000.0, 0.0057], [122949000.0, 0.0002], [122944000.0, 0.003], [122940000.0, 0.0], [122931000.0, 0.0], [122930000.0, 0.0], [122926000.0, 0.0024]], "asks": [[122973000.0, 0.0079], [122980000.0, 0.0004], [122991000.0, 0.2215], [122992000.0, 0.0203], [123000000.0, 0.1049], [123001000.0, 0.0001], [123002000.0, 0.0023], [123003000.0, 0.0081], [123004000.0, 0.0001], [123006000.0, 0.0081]]},
{"timestamp": "1743933257975", "bids": [[122968000.0, 0.0001], [122960000.0, 0.1515], [122956000.0, 0.0], [122950000.0, 0.0057], [122949000.0, 0.0002], [122944000.0, 0.003], [122940000.0, 0.0], [122931000.0, 0.0], [122930000.0, 0.0], [122926000.0, 0.0024]], "asks": [[122973000.0, 0.0079], [122980000.0, 0.0004], [122990000.0, 0.2215], [122992000.0, 0.0203], [123000000.0, 0.1049], [123001000.0, 0.0001], [123002000.0, 0.0023], [123003000.0, 0.0081], [123004000.0, 0.0001], [123006000.0, 0.0081]]},
{"timestamp": "1743933258483", "bids": [[122968000.0, 0.0001], [122960000.0, 0.1515], [122956000.0, 0.0], [122950000.0, 0.0057], [122949000.0, 0.0002], [122944000.0, 0.003], [122940000.0, 0.0], [122931000.0, 0.0], [122930000.0, 0.0], [122926000.0, 0.0024]], "asks": [[122973000.0, 0.0079], [122980000.0, 0.0004], [122989000.0, 0.1363], [122992000.0, 0.0203], [123000000.0, 0.1049], [123001000.0, 0.0001], [123002000.0, 0.0023], [123003000.0, 0.0081], [123004000.0, 0.0001], [123005000.0, 0.0081]]},
{"timestamp": "1743933258992", "bids": [[122968000.0, 0.0001], [122960000.0, 0.1515], [122956000.0, 0.0], [122950000.0, 0.0057], [122949000.0, 0.0002], [122944000.0, 0.003], [122940000.0, 0.0], [122931000.0, 0.0], [122930000.0, 0.0], [122926000.0, 0.0024]], "asks": [[122973000.0, 0.0079], [122980000.0, 0.0004], [122990000.0, 0.2215], [122992000.0, 0.0203], [123000000.0, 0.1049], [123001000.0, 0.0001], [123002000.0, 0.0023], [123003000.0, 0.0081], [123004000.0, 0.0001], [123005000.0, 0.0081]]},
{"timestamp": "1743933259524", "bids": [[122968000.0, 0.0001], [122960000.0, 0.1515], [122956000.0, 0.0], [122950000.0, 0.0057], [122949000.0, 0.0002], [122944000.0, 0.003], [122940000.0, 0.0], [122931000.0, 0.0], [122930000.0, 0.0], [122926000.0, 0.0024]], "asks": [[122973000.0, 0.0069], [122980000.0, 0.0004], [122989000.0, 0.2215], [122992000.0, 0.0203], [123000000.0, 0.1049], [123001000.0, 0.0001], [123002000.0, 0.0023], [123003000.0, 0.0081], [123004000.0, 0.0001], [123005000.0, 0.0081]]},
{"timestamp": "1743933260035", "bids": [[122968000.0, 0.0001], [122960000.0, 0.1515], [122956000.0, 0.0], [122950000.0, 0.0057], [122949000.0, 0.0002], [122944000.0, 0.003], [122940000.0, 0.0], [122931000.0, 0.0], [122930000.0, 0.0], [122926000.0, 0.0024]], "asks": [[122973000.0, 0.0069], [122980000.0, 0.0004], [122988000.0, 0.1363], [122992000.0, 0.0203], [123000000.0, 0.1049], [123001000.0, 0.0001], [123002000.0, 0.0023], [123003000.0, 0.0081], [123004000.0, 0.0001], [123005000.0, 0.0081]]},
{"timestamp": "1743933260528", "bids": [[122968000.0, 0.0001], [122960000.0, 0.1515], [122956000.0, 0.0], [122950000.0, 0.0057], [122949000.0, 0.0002], [122944000.0, 0.003], [122940000.0, 0.0], [122931000.0, 0.0], [122930000.0, 0.0], [122926000.0, 0.0024]], "asks": [[122973000.0, 0.0069], [122980000.0, 0.0004], [122989000.0, 0.1363], [122992000.0, 0.0203], [123000000.0, 0.1049], [123001000.0, 0.0001], [123002000.0, 0.0023], [123003000.0, 0.0081], [123004000.0, 0.0001], [123005000.0, 0.0081]]},
{"timestamp": "1743933261035", "bids": [[122968000.0, 0.0001], [122960000.0, 0.1515], [122956000.0, 0.0], [122950000.0, 0.0057], [122949000.0, 0.0002], [122944000.0, 0.003], [122940000.0, 0.0], [122931000.0, 0.0], [122930000.0, 0.0], [122926000.0, 0.0024]], "asks": [[122973000.0, 0.0069], [122980000.0, 0.0004], [122989000.0, 0.1363], [122991000.0, 0.0852], [122992000.0, 0.0203], [123000000.0, 0.1049], [123001000.0, 0.0001], [123002000.0, 0.0023], [123003000.0, 0.0081], [123004000.0, 0.0001]]},
{"timestamp": "1743933261548", "bids": [[122968000.0, 0.0001], [122960000.0, 0.1515], [122956000.0, 0.0], [122950000.0, 0.0057], [122949000.0, 0.0002], [122944000.0, 0.003], [122940000.0, 0.0], [122931000.0, 0.0], [122930000.0, 0.0], [122926000.0, 0.0024]], "asks": [[122973000.0, 0.0069], [122980000.0, 0.0004], [122988000.0, 0.0852], [122990000.0, 0.1363], [122992000.0, 0.0203], [123000000.0, 0.1049], [123001000.0, 0.0001], [123002000.0, 0.0023], [123003000.0, 0.0081], [123004000.0, 0.0001]]},
{"timestamp": "1743933262055", "bids": [[122968000.0, 0.0001], [122960000.0, 0.1515], [122956000.0, 0.0], [122950000.0, 0.0057], [122949000.0, 0.0002], [122944000.0, 0.003], [122940000.0, 0.0], [122931000.0, 0.0], [122930000.0, 0.0], [122926000.0, 0.0024]], "asks": [[122973000.0, 0.0069], [122980000.0, 0.0004], [122992000.0, 0.0203], [123000000.0, 0.1049], [123001000.0, 0.0001], [123002000.0, 0.0023], [123003000.0, 0.0081], [123004000.0, 0.0001], [123005000.0, 0.0081], [123006000.0, 0.0081]]},
{"timestamp": "1743933262602", "bids": [[122968000.0, 0.0001], [122960000.0, 0.1515], [122956000.0, 0.0], [122950000.0, 0.0057], [122949000.0, 0.0002], [122944000.0, 0.003], [122940000.0, 0.0], [122931000.0, 0.0], [122930000.0, 0.0], [122926000.0, 0.0024]], "asks": [[122973000.0, 0.0069], [122980000.0, 0.0004], [122990000.0, 0.0852], [122991000.0, 0.1363], [122992000.0, 0.0203], [123000000.0, 0.1049], [123001000.0, 0.0024], [123003000.0, 0.0081], [123004000.0, 0.0001], [123005000.0, 0.0081]]},
{"timestamp": "1743933263076", "bids": [[122960000.0, 0.1515], [122956000.0, 0.0], [122950000.0, 0.0057], [122949000.0, 0.0002], [122944000.0, 0.003], [122940000.0, 0.0], [122931000.0, 0.0], [122930000.0, 0.0], [122926000.0, 0.0024], [122918000.0, 0.0]], "asks": [[122968000.0, 0.0003], [122973000.0, 0.0069], [122980000.0, 0.0004], [122989000.0, 0.2215], [122992000.0, 0.0203], [123000000.0, 0.1049], [123001000.0, 0.0024], [123003000.0, 0.0081], [123004000.0, 0.0001], [123005000.0, 0.0081]]},
{"timestamp": "1743933263586", "bids": [[122960000.0, 0.1515], [122956000.0, 0.0], [122950000.0, 0.0057], [122949000.0, 0.0002], [122944000.0, 0.003], [122940000.0, 0.0], [122931000.0, 0.0], [122930000.0, 0.0], [122926000.0, 0.0024], [122918000.0, 0.0]], "asks": [[122968000.0, 0.0003], [122973000.0, 0.0069], [122980000.0, 0.0004], [122992000.0, 0.0203], [122998000.0, 0.0852], [122999000.0, 0.1363], [123000000.0, 0.1049], [123001000.0, 0.0024], [123003000.0, 0.0081], [123004000.0, 0.0001]]},
{"timestamp": "1743933264083", "bids": [[122960000.0, 0.1515], [122956000.0, 0.0], [122950000.0, 0.0057], [122949000.0, 0.0002], [122944000.0, 0.003], [122940000.0, 0.0], [122931000.0, 0.0], [122930000.0, 0.0], [122926000.0, 0.0024], [122918000.0, 0.0]], "asks": [[122968000.0, 0.0003], [122973000.0, 0.0069], [122980000.0, 0.0004], [122992000.0, 0.0203], [122997000.0, 0.1363], [123000000.0, 0.1049], [123001000.0, 0.0024], [123003000.0, 0.0081], [123004000.0, 0.0001], [123005000.0, 0.0081]]},
{"timestamp": "1743933264598", "bids": [[122960000.0, 0.1515], [122956000.0, 0.0], [122950000.0, 0.0057], [122949000.0, 0.0002], [122944000.0, 0.003], [122940000.0, 0.0], [122931000.0, 0.0], [122930000.0, 0.0], [122926000.0, 0.0024], [122918000.0, 0.0]], "asks": [[122968000.0, 0.0003], [122973000.0, 0.0069], [122980000.0, 0.0004], [122992000.0, 0.0203], [122996000.0, 0.0852], [122999000.0, 0.1363], [123000000.0, 0.1049], [123001000.0, 0.0024], [123003000.0, 0.0081], [123004000.0, 0.0001]]},
{"timestamp": "1743933265103", "bids": [[122960000.0, 0.1515], [122956000.0, 0.0], [122950000.0, 0.0057], [122949000.0, 0.0002], [122944000.0, 0.003], [122940000.0, 0.0], [122931000.0, 0.0], [122930000.0, 0.0], [122926000.0, 0.0024], [122918000.0, 0.0]], "asks": [[122968000.0, 0.0003], [122973000.0, 0.0069], [122980000.0, 0.0004], [122992000.0, 0.0203], [122995000.0, 0.1363], [122998000.0, 0.0852], [122999000.0, 0.1363], [123000000.0, 0.1049], [123001000.0, 0.0024], [123003000.0, 0.0081]]},
{"timestamp": "1743933265617", "bids": [[122960000.0, 0.1515], [122956000.0, 0.0], [122950000.0, 0.0057], [122949000.0, 0.0002], [122944000.0, 0.003], [122940000.0, 0.0], [122931000.0, 0.0], [122930000.0, 0.0], [122926000.0, 0.0024], [122918000.0, 0.0]], "asks": [[122968000.0, 0.0003], [122973000.0, 0.0069], [122980000.0, 0.0004], [122992000.0, 0.0203], [122995000.0, 0.1363], [123000000.0, 0.1049], [123001000.0, 0.0024], [123003000.0, 0.0081], [123004000.0, 0.0001], [123005000.0, 0.0081]]},
{"timestamp": "1743933266129", "bids": [[122960000.0, 0.1515], [122956000.0, 0.0], [122950000.0, 0.0057], [122949000.0, 0.0002], [122944000.0, 0.003], [122940000.0, 0.0], [122931000.0, 0.0], [122930000.0, 0.0], [122926000.0, 0.0024], [122918000.0, 0.0]], "asks": [[122968000.0, 0.0003], [122973000.0, 0.0069], [122980000.0, 0.0004], [122992000.0, 0.0203], [122998000.0, 0.0852], [122999000.0, 0.1363], [123000000.0, 0.1049], [123001000.0, 0.0024], [123003000.0, 0.0081], [123004000.0, 0.0001]]},
{"timestamp": "1743933266683", "bids": [[122960000.0, 0.1515], [122956000.0, 0.0], [122950000.0, 0.0057], [122949000.0, 0.0002], [122944000.0, 0.003], [122940000.0, 0.0], [122931000.0, 0.0], [122930000.0, 0.0], [122926000.0, 0.0024], [122918000.0, 0.0]], "asks": [[122968000.0, 0.0003], [122973000.0, 0.0069], [122980000.0, 0.0004], [122992000.0, 0.0203], [122997000.0, 0.1363], [122998000.0, 0.0852], [123000000.0, 0.1049], [123001000.0, 0.0024], [123003000.0, 0.0081], [123004000.0, 0.0001]]},
{"timestamp": "1743933267144", "bids": [[122960000.0, 0.1515], [122956000.0, 0.0], [122950000.0, 0.0057], [122949000.0, 0.0002], [122944000.0, 0.003], [122940000.0, 0.0], [122931000.0, 0.0], [122930000.0, 0.0], [122926000.0, 0.0024], [122918000.0, 0.0]], "asks": [[122968000.0, 0.0003], [122973000.0, 0.0069], [122980000.0, 0.0004], [122992000.0, 0.0203], [122997000.0, 0.1363], [123000000.0, 0.1049], [123001000.0, 0.0024], [123003000.0, 0.0081], [123004000.0, 0.0001], [123005000.0, 0.0081]]},
{"timestamp": "1743933267681", "bids": [[122960000.0, 0.1515], [122956000.0, 0.0], [122950000.0, 0.0057], [122949000.0, 0.0002], [122944000.0, 0.003], [122940000.0, 0.0], [122931000.0, 0.0], [122930000.0, 0.0], [122926000.0, 0.0024], [122918000.0, 0.0]], "asks": [[122968000.0, 0.0005], [122973000.0, 0.0069], [122980000.0, 0.0004], [122992000.0, 0.0203], [122998000.0, 0.0852], [122999000.0, 0.1363], [123000000.0, 0.1049], [123001000.0, 0.0024], [123003000.0, 0.0081], [123004000.0, 0.0001]]},
{"timestamp": "1743933268190", "bids": [[122960000.0, 0.1515], [122956000.0, 0.0], [122950000.0, 0.0057], [122949000.0, 0.0002], [122944000.0, 0.003], [122940000.0, 0.0], [122931000.0, 0.0], [122930000.0, 0.0], [122926000.0, 0.0024], [122918000.0, 0.0]], "asks": [[122968000.0, 0.0005], [122973000.0, 0.0069], [122980000.0, 0.0004], [122992000.0, 0.0203], [122997000.0, 0.1363], [122998000.0, 0.0852], [123000000.0, 0.1049], [123001000.0, 0.0024], [123003000.0, 0.0081], [123004000.0, 0.0001]]},
{"timestamp": "1743933268681", "bids": [[122960000.0, 0.1515], [122956000.0, 0.0], [122950000.0, 0.0057], [122949000.0, 0.0002], [122944000.0, 0.003], [122940000.0, 0.0], [122931000.0, 0.0], [122930000.0, 0.0], [122926000.0, 0.0024], [122918000.0, 0.0]], "asks": [[122968000.0, 0.0005], [122973000.0, 0.0069], [122980000.0, 0.0004], [122992000.0, 0.0203], [122995000.0, 0.0023], [122997000.0, 0.1363], [123000000.0, 0.1049], [123001000.0, 0.0024], [123003000.0, 0.0081], [123004000.0, 0.0001]]},
{"timestamp": "1743933269219", "bids": [[122960000.0, 0.1515], [122956000.0, 0.0], [122950000.0, 0.0057], [122949000.0, 0.0002], [122944000.0, 0.003], [122940000.0, 0.0], [122931000.0, 0.0], [122930000.0, 0.0], [122926000.0, 0.0024], [122918000.0, 0.0]], "asks": [[122968000.0, 0.0005], [122973000.0, 0.0069], [122980000.0, 0.0004], [122992000.0, 0.0203], [122995000.0, 0.0023], [122998000.0, 0.0852], [122999000.0, 0.1363], [123000000.0, 0.1049], [123001000.0, 0.0001], [123003000.0, 0.0081]]},
{"timestamp": "1743933269721", "bids": [[122960000.0, 0.1505], [122956000.0, 0.0], [122950000.0, 0.0057], [122949000.0, 0.0002], [122944000.0, 0.003], [122940000.0, 0.0], [122931000.0, 0.0], [122930000.0, 0.0], [122926000.0, 0.0024], [122918000.0, 0.0]], "asks": [[122968000.0, 0.0005], [122973000.0, 0.0069], [122980000.0, 0.0004], [122992000.0, 0.0203], [122995000.0, 0.0023], [122997000.0, 0.1363], [122998000.0, 0.0852], [123000000.0, 0.1049], [123001000.0, 0.0001], [123003000.0, 0.0081]]},
{"timestamp": "1743933270231", "bids": [[122960000.0, 0.1505], [122956000.0, 0.0], [122950000.0, 0.0057], [122949000.0, 0.0002], [122944000.0, 0.003], [122940000.0, 0.0], [122931000.0, 0.0], [122930000.0, 0.0], [122926000.0, 0.0024], [122918000.0, 0.0]], "asks": [[122968000.0, 0.0005], [122973000.0, 0.0069], [122980000.0, 0.0004], [122992000.0, 0.0203], [122995000.0, 0.0023], [122997000.0, 0.1363], [123000000.0, 0.1049], [123001000.0, 0.0001], [123003000.0, 0.0081], [123004000.0, 0.0001]]},
{"timestamp": "1743933270723", "bids": [[122960000.0, 0.1505], [122956000.0, 0.0], [122950000.0, 0.0057], [122949000.0, 0.0002], [122944000.0, 0.003], [122940000.0, 0.0], [122931000.0, 0.0], [122930000.0, 0.0], [122926000.0, 0.0024], [122918000.0, 0.0]], "asks": [[122968000.0, 0.0005], [122973000.0, 0.0069], [122980000.0, 0.0004], [122992000.0, 0.0203], [122995000.0, 0.0023], [122998000.0, 0.0852], [122999000.0, 0.1363], [123000000.0, 0.1049], [123001000.0, 0.0001], [123003000.0, 0.0081]]},
{"timestamp": "1743933271276", "bids": [[122960000.0, 0.1505], [122956000.0, 0.0], [122950000.0, 0.0057], [122949000.0, 0.0002], [122944000.0, 0.003], [122940000.0, 0.0], [122931000.0, 0.0], [122930000.0, 0.0], [122926000.0, 0.0024], [122918000.0, 0.0]], "asks": [[122968000.0, 0.0005], [122973000.0, 0.0069], [122980000.0, 0.0004], [122992000.0, 0.0203], [122995000.0, 0.0023], [122997000.0, 0.1363], [122998000.0, 0.0852], [123000000.0, 0.1049], [123001000.0, 0.0001], [123003000.0, 0.0081]]},
{"timestamp": "1743933271757", "bids": [[122960000.0, 0.1505], [122956000.0, 0.0], [122950000.0, 0.0057], [122949000.0, 0.0002], [122944000.0, 0.003], [122940000.0, 0.0], [122931000.0, 0.0], [122930000.0, 0.0], [122926000.0, 0.0024], [122918000.0, 0.0]], "asks": [[122968000.0, 0.0005], [122973000.0, 0.0069], [122980000.0, 0.0004], [122992000.0, 0.0203], [122994000.0, 0.0023], [122999000.0, 0.1363], [123000000.0, 0.1049], [123001000.0, 0.0001], [123003000.0, 0.0081], [123004000.0, 0.0001]]},
{"timestamp": "1743933272296", "bids": [[122960000.0, 0.1505], [122956000.0, 0.0], [122950000.0, 0.0057], [122949000.0, 0.0002], [122944000.0, 0.003], [122940000.0, 0.0], [122931000.0, 0.0], [122930000.0, 0.0], [122926000.0, 0.0024], [122918000.0, 0.0]], "asks": [[122968000.0, 0.0005], [122973000.0, 0.0069], [122980000.0, 0.0004], [122992000.0, 0.0203], [122994000.0, 0.0023], [122998000.0, 0.0852], [122999000.0, 0.1363], [123000000.0, 0.1049], [123001000.0, 0.0001], [123003000.0, 0.0081]]},
{"timestamp": "1743933272791", "bids": [[122960000.0, 0.1505], [122956000.0, 0.0], [122950000.0, 0.0057], [122949000.0, 0.0002], [122944000.0, 0.003], [122940000.0, 0.0], [122931000.0, 0.0], [122930000.0, 0.0], [122926000.0, 0.0024], [122918000.0, 0.0]], "asks": [[122968000.0, 0.0005], [122973000.0, 0.0069], [122980000.0, 0.0004], [122992000.0, 0.0203], [122994000.0, 0.0023], [122997000.0, 0.1363], [122998000.0, 0.0852], [123000000.0, 0.1049], [123001000.0, 0.0001], [123003000.0, 0.0081]]},
{"timestamp": "1743933273288", "bids": [[122960000.0, 0.1505], [122956000.0, 0.0], [122950000.0, 0.0057], [122949000.0, 0.0002], [122944000.0, 0.003], [122940000.0, 0.0], [122931000.0, 0.0], [122930000.0, 0.0], [122926000.0, 0.0024], [122918000.0, 0.0]], "asks": [[122968000.0, 0.0005], [122973000.0, 0.0069], [122980000.0, 0.0004], [122992000.0, 0.0203], [122994000.0, 0.0023], [122997000.0, 0.1363], [123000000.0, 0.1049], [123001000.0, 0.0001], [123003000.0, 0.0081], [123004000.0, 0.0001]]},
{"timestamp": "1743933273793", "bids": [[122960000.0, 0.1505], [122956000.0, 0.0], [122950000.0, 0.0057], [122949000.0, 0.0002], [122944000.0, 0.003], [122940000.0, 0.0], [122931000.0, 0.0], [122930000.0, 0.0], [122926000.0, 0.0024], [122918000.0, 0.0]], "asks": [[122968000.0, 0.0005], [122973000.0, 0.0069], [122980000.0, 0.0004], [122992000.0, 0.0203], [122994000.0, 0.0023], [122998000.0, 0.0852], [122999000.0, 0.1363], [123000000.0, 0.1049], [123001000.0, 0.0001], [123003000.0, 0.0081]]},
{"timestamp": "1743933274324", "bids": [[122960000.0, 0.1505], [122956000.0, 0.0], [122950000.0, 0.0057], [122949000.0, 0.0002], [122944000.0, 0.003], [122940000.0, 0.0], [122931000.0, 0.0], [122930000.0, 0.0], [122926000.0, 0.0024], [122918000.0, 0.0]], "asks": [[122968000.0, 0.0005], [122973000.0, 0.0069], [122980000.0, 0.0004], [122992000.0, 0.0203], [122994000.0, 0.0023], [122997000.0, 0.1363], [122998000.0, 0.0852], [123000000.0, 0.1049], [123001000.0, 0.0001], [123003000.0, 0.0081]]},
{"timestamp": "1743933274822", "bids": [[122960000.0, 0.1505], [122956000.0, 0.0], [122950000.0, 0.0057], [122949000.0, 0.0002], [122944000.0, 0.003], [122940000.0, 0.0], [122931000.0, 0.0], [122930000.0, 0.0], [122926000.0, 0.0024], [122918000.0, 0.0]], "asks": [[122968000.0, 0.0005], [122973000.0, 0.0069], [122980000.0, 0.0004], [122992000.0, 0.0203], [122994000.0, 0.0023], [122997000.0, 0.1363], [123000000.0, 0.1049], [123001000.0, 0.0001], [123003000.0, 0.0081], [123004000.0, 0.0001]]},
{"timestamp": "1743933275351", "bids": [[122960000.0, 0.1505], [122956000.0, 0.0], [122950000.0, 0.0057], [122949000.0, 0.0002], [122944000.0, 0.003], [122940000.0, 0.0], [122931000.0, 0.0], [122930000.0, 0.0], [122926000.0, 0.0024], [122918000.0, 0.0]], "asks": [[122968000.0, 0.0005], [122973000.0, 0.0069], [122980000.0, 0.0004], [122992000.0, 0.0203], [122994000.0, 0.0023], [122999000.0, 0.1363], [123000000.0, 0.1049], [123001000.0, 0.0001], [123003000.0, 0.0081], [123004000.0, 0.0001]]},
{"timestamp": "1743933275843", "bids": [[122960000.0, 0.1505], [122956000.0, 0.0], [122950000.0, 0.0057], [122949000.0, 0.0002], [122944000.0, 0.003], [122940000.0, 0.0], [122931000.0, 0.0], [122930000.0, 0.0], [122926000.0, 0.0024], [122918000.0, 0.0]], "asks": [[122968000.0, 0.0005], [122973000.0, 0.0069], [122980000.0, 0.0004], [122992000.0, 0.0203], [122994000.0, 0.0023], [122998000.0, 0.0852], [122999000.0, 0.1363], [123000000.0, 0.1049], [123001000.0, 0.0001], [123003000.0, 0.0081]]},
{"timestamp": "1743933276379", "bids": [[122960000.0, 0.1505], [122956000.0, 0.0], [122950000.0, 0.0057], [122949000.0, 0.0002], [122944000.0, 0.003], [122940000.0, 0.0], [122931000.0, 0.0], [122930000.0, 0.0], [122926000.0, 0.0024], [122918000.0, 0.0]], "asks": [[122968000.0, 0.0004], [122973000.0, 0.0069], [122980000.0, 0.0004], [122992000.0, 0.0203], [122994000.0, 0.0023], [123000000.0, 0.1049], [123001000.0, 0.0001], [123003000.0, 0.0081], [123004000.0, 0.0001], [123005000.0, 0.0081]]},
{"timestamp": "1743933276882", "bids": [[122960000.0, 0.1505], [122956000.0, 0.0], [122950000.0, 0.0057], [122949000.0, 0.0002], [122944000.0, 0.003], [122940000.0, 0.0], [122931000.0, 0.0], [122930000.0, 0.0], [122926000.0, 0.0024], [122918000.0, 0.0]], "asks": [[122968000.0, 0.0003], [122973000.0, 0.0069], [122980000.0, 0.0004], [122992000.0, 0.0203], [122994000.0, 0.0023], [122999000.0, 0.2215], [123000000.0, 0.1049], [123001000.0, 0.0001], [123003000.0, 0.0081], [123004000.0, 0.0001]]},
{"timestamp": "1743933277672", "bids": [[122960000.0, 0.1505], [122956000.0, 0.0], [122950000.0, 0.0057], [122949000.0, 0.0002], [122944000.0, 0.003], [122940000.0, 0.0], [122931000.0, 0.0], [122930000.0, 0.0], [122926000.0, 0.0024], [122918000.0, 0.0]], "asks": [[122968000.0, 0.0003], [122973000.0, 0.0069], [122980000.0, 0.0004], [122992000.0, 0.0203], [122994000.0, 0.0023], [122997000.0, 0.1363], [123000000.0, 0.1049], [123001000.0, 0.0001], [123003000.0, 0.0081], [123004000.0, 0.0001]]},
{"timestamp": "1743933277944", "bids": [[122960000.0, 0.1505], [122956000.0, 0.0], [122950000.0, 0.0057], [122949000.0, 0.0002], [122944000.0, 0.003], [122940000.0, 0.0], [122931000.0, 0.0], [122930000.0, 0.0], [122926000.0, 0.0024], [122918000.0, 0.0]], "asks": [[122968000.0, 0.0003], [122973000.0, 0.0069], [122980000.0, 0.0004], [122992000.0, 0.0203], [122994000.0, 0.0023], [122999000.0, 0.1363], [123000000.0, 0.1049], [123001000.0, 0.0001], [123003000.0, 0.0081], [123004000.0, 0.0001]]},
{"timestamp": "1743933278436", "bids": [[122960000.0, 0.1505], [122956000.0, 0.0], [122950000.0, 0.0057], [122949000.0, 0.0002], [122944000.0, 0.003], [122940000.0, 0.0], [122931000.0, 0.0], [122930000.0, 0.0], [122926000.0, 0.0024], [122918000.0, 0.0]], "asks": [[122968000.0, 0.0003], [122973000.0, 0.0069], [122980000.0, 0.0004], [122992000.0, 0.0203], [122994000.0, 0.0023], [122998000.0, 0.0852], [122999000.0, 0.1363], [123000000.0, 0.1049], [123001000.0, 0.0001], [123003000.0, 0.0081]]},
{"timestamp": "1743933278914", "bids": [[122960000.0, 0.1505], [122956000.0, 0.0], [122950000.0, 0.0057], [122949000.0, 0.0002], [122944000.0, 0.003], [122940000.0, 0.0], [122931000.0, 0.0], [122930000.0, 0.0], [122926000.0, 0.0024], [122918000.0, 0.0]], "asks": [[122968000.0, 0.0003], [122973000.0, 0.0069], [122980000.0, 0.0004], [122992000.0, 0.0203], [122995000.0, 0.0023], [122997000.0, 0.1363], [123000000.0, 0.1049], [123001000.0, 0.0001], [123003000.0, 0.0081], [123004000.0, 0.0001]]},
{"timestamp": "1743933279501", "bids": [[122960000.0, 0.1505], [122956000.0, 0.0], [122950000.0, 0.0057], [122949000.0, 0.0002], [122944000.0, 0.003], [122940000.0, 0.0], [122931000.0, 0.0], [122930000.0, 0.0], [122926000.0, 0.0024], [122918000.0, 0.0]], "asks": [[122968000.0, 0.0003], [122973000.0, 0.0069], [122980000.0, 0.0004], [122992000.0, 0.0203], [122995000.0, 0.0023], [122999000.0, 0.2215], [123000000.0, 0.1049], [123001000.0, 0.0001], [123003000.0, 0.0081], [123004000.0, 0.0001]]},
{"timestamp": "1743933279958", "bids": [[122960000.0, 0.1505], [122956000.0, 0.0], [122950000.0, 0.0057], [122949000.0, 0.0002], [122944000.0, 0.003], [122940000.0, 0.0], [122931000.0, 0.0], [122930000.0, 0.0], [122926000.0, 0.0024], [122918000.0, 0.0]], "asks": [[122968000.0, 0.0003], [122973000.0, 0.0069], [122980000.0, 0.0004], [122992000.0, 0.0203], [122995000.0, 0.0023], [122999000.0, 0.2215], [123000000.0, 0.1049], [123001000.0, 0.0001], [123003000.0, 0.0081], [123004000.0, 0.0001]]},
{"timestamp": "1743933280521", "bids": [[122960000.0, 0.1505], [122956000.0, 0.0], [122950000.0, 0.0057], [122949000.0, 0.0002], [122944000.0, 0.003], [122940000.0, 0.0], [122931000.0, 0.0], [122930000.0, 0.0], [122926000.0, 0.0024], [122918000.0, 0.0]], "asks": [[122968000.0, 0.0003], [122973000.0, 0.0069], [122980000.0, 0.0004], [122992000.0, 0.0203], [122995000.0, 0.0023], [122998000.0, 0.2215], [123000000.0, 0.1049], [123001000.0, 0.0001], [123003000.0, 0.0081], [123004000.0, 0.0001]]},
{"timestamp": "1743933281039", "bids": [[122960000.0, 0.1505], [122956000.0, 0.0], [122950000.0, 0.0057], [122949000.0, 0.0002], [122944000.0, 0.003], [122940000.0, 0.0], [122931000.0, 0.0], [122930000.0, 0.0], [122926000.0, 0.0024], [122918000.0, 0.0]], "asks": [[122968000.0, 0.0003], [122973000.0, 0.0069], [122980000.0, 0.0004], [122992000.0, 0.0203], [122995000.0, 0.0023], [122997000.0, 0.2215], [123000000.0, 0.1049], [123001000.0, 0.0001], [123003000.0, 0.0081], [123004000.0, 0.0001]]},
{"timestamp": "1743933281497", "bids": [[122960000.0, 0.1505], [122956000.0, 0.0], [122950000.0, 0.0057], [122949000.0, 0.0002], [122944000.0, 0.003], [122940000.0, 0.0], [122931000.0, 0.0], [122930000.0, 0.0], [122926000.0, 0.0024], [122918000.0, 0.0]], "asks": [[122968000.0, 0.0003], [122973000.0, 0.0069], [122980000.0, 0.0004], [122992000.0, 0.0203], [122995000.0, 0.0023], [122999000.0, 0.1363], [123000000.0, 0.1049], [123001000.0, 0.0001], [123003000.0, 0.0081], [123004000.0, 0.0001]]},
{"timestamp": "1743933281976", "bids": [[122960000.0, 0.1505], [122956000.0, 0.0], [122950000.0, 0.0057], [122949000.0, 0.0002], [122944000.0, 0.003], [122940000.0, 0.0], [122931000.0, 0.0], [122930000.0, 0.0], [122926000.0, 0.0024], [122918000.0, 0.0]], "asks": [[122968000.0, 0.0003], [122973000.0, 0.0069], [122980000.0, 0.0004], [122992000.0, 0.0203], [122995000.0, 0.0023], [122998000.0, 0.0852], [122999000.0, 0.1363], [123000000.0, 0.1049], [123001000.0, 0.0001], [123003000.0, 0.0081]]},
{"timestamp": "1743933282507", "bids": [[122960000.0, 0.1505], [122956000.0, 0.0], [122950000.0, 0.0057], [122949000.0, 0.0002], [122944000.0, 0.003], [122940000.0, 0.0], [122931000.0, 0.0], [122930000.0, 0.0], [122926000.0, 0.0024], [122918000.0, 0.0]], "asks": [[122968000.0, 0.0003], [122973000.0, 0.0069], [122980000.0, 0.0004], [122992000.0, 0.0203], [122995000.0, 0.0023], [122997000.0, 0.1363], [123000000.0, 0.1049], [123001000.0, 0.0001], [123003000.0, 0.0081], [123004000.0, 0.0001]]},
{"timestamp": "1743933283026", "bids": [[122960000.0, 0.1505], [122956000.0, 0.0], [122950000.0, 0.0057], [122949000.0, 0.0002], [122944000.0, 0.003], [122940000.0, 0.0], [122931000.0, 0.0], [122930000.0, 0.0], [122926000.0, 0.0024], [122918000.0, 0.0]], "asks": [[122968000.0, 0.0003], [122973000.0, 0.0069], [122980000.0, 0.0004], [122992000.0, 0.0203], [122995000.0, 0.0023], [122999000.0, 0.1363], [123000000.0, 0.1049], [123001000.0, 0.0001], [123003000.0, 0.0081], [123004000.0, 0.0001]]},
{"timestamp": "1743933283530", "bids": [[122960000.0, 0.1505], [122956000.0, 0.0], [122950000.0, 0.0057], [122949000.0, 0.0002], [122944000.0, 0.003], [122940000.0, 0.0], [122931000.0, 0.0], [122930000.0, 0.0], [122926000.0, 0.0024], [122918000.0, 0.0]], "asks": [[122968000.0, 0.0003], [122973000.0, 0.0069], [122980000.0, 0.0004], [122992000.0, 0.0203], [122995000.0, 0.0023], [122998000.0, 0.0852], [122999000.0, 0.1363], [123000000.0, 0.1049], [123001000.0, 0.0001], [123003000.0, 0.0081]]},
{"timestamp": "1743933284030", "bids": [[122960000.0, 0.1505], [122956000.0, 0.0], [122950000.0, 0.0057], [122949000.0, 0.0002], [122944000.0, 0.003], [122940000.0, 0.0], [122931000.0, 0.0], [122930000.0, 0.0], [122926000.0, 0.0024], [122918000.0, 0.0]], "asks": [[122968000.0, 0.0003], [122973000.0, 0.0069], [122980000.0, 0.0004], [122992000.0, 0.0203], [122995000.0, 0.0023], [122997000.0, 0.1363], [123000000.0, 0.1049], [123001000.0, 0.0001], [123003000.0, 0.0081], [123004000.0, 0.0001]]},
{"timestamp": "1743933284536", "bids": [[122960000.0, 0.1505], [122956000.0, 0.0], [122950000.0, 0.0057], [122949000.0, 0.0002], [122944000.0, 0.003], [122940000.0, 0.0], [122931000.0, 0.0], [122930000.0, 0.0], [122926000.0, 0.0024], [122918000.0, 0.0]], "asks": [[122968000.0, 0.0003], [122973000.0, 0.0069], [122980000.0, 0.0004], [122992000.0, 0.0203], [122995000.0, 0.0023], [122999000.0, 0.1363], [123000000.0, 0.1049], [123001000.0, 0.0001], [123003000.0, 0.0081], [123004000.0, 0.0001]]},
{"timestamp": "1743933285064", "bids": [[122960000.0, 0.1505], [122956000.0, 0.0], [122950000.0, 0.0057], [122949000.0, 0.0002], [122944000.0, 0.003], [122940000.0, 0.0], [122931000.0, 0.0], [122930000.0, 0.0], [122926000.0, 0.0024], [122918000.0, 0.0]], "asks": [[122968000.0, 0.0003], [122973000.0, 0.0069], [122980000.0, 0.0004], [122992000.0, 0.0203], [122995000.0, 0.0023], [122998000.0, 0.0852], [122999000.0, 0.1363], [123000000.0, 0.1049], [123001000.0, 0.0001], [123003000.0, 0.0081]]},
{"timestamp": "1743933285570", "bids": [[122960000.0, 0.1505], [122956000.0, 0.0], [122950000.0, 0.0057], [122949000.0, 0.0002], [122944000.0, 0.003], [122940000.0, 0.0], [122931000.0, 0.0], [122930000.0, 0.0], [122926000.0, 0.0024], [122918000.0, 0.0]], "asks": [[122968000.0, 0.0003], [122973000.0, 0.0069], [122980000.0, 0.0004], [122991000.0, 0.1363], [122992000.0, 0.0203], [122995000.0, 0.0023], [123000000.0, 0.1049], [123001000.0, 0.0001], [123003000.0, 0.0081], [123004000.0, 0.0001]]},
{"timestamp": "1743933286115", "bids": [[122960000.0, 0.1505], [122956000.0, 0.0], [122950000.0, 0.0057], [122949000.0, 0.0002], [122944000.0, 0.003], [122940000.0, 0.0], [122931000.0, 0.0], [122930000.0, 0.0], [122926000.0, 0.0024], [122918000.0, 0.0]], "asks": [[122968000.0, 0.0003], [122973000.0, 0.0069], [122980000.0, 0.0004], [122991000.0, 0.1363], [122992000.0, 0.0203], [122995000.0, 0.0023], [123000000.0, 0.1049], [123001000.0, 0.0001], [123003000.0, 0.0081], [123004000.0, 0.0001]]},
{"timestamp": "1743933286613", "bids": [[122960000.0, 0.1505], [122956000.0, 0.0], [122950000.0, 0.0057], [122949000.0, 0.0002], [122944000.0, 0.003], [122940000.0, 0.0], [122931000.0, 0.0], [122930000.0, 0.0], [122926000.0, 0.0024], [122918000.0, 0.0]], "asks": [[122968000.0, 0.0003], [122973000.0, 0.0069], [122980000.0, 0.0004], [122991000.0, 0.1363], [122992000.0, 0.0203], [122995000.0, 0.0023], [123000000.0, 0.1049], [123001000.0, 0.0001], [123003000.0, 0.0081], [123004000.0, 0.0001]]},
{"timestamp": "1743933287111", "bids": [[122960000.0, 0.1505], [122956000.0, 0.0], [122950000.0, 0.0057], [122949000.0, 0.0002], [122944000.0, 0.003], [122940000.0, 0.0], [122931000.0, 0.0], [122930000.0, 0.0], [122926000.0, 0.0024], [122918000.0, 0.0]], "asks": [[122968000.0, 0.0003], [122973000.0, 0.0069], [122980000.0, 0.0004], [122991000.0, 0.1363], [122992000.0, 0.0203], [122995000.0, 0.0023], [123000000.0, 0.1049], [123001000.0, 0.0001], [123003000.0, 0.0081], [123004000.0, 0.0001]]},
{"timestamp": "1743933287633", "bids": [[122960000.0, 0.1505], [122956000.0, 0.0], [122950000.0, 0.0057], [122949000.0, 0.0002], [122944000.0, 0.003], [122940000.0, 0.0], [122931000.0, 0.0], [122930000.0, 0.0], [122926000.0, 0.0024], [122918000.0, 0.0]], "asks": [[122968000.0, 0.0003], [122973000.0, 0.0069], [122980000.0, 0.0004], [122991000.0, 0.1363], [122992000.0, 0.0203], [122995000.0, 0.0023], [123000000.0, 0.1049], [123001000.0, 0.0001], [123003000.0, 0.0081], [123004000.0, 0.0001]]},
{"timestamp": "1743933288151", "bids": [[122960000.0, 0.1505], [122956000.0, 0.0], [122950000.0, 0.0057], [122949000.0, 0.0002], [122944000.0, 0.003], [122940000.0, 0.0], [122931000.0, 0.0], [122930000.0, 0.0], [122926000.0, 0.0024], [122918000.0, 0.0]], "asks": [[122968000.0, 0.0003], [122973000.0, 0.0069], [122980000.0, 0.0004], [122991000.0, 0.1363], [122992000.0, 0.0203], [122995000.0, 0.0023], [123000000.0, 0.1049], [123001000.0, 0.0001], [123003000.0, 0.0081], [123004000.0, 0.0001]]},
{"timestamp": "1743933288663", "bids": [[122960000.0, 0.1505], [122956000.0, 0.0], [122950000.0, 0.0057], [122949000.0, 0.0002], [122944000.0, 0.003], [122940000.0, 0.0], [122931000.0, 0.0], [122930000.0, 0.0], [122926000.0, 0.0024], [122918000.0, 0.0]], "asks": [[122968000.0, 0.0003], [122973000.0, 0.0069], [122980000.0, 0.0004], [122991000.0, 0.1363], [122992000.0, 0.0203], [122995000.0, 0.0023], [123000000.0, 0.1049], [123001000.0, 0.0001], [123003000.0, 0.0081], [123004000.0, 0.0001]]},
{"timestamp": "1743933289171", "bids": [[122960000.0, 0.1505], [122956000.0, 0.0], [122950000.0, 0.0057], [122949000.0, 0.0002], [122944000.0, 0.003], [122940000.0, 0.0], [122931000.0, 0.0], [122930000.0, 0.0], [122926000.0, 0.0024], [122918000.0, 0.0]], "asks": [[122968000.0, 0.0003], [122973000.0, 0.0069], [122980000.0, 0.0004], [122991000.0, 0.1363], [122992000.0, 0.0203], [122995000.0, 0.0023], [123000000.0, 0.1049], [123001000.0, 0.0001], [123003000.0, 0.0081], [123004000.0, 0.0001]]},
{"timestamp": "1743933289666", "bids": [[122960000.0, 0.1505], [122956000.0, 0.0], [122950000.0, 0.0057], [122949000.0, 0.0002], [122944000.0, 0.003], [122940000.0, 0.0], [122931000.0, 0.0], [122930000.0, 0.0], [122926000.0, 0.0024], [122918000.0, 0.0]], "asks": [[122968000.0, 0.0003], [122973000.0, 0.0069], [122980000.0, 0.0004], [122991000.0, 0.1363], [122992000.0, 0.0203], [122995000.0, 0.0023], [123000000.0, 0.1049], [123001000.0, 0.0001], [123003000.0, 0.0081], [123004000.0, 0.0001]]},
{"timestamp": "1743933290192", "bids": [[122960000.0, 0.1505], [122956000.0, 0.0], [122950000.0, 0.0057], [122949000.0, 0.0002], [122944000.0, 0.003], [122940000.0, 0.0], [122931000.0, 0.0], [122930000.0, 0.0], [122926000.0, 0.0024], [122918000.0, 0.0]], "asks": [[122968000.0, 0.0003], [122973000.0, 0.0069], [122980000.0, 0.0004], [122991000.0, 0.1363], [122992000.0, 0.0203], [122995000.0, 0.0023], [123000000.0, 0.1049], [123001000.0, 0.0001], [123003000.0, 0.0081], [123004000.0, 0.0001]]},
{"timestamp": "1743933290680", "bids": [[122960000.0, 0.1505], [122956000.0, 0.0], [122950000.0, 0.0057], [122949000.0, 0.0002], [122944000.0, 0.003], [122940000.0, 0.0], [122931000.0, 0.0], [122930000.0, 0.0], [122926000.0, 0.0024], [122918000.0, 0.0]], "asks": [[122968000.0, 0.0003], [122973000.0, 0.0069], [122980000.0, 0.0004], [122991000.0, 0.1363], [122992000.0, 0.0203], [122995000.0, 0.0023], [123000000.0, 0.1049], [123001000.0, 0.0001], [123003000.0, 0.0081], [123004000.0, 0.0001]]},
{"timestamp": "1743933291221", "bids": [[122960000.0, 0.1505], [122956000.0, 0.0], [122950000.0, 0.0057], [122949000.0, 0.0002], [122944000.0, 0.003], [122940000.0, 0.0], [122931000.0, 0.0], [122930000.0, 0.0], [122926000.0, 0.0024], [122918000.0, 0.0]], "asks": [[122968000.0, 0.0003], [122973000.0, 0.0069], [122980000.0, 0.0004], [122991000.0, 0.1363], [122992000.0, 0.0203], [122995000.0, 0.0023], [123000000.0, 0.1049], [123001000.0, 0.0001], [123003000.0, 0.0081], [123004000.0, 0.0001]]},
{"timestamp": "1743933291710", "bids": [[122960000.0, 0.1505], [122956000.0, 0.0], [122950000.0, 0.0057], [122949000.0, 0.0002], [122944000.0, 0.003], [122940000.0, 0.0], [122931000.0, 0.0], [122930000.0, 0.0], [122926000.0, 0.0024], [122918000.0, 0.0]], "asks": [[122968000.0, 0.0003], [122973000.0, 0.0069], [122980000.0, 0.0004], [122991000.0, 0.1363], [122992000.0, 0.0203], [122995000.0, 0.0023], [123000000.0, 0.1049], [123001000.0, 0.0001], [123003000.0, 0.0081], [123004000.0, 0.0001]]},
{"timestamp": "1743933292209", "bids": [[122960000.0, 0.1505], [122956000.0, 0.0], [122950000.0, 0.0057], [122949000.0, 0.0002], [122944000.0, 0.003], [122940000.0, 0.0], [122931000.0, 0.0], [122930000.0, 0.0], [122926000.0, 0.0024], [122918000.0, 0.0]], "asks": [[122968000.0, 0.0003], [122973000.0, 0.0069], [122980000.0, 0.0004], [122991000.0, 0.1363], [122992000.0, 0.0203], [122995000.0, 0.0023], [123000000.0, 0.1049], [123001000.0, 0.0001], [123003000.0, 0.0081], [123004000.0, 0.0001]]},
{"timestamp": "1743933292727", "bids": [[122960000.0, 0.1505], [122956000.0, 0.0], [122950000.0, 0.0057], [122949000.0, 0.0002], [122944000.0, 0.003], [122940000.0, 0.0], [122931000.0, 0.0], [122930000.0, 0.0], [122926000.0, 0.0024], [122918000.0, 0.0]], "asks": [[122968000.0, 0.0003], [122973000.0, 0.0069], [122980000.0, 0.0004], [122991000.0, 0.1363], [122992000.0, 0.0203], [122995000.0, 0.0023], [123000000.0, 0.1049], [123001000.0, 0.0001], [123003000.0, 0.0081], [123004000.0, 0.0001]]},
{"timestamp": "1743933293237", "bids": [[122960000.0, 0.1505], [122956000.0, 0.0], [122950000.0, 0.0057], [122949000.0, 0.0002], [122944000.0, 0.003], [122940000.0, 0.0], [122931000.0, 0.0], [122930000.0, 0.0], [122926000.0, 0.0024], [122918000.0, 0.0]], "asks": [[122968000.0, 0.0003], [122973000.0, 0.0069], [122980000.0, 0.0004], [122991000.0, 0.1363], [122992000.0, 0.0203], [122995000.0, 0.0023], [123000000.0, 0.1049], [123001000.0, 0.0001], [123003000.0, 0.0081], [123004000.0, 0.0001]]},
{"timestamp": "1743933293781", "bids": [[122960000.0, 0.1505], [122956000.0, 0.0], [122950000.0, 0.0057], [122949000.0, 0.0002], [122944000.0, 0.003], [122940000.0, 0.0], [122931000.0, 0.0], [122930000.0, 0.0], [122926000.0, 0.0024], [122918000.0, 0.0]], "asks": [[122968000.0, 0.0003], [122973000.0, 0.0069], [122980000.0, 0.0004], [122991000.0, 0.1363], [122992000.0, 0.0203], [122995000.0, 0.0023], [123000000.0, 0.1049], [123001000.0, 0.0001], [123003000.0, 0.0081], [123004000.0, 0.0001]]},
{"timestamp": "1743933294265", "bids": [[122960000.0, 0.1505], [122956000.0, 0.0], [122950000.0, 0.0057], [122949000.0, 0.0002], [122944000.0, 0.003], [122940000.0, 0.0], [122931000.0, 0.0], [122930000.0, 0.0], [122926000.0, 0.0024], [122918000.0, 0.0]], "asks": [[122968000.0, 0.0004], [122973000.0, 0.0069], [122980000.0, 0.0004], [122991000.0, 0.1363], [122992000.0, 0.0203], [122995000.0, 0.0023], [123000000.0, 0.1049], [123001000.0, 0.0001], [123003000.0, 0.0081], [123004000.0, 0.0001]]},
{"timestamp": "1743933294776", "bids": [[122960000.0, 0.1505], [122956000.0, 0.0], [122950000.0, 0.0057], [122949000.0, 0.0002], [122944000.0, 0.003], [122940000.0, 0.0], [122931000.0, 0.0], [122930000.0, 0.0], [122926000.0, 0.0024], [122918000.0, 0.0]], "asks": [[122968000.0, 0.0004], [122973000.0, 0.0069], [122980000.0, 0.0004], [122991000.0, 0.1363], [122992000.0, 0.0203], [122995000.0, 0.0023], [123000000.0, 0.1049], [123001000.0, 0.0001], [123003000.0, 0.0081], [123004000.0, 0.0001]]},
{"timestamp": "1743933295319", "bids": [[122960000.0, 0.1505], [122956000.0, 0.0], [122950000.0, 0.0057], [122949000.0, 0.0002], [122944000.0, 0.003], [122940000.0, 0.0], [122931000.0, 0.0], [122930000.0, 0.0], [122926000.0, 0.0024], [122918000.0, 0.0]], "asks": [[122968000.0, 0.0004], [122973000.0, 0.0069], [122980000.0, 0.0004], [122991000.0, 0.1363], [122992000.0, 0.0203], [122995000.0, 0.0023], [123000000.0, 0.1049], [123001000.0, 0.0001], [123003000.0, 0.0081], [123004000.0, 0.0001]]},
{"timestamp": "1743933295829", "bids": [[122960000.0, 0.1505], [122956000.0, 0.0], [122950000.0, 0.0057], [122949000.0, 0.0002], [122944000.0, 0.003], [122940000.0, 0.0], [122931000.0, 0.0], [122930000.0, 0.0], [122926000.0, 0.0024], [122918000.0, 0.0]], "asks": [[122968000.0, 0.0004], [122973000.0, 0.0069], [122980000.0, 0.0004], [122991000.0, 0.1363], [122992000.0, 0.0203], [122995000.0, 0.0023], [123000000.0, 0.1049], [123001000.0, 0.0001], [123003000.0, 0.0081], [123004000.0, 0.0001]]},
{"timestamp": "1743933296334", "bids": [[122960000.0, 0.1505], [122956000.0, 0.0], [122950000.0, 0.0057], [122949000.0, 0.0002], [122944000.0, 0.003], [122940000.0, 0.0], [122931000.0, 0.0], [122930000.0, 0.0], [122926000.0, 0.0024], [122918000.0, 0.0]], "asks": [[122968000.0, 0.0004], [122973000.0, 0.0069], [122980000.0, 0.0004], [122989000.0, 0.1363], [122990000.0, 0.0852], [122992000.0, 0.0203], [122995000.0, 0.0023], [123000000.0, 0.1049], [123001000.0, 0.0001], [123003000.0, 0.0081]]},
{"timestamp": "1743933296855", "bids": [[122960000.0, 0.1505], [122956000.0, 0.0], [122950000.0, 0.0057], [122949000.0, 0.0002], [122944000.0, 0.003], [122940000.0, 0.0], [122931000.0, 0.0], [122930000.0, 0.0], [122926000.0, 0.0024], [122918000.0, 0.0]], "asks": [[122968000.0, 0.0004], [122973000.0, 0.0069], [122980000.0, 0.0004], [122988000.0, 0.0852], [122992000.0, 0.0203], [122995000.0, 0.0023], [123000000.0, 0.1049], [123001000.0, 0.0001], [123003000.0, 0.0081], [123004000.0, 0.0001]]},
{"timestamp": "1743933297360", "bids": [[122960000.0, 0.1505], [122956000.0, 0.0], [122950000.0, 0.0057], [122949000.0, 0.0002], [122944000.0, 0.003], [122940000.0, 0.0], [122931000.0, 0.0], [122930000.0, 0.0], [122926000.0, 0.0024], [122918000.0, 0.0]], "asks": [[122968000.0, 0.0004], [122973000.0, 0.0069], [122980000.0, 0.0004], [122991000.0, 0.0852], [122992000.0, 0.0203], [122995000.0, 0.0023], [123000000.0, 0.1049], [123001000.0, 0.0001], [123003000.0, 0.0081], [123004000.0, 0.0001]]},
{"timestamp": "1743933297851", "bids": [[122960000.0, 0.1505], [122956000.0, 0.0], [122950000.0, 0.0057], [122949000.0, 0.0002], [122944000.0, 0.003], [122940000.0, 0.0], [122931000.0, 0.0], [122930000.0, 0.0], [122926000.0, 0.0024], [122918000.0, 0.0]], "asks": [[122968000.0, 0.0004], [122973000.0, 0.0069], [122980000.0, 0.0004], [122986000.0, 0.0852], [122991000.0, 0.1363], [122992000.0, 0.0203], [122995000.0, 0.0023], [123000000.0, 0.1049], [123001000.0, 0.0001], [123003000.0, 0.0081]]},
{"timestamp": "1743933298350", "bids": [[122960000.0, 0.1505], [122956000.0, 0.0], [122950000.0, 0.0057], [122949000.0, 0.0002], [122944000.0, 0.003], [122940000.0, 0.0], [122931000.0, 0.0], [122930000.0, 0.0], [122926000.0, 0.0024], [122918000.0, 0.0]], "asks": [[122968000.0, 0.0004], [122973000.0, 0.0069], [122980000.0, 0.0004], [122984000.0, 0.0852], [122991000.0, 0.1363], [122992000.0, 0.0203], [122994000.0, 0.0023], [123000000.0, 0.1049], [123001000.0, 0.0001], [123003000.0, 0.0081]]},
{"timestamp": "1743933298892", "bids": [[122960000.0, 0.1505], [122956000.0, 0.0], [122950000.0, 0.0057], [122949000.0, 0.0002], [122944000.0, 0.003], [122940000.0, 0.0], [122931000.0, 0.0], [122930000.0, 0.0], [122926000.0, 0.0024], [122918000.0, 0.0]], "asks": [[122968000.0, 0.0004], [122973000.0, 0.0069], [122980000.0, 0.0004], [122992000.0, 0.0203], [122994000.0, 0.0023], [123000000.0, 0.1049], [123001000.0, 0.0001], [123003000.0, 0.0081], [123004000.0, 0.0001], [123005000.0, 0.0081]]},
{"timestamp": "1743933299399", "bids": [[122960000.0, 0.1505], [122956000.0, 0.0], [122950000.0, 0.0057], [122949000.0, 0.0002], [122944000.0, 0.003], [122940000.0, 0.0], [122931000.0, 0.0], [122930000.0, 0.0], [122926000.0, 0.0024], [122918000.0, 0.0]], "asks": [[122967000.0, 0.0975], [122968000.0, 0.0004], [122973000.0, 0.0069], [122980000.0, 0.0004], [122991000.0, 0.1363], [122992000.0, 0.0203], [122994000.0, 0.0023], [123000000.0, 0.1049], [123001000.0, 0.0001], [123003000.0, 0.0081]]},
{"timestamp": "1743933299927", "bids": [[122960000.0, 0.1505], [122956000.0, 0.0], [122950000.0, 0.0057], [122949000.0, 0.0002], [122944000.0, 0.003], [122940000.0, 0.0], [122931000.0, 0.0], [122930000.0, 0.0], [122926000.0, 0.0024], [122918000.0, 0.0]], "asks": [[122968000.0, 0.0004], [122973000.0, 0.0069], [122980000.0, 0.0004], [122989000.0, 0.1363], [122990000.0, 0.0852], [122992000.0, 0.0203], [122994000.0, 0.0023], [123000000.0, 0.1049], [123001000.0, 0.0001], [123003000.0, 0.0081]]},
{"timestamp": "1743933300439", "bids": [[122960000.0, 0.1505], [122956000.0, 0.0], [122950000.0, 0.0057], [122949000.0, 0.0002], [122944000.0, 0.003], [122940000.0, 0.0], [122931000.0, 0.0], [122930000.0, 0.0], [122926000.0, 0.0024], [122918000.0, 0.0]], "asks": [[122968000.0, 0.0004], [122973000.0, 0.0069], [122980000.0, 0.0004], [122988000.0, 0.0852], [122992000.0, 0.0203], [122994000.0, 0.0023], [123000000.0, 0.1049], [123001000.0, 0.0001], [123003000.0, 0.0081], [123004000.0, 0.0001]]},
{"timestamp": "1743933300949", "bids": [[122960000.0, 0.1505], [122956000.0, 0.0], [122950000.0, 0.0057], [122949000.0, 0.0002], [122944000.0, 0.003], [122940000.0, 0.0], [122931000.0, 0.0], [122930000.0, 0.0], [122926000.0, 0.0024], [122918000.0, 0.0]], "asks": [[122968000.0, 0.0004], [122973000.0, 0.0069], [122980000.0, 0.0004], [122991000.0, 0.0852], [122992000.0, 0.0203], [122994000.0, 0.0023], [123000000.0, 0.1049], [123001000.0, 0.0001], [123003000.0, 0.0081], [123004000.0, 0.0001]]},
{"timestamp": "1743933301441", "bids": [[122960000.0, 0.1505], [122956000.0, 0.0], [122950000.0, 0.0057], [122949000.0, 0.0002], [122944000.0, 0.003], [122940000.0, 0.0], [122931000.0, 0.0], [122930000.0, 0.0], [122926000.0, 0.0024], [122918000.0, 0.0]], "asks": [[122968000.0, 0.0004], [122973000.0, 0.0069], [122980000.0, 0.0004], [122985000.0, 0.1363], [122991000.0, 0.0852], [122992000.0, 0.0203], [122994000.0, 0.0023], [123000000.0, 0.1049], [123001000.0, 0.0001], [123003000.0, 0.0081]]},
{"timestamp": "1743933301979", "bids": [[122960000.0, 0.1419], [122956000.0, 0.0], [122950000.0, 0.0057], [122949000.0, 0.0002], [122944000.0, 0.003], [122940000.0, 0.0], [122931000.0, 0.0], [122930000.0, 0.0], [122926000.0, 0.0024], [122918000.0, 0.0]], "asks": [[122968000.0, 0.0004], [122973000.0, 0.0069], [122980000.0, 0.0004], [122984000.0, 0.0852], [122989000.0, 0.1363], [122992000.0, 0.0203], [122994000.0, 0.0023], [123000000.0, 0.1049], [123001000.0, 0.0001], [123003000.0, 0.0081]]},
{"timestamp": "1743933302458", "bids": [[122960000.0, 0.1419], [122956000.0, 0.0], [122950000.0, 0.0057], [122949000.0, 0.0002], [122944000.0, 0.003], [122940000.0, 0.0], [122931000.0, 0.0], [122930000.0, 0.0], [122926000.0, 0.0024], [122918000.0, 0.0]], "asks": [[122968000.0, 0.0004], [122973000.0, 0.0069], [122980000.0, 0.0004], [122988000.0, 0.085], [122992000.0, 0.0203], [122994000.0, 0.0023], [123000000.0, 0.1049], [123001000.0, 0.0001], [123003000.0, 0.0081], [123004000.0, 0.0001]]},
{"timestamp": "1743933302990", "bids": [[122960000.0, 0.1419], [122956000.0, 0.0], [122950000.0, 0.0057], [122949000.0, 0.0002], [122944000.0, 0.003], [122940000.0, 0.0], [122931000.0, 0.0], [122930000.0, 0.0], [122926000.0, 0.0024], [122918000.0, 0.0]], "asks": [[122968000.0, 0.0004], [122973000.0, 0.0069], [122980000.0, 0.0004], [122992000.0, 0.0203], [122994000.0, 0.0023], [123000000.0, 0.1049], [123001000.0, 0.0001], [123003000.0, 0.0081], [123004000.0, 0.0001], [123005000.0, 0.0081]]},
{"timestamp": "1743933303487", "bids": [[122960000.0, 0.1419], [122956000.0, 0.0], [122950000.0, 0.0057], [122949000.0, 0.0002], [122944000.0, 0.003], [122940000.0, 0.0], [122931000.0, 0.0], [122930000.0, 0.0], [122926000.0, 0.0024], [122918000.0, 0.0]], "asks": [[122968000.0, 0.0004], [122973000.0, 0.0069], [122980000.0, 0.0004], [122991000.0, 0.221], [122992000.0, 0.0203], [122994000.0, 0.0023], [123000000.0, 0.1049], [123001000.0, 0.0001], [123003000.0, 0.0081], [123004000.0, 0.0001]]},
{"timestamp": "1743933304032", "bids": [[122960000.0, 0.1419], [122956000.0, 0.0], [122950000.0, 0.0057], [122949000.0, 0.0002], [122944000.0, 0.003], [122940000.0, 0.0], [122931000.0, 0.0], [122930000.0, 0.0], [122926000.0, 0.0024], [122918000.0, 0.0]], "asks": [[122968000.0, 0.0004], [122973000.0, 0.0069], [122980000.0, 0.0004], [122986000.0, 0.085], [122988000.0, 0.136], [122992000.0, 0.0203], [122994000.0, 0.0023], [123000000.0, 0.1049], [123001000.0, 0.0001], [123003000.0, 0.0081]]},
{"timestamp": "1743933304535", "bids": [[122960000.0, 0.1419], [122956000.0, 0.0], [122950000.0, 0.0057], [122949000.0, 0.0002], [122944000.0, 0.003], [122940000.0, 0.0], [122931000.0, 0.0], [122930000.0, 0.0], [122926000.0, 0.0024], [122918000.0, 0.0]], "asks": [[122968000.0, 0.0004], [122973000.0, 0.0069], [122980000.0, 0.0004], [122985000.0, 0.136], [122992000.0, 0.0203], [122994000.0, 0.0023], [123000000.0, 0.1049], [123001000.0, 0.0001], [123003000.0, 0.0081], [123004000.0, 0.0001]]},
{"timestamp": "1743933305055", "bids": [[122960000.0, 0.1419], [122956000.0, 0.0], [122950000.0, 0.0057], [122949000.0, 0.0002], [122944000.0, 0.003], [122940000.0, 0.0], [122931000.0, 0.0], [122930000.0, 0.0], [122926000.0, 0.0024], [122918000.0, 0.0]], "asks": [[122968000.0, 0.0004], [122973000.0, 0.0069], [122980000.0, 0.0004], [122991000.0, 0.136], [122994000.0, 0.0023], [123000000.0, 0.1049], [123001000.0, 0.0001], [123003000.0, 0.0081], [123004000.0, 0.0001], [123005000.0, 0.0081]]},
{"timestamp": "1743933305566", "bids": [[122960000.0, 0.1419], [122956000.0, 0.0], [122950000.0, 0.0057], [122949000.0, 0.0002], [122944000.0, 0.003], [122940000.0, 0.0], [122931000.0, 0.0], [122930000.0, 0.0], [122926000.0, 0.0024], [122920000.0, 0.0156]], "asks": [[122968000.0, 0.0004], [122973000.0, 0.0069], [122980000.0, 0.0004], [122994000.0, 0.0023], [122996000.0, 0.0069], [122999000.0, 0.136], [123000000.0, 0.1049], [123001000.0, 0.0001], [123002000.0, 0.0203], [123003000.0, 0.0081]]},
{"timestamp": "1743933306051", "bids": [[122960000.0, 0.1419], [122956000.0, 0.0], [122950000.0, 0.0057], [122949000.0, 0.0002], [122944000.0, 0.003], [122940000.0, 0.0], [122931000.0, 0.0], [122930000.0, 0.0], [122926000.0, 0.0024], [122920000.0, 0.0156]], "asks": [[122968000.0, 0.0004], [122973000.0, 0.0069], [122980000.0, 0.0004], [122994000.0, 0.0023], [122995000.0, 0.085], [122996000.0, 0.0069], [122999000.0, 0.136], [123000000.0, 0.1049], [123001000.0, 0.0001], [123002000.0, 0.0203]]},
{"timestamp": "1743933306565", "bids": [[122960000.0, 0.1419], [122956000.0, 0.0], [122950000.0, 0.0057], [122949000.0, 0.0002], [122944000.0, 0.003], [122940000.0, 0.0], [122931000.0, 0.0], [122930000.0, 0.0], [122926000.0, 0.0024], [122920000.0, 0.0156]], "asks": [[122968000.0, 0.0004], [122973000.0, 0.0069], [122980000.0, 0.0004], [122994000.0, 0.1383], [122995000.0, 0.085], [123000000.0, 0.1049], [123001000.0, 0.0001], [123002000.0, 0.0203], [123003000.0, 0.0081], [123004000.0, 0.0001]]},
{"timestamp": "1743933307078", "bids": [[122960000.0, 0.1419], [122956000.0, 0.0], [122950000.0, 0.0057], [122949000.0, 0.0002], [122944000.0, 0.003], [122940000.0, 0.0], [122931000.0, 0.0], [122930000.0, 0.0], [122926000.0, 0.0024], [122920000.0, 0.0156]], "asks": [[122968000.0, 0.0004], [122973000.0, 0.0069], [122980000.0, 0.0004], [122986000.0, 0.085], [122994000.0, 0.0023], [122999000.0, 0.1429], [123000000.0, 0.1049], [123001000.0, 0.0001], [123002000.0, 0.0203], [123003000.0, 0.0081]]},
{"timestamp": "1743933307612", "bids": [[122960000.0, 0.1419], [122956000.0, 0.0], [122950000.0, 0.0057], [122949000.0, 0.0002], [122944000.0, 0.003], [122940000.0, 0.0], [122931000.0, 0.0], [122930000.0, 0.0], [122926000.0, 0.0024], [122920000.0, 0.0156]], "asks": [[122968000.0, 0.0004], [122973000.0, 0.0069], [122980000.0, 0.0004], [122992000.0, 0.136], [122994000.0, 0.0023], [122998000.0, 0.085], [122999000.0, 0.0069], [123000000.0, 0.1049], [123001000.0, 0.0001], [123002000.0, 0.0203]]},
{"timestamp": "1743933308105", "bids": [[122960000.0, 0.1419], [122956000.0, 0.0], [122950000.0, 0.0057], [122949000.0, 0.0002], [122944000.0, 0.003], [122940000.0, 0.0], [122931000.0, 0.0], [122930000.0, 0.0], [122926000.0, 0.0024], [122920000.0, 0.0156]], "asks": [[122968000.0, 0.0004], [122973000.0, 0.0069], [122980000.0, 0.0004], [122991000.0, 0.085], [122994000.0, 0.0023], [122999000.0, 0.1429], [123000000.0, 0.1049], [123001000.0, 0.0001], [123002000.0, 0.0203], [123003000.0, 0.0081]]},
{"timestamp": "1743933308629", "bids": [[122960000.0, 0.1419], [122956000.0, 0.0], [122950000.0, 0.0057], [122949000.0, 0.0002], [122944000.0, 0.003], [122940000.0, 0.0], [122931000.0, 0.0], [122930000.0, 0.0], [122926000.0, 0.0024], [122920000.0, 0.0156]], "asks": [[122968000.0, 0.0004], [122973000.0, 0.0069], [122980000.0, 0.0004], [122994000.0, 0.0023], [122997000.0, 0.136], [122998000.0, 0.085], [122999000.0, 0.0069], [123000000.0, 0.1049], [123001000.0, 0.0001], [123002000.0, 0.0203]]},
{"timestamp": "1743933309149", "bids": [[122960000.0, 0.1419], [122956000.0, 0.0], [122950000.0, 0.0057], [122949000.0, 0.0002], [122944000.0, 0.003], [122940000.0, 0.0], [122931000.0, 0.0], [122930000.0, 0.0], [122926000.0, 0.0024], [122920000.0, 0.0156]], "asks": [[122968000.0, 0.0004], [122973000.0, 0.0069], [122980000.0, 0.0004], [122994000.0, 0.0023], [122996000.0, 0.085], [122997000.0, 0.136], [122999000.0, 0.0069], [123000000.0, 0.1049], [123001000.0, 0.0001], [123002000.0, 0.0203]]},
{"timestamp": "1743933309635", "bids": [[122960000.0, 0.1419], [122956000.0, 0.0], [122950000.0, 0.0057], [122949000.0, 0.0002], [122944000.0, 0.003], [122940000.0, 0.0], [122931000.0, 0.0], [122930000.0, 0.0], [122926000.0, 0.0024], [122920000.0, 0.0156]], "asks": [[122968000.0, 0.0004], [122973000.0, 0.0069], [122980000.0, 0.0004], [122994000.0, 0.0023], [122995000.0, 0.136], [122999000.0, 0.0069], [123000000.0, 0.1049], [123001000.0, 0.0001], [123002000.0, 0.0203], [123003000.0, 0.0081]]},
{"timestamp": "1743933310165", "bids": [[122960000.0, 0.1419], [122956000.0, 0.0], [122950000.0, 0.0057], [122949000.0, 0.0002], [122944000.0, 0.003], [122940000.0, 0.0], [122931000.0, 0.0], [122930000.0, 0.0], [122926000.0, 0.0024], [122920000.0, 0.0156]], "asks": [[122968000.0, 0.0004], [122973000.0, 0.0069], [122980000.0, 0.0004], [122993000.0, 0.136], [122994000.0, 0.0023], [122998000.0, 0.085], [122999000.0, 0.0069], [123000000.0, 0.1049], [123001000.0, 0.0001], [123002000.0, 0.0203]]},
{"timestamp": "1743933310671", "bids": [[122960000.0, 0.1419], [122956000.0, 0.0], [122950000.0, 0.0057], [122949000.0, 0.0002], [122944000.0, 0.003], [122940000.0, 0.0], [122931000.0, 0.0], [122930000.0, 0.0], [122926000.0, 0.0024], [122920000.0, 0.0156]], "asks": [[122968000.0, 0.0004], [122973000.0, 0.0069], [122980000.0, 0.0004], [122994000.0, 0.0023], [122997000.0, 0.136], [122999000.0, 0.0069], [123000000.0, 0.1049], [123001000.0, 0.0001], [123002000.0, 0.0203], [123003000.0, 0.0081]]},
{"timestamp": "1743933311203", "bids": [[122960000.0, 0.1419], [122956000.0, 0.0], [122950000.0, 0.0057], [122949000.0, 0.0002], [122944000.0, 0.003], [122940000.0, 0.0], [122931000.0, 0.0], [122930000.0, 0.0], [122926000.0, 0.0024], [122920000.0, 0.0156]], "asks": [[122968000.0, 0.0004], [122973000.0, 0.0069], [122980000.0, 0.0004], [122994000.0, 0.0023], [122996000.0, 0.085], [122999000.0, 0.1429], [123000000.0, 0.1049], [123001000.0, 0.0001], [123002000.0, 0.0203], [123003000.0, 0.0081]]},
{"timestamp": "1743933311709", "bids": [[122960000.0, 0.1419], [122956000.0, 0.0], [122950000.0, 0.0057], [122949000.0, 0.0002], [122944000.0, 0.003], [122940000.0, 0.0], [122931000.0, 0.0], [122930000.0, 0.0], [122926000.0, 0.0024], [122920000.0, 0.0156]], "asks": [[122968000.0, 0.0004], [122973000.0, 0.0069], [122980000.0, 0.0004], [122994000.0, 0.0023], [122998000.0, 0.085], [122999000.0, 0.0069], [123000000.0, 0.1049], [123001000.0, 0.0001], [123002000.0, 0.0203], [123003000.0, 0.0081]]},
{"timestamp": "1743933312214", "bids": [[122960000.0, 0.1419], [122956000.0, 0.0], [122950000.0, 0.0057], [122949000.0, 0.0002], [122944000.0, 0.003], [122940000.0, 0.0], [122931000.0, 0.0], [122930000.0, 0.0], [122926000.0, 0.0024], [122920000.0, 0.0156]], "asks": [[122968000.0, 0.0004], [122973000.0, 0.0069], [122980000.0, 0.0004], [122994000.0, 0.0023], [122997000.0, 0.136], [122999000.0, 0.0069], [123000000.0, 0.1049], [123001000.0, 0.0001], [123002000.0, 0.0203], [123003000.0, 0.0081]]},
{"timestamp": "1743933312700", "bids": [[122960000.0, 0.1419], [122956000.0, 0.0], [122950000.0, 0.0057], [122949000.0, 0.0002], [122944000.0, 0.003], [122940000.0, 0.0], [122931000.0, 0.0], [122930000.0, 0.0], [122926000.0, 0.0024], [122920000.0, 0.0156]], "asks": [[122968000.0, 0.0004], [122973000.0, 0.0069], [122980000.0, 0.0004], [122994000.0, 0.0023], [122998000.0, 0.085], [122999000.0, 0.1429], [123000000.0, 0.1049], [123001000.0, 0.0001], [123002000.0, 0.0203], [123003000.0, 0.0081]]},
{"timestamp": "1743933313227", "bids": [[122960000.0, 0.1419], [122956000.0, 0.0], [122950000.0, 0.0057], [122949000.0, 0.0002], [122944000.0, 0.003], [122940000.0, 0.0], [122931000.0, 0.0], [122930000.0, 0.0], [122926000.0, 0.0024], [122920000.0, 0.0156]], "asks": [[122968000.0, 0.0004], [122973000.0, 0.0069], [122980000.0, 0.0004], [122994000.0, 0.0023], [122997000.0, 0.136], [122998000.0, 0.085], [122999000.0, 0.0069], [123000000.0, 0.1049], [123001000.0, 0.0001], [123002000.0, 0.0203]]},
{"timestamp": "1743933313758", "bids": [[122960000.0, 0.1419], [122956000.0, 0.0], [122950000.0, 0.0057], [122949000.0, 0.0002], [122944000.0, 0.003], [122940000.0, 0.0], [122931000.0, 0.0], [122930000.0, 0.0], [122926000.0, 0.0024], [122920000.0, 0.0156]], "asks": [[122968000.0, 0.0004], [122973000.0, 0.0069], [122980000.0, 0.0004], [122994000.0, 0.0023], [122996000.0, 0.085], [122997000.0, 0.136], [122999000.0, 0.0069], [123000000.0, 0.1049], [123001000.0, 0.0001], [123002000.0, 0.0203]]},
{"timestamp": "1743933314242", "bids": [[122960000.0, 0.1419], [122956000.0, 0.0], [122950000.0, 0.0057], [122949000.0, 0.0002], [122944000.0, 0.003], [122940000.0, 0.0], [122931000.0, 0.0], [122930000.0, 0.0], [122926000.0, 0.0024], [122920000.0, 0.0156]], "asks": [[122968000.0, 0.0004], [122973000.0, 0.0069], [122980000.0, 0.0004], [122994000.0, 0.0023], [122995000.0, 0.136], [122996000.0, 0.085], [122999000.0, 0.0069], [123000000.0, 0.1049], [123001000.0, 0.0001], [123002000.0, 0.0203]]},
{"timestamp": "1743933314750", "bids": [[122960000.0, 0.1419], [122956000.0, 0.0], [122950000.0, 0.0057], [122949000.0, 0.0002], [122944000.0, 0.003], [122940000.0, 0.0], [122931000.0, 0.0], [122930000.0, 0.0], [122926000.0, 0.0024], [122920000.0, 0.0156]], "asks": [[122968000.0, 0.0004], [122973000.0, 0.0069], [122980000.0, 0.0004], [122993000.0, 0.136], [122994000.0, 0.0873], [123000000.0, 0.1049], [123001000.0, 0.0001], [123002000.0, 0.0203], [123003000.0, 0.0081], [123004000.0, 0.0001]]},
{"timestamp": "1743933315259", "bids": [[122960000.0, 0.1419], [122956000.0, 0.0], [122950000.0, 0.0057], [122949000.0, 0.0002], [122944000.0, 0.003], [122940000.0, 0.0], [122931000.0, 0.0], [122930000.0, 0.0], [122926000.0, 0.0024], [122920000.0, 0.0156]], "asks": [[122968000.0, 0.0004], [122973000.0, 0.0069], [122980000.0, 0.0004], [122992000.0, 0.085], [122993000.0, 0.136], [122994000.0, 0.0023], [123000000.0, 0.1049], [123001000.0, 0.0001], [123002000.0, 0.0203], [123003000.0, 0.0081]]},
{"timestamp": "1743933315770", "bids": [[122960000.0, 0.1419], [122956000.0, 0.0], [122950000.0, 0.0057], [122949000.0, 0.0002], [122944000.0, 0.003], [122940000.0, 0.0], [122931000.0, 0.0], [122930000.0, 0.0], [122926000.0, 0.0024], [122920000.0, 0.0156]], "asks": [[122968000.0, 0.0004], [122973000.0, 0.0069], [122980000.0, 0.0004], [122990000.0, 0.085], [122991000.0, 0.136], [122994000.0, 0.0023], [123000000.0, 0.1049], [123001000.0, 0.0001], [123002000.0, 0.0203], [123003000.0, 0.0081]]},
{"timestamp": "1743933316278", "bids": [[122960000.0, 0.1419], [122956000.0, 0.0], [122950000.0, 0.0057], [122949000.0, 0.0002], [122944000.0, 0.003], [122940000.0, 0.0], [122931000.0, 0.0], [122930000.0, 0.0], [122926000.0, 0.0024], [122920000.0, 0.0156]], "asks": [[122968000.0, 0.0004], [122973000.0, 0.0069], [122980000.0, 0.0004], [122989000.0, 0.136], [122990000.0, 0.085], [122994000.0, 0.0023], [123000000.0, 0.1049], [123001000.0, 0.0001], [123002000.0, 0.0203], [123003000.0, 0.0081]]},
{"timestamp": "1743933316785", "bids": [[122960000.0, 0.1419], [122956000.0, 0.0], [122950000.0, 0.0057], [122949000.0, 0.0002], [122944000.0, 0.003], [122940000.0, 0.0], [122931000.0, 0.0], [122930000.0, 0.0], [122926000.0, 0.0024], [122920000.0, 0.0156]], "asks": [[122968000.0, 0.0004], [122973000.0, 0.0069], [122980000.0, 0.0004], [122988000.0, 0.085], [122989000.0, 0.136], [122994000.0, 0.0046], [123000000.0, 0.1049], [123001000.0, 0.0001], [123002000.0, 0.0203], [123003000.0, 0.0081]]},
{"timestamp": "1743933317298", "bids": [[122960000.0, 0.1419], [122956000.0, 0.0], [122950000.0, 0.0057], [122949000.0, 0.0002], [122944000.0, 0.003], [122940000.0, 0.0], [122931000.0, 0.0], [122930000.0, 0.0], [122926000.0, 0.0024], [122920000.0, 0.0156]], "asks": [[122968000.0, 0.0004], [122973000.0, 0.0069], [122980000.0, 0.0004], [122987000.0, 0.136], [122994000.0, 0.0023], [123000000.0, 0.1049], [123001000.0, 0.0001], [123002000.0, 0.0203], [123003000.0, 0.0081], [123004000.0, 0.007]]},
{"timestamp": "1743933317828", "bids": [[122960000.0, 0.1419], [122956000.0, 0.0], [122950000.0, 0.0057], [122949000.0, 0.0002], [122944000.0, 0.003], [122940000.0, 0.0], [122931000.0, 0.0], [122930000.0, 0.0], [122926000.0, 0.0024], [122920000.0, 0.0156]], "asks": [[122968000.0, 0.0004], [122973000.0, 0.0069], [122980000.0, 0.0004], [122986000.0, 0.085], [122994000.0, 0.0023], [122999000.0, 0.136], [123000000.0, 0.1049], [123001000.0, 0.0001], [123002000.0, 0.0203], [123003000.0, 0.0081]]},
{"timestamp": "1743933318319", "bids": [[122960000.0, 0.1419], [122956000.0, 0.0], [122950000.0, 0.0057], [122949000.0, 0.0002], [122944000.0, 0.003], [122940000.0, 0.0], [122931000.0, 0.0], [122930000.0, 0.0], [122926000.0, 0.0024], [122920000.0, 0.0156]], "asks": [[122968000.0, 0.0004], [122973000.0, 0.0069], [122980000.0, 0.0004], [122985000.0, 0.136], [122994000.0, 0.0023], [122998000.0, 0.085], [123000000.0, 0.1049], [123001000.0, 0.0001], [123002000.0, 0.0203], [123003000.0, 0.0081]]},
{"timestamp": "1743933318859", "bids": [[122960000.0, 0.1419], [122956000.0, 0.0], [122950000.0, 0.0057], [122949000.0, 0.0002], [122944000.0, 0.003], [122940000.0, 0.0], [122931000.0, 0.0], [122930000.0, 0.0], [122926000.0, 0.0024], [122920000.0, 0.0156]], "asks": [[122968000.0, 0.0004], [122973000.0, 0.0069], [122980000.0, 0.0004], [122983000.0, 0.136], [122994000.0, 0.0023], [122996000.0, 0.085], [123000000.0, 0.1049], [123001000.0, 0.0001], [123002000.0, 0.0203], [123003000.0, 0.0081]]},
{"timestamp": "1743933319356", "bids": [[122960000.0, 0.1419], [122956000.0, 0.0], [122950000.0, 0.0057], [122949000.0, 0.0002], [122944000.0, 0.003], [122940000.0, 0.0], [122931000.0, 0.0], [122930000.0, 0.0], [122926000.0, 0.0024], [122920000.0, 0.0156]], "asks": [[122968000.0, 0.0004], [122973000.0, 0.0069], [122980000.0, 0.0004], [122994000.0, 0.0023], [122999000.0, 0.221], [123000000.0, 0.1049], [123001000.0, 0.0001], [123002000.0, 0.0203], [123003000.0, 0.0081], [123004000.0, 0.0001]]},
{"timestamp": "1743933319900", "bids": [[122960000.0, 0.1419], [122956000.0, 0.0], [122950000.0, 0.0057], [122949000.0, 0.0002], [122944000.0, 0.003], [122940000.0, 0.0], [122931000.0, 0.0], [122930000.0, 0.0], [122926000.0, 0.0024], [122920000.0, 0.0156]], "asks": [[122968000.0, 0.0004], [122973000.0, 0.0069], [122980000.0, 0.0004], [122993000.0, 0.0069], [122994000.0, 0.0023], [122998000.0, 0.085], [123000000.0, 0.1049], [123001000.0, 0.0001], [123002000.0, 0.0203], [123003000.0, 0.0081]]},
{"timestamp": "1743933320408", "bids": [[122960000.0, 0.1419], [122956000.0, 0.0], [122950000.0, 0.0057], [122949000.0, 0.0002], [122944000.0, 0.003], [122940000.0, 0.0], [122931000.0, 0.0], [122930000.0, 0.0], [122926000.0, 0.0024], [122918000.0, 0.0]], "asks": [[122968000.0, 0.0004], [122973000.0, 0.0069], [122980000.0, 0.0004], [122985000.0, 0.0247], [122993000.0, 0.0919], [122994000.0, 0.0023], [122998000.0, 0.085], [123000000.0, 0.1049], [123001000.0, 0.0001], [123003000.0, 0.0081]]},
{"timestamp": "1743933320911", "bids": [[122960000.0, 0.1419], [122956000.0, 0.0], [122950000.0, 0.0057], [122949000.0, 0.0002], [122944000.0, 0.003], [122940000.0, 0.0], [122931000.0, 0.0], [122930000.0, 0.0], [122926000.0, 0.0024], [122918000.0, 0.0]], "asks": [[122968000.0, 0.0004], [122973000.0, 0.0213], [122980000.0, 0.0004], [122981000.0, 0.028], [122984000.0, 0.136], [122985000.0, 0.0247], [122993000.0, 0.085], [122994000.0, 0.0023], [122997000.0, 0.0203], [122999000.0, 0.136]]},
{"timestamp": "1743933321397", "bids": [[122960000.0, 0.1419], [122956000.0, 0.0], [122950000.0, 0.0057], [122949000.0, 0.0002], [122944000.0, 0.003], [122940000.0, 0.0], [122931000.0, 0.0], [122930000.0, 0.0], [122926000.0, 0.0024], [122918000.0, 0.0]], "asks": [[122968000.0, 0.0004], [122973000.0, 0.0213], [122980000.0, 0.0004], [122981000.0, 0.028], [122983000.0, 0.085], [122984000.0, 0.136], [122985000.0, 0.0247], [122991000.0, 0.0048], [122994000.0, 0.0023], [122997000.0, 0.0203]]},
{"timestamp": "1743933321914", "bids": [[122960000.0, 0.1419], [122956000.0, 0.0], [122950000.0, 0.0057], [122949000.0, 0.0002], [122944000.0, 0.003], [122940000.0, 0.0], [122931000.0, 0.0], [122930000.0, 0.0], [122926000.0, 0.0024], [122918000.0, 0.0]], "asks": [[122968000.0, 0.0004], [122973000.0, 0.0213], [122980000.0, 0.1364], [122981000.0, 0.028], [122983000.0, 0.085], [122985000.0, 0.0247], [122991000.0, 0.0048], [122994000.0, 0.0023], [122997000.0, 0.0203], [123000000.0, 0.1049]]},
{"timestamp": "1743933322439", "bids": [[122960000.0, 0.1419], [122956000.0, 0.0], [122950000.0, 0.0057], [122949000.0, 0.0002], [122944000.0, 0.003], [122940000.0, 0.0], [122931000.0, 0.0], [122930000.0, 0.0], [122926000.0, 0.0024], [122918000.0, 0.0]], "asks": [[122968000.0, 0.0004], [122973000.0, 0.0213], [122980000.0, 0.1364], [122981000.0, 0.028], [122985000.0, 0.0247], [122991000.0, 0.0048], [122994000.0, 0.0023], [122997000.0, 0.0203], [123000000.0, 0.1049], [123001000.0, 0.0001]]},
{"timestamp": "1743933322958", "bids": [[122960000.0, 0.1419], [122956000.0, 0.0], [122950000.0, 0.0057], [122949000.0, 0.0002], [122944000.0, 0.003], [122940000.0, 0.0], [122931000.0, 0.0], [122930000.0, 0.0], [122926000.0, 0.0024], [122918000.0, 0.0]], "asks": [[122968000.0, 0.0004], [122973000.0, 0.0213], [122980000.0, 0.1364], [122981000.0, 0.028], [122985000.0, 0.0247], [122991000.0, 0.0048], [122994000.0, 0.0023], [122997000.0, 0.0203], [123000000.0, 0.1049], [123001000.0, 0.0001]]},
{"timestamp": "1743933323485", "bids": [[122960000.0, 0.1419], [122956000.0, 0.0], [122950000.0, 0.0057], [122949000.0, 0.0002], [122944000.0, 0.003], [122940000.0, 0.0], [122931000.0, 0.0], [122930000.0, 0.0], [122926000.0, 0.0024], [122918000.0, 0.0]], "asks": [[122968000.0, 0.0004], [122973000.0, 0.0213], [122980000.0, 0.1364], [122981000.0, 0.028], [122985000.0, 0.0247], [122991000.0, 0.0048], [122993000.0, 0.0023], [122997000.0, 0.0203], [123000000.0, 0.1049], [123001000.0, 0.0001]]},
{"timestamp": "1743933323977", "bids": [[122960000.0, 0.1419], [122956000.0, 0.0], [122950000.0, 0.0057], [122949000.0, 0.0002], [122944000.0, 0.003], [122940000.0, 0.0], [122931000.0, 0.0], [122930000.0, 0.0], [122926000.0, 0.0024], [122918000.0, 0.0]], "asks": [[122968000.0, 0.0004], [122973000.0, 0.0213], [122980000.0, 0.0004], [122981000.0, 0.028], [122983000.0, 0.085], [122984000.0, 0.136], [122985000.0, 0.0247], [122991000.0, 0.0048], [122993000.0, 0.0023], [122997000.0, 0.0203]]},
{"timestamp": "1743933324482", "bids": [[122960000.0, 0.1419], [122956000.0, 0.0], [122950000.0, 0.0057], [122949000.0, 0.0002], [122944000.0, 0.003], [122940000.0, 0.0], [122931000.0, 0.0], [122930000.0, 0.0], [122926000.0, 0.0024], [122918000.0, 0.0]], "asks": [[122968000.0, 0.0004], [122973000.0, 0.0213], [122980000.0, 0.0004], [122981000.0, 0.028], [122983000.0, 0.085], [122985000.0, 0.0247], [122991000.0, 0.0048], [122993000.0, 0.0023], [122997000.0, 0.0203], [123000000.0, 0.1049]]},
{"timestamp": "1743933324986", "bids": [[122960000.0, 0.1419], [122956000.0, 0.0], [122950000.0, 0.0057], [122949000.0, 0.0002], [122944000.0, 0.003], [122940000.0, 0.0], [122931000.0, 0.0], [122930000.0, 0.0], [122926000.0, 0.0024], [122918000.0, 0.0]], "asks": [[122968000.0, 0.0004], [122973000.0, 0.0213], [122980000.0, 0.0004], [122981000.0, 0.028], [122982000.0, 0.136], [122985000.0, 0.0247], [122991000.0, 0.0048], [122993000.0, 0.0023], [122997000.0, 0.0203], [123000000.0, 0.1049]]},
{"timestamp": "1743933325495", "bids": [[122960000.0, 0.1419], [122956000.0, 0.0], [122950000.0, 0.0057], [122949000.0, 0.0002], [122944000.0, 0.003], [122940000.0, 0.0], [122931000.0, 0.0], [122930000.0, 0.0], [122926000.0, 0.0024], [122918000.0, 0.0]], "asks": [[122968000.0, 0.0004], [122973000.0, 0.0213], [122980000.0, 0.1364], [122981000.0, 0.028], [122985000.0, 0.0247], [122993000.0, 0.0023], [122997000.0, 0.0203], [123000000.0, 0.1262], [123001000.0, 0.0001], [123003000.0, 0.0081]]},
{"timestamp": "1743933326043", "bids": [[122960000.0, 0.1419], [122956000.0, 0.0], [122950000.0, 0.0057], [122949000.0, 0.0002], [122944000.0, 0.003], [122940000.0, 0.0], [122931000.0, 0.0], [122930000.0, 0.0], [122926000.0, 0.0024], [122918000.0, 0.0]], "asks": [[122968000.0, 0.0004], [122973000.0, 0.0213], [122980000.0, 0.1364], [122981000.0, 0.028], [122985000.0, 0.0247], [122993000.0, 0.0023], [122997000.0, 0.0203], [123000000.0, 0.1262], [123001000.0, 0.0001], [123003000.0, 0.0081]]},
{"timestamp": "1743933326547", "bids": [[122960000.0, 0.1419], [122956000.0, 0.0], [122950000.0, 0.0057], [122949000.0, 0.0002], [122944000.0, 0.003], [122940000.0, 0.0], [122931000.0, 0.0], [122930000.0, 0.0], [122926000.0, 0.0024], [122918000.0, 0.0]], "asks": [[122968000.0, 0.0004], [122973000.0, 0.0213], [122980000.0, 0.0004], [122981000.0, 0.028], [122984000.0, 0.136], [122985000.0, 0.0247], [122993000.0, 0.0023], [122997000.0, 0.0203], [123000000.0, 0.1262], [123001000.0, 0.0001]]},
{"timestamp": "1743933327054", "bids": [[122960000.0, 0.1419], [122956000.0, 0.0], [122950000.0, 0.0057], [122949000.0, 0.0002], [122944000.0, 0.003], [122940000.0, 0.0], [122931000.0, 0.0], [122930000.0, 0.0], [122926000.0, 0.0024], [122918000.0, 0.0]], "asks": [[122968000.0, 0.0004], [122973000.0, 0.0213], [122980000.0, 0.0004], [122981000.0, 0.028], [122983000.0, 0.085], [122985000.0, 0.0247], [122993000.0, 0.0023], [122997000.0, 0.0203], [123000000.0, 0.1262], [123001000.0, 0.0001]]},
{"timestamp": "1743933327534", "bids": [[122960000.0, 0.1419], [122956000.0, 0.0], [122950000.0, 0.0057], [122949000.0, 0.0002], [122944000.0, 0.003], [122940000.0, 0.0], [122931000.0, 0.0], [122930000.0, 0.0], [122926000.0, 0.0024], [122918000.0, 0.0]], "asks": [[122968000.0, 0.0004], [122973000.0, 0.0213], [122980000.0, 0.0004], [122981000.0, 0.028], [122985000.0, 0.0247], [122993000.0, 0.0023], [122997000.0, 0.0203], [123000000.0, 0.1262], [123001000.0, 0.0001], [123003000.0, 0.0081]]},
{"timestamp": "1743933328076", "bids": [[122960000.0, 0.1419], [122956000.0, 0.0], [122950000.0, 0.0057], [122949000.0, 0.0002], [122944000.0, 0.003], [122940000.0, 0.0], [122931000.0, 0.0], [122930000.0, 0.0], [122926000.0, 0.0024], [122918000.0, 0.0]], "asks": [[122968000.0, 0.0004], [122973000.0, 0.0213], [122980000.0, 0.0004], [122981000.0, 0.028], [122984000.0, 0.136], [122985000.0, 0.0247], [122993000.0, 0.0023], [122997000.0, 0.0203], [123000000.0, 0.1262], [123001000.0, 0.0001]]},
{"timestamp": "1743933328564", "bids": [[122960000.0, 0.1419], [122956000.0, 0.0], [122950000.0, 0.0057], [122949000.0, 0.0002], [122944000.0, 0.003], [122940000.0, 0.0], [122931000.0, 0.0], [122930000.0, 0.0], [122926000.0, 0.0024], [122918000.0, 0.0]], "asks": [[122968000.0, 0.0004], [122973000.0, 0.0213], [122980000.0, 0.0004], [122981000.0, 0.028], [122983000.0, 0.085], [122985000.0, 0.0247], [122993000.0, 0.0023], [122997000.0, 0.0203], [123000000.0, 0.1262], [123001000.0, 0.0001]]},
{"timestamp": "1743933329077", "bids": [[122960000.0, 0.1419], [122956000.0, 0.0], [122950000.0, 0.0057], [122949000.0, 0.0002], [122944000.0, 0.003], [122940000.0, 0.0], [122931000.0, 0.0], [122930000.0, 0.0], [122926000.0, 0.0024], [122918000.0, 0.0]], "asks": [[122968000.0, 0.0004], [122973000.0, 0.0213], [122980000.0, 0.0004], [122981000.0, 0.028], [122982000.0, 0.136], [122984000.0, 0.085], [122985000.0, 0.0247], [122993000.0, 0.0023], [122997000.0, 0.0203], [123000000.0, 0.1262]]},
{"timestamp": "1743933329588", "bids": [[122960000.0, 0.1419], [122956000.0, 0.0], [122950000.0, 0.0057], [122949000.0, 0.0002], [122944000.0, 0.003], [122940000.0, 0.0], [122931000.0, 0.0], [122930000.0, 0.0], [122926000.0, 0.0024], [122918000.0, 0.0]], "asks": [[122968000.0, 0.0004], [122973000.0, 0.0213], [122980000.0, 0.0004], [122981000.0, 0.028], [122983000.0, 0.136], [122984000.0, 0.085], [122985000.0, 0.0247], [122993000.0, 0.0023], [122997000.0, 0.0203], [123000000.0, 0.1049]]},
{"timestamp": "1743933330125", "bids": [[122960000.0, 0.1419], [122956000.0, 0.0], [122950000.0, 0.0057], [122949000.0, 0.0002], [122944000.0, 0.003], [122940000.0, 0.0], [122931000.0, 0.0], [122930000.0, 0.0], [122926000.0, 0.0024], [122918000.0, 0.0]], "asks": [[122968000.0, 0.0004], [122973000.0, 0.0213], [122980000.0, 0.0004], [122981000.0, 0.028], [122983000.0, 0.136], [122985000.0, 0.0247], [122993000.0, 0.0023], [122997000.0, 0.0203], [123000000.0, 0.1049], [123001000.0, 0.0001]]},
{"timestamp": "1743933330637", "bids": [[122960000.0, 0.1419], [122956000.0, 0.0], [122950000.0, 0.0057], [122949000.0, 0.0002], [122944000.0, 0.003], [122940000.0, 0.0], [122931000.0, 0.0], [122930000.0, 0.0], [122926000.0, 0.0024], [122918000.0, 0.0]], "asks": [[122968000.0, 0.0004], [122973000.0, 0.0213], [122980000.0, 0.0004], [122981000.0, 0.028], [122983000.0, 0.085], [122984000.0, 0.136], [122985000.0, 0.0247], [122993000.0, 0.0023], [122997000.0, 0.0203], [123000000.0, 0.1049]]},
{"timestamp": "1743933331120", "bids": [[122960000.0, 0.1419], [122956000.0, 0.0], [122950000.0, 0.0057], [122949000.0, 0.0002], [122944000.0, 0.003], [122940000.0, 0.0], [122931000.0, 0.0], [122930000.0, 0.0], [122926000.0, 0.0024], [122918000.0, 0.0]], "asks": [[122968000.0, 0.0004], [122973000.0, 0.0213], [122980000.0, 0.0004], [122981000.0, 0.028], [122983000.0, 0.085], [122985000.0, 0.0247], [122993000.0, 0.0023], [122997000.0, 0.0203], [123000000.0, 0.1049], [123001000.0, 0.0001]]},
{"timestamp": "1743933331645", "bids": [[122960000.0, 0.1419], [122956000.0, 0.0], [122950000.0, 0.0061], [122949000.0, 0.0002], [122944000.0, 0.003], [122940000.0, 0.0], [122931000.0, 0.0], [122930000.0, 0.0], [122926000.0, 0.0024], [122918000.0, 0.0]], "asks": [[122968000.0, 0.0004], [122973000.0, 0.0213], [122980000.0, 0.1364], [122981000.0, 0.028], [122984000.0, 0.085], [122985000.0, 0.0247], [122993000.0, 0.0023], [122997000.0, 0.0203], [123000000.0, 0.1049], [123001000.0, 0.0001]]},
{"timestamp": "1743933332143", "bids": [[122960000.0, 0.1419], [122956000.0, 0.0], [122950000.0, 0.0061], [122949000.0, 0.0002], [122944000.0, 0.003], [122940000.0, 0.0], [122931000.0, 0.0], [122930000.0, 0.0], [122926000.0, 0.0024], [122918000.0, 0.0]], "asks": [[122968000.0, 0.0004], [122973000.0, 0.0213], [122980000.0, 0.0004], [122981000.0, 0.028], [122983000.0, 0.136], [122985000.0, 0.0247], [122993000.0, 0.0023], [122997000.0, 0.0203], [123000000.0, 0.1049], [123001000.0, 0.0001]]},
{"timestamp": "1743933332684", "bids": [[122960000.0, 0.1419], [122956000.0, 0.0], [122950000.0, 0.0061], [122949000.0, 0.0002], [122944000.0, 0.003], [122940000.0, 0.0], [122931000.0, 0.0], [122930000.0, 0.0], [122926000.0, 0.0024], [122918000.0, 0.0]], "asks": [[122968000.0, 0.0004], [122973000.0, 0.0213], [122980000.0, 0.0004], [122981000.0, 0.028], [122985000.0, 0.0247], [122993000.0, 0.0023], [122997000.0, 0.0203], [123000000.0, 0.1049], [123001000.0, 0.0001], [123003000.0, 0.0081]]},
{"timestamp": "1743933333180", "bids": [[122960000.0, 0.1419], [122956000.0, 0.0], [122950000.0, 0.0061], [122949000.0, 0.0002], [122944000.0, 0.003], [122940000.0, 0.0], [122931000.0, 0.0], [122930000.0, 0.0], [122926000.0, 0.0024], [122918000.0, 0.0]], "asks": [[122968000.0, 0.0004], [122973000.0, 0.0006], [122980000.0, 0.1364], [122981000.0, 0.0091], [122982000.0, 0.0247], [122993000.0, 0.0023], [122994000.0, 0.0063], [122995000.0, 0.0203], [122996000.0, 0.085], [123000000.0, 0.1049]]},
{"timestamp": "1743933333698", "bids": [[122960000.0, 0.1419], [122956000.0, 0.0], [122950000.0, 0.0061], [122949000.0, 0.0002], [122944000.0, 0.003], [122940000.0, 0.0], [122931000.0, 0.0], [122930000.0, 0.0], [122926000.0, 0.0024], [122918000.0, 0.0]], "asks": [[122968000.0, 0.0004], [122973000.0, 0.0006], [122980000.0, 0.0004], [122981000.0, 0.1451], [122982000.0, 0.0247], [122993000.0, 0.0023], [122994000.0, 0.0063], [122995000.0, 0.0203], [122996000.0, 0.085], [123000000.0, 0.1049]]},
{"timestamp": "1743933334222", "bids": [[122960000.0, 0.1419], [122956000.0, 0.0], [122950000.0, 0.0061], [122949000.0, 0.0002], [122944000.0, 0.003], [122940000.0, 0.0], [122931000.0, 0.0], [122930000.0, 0.0], [122926000.0, 0.0024], [122918000.0, 0.0]], "asks": [[122968000.0, 0.0004], [122973000.0, 0.0006], [122980000.0, 0.0004], [122981000.0, 0.1451], [122982000.0, 0.0247], [122993000.0, 0.0023], [122994000.0, 0.0063], [122995000.0, 0.0203], [123000000.0, 0.1049], [123001000.0, 0.0001]]},
{"timestamp": "1743933334715", "bids": [[122960000.0, 0.1419], [122956000.0, 0.0], [122950000.0, 0.0061], [122949000.0, 0.0002], [122944000.0, 0.003], [122940000.0, 0.0], [122931000.0, 0.0], [122930000.0, 0.0], [122926000.0, 0.0024], [122918000.0, 0.0]], "asks": [[122968000.0, 0.0004], [122973000.0, 0.0006], [122980000.0, 0.0004], [122981000.0, 0.1451], [122982000.0, 0.0247], [122993000.0, 0.0023], [122994000.0, 0.0063], [122995000.0, 0.0203], [123000000.0, 0.1049], [123001000.0, 0.0001]]},
{"timestamp": "1743933335254", "bids": [[122960000.0, 0.1419], [122956000.0, 0.0], [122950000.0, 0.0061], [122949000.0, 0.0002], [122944000.0, 0.003], [122940000.0, 0.0], [122931000.0, 0.0], [122930000.0, 0.0], [122926000.0, 0.0024], [122918000.0, 0.0]], "asks": [[122968000.0, 0.0004], [122973000.0, 0.0006], [122980000.0, 0.0004], [122981000.0, 0.1451], [122982000.0, 0.0247], [122993000.0, 0.0023], [122994000.0, 0.0063], [122995000.0, 0.0203], [123000000.0, 0.1049], [123001000.0, 0.0001]]},
{"timestamp": "1743933335757", "bids": [[122960000.0, 0.1419], [122956000.0, 0.0], [122950000.0, 0.0061], [122949000.0, 0.0002], [122944000.0, 0.003], [122940000.0, 0.0], [122931000.0, 0.0], [122930000.0, 0.0], [122926000.0, 0.0024], [122918000.0, 0.0]], "asks": [[122968000.0, 0.0004], [122973000.0, 0.0006], [122979000.0, 0.136], [122980000.0, 0.0004], [122981000.0, 0.0091], [122982000.0, 0.0247], [122993000.0, 0.0023], [122994000.0, 0.0063], [122995000.0, 0.0203], [123000000.0, 0.1049]]},
{"timestamp": "1743933336244", "bids": [[122960000.0, 0.1419], [122956000.0, 0.0], [122950000.0, 0.0061], [122949000.0, 0.0002], [122944000.0, 0.003], [122940000.0, 0.0], [122931000.0, 0.0], [122930000.0, 0.0], [122926000.0, 0.0024], [122918000.0, 0.0]], "asks": [[122968000.0, 0.0004], [122973000.0, 0.0006], [122980000.0, 0.0004], [122981000.0, 0.1451], [122982000.0, 0.0247], [122993000.0, 0.0873], [122994000.0, 0.0063], [122995000.0, 0.0203], [123000000.0, 0.1049], [123001000.0, 0.0001]]},
{"timestamp": "1743933336782", "bids": [[122960000.0, 0.1419], [122956000.0, 0.0], [122950000.0, 0.0061], [122949000.0, 0.0002], [122944000.0, 0.003], [122940000.0, 0.0], [122931000.0, 0.0], [122930000.0, 0.0], [122926000.0, 0.0024], [122918000.0, 0.0]], "asks": [[122968000.0, 0.0004], [122973000.0, 0.0006], [122980000.0, 0.0004], [122981000.0, 0.1451], [122982000.0, 0.0247], [122993000.0, 0.0023], [122994000.0, 0.0063], [122995000.0, 0.0203], [123000000.0, 0.1049], [123001000.0, 0.0001]]},
{"timestamp": "1743933337298", "bids": [[122960000.0, 0.1419], [122956000.0, 0.0], [122950000.0, 0.0061], [122949000.0, 0.0002], [122944000.0, 0.003], [122940000.0, 0.0], [122931000.0, 0.0], [122930000.0, 0.0], [122926000.0, 0.0024], [122918000.0, 0.0]], "asks": [[122968000.0, 0.0004], [122973000.0, 0.0006], [122980000.0, 0.0004], [122981000.0, 0.1451], [122982000.0, 0.0247], [122993000.0, 0.0023], [122994000.0, 0.0063], [122995000.0, 0.0203], [123000000.0, 0.1049], [123001000.0, 0.0001]]},
{"timestamp": "1743933337805", "bids": [[122960000.0, 0.1419], [122956000.0, 0.0], [122950000.0, 0.0061], [122949000.0, 0.0002], [122944000.0, 0.003], [122940000.0, 0.0], [122931000.0, 0.0], [122930000.0, 0.0], [122926000.0, 0.0024], [122918000.0, 0.0]], "asks": [[122968000.0, 0.0004], [122973000.0, 0.0006], [122980000.0, 0.0004], [122981000.0, 0.1451], [122982000.0, 0.0247], [122993000.0, 0.0023], [122994000.0, 0.0063], [122995000.0, 0.0203], [123000000.0, 0.1049], [123001000.0, 0.0001]]},
{"timestamp": "1743933338313", "bids": [[122960000.0, 0.1419], [122956000.0, 0.0], [122950000.0, 0.0061], [122949000.0, 0.0002], [122944000.0, 0.003], [122940000.0, 0.0], [122931000.0, 0.0], [122930000.0, 0.0], [122926000.0, 0.0024], [122918000.0, 0.0]], "asks": [[122968000.0, 0.0004], [122973000.0, 0.0006], [122980000.0, 0.0004], [122981000.0, 0.1451], [122982000.0, 0.0247], [122993000.0, 0.0023], [122994000.0, 0.0063], [122995000.0, 0.0203], [123000000.0, 0.1049], [123001000.0, 0.0001]]},
{"timestamp": "1743933338809", "bids": [[122960000.0, 0.1419], [122956000.0, 0.0], [122950000.0, 0.0061], [122949000.0, 0.0002], [122944000.0, 0.003], [122940000.0, 0.0], [122931000.0, 0.0], [122930000.0, 0.0], [122926000.0, 0.0024], [122918000.0, 0.0]], "asks": [[122968000.0, 0.0004], [122973000.0, 0.0006], [122980000.0, 0.0004], [122981000.0, 0.1451], [122982000.0, 0.0247], [122993000.0, 0.0023], [122994000.0, 0.0063], [122995000.0, 0.0203], [123000000.0, 0.1049], [123001000.0, 0.0001]]},
{"timestamp": "1743933339316", "bids": [[122960000.0, 0.1419], [122956000.0, 0.0], [122950000.0, 0.0061], [122949000.0, 0.0002], [122944000.0, 0.003], [122940000.0, 0.0], [122931000.0, 0.0], [122930000.0, 0.0], [122926000.0, 0.0024], [122918000.0, 0.0]], "asks": [[122968000.0, 0.0003], [122973000.0, 0.0006], [122980000.0, 0.0854], [122981000.0, 0.1451], [122982000.0, 0.0247], [122993000.0, 0.0023], [122994000.0, 0.0063], [122995000.0, 0.0203], [123000000.0, 0.1049], [123001000.0, 0.0001]]},
{"timestamp": "1743933339836", "bids": [[122960000.0, 0.1419], [122956000.0, 0.0], [122950000.0, 0.0061], [122949000.0, 0.0002], [122944000.0, 0.003], [122940000.0, 0.0], [122931000.0, 0.0], [122930000.0, 0.0], [122926000.0, 0.0024], [122918000.0, 0.0]], "asks": [[122967000.0, 0.1042], [122968000.0, 0.0003], [122973000.0, 0.0006], [122979000.0, 0.136], [122980000.0, 0.0854], [122981000.0, 0.0091], [122982000.0, 0.0247], [122993000.0, 0.0023], [122995000.0, 0.0203], [123000000.0, 0.1049]]},
{"timestamp": "1743933340364", "bids": [[122960000.0, 0.1419], [122956000.0, 0.0], [122950000.0, 0.0061], [122949000.0, 0.0002], [122944000.0, 0.003], [122940000.0, 0.0], [122931000.0, 0.0], [122930000.0, 0.0], [122926000.0, 0.0024], [122918000.0, 0.0]], "asks": [[122962000.0, 0.0207], [122968000.0, 0.0003], [122973000.0, 0.0253], [122974000.0, 0.0189], [122978000.0, 0.085], [122980000.0, 0.0004], [122984000.0, 0.0063], [122993000.0, 0.0023], [122999000.0, 0.136], [123000000.0, 0.1049]]},
{"timestamp": "1743933340858", "bids": [[122960000.0, 0.1419], [122956000.0, 0.0], [122950000.0, 0.0061], [122949000.0, 0.0002], [122944000.0, 0.003], [122940000.0, 0.0], [122931000.0, 0.0], [122930000.0, 0.0], [122926000.0, 0.0024], [122918000.0, 0.0]], "asks": [[122962000.0, 0.0207], [122968000.0, 0.0003], [122969000.0, 0.0091], [122973000.0, 0.0253], [122974000.0, 0.0189], [122978000.0, 0.085], [122980000.0, 0.0004], [122984000.0, 0.0063], [122985000.0, 0.0203], [122993000.0, 0.0023]]},
{"timestamp": "1743933341386", "bids": [[122960000.0, 0.1419], [122956000.0, 0.0], [122950000.0, 0.0061], [122949000.0, 0.0002], [122944000.0, 0.003], [122940000.0, 0.0], [122931000.0, 0.0], [122930000.0, 0.0], [122926000.0, 0.0024], [122918000.0, 0.0]], "asks": [[122962000.0, 0.0207], [122968000.0, 0.0003], [122969000.0, 0.0091], [122973000.0, 0.0253], [122974000.0, 0.0189], [122980000.0, 0.0004], [122984000.0, 0.1423], [122985000.0, 0.0203], [122993000.0, 0.0023], [123000000.0, 0.1049]]},
{"timestamp": "1743933341878", "bids": [[122960000.0, 0.1419], [122956000.0, 0.0], [122950000.0, 0.0061], [122949000.0, 0.0002], [122944000.0, 0.003], [122940000.0, 0.0], [122931000.0, 0.0], [122930000.0, 0.0], [122926000.0, 0.0024], [122918000.0, 0.0]], "asks": [[122962000.0, 0.0207], [122968000.0, 0.0003], [122969000.0, 0.0091], [122973000.0, 0.0253], [122974000.0, 0.0189], [122980000.0, 0.0004], [122983000.0, 0.085], [122984000.0, 0.0063], [122985000.0, 0.0203], [122993000.0, 0.0023]]},
{"timestamp": "1743933342411", "bids": [[122960000.0, 0.1419], [122956000.0, 0.0], [122950000.0, 0.0061], [122949000.0, 0.0002], [122944000.0, 0.003], [122940000.0, 0.0], [122931000.0, 0.0], [122930000.0, 0.0], [122926000.0, 0.0024], [122918000.0, 0.0]], "asks": [[122962000.0, 0.0207], [122968000.0, 0.0003], [122969000.0, 0.0091], [122973000.0, 0.0253], [122974000.0, 0.0189], [122980000.0, 0.0004], [122984000.0, 0.0913], [122985000.0, 0.0203], [122993000.0, 0.0023], [123000000.0, 0.1049]]},
{"timestamp": "1743933342921", "bids": [[122960000.0, 0.1419], [122956000.0, 0.0], [122950000.0, 0.0061], [122949000.0, 0.0002], [122944000.0, 0.003], [122940000.0, 0.0], [122931000.0, 0.0], [122930000.0, 0.0], [122926000.0, 0.0024], [122918000.0, 0.0]], "asks": [[122962000.0, 0.0207], [122968000.0, 0.0003], [122969000.0, 0.0091], [122973000.0, 0.0253], [122974000.0, 0.0189], [122980000.0, 0.1364], [122984000.0, 0.0913], [122985000.0, 0.0203], [122993000.0, 0.0023], [123000000.0, 0.1049]]},
{"timestamp": "1743933343434", "bids": [[122960000.0, 0.1419], [122956000.0, 0.0], [122950000.0, 0.0061], [122949000.0, 0.0002], [122944000.0, 0.003], [122940000.0, 0.0], [122931000.0, 0.0], [122930000.0, 0.0], [122926000.0, 0.0024], [122918000.0, 0.0]], "asks": [[122962000.0, 0.0207], [122968000.0, 0.0003], [122969000.0, 0.0091], [122973000.0, 0.0253], [122974000.0, 0.0189], [122979000.0, 0.085], [122980000.0, 0.0004], [122983000.0, 0.136], [122984000.0, 0.0063], [122985000.0, 0.0203]]},
{"timestamp": "1743933343918", "bids": [[122960000.0, 0.1419], [122956000.0, 0.0], [122950000.0, 0.0061], [122949000.0, 0.0002], [122944000.0, 0.003], [122940000.0, 0.0], [122931000.0, 0.0], [122930000.0, 0.0], [122926000.0, 0.0024], [122918000.0, 0.0]], "asks": [[122962000.0, 0.0207], [122968000.0, 0.0003], [122969000.0, 0.0091], [122973000.0, 0.0253], [122974000.0, 0.0189], [122980000.0, 0.0004], [122984000.0, 0.1423], [122985000.0, 0.0203], [122989000.0, 0.0023], [122993000.0, 0.0023]]},
{"timestamp": "1743933344431", "bids": [[122960000.0, 0.1419], [122956000.0, 0.0], [122950000.0, 0.0061], [122949000.0, 0.0002], [122944000.0, 0.003], [122940000.0, 0.0], [122931000.0, 0.0], [122930000.0, 0.0], [122926000.0, 0.0024], [122918000.0, 0.0]], "asks": [[122962000.0, 0.0207], [122968000.0, 0.0003], [122969000.0, 0.0091], [122973000.0, 0.0253], [122974000.0, 0.0189], [122980000.0, 0.0004], [122983000.0, 0.085], [122984000.0, 0.0063], [122985000.0, 0.0203], [122989000.0, 0.0023]]},
{"timestamp": "1743933344946", "bids": [[122960000.0, 0.1419], [122956000.0, 0.0], [122950000.0, 0.0061], [122949000.0, 0.0002], [122944000.0, 0.003], [122940000.0, 0.0], [122931000.0, 0.0], [122930000.0, 0.0], [122926000.0, 0.0024], [122918000.0, 0.0]], "asks": [[122962000.0, 0.0207], [122968000.0, 0.0003], [122969000.0, 0.0091], [122973000.0, 0.0253], [122974000.0, 0.0189], [122980000.0, 0.0004], [122984000.0, 0.0063], [122985000.0, 0.0203], [122989000.0, 0.0023], [123000000.0, 0.1049]]},
{"timestamp": "1743933345504", "bids": [[122960000.0, 0.1419], [122956000.0, 0.0], [122950000.0, 0.0061], [122949000.0, 0.0002], [122944000.0, 0.003], [122940000.0, 0.0], [122931000.0, 0.0], [122930000.0, 0.0], [122926000.0, 0.0024], [122918000.0, 0.0]], "asks": [[122962000.0, 0.0207], [122968000.0, 0.0003], [122969000.0, 0.0091], [122973000.0, 0.0253], [122974000.0, 0.0189], [122980000.0, 0.1364], [122982000.0, 0.085], [122984000.0, 0.0063], [122985000.0, 0.0203], [122989000.0, 0.0023]]},
{"timestamp": "1743933346001", "bids": [[122960000.0, 0.1419], [122956000.0, 0.0], [122950000.0, 0.0061], [122949000.0, 0.0002], [122944000.0, 0.003], [122940000.0, 0.0], [122931000.0, 0.0], [122930000.0, 0.0], [122926000.0, 0.0024], [122918000.0, 0.0]], "asks": [[122962000.0, 0.0207], [122968000.0, 0.0003], [122969000.0, 0.0091], [122973000.0, 0.0253], [122974000.0, 0.0189], [122980000.0, 0.0004], [122981000.0, 0.136], [122982000.0, 0.085], [122984000.0, 0.0063], [122985000.0, 0.0203]]},
{"timestamp": "1743933346500", "bids": [[122960000.0, 0.1419], [122956000.0, 0.0], [122950000.0, 0.0061], [122949000.0, 0.0002], [122944000.0, 0.003], [122940000.0, 0.0], [122931000.0, 0.0], [122930000.0, 0.0], [122926000.0, 0.0024], [122918000.0, 0.0]], "asks": [[122962000.0, 0.0207], [122968000.0, 0.0003], [122969000.0, 0.0091], [122973000.0, 0.0253], [122974000.0, 0.0189], [122980000.0, 0.0854], [122981000.0, 0.136], [122984000.0, 0.0063], [122985000.0, 0.0203], [122989000.0, 0.0023]]},
{"timestamp": "1743933346998", "bids": [[122960000.0, 0.1419], [122956000.0, 0.0], [122950000.0, 0.0061], [122949000.0, 0.0002], [122944000.0, 0.003], [122940000.0, 0.0], [122931000.0, 0.0], [122930000.0, 0.0], [122926000.0, 0.0024], [122918000.0, 0.0]], "asks": [[122962000.0, 0.0207], [122968000.0, 0.0003], [122969000.0, 0.0091], [122973000.0, 0.0253], [122974000.0, 0.0189], [122979000.0, 0.136], [122980000.0, 0.0854], [122984000.0, 0.0063], [122985000.0, 0.0203], [122989000.0, 0.0023]]},
{"timestamp": "1743933347526", "bids": [[122960000.0, 0.1419], [122956000.0, 0.0], [122950000.0, 0.0061], [122949000.0, 0.0002], [122944000.0, 0.003], [122940000.0, 0.0], [122931000.0, 0.0], [122930000.0, 0.0], [122926000.0, 0.0024], [122918000.0, 0.0]], "asks": [[122962000.0, 0.0207], [122968000.0, 0.0003], [122969000.0, 0.0091], [122973000.0, 0.0253], [122974000.0, 0.0189], [122979000.0, 0.085], [122980000.0, 0.0004], [122984000.0, 0.1423], [122985000.0, 0.0203], [122989000.0, 0.0023]]},
{"timestamp": "1743933348024", "bids": [[122960000.0, 0.1419], [122956000.0, 0.0], [122950000.0, 0.0061], [122949000.0, 0.0002], [122944000.0, 0.003], [122940000.0, 0.0], [122931000.0, 0.0], [122930000.0, 0.0], [122926000.0, 0.0024], [122918000.0, 0.0]], "asks": [[122962000.0, 0.0207], [122968000.0, 0.0003], [122969000.0, 0.0091], [122973000.0, 0.0253], [122974000.0, 0.0189], [122978000.0, 0.136], [122980000.0, 0.0004], [122984000.0, 0.0063], [122985000.0, 0.0203], [122989000.0, 0.0023]]},
{"timestamp": "1743933348525", "bids": [[122960000.0, 0.1419], [122956000.0, 0.0], [122950000.0, 0.0061], [122949000.0, 0.0002], [122944000.0, 0.003], [122940000.0, 0.0], [122931000.0, 0.0], [122930000.0, 0.0], [122926000.0, 0.0024], [122918000.0, 0.0]], "asks": [[122962000.0, 0.0207], [122968000.0, 0.0003], [122969000.0, 0.0091], [122973000.0, 0.0253], [122974000.0, 0.0189], [122980000.0, 0.0004], [122984000.0, 0.0913], [122985000.0, 0.0203], [122989000.0, 0.0023], [123000000.0, 0.1049]]},
{"timestamp": "1743933349042", "bids": [[122960000.0, 0.1419], [122956000.0, 0.0], [122950000.0, 0.0061], [122949000.0, 0.0002], [122944000.0, 0.003], [122940000.0, 0.0], [122931000.0, 0.0], [122930000.0, 0.0], [122926000.0, 0.0024], [122918000.0, 0.0]], "asks": [[122962000.0, 0.0207], [122968000.0, 0.0003], [122969000.0, 0.0091], [122973000.0, 0.0253], [122974000.0, 0.0189], [122980000.0, 0.0004], [122983000.0, 0.136], [122984000.0, 0.0913], [122985000.0, 0.0203], [122989000.0, 0.0023]]},
{"timestamp": "1743933349586", "bids": [[122960000.0, 0.1419], [122956000.0, 0.0], [122950000.0, 0.0061], [122949000.0, 0.0002], [122944000.0, 0.003], [122940000.0, 0.0], [122931000.0, 0.0], [122930000.0, 0.0], [122926000.0, 0.0024], [122918000.0, 0.0]], "asks": [[122962000.0, 0.0207], [122968000.0, 0.0003], [122969000.0, 0.0091], [122973000.0, 0.0253], [122974000.0, 0.0189], [122980000.0, 0.0004], [122982000.0, 0.085], [122984000.0, 0.1423], [122985000.0, 0.0203], [122989000.0, 0.0023]]},
{"timestamp": "1743933350059", "bids": [[122960000.0, 0.1419], [122956000.0, 0.0], [122950000.0, 0.0061], [122949000.0, 0.0002], [122944000.0, 0.003], [122940000.0, 0.0], [122931000.0, 0.0], [122930000.0, 0.0], [122926000.0, 0.0024], [122918000.0, 0.0]], "asks": [[122962000.0, 0.0207], [122968000.0, 0.0003], [122969000.0, 0.0091], [122973000.0, 0.0253], [122974000.0, 0.0189], [122980000.0, 0.0004], [122984000.0, 0.0063], [122985000.0, 0.0203], [122989000.0, 0.0023], [123000000.0, 0.1049]]},
{"timestamp": "1743933350584", "bids": [[122960000.0, 0.1419], [122956000.0, 0.0], [122950000.0, 0.0061], [122949000.0, 0.0002], [122944000.0, 0.003], [122940000.0, 0.0], [122931000.0, 0.0], [122930000.0, 0.0], [122926000.0, 0.0024], [122918000.0, 0.0]], "asks": [[122962000.0, 0.0207], [122968000.0, 0.0003], [122969000.0, 0.0091], [122973000.0, 0.0253], [122974000.0, 0.0189], [122980000.0, 0.0004], [122984000.0, 0.2273], [122985000.0, 0.0203], [122989000.0, 0.0023], [123000000.0, 0.1049]]},
{"timestamp": "1743933351080", "bids": [[122960000.0, 0.1419], [122956000.0, 0.0], [122950000.0, 0.0061], [122949000.0, 0.0002], [122944000.0, 0.003], [122940000.0, 0.0], [122931000.0, 0.0], [122930000.0, 0.0], [122926000.0, 0.0024], [122918000.0, 0.0]], "asks": [[122962000.0, 0.0207], [122968000.0, 0.0003], [122969000.0, 0.0091], [122973000.0, 0.0253], [122974000.0, 0.0189], [122980000.0, 0.0004], [122983000.0, 0.221], [122984000.0, 0.0063], [122985000.0, 0.0203], [122989000.0, 0.0023]]},
{"timestamp": "1743933351601", "bids": [[122960000.0, 0.1419], [122956000.0, 0.0], [122950000.0, 0.0061], [122949000.0, 0.0002], [122944000.0, 0.003], [122940000.0, 0.0], [122931000.0, 0.0], [122930000.0, 0.0], [122926000.0, 0.0024], [122918000.0, 0.0]], "asks": [[122962000.0, 0.0207], [122968000.0, 0.0003], [122969000.0, 0.0091], [122973000.0, 0.0253], [122974000.0, 0.0189], [122980000.0, 0.0004], [122984000.0, 0.0063], [122985000.0, 0.0203], [122989000.0, 0.0023], [123000000.0, 0.1049]]},
{"timestamp": "1743933352126", "bids": [[122960000.0, 0.1419], [122956000.0, 0.0], [122950000.0, 0.0061], [122949000.0, 0.0002], [122944000.0, 0.003], [122940000.0, 0.0], [122931000.0, 0.0], [122930000.0, 0.0], [122926000.0, 0.0024], [122918000.0, 0.0]], "asks": [[122962000.0, 0.0207], [122968000.0, 0.0003], [122969000.0, 0.0091], [122973000.0, 0.0253], [122974000.0, 0.0189], [122980000.0, 0.0004], [122984000.0, 0.2273], [122985000.0, 0.0203], [122989000.0, 0.0046], [123000000.0, 0.1049]]},
{"timestamp": "1743933352628", "bids": [[122960000.0, 0.1376], [122956000.0, 0.0], [122950000.0, 0.0061], [122949000.0, 0.0002], [122944000.0, 0.003], [122940000.0, 0.0], [122931000.0, 0.0], [122930000.0, 0.0], [122926000.0, 0.0024], [122918000.0, 0.0]], "asks": [[122962000.0, 0.0207], [122968000.0, 0.0003], [122969000.0, 0.0091], [122973000.0, 0.0253], [122974000.0, 0.0189], [122980000.0, 0.0004], [122984000.0, 0.2273], [122985000.0, 0.0203], [122989000.0, 0.0023], [123000000.0, 0.1049]]},
{"timestamp": "1743933353157", "bids": [[122960000.0, 0.1376], [122956000.0, 0.0], [122950000.0, 0.0061], [122949000.0, 0.0002], [122944000.0, 0.003], [122940000.0, 0.0], [122931000.0, 0.0], [122930000.0, 0.0], [122926000.0, 0.0024], [122918000.0, 0.0]], "asks": [[122962000.0, 0.0207], [122968000.0, 0.0003], [122969000.0, 0.0091], [122973000.0, 0.0253], [122974000.0, 0.0189], [122980000.0, 0.0004], [122984000.0, 0.0913], [122985000.0, 0.0203], [122989000.0, 0.0023], [123000000.0, 0.1049]]},
{"timestamp": "1743933353654", "bids": [[122960000.0, 0.1376], [122956000.0, 0.0], [122950000.0, 0.0061], [122949000.0, 0.0002], [122944000.0, 0.003], [122940000.0, 0.0], [122931000.0, 0.0], [122930000.0, 0.0], [122926000.0, 0.0024], [122918000.0, 0.0]], "asks": [[122962000.0, 0.0207], [122968000.0, 0.0003], [122969000.0, 0.0091], [122973000.0, 0.0253], [122974000.0, 0.0189], [122980000.0, 0.0004], [122984000.0, 0.2273], [122985000.0, 0.0203], [122989000.0, 0.0023], [123000000.0, 0.1049]]},
{"timestamp": "1743933354155", "bids": [[122960000.0, 0.1376], [122956000.0, 0.0], [122950000.0, 0.0061], [122949000.0, 0.0002], [122944000.0, 0.003], [122940000.0, 0.0], [122931000.0, 0.0], [122930000.0, 0.0], [122926000.0, 0.0024], [122918000.0, 0.0]], "asks": [[122962000.0, 0.0207], [122968000.0, 0.0003], [122969000.0, 0.0091], [122973000.0, 0.0253], [122974000.0, 0.0189], [122980000.0, 0.0004], [122982000.0, 0.221], [122984000.0, 0.0063], [122985000.0, 0.0203], [122989000.0, 0.0023]]},
{"timestamp": "1743933354672", "bids": [[122960000.0, 0.1376], [122956000.0, 0.0], [122950000.0, 0.0061], [122949000.0, 0.0002], [122944000.0, 0.003], [122940000.0, 0.0], [122931000.0, 0.0], [122930000.0, 0.0], [122926000.0, 0.0024], [122918000.0, 0.0]], "asks": [[122962000.0, 0.0207], [122968000.0, 0.0003], [122969000.0, 0.0091], [122973000.0, 0.0253], [122974000.0, 0.0189], [122980000.0, 0.0004], [122981000.0, 0.221], [122984000.0, 0.0063], [122985000.0, 0.0203], [122989000.0, 0.0023]]},
{"timestamp": "1743933355193", "bids": [[122960000.0, 0.1376], [122956000.0, 0.0], [122950000.0, 0.0061], [122949000.0, 0.0002], [122944000.0, 0.003], [122940000.0, 0.0], [122931000.0, 0.0], [122930000.0, 0.0], [122926000.0, 0.0024], [122918000.0, 0.0]], "asks": [[122962000.0, 0.0207], [122968000.0, 0.0003], [122969000.0, 0.0091], [122973000.0, 0.0253], [122974000.0, 0.0189], [122980000.0, 0.1364], [122984000.0, 0.0063], [122985000.0, 0.0203], [122989000.0, 0.0023], [123000000.0, 0.1049]]},
{"timestamp": "1743933355706", "bids": [[122960000.0, 0.1376], [122956000.0, 0.0], [122950000.0, 0.0061], [122949000.0, 0.0002], [122944000.0, 0.003], [122940000.0, 0.0], [122931000.0, 0.0], [122930000.0, 0.0], [122926000.0, 0.0024], [122918000.0, 0.0]], "asks": [[122962000.0, 0.0207], [122968000.0, 0.0003], [122969000.0, 0.0091], [122973000.0, 0.0253], [122974000.0, 0.0189], [122980000.0, 0.0004], [122983000.0, 0.085], [122984000.0, 0.1423], [122985000.0, 0.0203], [122989000.0, 0.0023]]},
{"timestamp": "1743933356238", "bids": [[122960000.0, 0.1376], [122956000.0, 0.0], [122950000.0, 0.0061], [122949000.0, 0.0002], [122944000.0, 0.003], [122940000.0, 0.0], [122931000.0, 0.0], [122930000.0, 0.0], [122926000.0, 0.0024], [122918000.0, 0.0]], "asks": [[122962000.0, 0.0207], [122968000.0, 0.0003], [122969000.0, 0.0091], [122973000.0, 0.0253], [122974000.0, 0.0189], [122980000.0, 0.0004], [122982000.0, 0.136], [122983000.0, 0.085], [122984000.0, 0.0063], [122985000.0, 0.0203]]},
{"timestamp": "1743933356727", "bids": [[122960000.0, 0.1376], [122956000.0, 0.0], [122950000.0, 0.0061], [122949000.0, 0.0002], [122944000.0, 0.003], [122940000.0, 0.0], [122931000.0, 0.0], [122930000.0, 0.0], [122926000.0, 0.0024], [122918000.0, 0.0]], "asks": [[122962000.0, 0.0207], [122968000.0, 0.0003], [122969000.0, 0.0091], [122973000.0, 0.0253], [122974000.0, 0.0189], [122980000.0, 0.1364], [122981000.0, 0.085], [122984000.0, 0.0063], [122985000.0, 0.0203], [122989000.0, 0.0023]]},
{"timestamp": "1743933357211", "bids": [[122960000.0, 0.1376], [122956000.0, 0.0], [122950000.0, 0.0061], [122949000.0, 0.0002], [122944000.0, 0.003], [122940000.0, 0.0], [122931000.0, 0.0], [122930000.0, 0.0], [122926000.0, 0.0024], [122918000.0, 0.0]], "asks": [[122962000.0, 0.0207], [122968000.0, 0.0003], [122969000.0, 0.0091], [122973000.0, 0.0253], [122974000.0, 0.0189], [122980000.0, 0.1364], [122984000.0, 0.0063], [122985000.0, 0.0203], [122989000.0, 0.0023], [123000000.0, 0.1049]]},
{"timestamp": "1743933357753", "bids": [[122960000.0, 0.1376], [122956000.0, 0.0], [122950000.0, 0.0061], [122949000.0, 0.0002], [122944000.0, 0.003], [122940000.0, 0.0], [122931000.0, 0.0], [122930000.0, 0.0], [122926000.0, 0.0024], [122918000.0, 0.0]], "asks": [[122962000.0, 0.0207], [122968000.0, 0.0003], [122969000.0, 0.0091], [122973000.0, 0.0253], [122974000.0, 0.0189], [122980000.0, 0.0004], [122984000.0, 0.1423], [122985000.0, 0.0203], [122989000.0, 0.0023], [123000000.0, 0.1049]]},
{"timestamp": "1743933358259", "bids": [[122960000.0, 0.1376], [122956000.0, 0.0], [122950000.0, 0.0061], [122949000.0, 0.0002], [122944000.0, 0.003], [122940000.0, 0.0], [122931000.0, 0.0], [122930000.0, 0.0], [122926000.0, 0.0024], [122918000.0, 0.0]], "asks": [[122962000.0, 0.0207], [122968000.0, 0.0003], [122969000.0, 0.0091], [122973000.0, 0.0253], [122974000.0, 0.0189], [122980000.0, 0.0004], [122983000.0, 0.085], [122984000.0, 0.1423], [122985000.0, 0.0203], [122989000.0, 0.0023]]},
{"timestamp": "1743933358789", "bids": [[122960000.0, 0.1376], [122956000.0, 0.0], [122950000.0, 0.0061], [122949000.0, 0.0002], [122944000.0, 0.003], [122940000.0, 0.0], [122931000.0, 0.0], [122930000.0, 0.0], [122926000.0, 0.0024], [122918000.0, 0.0]], "asks": [[122962000.0, 0.0207], [122968000.0, 0.0003], [122969000.0, 0.0091], [122973000.0, 0.0253], [122974000.0, 0.0189], [122980000.0, 0.0004], [122981000.0, 0.085], [122984000.0, 0.0063], [122985000.0, 0.0203], [122989000.0, 0.0023]]},
{"timestamp": "1743933359266", "bids": [[122960000.0, 0.1376], [122956000.0, 0.0], [122950000.0, 0.0061], [122949000.0, 0.0002], [122944000.0, 0.003], [122940000.0, 0.0], [122931000.0, 0.0], [122930000.0, 0.0], [122926000.0, 0.0024], [122918000.0, 0.0]], "asks": [[122962000.0, 0.0207], [122968000.0, 0.0003], [122969000.0, 0.0091], [122973000.0, 0.0253], [122974000.0, 0.0189], [122980000.0, 0.0004], [122984000.0, 0.1423], [122985000.0, 0.0203], [122989000.0, 0.0023], [123000000.0, 0.1049]]},
{"timestamp": "1743933359783", "bids": [[122960000.0, 0.1376], [122956000.0, 0.0], [122950000.0, 0.0061], [122949000.0, 0.0002], [122944000.0, 0.003], [122940000.0, 0.0], [122931000.0, 0.0], [122930000.0, 0.0], [122926000.0, 0.0024], [122918000.0, 0.0]], "asks": [[122962000.0, 0.0207], [122968000.0, 0.0003], [122969000.0, 0.0091], [122973000.0, 0.0253], [122974000.0, 0.0189], [122980000.0, 0.0004], [122983000.0, 0.085], [122984000.0, 0.1423], [122985000.0, 0.0203], [122989000.0, 0.0023]]},
{"timestamp": "1743933360336", "bids": [[122960000.0, 0.1376], [122956000.0, 0.0], [122950000.0, 0.0061], [122949000.0, 0.0002], [122944000.0, 0.003], [122940000.0, 0.0], [122931000.0, 0.0], [122930000.0, 0.0], [122926000.0, 0.0024], [122918000.0, 0.0]], "asks": [[122962000.0, 0.0207], [122968000.0, 0.0003], [122969000.0, 0.0091], [122973000.0, 0.0253], [122974000.0, 0.0189], [122980000.0, 0.0004], [122982000.0, 0.136], [122984000.0, 0.0063], [122985000.0, 0.0203], [122989000.0, 0.0023]]},
{"timestamp": "1743933360810", "bids": [[122960000.0, 0.1376], [122956000.0, 0.0], [122950000.0, 0.0061], [122949000.0, 0.0002], [122944000.0, 0.003], [122940000.0, 0.0], [122931000.0, 0.0], [122930000.0, 0.0], [122926000.0, 0.0024], [122918000.0, 0.0]], "asks": [[122962000.0, 0.0207], [122968000.0, 0.0003], [122969000.0, 0.0091], [122973000.0, 0.0253], [122974000.0, 0.0189], [122980000.0, 0.0004], [122981000.0, 0.085], [122984000.0, 0.1423], [122985000.0, 0.0203], [122989000.0, 0.0023]]},
{"timestamp": "1743933361343", "bids": [[122960000.0, 0.1376], [122956000.0, 0.0], [122950000.0, 0.0061], [122949000.0, 0.0002], [122944000.0, 0.003], [122940000.0, 0.0], [122931000.0, 0.0], [122930000.0, 0.0], [122926000.0, 0.0024], [122918000.0, 0.0]], "asks": [[122962000.0, 0.0207], [122968000.0, 0.0003], [122969000.0, 0.0091], [122973000.0, 0.0253], [122974000.0, 0.0189], [122980000.0, 0.0004], [122984000.0, 0.0063], [122985000.0, 0.0203], [122989000.0, 0.0023], [123000000.0, 0.1049]]},
{"timestamp": "1743933361838", "bids": [[122960000.0, 0.1376], [122956000.0, 0.0], [122950000.0, 0.0061], [122949000.0, 0.0002], [122944000.0, 0.003], [122940000.0, 0.0], [122931000.0, 0.0], [122930000.0, 0.0], [122926000.0, 0.0024], [122918000.0, 0.0]], "asks": [[122962000.0, 0.0207], [122968000.0, 0.0003], [122969000.0, 0.0091], [122973000.0, 0.0253], [122974000.0, 0.0189], [122980000.0, 0.0004], [122983000.0, 0.221], [122984000.0, 0.0063], [122985000.0, 0.0203], [122989000.0, 0.0023]]},
{"timestamp": "1743933362380", "bids": [[122960000.0, 0.1376], [122956000.0, 0.0], [122950000.0, 0.0061], [122949000.0, 0.0002], [122944000.0, 0.003], [122940000.0, 0.0], [122931000.0, 0.0], [122930000.0, 0.0], [122926000.0, 0.0024], [122918000.0, 0.0]], "asks": [[122962000.0, 0.0207], [122968000.0, 0.0003], [122969000.0, 0.0091], [122973000.0, 0.0253], [122974000.0, 0.0189], [122980000.0, 0.0004], [122982000.0, 0.221], [122984000.0, 0.0063], [122985000.0, 0.0203], [122989000.0, 0.0023]]},
{"timestamp": "1743933362895", "bids": [[122960000.0, 0.1376], [122956000.0, 0.0], [122950000.0, 0.0061], [122949000.0, 0.0002], [122944000.0, 0.003], [122940000.0, 0.0], [122931000.0, 0.0], [122930000.0, 0.0], [122926000.0, 0.0024], [122918000.0, 0.0]], "asks": [[122962000.0, 0.0207], [122968000.0, 0.0003], [122969000.0, 0.0091], [122973000.0, 0.0253], [122974000.0, 0.0189], [122980000.0, 0.0004], [122984000.0, 0.0063], [122985000.0, 0.0203], [122989000.0, 0.0023], [123000000.0, 0.1049]]},
{"timestamp": "1743933363410", "bids": [[122960000.0, 0.1376], [122956000.0, 0.0], [122950000.0, 0.0061], [122949000.0, 0.0002], [122944000.0, 0.003], [122940000.0, 0.0], [122931000.0, 0.0], [122930000.0, 0.0], [122926000.0, 0.0024], [122918000.0, 0.0]], "asks": [[122962000.0, 0.019], [122968000.0, 0.0003], [122969000.0, 0.0091], [122973000.0, 0.0253], [122974000.0, 0.0189], [122980000.0, 0.0004], [122983000.0, 0.085], [122984000.0, 0.2273], [122985000.0, 0.0203], [122989000.0, 0.0023]]},
{"timestamp": "1743933363897", "bids": [[122960000.0, 0.1376], [122956000.0, 0.0], [122950000.0, 0.0061], [122949000.0, 0.0002], [122944000.0, 0.003], [122940000.0, 0.0], [122931000.0, 0.0], [122930000.0, 0.0], [122926000.0, 0.0024], [122918000.0, 0.0]], "asks": [[122962000.0, 0.0158], [122968000.0, 0.0003], [122969000.0, 0.0091], [122973000.0, 0.0253], [122974000.0, 0.0189], [122980000.0, 0.0004], [122982000.0, 0.136], [122984000.0, 0.0913], [122985000.0, 0.0203], [122989000.0, 0.0023]]},
{"timestamp": "1743933364404", "bids": [[122960000.0, 0.1376], [122956000.0, 0.0], [122950000.0, 0.0061], [122949000.0, 0.0002], [122944000.0, 0.003], [122940000.0, 0.0], [122931000.0, 0.0], [122930000.0, 0.0], [122926000.0, 0.0024], [122918000.0, 0.0]], "asks": [[122962000.0, 0.0078], [122968000.0, 0.0003], [122969000.0, 0.0091], [122973000.0, 0.0253], [122974000.0, 0.0189], [122980000.0, 0.0004], [122983000.0, 0.136], [122984000.0, 0.0063], [122985000.0, 0.0203], [122989000.0, 0.0023]]},
{"timestamp": "1743933364945", "bids": [[122960000.0, 0.1376], [122956000.0, 0.0], [122950000.0, 0.0061], [122949000.0, 0.0002], [122944000.0, 0.003], [122940000.0, 0.0], [122931000.0, 0.0], [122930000.0, 0.0], [122926000.0, 0.0024], [122918000.0, 0.0]], "asks": [[122962000.0, 0.0078], [122968000.0, 0.0003], [122969000.0, 0.0091], [122973000.0, 0.0253], [122974000.0, 0.0189], [122980000.0, 0.0004], [122984000.0, 0.1419], [122985000.0, 0.0203], [122989000.0, 0.0046], [123000000.0, 0.1049]]},
{"timestamp": "1743933365452", "bids": [[122960000.0, 0.1376], [122956000.0, 0.0], [122950000.0, 0.0061], [122949000.0, 0.0002], [122944000.0, 0.003], [122940000.0, 0.0], [122931000.0, 0.0], [122930000.0, 0.0], [122926000.0, 0.0024], [122918000.0, 0.0]], "asks": [[122962000.0, 0.0078], [122968000.0, 0.0003], [122969000.0, 0.0091], [122973000.0, 0.0253], [122974000.0, 0.0189], [122980000.0, 0.0004], [122984000.0, 0.0063], [122989000.0, 0.0023], [123000000.0, 0.1049], [123001000.0, 0.0001]]},
{"timestamp": "1743933365950", "bids": [[122960000.0, 0.1376], [122956000.0, 0.0], [122950000.0, 0.0061], [122949000.0, 0.0002], [122944000.0, 0.003], [122940000.0, 0.0], [122931000.0, 0.0], [122930000.0, 0.0], [122926000.0, 0.0024], [122918000.0, 0.0]], "asks": [[122962000.0, 0.0078], [122968000.0, 0.0003], [122969000.0, 0.0091], [122973000.0, 0.0253], [122974000.0, 0.0189], [122980000.0, 0.0004], [122984000.0, 0.0063], [122989000.0, 0.0023], [122998000.0, 0.0203], [122999000.0, 0.0847]]},
{"timestamp": "1743933366475", "bids": [[122960000.0, 0.1376], [122956000.0, 0.0], [122950000.0, 0.0061], [122949000.0, 0.0002], [122944000.0, 0.003], [122940000.0, 0.0], [122931000.0, 0.0], [122930000.0, 0.0], [122926000.0, 0.0024], [122918000.0, 0.0]], "asks": [[122962000.0, 0.0078], [122968000.0, 0.0003], [122969000.0, 0.0091], [122973000.0, 0.0253], [122974000.0, 0.0189], [122980000.0, 0.0004], [122984000.0, 0.0063], [122989000.0, 0.0023], [122996000.0, 0.0847], [122998000.0, 0.0203]]},
{"timestamp": "1743933366974", "bids": [[122960000.0, 0.1376], [122956000.0, 0.0], [122950000.0, 0.0061], [122949000.0, 0.0002], [122944000.0, 0.003], [122940000.0, 0.0], [122931000.0, 0.0], [122930000.0, 0.0], [122926000.0, 0.0024], [122918000.0, 0.0]], "asks": [[122962000.0, 0.0078], [122968000.0, 0.0003], [122969000.0, 0.0091], [122973000.0, 0.0253], [122974000.0, 0.0189], [122980000.0, 0.0004], [122984000.0, 0.0063], [122989000.0, 0.0023], [122997000.0, 0.2203], [122998000.0, 0.0203]]},
{"timestamp": "1743933367495", "bids": [[122960000.0, 0.1376], [122956000.0, 0.0], [122950000.0, 0.0061], [122949000.0, 0.0002], [122944000.0, 0.003], [122940000.0, 0.0], [122931000.0, 0.0], [122930000.0, 0.0], [122926000.0, 0.0024], [122918000.0, 0.0]], "asks": [[122962000.0, 0.0078], [122968000.0, 0.0003], [122969000.0, 0.0091], [122973000.0, 0.0253], [122974000.0, 0.0189], [122980000.0, 0.0004], [122984000.0, 0.0063], [122989000.0, 0.0023], [122996000.0, 0.2203], [122998000.0, 0.0203]]},
{"timestamp": "1743933368031", "bids": [[122960000.0, 0.1376], [122956000.0, 0.0], [122950000.0, 0.0061], [122949000.0, 0.0002], [122944000.0, 0.003], [122940000.0, 0.0], [122931000.0, 0.0], [122930000.0, 0.0], [122926000.0, 0.0024], [122918000.0, 0.0]], "asks": [[122962000.0, 0.0078], [122968000.0, 0.0003], [122969000.0, 0.0091], [122973000.0, 0.0253], [122974000.0, 0.0189], [122980000.0, 0.0004], [122984000.0, 0.0063], [122989000.0, 0.0023], [122998000.0, 0.0203], [123000000.0, 0.1049]]},
{"timestamp": "1743933368509", "bids": [[122960000.0, 0.1376], [122956000.0, 0.0], [122950000.0, 0.0061], [122949000.0, 0.0002], [122944000.0, 0.003], [122940000.0, 0.0], [122931000.0, 0.0], [122930000.0, 0.0], [122926000.0, 0.0024], [122918000.0, 0.0]], "asks": [[122962000.0, 0.0078], [122968000.0, 0.0003], [122969000.0, 0.0091], [122973000.0, 0.0253], [122974000.0, 0.0189], [122980000.0, 0.0004], [122984000.0, 0.0063], [122989000.0, 0.0023], [122997000.0, 0.0847], [122998000.0, 0.0203]]},
{"timestamp": "1743933369023", "bids": [[122960000.0, 0.1376], [122956000.0, 0.0], [122950000.0, 0.0061], [122949000.0, 0.0002], [122944000.0, 0.003], [122940000.0, 0.0], [122931000.0, 0.0], [122930000.0, 0.0], [122926000.0, 0.0024], [122918000.0, 0.0]], "asks": [[122962000.0, 0.0078], [122968000.0, 0.0003], [122969000.0, 0.0091], [122973000.0, 0.0253], [122974000.0, 0.0189], [122980000.0, 0.0004], [122984000.0, 0.0063], [122989000.0, 0.0023], [122992000.0, 0.0847], [122998000.0, 0.0203]]},
{"timestamp": "1743933369552", "bids": [[122960000.0, 0.1376], [122956000.0, 0.0], [122950000.0, 0.0061], [122949000.0, 0.0002], [122944000.0, 0.003], [122940000.0, 0.0], [122931000.0, 0.0], [122930000.0, 0.0], [122926000.0, 0.0024], [122918000.0, 0.0]], "asks": [[122962000.0, 0.0078], [122968000.0, 0.0003], [122969000.0, 0.0091], [122973000.0, 0.0253], [122974000.0, 0.0189], [122980000.0, 0.0004], [122984000.0, 0.0063], [122989000.0, 0.0023], [122997000.0, 0.2203], [122998000.0, 0.0203]]},
{"timestamp": "1743933370082", "bids": [[122960000.0, 0.1376], [122956000.0, 0.0], [122950000.0, 0.0061], [122949000.0, 0.0002], [122944000.0, 0.003], [122940000.0, 0.0], [122931000.0, 0.0], [122930000.0, 0.0], [122926000.0, 0.0024], [122918000.0, 0.0]], "asks": [[122962000.0, 0.0078], [122968000.0, 0.0003], [122969000.0, 0.0091], [122973000.0, 0.0253], [122974000.0, 0.0189], [122980000.0, 0.0004], [122984000.0, 0.0063], [122989000.0, 0.0023], [122994000.0, 0.1356], [122996000.0, 0.0847]]},
{"timestamp": "1743933370543", "bids": [[122960000.0, 0.1376], [122956000.0, 0.0], [122950000.0, 0.0061], [122949000.0, 0.0002], [122944000.0, 0.003], [122940000.0, 0.0], [122931000.0, 0.0], [122930000.0, 0.0], [122926000.0, 0.0024], [122918000.0, 0.0]], "asks": [[122962000.0, 0.0078], [122968000.0, 0.0003], [122969000.0, 0.0091], [122973000.0, 0.0253], [122974000.0, 0.0189], [122980000.0, 0.0004], [122984000.0, 0.0063], [122989000.0, 0.0023], [122993000.0, 0.0847], [122998000.0, 0.0203]]},
{"timestamp": "1743933371087", "bids": [[122960000.0, 0.1376], [122956000.0, 0.0], [122950000.0, 0.0061], [122949000.0, 0.0002], [122944000.0, 0.003], [122940000.0, 0.0], [122931000.0, 0.0], [122930000.0, 0.0], [122926000.0, 0.0024], [122918000.0, 0.0]], "asks": [[122962000.0, 0.0078], [122968000.0, 0.0003], [122969000.0, 0.0091], [122973000.0, 0.0253], [122974000.0, 0.0189], [122980000.0, 0.0004], [122984000.0, 0.0063], [122989000.0, 0.0023], [122997000.0, 0.0847], [122998000.0, 0.0203]]},
{"timestamp": "1743933371566", "bids": [[122960000.0, 0.1376], [122956000.0, 0.0], [122950000.0, 0.0061], [122949000.0, 0.0002], [122944000.0, 0.003], [122940000.0, 0.0], [122931000.0, 0.0], [122930000.0, 0.0], [122926000.0, 0.0024], [122918000.0, 0.0]], "asks": [[122962000.0, 0.0078], [122968000.0, 0.0003], [122969000.0, 0.0091], [122973000.0, 0.0253], [122974000.0, 0.0189], [122980000.0, 0.0004], [122984000.0, 0.0063], [122989000.0, 0.0023], [122996000.0, 0.1356], [122998000.0, 0.0203]]},
{"timestamp": "1743933372090", "bids": [[122960000.0, 0.1376], [122956000.0, 0.0], [122950000.0, 0.0061], [122949000.0, 0.0002], [122944000.0, 0.003], [122940000.0, 0.0], [122931000.0, 0.0], [122930000.0, 0.0], [122926000.0, 0.0024], [122918000.0, 0.0]], "asks": [[122962000.0, 0.0078], [122968000.0, 0.0003], [122969000.0, 0.0091], [122973000.0, 0.0253], [122974000.0, 0.0189], [122980000.0, 0.0004], [122984000.0, 0.0063], [122989000.0, 0.0023], [122997000.0, 0.0847], [122998000.0, 0.0203]]},
{"timestamp": "1743933372642", "bids": [[122960000.0, 0.1376], [122956000.0, 0.0], [122950000.0, 0.0061], [122949000.0, 0.0002], [122944000.0, 0.003], [122940000.0, 0.0], [122931000.0, 0.0], [122930000.0, 0.0], [122926000.0, 0.0024], [122918000.0, 0.0]], "asks": [[122962000.0, 0.0078], [122968000.0, 0.0003], [122969000.0, 0.0091], [122973000.0, 0.0253], [122974000.0, 0.0189], [122980000.0, 0.0004], [122984000.0, 0.0063], [122989000.0, 0.0023], [122993000.0, 0.0847], [122998000.0, 0.0203]]},
{"timestamp": "1743933373181", "bids": [[122960000.0, 0.1376], [122956000.0, 0.0], [122950000.0, 0.0061], [122949000.0, 0.0002], [122944000.0, 0.003], [122940000.0, 0.0], [122931000.0, 0.0], [122930000.0, 0.0], [122926000.0, 0.0024], [122918000.0, 0.0]], "asks": [[122962000.0, 0.0078], [122968000.0, 0.0003], [122969000.0, 0.0091], [122973000.0, 0.0253], [122974000.0, 0.0189], [122980000.0, 0.0004], [122984000.0, 0.0063], [122989000.0, 0.0023], [122992000.0, 0.1356], [122996000.0, 0.0847]]},
{"timestamp": "1743933373614", "bids": [[122960000.0, 0.1376], [122956000.0, 0.0], [122950000.0, 0.0061], [122949000.0, 0.0002], [122944000.0, 0.003], [122940000.0, 0.0], [122931000.0, 0.0], [122930000.0, 0.0], [122926000.0, 0.0024], [122918000.0, 0.0]], "asks": [[122962000.0, 0.0078], [122968000.0, 0.0003], [122969000.0, 0.0091], [122973000.0, 0.0253], [122974000.0, 0.0189], [122980000.0, 0.0004], [122984000.0, 0.0063], [122989000.0, 0.0023], [122991000.0, 0.0847], [122996000.0, 0.1356]]},
{"timestamp": "1743933374126", "bids": [[122960000.0, 0.1376], [122956000.0, 0.0], [122950000.0, 0.0061], [122949000.0, 0.0002], [122944000.0, 0.003], [122940000.0, 0.0], [122931000.0, 0.0], [122930000.0, 0.0], [122926000.0, 0.0024], [122918000.0, 0.0]], "asks": [[122962000.0, 0.0078], [122968000.0, 0.0003], [122969000.0, 0.0091], [122973000.0, 0.0253], [122974000.0, 0.0189], [122980000.0, 0.0004], [122984000.0, 0.0063], [122989000.0, 0.0023], [122995000.0, 0.0847], [122998000.0, 0.0203]]},
{"timestamp": "1743933374650", "bids": [[122960000.0, 0.1376], [122956000.0, 0.0], [122950000.0, 0.0061], [122949000.0, 0.0002], [122944000.0, 0.003], [122940000.0, 0.0], [122931000.0, 0.0], [122930000.0, 0.0], [122926000.0, 0.0024], [122918000.0, 0.0]], "asks": [[122962000.0, 0.0078], [122968000.0, 0.0003], [122969000.0, 0.0091], [122973000.0, 0.0253], [122974000.0, 0.0189], [122980000.0, 0.0004], [122984000.0, 0.0063], [122989000.0, 0.0023], [122993000.0, 0.0847], [122998000.0, 0.0203]]},
{"timestamp": "1743933375137", "bids": [[122960000.0, 0.1376], [122956000.0, 0.0], [122950000.0, 0.0061], [122949000.0, 0.0002], [122944000.0, 0.003], [122940000.0, 0.0], [122931000.0, 0.0], [122930000.0, 0.0], [122926000.0, 0.0024], [122918000.0, 0.0]], "asks": [[122962000.0, 0.0078], [122968000.0, 0.0003], [122969000.0, 0.0091], [122973000.0, 0.0253], [122974000.0, 0.0189], [122980000.0, 0.0004], [122984000.0, 0.0063], [122988000.0, 0.0023], [122992000.0, 0.1356], [122997000.0, 0.0847]]},
{"timestamp": "1743933375657", "bids": [[122960000.0, 0.1376], [122956000.0, 0.0], [122950000.0, 0.0061], [122949000.0, 0.0002], [122944000.0, 0.003], [122940000.0, 0.0], [122931000.0, 0.0], [122930000.0, 0.0], [122926000.0, 0.0024], [122918000.0, 0.0]], "asks": [[122962000.0, 0.0078], [122968000.0, 0.0003], [122969000.0, 0.0091], [122973000.0, 0.0253], [122974000.0, 0.0189], [122980000.0, 0.0004], [122984000.0, 0.0063], [122988000.0, 0.0023], [122991000.0, 0.0847], [122996000.0, 0.1356]]},
{"timestamp": "1743933376162", "bids": [[122960000.0, 0.1376], [122956000.0, 0.0], [122950000.0, 0.0061], [122949000.0, 0.0002], [122944000.0, 0.003], [122940000.0, 0.0], [122931000.0, 0.0], [122930000.0, 0.0], [122926000.0, 0.0024], [122918000.0, 0.0]], "asks": [[122962000.0, 0.0078], [122968000.0, 0.0003], [122969000.0, 0.0091], [122973000.0, 0.0253], [122974000.0, 0.0189], [122980000.0, 0.0004], [122984000.0, 0.0063], [122988000.0, 0.0023], [122995000.0, 0.0847], [122998000.0, 0.0203]]},
{"timestamp": "1743933376698", "bids": [[122960000.0, 0.1376], [122956000.0, 0.0], [122950000.0, 0.0061], [122949000.0, 0.0002], [122944000.0, 0.003], [122940000.0, 0.0], [122931000.0, 0.0], [122930000.0, 0.0], [122926000.0, 0.0024], [122918000.0, 0.0]], "asks": [[122962000.0, 0.0078], [122968000.0, 0.0003], [122969000.0, 0.0091], [122973000.0, 0.0253], [122974000.0, 0.0189], [122980000.0, 0.0004], [122984000.0, 0.0063], [122988000.0, 0.0023], [122994000.0, 0.1356], [122996000.0, 0.0847]]},
{"timestamp": "1743933377183", "bids": [[122960000.0, 0.1376], [122956000.0, 0.0], [122950000.0, 0.0061], [122949000.0, 0.0002], [122944000.0, 0.003], [122940000.0, 0.0], [122931000.0, 0.0], [122930000.0, 0.0], [122926000.0, 0.0024], [122918000.0, 0.0]], "asks": [[122962000.0, 0.0078], [122968000.0, 0.0003], [122969000.0, 0.0091], [122973000.0, 0.0253], [122974000.0, 0.0189], [122980000.0, 0.0004], [122984000.0, 0.0063], [122988000.0, 0.0023], [122993000.0, 0.2203], [122998000.0, 0.0203]]},
{"timestamp": "1743933377703", "bids": [[122960000.0, 0.1376], [122956000.0, 0.0], [122950000.0, 0.0061], [122949000.0, 0.0002], [122944000.0, 0.003], [122940000.0, 0.0], [122931000.0, 0.0], [122930000.0, 0.0], [122926000.0, 0.0024], [122918000.0, 0.0]], "asks": [[122962000.0, 0.0078], [122968000.0, 0.0003], [122969000.0, 0.0091], [122973000.0, 0.0253], [122974000.0, 0.0189], [122980000.0, 0.0004], [122984000.0, 0.0063], [122988000.0, 0.0023], [122992000.0, 0.2203], [122998000.0, 0.0203]]},
{"timestamp": "1743933378215", "bids": [[122960000.0, 0.1376], [122956000.0, 0.0], [122950000.0, 0.0061], [122949000.0, 0.0002], [122944000.0, 0.003], [122940000.0, 0.0], [122931000.0, 0.0], [122930000.0, 0.0], [122926000.0, 0.0024], [122918000.0, 0.0]], "asks": [[122962000.0, 0.0078], [122968000.0, 0.0003], [122969000.0, 0.0091], [122973000.0, 0.0253], [122974000.0, 0.0189], [122980000.0, 0.0004], [122984000.0, 0.0063], [122988000.0, 0.0023], [122991000.0, 0.0847], [122996000.0, 0.1356]]},
{"timestamp": "1743933378729", "bids": [[122960000.0, 0.1376], [122956000.0, 0.0], [122950000.0, 0.0061], [122949000.0, 0.0002], [122944000.0, 0.003], [122940000.0, 0.0], [122931000.0, 0.0], [122930000.0, 0.0], [122926000.0, 0.0024], [122918000.0, 0.0]], "asks": [[122962000.0, 0.0078], [122968000.0, 0.0003], [122969000.0, 0.0091], [122973000.0, 0.0253], [122974000.0, 0.0189], [122980000.0, 0.0004], [122984000.0, 0.0063], [122988000.0, 0.0023], [122997000.0, 0.2203], [122998000.0, 0.0203]]},
{"timestamp": "1743933379250", "bids": [[122960000.0, 0.1376], [122956000.0, 0.0], [122950000.0, 0.0061], [122949000.0, 0.0002], [122944000.0, 0.003], [122940000.0, 0.0], [122931000.0, 0.0], [122930000.0, 0.0], [122926000.0, 0.0024], [122918000.0, 0.0]], "asks": [[122962000.0, 0.0078], [122968000.0, 0.0003], [122969000.0, 0.0091], [122973000.0, 0.0253], [122974000.0, 0.0189], [122980000.0, 0.0004], [122984000.0, 0.0063], [122988000.0, 0.0023], [122994000.0, 0.1356], [122996000.0, 0.0847]]},
{"timestamp": "1743933379764", "bids": [[122960000.0, 0.1376], [122956000.0, 0.0], [122950000.0, 0.0061], [122949000.0, 0.0002], [122944000.0, 0.003], [122940000.0, 0.0], [122931000.0, 0.0], [122930000.0, 0.0], [122926000.0, 0.0024], [122918000.0, 0.0]], "asks": [[122962000.0, 0.0078], [122968000.0, 0.0003], [122969000.0, 0.0091], [122973000.0, 0.0253], [122974000.0, 0.0189], [122980000.0, 0.0004], [122984000.0, 0.0063], [122988000.0, 0.0023], [122993000.0, 0.0847], [122994000.0, 0.1356]]},
{"timestamp": "1743933380267", "bids": [[122960000.0, 0.1376], [122956000.0, 0.0], [122950000.0, 0.0061], [122949000.0, 0.0002], [122944000.0, 0.003], [122940000.0, 0.0], [122931000.0, 0.0], [122930000.0, 0.0], [122926000.0, 0.0024], [122918000.0, 0.0]], "asks": [[122962000.0, 0.0078], [122968000.0, 0.0003], [122969000.0, 0.0091], [122973000.0, 0.0253], [122974000.0, 0.0189], [122980000.0, 0.0004], [122984000.0, 0.0063], [122988000.0, 0.0023], [122993000.0, 0.0847], [122998000.0, 0.0203]]},
{"timestamp": "1743933380788", "bids": [[122960000.0, 0.1376], [122956000.0, 0.0], [122950000.0, 0.0061], [122949000.0, 0.0002], [122944000.0, 0.003], [122940000.0, 0.0], [122931000.0, 0.0], [122930000.0, 0.0], [122926000.0, 0.0024], [122918000.0, 0.0]], "asks": [[122962000.0, 0.0078], [122968000.0, 0.0003], [122969000.0, 0.0091], [122973000.0, 0.0253], [122974000.0, 0.0189], [122980000.0, 0.0004], [122984000.0, 0.0063], [122988000.0, 0.0023], [122992000.0, 0.1356], [122997000.0, 0.0847]]},
{"timestamp": "1743933381293", "bids": [[122960000.0, 0.1376], [122956000.0, 0.0], [122950000.0, 0.0061], [122949000.0, 0.0002], [122944000.0, 0.003], [122940000.0, 0.0], [122931000.0, 0.0], [122930000.0, 0.0], [122926000.0, 0.0024], [122918000.0, 0.0]], "asks": [[122962000.0, 0.0078], [122968000.0, 0.0003], [122969000.0, 0.0091], [122973000.0, 0.0253], [122974000.0, 0.0189], [122980000.0, 0.0004], [122984000.0, 0.0063], [122988000.0, 0.0023], [122991000.0, 0.0847], [122994000.0, 0.1356]]},
{"timestamp": "1743933381825", "bids": [[122960000.0, 0.1376], [122956000.0, 0.0], [122950000.0, 0.0061], [122949000.0, 0.0002], [122944000.0, 0.003], [122940000.0, 0.0], [122931000.0, 0.0], [122930000.0, 0.0], [122926000.0, 0.0024], [122918000.0, 0.0]], "asks": [[122962000.0, 0.0077], [122968000.0, 0.0003], [122969000.0, 0.0091], [122973000.0, 0.0253], [122974000.0, 0.0189], [122980000.0, 0.0004], [122984000.0, 0.0063], [122988000.0, 0.0023], [122990000.0, 0.1356], [122993000.0, 0.0847]]},
{"timestamp": "1743933382318", "bids": [[122960000.0, 0.1376], [122956000.0, 0.0], [122950000.0, 0.0061], [122949000.0, 0.0002], [122944000.0, 0.003], [122940000.0, 0.0], [122931000.0, 0.0], [122930000.0, 0.0], [122926000.0, 0.0024], [122918000.0, 0.0]], "asks": [[122962000.0, 0.0077], [122968000.0, 0.0003], [122969000.0, 0.0091], [122973000.0, 0.0253], [122974000.0, 0.0189], [122980000.0, 0.0004], [122984000.0, 0.0063], [122988000.0, 0.0023], [122993000.0, 0.0847], [122997000.0, 0.1356]]},
{"timestamp": "1743933382841", "bids": [[122960000.0, 0.1376], [122956000.0, 0.0], [122950000.0, 0.0061], [122949000.0, 0.0002], [122944000.0, 0.003], [122940000.0, 0.0], [122931000.0, 0.0], [122930000.0, 0.0], [122926000.0, 0.0024], [122918000.0, 0.0]], "asks": [[122962000.0, 0.0077], [122968000.0, 0.0003], [122969000.0, 0.0091], [122973000.0, 0.0253], [122974000.0, 0.0189], [122980000.0, 0.0004], [122984000.0, 0.0063], [122988000.0, 0.0023], [122996000.0, 0.0847], [122998000.0, 0.0203]]},
{"timestamp": "1743933383371", "bids": [[122960000.0, 0.1376], [122956000.0, 0.0], [122950000.0, 0.0061], [122949000.0, 0.0002], [122944000.0, 0.003], [122940000.0, 0.0], [122931000.0, 0.0], [122930000.0, 0.0], [122926000.0, 0.0024], [122918000.0, 0.0]], "asks": [[122962000.0, 0.0077], [122968000.0, 0.0003], [122969000.0, 0.0091], [122973000.0, 0.0253], [122974000.0, 0.0189], [122980000.0, 0.0004], [122984000.0, 0.0063], [122988000.0, 0.0023], [122995000.0, 0.1356], [122997000.0, 0.0847]]},
{"timestamp": "1743933383857", "bids": [[122960000.0, 0.1376], [122956000.0, 0.0], [122950000.0, 0.0061], [122949000.0, 0.0002], [122944000.0, 0.003], [122940000.0, 0.0], [122931000.0, 0.0], [122930000.0, 0.0], [122926000.0, 0.0024], [122918000.0, 0.0]], "asks": [[122962000.0, 0.0077], [122968000.0, 0.0003], [122969000.0, 0.0091], [122973000.0, 0.0253], [122974000.0, 0.0189], [122980000.0, 0.0004], [122984000.0, 0.0063], [122988000.0, 0.0023], [122994000.0, 0.0847], [122998000.0, 0.0203]]},
{"timestamp": "1743933384353", "bids": [[122960000.0, 0.1376], [122956000.0, 0.0], [122950000.0, 0.0061], [122949000.0, 0.0002], [122944000.0, 0.003], [122940000.0, 0.0], [122931000.0, 0.0], [122930000.0, 0.0], [122926000.0, 0.0024], [122918000.0, 0.0]], "asks": [[122962000.0, 0.0077], [122968000.0, 0.0003], [122969000.0, 0.0091], [122973000.0, 0.0253], [122974000.0, 0.0189], [122980000.0, 0.0004], [122984000.0, 0.0063], [122987000.0, 0.0847], [122988000.0, 0.0023], [122996000.0, 0.1356]]},
{"timestamp": "1743933384909", "bids": [[122960000.0, 0.1376], [122956000.0, 0.0], [122950000.0, 0.0061], [122949000.0, 0.0002], [122944000.0, 0.003], [122940000.0, 0.0], [122931000.0, 0.0], [122930000.0, 0.0], [122926000.0, 0.0024], [122918000.0, 0.0]], "asks": [[122962000.0, 0.0077], [122968000.0, 0.0003], [122969000.0, 0.0091], [122973000.0, 0.0253], [122974000.0, 0.0189], [122980000.0, 0.0004], [122984000.0, 0.0063], [122986000.0, 0.1356], [122988000.0, 0.0023], [122995000.0, 0.0847]]},
{"timestamp": "1743933385414", "bids": [[122960000.0, 0.1376], [122956000.0, 0.0], [122950000.0, 0.0061], [122949000.0, 0.0002], [122944000.0, 0.003], [122940000.0, 0.0], [122931000.0, 0.0], [122930000.0, 0.0], [122926000.0, 0.0024], [122918000.0, 0.0]], "asks": [[122962000.0, 0.0077], [122968000.0, 0.0003], [122969000.0, 0.0091], [122973000.0, 0.0253], [122974000.0, 0.0189], [122980000.0, 0.0004], [122984000.0, 0.0063], [122988000.0, 0.0023], [122994000.0, 0.1356], [122998000.0, 0.0203]]},
{"timestamp": "1743933385900", "bids": [[122960000.0, 0.1376], [122956000.0, 0.0], [122950000.0, 0.0061], [122949000.0, 0.0002], [122944000.0, 0.003], [122940000.0, 0.0], [122931000.0, 0.0], [122930000.0, 0.0], [122926000.0, 0.0024], [122918000.0, 0.0]], "asks": [[122962000.0, 0.0077], [122968000.0, 0.0003], [122969000.0, 0.0091], [122973000.0, 0.0253], [122974000.0, 0.0189], [122980000.0, 0.0004], [122984000.0, 0.0063], [122988000.0, 0.0023], [122993000.0, 0.0847], [122997000.0, 0.1356]]},
{"timestamp": "1743933386427", "bids": [[122960000.0, 0.1376], [122956000.0, 0.0], [122950000.0, 0.0061], [122949000.0, 0.0002], [122944000.0, 0.003], [122940000.0, 0.0], [122931000.0, 0.0], [122930000.0, 0.0], [122926000.0, 0.0024], [122918000.0, 0.0]], "asks": [[122962000.0, 0.0077], [122968000.0, 0.0003], [122969000.0, 0.0091], [122973000.0, 0.0253], [122974000.0, 0.0189], [122980000.0, 0.0004], [122984000.0, 0.0063], [122988000.0, 0.0023], [122991000.0, 0.0847], [122995000.0, 0.1356]]},
{"timestamp": "1743933386932", "bids": [[122960000.0, 0.1376], [122956000.0, 0.0], [122950000.0, 0.0061], [122949000.0, 0.0002], [122944000.0, 0.003], [122940000.0, 0.0], [122931000.0, 0.0], [122930000.0, 0.0], [122926000.0, 0.0024], [122918000.0, 0.0]], "asks": [[122962000.0, 0.0077], [122968000.0, 0.0003], [122969000.0, 0.0091], [122973000.0, 0.0253], [122974000.0, 0.0189], [122980000.0, 0.0004], [122984000.0, 0.0063], [122988000.0, 0.0023], [122994000.0, 0.0847], [122998000.0, 0.0203]]},
{"timestamp": "1743933387465", "bids": [[122960000.0, 0.1376], [122956000.0, 0.0], [122950000.0, 0.0061], [122949000.0, 0.0002], [122944000.0, 0.003], [122940000.0, 0.0], [122931000.0, 0.0], [122930000.0, 0.0], [122926000.0, 0.0024], [122918000.0, 0.0]], "asks": [[122962000.0, 0.0077], [122968000.0, 0.0003], [122969000.0, 0.0091], [122973000.0, 0.0253], [122974000.0, 0.0189], [122980000.0, 0.0004], [122984000.0, 0.0063], [122988000.0, 0.0023], [122993000.0, 0.1356], [122997000.0, 0.0847]]},
{"timestamp": "1743933387951", "bids": [[122960000.0, 0.1376], [122956000.0, 0.0], [122950000.0, 0.0061], [122949000.0, 0.0002], [122944000.0, 0.003], [122940000.0, 0.0], [122931000.0, 0.0], [122930000.0, 0.0], [122926000.0, 0.0024], [122918000.0, 0.0]], "asks": [[122962000.0, 0.0077], [122968000.0, 0.0003], [122969000.0, 0.0091], [122973000.0, 0.0253], [122974000.0, 0.0189], [122980000.0, 0.0004], [122984000.0, 0.0063], [122988000.0, 0.0046], [122996000.0, 0.1356], [122998000.0, 0.0203]]},
{"timestamp": "1743933388508", "bids": [[122960000.0, 0.1376], [122956000.0, 0.0], [122950000.0, 0.0061], [122949000.0, 0.0002], [122944000.0, 0.003], [122940000.0, 0.0], [122931000.0, 0.0], [122930000.0, 0.0], [122926000.0, 0.0024], [122918000.0, 0.0]], "asks": [[122962000.0, 0.0077], [122968000.0, 0.0003], [122969000.0, 0.0091], [122973000.0, 0.0253], [122974000.0, 0.0189], [122980000.0, 0.0004], [122984000.0, 0.0063], [122988000.0, 0.0023], [122995000.0, 0.0847], [122997000.0, 0.1356]]},
{"timestamp": "1743933388977", "bids": [[122960000.0, 0.1376], [122956000.0, 0.0], [122950000.0, 0.0061], [122949000.0, 0.0002], [122944000.0, 0.003], [122940000.0, 0.0], [122931000.0, 0.0], [122930000.0, 0.0], [122926000.0, 0.0024], [122918000.0, 0.0]], "asks": [[122962000.0, 0.0077], [122968000.0, 0.0003], [122969000.0, 0.0091], [122973000.0, 0.0253], [122974000.0, 0.0189], [122980000.0, 0.0004], [122984000.0, 0.0063], [122988000.0, 0.0023], [122989000.0, 0.1356], [122996000.0, 0.0847]]},
{"timestamp": "1743933389505", "bids": [[122960000.0, 0.1376], [122956000.0, 0.0], [122950000.0, 0.0061], [122949000.0, 0.0002], [122944000.0, 0.003], [122940000.0, 0.0], [122931000.0, 0.0], [122930000.0, 0.0], [122926000.0, 0.0024], [122918000.0, 0.0]], "asks": [[122962000.0, 0.0077], [122968000.0, 0.0003], [122969000.0, 0.0091], [122973000.0, 0.0253], [122974000.0, 0.0189], [122980000.0, 0.0004], [122984000.0, 0.0063], [122988000.0, 0.087], [122992000.0, 0.1356], [122998000.0, 0.0203]]},
{"timestamp": "1743933390009", "bids": [[122960000.0, 0.1376], [122956000.0, 0.0], [122950000.0, 0.0061], [122949000.0, 0.0002], [122944000.0, 0.003], [122940000.0, 0.0], [122931000.0, 0.0], [122930000.0, 0.0], [122926000.0, 0.0024], [122918000.0, 0.0]], "asks": [[122962000.0, 0.0077], [122968000.0, 0.0003], [122969000.0, 0.0091], [122973000.0, 0.0253], [122974000.0, 0.0189], [122980000.0, 0.0004], [122984000.0, 0.0063], [122988000.0, 0.0023], [122991000.0, 0.0847], [122998000.0, 0.0203]]},
{"timestamp": "1743933390527", "bids": [[122960000.0, 0.1376], [122956000.0, 0.0], [122950000.0, 0.0061], [122949000.0, 0.0002], [122944000.0, 0.003], [122940000.0, 0.0], [122931000.0, 0.0], [122930000.0, 0.0], [122926000.0, 0.0024], [122918000.0, 0.0]], "asks": [[122962000.0, 0.0077], [122968000.0, 0.0003], [122969000.0, 0.0091], [122973000.0, 0.0253], [122974000.0, 0.0189], [122980000.0, 0.0004], [122984000.0, 0.0063], [122988000.0, 0.0023], [122990000.0, 0.1356], [122992000.0, 0.0847]]},
{"timestamp": "1743933391040", "bids": [[122960000.0, 0.1376], [122956000.0, 0.0], [122950000.0, 0.0061], [122949000.0, 0.0002], [122944000.0, 0.003], [122940000.0, 0.0], [122931000.0, 0.0], [122930000.0, 0.0], [122926000.0, 0.0024], [122918000.0, 0.0]], "asks": [[122962000.0, 0.0077], [122968000.0, 0.0003], [122969000.0, 0.0091], [122973000.0, 0.0253], [122974000.0, 0.0189], [122980000.0, 0.0004], [122984000.0, 0.0063], [122988000.0, 0.0023], [122989000.0, 0.0847], [122991000.0, 0.1356]]},
{"timestamp": "1743933391546", "bids": [[122960000.0, 0.1376], [122956000.0, 0.0], [122950000.0, 0.0061], [122949000.0, 0.0002], [122944000.0, 0.003], [122940000.0, 0.0], [122931000.0, 0.0], [122930000.0, 0.0], [122926000.0, 0.0024], [122918000.0, 0.0]], "asks": [[122962000.0, 0.0077], [122968000.0, 0.0003], [122969000.0, 0.0091], [122973000.0, 0.0253], [122974000.0, 0.0189], [122980000.0, 0.0004], [122984000.0, 0.0063], [122988000.0, 0.1402], [122990000.0, 0.0847], [122998000.0, 0.0203]]},
{"timestamp": "1743933392081", "bids": [[122960000.0, 0.1376], [122956000.0, 0.0], [122950000.0, 0.0061], [122949000.0, 0.0002], [122944000.0, 0.003], [122940000.0, 0.0], [122931000.0, 0.0], [122930000.0, 0.0], [122926000.0, 0.0024], [122918000.0, 0.0]], "asks": [[122962000.0, 0.0077], [122968000.0, 0.0003], [122969000.0, 0.0091], [122973000.0, 0.0253], [122974000.0, 0.0189], [122980000.0, 0.0004], [122984000.0, 0.0063], [122987000.0, 0.0847], [122988000.0, 0.0023], [122989000.0, 0.1356]]},
{"timestamp": "1743933392585", "bids": [[122960000.0, 0.1376], [122956000.0, 0.0], [122950000.0, 0.0061], [122949000.0, 0.0002], [122944000.0, 0.003], [122940000.0, 0.0], [122931000.0, 0.0], [122930000.0, 0.0], [122926000.0, 0.0024], [122918000.0, 0.0]], "asks": [[122962000.0, 0.0077], [122968000.0, 0.0003], [122969000.0, 0.0091], [122973000.0, 0.0253], [122974000.0, 0.0189], [122980000.0, 0.0004], [122984000.0, 0.0063], [122986000.0, 0.1356], [122988000.0, 0.087], [122998000.0, 0.0203]]},
{"timestamp": "1743933393102", "bids": [[122960000.0, 0.1376], [122956000.0, 0.0], [122950000.0, 0.0061], [122949000.0, 0.0002], [122944000.0, 0.003], [122940000.0, 0.0], [122931000.0, 0.0], [122930000.0, 0.0], [122926000.0, 0.0024], [122918000.0, 0.0]], "asks": [[122962000.0, 0.0077], [122968000.0, 0.0003], [122969000.0, 0.0091], [122973000.0, 0.0253], [122974000.0, 0.0189], [122980000.0, 0.0004], [122984000.0, 0.0063], [122988000.0, 0.0023], [122998000.0, 0.0203], [123000000.0, 0.1049]]},
{"timestamp": "1743933393618", "bids": [[122960000.0, 0.1376], [122956000.0, 0.0], [122950000.0, 0.0061], [122949000.0, 0.0002], [122944000.0, 0.003], [122940000.0, 0.0], [122931000.0, 0.0], [122930000.0, 0.0], [122926000.0, 0.0024], [122918000.0, 0.0]], "asks": [[122962000.0, 0.0077], [122968000.0, 0.0003], [122969000.0, 0.0091], [122973000.0, 0.0253], [122974000.0, 0.0189], [122980000.0, 0.0004], [122984000.0, 0.0063], [122988000.0, 0.0023], [122997000.0, 0.2203], [122998000.0, 0.0203]]},
{"timestamp": "1743933394113", "bids": [[122960000.0, 0.1376], [122956000.0, 0.0], [122950000.0, 0.0061], [122949000.0, 0.0002], [122944000.0, 0.003], [122940000.0, 0.0], [122931000.0, 0.0], [122930000.0, 0.0], [122926000.0, 0.0024], [122918000.0, 0.0]], "asks": [[122962000.0, 0.0077], [122968000.0, 0.0003], [122969000.0, 0.0091], [122973000.0, 0.0253], [122974000.0, 0.0189], [122980000.0, 0.0004], [122984000.0, 0.0063], [122988000.0, 0.0023], [122991000.0, 0.1356], [122996000.0, 0.0847]]},
{"timestamp": "1743933394648", "bids": [[122960000.0, 0.1376], [122956000.0, 0.0], [122950000.0, 0.0061], [122949000.0, 0.0002], [122944000.0, 0.003], [122940000.0, 0.0], [122931000.0, 0.0], [122930000.0, 0.0], [122926000.0, 0.0024], [122918000.0, 0.0]], "asks": [[122962000.0, 0.0077], [122968000.0, 0.0003], [122969000.0, 0.0091], [122973000.0, 0.0253], [122974000.0, 0.0189], [122980000.0, 0.0004], [122984000.0, 0.0063], [122988000.0, 0.0023], [122990000.0, 0.0847], [122998000.0, 0.0203]]},
{"timestamp": "1743933395146", "bids": [[122960000.0, 0.1376], [122956000.0, 0.0], [122950000.0, 0.0061], [122949000.0, 0.0002], [122944000.0, 0.003], [122940000.0, 0.0], [122931000.0, 0.0], [122930000.0, 0.0], [122926000.0, 0.0024], [122918000.0, 0.0]], "asks": [[122962000.0, 0.0077], [122968000.0, 0.0003], [122969000.0, 0.0091], [122973000.0, 0.0253], [122974000.0, 0.0189], [122980000.0, 0.0004], [122984000.0, 0.0063], [122988000.0, 0.0023], [122997000.0, 0.0847], [122998000.0, 0.0203]]},
{"timestamp": "1743933395647", "bids": [[122960000.0, 0.1376], [122956000.0, 0.0], [122950000.0, 0.0061], [122949000.0, 0.0002], [122944000.0, 0.003], [122940000.0, 0.0], [122931000.0, 0.0], [122930000.0, 0.0], [122926000.0, 0.0024], [122918000.0, 0.0]], "asks": [[122962000.0, 0.0077], [122968000.0, 0.0003], [122969000.0, 0.0091], [122973000.0, 0.0253], [122974000.0, 0.0189], [122980000.0, 0.0004], [122984000.0, 0.0063], [122988000.0, 0.0023], [122997000.0, 0.0847], [122998000.0, 0.0203]]},
{"timestamp": "1743933396169", "bids": [[122960000.0, 0.1376], [122956000.0, 0.0], [122950000.0, 0.0061], [122949000.0, 0.0002], [122944000.0, 0.003], [122940000.0, 0.0], [122931000.0, 0.0], [122930000.0, 0.0], [122926000.0, 0.0024], [122918000.0, 0.0]], "asks": [[122962000.0, 0.0077], [122968000.0, 0.0003], [122969000.0, 0.0091], [122973000.0, 0.0253], [122974000.0, 0.0189], [122980000.0, 0.0004], [122984000.0, 0.0063], [122988000.0, 0.0023], [122996000.0, 0.1356], [122997000.0, 0.0847]]},
{"timestamp": "1743933396689", "bids": [[122960000.0, 0.1376], [122956000.0, 0.0], [122950000.0, 0.0061], [122949000.0, 0.0002], [122944000.0, 0.003], [122940000.0, 0.0], [122931000.0, 0.0], [122930000.0, 0.0], [122926000.0, 0.0024], [122918000.0, 0.0]], "asks": [[122962000.0, 0.0077], [122968000.0, 0.0003], [122969000.0, 0.0091], [122973000.0, 0.0253], [122974000.0, 0.0189], [122980000.0, 0.0004], [122984000.0, 0.0063], [122988000.0, 0.0023], [122995000.0, 0.0847], [122996000.0, 0.1356]]},
{"timestamp": "1743933397179", "bids": [[122960000.0, 0.1376], [122956000.0, 0.0], [122950000.0, 0.0061], [122949000.0, 0.0002], [122944000.0, 0.003], [122940000.0, 0.0], [122931000.0, 0.0], [122930000.0, 0.0], [122926000.0, 0.0024], [122918000.0, 0.0]], "asks": [[122962000.0, 0.0077], [122968000.0, 0.0003], [122969000.0, 0.0091], [122973000.0, 0.0253], [122974000.0, 0.0189], [122980000.0, 0.0004], [122984000.0, 0.0063], [122988000.0, 0.0023], [122993000.0, 0.0847], [122994000.0, 0.1356]]},
