{"timestamp": "1743933397691", "bids": [[122960000.0, 0.1376], [122956000.0, 0.0], [122950000.0, 0.0061], [122949000.0, 0.0002], [122944000.0, 0.003], [122940000.0, 0.0], [122931000.0, 0.0], [122930000.0, 0.0], [122926000.0, 0.0024], [122918000.0, 0.0]], "asks": [[122962000.0, 0.0077], [122968000.0, 0.0003], [122969000.0, 0.0091], [122973000.0, 0.0253], [122974000.0, 0.0189], [122980000.0, 0.0004], [122984000.0, 0.0063], [122988000.0, 0.0023], [122992000.0, 0.1356], [122993000.0, 0.0847]]},
{"timestamp": "1743933398191", "bids": [[122960000.0, 0.1376], [122956000.0, 0.0], [122950000.0, 0.0061], [122949000.0, 0.0002], [122944000.0, 0.003], [122940000.0, 0.0], [122931000.0, 0.0], [122930000.0, 0.0], [122926000.0, 0.0024], [122918000.0, 0.0]], "asks": [[122962000.0, 0.0077], [122968000.0, 0.0003], [122969000.0, 0.0091], [122973000.0, 0.0253], [122974000.0, 0.0189], [122980000.0, 0.0004], [122984000.0, 0.0063], [122988000.0, 0.0023], [122991000.0, 0.0847], [122992000.0, 0.1356]]},
{"timestamp": "1743933398711", "bids": [[122960000.0, 0.1376], [122956000.0, 0.0], [122950000.0, 0.0061], [122949000.0, 0.0002], [122944000.0, 0.003], [122940000.0, 0.0], [122931000.0, 0.0], [122930000.0, 0.0], [122926000.0, 0.0024], [122918000.0, 0.0]], "asks": [[122962000.0, 0.0077], [122968000.0, 0.0003], [122969000.0, 0.0091], [122973000.0, 0.0253], [122974000.0, 0.0189], [122980000.0, 0.0004], [122984000.0, 0.0063], [122988000.0, 0.0023], [122997000.0, 0.2203], [122998000.0, 0.0203]]},
{"timestamp": "1743933399222", "bids": [[122960000.0, 0.1376], [122956000.0, 0.0], [122950000.0, 0.0061], [122949000.0, 0.0002], [122944000.0, 0.003], [122940000.0, 0.0], [122931000.0, 0.0], [122930000.0, 0.0], [122926000.0, 0.0024], [122918000.0, 0.0]], "asks": [[122962000.0, 0.0077], [122968000.0, 0.0003], [122969000.0, 0.0091], [122973000.0, 0.0253], [122974000.0, 0.0189], [122980000.0, 0.0004], [122984000.0, 0.0063], [122988000.0, 0.0023], [122989000.0, 0.0847], [122998000.0, 0.0203]]},
{"timestamp": "1743933399750", "bids": [[122960000.0, 0.1376], [122956000.0, 0.0], [122950000.0, 0.0061], [122949000.0, 0.0002], [122944000.0, 0.003], [122940000.0, 0.0], [122931000.0, 0.0], [122930000.0, 0.0], [122926000.0, 0.0024], [122918000.0, 0.0]], "asks": [[122962000.0, 0.0077], [122968000.0, 0.0003], [122969000.0, 0.0091], [122973000.0, 0.0253], [122974000.0, 0.0189], [122980000.0, 0.0004], [122984000.0, 0.0063], [122987000.0, 0.0847], [122988000.0, 0.0023], [122996000.0, 0.1356]]},
{"timestamp": "1743933400243", "bids": [[122960000.0, 0.1376], [122956000.0, 0.0], [122950000.0, 0.0061], [122949000.0, 0.0002], [122944000.0, 0.003], [122940000.0, 0.0], [122931000.0, 0.0], [122930000.0, 0.0], [122926000.0, 0.0024], [122918000.0, 0.0]], "asks": [[122962000.0, 0.0077], [122968000.0, 0.0003], [122969000.0, 0.0091], [122973000.0, 0.0253], [122974000.0, 0.0189], [122980000.0, 0.0004], [122984000.0, 0.0063], [122986000.0, 0.1356], [122988000.0, 0.0023], [122995000.0, 0.0847]]},
{"timestamp": "1743933400754", "bids": [[122960000.0, 0.1376], [122956000.0, 0.0], [122950000.0, 0.0061], [122949000.0, 0.0002], [122944000.0, 0.003], [122940000.0, 0.0], [122931000.0, 0.0], [122930000.0, 0.0], [122926000.0, 0.0024], [122918000.0, 0.0]], "asks": [[122962000.0, 0.0077], [122968000.0, 0.0003], [122969000.0, 0.0091], [122973000.0, 0.0253], [122974000.0, 0.0189], [122980000.0, 0.0004], [122984000.0, 0.0063], [122988000.0, 0.0023], [122994000.0, 0.1356], [122998000.0, 0.0203]]},
{"timestamp": "1743933401272", "bids": [[122960000.0, 0.1376], [122956000.0, 0.0], [122950000.0, 0.0061], [122949000.0, 0.0002], [122944000.0, 0.003], [122940000.0, 0.0], [122931000.0, 0.0], [122930000.0, 0.0], [122926000.0, 0.0024], [122918000.0, 0.0]], "asks": [[122962000.0, 0.0077], [122968000.0, 0.0003], [122969000.0, 0.0091], [122973000.0, 0.0253], [122974000.0, 0.0189], [122980000.0, 0.0004], [122984000.0, 0.0063], [122988000.0, 0.0023], [122992000.0, 0.1356], [122995000.0, 0.0847]]},
{"timestamp": "1743933401779", "bids": [[122960000.0, 0.1376], [122956000.0, 0.0], [122950000.0, 0.0061], [122949000.0, 0.0002], [122944000.0, 0.003], [122940000.0, 0.0], [122931000.0, 0.0], [122930000.0, 0.0], [122926000.0, 0.0024], [122918000.0, 0.0]], "asks": [[122962000.0, 0.0077], [122968000.0, 0.0003], [122969000.0, 0.0091], [122973000.0, 0.0253], [122974000.0, 0.0189], [122980000.0, 0.0004], [122984000.0, 0.0063], [122988000.0, 0.0023], [122991000.0, 0.0847], [122995000.0, 0.1356]]},
{"timestamp": "1743933402292", "bids": [[122960000.0, 0.1376], [122956000.0, 0.0], [122950000.0, 0.0061], [122949000.0, 0.0002], [122944000.0, 0.003], [122940000.0, 0.0], [122931000.0, 0.0], [122930000.0, 0.0], [122926000.0, 0.0024], [122918000.0, 0.0]], "asks": [[122962000.0, 0.0077], [122968000.0, 0.0003], [122969000.0, 0.0091], [122973000.0, 0.0253], [122974000.0, 0.0189], [122980000.0, 0.0004], [122984000.0, 0.0063], [122988000.0, 0.0023], [122990000.0, 0.1356], [122994000.0, 0.0847]]},
{"timestamp": "1743933402801", "bids": [[122960000.0, 0.1376], [122956000.0, 0.0], [122950000.0, 0.0061], [122949000.0, 0.0002], [122944000.0, 0.003], [122940000.0, 0.0], [122931000.0, 0.0], [122930000.0, 0.0], [122926000.0, 0.0024], [122918000.0, 0.0]], "asks": [[122962000.0, 0.0077], [122968000.0, 0.0003], [122969000.0, 0.0091], [122973000.0, 0.0253], [122974000.0, 0.0189], [122980000.0, 0.0004], [122984000.0, 0.0063], [122988000.0, 0.0023], [122989000.0, 0.0847], [122993000.0, 0.1356]]},
{"timestamp": "1743933403338", "bids": [[122960000.0, 0.1376], [122956000.0, 0.0], [122950000.0, 0.0061], [122949000.0, 0.0002], [122944000.0, 0.003], [122940000.0, 0.0], [122931000.0, 0.0], [122930000.0, 0.0], [122926000.0, 0.0024], [122918000.0, 0.0]], "asks": [[122962000.0, 0.0077], [122968000.0, 0.0003], [122969000.0, 0.0091], [122973000.0, 0.0253], [122974000.0, 0.0189], [122980000.0, 0.0004], [122984000.0, 0.0063], [122988000.0, 0.0023], [122992000.0, 0.0847], [122995000.0, 0.1356]]},
{"timestamp": "1743933403847", "bids": [[122960000.0, 0.1376], [122956000.0, 0.0], [122950000.0, 0.0061], [122949000.0, 0.0002], [122944000.0, 0.003], [122940000.0, 0.0], [122931000.0, 0.0], [122930000.0, 0.0], [122926000.0, 0.0024], [122918000.0, 0.0]], "asks": [[122962000.0, 0.0077], [122968000.0, 0.0003], [122969000.0, 0.0091], [122973000.0, 0.0253], [122974000.0, 0.0189], [122980000.0, 0.0004], [122984000.0, 0.0063], [122986000.0, 0.1356], [122988000.0, 0.0023], [122994000.0, 0.0847]]},
{"timestamp": "1743933404343", "bids": [[122960000.0, 0.1376], [122956000.0, 0.0], [122950000.0, 0.0061], [122949000.0, 0.0002], [122944000.0, 0.003], [122940000.0, 0.0], [122931000.0, 0.0], [122930000.0, 0.0], [122926000.0, 0.0024], [122918000.0, 0.0]], "asks": [[122962000.0, 0.0077], [122968000.0, 0.0003], [122969000.0, 0.0091], [122973000.0, 0.0253], [122974000.0, 0.0189], [122980000.0, 0.0004], [122984000.0, 0.0063], [122985000.0, 0.0847], [122988000.0, 0.0023], [122989000.0, 0.1356]]},
{"timestamp": "1743933404871", "bids": [[122961000.0, 0.0742], [122960000.0, 0.1376], [122956000.0, 0.0], [122950000.0, 0.0061], [122949000.0, 0.0002], [122944000.0, 0.003], [122940000.0, 0.0], [122931000.0, 0.0], [122930000.0, 0.0], [122926000.0, 0.0024]], "asks": [[122962000.0, 0.0077], [122968000.0, 0.0003], [122973000.0, 0.0006], [122974000.0, 0.0189], [122980000.0, 0.0004], [122984000.0, 0.0063], [122987000.0, 0.0023], [122989000.0, 0.1356], [123000000.0, 0.1049], [123001000.0, 0.0001]]},
{"timestamp": "1743933405367", "bids": [[122961000.0, 0.0742], [122960000.0, 0.1376], [122956000.0, 0.0], [122950000.0, 0.0061], [122949000.0, 0.0002], [122944000.0, 0.003], [122940000.0, 0.0], [122931000.0, 0.0], [122930000.0, 0.0], [122926000.0, 0.0024]], "asks": [[122968000.0, 0.0003], [122973000.0, 0.0006], [122980000.0, 0.0004], [122987000.0, 0.0023], [122989000.0, 0.1356], [122997000.0, 0.1356], [123000000.0, 0.1049], [123001000.0, 0.0001], [123003000.0, 0.0081], [123004000.0, 0.0001]]},
{"timestamp": "1743933405874", "bids": [[122961000.0, 0.03], [122960000.0, 0.1376], [122956000.0, 0.0], [122950000.0, 0.0061], [122949000.0, 0.0002], [122944000.0, 0.003], [122940000.0, 0.0], [122931000.0, 0.0], [122930000.0, 0.0], [122926000.0, 0.0024]], "asks": [[122968000.0, 0.0003], [122973000.0, 0.0006], [122980000.0, 0.0004], [122984000.0, 0.0169], [122987000.0, 0.0023], [122998000.0, 0.0247], [123000000.0, 0.1049], [123001000.0, 0.0001], [123003000.0, 0.0081], [123004000.0, 0.0001]]},
{"timestamp": "1743933406381", "bids": [[122961000.0, 0.03], [122960000.0, 0.1376], [122956000.0, 0.0], [122950000.0, 0.0061], [122949000.0, 0.0002], [122944000.0, 0.003], [122940000.0, 0.0], [122931000.0, 0.0], [122930000.0, 0.0], [122928000.0, 0.0156]], "asks": [[122968000.0, 0.0003], [122973000.0, 0.0006], [122980000.0, 0.0004], [122984000.0, 0.0169], [122987000.0, 0.0023], [122998000.0, 0.0247], [123000000.0, 0.1049], [123001000.0, 0.0001], [123003000.0, 0.0081], [123004000.0, 0.0001]]},
{"timestamp": "1743933406915", "bids": [[122962000.0, 0.0081], [122961000.0, 0.03], [122960000.0, 0.1376], [122956000.0, 0.0], [122950000.0, 0.0061], [122949000.0, 0.0002], [122944000.0, 0.003], [122940000.0, 0.0], [122931000.0, 0.0], [122930000.0, 0.0]], "asks": [[122968000.0, 0.0003], [122973000.0, 0.0006], [122980000.0, 0.0004], [122984000.0, 0.0169], [122987000.0, 0.0023], [122998000.0, 0.0247], [122999000.0, 0.1356], [123000000.0, 0.1049], [123001000.0, 0.0001], [123003000.0, 0.0081]]},
{"timestamp": "1743933407416", "bids": [[122963000.0, 0.0448], [122962000.0, 0.0081], [122961000.0, 0.03], [122960000.0, 0.1376], [122956000.0, 0.0], [122950000.0, 0.0061], [122949000.0, 0.0002], [122944000.0, 0.003], [122940000.0, 0.0], [122931000.0, 0.0]], "asks": [[122968000.0, 0.0003], [122973000.0, 0.0006], [122980000.0, 0.0004], [122984000.0, 0.0169], [122987000.0, 0.0023], [122998000.0, 0.0247], [122999000.0, 0.1356], [123000000.0, 0.1049], [123001000.0, 0.0001], [123003000.0, 0.0081]]},
{"timestamp": "1743933407941", "bids": [[122962000.0, 0.0081], [122960000.0, 0.1376], [122956000.0, 0.0], [122950000.0, 0.0061], [122949000.0, 0.0002], [122944000.0, 0.003], [122940000.0, 0.0], [122931000.0, 0.0], [122930000.0, 0.0], [122928000.0, 0.0156]], "asks": [[122968000.0, 0.0003], [122973000.0, 0.0006], [122980000.0, 0.0004], [122984000.0, 0.0169], [122987000.0, 0.0023], [122998000.0, 0.0247], [123000000.0, 0.1049], [123001000.0, 0.0001], [123003000.0, 0.0081], [123004000.0, 0.0001]]},
{"timestamp": "1743933408426", "bids": [[122962000.0, 0.0081], [122960000.0, 0.1376], [122956000.0, 0.0], [122950000.0, 0.0061], [122949000.0, 0.0002], [122944000.0, 0.003], [122940000.0, 0.0], [122931000.0, 0.0], [122930000.0, 0.0], [122928000.0, 0.0156]], "asks": [[122968000.0, 0.0003], [122973000.0, 0.0006], [122980000.0, 0.0004], [122984000.0, 0.0169], [122987000.0, 0.0023], [122998000.0, 0.0247], [123000000.0, 0.1049], [123001000.0, 0.0001], [123003000.0, 0.0081], [123004000.0, 0.0001]]},
{"timestamp": "1743933408939", "bids": [[122962000.0, 0.0081], [122960000.0, 0.1376], [122956000.0, 0.0], [122950000.0, 0.0061], [122949000.0, 0.0002], [122944000.0, 0.003], [122940000.0, 0.0], [122931000.0, 0.0], [122930000.0, 0.0], [122928000.0, 0.0156]], "asks": [[122968000.0, 0.0003], [122973000.0, 0.0006], [122980000.0, 0.0004], [122984000.0, 0.0169], [122987000.0, 0.0023], [122998000.0, 0.0247], [123000000.0, 0.1049], [123001000.0, 0.0001], [123003000.0, 0.0081], [123004000.0, 0.0001]]},
{"timestamp": "1743933409446", "bids": [[122962000.0, 0.0081], [122960000.0, 0.1376], [122956000.0, 0.0], [122950000.0, 0.0061], [122949000.0, 0.0002], [122944000.0, 0.003], [122940000.0, 0.0], [122931000.0, 0.0], [122930000.0, 0.0], [122928000.0, 0.0156]], "asks": [[122968000.0, 0.0003], [122973000.0, 0.0006], [122980000.0, 0.0004], [122984000.0, 0.0169], [122987000.0, 0.0023], [122998000.0, 0.0247], [122999000.0, 0.1356], [123000000.0, 0.1049], [123001000.0, 0.0001], [123003000.0, 0.0081]]},
{"timestamp": "1743933409982", "bids": [[122962000.0, 0.0081], [122960000.0, 0.1376], [122956000.0, 0.0], [122950000.0, 0.0061], [122949000.0, 0.0002], [122944000.0, 0.003], [122940000.0, 0.0], [122931000.0, 0.0], [122930000.0, 0.0], [122928000.0, 0.0156]], "asks": [[122968000.0, 0.0003], [122973000.0, 0.0006], [122980000.0, 0.0004], [122984000.0, 0.0169], [122987000.0, 0.0023], [122998000.0, 0.0247], [123000000.0, 0.1049], [123001000.0, 0.0001], [123003000.0, 0.0081], [123004000.0, 0.0001]]},
{"timestamp": "1743933410467", "bids": [[122962000.0, 0.0081], [122960000.0, 0.1376], [122956000.0, 0.0], [122950000.0, 0.0061], [122949000.0, 0.0002], [122944000.0, 0.003], [122940000.0, 0.0], [122931000.0, 0.0], [122930000.0, 0.0], [122928000.0, 0.0156]], "asks": [[122968000.0, 0.0003], [122973000.0, 0.0006], [122980000.0, 0.0004], [122984000.0, 0.0169], [122987000.0, 0.0023], [122998000.0, 0.0247], [123000000.0, 0.1049], [123001000.0, 0.0001], [123003000.0, 0.0081], [123004000.0, 0.0001]]},
{"timestamp": "1743933411021", "bids": [[122962000.0, 0.0081], [122960000.0, 0.1376], [122956000.0, 0.0], [122950000.0, 0.0061], [122949000.0, 0.0002], [122944000.0, 0.003], [122940000.0, 0.0], [122931000.0, 0.0], [122930000.0, 0.0], [122928000.0, 0.0156]], "asks": [[122968000.0, 0.0003], [122973000.0, 0.0006], [122980000.0, 0.0004], [122984000.0, 0.0169], [122987000.0, 0.0023], [122991000.0, 0.0023], [122998000.0, 0.0247], [122999000.0, 0.1356], [123000000.0, 0.1049], [123001000.0, 0.0001]]},
{"timestamp": "1743933411505", "bids": [[122962000.0, 0.0081], [122960000.0, 0.1376], [122956000.0, 0.0], [122950000.0, 0.0061], [122949000.0, 0.0002], [122944000.0, 0.003], [122940000.0, 0.0], [122931000.0, 0.0], [122930000.0, 0.0], [122928000.0, 0.0156]], "asks": [[122968000.0, 0.0003], [122973000.0, 0.0006], [122980000.0, 0.0004], [122984000.0, 0.0169], [122991000.0, 0.0023], [122998000.0, 0.0247], [122999000.0, 0.1356], [123000000.0, 0.1049], [123001000.0, 0.0001], [123003000.0, 0.0081]]},
{"timestamp": "1743933412025", "bids": [[122962000.0, 0.0081], [122960000.0, 0.1376], [122956000.0, 0.0], [122950000.0, 0.0061], [122949000.0, 0.0002], [122944000.0, 0.003], [122940000.0, 0.0], [122931000.0, 0.0], [122930000.0, 0.0], [122928000.0, 0.0156]], "asks": [[122968000.0, 0.0003], [122973000.0, 0.0006], [122980000.0, 0.0004], [122984000.0, 0.0169], [122991000.0, 0.0023], [122997000.0, 0.1356], [122998000.0, 0.0247], [123000000.0, 0.1049], [123001000.0, 0.0001], [123003000.0, 0.0081]]},
{"timestamp": "1743933412551", "bids": [[122962000.0, 0.0081], [122960000.0, 0.1376], [122956000.0, 0.0], [122950000.0, 0.0061], [122949000.0, 0.0002], [122944000.0, 0.003], [122940000.0, 0.0], [122931000.0, 0.0], [122930000.0, 0.0], [122928000.0, 0.0156]], "asks": [[122968000.0, 0.0003], [122973000.0, 0.0006], [122980000.0, 0.0004], [122984000.0, 0.0169], [122991000.0, 0.0023], [122997000.0, 0.1356], [122998000.0, 0.0247], [123000000.0, 0.1049], [123001000.0, 0.0001], [123003000.0, 0.0081]]},
{"timestamp": "1743933413069", "bids": [[122962000.0, 0.0081], [122960000.0, 0.1376], [122956000.0, 0.0], [122950000.0, 0.0061], [122949000.0, 0.0002], [122944000.0, 0.003], [122940000.0, 0.0], [122931000.0, 0.0], [122930000.0, 0.0], [122928000.0, 0.0156]], "asks": [[122968000.0, 0.0003], [122973000.0, 0.0006], [122980000.0, 0.0004], [122984000.0, 0.0169], [122991000.0, 0.0023], [122997000.0, 0.1356], [122998000.0, 0.0247], [123000000.0, 0.1049], [123001000.0, 0.0001], [123003000.0, 0.0081]]},
{"timestamp": "1743933413577", "bids": [[122962000.0, 0.0081], [122960000.0, 0.1376], [122956000.0, 0.0], [122950000.0, 0.0061], [122949000.0, 0.0002], [122944000.0, 0.003], [122940000.0, 0.0], [122931000.0, 0.0], [122930000.0, 0.0], [122928000.0, 0.0156]], "asks": [[122968000.0, 0.0003], [122973000.0, 0.0006], [122980000.0, 0.0004], [122984000.0, 0.0169], [122991000.0, 0.0023], [122998000.0, 0.0247], [122999000.0, 0.1356], [123000000.0, 0.1049], [123001000.0, 0.0001], [123003000.0, 0.0081]]},
{"timestamp": "1743933414094", "bids": [[122962000.0, 0.0081], [122960000.0, 0.1376], [122956000.0, 0.0], [122950000.0, 0.0061], [122949000.0, 0.0002], [122944000.0, 0.003], [122940000.0, 0.0], [122931000.0, 0.0], [122930000.0, 0.0], [122928000.0, 0.0156]], "asks": [[122968000.0, 0.0003], [122973000.0, 0.0006], [122980000.0, 0.0004], [122984000.0, 0.0169], [122991000.0, 0.0046], [122998000.0, 0.0247], [122999000.0, 0.1356], [123000000.0, 0.1049], [123001000.0, 0.0001], [123003000.0, 0.0081]]},
{"timestamp": "1743933414600", "bids": [[122968000.0, 0.0058], [122962000.0, 0.0081], [122960000.0, 0.1376], [122956000.0, 0.0], [122950000.0, 0.0061], [122949000.0, 0.0002], [122944000.0, 0.003], [122940000.0, 0.0], [122931000.0, 0.0], [122930000.0, 0.0]], "asks": [[122973000.0, 0.0006], [122980000.0, 0.0004], [122984000.0, 0.0169], [122991000.0, 0.0023], [122997000.0, 0.1356], [122998000.0, 0.0247], [123000000.0, 0.1049], [123001000.0, 0.0001], [123003000.0, 0.0081], [123004000.0, 0.0001]]},
{"timestamp": "1743933415098", "bids": [[122968000.0, 0.0058], [122962000.0, 0.0081], [122960000.0, 0.1376], [122956000.0, 0.0], [122950000.0, 0.0061], [122949000.0, 0.0002], [122944000.0, 0.003], [122940000.0, 0.0], [122931000.0, 0.0], [122930000.0, 0.0]], "asks": [[122973000.0, 0.0006], [122980000.0, 0.0004], [122984000.0, 0.0169], [122991000.0, 0.0023], [122997000.0, 0.1356], [122998000.0, 0.0247], [123000000.0, 0.1049], [123001000.0, 0.0001], [123003000.0, 0.0081], [123004000.0, 0.0001]]},
{"timestamp": "1743933415611", "bids": [[122968000.0, 0.0058], [122962000.0, 0.0081], [122960000.0, 0.1376], [122956000.0, 0.0], [122950000.0, 0.0061], [122949000.0, 0.0002], [122944000.0, 0.003], [122940000.0, 0.0], [122931000.0, 0.0], [122930000.0, 0.0]], "asks": [[122973000.0, 0.0006], [122980000.0, 0.0004], [122984000.0, 0.0169], [122991000.0, 0.0023], [122997000.0, 0.1356], [122998000.0, 0.0247], [123000000.0, 0.1049], [123001000.0, 0.0001], [123003000.0, 0.0081], [123004000.0, 0.0001]]},
{"timestamp": "1743933416133", "bids": [[122968000.0, 0.0058], [122962000.0, 0.0081], [122960000.0, 0.1376], [122956000.0, 0.0], [122950000.0, 0.0061], [122949000.0, 0.0002], [122944000.0, 0.003], [122940000.0, 0.0], [122931000.0, 0.0], [122930000.0, 0.0]], "asks": [[122973000.0, 0.0006], [122980000.0, 0.0004], [122984000.0, 0.0169], [122991000.0, 0.0023], [122997000.0, 0.1356], [122998000.0, 0.0247], [123000000.0, 0.1049], [123001000.0, 0.0001], [123003000.0, 0.0081], [123004000.0, 0.0001]]},
{"timestamp": "1743933416624", "bids": [[122968000.0, 0.0058], [122962000.0, 0.0081], [122960000.0, 0.1376], [122956000.0, 0.0], [122950000.0, 0.0061], [122949000.0, 0.0002], [122944000.0, 0.003], [122940000.0, 0.0], [122931000.0, 0.0], [122930000.0, 0.0]], "asks": [[122973000.0, 0.0006], [122980000.0, 0.0004], [122984000.0, 0.0169], [122991000.0, 0.0023], [122997000.0, 0.1356], [122998000.0, 0.0247], [123000000.0, 0.1049], [123001000.0, 0.0001], [123003000.0, 0.0081], [123004000.0, 0.0001]]},
{"timestamp": "1743933417126", "bids": [[122968000.0, 0.0058], [122962000.0, 0.0081], [122960000.0, 0.1376], [122956000.0, 0.0], [122950000.0, 0.0061], [122949000.0, 0.0002], [122944000.0, 0.003], [122940000.0, 0.0], [122931000.0, 0.0], [122930000.0, 0.0]], "asks": [[122973000.0, 0.0006], [122980000.0, 0.0004], [122984000.0, 0.0169], [122991000.0, 0.0023], [122997000.0, 0.1356], [122998000.0, 0.0247], [123000000.0, 0.1049], [123001000.0, 0.0001], [123003000.0, 0.0081], [123004000.0, 0.0001]]},
{"timestamp": "1743933417642", "bids": [[122968000.0, 0.0058], [122962000.0, 0.0081], [122960000.0, 0.1376], [122956000.0, 0.0], [122950000.0, 0.0061], [122949000.0, 0.0002], [122944000.0, 0.003], [122940000.0, 0.0], [122931000.0, 0.0], [122930000.0, 0.0]], "asks": [[122973000.0, 0.0006], [122980000.0, 0.0004], [122984000.0, 0.0169], [122991000.0, 0.0023], [122997000.0, 0.1356], [122998000.0, 0.0247], [123000000.0, 0.1049], [123001000.0, 0.0001], [123003000.0, 0.0081], [123004000.0, 0.0001]]},
{"timestamp": "1743933418141", "bids": [[122968000.0, 0.0058], [122962000.0, 0.0081], [122960000.0, 0.1376], [122956000.0, 0.0], [122950000.0, 0.0061], [122949000.0, 0.0002], [122944000.0, 0.003], [122940000.0, 0.0], [122931000.0, 0.0], [122930000.0, 0.0]], "asks": [[122973000.0, 0.0006], [122980000.0, 0.0004], [122984000.0, 0.0169], [122991000.0, 0.0023], [122997000.0, 0.1356], [122998000.0, 0.0247], [123000000.0, 0.1049], [123001000.0, 0.0001], [123003000.0, 0.0081], [123004000.0, 0.0001]]},
{"timestamp": "1743933418687", "bids": [[122968000.0, 0.0058], [122962000.0, 0.0081], [122960000.0, 0.1376], [122956000.0, 0.0], [122950000.0, 0.0061], [122949000.0, 0.0002], [122944000.0, 0.003], [122940000.0, 0.0], [122931000.0, 0.0], [122930000.0, 0.0]], "asks": [[122973000.0, 0.0006], [122980000.0, 0.0004], [122984000.0, 0.0169], [122991000.0, 0.0023], [122997000.0, 0.1356], [122998000.0, 0.0247], [123000000.0, 0.1049], [123001000.0, 0.0001], [123003000.0, 0.0081], [123004000.0, 0.0001]]},
{"timestamp": "1743933419199", "bids": [[122962000.0, 0.0058], [122960000.0, 0.1376], [122956000.0, 0.0], [122950000.0, 0.0061], [122949000.0, 0.0002], [122944000.0, 0.003], [122940000.0, 0.0], [122931000.0, 0.0], [122930000.0, 0.0], [122928000.0, 0.0156]], "asks": [[122973000.0, 0.0006], [122980000.0, 0.0004], [122984000.0, 0.0169], [122991000.0, 0.0023], [122997000.0, 0.1356], [122998000.0, 0.0247], [123000000.0, 0.1049], [123001000.0, 0.0001], [123003000.0, 0.0081], [123004000.0, 0.0001]]},
{"timestamp": "1743933419679", "bids": [[122962000.0, 0.0058], [122960000.0, 0.1376], [122956000.0, 0.0], [122950000.0, 0.0061], [122949000.0, 0.0002], [122944000.0, 0.003], [122940000.0, 0.0], [122931000.0, 0.0], [122930000.0, 0.0], [122928000.0, 0.0156]], "asks": [[122973000.0, 0.0006], [122980000.0, 0.0004], [122984000.0, 0.0169], [122991000.0, 0.0023], [122997000.0, 0.1356], [122998000.0, 0.0247], [123000000.0, 0.1049], [123001000.0, 0.0001], [123003000.0, 0.0081], [123004000.0, 0.0001]]},
{"timestamp": "1743933420182", "bids": [[122962000.0, 0.0058], [122960000.0, 0.1376], [122956000.0, 0.0], [122950000.0, 0.0061], [122949000.0, 0.0002], [122944000.0, 0.003], [122940000.0, 0.0], [122931000.0, 0.0], [122930000.0, 0.0], [122928000.0, 0.0156]], "asks": [[122973000.0, 0.0006], [122980000.0, 0.0004], [122984000.0, 0.0169], [122991000.0, 0.0023], [122997000.0, 0.1356], [122998000.0, 0.0247], [123000000.0, 0.1049], [123001000.0, 0.0001], [123003000.0, 0.0081], [123004000.0, 0.0001]]},
{"timestamp": "1743933420705", "bids": [[122962000.0, 0.0058], [122960000.0, 0.1376], [122956000.0, 0.0], [122950000.0, 0.0061], [122949000.0, 0.0002], [122944000.0, 0.003], [122940000.0, 0.0], [122931000.0, 0.0], [122930000.0, 0.0], [122928000.0, 0.0156]], "asks": [[122973000.0, 0.0006], [122980000.0, 0.0004], [122984000.0, 0.0169], [122991000.0, 0.0023], [122997000.0, 0.1356], [122998000.0, 0.0247], [123000000.0, 0.1049], [123001000.0, 0.0001], [123003000.0, 0.0081], [123004000.0, 0.0001]]},
{"timestamp": "1743933421205", "bids": [[122962000.0, 0.0058], [122960000.0, 0.1376], [122956000.0, 0.0], [122950000.0, 0.0061], [122949000.0, 0.0002], [122944000.0, 0.003], [122940000.0, 0.0], [122931000.0, 0.0], [122930000.0, 0.0], [122928000.0, 0.0156]], "asks": [[122972000.0, 0.0975], [122973000.0, 0.0006], [122980000.0, 0.0004], [122984000.0, 0.0169], [122991000.0, 0.0023], [122997000.0, 0.1379], [122998000.0, 0.0247], [123000000.0, 0.1049], [123001000.0, 0.0001], [123003000.0, 0.0081]]},
{"timestamp": "1743933421726", "bids": [[122962000.0, 0.0058], [122960000.0, 0.1376], [122956000.0, 0.0], [122950000.0, 0.0061], [122949000.0, 0.0002], [122944000.0, 0.003], [122940000.0, 0.0], [122931000.0, 0.0], [122930000.0, 0.0], [122928000.0, 0.0156]], "asks": [[122972000.0, 0.0975], [122973000.0, 0.0006], [122980000.0, 0.0004], [122984000.0, 0.0169], [122996000.0, 0.0845], [122997000.0, 0.0023], [122998000.0, 0.0247], [122999000.0, 0.1352], [123000000.0, 0.1049], [123001000.0, 0.0001]]},
{"timestamp": "1743933422257", "bids": [[122962000.0, 0.0058], [122960000.0, 0.1376], [122956000.0, 0.0], [122950000.0, 0.0061], [122949000.0, 0.0002], [122944000.0, 0.003], [122940000.0, 0.0], [122931000.0, 0.0], [122930000.0, 0.0], [122928000.0, 0.0156]], "asks": [[122973000.0, 0.0006], [122980000.0, 0.0004], [122984000.0, 0.0169], [122996000.0, 0.0845], [122997000.0, 0.0023], [122998000.0, 0.0247], [123000000.0, 0.1049], [123001000.0, 0.0001], [123003000.0, 0.0081], [123004000.0, 0.0001]]},
{"timestamp": "1743933422733", "bids": [[122962000.0, 0.0058], [122960000.0, 0.1376], [122956000.0, 0.0], [122950000.0, 0.0061], [122949000.0, 0.0002], [122944000.0, 0.003], [122940000.0, 0.0], [122931000.0, 0.0], [122930000.0, 0.0], [122928000.0, 0.0156]], "asks": [[122973000.0, 0.0006], [122980000.0, 0.0004], [122984000.0, 0.0169], [122996000.0, 0.0845], [122997000.0, 0.0023], [122998000.0, 0.0247], [123000000.0, 0.1049], [123001000.0, 0.0001], [123003000.0, 0.0081], [123004000.0, 0.0001]]},
{"timestamp": "1743933423251", "bids": [[122962000.0, 0.0058], [122960000.0, 0.1376], [122956000.0, 0.0], [122950000.0, 0.0061], [122949000.0, 0.0002], [122944000.0, 0.003], [122940000.0, 0.0], [122931000.0, 0.0], [122930000.0, 0.0], [122928000.0, 0.0156]], "asks": [[122973000.0, 0.0006], [122980000.0, 0.0004], [122984000.0, 0.0169], [122995000.0, 0.1352], [122997000.0, 0.0868], [122998000.0, 0.0247], [123000000.0, 0.1049], [123001000.0, 0.0001], [123003000.0, 0.0081], [123004000.0, 0.0001]]},
{"timestamp": "1743933423792", "bids": [[122962000.0, 0.0058], [122960000.0, 0.1376], [122956000.0, 0.0], [122950000.0, 0.0061], [122949000.0, 0.0002], [122944000.0, 0.003], [122940000.0, 0.0], [122931000.0, 0.0], [122930000.0, 0.0], [122928000.0, 0.0156]], "asks": [[122973000.0, 0.0006], [122980000.0, 0.0004], [122984000.0, 0.0169], [122994000.0, 0.0845], [122996000.0, 0.1352], [122997000.0, 0.0023], [122998000.0, 0.0247], [123000000.0, 0.1049], [123001000.0, 0.0001], [123003000.0, 0.0081]]},
{"timestamp": "1743933424292", "bids": [[122962000.0, 0.0058], [122960000.0, 0.1376], [122956000.0, 0.0], [122950000.0, 0.0061], [122949000.0, 0.0002], [122944000.0, 0.003], [122940000.0, 0.0], [122931000.0, 0.0], [122930000.0, 0.0], [122928000.0, 0.0156]], "asks": [[122973000.0, 0.0006], [122980000.0, 0.0004], [122984000.0, 0.0169], [122993000.0, 0.1352], [122995000.0, 0.0845], [122997000.0, 0.1375], [122998000.0, 0.0247], [123000000.0, 0.1049], [123001000.0, 0.0001], [123003000.0, 0.0081]]},
{"timestamp": "1743933424811", "bids": [[122962000.0, 0.0058], [122960000.0, 0.1376], [122956000.0, 0.0], [122950000.0, 0.0061], [122949000.0, 0.0002], [122944000.0, 0.003], [122940000.0, 0.0], [122931000.0, 0.0], [122930000.0, 0.0], [122926000.0, 0.0024]], "asks": [[122973000.0, 0.0006], [122980000.0, 0.0004], [122984000.0, 0.0169], [122992000.0, 0.0845], [122993000.0, 0.1352], [122994000.0, 0.0023], [122998000.0, 0.0247], [123000000.0, 0.1049], [123001000.0, 0.0001], [123003000.0, 0.0081]]},
{"timestamp": "1743933425300", "bids": [[122962000.0, 0.0058], [122960000.0, 0.1376], [122956000.0, 0.0], [122950000.0, 0.0061], [122949000.0, 0.0002], [122944000.0, 0.003], [122940000.0, 0.0], [122932000.0, 0.0156], [122931000.0, 0.0], [122930000.0, 0.0]], "asks": [[122973000.0, 0.0006], [122980000.0, 0.0004], [122984000.0, 0.0169], [122991000.0, 0.1352], [122994000.0, 0.0023], [122998000.0, 0.0247], [123000000.0, 0.1049], [123001000.0, 0.0001], [123003000.0, 0.0081], [123004000.0, 0.0001]]},
{"timestamp": "1743933425839", "bids": [[122962000.0, 0.0058], [122960000.0, 0.1376], [122956000.0, 0.0], [122950000.0, 0.0061], [122949000.0, 0.0002], [122944000.0, 0.003], [122940000.0, 0.0], [122932000.0, 0.0156], [122931000.0, 0.0], [122930000.0, 0.0]], "asks": [[122973000.0, 0.0006], [122980000.0, 0.0004], [122984000.0, 0.0169], [122994000.0, 0.0023], [122997000.0, 0.2197], [122998000.0, 0.0247], [123000000.0, 0.1049], [123001000.0, 0.0001], [123003000.0, 0.0081], [123004000.0, 0.0001]]},
{"timestamp": "1743933426341", "bids": [[122962000.0, 0.0058], [122960000.0, 0.1376], [122956000.0, 0.0], [122950000.0, 0.0061], [122949000.0, 0.0002], [122944000.0, 0.003], [122940000.0, 0.0], [122932000.0, 0.0156], [122931000.0, 0.0], [122930000.0, 0.0]], "asks": [[122984000.0, 0.0079], [122994000.0, 0.0023], [122997000.0, 0.1352], [122998000.0, 0.0247], [122999000.0, 0.0845], [123000000.0, 0.1049], [123001000.0, 0.0001], [123003000.0, 0.0081], [123004000.0, 0.0001], [123005000.0, 0.0081]]},
{"timestamp": "1743933426878", "bids": [[122962000.0, 0.0058], [122960000.0, 0.1376], [122956000.0, 0.0], [122950000.0, 0.0061], [122949000.0, 0.0002], [122944000.0, 0.003], [122940000.0, 0.0], [122932000.0, 0.0156], [122931000.0, 0.0], [122930000.0, 0.0]], "asks": [[122984000.0, 0.0079], [122994000.0, 0.0023], [122997000.0, 0.1352], [122998000.0, 0.0247], [123000000.0, 0.1049], [123001000.0, 0.0001], [123003000.0, 0.0081], [123004000.0, 0.0001], [123005000.0, 0.0081], [123006000.0, 0.0081]]},
{"timestamp": "1743933427382", "bids": [[122962000.0, 0.0058], [122960000.0, 0.1376], [122956000.0, 0.0], [122950000.0, 0.0061], [122949000.0, 0.0002], [122944000.0, 0.003], [122940000.0, 0.0], [122932000.0, 0.0156], [122931000.0, 0.0], [122930000.0, 0.0]], "asks": [[122984000.0, 0.0079], [122994000.0, 0.0023], [122997000.0, 0.1352], [122998000.0, 0.0247], [123000000.0, 0.1049], [123001000.0, 0.0001], [123003000.0, 0.0081], [123004000.0, 0.0001], [123005000.0, 0.0081], [123006000.0, 0.0081]]},
{"timestamp": "1743933427893", "bids": [[122962000.0, 0.0058], [122960000.0, 0.1376], [122956000.0, 0.0], [122950000.0, 0.0061], [122949000.0, 0.0002], [122944000.0, 0.003], [122940000.0, 0.0], [122932000.0, 0.0156], [122931000.0, 0.0], [122930000.0, 0.0]], "asks": [[122984000.0, 0.0079], [122994000.0, 0.0023], [122997000.0, 0.1352], [122998000.0, 0.0247], [123000000.0, 0.1049], [123001000.0, 0.0001], [123003000.0, 0.0081], [123004000.0, 0.0001], [123005000.0, 0.0081], [123006000.0, 0.0081]]},
{"timestamp": "1743933428371", "bids": [[122962000.0, 0.0058], [122960000.0, 0.1376], [122956000.0, 0.0], [122950000.0, 0.0061], [122949000.0, 0.0002], [122944000.0, 0.003], [122940000.0, 0.0], [122932000.0, 0.0156], [122931000.0, 0.0], [122930000.0, 0.0]], "asks": [[122984000.0, 0.0079], [122997000.0, 0.1352], [122998000.0, 0.0247], [123000000.0, 0.1049], [123001000.0, 0.0024], [123003000.0, 0.0081], [123004000.0, 0.0001], [123005000.0, 0.0081], [123006000.0, 0.0081], [123007000.0, 0.0082]]},
{"timestamp": "1743933428893", "bids": [[122962000.0, 0.0058], [122960000.0, 0.1376], [122956000.0, 0.0], [122950000.0, 0.0061], [122949000.0, 0.0002], [122944000.0, 0.003], [122940000.0, 0.0], [122932000.0, 0.0156], [122931000.0, 0.0], [122930000.0, 0.0]], "asks": [[122984000.0, 0.0079], [122997000.0, 0.1352], [122998000.0, 0.0247], [123000000.0, 0.1049], [123001000.0, 0.0024], [123003000.0, 0.0081], [123004000.0, 0.0001], [123005000.0, 0.0081], [123006000.0, 0.0081], [123007000.0, 0.0082]]},
{"timestamp": "1743933429428", "bids": [[122962000.0, 0.0058], [122960000.0, 0.1376], [122956000.0, 0.0], [122950000.0, 0.0061], [122949000.0, 0.0002], [122944000.0, 0.003], [122940000.0, 0.0], [122932000.0, 0.0156], [122931000.0, 0.0], [122930000.0, 0.0]], "asks": [[122984000.0, 0.0079], [122997000.0, 0.1352], [122998000.0, 0.0247], [123000000.0, 0.1049], [123001000.0, 0.0024], [123003000.0, 0.0081], [123004000.0, 0.0001], [123005000.0, 0.0081], [123006000.0, 0.0081], [123007000.0, 0.0082]]},
{"timestamp": "1743933429935", "bids": [[122962000.0, 0.0058], [122960000.0, 0.1376], [122956000.0, 0.0], [122950000.0, 0.0061], [122949000.0, 0.0002], [122944000.0, 0.003], [122940000.0, 0.0], [122932000.0, 0.0156], [122931000.0, 0.0], [122930000.0, 0.0]], "asks": [[122984000.0, 0.0079], [122997000.0, 0.1352], [122998000.0, 0.0247], [123000000.0, 0.1049], [123001000.0, 0.0024], [123003000.0, 0.0081], [123004000.0, 0.0001], [123005000.0, 0.0081], [123006000.0, 0.0081], [123007000.0, 0.0082]]},
{"timestamp": "1743933430412", "bids": [[122962000.0, 0.0058], [122960000.0, 0.1376], [122956000.0, 0.0], [122950000.0, 0.0061], [122949000.0, 0.0002], [122944000.0, 0.003], [122940000.0, 0.0], [122932000.0, 0.0156], [122931000.0, 0.0], [122930000.0, 0.0]], "asks": [[122984000.0, 0.0079], [122997000.0, 0.1352], [122998000.0, 0.0247], [123000000.0, 0.1049], [123001000.0, 0.0024], [123003000.0, 0.0081], [123004000.0, 0.0001], [123005000.0, 0.0081], [123006000.0, 0.0081], [123007000.0, 0.0082]]},
{"timestamp": "1743933430940", "bids": [[122962000.0, 0.0058], [122960000.0, 0.1376], [122956000.0, 0.0], [122950000.0, 0.0061], [122949000.0, 0.0002], [122944000.0, 0.003], [122940000.0, 0.0], [122932000.0, 0.0156], [122931000.0, 0.0], [122930000.0, 0.0]], "asks": [[122984000.0, 0.0079], [122996000.0, 0.0843], [122997000.0, 0.1352], [122998000.0, 0.0247], [123000000.0, 0.1049], [123001000.0, 0.0024], [123003000.0, 0.0081], [123004000.0, 0.0001], [123005000.0, 0.0081], [123006000.0, 0.0081]]},
{"timestamp": "1743933431446", "bids": [[122962000.0, 0.0058], [122960000.0, 0.1376], [122956000.0, 0.0], [122950000.0, 0.0061], [122949000.0, 0.0002], [122944000.0, 0.003], [122940000.0, 0.0], [122932000.0, 0.0156], [122931000.0, 0.0], [122930000.0, 0.0]], "asks": [[122984000.0, 0.0079], [122995000.0, 0.1349], [122996000.0, 0.0843], [122998000.0, 0.0247], [123000000.0, 0.1049], [123001000.0, 0.0024], [123003000.0, 0.0081], [123004000.0, 0.0001], [123005000.0, 0.0081], [123006000.0, 0.0081]]},
{"timestamp": "1743933432001", "bids": [[122962000.0, 0.0058], [122960000.0, 0.1376], [122956000.0, 0.0], [122950000.0, 0.0061], [122949000.0, 0.0002], [122944000.0, 0.003], [122940000.0, 0.0], [122932000.0, 0.0156], [122931000.0, 0.0], [122930000.0, 0.0]], "asks": [[122984000.0, 0.0079], [122994000.0, 0.0843], [122998000.0, 0.0247], [123000000.0, 0.1049], [123001000.0, 0.0024], [123003000.0, 0.0081], [123004000.0, 0.0001], [123005000.0, 0.0081], [123006000.0, 0.0081], [123007000.0, 0.0082]]},
{"timestamp": "1743933432487", "bids": [[122962000.0, 0.0058], [122960000.0, 0.1376], [122956000.0, 0.0], [122950000.0, 0.0061], [122949000.0, 0.0002], [122944000.0, 0.003], [122940000.0, 0.0], [122932000.0, 0.0156], [122931000.0, 0.0], [122930000.0, 0.0]], "asks": [[122984000.0, 0.0079], [122996000.0, 0.1349], [122998000.0, 0.0247], [123000000.0, 0.1049], [123001000.0, 0.0024], [123003000.0, 0.0081], [123004000.0, 0.0001], [123005000.0, 0.0081], [123006000.0, 0.0081], [123007000.0, 0.0082]]},
{"timestamp": "1743933433008", "bids": [[122962000.0, 0.0058], [122960000.0, 0.1376], [122956000.0, 0.0], [122950000.0, 0.0061], [122949000.0, 0.0002], [122944000.0, 0.003], [122940000.0, 0.0], [122932000.0, 0.0156], [122931000.0, 0.0], [122930000.0, 0.0]], "asks": [[122984000.0, 0.0079], [122997000.0, 0.1349], [122998000.0, 0.0247], [123000000.0, 0.1049], [123001000.0, 0.0024], [123003000.0, 0.0081], [123004000.0, 0.0001], [123005000.0, 0.0081], [123006000.0, 0.0081], [123007000.0, 0.0082]]},
{"timestamp": "1743933433512", "bids": [[122962000.0, 0.0058], [122960000.0, 0.1376], [122956000.0, 0.0], [122950000.0, 0.0061], [122949000.0, 0.0002], [122944000.0, 0.003], [122940000.0, 0.0], [122932000.0, 0.0156], [122931000.0, 0.0], [122930000.0, 0.0]], "asks": [[122984000.0, 0.0079], [122996000.0, 0.0843], [122997000.0, 0.1349], [122998000.0, 0.0247], [123000000.0, 0.1049], [123001000.0, 0.0024], [123003000.0, 0.0081], [123004000.0, 0.0001], [123005000.0, 0.0081], [123006000.0, 0.0081]]},
{"timestamp": "1743933434005", "bids": [[122962000.0, 0.0058], [122960000.0, 0.1376], [122956000.0, 0.0], [122950000.0, 0.0061], [122949000.0, 0.0002], [122944000.0, 0.003], [122940000.0, 0.0], [122932000.0, 0.0156], [122931000.0, 0.0], [122930000.0, 0.0]], "asks": [[122984000.0, 0.0079], [122995000.0, 0.1349], [122998000.0, 0.0247], [123000000.0, 0.1049], [123001000.0, 0.0024], [123003000.0, 0.0081], [123004000.0, 0.0001], [123005000.0, 0.0081], [123006000.0, 0.0081], [123007000.0, 0.0082]]},
{"timestamp": "1743933434516", "bids": [[122962000.0, 0.0058], [122960000.0, 0.1376], [122956000.0, 0.0], [122950000.0, 0.0061], [122949000.0, 0.0002], [122944000.0, 0.003], [122940000.0, 0.0], [122932000.0, 0.0156], [122931000.0, 0.0], [122930000.0, 0.0]], "asks": [[122984000.0, 0.0079], [122997000.0, 0.1349], [122998000.0, 0.0247], [123000000.0, 0.1049], [123001000.0, 0.0024], [123003000.0, 0.0081], [123004000.0, 0.0001], [123005000.0, 0.0081], [123006000.0, 0.0081], [123007000.0, 0.0082]]},
{"timestamp": "1743933435046", "bids": [[122962000.0, 0.0058], [122960000.0, 0.1376], [122956000.0, 0.0], [122950000.0, 0.0061], [122949000.0, 0.0002], [122944000.0, 0.003], [122940000.0, 0.0], [122932000.0, 0.0156], [122931000.0, 0.0], [122930000.0, 0.0]], "asks": [[122984000.0, 0.0079], [122997000.0, 0.1349], [122998000.0, 0.0247], [123000000.0, 0.1049], [123001000.0, 0.0024], [123003000.0, 0.0081], [123004000.0, 0.0001], [123005000.0, 0.0081], [123006000.0, 0.0081], [123007000.0, 0.0082]]},
{"timestamp": "1743933435555", "bids": [[122962000.0, 0.0058], [122960000.0, 0.1376], [122956000.0, 0.0], [122950000.0, 0.0061], [122949000.0, 0.0002], [122944000.0, 0.003], [122940000.0, 0.0], [122932000.0, 0.0156], [122931000.0, 0.0], [122930000.0, 0.0]], "asks": [[122984000.0, 0.0079], [122997000.0, 0.1349], [122998000.0, 0.0247], [123000000.0, 0.1049], [123001000.0, 0.0024], [123003000.0, 0.0081], [123004000.0, 0.0001], [123005000.0, 0.0081], [123006000.0, 0.0081], [123007000.0, 0.0082]]},
{"timestamp": "1743933436067", "bids": [[122962000.0, 0.0058], [122960000.0, 0.1376], [122956000.0, 0.0], [122950000.0, 0.0061], [122949000.0, 0.0002], [122944000.0, 0.003], [122940000.0, 0.0], [122932000.0, 0.0156], [122931000.0, 0.0], [122930000.0, 0.0]], "asks": [[122984000.0, 0.0079], [122996000.0, 0.0843], [122997000.0, 0.1349], [122998000.0, 0.0247], [123000000.0, 0.1049], [123001000.0, 0.0024], [123003000.0, 0.0081], [123004000.0, 0.0001], [123005000.0, 0.0081], [123006000.0, 0.0081]]},
{"timestamp": "1743933436552", "bids": [[122962000.0, 0.0058], [122960000.0, 0.1376], [122956000.0, 0.0], [122950000.0, 0.0061], [122949000.0, 0.0002], [122944000.0, 0.003], [122940000.0, 0.0], [122932000.0, 0.0156], [122931000.0, 0.0], [122930000.0, 0.0]], "asks": [[122984000.0, 0.0079], [122995000.0, 0.1349], [122996000.0, 0.0843], [122998000.0, 0.0247], [123000000.0, 0.1049], [123001000.0, 0.0024], [123003000.0, 0.0081], [123004000.0, 0.0001], [123005000.0, 0.0081], [123006000.0, 0.0081]]},
{"timestamp": "1743933437094", "bids": [[122962000.0, 0.0058], [122960000.0, 0.1376], [122956000.0, 0.0], [122950000.0, 0.0061], [122949000.0, 0.0002], [122944000.0, 0.003], [122940000.0, 0.0], [122932000.0, 0.0156], [122931000.0, 0.0], [122930000.0, 0.0]], "asks": [[122984000.0, 0.0079], [122993000.0, 0.1349], [122998000.0, 0.0247], [123000000.0, 0.1049], [123001000.0, 0.0024], [123003000.0, 0.0081], [123004000.0, 0.0001], [123005000.0, 0.0081], [123006000.0, 0.0081], [123007000.0, 0.0082]]},
{"timestamp": "1743933437614", "bids": [[122962000.0, 0.0058], [122960000.0, 0.1376], [122956000.0, 0.0], [122950000.0, 0.0061], [122949000.0, 0.0002], [122944000.0, 0.003], [122940000.0, 0.0], [122932000.0, 0.0156], [122931000.0, 0.0], [122930000.0, 0.0]], "asks": [[122984000.0, 0.0079], [122997000.0, 0.2192], [122998000.0, 0.0247], [123000000.0, 0.1049], [123001000.0, 0.0024], [123003000.0, 0.0081], [123004000.0, 0.0001], [123005000.0, 0.0081], [123006000.0, 0.0081], [123007000.0, 0.0082]]},
{"timestamp": "1743933438146", "bids": [[122962000.0, 0.0058], [122960000.0, 0.1376], [122956000.0, 0.0], [122950000.0, 0.0061], [122949000.0, 0.0002], [122944000.0, 0.003], [122940000.0, 0.0], [122932000.0, 0.0156], [122931000.0, 0.0], [122930000.0, 0.0]], "asks": [[122984000.0, 0.0079], [122997000.0, 0.1349], [122998000.0, 0.0247], [123000000.0, 0.1049], [123001000.0, 0.0024], [123003000.0, 0.0081], [123004000.0, 0.0001], [123005000.0, 0.0081], [123006000.0, 0.0081], [123007000.0, 0.0082]]},
{"timestamp": "1743933438676", "bids": [[122962000.0, 0.0058], [122960000.0, 0.1376], [122956000.0, 0.0], [122950000.0, 0.0061], [122949000.0, 0.0002], [122944000.0, 0.003], [122940000.0, 0.0], [122932000.0, 0.0156], [122931000.0, 0.0], [122930000.0, 0.0]], "asks": [[122984000.0, 0.0079], [122996000.0, 0.1349], [122997000.0, 0.0843], [122998000.0, 0.0247], [123000000.0, 0.1049], [123001000.0, 0.0024], [123003000.0, 0.0081], [123004000.0, 0.0001], [123005000.0, 0.0081], [123006000.0, 0.0081]]},
{"timestamp": "1743933439146", "bids": [[122962000.0, 0.0058], [122960000.0, 0.1376], [122956000.0, 0.0], [122950000.0, 0.0061], [122949000.0, 0.0002], [122944000.0, 0.003], [122940000.0, 0.0], [122932000.0, 0.0156], [122931000.0, 0.0], [122930000.0, 0.0]], "asks": [[122984000.0, 0.0079], [122996000.0, 0.1349], [122998000.0, 0.0247], [123000000.0, 0.1049], [123001000.0, 0.0024], [123003000.0, 0.0081], [123004000.0, 0.0001], [123005000.0, 0.0081], [123006000.0, 0.0081], [123007000.0, 0.0082]]},
{"timestamp": "1743933439700", "bids": [[122962000.0, 0.0058], [122960000.0, 0.1376], [122956000.0, 0.0], [122950000.0, 0.0061], [122949000.0, 0.0002], [122944000.0, 0.003], [122940000.0, 0.0], [122932000.0, 0.0156], [122931000.0, 0.0], [122930000.0, 0.0]], "asks": [[122984000.0, 0.0079], [122996000.0, 0.0843], [122997000.0, 0.1349], [122998000.0, 0.0247], [123000000.0, 0.1049], [123001000.0, 0.0024], [123002000.0, 0.0023], [123003000.0, 0.0081], [123004000.0, 0.0001], [123005000.0, 0.0081]]},
{"timestamp": "1743933440257", "bids": [[122962000.0, 0.0058], [122960000.0, 0.1376], [122956000.0, 0.0], [122950000.0, 0.0061], [122949000.0, 0.0002], [122944000.0, 0.003], [122940000.0, 0.0], [122932000.0, 0.0156], [122931000.0, 0.0], [122930000.0, 0.0]], "asks": [[122984000.0, 0.0079], [122995000.0, 0.1349], [122996000.0, 0.0843], [122998000.0, 0.0247], [123000000.0, 0.1049], [123001000.0, 0.0001], [123002000.0, 0.0023], [123003000.0, 0.0081], [123004000.0, 0.0001], [123005000.0, 0.0081]]},
{"timestamp": "1743933440738", "bids": [[122962000.0, 0.0058], [122960000.0, 0.1376], [122956000.0, 0.0], [122950000.0, 0.0061], [122949000.0, 0.0002], [122944000.0, 0.003], [122940000.0, 0.0], [122932000.0, 0.0156], [122931000.0, 0.0], [122930000.0, 0.0]], "asks": [[122984000.0, 0.0079], [122994000.0, 0.0843], [122995000.0, 0.1349], [122998000.0, 0.0247], [123000000.0, 0.1049], [123001000.0, 0.0001], [123002000.0, 0.0023], [123003000.0, 0.0081], [123004000.0, 0.0001], [123005000.0, 0.0081]]},
{"timestamp": "1743933441192", "bids": [[122962000.0, 0.0058], [122960000.0, 0.1376], [122956000.0, 0.0], [122950000.0, 0.0061], [122949000.0, 0.0002], [122944000.0, 0.003], [122940000.0, 0.0], [122932000.0, 0.0156], [122931000.0, 0.0], [122930000.0, 0.0]], "asks": [[122984000.0, 0.0079], [122993000.0, 0.1349], [122998000.0, 0.0247], [123000000.0, 0.1049], [123001000.0, 0.0001], [123002000.0, 0.0023], [123003000.0, 0.0081], [123004000.0, 0.0001], [123005000.0, 0.0081], [123006000.0, 0.0081]]},
{"timestamp": "1743933441722", "bids": [[122962000.0, 0.0058], [122960000.0, 0.1376], [122956000.0, 0.0], [122950000.0, 0.0061], [122949000.0, 0.0002], [122944000.0, 0.003], [122940000.0, 0.0], [122932000.0, 0.0156], [122931000.0, 0.0], [122930000.0, 0.0]], "asks": [[122984000.0, 0.0079], [122996000.0, 0.1349], [122997000.0, 0.1349], [122998000.0, 0.0247], [123000000.0, 0.1049], [123001000.0, 0.0001], [123002000.0, 0.0023], [123003000.0, 0.0081], [123004000.0, 0.0001], [123005000.0, 0.0081]]},
{"timestamp": "1743933442199", "bids": [[122962000.0, 0.0058], [122960000.0, 0.1376], [122956000.0, 0.0], [122950000.0, 0.0061], [122949000.0, 0.0002], [122944000.0, 0.003], [122940000.0, 0.0], [122932000.0, 0.0156], [122931000.0, 0.0], [122930000.0, 0.0]], "asks": [[122984000.0, 0.0079], [122997000.0, 0.1349], [122998000.0, 0.0247], [123000000.0, 0.1049], [123001000.0, 0.0001], [123002000.0, 0.0023], [123003000.0, 0.0081], [123004000.0, 0.0001], [123005000.0, 0.0081], [123006000.0, 0.0081]]},
{"timestamp": "1743933442720", "bids": [[122962000.0, 0.0058], [122960000.0, 0.1376], [122956000.0, 0.0], [122950000.0, 0.0061], [122949000.0, 0.0002], [122944000.0, 0.003], [122940000.0, 0.0], [122932000.0, 0.0156], [122931000.0, 0.0], [122930000.0, 0.0]], "asks": [[122984000.0, 0.0079], [122995000.0, 0.1349], [122996000.0, 0.0843], [122998000.0, 0.0247], [123000000.0, 0.1049], [123001000.0, 0.0001], [123002000.0, 0.0023], [123003000.0, 0.0081], [123004000.0, 0.0001], [123005000.0, 0.0081]]},
{"timestamp": "1743933443222", "bids": [[122962000.0, 0.0058], [122960000.0, 0.1376], [122956000.0, 0.0], [122950000.0, 0.0061], [122949000.0, 0.0002], [122944000.0, 0.003], [122940000.0, 0.0], [122932000.0, 0.0156], [122931000.0, 0.0], [122930000.0, 0.0]], "asks": [[122984000.0, 0.0079], [122997000.0, 0.1349], [122998000.0, 0.0247], [123000000.0, 0.1049], [123001000.0, 0.0001], [123002000.0, 0.0023], [123003000.0, 0.0081], [123004000.0, 0.0001], [123005000.0, 0.0081], [123006000.0, 0.0081]]},
{"timestamp": "1743933443711", "bids": [[122962000.0, 0.0058], [122960000.0, 0.1376], [122956000.0, 0.0], [122950000.0, 0.0061], [122949000.0, 0.0002], [122944000.0, 0.003], [122940000.0, 0.0], [122932000.0, 0.0156], [122931000.0, 0.0], [122930000.0, 0.0]], "asks": [[122984000.0, 0.0079], [122997000.0, 0.1349], [122998000.0, 0.0247], [123000000.0, 0.1049], [123001000.0, 0.0001], [123002000.0, 0.0023], [123003000.0, 0.0081], [123004000.0, 0.0001], [123005000.0, 0.0081], [123006000.0, 0.0081]]},
{"timestamp": "1743933444245", "bids": [[122962000.0, 0.0058], [122960000.0, 0.1376], [122956000.0, 0.0], [122950000.0, 0.0061], [122949000.0, 0.0002], [122944000.0, 0.003], [122940000.0, 0.0], [122932000.0, 0.0156], [122931000.0, 0.0], [122930000.0, 0.0]], "asks": [[122984000.0, 0.0079], [122997000.0, 0.1349], [122998000.0, 0.0247], [123000000.0, 0.1049], [123001000.0, 0.0001], [123002000.0, 0.0023], [123003000.0, 0.0081], [123004000.0, 0.0001], [123005000.0, 0.0081], [123006000.0, 0.0081]]},
{"timestamp": "1743933444754", "bids": [[122962000.0, 0.0058], [122960000.0, 0.1376], [122956000.0, 0.0], [122950000.0, 0.0061], [122949000.0, 0.0002], [122944000.0, 0.003], [122940000.0, 0.0], [122932000.0, 0.0156], [122931000.0, 0.0], [122930000.0, 0.0]], "asks": [[122984000.0, 0.0079], [122997000.0, 0.1349], [122998000.0, 0.0247], [123000000.0, 0.1049], [123001000.0, 0.0001], [123002000.0, 0.0023], [123003000.0, 0.0081], [123004000.0, 0.0001], [123005000.0, 0.0081], [123006000.0, 0.0081]]},
{"timestamp": "1743933445278", "bids": [[122962000.0, 0.0058], [122960000.0, 0.1376], [122956000.0, 0.0], [122950000.0, 0.0061], [122949000.0, 0.0002], [122944000.0, 0.003], [122940000.0, 0.0], [122932000.0, 0.0156], [122931000.0, 0.0], [122930000.0, 0.0]], "asks": [[122984000.0, 0.0079], [122996000.0, 0.0843], [122997000.0, 0.1349], [122998000.0, 0.0247], [123000000.0, 0.1049], [123001000.0, 0.0001], [123002000.0, 0.0023], [123003000.0, 0.0081], [123004000.0, 0.0001], [123005000.0, 0.0081]]},
{"timestamp": "1743933445777", "bids": [[122962000.0, 0.0058], [122960000.0, 0.1376], [122956000.0, 0.0], [122950000.0, 0.0061], [122949000.0, 0.0002], [122944000.0, 0.003], [122940000.0, 0.0], [122932000.0, 0.0156], [122931000.0, 0.0], [122930000.0, 0.0]], "asks": [[122984000.0, 0.0079], [122995000.0, 0.1349], [122996000.0, 0.0843], [122998000.0, 0.0247], [123000000.0, 0.1049], [123001000.0, 0.0001], [123002000.0, 0.0023], [123003000.0, 0.0081], [123004000.0, 0.0001], [123005000.0, 0.0081]]},
{"timestamp": "1743933446283", "bids": [[122962000.0, 0.0058], [122960000.0, 0.1376], [122956000.0, 0.0], [122950000.0, 0.0061], [122949000.0, 0.0002], [122944000.0, 0.003], [122940000.0, 0.0], [122932000.0, 0.0156], [122931000.0, 0.0], [122930000.0, 0.0]], "asks": [[122984000.0, 0.0079], [122997000.0, 0.1349], [122998000.0, 0.0247], [123000000.0, 0.1049], [123001000.0, 0.0001], [123002000.0, 0.0023], [123003000.0, 0.0081], [123004000.0, 0.0001], [123005000.0, 0.0081], [123006000.0, 0.0081]]},
{"timestamp": "1743933446809", "bids": [[122962000.0, 0.0058], [122960000.0, 0.1376], [122956000.0, 0.0], [122950000.0, 0.0061], [122949000.0, 0.0002], [122944000.0, 0.003], [122940000.0, 0.0], [122932000.0, 0.0156], [122931000.0, 0.0], [122930000.0, 0.0]], "asks": [[122984000.0, 0.0079], [122997000.0, 0.1349], [122998000.0, 0.0247], [123000000.0, 0.1049], [123001000.0, 0.0001], [123002000.0, 0.0023], [123003000.0, 0.0081], [123004000.0, 0.0001], [123005000.0, 0.0081], [123006000.0, 0.0081]]},
{"timestamp": "1743933447310", "bids": [[122962000.0, 0.0058], [122960000.0, 0.1376], [122956000.0, 0.0], [122950000.0, 0.0061], [122949000.0, 0.0002], [122944000.0, 0.003], [122940000.0, 0.0], [122932000.0, 0.0156], [122931000.0, 0.0], [122930000.0, 0.0]], "asks": [[122984000.0, 0.0079], [122997000.0, 0.1349], [122998000.0, 0.0247], [123000000.0, 0.1049], [123001000.0, 0.0001], [123002000.0, 0.0023], [123003000.0, 0.0081], [123004000.0, 0.0001], [123005000.0, 0.0081], [123006000.0, 0.0081]]},
{"timestamp": "1743933447838", "bids": [[122962000.0, 0.0058], [122960000.0, 0.1376], [122956000.0, 0.0], [122950000.0, 0.0061], [122949000.0, 0.0002], [122944000.0, 0.003], [122940000.0, 0.0], [122932000.0, 0.0156], [122931000.0, 0.0], [122930000.0, 0.0]], "asks": [[122984000.0, 0.0079], [122997000.0, 0.1349], [122998000.0, 0.0247], [123000000.0, 0.1049], [123001000.0, 0.0001], [123002000.0, 0.0023], [123003000.0, 0.0081], [123004000.0, 0.0001], [123005000.0, 0.0081], [123006000.0, 0.0081]]},
{"timestamp": "1743933448360", "bids": [[122962000.0, 0.0058], [122960000.0, 0.1376], [122956000.0, 0.0], [122950000.0, 0.0061], [122949000.0, 0.0002], [122944000.0, 0.003], [122940000.0, 0.0], [122932000.0, 0.0156], [122931000.0, 0.0], [122930000.0, 0.0]], "asks": [[122984000.0, 0.0079], [122997000.0, 0.1349], [122998000.0, 0.0247], [123000000.0, 0.1049], [123001000.0, 0.0001], [123002000.0, 0.0023], [123003000.0, 0.0081], [123004000.0, 0.0001], [123005000.0, 0.0081], [123006000.0, 0.0081]]},
{"timestamp": "1743933448858", "bids": [[122962000.0, 0.0058], [122960000.0, 0.1376], [122956000.0, 0.0], [122950000.0, 0.0061], [122949000.0, 0.0002], [122944000.0, 0.003], [122940000.0, 0.0], [122932000.0, 0.0156], [122931000.0, 0.0], [122930000.0, 0.0]], "asks": [[122984000.0, 0.0079], [122997000.0, 0.1349], [122998000.0, 0.0247], [123000000.0, 0.1049], [123001000.0, 0.0001], [123002000.0, 0.0023], [123003000.0, 0.0081], [123004000.0, 0.0001], [123005000.0, 0.0081], [123006000.0, 0.0081]]},
{"timestamp": "1743933449353", "bids": [[122962000.0, 0.0058], [122960000.0, 0.1376], [122956000.0, 0.0], [122950000.0, 0.0061], [122949000.0, 0.0002], [122944000.0, 0.003], [122940000.0, 0.0], [122932000.0, 0.0156], [122931000.0, 0.0], [122930000.0, 0.0]], "asks": [[122984000.0, 0.0079], [122997000.0, 0.1349], [122998000.0, 0.0247], [123000000.0, 0.1049], [123001000.0, 0.0001], [123002000.0, 0.0023], [123003000.0, 0.0081], [123004000.0, 0.0001], [123005000.0, 0.0081], [123006000.0, 0.0081]]},
{"timestamp": "1743933449887", "bids": [[122962000.0, 0.0058], [122960000.0, 0.1376], [122956000.0, 0.0], [122950000.0, 0.0061], [122949000.0, 0.0002], [122944000.0, 0.003], [122940000.0, 0.0], [122932000.0, 0.0156], [122931000.0, 0.0], [122930000.0, 0.0]], "asks": [[122984000.0, 0.0079], [122997000.0, 0.1349], [122998000.0, 0.0247], [123000000.0, 0.1049], [123001000.0, 0.0001], [123002000.0, 0.0023], [123003000.0, 0.0081], [123004000.0, 0.0001], [123005000.0, 0.0081], [123006000.0, 0.0081]]},
{"timestamp": "1743933450375", "bids": [[122962000.0, 0.0058], [122960000.0, 0.1376], [122956000.0, 0.0], [122950000.0, 0.0061], [122949000.0, 0.0002], [122944000.0, 0.003], [122940000.0, 0.0], [122932000.0, 0.0156], [122931000.0, 0.0], [122930000.0, 0.0]], "asks": [[122984000.0, 0.0079], [122997000.0, 0.1349], [122998000.0, 0.0247], [123000000.0, 0.1049], [123001000.0, 0.0001], [123002000.0, 0.0023], [123003000.0, 0.0081], [123004000.0, 0.0001], [123005000.0, 0.0081], [123006000.0, 0.0081]]},
{"timestamp": "1743933450893", "bids": [[122962000.0, 0.0058], [122960000.0, 0.1376], [122956000.0, 0.0], [122950000.0, 0.0061], [122949000.0, 0.0002], [122944000.0, 0.003], [122940000.0, 0.0], [122932000.0, 0.0156], [122931000.0, 0.0], [122930000.0, 0.0]], "asks": [[122984000.0, 0.0079], [122996000.0, 0.0843], [122997000.0, 0.1349], [122998000.0, 0.0247], [123000000.0, 0.1049], [123001000.0, 0.0001], [123002000.0, 0.0023], [123003000.0, 0.0081], [123004000.0, 0.0001], [123005000.0, 0.0081]]},
{"timestamp": "1743933451421", "bids": [[122962000.0, 0.0058], [122960000.0, 0.1376], [122956000.0, 0.0], [122950000.0, 0.0061], [122949000.0, 0.0002], [122944000.0, 0.003], [122940000.0, 0.0], [122932000.0, 0.0156], [122931000.0, 0.0], [122930000.0, 0.0]], "asks": [[122984000.0, 0.0079], [122995000.0, 0.1349], [122996000.0, 0.0843], [122998000.0, 0.0247], [123000000.0, 0.1049], [123001000.0, 0.0001], [123002000.0, 0.0023], [123003000.0, 0.0081], [123004000.0, 0.0001], [123005000.0, 0.0081]]},
{"timestamp": "1743933451929", "bids": [[122962000.0, 0.0058], [122960000.0, 0.1376], [122956000.0, 0.0], [122950000.0, 0.0061], [122949000.0, 0.0002], [122944000.0, 0.003], [122940000.0, 0.0], [122932000.0, 0.0156], [122931000.0, 0.0], [122930000.0, 0.0]], "asks": [[122984000.0, 0.0079], [122993000.0, 0.1349], [122994000.0, 0.0843], [122998000.0, 0.0247], [123000000.0, 0.1049], [123001000.0, 0.0001], [123002000.0, 0.0023], [123003000.0, 0.0081], [123004000.0, 0.0001], [123005000.0, 0.0081]]},
{"timestamp": "1743933452427", "bids": [[122962000.0, 0.0058], [122960000.0, 0.1376], [122956000.0, 0.0], [122950000.0, 0.0061], [122949000.0, 0.0002], [122944000.0, 0.003], [122940000.0, 0.0], [122932000.0, 0.0156], [122931000.0, 0.0], [122930000.0, 0.0]], "asks": [[122984000.0, 0.0079], [122993000.0, 0.1349], [122998000.0, 0.0247], [123000000.0, 0.1049], [123001000.0, 0.0001], [123002000.0, 0.0023], [123003000.0, 0.0081], [123004000.0, 0.0001], [123005000.0, 0.0081], [123006000.0, 0.0081]]},
{"timestamp": "1743933452951", "bids": [[122962000.0, 0.0058], [122960000.0, 0.1376], [122956000.0, 0.0], [122950000.0, 0.0061], [122949000.0, 0.0002], [122944000.0, 0.003], [122940000.0, 0.0], [122932000.0, 0.0156], [122931000.0, 0.0], [122930000.0, 0.0]], "asks": [[122984000.0, 0.0079], [122996000.0, 0.0843], [122997000.0, 0.1349], [122998000.0, 0.0247], [123000000.0, 0.1049], [123001000.0, 0.0001], [123002000.0, 0.0023], [123003000.0, 0.0081], [123004000.0, 0.0001], [123005000.0, 0.0081]]},
{"timestamp": "1743933453468", "bids": [[122962000.0, 0.0058], [122960000.0, 0.1376], [122956000.0, 0.0], [122950000.0, 0.0061], [122949000.0, 0.0002], [122944000.0, 0.003], [122940000.0, 0.0], [122932000.0, 0.0156], [122931000.0, 0.0], [122930000.0, 0.0]], "asks": [[122984000.0, 0.0079], [122997000.0, 0.0843], [122998000.0, 0.0247], [123000000.0, 0.1049], [123001000.0, 0.0001], [123002000.0, 0.0023], [123003000.0, 0.0081], [123004000.0, 0.0001], [123005000.0, 0.0081], [123006000.0, 0.0081]]},
{"timestamp": "1743933453951", "bids": [[122962000.0, 0.0058], [122960000.0, 0.1376], [122956000.0, 0.0], [122950000.0, 0.0061], [122949000.0, 0.0002], [122944000.0, 0.003], [122940000.0, 0.0], [122932000.0, 0.0156], [122931000.0, 0.0], [122930000.0, 0.0]], "asks": [[122984000.0, 0.0078], [122993000.0, 0.1349], [122997000.0, 0.0843], [122998000.0, 0.0247], [123000000.0, 0.1049], [123001000.0, 0.0001], [123002000.0, 0.0023], [123003000.0, 0.0081], [123004000.0, 0.0001], [123005000.0, 0.0081]]},
{"timestamp": "1743933454475", "bids": [[122962000.0, 0.0058], [122960000.0, 0.1376], [122956000.0, 0.0], [122950000.0, 0.0061], [122949000.0, 0.0002], [122944000.0, 0.003], [122940000.0, 0.0], [122932000.0, 0.0156], [122931000.0, 0.0], [122930000.0, 0.0]], "asks": [[122984000.0, 0.0078], [122998000.0, 0.0247], [123000000.0, 0.1049], [123001000.0, 0.0001], [123002000.0, 0.0023], [123003000.0, 0.0081], [123004000.0, 0.0001], [123005000.0, 0.0081], [123006000.0, 0.0081], [123007000.0, 0.0082]]},
{"timestamp": "1743933454975", "bids": [[122962000.0, 0.0058], [122960000.0, 0.1376], [122956000.0, 0.0], [122950000.0, 0.0061], [122949000.0, 0.0002], [122944000.0, 0.003], [122940000.0, 0.0], [122932000.0, 0.0156], [122931000.0, 0.0], [122930000.0, 0.0]], "asks": [[122984000.0, 0.0078], [122997000.0, 0.2192], [122998000.0, 0.0247], [123000000.0, 0.1049], [123001000.0, 0.0001], [123002000.0, 0.0023], [123003000.0, 0.0081], [123004000.0, 0.0001], [123005000.0, 0.0081], [123006000.0, 0.0081]]},
{"timestamp": "1743933455520", "bids": [[122962000.0, 0.0058], [122960000.0, 0.1376], [122956000.0, 0.0], [122950000.0, 0.0061], [122949000.0, 0.0002], [122944000.0, 0.003], [122940000.0, 0.0], [122932000.0, 0.0156], [122931000.0, 0.0], [122930000.0, 0.0]], "asks": [[122984000.0, 0.0078], [122995000.0, 0.2192], [122998000.0, 0.0247], [123000000.0, 0.1049], [123001000.0, 0.0001], [123002000.0, 0.0023], [123003000.0, 0.0081], [123004000.0, 0.0001], [123005000.0, 0.0081], [123006000.0, 0.0081]]},
{"timestamp": "1743933456023", "bids": [[122970000.0, 0.0004], [122962000.0, 0.0058], [122960000.0, 0.1376], [122956000.0, 0.0], [122950000.0, 0.0061], [122949000.0, 0.0002], [122944000.0, 0.003], [122940000.0, 0.0], [122932000.0, 0.0156], [122931000.0, 0.0]], "asks": [[122984000.0, 0.0078], [122998000.0, 0.0247], [123000000.0, 0.1049], [123001000.0, 0.0001], [123002000.0, 0.0023], [123003000.0, 0.0081], [123004000.0, 0.0001], [123005000.0, 0.0081], [123006000.0, 0.0081], [123007000.0, 0.0082]]},
{"timestamp": "1743933456744", "bids": [[122970000.0, 0.0004], [122962000.0, 0.0058], [122960000.0, 0.1376], [122956000.0, 0.0], [122950000.0, 0.0061], [122949000.0, 0.0002], [122944000.0, 0.003], [122940000.0, 0.0], [122932000.0, 0.0156], [122931000.0, 0.0]], "asks": [[122984000.0, 0.0078], [122996000.0, 0.1349], [122997000.0, 0.0843], [122998000.0, 0.0247], [123000000.0, 0.1049], [123001000.0, 0.0001], [123002000.0, 0.0023], [123003000.0, 0.0081], [123004000.0, 0.0001], [123005000.0, 0.0081]]},
{"timestamp": "1743933457044", "bids": [[122970000.0, 0.0004], [122962000.0, 0.0058], [122960000.0, 0.1376], [122956000.0, 0.0], [122950000.0, 0.0061], [122949000.0, 0.0002], [122944000.0, 0.003], [122940000.0, 0.0], [122932000.0, 0.0156], [122931000.0, 0.0]], "asks": [[122984000.0, 0.0078], [122996000.0, 0.1349], [122998000.0, 0.0247], [123000000.0, 0.1049], [123001000.0, 0.0001], [123002000.0, 0.0023], [123003000.0, 0.0081], [123004000.0, 0.0001], [123005000.0, 0.0081], [123006000.0, 0.0081]]},
{"timestamp": "1743933457589", "bids": [[122970000.0, 0.0004], [122962000.0, 0.0058], [122960000.0, 0.1376], [122956000.0, 0.0], [122950000.0, 0.0061], [122949000.0, 0.0002], [122944000.0, 0.003], [122940000.0, 0.0], [122932000.0, 0.0156], [122931000.0, 0.0]], "asks": [[122984000.0, 0.0078], [122997000.0, 0.1349], [122998000.0, 0.0247], [123000000.0, 0.1049], [123001000.0, 0.0001], [123002000.0, 0.0023], [123003000.0, 0.0081], [123004000.0, 0.0001], [123005000.0, 0.0081], [123006000.0, 0.0081]]},
{"timestamp": "1743933458059", "bids": [[122970000.0, 0.0004], [122962000.0, 0.0058], [122960000.0, 0.1376], [122956000.0, 0.0], [122950000.0, 0.0061], [122949000.0, 0.0002], [122944000.0, 0.003], [122940000.0, 0.0], [122932000.0, 0.0156], [122931000.0, 0.0]], "asks": [[122984000.0, 0.0078], [122996000.0, 0.0843], [122997000.0, 0.1349], [122998000.0, 0.0247], [123000000.0, 0.1049], [123001000.0, 0.0001], [123002000.0, 0.0023], [123003000.0, 0.0081], [123004000.0, 0.0001], [123005000.0, 0.0081]]},
{"timestamp": "1743933458564", "bids": [[122970000.0, 0.0004], [122962000.0, 0.0058], [122960000.0, 0.1376], [122956000.0, 0.0], [122950000.0, 0.0061], [122949000.0, 0.0002], [122944000.0, 0.003], [122940000.0, 0.0], [122932000.0, 0.0156], [122931000.0, 0.0]], "asks": [[122984000.0, 0.0078], [122995000.0, 0.1349], [122998000.0, 0.0247], [123000000.0, 0.1049], [123001000.0, 0.0024], [123002000.0, 0.0023], [123003000.0, 0.0081], [123004000.0, 0.0001], [123005000.0, 0.0081], [123006000.0, 0.0081]]},
{"timestamp": "1743933459076", "bids": [[122970000.0, 0.0004], [122962000.0, 0.0058], [122960000.0, 0.1376], [122956000.0, 0.0], [122950000.0, 0.0061], [122949000.0, 0.0002], [122944000.0, 0.003], [122940000.0, 0.0], [122932000.0, 0.0156], [122931000.0, 0.0]], "asks": [[122984000.0, 0.0078], [122997000.0, 0.1349], [122998000.0, 0.0247], [123000000.0, 0.1049], [123001000.0, 0.0024], [123003000.0, 0.0081], [123004000.0, 0.0001], [123005000.0, 0.0081], [123006000.0, 0.0081], [123007000.0, 0.0082]]},
{"timestamp": "1743933459614", "bids": [[122970000.0, 0.0004], [122962000.0, 0.0058], [122960000.0, 0.1376], [122956000.0, 0.0], [122950000.0, 0.0061], [122949000.0, 0.0002], [122944000.0, 0.003], [122940000.0, 0.0], [122932000.0, 0.0156], [122931000.0, 0.0]], "asks": [[122984000.0, 0.0078], [122996000.0, 0.0843], [122997000.0, 0.1349], [122998000.0, 0.0247], [123000000.0, 0.1049], [123001000.0, 0.0024], [123003000.0, 0.0081], [123004000.0, 0.0001], [123005000.0, 0.0081], [123006000.0, 0.0081]]},
{"timestamp": "1743933460129", "bids": [[122970000.0, 0.0004], [122962000.0, 0.0058], [122960000.0, 0.1376], [122956000.0, 0.0], [122950000.0, 0.0061], [122949000.0, 0.0002], [122944000.0, 0.003], [122940000.0, 0.0], [122932000.0, 0.0156], [122931000.0, 0.0]], "asks": [[122984000.0, 0.0078], [122995000.0, 0.1349], [122996000.0, 0.0843], [122998000.0, 0.0247], [123000000.0, 0.1049], [123001000.0, 0.0024], [123003000.0, 0.0081], [123004000.0, 0.0001], [123005000.0, 0.0081], [123006000.0, 0.0081]]},
{"timestamp": "1743933460615", "bids": [[122970000.0, 0.0004], [122962000.0, 0.0058], [122960000.0, 0.1376], [122956000.0, 0.0], [122950000.0, 0.0061], [122949000.0, 0.0002], [122944000.0, 0.003], [122940000.0, 0.0], [122932000.0, 0.0156], [122931000.0, 0.0]], "asks": [[122984000.0, 0.0078], [122997000.0, 0.1349], [122998000.0, 0.0247], [123000000.0, 0.1049], [123001000.0, 0.0024], [123003000.0, 0.0081], [123004000.0, 0.0001], [123005000.0, 0.0081], [123006000.0, 0.0081], [123007000.0, 0.0082]]},
{"timestamp": "1743933461119", "bids": [[122970000.0, 0.0004], [122962000.0, 0.0058], [122960000.0, 0.1376], [122956000.0, 0.0], [122950000.0, 0.0061], [122949000.0, 0.0002], [122944000.0, 0.003], [122940000.0, 0.0], [122932000.0, 0.0156], [122931000.0, 0.0]], "asks": [[122984000.0, 0.0078], [122995000.0, 0.1349], [122998000.0, 0.0247], [123000000.0, 0.1049], [123001000.0, 0.0024], [123003000.0, 0.0081], [123004000.0, 0.0001], [123005000.0, 0.0081], [123006000.0, 0.0081], [123007000.0, 0.0082]]},
{"timestamp": "1743933461649", "bids": [[122970000.0, 0.0004], [122962000.0, 0.0058], [122960000.0, 0.1376], [122956000.0, 0.0], [122950000.0, 0.0061], [122949000.0, 0.0002], [122944000.0, 0.003], [122940000.0, 0.0], [122932000.0, 0.0156], [122931000.0, 0.0]], "asks": [[122984000.0, 0.0078], [122997000.0, 0.1349], [122998000.0, 0.0247], [123000000.0, 0.1049], [123001000.0, 0.0024], [123003000.0, 0.0081], [123004000.0, 0.0001], [123005000.0, 0.0081], [123006000.0, 0.0081], [123007000.0, 0.0082]]},
{"timestamp": "1743933462152", "bids": [[122970000.0, 0.0004], [122962000.0, 0.0058], [122960000.0, 0.1376], [122956000.0, 0.0], [122950000.0, 0.0061], [122949000.0, 0.0002], [122944000.0, 0.003], [122940000.0, 0.0], [122932000.0, 0.0156], [122931000.0, 0.0]], "asks": [[122984000.0, 0.0078], [122997000.0, 0.1349], [122998000.0, 0.0247], [123000000.0, 0.1049], [123001000.0, 0.0024], [123003000.0, 0.0081], [123004000.0, 0.0001], [123005000.0, 0.0081], [123006000.0, 0.0081], [123007000.0, 0.0082]]},
{"timestamp": "1743933462676", "bids": [[122970000.0, 0.0004], [122962000.0, 0.0058], [122960000.0, 0.1376], [122956000.0, 0.0], [122950000.0, 0.0061], [122949000.0, 0.0002], [122944000.0, 0.003], [122940000.0, 0.0], [122932000.0, 0.0156], [122931000.0, 0.0]], "asks": [[122984000.0, 0.0078], [122997000.0, 0.1349], [122998000.0, 0.0247], [123000000.0, 0.1049], [123001000.0, 0.0024], [123003000.0, 0.0081], [123004000.0, 0.0001], [123005000.0, 0.0081], [123006000.0, 0.0081], [123007000.0, 0.0082]]},
{"timestamp": "1743933463171", "bids": [[122970000.0, 0.0004], [122962000.0, 0.0058], [122960000.0, 0.1376], [122956000.0, 0.0], [122950000.0, 0.0061], [122949000.0, 0.0002], [122944000.0, 0.003], [122940000.0, 0.0], [122932000.0, 0.0156], [122931000.0, 0.0]], "asks": [[122984000.0, 0.0078], [122996000.0, 0.0843], [122997000.0, 0.1349], [122998000.0, 0.0247], [123000000.0, 0.1049], [123001000.0, 0.0024], [123003000.0, 0.0081], [123004000.0, 0.0001], [123005000.0, 0.0081], [123006000.0, 0.0081]]},
{"timestamp": "1743933463691", "bids": [[122970000.0, 0.0004], [122968000.0, 0.0005], [122962000.0, 0.0058], [122960000.0, 0.1376], [122956000.0, 0.0], [122950000.0, 0.0061], [122949000.0, 0.0002], [122944000.0, 0.003], [122940000.0, 0.0], [122932000.0, 0.0156]], "asks": [[122984000.0, 0.0078], [122995000.0, 0.1349], [122998000.0, 0.0247], [123000000.0, 0.1049], [123001000.0, 0.0024], [123003000.0, 0.0081], [123004000.0, 0.0001], [123005000.0, 0.0081], [123006000.0, 0.0081], [123007000.0, 0.0082]]},
{"timestamp": "1743933464198", "bids": [[122970000.0, 0.0004], [122968000.0, 0.0005], [122962000.0, 0.0058], [122960000.0, 0.1376], [122956000.0, 0.0], [122950000.0, 0.0061], [122949000.0, 0.0002], [122944000.0, 0.003], [122940000.0, 0.0], [122932000.0, 0.0156]], "asks": [[122984000.0, 0.0078], [122997000.0, 0.1349], [122998000.0, 0.0247], [123000000.0, 0.1049], [123001000.0, 0.0024], [123003000.0, 0.0081], [123004000.0, 0.0001], [123005000.0, 0.0081], [123006000.0, 0.0081], [123007000.0, 0.0082]]},
{"timestamp": "1743933464741", "bids": [[122970000.0, 0.0004], [122968000.0, 0.0005], [122962000.0, 0.0058], [122960000.0, 0.1376], [122956000.0, 0.0], [122950000.0, 0.0061], [122949000.0, 0.0002], [122944000.0, 0.003], [122940000.0, 0.0], [122932000.0, 0.0156]], "asks": [[122984000.0, 0.0078], [122997000.0, 0.1349], [122998000.0, 0.0247], [123000000.0, 0.1049], [123001000.0, 0.0024], [123003000.0, 0.0081], [123004000.0, 0.0001], [123005000.0, 0.0081], [123006000.0, 0.0081], [123007000.0, 0.0082]]},
{"timestamp": "1743933465254", "bids": [[122970000.0, 0.0004], [122968000.0, 0.0005], [122962000.0, 0.0058], [122960000.0, 0.1376], [122956000.0, 0.0], [122950000.0, 0.0061], [122949000.0, 0.0002], [122944000.0, 0.003], [122940000.0, 0.0], [122932000.0, 0.0156]], "asks": [[122984000.0, 0.0078], [122997000.0, 0.1349], [122998000.0, 0.0247], [123000000.0, 0.1049], [123001000.0, 0.0001], [123003000.0, 0.0081], [123004000.0, 0.0001], [123005000.0, 0.0104], [123006000.0, 0.0081], [123007000.0, 0.0082]]},
{"timestamp": "1743933465733", "bids": [[122970000.0, 0.0004], [122968000.0, 0.0005], [122962000.0, 0.0058], [122960000.0, 0.1376], [122956000.0, 0.0], [122950000.0, 0.0061], [122949000.0, 0.0002], [122944000.0, 0.003], [122940000.0, 0.0], [122932000.0, 0.0156]], "asks": [[122984000.0, 0.0078], [122997000.0, 0.1349], [122998000.0, 0.0247], [123000000.0, 0.1049], [123001000.0, 0.0001], [123003000.0, 0.0081], [123004000.0, 0.0001], [123005000.0, 0.0104], [123006000.0, 0.0081], [123007000.0, 0.0082]]},
{"timestamp": "1743933466278", "bids": [[122970000.0, 0.0004], [122968000.0, 0.0005], [122962000.0, 0.0058], [122960000.0, 0.1376], [122956000.0, 0.0], [122950000.0, 0.0061], [122949000.0, 0.0002], [122944000.0, 0.003], [122940000.0, 0.0], [122932000.0, 0.0156]], "asks": [[122984000.0, 0.0078], [122997000.0, 0.1349], [122998000.0, 0.0247], [123000000.0, 0.1049], [123001000.0, 0.0001], [123003000.0, 0.0081], [123004000.0, 0.0001], [123005000.0, 0.0104], [123006000.0, 0.0081], [123007000.0, 0.0082]]},
{"timestamp": "1743933466775", "bids": [[122970000.0, 0.0004], [122968000.0, 0.0005], [122962000.0, 0.0058], [122960000.0, 0.1376], [122956000.0, 0.0], [122950000.0, 0.0061], [122949000.0, 0.0002], [122944000.0, 0.003], [122940000.0, 0.0], [122932000.0, 0.0156]], "asks": [[122984000.0, 0.0078], [122997000.0, 0.1349], [122998000.0, 0.0247], [123000000.0, 0.1049], [123001000.0, 0.0001], [123003000.0, 0.0081], [123004000.0, 0.0001], [123005000.0, 0.0104], [123006000.0, 0.0081], [123007000.0, 0.0082]]},
{"timestamp": "1743933467272", "bids": [[122970000.0, 0.0004], [122968000.0, 0.0005], [122962000.0, 0.0058], [122960000.0, 0.1376], [122956000.0, 0.0], [122950000.0, 0.0061], [122949000.0, 0.0002], [122944000.0, 0.003], [122940000.0, 0.0], [122932000.0, 0.0156]], "asks": [[122984000.0, 0.0078], [122997000.0, 0.1349], [122998000.0, 0.0247], [123000000.0, 0.1049], [123001000.0, 0.0001], [123003000.0, 0.0081], [123004000.0, 0.0001], [123005000.0, 0.0104], [123006000.0, 0.0081], [123007000.0, 0.0082]]},
{"timestamp": "1743933467818", "bids": [[122970000.0, 0.0004], [122968000.0, 0.0005], [122962000.0, 0.0058], [122960000.0, 0.1376], [122956000.0, 0.0], [122950000.0, 0.0061], [122949000.0, 0.0002], [122944000.0, 0.003], [122940000.0, 0.0], [122932000.0, 0.0156]], "asks": [[122984000.0, 0.0078], [122997000.0, 0.1349], [122998000.0, 0.0247], [123000000.0, 0.1049], [123001000.0, 0.0001], [123003000.0, 0.0081], [123004000.0, 0.0001], [123005000.0, 0.0104], [123006000.0, 0.0081], [123007000.0, 0.0082]]},
{"timestamp": "1743933468312", "bids": [[122970000.0, 0.0004], [122968000.0, 0.0005], [122962000.0, 0.0058], [122960000.0, 0.1376], [122956000.0, 0.0], [122950000.0, 0.0061], [122949000.0, 0.0002], [122944000.0, 0.003], [122940000.0, 0.0], [122932000.0, 0.0156]], "asks": [[122984000.0, 0.0078], [122997000.0, 0.1349], [122998000.0, 0.0247], [123000000.0, 0.1049], [123001000.0, 0.0001], [123003000.0, 0.0081], [123004000.0, 0.0001], [123005000.0, 0.0104], [123006000.0, 0.0081], [123007000.0, 0.0082]]},
{"timestamp": "1743933468809", "bids": [[122970000.0, 0.0004], [122968000.0, 0.0005], [122962000.0, 0.0058], [122960000.0, 0.1376], [122956000.0, 0.0], [122950000.0, 0.0061], [122949000.0, 0.0002], [122944000.0, 0.003], [122940000.0, 0.0], [122932000.0, 0.0156]], "asks": [[122984000.0, 0.0078], [122997000.0, 0.1349], [122998000.0, 0.0247], [123000000.0, 0.1049], [123001000.0, 0.0001], [123003000.0, 0.0081], [123004000.0, 0.0001], [123005000.0, 0.0104], [123006000.0, 0.0081], [123007000.0, 0.0082]]},
{"timestamp": "1743933469331", "bids": [[122970000.0, 0.0004], [122968000.0, 0.0005], [122962000.0, 0.0058], [122960000.0, 0.1376], [122956000.0, 0.0], [122950000.0, 0.0061], [122949000.0, 0.0002], [122944000.0, 0.003], [122940000.0, 0.0], [122932000.0, 0.0156]], "asks": [[122984000.0, 0.0078], [122997000.0, 0.1349], [122998000.0, 0.0247], [123000000.0, 0.1049], [123001000.0, 0.0001], [123003000.0, 0.0081], [123004000.0, 0.0001], [123005000.0, 0.0104], [123006000.0, 0.0081], [123007000.0, 0.0082]]},
{"timestamp": "1743933469854", "bids": [[122970000.0, 0.0004], [122968000.0, 0.0005], [122962000.0, 0.0058], [122960000.0, 0.1376], [122956000.0, 0.0], [122950000.0, 0.0061], [122949000.0, 0.0002], [122944000.0, 0.003], [122940000.0, 0.0], [122932000.0, 0.0156]], "asks": [[122984000.0, 0.0078], [122997000.0, 0.1349], [122998000.0, 0.0247], [123000000.0, 0.1049], [123001000.0, 0.0001], [123003000.0, 0.0081], [123004000.0, 0.0001], [123005000.0, 0.0104], [123006000.0, 0.0081], [123007000.0, 0.0082]]},
{"timestamp": "1743933470374", "bids": [[122968000.0, 0.0005], [122962000.0, 0.0058], [122960000.0, 0.1376], [122956000.0, 0.0], [122950000.0, 0.0061], [122949000.0, 0.0002], [122944000.0, 0.003], [122940000.0, 0.0], [122932000.0, 0.0156], [122931000.0, 0.0]], "asks": [[122970000.0, 0.2599], [122984000.0, 0.0078], [122997000.0, 0.1349], [122998000.0, 0.0247], [123000000.0, 0.1049], [123001000.0, 0.0001], [123003000.0, 0.0081], [123004000.0, 0.0001], [123005000.0, 0.0104], [123006000.0, 0.0081]]},
{"timestamp": "1743933470859", "bids": [[122968000.0, 0.0005], [122962000.0, 0.0058], [122960000.0, 0.1376], [122956000.0, 0.0], [122950000.0, 0.0061], [122949000.0, 0.0002], [122944000.0, 0.003], [122940000.0, 0.0], [122932000.0, 0.0156], [122931000.0, 0.0]], "asks": [[122970000.0, 0.2599], [122984000.0, 0.0078], [122998000.0, 0.0247], [123000000.0, 0.1049], [123001000.0, 0.0001], [123003000.0, 0.0081], [123004000.0, 0.0001], [123005000.0, 0.0104], [123006000.0, 0.0081], [123007000.0, 0.0082]]},
{"timestamp": "1743933471401", "bids": [[122968000.0, 0.0005], [122962000.0, 0.0058], [122960000.0, 0.1376], [122956000.0, 0.0], [122950000.0, 0.0061], [122949000.0, 0.0002], [122944000.0, 0.003], [122940000.0, 0.0], [122932000.0, 0.0156], [122931000.0, 0.0]], "asks": [[122970000.0, 0.2599], [122984000.0, 0.0078], [122998000.0, 0.0247], [123000000.0, 0.1049], [123001000.0, 0.0001], [123003000.0, 0.0081], [123004000.0, 0.0001], [123005000.0, 0.0104], [123006000.0, 0.0081], [123007000.0, 0.0082]]},
{"timestamp": "1743933471895", "bids": [[122968000.0, 0.0005], [122962000.0, 0.0058], [122960000.0, 0.1376], [122956000.0, 0.0], [122950000.0, 0.0061], [122949000.0, 0.0002], [122944000.0, 0.003], [122940000.0, 0.0], [122932000.0, 0.0156], [122931000.0, 0.0]], "asks": [[122970000.0, 0.2599], [122984000.0, 0.0078], [122998000.0, 0.0247], [123000000.0, 0.1049], [123001000.0, 0.0001], [123003000.0, 0.0081], [123004000.0, 0.0001], [123005000.0, 0.0104], [123006000.0, 0.0081], [123007000.0, 0.0082]]},
{"timestamp": "1743933472393", "bids": [[122968000.0, 0.0005], [122962000.0, 0.0058], [122960000.0, 0.1376], [122956000.0, 0.0], [122950000.0, 0.0061], [122949000.0, 0.0002], [122944000.0, 0.003], [122940000.0, 0.0], [122932000.0, 0.0156], [122931000.0, 0.0]], "asks": [[122970000.0, 0.2599], [122984000.0, 0.0078], [122998000.0, 0.0247], [123000000.0, 0.1049], [123001000.0, 0.0001], [123003000.0, 0.0081], [123004000.0, 0.0001], [123005000.0, 0.0104], [123006000.0, 0.0081], [123007000.0, 0.0082]]},
{"timestamp": "1743933472918", "bids": [[122968000.0, 0.0005], [122962000.0, 0.0058], [122960000.0, 0.1376], [122956000.0, 0.0], [122950000.0, 0.0061], [122949000.0, 0.0002], [122944000.0, 0.003], [122940000.0, 0.0], [122932000.0, 0.0156], [122931000.0, 0.0]], "asks": [[122970000.0, 0.2599], [122984000.0, 0.0078], [122998000.0, 0.0247], [123000000.0, 0.1049], [123001000.0, 0.0001], [123003000.0, 0.0081], [123004000.0, 0.0001], [123005000.0, 0.0104], [123006000.0, 0.0081], [123007000.0, 0.0082]]},
{"timestamp": "1743933473439", "bids": [[122968000.0, 0.0005], [122962000.0, 0.0058], [122960000.0, 0.1376], [122956000.0, 0.0], [122950000.0, 0.0061], [122949000.0, 0.0002], [122944000.0, 0.003], [122940000.0, 0.0], [122932000.0, 0.0156], [122931000.0, 0.0]], "asks": [[122970000.0, 0.2599], [122984000.0, 0.0078], [122998000.0, 0.0247], [123000000.0, 0.1049], [123001000.0, 0.0001], [123003000.0, 0.0081], [123004000.0, 0.0001], [123005000.0, 0.0104], [123006000.0, 0.0081], [123007000.0, 0.0082]]},
{"timestamp": "1743933473926", "bids": [[122968000.0, 0.0005], [122962000.0, 0.0058], [122960000.0, 0.1376], [122956000.0, 0.0], [122950000.0, 0.0061], [122949000.0, 0.0002], [122944000.0, 0.003], [122940000.0, 0.0], [122932000.0, 0.0156], [122931000.0, 0.0]], "asks": [[122970000.0, 0.2599], [122984000.0, 0.0078], [122998000.0, 0.0247], [123000000.0, 0.1049], [123001000.0, 0.0001], [123003000.0, 0.0081], [123004000.0, 0.0001], [123005000.0, 0.0104], [123006000.0, 0.0081], [123007000.0, 0.0082]]},
{"timestamp": "1743933474484", "bids": [[122968000.0, 0.0005], [122962000.0, 0.0058], [122960000.0, 0.1376], [122956000.0, 0.0], [122950000.0, 0.0061], [122949000.0, 0.0002], [122944000.0, 0.003], [122940000.0, 0.0], [122932000.0, 0.0156], [122931000.0, 0.0]], "asks": [[122970000.0, 0.2599], [122984000.0, 0.0078], [122998000.0, 0.0247], [123000000.0, 0.1049], [123001000.0, 0.0001], [123003000.0, 0.0081], [123004000.0, 0.0001], [123005000.0, 0.0104], [123006000.0, 0.0081], [123007000.0, 0.0082]]},
{"timestamp": "1743933474954", "bids": [[122968000.0, 0.0005], [122962000.0, 0.0058], [122960000.0, 0.1376], [122956000.0, 0.0], [122950000.0, 0.0061], [122949000.0, 0.0002], [122944000.0, 0.003], [122940000.0, 0.0], [122932000.0, 0.0156], [122931000.0, 0.0]], "asks": [[122970000.0, 0.2599], [122984000.0, 0.0078], [122998000.0, 0.0247], [123000000.0, 0.1049], [123001000.0, 0.0001], [123003000.0, 0.0081], [123004000.0, 0.0001], [123005000.0, 0.0104], [123006000.0, 0.0081], [123007000.0, 0.0082]]},
{"timestamp": "1743933475518", "bids": [[122968000.0, 0.0005], [122962000.0, 0.0058], [122960000.0, 0.1376], [122956000.0, 0.0], [122950000.0, 0.0061], [122949000.0, 0.0002], [122944000.0, 0.003], [122940000.0, 0.0], [122932000.0, 0.0156], [122931000.0, 0.0]], "asks": [[122970000.0, 0.2599], [122980000.0, 0.0004], [122984000.0, 0.0078], [122997000.0, 0.0023], [122998000.0, 0.0247], [123000000.0, 0.1049], [123001000.0, 0.0001], [123003000.0, 0.0081], [123004000.0, 0.0001], [123005000.0, 0.0104]]},
{"timestamp": "1743933476022", "bids": [[122968000.0, 0.0005], [122962000.0, 0.0058], [122960000.0, 0.1376], [122956000.0, 0.0], [122950000.0, 0.0061], [122949000.0, 0.0002], [122944000.0, 0.003], [122940000.0, 0.0], [122932000.0, 0.0156], [122931000.0, 0.0]], "asks": [[122970000.0, 0.2599], [122980000.0, 0.0004], [122984000.0, 0.0078], [122997000.0, 0.0023], [122998000.0, 0.0247], [123000000.0, 0.1049], [123001000.0, 0.0001], [123003000.0, 0.0081], [123004000.0, 0.0001], [123005000.0, 0.0081]]},
{"timestamp": "1743933476530", "bids": [[122968000.0, 0.0005], [122962000.0, 0.0058], [122960000.0, 0.1376], [122956000.0, 0.0], [122950000.0, 0.0061], [122949000.0, 0.0002], [122944000.0, 0.003], [122940000.0, 0.0], [122932000.0, 0.0156], [122931000.0, 0.0]], "asks": [[122970000.0, 0.2599], [122980000.0, 0.0004], [122984000.0, 0.0078], [122997000.0, 0.0023], [122998000.0, 0.0247], [123000000.0, 0.1049], [123001000.0, 0.0001], [123003000.0, 0.0081], [123004000.0, 0.0001], [123005000.0, 0.0081]]},
{"timestamp": "1743933477077", "bids": [[122968000.0, 0.0005], [122962000.0, 0.0058], [122960000.0, 0.1376], [122956000.0, 0.0], [122950000.0, 0.0061], [122949000.0, 0.0002], [122944000.0, 0.003], [122940000.0, 0.0], [122932000.0, 0.0156], [122931000.0, 0.0]], "asks": [[122970000.0, 0.2599], [122980000.0, 0.0004], [122984000.0, 0.0078], [122997000.0, 0.0023], [122998000.0, 0.0247], [123000000.0, 0.1049], [123001000.0, 0.0001], [123003000.0, 0.0081], [123004000.0, 0.0001], [123005000.0, 0.0081]]},
{"timestamp": "1743933477599", "bids": [[122968000.0, 0.0005], [122962000.0, 0.0058], [122960000.0, 0.1376], [122956000.0, 0.0], [122950000.0, 0.0061], [122949000.0, 0.0002], [122944000.0, 0.003], [122940000.0, 0.0], [122932000.0, 0.0156], [122931000.0, 0.0]], "asks": [[122970000.0, 0.2599], [122980000.0, 0.0004], [122984000.0, 0.0078], [122997000.0, 0.0023], [122998000.0, 0.0247], [123000000.0, 0.1049], [123001000.0, 0.0001], [123003000.0, 0.0081], [123004000.0, 0.0001], [123005000.0, 0.0081]]},
{"timestamp": "1743933478050", "bids": [[122968000.0, 0.0005], [122962000.0, 0.0058], [122960000.0, 0.1376], [122956000.0, 0.0], [122950000.0, 0.0061], [122949000.0, 0.0002], [122944000.0, 0.003], [122940000.0, 0.0], [122932000.0, 0.0156], [122931000.0, 0.0]], "asks": [[122970000.0, 0.2599], [122980000.0, 0.0004], [122984000.0, 0.0078], [122997000.0, 0.0023], [122998000.0, 0.0247], [123000000.0, 0.1049], [123001000.0, 0.0001], [123003000.0, 0.0081], [123004000.0, 0.0001], [123005000.0, 0.0081]]},
{"timestamp": "1743933478575", "bids": [[122968000.0, 0.0005], [122962000.0, 0.0058], [122960000.0, 0.1376], [122956000.0, 0.0], [122950000.0, 0.0061], [122949000.0, 0.0002], [122944000.0, 0.003], [122940000.0, 0.0], [122932000.0, 0.0156], [122931000.0, 0.0]], "asks": [[122970000.0, 0.2599], [122980000.0, 0.0004], [122984000.0, 0.0078], [122997000.0, 0.0046], [122998000.0, 0.0247], [123000000.0, 0.1049], [123001000.0, 0.0001], [123003000.0, 0.0081], [123004000.0, 0.0001], [123005000.0, 0.0081]]},
{"timestamp": "1743933479033", "bids": [[122968000.0, 0.0005], [122962000.0, 0.0058], [122960000.0, 0.1376], [122956000.0, 0.0], [122950000.0, 0.0061], [122949000.0, 0.0002], [122944000.0, 0.003], [122940000.0, 0.0], [122932000.0, 0.0156], [122931000.0, 0.0]], "asks": [[122970000.0, 0.2599], [122980000.0, 0.0004], [122984000.0, 0.0078], [122997000.0, 0.0023], [122998000.0, 0.0247], [123000000.0, 0.1049], [123001000.0, 0.0001], [123003000.0, 0.0081], [123004000.0, 0.0001], [123005000.0, 0.0081]]},
{"timestamp": "1743933479567", "bids": [[122968000.0, 0.0005], [122962000.0, 0.0058], [122960000.0, 0.1376], [122956000.0, 0.0], [122950000.0, 0.0061], [122949000.0, 0.0002], [122944000.0, 0.003], [122940000.0, 0.0], [122931000.0, 0.0], [122930000.0, 0.0]], "asks": [[122970000.0, 0.2599], [122980000.0, 0.0004], [122984000.0, 0.0078], [122997000.0, 0.0023], [123000000.0, 0.1049], [123001000.0, 0.0001], [123003000.0, 0.0081], [123004000.0, 0.0001], [123005000.0, 0.0081], [123006000.0, 0.0081]]},
{"timestamp": "1743933480078", "bids": [[122968000.0, 0.0005], [122960000.0, 0.1376], [122956000.0, 0.0], [122950000.0, 0.0061], [122949000.0, 0.0002], [122944000.0, 0.003], [122940000.0, 0.0], [122936000.0, 0.0156], [122934000.0, 0.0269], [122932000.0, 0.0311]], "asks": [[122970000.0, 0.2599], [122980000.0, 0.0004], [122997000.0, 0.0023], [123000000.0, 0.1049], [123001000.0, 0.0001], [123002000.0, 0.0189], [123003000.0, 0.0081], [123004000.0, 0.0001], [123005000.0, 0.0081], [123006000.0, 0.0328]]},
{"timestamp": "1743933480587", "bids": [[122968000.0, 0.0005], [122960000.0, 0.1376], [122956000.0, 0.0], [122950000.0, 0.0061], [122949000.0, 0.0002], [122944000.0, 0.003], [122940000.0, 0.0], [122936000.0, 0.0156], [122934000.0, 0.0269], [122932000.0, 0.0311]], "asks": [[122970000.0, 0.2599], [122980000.0, 0.0004], [122994000.0, 0.0078], [122997000.0, 0.0023], [123000000.0, 0.1049], [123001000.0, 0.0001], [123002000.0, 0.0189], [123003000.0, 0.0081], [123004000.0, 0.0001], [123005000.0, 0.0081]]},
{"timestamp": "1743933481097", "bids": [[122968000.0, 0.0005], [122960000.0, 0.1376], [122956000.0, 0.0], [122950000.0, 0.0061], [122949000.0, 0.0002], [122944000.0, 0.003], [122940000.0, 0.0], [122936000.0, 0.0156], [122934000.0, 0.0269], [122932000.0, 0.0311]], "asks": [[122970000.0, 0.2599], [122980000.0, 0.0004], [122994000.0, 0.0078], [122997000.0, 0.0023], [123000000.0, 0.1049], [123001000.0, 0.0001], [123002000.0, 0.0189], [123003000.0, 0.0081], [123004000.0, 0.0001], [123005000.0, 0.0081]]},
{"timestamp": "1743933481609", "bids": [[122968000.0, 0.0005], [122960000.0, 0.1376], [122956000.0, 0.0], [122950000.0, 0.0061], [122949000.0, 0.0002], [122944000.0, 0.003], [122940000.0, 0.0], [122936000.0, 0.0156], [122934000.0, 0.0269], [122932000.0, 0.0311]], "asks": [[122970000.0, 0.2599], [122980000.0, 0.0004], [122994000.0, 0.0078], [122997000.0, 0.0023], [123000000.0, 0.1049], [123001000.0, 0.0001], [123002000.0, 0.0189], [123003000.0, 0.0081], [123004000.0, 0.0001], [123005000.0, 0.0081]]},
{"timestamp": "1743933482104", "bids": [[122968000.0, 0.0005], [122960000.0, 0.1376], [122956000.0, 0.0], [122950000.0, 0.0061], [122949000.0, 0.0002], [122944000.0, 0.003], [122940000.0, 0.0], [122936000.0, 0.0156], [122934000.0, 0.0269], [122932000.0, 0.0311]], "asks": [[122970000.0, 0.2599], [122980000.0, 0.0004], [122994000.0, 0.0078], [122997000.0, 0.0023], [123000000.0, 0.1049], [123001000.0, 0.0001], [123002000.0, 0.0189], [123003000.0, 0.0081], [123004000.0, 0.0001], [123005000.0, 0.0081]]},
{"timestamp": "1743933482660", "bids": [[122968000.0, 0.0005], [122960000.0, 0.1376], [122956000.0, 0.0], [122950000.0, 0.0061], [122949000.0, 0.0002], [122944000.0, 0.003], [122940000.0, 0.0], [122936000.0, 0.0156], [122934000.0, 0.0269], [122932000.0, 0.0311]], "asks": [[122970000.0, 0.2599], [122980000.0, 0.0004], [122994000.0, 0.0078], [122997000.0, 0.0023], [123000000.0, 0.1049], [123001000.0, 0.0001], [123002000.0, 0.0189], [123003000.0, 0.0081], [123004000.0, 0.0001], [123005000.0, 0.0081]]},
{"timestamp": "1743933483170", "bids": [[122968000.0, 0.0005], [122960000.0, 0.1376], [122956000.0, 0.0], [122950000.0, 0.0061], [122949000.0, 0.0002], [122944000.0, 0.003], [122940000.0, 0.0], [122936000.0, 0.0156], [122934000.0, 0.0269], [122932000.0, 0.0311]], "asks": [[122970000.0, 0.2599], [122980000.0, 0.0004], [122994000.0, 0.0078], [122997000.0, 0.0023], [122999000.0, 0.0023], [123000000.0, 0.1049], [123001000.0, 0.0001], [123002000.0, 0.0189], [123003000.0, 0.0081], [123004000.0, 0.0001]]},
{"timestamp": "1743933483699", "bids": [[122968000.0, 0.0005], [122960000.0, 0.1376], [122956000.0, 0.0], [122950000.0, 0.0061], [122949000.0, 0.0002], [122944000.0, 0.003], [122940000.0, 0.0], [122936000.0, 0.0156], [122934000.0, 0.0269], [122932000.0, 0.0311]], "asks": [[122970000.0, 0.2599], [122980000.0, 0.0004], [122994000.0, 0.0078], [122999000.0, 0.0023], [123000000.0, 0.1049], [123001000.0, 0.0001], [123002000.0, 0.0189], [123003000.0, 0.0081], [123004000.0, 0.0001], [123005000.0, 0.0081]]},
{"timestamp": "1743933484219", "bids": [[122969000.0, 0.0814], [122968000.0, 0.0005], [122960000.0, 0.1376], [122956000.0, 0.0], [122950000.0, 0.0061], [122949000.0, 0.0002], [122944000.0, 0.003], [122940000.0, 0.0], [122931000.0, 0.0], [122930000.0, 0.0]], "asks": [[122970000.0, 0.2599], [122980000.0, 0.0004], [122999000.0, 0.0023], [123000000.0, 0.1049], [123001000.0, 0.0001], [123003000.0, 0.0081], [123004000.0, 0.0001], [123005000.0, 0.0081], [123006000.0, 0.0081], [123007000.0, 0.0082]]},
{"timestamp": "1743933484666", "bids": [[122969000.0, 0.0644], [122968000.0, 0.0005], [122960000.0, 0.1376], [122956000.0, 0.0], [122950000.0, 0.0061], [122949000.0, 0.0002], [122946000.0, 0.0269], [122944000.0, 0.0189], [122940000.0, 0.0], [122931000.0, 0.0]], "asks": [[122970000.0, 0.2598], [122980000.0, 0.0004], [122999000.0, 0.0023], [123000000.0, 0.1049], [123001000.0, 0.0001], [123003000.0, 0.0081], [123004000.0, 0.0001], [123005000.0, 0.0081], [123006000.0, 0.0081], [123007000.0, 0.0082]]},
{"timestamp": "1743933485224", "bids": [[122968000.0, 0.0005], [122960000.0, 0.1376], [122956000.0, 0.0], [122950000.0, 0.0061], [122949000.0, 0.0002], [122948000.0, 0.0156], [122946000.0, 0.0269], [122944000.0, 0.0341], [122943000.0, 0.0152], [122940000.0, 0.0]], "asks": [[122970000.0, 0.2598], [122980000.0, 0.0004], [122999000.0, 0.0023], [123000000.0, 0.1049], [123001000.0, 0.0001], [123003000.0, 0.0081], [123004000.0, 0.0001], [123005000.0, 0.0081], [123006000.0, 0.0159], [123007000.0, 0.0082]]},
{"timestamp": "1743933485753", "bids": [[122968000.0, 0.0005], [122960000.0, 0.1376], [122956000.0, 0.0], [122950000.0, 0.0061], [122949000.0, 0.0002], [122948000.0, 0.0156], [122946000.0, 0.0269], [122944000.0, 0.0341], [122943000.0, 0.0152], [122940000.0, 0.0]], "asks": [[122970000.0, 0.2598], [122980000.0, 0.0004], [122999000.0, 0.0023], [123000000.0, 0.1049], [123001000.0, 0.0001], [123003000.0, 0.0081], [123004000.0, 0.0001], [123005000.0, 0.0081], [123006000.0, 0.0159], [123007000.0, 0.0082]]},
{"timestamp": "1743933486197", "bids": [[122968000.0, 0.0005], [122960000.0, 0.1376], [122956000.0, 0.0], [122950000.0, 0.0061], [122949000.0, 0.0002], [122948000.0, 0.0156], [122946000.0, 0.0269], [122944000.0, 0.0341], [122943000.0, 0.0152], [122940000.0, 0.0]], "asks": [[122970000.0, 0.2598], [122980000.0, 0.0004], [122999000.0, 0.0023], [123000000.0, 0.1049], [123001000.0, 0.0001], [123003000.0, 0.0081], [123004000.0, 0.0001], [123005000.0, 0.0081], [123006000.0, 0.0159], [123007000.0, 0.0082]]},
{"timestamp": "1743933486731", "bids": [[122968000.0, 0.0005], [122960000.0, 0.1376], [122956000.0, 0.0], [122950000.0, 0.0061], [122949000.0, 0.0002], [122948000.0, 0.0156], [122946000.0, 0.0269], [122944000.0, 0.0341], [122943000.0, 0.0152], [122940000.0, 0.0]], "asks": [[122970000.0, 0.2598], [122980000.0, 0.0004], [122999000.0, 0.0023], [123000000.0, 0.1049], [123001000.0, 0.0001], [123003000.0, 0.0081], [123004000.0, 0.0001], [123005000.0, 0.0081], [123006000.0, 0.0159], [123007000.0, 0.0082]]},
{"timestamp": "1743933487232", "bids": [[122968000.0, 0.0005], [122960000.0, 0.1376], [122956000.0, 0.0], [122950000.0, 0.0061], [122949000.0, 0.0002], [122948000.0, 0.0156], [122946000.0, 0.0269], [122944000.0, 0.0341], [122943000.0, 0.0152], [122940000.0, 0.0]], "asks": [[122970000.0, 0.2598], [122980000.0, 0.0004], [122999000.0, 0.0023], [123000000.0, 0.1049], [123001000.0, 0.0001], [123003000.0, 0.0081], [123004000.0, 0.0001], [123005000.0, 0.0081], [123006000.0, 0.0159], [123007000.0, 0.0082]]},
{"timestamp": "1743933487736", "bids": [[122968000.0, 0.0005], [122960000.0, 0.1376], [122956000.0, 0.0], [122950000.0, 0.0061], [122949000.0, 0.0002], [122948000.0, 0.0156], [122946000.0, 0.0269], [122944000.0, 0.0341], [122943000.0, 0.0152], [122940000.0, 0.0]], "asks": [[122970000.0, 0.2596], [122980000.0, 0.0004], [122999000.0, 0.0023], [123000000.0, 0.1049], [123001000.0, 0.0001], [123003000.0, 0.0081], [123004000.0, 0.0001], [123005000.0, 0.0081], [123006000.0, 0.0159], [123007000.0, 0.0082]]},
{"timestamp": "1743933488254", "bids": [[122968000.0, 0.0005], [122960000.0, 0.1376], [122956000.0, 0.0], [122950000.0, 0.0061], [122949000.0, 0.0002], [122948000.0, 0.0156], [122946000.0, 0.0269], [122944000.0, 0.0341], [122943000.0, 0.0152], [122940000.0, 0.0]], "asks": [[122970000.0, 0.2596], [122980000.0, 0.0004], [122999000.0, 0.0023], [123000000.0, 0.1049], [123001000.0, 0.0001], [123003000.0, 0.0081], [123004000.0, 0.0001], [123005000.0, 0.0081], [123006000.0, 0.0159], [123007000.0, 0.0082]]},
{"timestamp": "1743933488770", "bids": [[122968000.0, 0.0005], [122960000.0, 0.1376], [122956000.0, 0.0], [122950000.0, 0.0061], [122949000.0, 0.0002], [122948000.0, 0.0156], [122946000.0, 0.0269], [122944000.0, 0.0341], [122943000.0, 0.0152], [122940000.0, 0.0]], "asks": [[122970000.0, 0.2596], [122980000.0, 0.0004], [122999000.0, 0.0023], [123000000.0, 0.1049], [123001000.0, 0.0001], [123003000.0, 0.0081], [123004000.0, 0.0001], [123005000.0, 0.0081], [123006000.0, 0.0159], [123007000.0, 0.0082]]},
{"timestamp": "1743933489278", "bids": [[122968000.0, 0.0005], [122960000.0, 0.1376], [122956000.0, 0.0], [122950000.0, 0.0061], [122949000.0, 0.0002], [122948000.0, 0.0156], [122946000.0, 0.0269], [122944000.0, 0.0341], [122943000.0, 0.0152], [122940000.0, 0.0]], "asks": [[122970000.0, 0.2596], [122980000.0, 0.0004], [122999000.0, 0.0023], [123000000.0, 0.1049], [123001000.0, 0.0001], [123003000.0, 0.0081], [123004000.0, 0.0001], [123005000.0, 0.0081], [123006000.0, 0.0159], [123007000.0, 0.0082]]},
{"timestamp": "1743933489781", "bids": [[122968000.0, 0.0005], [122960000.0, 0.1376], [122956000.0, 0.0], [122953000.0, 0.0156], [122950000.0, 0.0061], [122949000.0, 0.0002], [122947000.0, 0.0152], [122944000.0, 0.003], [122940000.0, 0.0], [122931000.0, 0.0]], "asks": [[122970000.0, 0.2596], [122980000.0, 0.0004], [122999000.0, 0.0046], [123000000.0, 0.1049], [123001000.0, 0.0001], [123003000.0, 0.0081], [123004000.0, 0.0001], [123005000.0, 0.0081], [123006000.0, 0.0081], [123007000.0, 0.0082]]},
{"timestamp": "1743933490272", "bids": [[122968000.0, 0.0005], [122960000.0, 0.1376], [122956000.0, 0.0], [122953000.0, 0.0156], [122950000.0, 0.0061], [122949000.0, 0.0002], [122948000.0, 0.0152], [122947000.0, 0.0152], [122944000.0, 0.003], [122940000.0, 0.0]], "asks": [[122970000.0, 0.2596], [122980000.0, 0.0004], [122999000.0, 0.0023], [123000000.0, 0.1049], [123001000.0, 0.0001], [123003000.0, 0.0081], [123004000.0, 0.0001], [123005000.0, 0.0081], [123006000.0, 0.0081], [123007000.0, 0.0082]]},
{"timestamp": "1743933490796", "bids": [[122968000.0, 0.0005], [122960000.0, 0.1376], [122956000.0, 0.0], [122953000.0, 0.0156], [122950000.0, 0.0061], [122949000.0, 0.0002], [122948000.0, 0.0152], [122947000.0, 0.0152], [122944000.0, 0.003], [122940000.0, 0.0]], "asks": [[122970000.0, 0.2596], [122980000.0, 0.0004], [122999000.0, 0.0023], [123000000.0, 0.1049], [123001000.0, 0.0001], [123003000.0, 0.0081], [123004000.0, 0.0001], [123005000.0, 0.0081], [123006000.0, 0.0081], [123007000.0, 0.0082]]},
{"timestamp": "1743933491330", "bids": [[122968000.0, 0.0063], [122960000.0, 0.1376], [122956000.0, 0.0], [122953000.0, 0.0156], [122950000.0, 0.0061], [122949000.0, 0.0002], [122948000.0, 0.0152], [122947000.0, 0.0152], [122944000.0, 0.003], [122940000.0, 0.0]], "asks": [[122970000.0, 0.2596], [122980000.0, 0.0004], [122999000.0, 0.0023], [123000000.0, 0.1049], [123001000.0, 0.0001], [123003000.0, 0.0081], [123004000.0, 0.0001], [123005000.0, 0.0081], [123006000.0, 0.0081], [123007000.0, 0.0082]]},
{"timestamp": "1743933491833", "bids": [[122968000.0, 0.0063], [122960000.0, 0.1376], [122956000.0, 0.0], [122953000.0, 0.0156], [122950000.0, 0.0061], [122949000.0, 0.0002], [122948000.0, 0.0152], [122947000.0, 0.0152], [122944000.0, 0.003], [122940000.0, 0.0]], "asks": [[122970000.0, 0.2596], [122980000.0, 0.0004], [122999000.0, 0.0023], [123000000.0, 0.1049], [123001000.0, 0.0001], [123003000.0, 0.0081], [123004000.0, 0.0001], [123005000.0, 0.0081], [123006000.0, 0.0081], [123007000.0, 0.0082]]},
{"timestamp": "1743933492340", "bids": [[122968000.0, 0.0063], [122960000.0, 0.1376], [122956000.0, 0.0], [122953000.0, 0.0156], [122950000.0, 0.0061], [122949000.0, 0.0002], [122948000.0, 0.0152], [122947000.0, 0.0152], [122944000.0, 0.003], [122940000.0, 0.0]], "asks": [[122970000.0, 0.2596], [122980000.0, 0.0004], [122999000.0, 0.0023], [123000000.0, 0.1049], [123001000.0, 0.0001], [123003000.0, 0.0081], [123004000.0, 0.0001], [123005000.0, 0.0081], [123006000.0, 0.0081], [123007000.0, 0.0082]]},
{"timestamp": "1743933492862", "bids": [[122968000.0, 0.0063], [122960000.0, 0.1376], [122956000.0, 0.0], [122953000.0, 0.0156], [122950000.0, 0.0061], [122949000.0, 0.0002], [122948000.0, 0.0152], [122947000.0, 0.0152], [122944000.0, 0.003], [122940000.0, 0.0]], "asks": [[122970000.0, 0.2596], [122980000.0, 0.0004], [122999000.0, 0.0023], [123000000.0, 0.1049], [123001000.0, 0.0001], [123003000.0, 0.0081], [123004000.0, 0.0001], [123005000.0, 0.0081], [123006000.0, 0.0081], [123007000.0, 0.0082]]},
{"timestamp": "1743933493357", "bids": [[122968000.0, 0.0063], [122960000.0, 0.1376], [122956000.0, 0.0], [122953000.0, 0.0156], [122950000.0, 0.0061], [122949000.0, 0.0002], [122948000.0, 0.0152], [122947000.0, 0.0152], [122944000.0, 0.003], [122940000.0, 0.0]], "asks": [[122970000.0, 0.2596], [122980000.0, 0.0004], [122999000.0, 0.0023], [123000000.0, 0.1049], [123001000.0, 0.0001], [123003000.0, 0.0081], [123004000.0, 0.0001], [123005000.0, 0.0081], [123006000.0, 0.0081], [123007000.0, 0.0082]]},
{"timestamp": "1743933493859", "bids": [[122968000.0, 0.0063], [122960000.0, 0.1376], [122956000.0, 0.0], [122953000.0, 0.0156], [122950000.0, 0.0061], [122949000.0, 0.0002], [122948000.0, 0.0152], [122947000.0, 0.0152], [122944000.0, 0.003], [122940000.0, 0.0]], "asks": [[122970000.0, 0.2596], [122980000.0, 0.0004], [122999000.0, 0.0023], [123000000.0, 0.1049], [123001000.0, 0.0001], [123003000.0, 0.0081], [123004000.0, 0.0001], [123005000.0, 0.0081], [123006000.0, 0.0081], [123007000.0, 0.0082]]},
{"timestamp": "1743933494376", "bids": [[122968000.0, 0.0063], [122960000.0, 0.1376], [122956000.0, 0.0], [122953000.0, 0.0156], [122950000.0, 0.0061], [122949000.0, 0.0002], [122948000.0, 0.0152], [122947000.0, 0.0152], [122944000.0, 0.003], [122940000.0, 0.0]], "asks": [[122970000.0, 0.2596], [122980000.0, 0.0004], [122999000.0, 0.0023], [123000000.0, 0.1049], [123001000.0, 0.0001], [123003000.0, 0.0081], [123004000.0, 0.0001], [123005000.0, 0.0081], [123006000.0, 0.0081], [123007000.0, 0.0082]]},
{"timestamp": "1743933494884", "bids": [[122968000.0, 0.0002], [122960000.0, 0.1376], [122956000.0, 0.0], [122953000.0, 0.0156], [122950000.0, 0.0061], [122949000.0, 0.0002], [122948000.0, 0.0152], [122947000.0, 0.0152], [122944000.0, 0.003], [122940000.0, 0.0]], "asks": [[122970000.0, 0.2596], [122980000.0, 0.0004], [122999000.0, 0.0023], [123000000.0, 0.1049], [123001000.0, 0.0001], [123003000.0, 0.0081], [123004000.0, 0.0001], [123005000.0, 0.0081], [123006000.0, 0.0081], [123007000.0, 0.0082]]},
{"timestamp": "1743933495406", "bids": [[122968000.0, 0.0002], [122960000.0, 0.1376], [122956000.0, 0.0], [122953000.0, 0.0156], [122950000.0, 0.0061], [122949000.0, 0.0002], [122948000.0, 0.0152], [122947000.0, 0.0152], [122944000.0, 0.003], [122940000.0, 0.0]], "asks": [[122970000.0, 0.2596], [122980000.0, 0.0004], [122999000.0, 0.0023], [123000000.0, 0.1049], [123001000.0, 0.0001], [123003000.0, 0.0081], [123004000.0, 0.0001], [123005000.0, 0.0081], [123006000.0, 0.0081], [123007000.0, 0.0082]]},
{"timestamp": "1743933495937", "bids": [[122968000.0, 0.0002], [122960000.0, 0.1376], [122956000.0, 0.0], [122953000.0, 0.0156], [122950000.0, 0.0061], [122949000.0, 0.0002], [122948000.0, 0.0152], [122947000.0, 0.0152], [122944000.0, 0.003], [122940000.0, 0.0]], "asks": [[122970000.0, 0.2596], [122980000.0, 0.0004], [122999000.0, 0.0023], [123000000.0, 0.1049], [123001000.0, 0.0001], [123003000.0, 0.0081], [123004000.0, 0.0001], [123005000.0, 0.0081], [123006000.0, 0.0081], [123007000.0, 0.0082]]},
{"timestamp": "1743933496429", "bids": [[122968000.0, 0.0002], [122960000.0, 0.1376], [122956000.0, 0.0], [122953000.0, 0.0156], [122950000.0, 0.0061], [122949000.0, 0.0002], [122948000.0, 0.0152], [122947000.0, 0.0152], [122944000.0, 0.003], [122940000.0, 0.0]], "asks": [[122970000.0, 0.219], [122980000.0, 0.0004], [122999000.0, 0.0023], [123000000.0, 0.1049], [123001000.0, 0.0001], [123003000.0, 0.0081], [123004000.0, 0.0001], [123005000.0, 0.0081], [123006000.0, 0.0081], [123007000.0, 0.0082]]},
{"timestamp": "1743933496943", "bids": [[122968000.0, 0.0002], [122960000.0, 0.1376], [122956000.0, 0.0], [122953000.0, 0.0156], [122950000.0, 0.0061], [122949000.0, 0.0002], [122948000.0, 0.0152], [122947000.0, 0.0152], [122944000.0, 0.003], [122940000.0, 0.0]], "asks": [[122970000.0, 0.219], [122980000.0, 0.0004], [122999000.0, 0.0023], [123000000.0, 0.1049], [123001000.0, 0.0001], [123003000.0, 0.0081], [123004000.0, 0.0001], [123005000.0, 0.0081], [123006000.0, 0.0081], [123007000.0, 0.0082]]},
{"timestamp": "1743933497430", "bids": [[122968000.0, 0.0002], [122960000.0, 0.1376], [122956000.0, 0.0], [122953000.0, 0.0156], [122950000.0, 0.0061], [122949000.0, 0.0002], [122948000.0, 0.0152], [122947000.0, 0.0152], [122944000.0, 0.003], [122940000.0, 0.0]], "asks": [[122970000.0, 0.219], [122980000.0, 0.0004], [122999000.0, 0.0023], [123000000.0, 0.1049], [123001000.0, 0.0001], [123003000.0, 0.0081], [123004000.0, 0.0001], [123005000.0, 0.0081], [123006000.0, 0.0081], [123007000.0, 0.0082]]},
{"timestamp": "1743933497959", "bids": [[122968000.0, 0.0002], [122960000.0, 0.1376], [122956000.0, 0.0], [122953000.0, 0.0156], [122950000.0, 0.0061], [122949000.0, 0.0002], [122948000.0, 0.0152], [122947000.0, 0.0152], [122944000.0, 0.003], [122940000.0, 0.0]], "asks": [[122970000.0, 0.219], [122980000.0, 0.0004], [122999000.0, 0.0023], [123000000.0, 0.1049], [123001000.0, 0.0001], [123003000.0, 0.0081], [123004000.0, 0.0001], [123005000.0, 0.0081], [123006000.0, 0.0081], [123007000.0, 0.0082]]},
{"timestamp": "1743933498459", "bids": [[122968000.0, 0.0002], [122960000.0, 0.1376], [122956000.0, 0.0], [122953000.0, 0.0156], [122950000.0, 0.0061], [122949000.0, 0.0002], [122948000.0, 0.0152], [122947000.0, 0.0152], [122944000.0, 0.003], [122940000.0, 0.0]], "asks": [[122970000.0, 0.219], [122980000.0, 0.0004], [122999000.0, 0.0023], [123000000.0, 0.1049], [123001000.0, 0.0001], [123003000.0, 0.0081], [123004000.0, 0.0001], [123005000.0, 0.0081], [123006000.0, 0.0081], [123007000.0, 0.0082]]},
{"timestamp": "1743933498957", "bids": [[122968000.0, 0.0002], [122960000.0, 0.1376], [122956000.0, 0.0], [122953000.0, 0.0156], [122950000.0, 0.0061], [122949000.0, 0.0002], [122948000.0, 0.0152], [122947000.0, 0.0152], [122944000.0, 0.003], [122940000.0, 0.0]], "asks": [[122970000.0, 0.219], [122980000.0, 0.0004], [122999000.0, 0.0023], [123000000.0, 0.1049], [123001000.0, 0.0001], [123003000.0, 0.0081], [123004000.0, 0.0001], [123005000.0, 0.0081], [123006000.0, 0.0081], [123007000.0, 0.0082]]},
{"timestamp": "1743933499496", "bids": [[122968000.0, 0.0], [122960000.0, 0.1376], [122956000.0, 0.0], [122953000.0, 0.0156], [122950000.0, 0.0061], [122949000.0, 0.0002], [122948000.0, 0.0152], [122947000.0, 0.0152], [122944000.0, 0.003], [122940000.0, 0.0]], "asks": [[122970000.0, 0.219], [122980000.0, 0.0004], [122999000.0, 0.0023], [123000000.0, 0.1049], [123001000.0, 0.0001], [123003000.0, 0.0081], [123004000.0, 0.0001], [123005000.0, 0.0081], [123006000.0, 0.0081], [123007000.0, 0.0082]]},
{"timestamp": "1743933499982", "bids": [[122968000.0, 0.0], [122960000.0, 0.1376], [122956000.0, 0.0], [122953000.0, 0.0156], [122950000.0, 0.0061], [122949000.0, 0.0002], [122948000.0, 0.0152], [122947000.0, 0.0152], [122944000.0, 0.003], [122940000.0, 0.0]], "asks": [[122970000.0, 0.219], [122980000.0, 0.0004], [122999000.0, 0.0023], [123000000.0, 0.1049], [123001000.0, 0.0001], [123003000.0, 0.0081], [123004000.0, 0.0001], [123005000.0, 0.0081], [123006000.0, 0.0081], [123007000.0, 0.0082]]},
{"timestamp": "1743933500513", "bids": [[122968000.0, 0.0], [122960000.0, 0.1376], [122956000.0, 0.0], [122953000.0, 0.0156], [122950000.0, 0.0061], [122949000.0, 0.0002], [122948000.0, 0.0152], [122947000.0, 0.0152], [122944000.0, 0.003], [122940000.0, 0.0]], "asks": [[122970000.0, 0.219], [122980000.0, 0.0004], [122999000.0, 0.0023], [123000000.0, 0.1049], [123001000.0, 0.0001], [123003000.0, 0.0081], [123004000.0, 0.0001], [123005000.0, 0.0081], [123006000.0, 0.0081], [123007000.0, 0.0082]]},
{"timestamp": "1743933501004", "bids": [[122968000.0, 0.0], [122960000.0, 0.1376], [122956000.0, 0.0], [122953000.0, 0.0156], [122950000.0, 0.0061], [122949000.0, 0.0002], [122948000.0, 0.0152], [122947000.0, 0.0152], [122944000.0, 0.003], [122940000.0, 0.0]], "asks": [[122970000.0, 0.219], [122980000.0, 0.0004], [122999000.0, 0.0023], [123000000.0, 0.1049], [123001000.0, 0.0001], [123003000.0, 0.0081], [123004000.0, 0.0001], [123005000.0, 0.0081], [123006000.0, 0.0081], [123007000.0, 0.0082]]},
{"timestamp": "1743933501555", "bids": [[122968000.0, 0.0], [122960000.0, 0.1376], [122956000.0, 0.0], [122953000.0, 0.0156], [122950000.0, 0.0061], [122949000.0, 0.0002], [122948000.0, 0.0152], [122947000.0, 0.0152], [122944000.0, 0.003], [122940000.0, 0.0]], "asks": [[122970000.0, 0.219], [122980000.0, 0.0004], [122999000.0, 0.0023], [123000000.0, 0.1049], [123001000.0, 0.0001], [123003000.0, 0.0081], [123004000.0, 0.0001], [123005000.0, 0.0081], [123006000.0, 0.0081], [123007000.0, 0.0082]]},
{"timestamp": "1743933502049", "bids": [[122968000.0, 0.0], [122960000.0, 0.1376], [122956000.0, 0.0], [122953000.0, 0.0156], [122950000.0, 0.0061], [122949000.0, 0.0002], [122948000.0, 0.0152], [122947000.0, 0.0152], [122944000.0, 0.003], [122940000.0, 0.0]], "asks": [[122970000.0, 0.219], [122980000.0, 0.0004], [122999000.0, 0.0023], [123000000.0, 0.1049], [123001000.0, 0.0001], [123003000.0, 0.0081], [123004000.0, 0.0001], [123005000.0, 0.0081], [123006000.0, 0.0081], [123007000.0, 0.0082]]},
{"timestamp": "1743933502548", "bids": [[122968000.0, 0.0], [122960000.0, 0.1376], [122956000.0, 0.0], [122953000.0, 0.0156], [122950000.0, 0.0061], [122949000.0, 0.0002], [122948000.0, 0.0152], [122947000.0, 0.0152], [122944000.0, 0.003], [122940000.0, 0.0]], "asks": [[122970000.0, 0.219], [122980000.0, 0.0004], [122999000.0, 0.0023], [123000000.0, 0.1049], [123001000.0, 0.0001], [123003000.0, 0.0081], [123004000.0, 0.0001], [123005000.0, 0.0081], [123006000.0, 0.0081], [123007000.0, 0.0082]]},
{"timestamp": "1743933503061", "bids": [[122968000.0, 0.0], [122960000.0, 0.1376], [122956000.0, 0.0], [122953000.0, 0.0156], [122950000.0, 0.0061], [122949000.0, 0.0002], [122948000.0, 0.0152], [122947000.0, 0.0152], [122944000.0, 0.003], [122940000.0, 0.0]], "asks": [[122970000.0, 0.219], [122980000.0, 0.0004], [122999000.0, 0.0023], [123000000.0, 0.1049], [123001000.0, 0.0001], [123003000.0, 0.0081], [123004000.0, 0.0001], [123005000.0, 0.0081], [123006000.0, 0.0081], [123007000.0, 0.0082]]},
{"timestamp": "1743933503603", "bids": [[122968000.0, 0.0], [122960000.0, 0.1376], [122956000.0, 0.0], [122953000.0, 0.0156], [122950000.0, 0.0061], [122949000.0, 0.0002], [122948000.0, 0.0152], [122947000.0, 0.0152], [122944000.0, 0.003], [122940000.0, 0.0]], "asks": [[122970000.0, 0.219], [122980000.0, 0.0004], [122999000.0, 0.0023], [123000000.0, 0.1049], [123001000.0, 0.0001], [123003000.0, 0.0081], [123004000.0, 0.0001], [123005000.0, 0.0081], [123006000.0, 0.0081], [123007000.0, 0.0082]]},
{"timestamp": "1743933504085", "bids": [[122968000.0, 0.0], [122960000.0, 0.1376], [122956000.0, 0.0], [122953000.0, 0.0156], [122950000.0, 0.0061], [122949000.0, 0.0002], [122948000.0, 0.0152], [122947000.0, 0.0152], [122944000.0, 0.003], [122940000.0, 0.0]], "asks": [[122970000.0, 0.219], [122980000.0, 0.0004], [122999000.0, 0.0023], [123000000.0, 0.1049], [123001000.0, 0.0001], [123003000.0, 0.0081], [123004000.0, 0.0001], [123005000.0, 0.0081], [123006000.0, 0.0081], [123007000.0, 0.0082]]},
{"timestamp": "1743933504594", "bids": [[122968000.0, 0.0], [122960000.0, 0.1376], [122956000.0, 0.0], [122953000.0, 0.0156], [122950000.0, 0.0061], [122949000.0, 0.0002], [122948000.0, 0.0152], [122947000.0, 0.0152], [122944000.0, 0.003], [122940000.0, 0.0]], "asks": [[122970000.0, 0.219], [122980000.0, 0.0004], [122999000.0, 0.0023], [123000000.0, 0.1049], [123001000.0, 0.0001], [123003000.0, 0.0081], [123004000.0, 0.0001], [123005000.0, 0.0081], [123006000.0, 0.0081], [123007000.0, 0.0082]]},
{"timestamp": "1743933505109", "bids": [[122968000.0, 0.0], [122960000.0, 0.1376], [122956000.0, 0.0], [122953000.0, 0.0156], [122950000.0, 0.0061], [122949000.0, 0.0002], [122948000.0, 0.0152], [122947000.0, 0.0152], [122944000.0, 0.003], [122940000.0, 0.0]], "asks": [[122970000.0, 0.219], [122980000.0, 0.0004], [122994000.0, 0.0023], [123000000.0, 0.1049], [123001000.0, 0.0001], [123003000.0, 0.0081], [123004000.0, 0.0001], [123005000.0, 0.0081], [123006000.0, 0.0081], [123007000.0, 0.0082]]},
{"timestamp": "1743933505647", "bids": [[122968000.0, 0.0], [122960000.0, 0.1376], [122956000.0, 0.0], [122953000.0, 0.0156], [122950000.0, 0.0061], [122949000.0, 0.0002], [122948000.0, 0.0152], [122947000.0, 0.0152], [122944000.0, 0.003], [122940000.0, 0.0]], "asks": [[122970000.0, 0.219], [122980000.0, 0.0004], [122994000.0, 0.0023], [123000000.0, 0.1049], [123001000.0, 0.0001], [123003000.0, 0.0081], [123004000.0, 0.0001], [123005000.0, 0.0081], [123006000.0, 0.0081], [123007000.0, 0.0082]]},
{"timestamp": "1743933506137", "bids": [[122968000.0, 0.0], [122960000.0, 0.1376], [122956000.0, 0.0], [122953000.0, 0.0156], [122950000.0, 0.0061], [122949000.0, 0.0002], [122948000.0, 0.0152], [122947000.0, 0.0152], [122944000.0, 0.003], [122940000.0, 0.0]], "asks": [[122970000.0, 0.219], [122980000.0, 0.0004], [122994000.0, 0.0023], [123000000.0, 0.1049], [123001000.0, 0.0001], [123003000.0, 0.0081], [123004000.0, 0.0001], [123005000.0, 0.0081], [123006000.0, 0.0081], [123007000.0, 0.0082]]},
{"timestamp": "1743933506661", "bids": [[122968000.0, 0.0], [122960000.0, 0.1376], [122956000.0, 0.0], [122953000.0, 0.0156], [122950000.0, 0.0061], [122949000.0, 0.0002], [122948000.0, 0.0152], [122947000.0, 0.0152], [122944000.0, 0.003], [122940000.0, 0.0]], "asks": [[122970000.0, 0.219], [122980000.0, 0.0004], [122994000.0, 0.0023], [123000000.0, 0.1049], [123001000.0, 0.0001], [123003000.0, 0.0081], [123004000.0, 0.0001], [123005000.0, 0.0081], [123006000.0, 0.0081], [123007000.0, 0.0082]]},
{"timestamp": "1743933507160", "bids": [[122968000.0, 0.0], [122960000.0, 0.1376], [122956000.0, 0.0], [122953000.0, 0.0156], [122950000.0, 0.0061], [122949000.0, 0.0002], [122948000.0, 0.0152], [122947000.0, 0.0152], [122944000.0, 0.003], [122940000.0, 0.0]], "asks": [[122970000.0, 0.219], [122980000.0, 0.0004], [122994000.0, 0.0023], [123000000.0, 0.1049], [123001000.0, 0.0001], [123003000.0, 0.0081], [123004000.0, 0.0001], [123005000.0, 0.0081], [123006000.0, 0.0081], [123007000.0, 0.0082]]},
{"timestamp": "1743933507691", "bids": [[122968000.0, 0.0], [122960000.0, 0.1376], [122956000.0, 0.0], [122953000.0, 0.0156], [122950000.0, 0.0061], [122949000.0, 0.0002], [122948000.0, 0.0152], [122947000.0, 0.0152], [122944000.0, 0.003], [122940000.0, 0.0]], "asks": [[122970000.0, 0.219], [122980000.0, 0.0004], [122994000.0, 0.0023], [123000000.0, 0.1049], [123001000.0, 0.0001], [123003000.0, 0.0081], [123004000.0, 0.0001], [123005000.0, 0.0081], [123006000.0, 0.0081], [123007000.0, 0.0082]]},
{"timestamp": "1743933508190", "bids": [[122968000.0, 0.0], [122960000.0, 0.1376], [122956000.0, 0.0], [122953000.0, 0.0156], [122950000.0, 0.0061], [122949000.0, 0.0002], [122948000.0, 0.0152], [122947000.0, 0.0152], [122944000.0, 0.003], [122940000.0, 0.0]], "asks": [[122970000.0, 0.219], [122980000.0, 0.0004], [122994000.0, 0.0023], [123000000.0, 0.1049], [123001000.0, 0.0001], [123003000.0, 0.0081], [123004000.0, 0.0001], [123005000.0, 0.0081], [123006000.0, 0.0081], [123007000.0, 0.0082]]},
{"timestamp": "1743933508701", "bids": [[122968000.0, 0.0], [122960000.0, 0.1376], [122956000.0, 0.0], [122953000.0, 0.0156], [122950000.0, 0.0061], [122949000.0, 0.0002], [122948000.0, 0.0152], [122947000.0, 0.0152], [122944000.0, 0.003], [122940000.0, 0.0]], "asks": [[122970000.0, 0.219], [122980000.0, 0.0004], [122994000.0, 0.0023], [123000000.0, 0.1049], [123001000.0, 0.0001], [123003000.0, 0.0081], [123004000.0, 0.0001], [123005000.0, 0.0081], [123006000.0, 0.0081], [123007000.0, 0.0082]]},
{"timestamp": "1743933509206", "bids": [[122968000.0, 0.0], [122960000.0, 0.1376], [122956000.0, 0.0], [122953000.0, 0.0156], [122950000.0, 0.0061], [122949000.0, 0.0002], [122948000.0, 0.0152], [122947000.0, 0.0152], [122944000.0, 0.003], [122940000.0, 0.0]], "asks": [[122970000.0, 0.219], [122980000.0, 0.0004], [122994000.0, 0.0023], [123000000.0, 0.1049], [123001000.0, 0.0001], [123003000.0, 0.0081], [123004000.0, 0.0001], [123005000.0, 0.0081], [123006000.0, 0.0081], [123007000.0, 0.0082]]},
{"timestamp": "1743933509733", "bids": [[122968000.0, 0.0], [122960000.0, 0.1376], [122956000.0, 0.0], [122953000.0, 0.0156], [122950000.0, 0.0061], [122949000.0, 0.0002], [122948000.0, 0.0152], [122947000.0, 0.0152], [122944000.0, 0.003], [122940000.0, 0.0]], "asks": [[122970000.0, 0.219], [122980000.0, 0.0004], [122994000.0, 0.0023], [123000000.0, 0.1049], [123001000.0, 0.0001], [123003000.0, 0.0081], [123004000.0, 0.0001], [123005000.0, 0.0081], [123006000.0, 0.0081], [123007000.0, 0.0082]]},
{"timestamp": "1743933510248", "bids": [[122968000.0, 0.0], [122960000.0, 0.1376], [122956000.0, 0.0], [122953000.0, 0.0156], [122950000.0, 0.0061], [122949000.0, 0.0002], [122948000.0, 0.0152], [122947000.0, 0.0152], [122944000.0, 0.003], [122940000.0, 0.0]], "asks": [[122970000.0, 0.219], [122980000.0, 0.0004], [122994000.0, 0.0023], [123000000.0, 0.1049], [123001000.0, 0.0001], [123003000.0, 0.0081], [123004000.0, 0.0001], [123005000.0, 0.0081], [123006000.0, 0.0081], [123007000.0, 0.0082]]},
{"timestamp": "1743933510743", "bids": [[122968000.0, 0.0], [122960000.0, 0.1376], [122956000.0, 0.0], [122953000.0, 0.0156], [122950000.0, 0.0061], [122949000.0, 0.0002], [122948000.0, 0.0152], [122947000.0, 0.0152], [122944000.0, 0.003], [122940000.0, 0.0]], "asks": [[122970000.0, 0.219], [122980000.0, 0.0004], [122994000.0, 0.0023], [123000000.0, 0.1049], [123001000.0, 0.0001], [123003000.0, 0.0081], [123004000.0, 0.0001], [123005000.0, 0.0081], [123006000.0, 0.0081], [123007000.0, 0.0082]]},
{"timestamp": "1743933511259", "bids": [[122968000.0, 0.0], [122960000.0, 0.1376], [122956000.0, 0.0], [122953000.0, 0.0156], [122950000.0, 0.0061], [122949000.0, 0.0002], [122948000.0, 0.0152], [122947000.0, 0.0152], [122944000.0, 0.003], [122940000.0, 0.0]], "asks": [[122970000.0, 0.219], [122980000.0, 0.0004], [122994000.0, 0.0023], [123000000.0, 0.1049], [123001000.0, 0.0001], [123003000.0, 0.0081], [123004000.0, 0.0001], [123005000.0, 0.0081], [123006000.0, 0.0081], [123007000.0, 0.0082]]},
{"timestamp": "1743933511779", "bids": [[122968000.0, 0.0], [122960000.0, 0.1376], [122956000.0, 0.0], [122953000.0, 0.0156], [122950000.0, 0.0061], [122949000.0, 0.0002], [122948000.0, 0.0152], [122947000.0, 0.0152], [122944000.0, 0.003], [122940000.0, 0.0]], "asks": [[122970000.0, 0.1379], [122980000.0, 0.0004], [122994000.0, 0.0023], [123000000.0, 0.1049], [123001000.0, 0.0001], [123003000.0, 0.0081], [123004000.0, 0.0001], [123005000.0, 0.0081], [123006000.0, 0.0081], [123007000.0, 0.0082]]},
{"timestamp": "1743933512264", "bids": [[122968000.0, 0.0], [122960000.0, 0.1376], [122956000.0, 0.0], [122953000.0, 0.0156], [122950000.0, 0.0061], [122949000.0, 0.0002], [122948000.0, 0.0152], [122947000.0, 0.0152], [122944000.0, 0.003], [122940000.0, 0.0]], "asks": [[122970000.0, 0.1379], [122980000.0, 0.0004], [122994000.0, 0.0023], [123000000.0, 0.1049], [123001000.0, 0.0001], [123003000.0, 0.0081], [123004000.0, 0.0001], [123005000.0, 0.0081], [123006000.0, 0.0081], [123007000.0, 0.0082]]},
{"timestamp": "1743933512797", "bids": [[122968000.0, 0.0], [122960000.0, 0.1376], [122956000.0, 0.0], [122953000.0, 0.0156], [122950000.0, 0.0061], [122949000.0, 0.0002], [122948000.0, 0.0152], [122947000.0, 0.0152], [122944000.0, 0.003], [122940000.0, 0.0]], "asks": [[122970000.0, 0.1378], [122980000.0, 0.0004], [122994000.0, 0.0023], [123000000.0, 0.1049], [123001000.0, 0.0001], [123003000.0, 0.0081], [123004000.0, 0.0001], [123005000.0, 0.0081], [123006000.0, 0.0081], [123007000.0, 0.0082]]},
{"timestamp": "1743933513311", "bids": [[122968000.0, 0.0], [122960000.0, 0.1376], [122956000.0, 0.0], [122953000.0, 0.0156], [122950000.0, 0.0061], [122949000.0, 0.0002], [122948000.0, 0.0152], [122947000.0, 0.0152], [122944000.0, 0.003], [122940000.0, 0.0]], "asks": [[122970000.0, 0.1378], [122980000.0, 0.0004], [122994000.0, 0.0023], [123000000.0, 0.1049], [123001000.0, 0.0001], [123003000.0, 0.0081], [123004000.0, 0.0001], [123005000.0, 0.0081], [123006000.0, 0.0081], [123007000.0, 0.0082]]},
{"timestamp": "1743933513824", "bids": [[122968000.0, 0.0], [122960000.0, 0.1376], [122956000.0, 0.0], [122953000.0, 0.0156], [122950000.0, 0.0061], [122949000.0, 0.0002], [122948000.0, 0.0152], [122947000.0, 0.0152], [122944000.0, 0.003], [122940000.0, 0.0]], "asks": [[122970000.0, 0.1378], [122980000.0, 0.0004], [122994000.0, 0.0023], [123000000.0, 0.1049], [123001000.0, 0.0001], [123003000.0, 0.0081], [123004000.0, 0.0001], [123005000.0, 0.0081], [123006000.0, 0.0081], [123007000.0, 0.0082]]},
{"timestamp": "1743933514313", "bids": [[122968000.0, 0.0], [122960000.0, 0.1376], [122956000.0, 0.0], [122953000.0, 0.0156], [122950000.0, 0.0061], [122949000.0, 0.0002], [122948000.0, 0.0152], [122947000.0, 0.0152], [122944000.0, 0.003], [122940000.0, 0.0]], "asks": [[122970000.0, 0.1378], [122980000.0, 0.0004], [122994000.0, 0.0023], [123000000.0, 0.1049], [123001000.0, 0.0001], [123003000.0, 0.0081], [123004000.0, 0.0001], [123005000.0, 0.0081], [123006000.0, 0.0081], [123007000.0, 0.0082]]},
{"timestamp": "1743933514825", "bids": [[122968000.0, 0.0], [122960000.0, 0.1376], [122956000.0, 0.0], [122953000.0, 0.0156], [122950000.0, 0.0061], [122949000.0, 0.0002], [122948000.0, 0.0152], [122947000.0, 0.0152], [122944000.0, 0.003], [122940000.0, 0.0]], "asks": [[122970000.0, 0.1378], [122980000.0, 0.0004], [122994000.0, 0.0023], [123000000.0, 0.1049], [123001000.0, 0.0001], [123003000.0, 0.0081], [123004000.0, 0.0001], [123005000.0, 0.0081], [123006000.0, 0.0081], [123007000.0, 0.0082]]},
{"timestamp": "1743933515349", "bids": [[122968000.0, 0.0], [122960000.0, 0.1376], [122956000.0, 0.0], [122953000.0, 0.0156], [122950000.0, 0.0061], [122949000.0, 0.0002], [122948000.0, 0.0152], [122947000.0, 0.0152], [122944000.0, 0.003], [122940000.0, 0.0]], "asks": [[122970000.0, 0.1378], [122980000.0, 0.0004], [122994000.0, 0.0023], [123000000.0, 0.1049], [123001000.0, 0.0001], [123003000.0, 0.0081], [123004000.0, 0.0001], [123005000.0, 0.0081], [123006000.0, 0.0081], [123007000.0, 0.0082]]},
{"timestamp": "1743933515875", "bids": [[122968000.0, 0.0], [122960000.0, 0.1376], [122956000.0, 0.0], [122953000.0, 0.0156], [122950000.0, 0.0061], [122949000.0, 0.0002], [122948000.0, 0.0152], [122947000.0, 0.0152], [122944000.0, 0.003], [122940000.0, 0.0]], "asks": [[122970000.0, 0.1378], [122980000.0, 0.0004], [122994000.0, 0.0023], [123000000.0, 0.1049], [123001000.0, 0.0001], [123003000.0, 0.0081], [123004000.0, 0.0001], [123005000.0, 0.0081], [123006000.0, 0.0081], [123007000.0, 0.0082]]},
{"timestamp": "1743933516351", "bids": [[122968000.0, 0.0], [122960000.0, 0.1376], [122956000.0, 0.0], [122953000.0, 0.0156], [122950000.0, 0.0061], [122949000.0, 0.0002], [122948000.0, 0.0152], [122947000.0, 0.0152], [122944000.0, 0.003], [122940000.0, 0.0]], "asks": [[122970000.0, 0.1378], [122980000.0, 0.0004], [122994000.0, 0.0023], [123000000.0, 0.1049], [123001000.0, 0.0001], [123003000.0, 0.0081], [123004000.0, 0.0001], [123005000.0, 0.0081], [123006000.0, 0.0081], [123007000.0, 0.0082]]},
{"timestamp": "1743933516879", "bids": [[122968000.0, 0.0], [122960000.0, 0.1376], [122956000.0, 0.0], [122953000.0, 0.0156], [122950000.0, 0.0061], [122949000.0, 0.0002], [122948000.0, 0.0152], [122947000.0, 0.0152], [122944000.0, 0.003], [122940000.0, 0.0]], "asks": [[122970000.0, 0.1378], [122980000.0, 0.0004], [122994000.0, 0.0023], [123000000.0, 0.1049], [123001000.0, 0.0001], [123003000.0, 0.0081], [123004000.0, 0.0001], [123005000.0, 0.0081], [123006000.0, 0.0081], [123007000.0, 0.0082]]},
{"timestamp": "1743933517409", "bids": [[122968000.0, 0.0], [122960000.0, 0.1376], [122956000.0, 0.0], [122953000.0, 0.0156], [122950000.0, 0.0061], [122949000.0, 0.0002], [122948000.0, 0.0152], [122947000.0, 0.0152], [122944000.0, 0.003], [122940000.0, 0.0]], "asks": [[122970000.0, 0.1378], [122980000.0, 0.0004], [122994000.0, 0.0023], [123000000.0, 0.1049], [123001000.0, 0.0001], [123003000.0, 0.0081], [123004000.0, 0.0001], [123005000.0, 0.0081], [123006000.0, 0.0081], [123007000.0, 0.0082]]},
{"timestamp": "1743933517900", "bids": [[122968000.0, 0.0], [122960000.0, 0.1376], [122956000.0, 0.0], [122953000.0, 0.0156], [122950000.0, 0.0061], [122949000.0, 0.0002], [122948000.0, 0.0152], [122947000.0, 0.0152], [122944000.0, 0.003], [122940000.0, 0.0]], "asks": [[122970000.0, 0.1378], [122980000.0, 0.0004], [122994000.0, 0.0023], [123000000.0, 0.1049], [123001000.0, 0.0001], [123003000.0, 0.0081], [123004000.0, 0.0001], [123005000.0, 0.0081], [123006000.0, 0.0081], [123007000.0, 0.0082]]},
{"timestamp": "1743933518412", "bids": [[122968000.0, 0.0], [122960000.0, 0.1376], [122956000.0, 0.0], [122953000.0, 0.0156], [122950000.0, 0.0061], [122949000.0, 0.0002], [122948000.0, 0.0152], [122947000.0, 0.0152], [122944000.0, 0.003], [122940000.0, 0.0]], "asks": [[122970000.0, 0.1378], [122980000.0, 0.0004], [122994000.0, 0.0023], [123000000.0, 0.1049], [123001000.0, 0.0001], [123003000.0, 0.0081], [123004000.0, 0.0001], [123005000.0, 0.0081], [123006000.0, 0.0081], [123007000.0, 0.0082]]},
{"timestamp": "1743933518928", "bids": [[122968000.0, 0.0], [122960000.0, 0.1376], [122956000.0, 0.0], [122953000.0, 0.0156], [122950000.0, 0.0061], [122949000.0, 0.0002], [122948000.0, 0.0152], [122947000.0, 0.0152], [122944000.0, 0.003], [122940000.0, 0.0]], "asks": [[122970000.0, 0.1378], [122980000.0, 0.0004], [122994000.0, 0.0023], [123000000.0, 0.1049], [123001000.0, 0.0001], [123003000.0, 0.0081], [123004000.0, 0.0001], [123005000.0, 0.0081], [123006000.0, 0.0081], [123007000.0, 0.0082]]},
{"timestamp": "1743933519416", "bids": [[122968000.0, 0.0], [122960000.0, 0.1376], [122956000.0, 0.0], [122953000.0, 0.0156], [122950000.0, 0.0061], [122949000.0, 0.0002], [122948000.0, 0.0152], [122947000.0, 0.0152], [122944000.0, 0.003], [122940000.0, 0.0]], "asks": [[122970000.0, 0.1378], [122980000.0, 0.0004], [122994000.0, 0.0023], [123000000.0, 0.1049], [123001000.0, 0.0001], [123003000.0, 0.0081], [123004000.0, 0.0001], [123005000.0, 0.0081], [123006000.0, 0.0081], [123007000.0, 0.0082]]},
{"timestamp": "1743933519934", "bids": [[122968000.0, 0.0], [122960000.0, 0.1376], [122956000.0, 0.0], [122953000.0, 0.0156], [122950000.0, 0.0061], [122949000.0, 0.0002], [122948000.0, 0.0152], [122947000.0, 0.0152], [122944000.0, 0.003], [122940000.0, 0.0]], "asks": [[122970000.0, 0.1378], [122980000.0, 0.0004], [122994000.0, 0.0023], [123000000.0, 0.1049], [123001000.0, 0.0001], [123003000.0, 0.0081], [123004000.0, 0.0001], [123005000.0, 0.0081], [123006000.0, 0.0081], [123007000.0, 0.0082]]},
{"timestamp": "1743933520461", "bids": [[122968000.0, 0.0], [122960000.0, 0.1376], [122956000.0, 0.0], [122953000.0, 0.0156], [122950000.0, 0.0061], [122949000.0, 0.0002], [122948000.0, 0.0152], [122947000.0, 0.0152], [122944000.0, 0.003], [122940000.0, 0.0]], "asks": [[122970000.0, 0.1378], [122980000.0, 0.0004], [122994000.0, 0.0023], [123000000.0, 0.1049], [123001000.0, 0.0001], [123003000.0, 0.0081], [123004000.0, 0.0001], [123005000.0, 0.0081], [123006000.0, 0.0081], [123007000.0, 0.0082]]},
{"timestamp": "1743933521008", "bids": [[122968000.0, 0.0], [122960000.0, 0.1376], [122956000.0, 0.0], [122953000.0, 0.0156], [122950000.0, 0.0061], [122949000.0, 0.0002], [122948000.0, 0.0152], [122947000.0, 0.0152], [122944000.0, 0.003], [122940000.0, 0.0]], "asks": [[122970000.0, 0.1378], [122980000.0, 0.0004], [122994000.0, 0.0023], [123000000.0, 0.1049], [123001000.0, 0.0001], [123003000.0, 0.0081], [123004000.0, 0.0001], [123005000.0, 0.0081], [123006000.0, 0.0081], [123007000.0, 0.0082]]},
{"timestamp": "1743933521479", "bids": [[122968000.0, 0.0], [122960000.0, 0.1376], [122956000.0, 0.0], [122953000.0, 0.0156], [122950000.0, 0.0061], [122949000.0, 0.0002], [122948000.0, 0.0152], [122947000.0, 0.0152], [122944000.0, 0.003], [122940000.0, 0.0]], "asks": [[122970000.0, 0.1378], [122980000.0, 0.0004], [122994000.0, 0.0023], [123000000.0, 0.1049], [123001000.0, 0.0001], [123003000.0, 0.0081], [123004000.0, 0.0001], [123005000.0, 0.0081], [123006000.0, 0.0081], [123007000.0, 0.0082]]},
{"timestamp": "1743933521995", "bids": [[122968000.0, 0.0], [122960000.0, 0.1376], [122956000.0, 0.0], [122953000.0, 0.0156], [122950000.0, 0.0061], [122949000.0, 0.0002], [122948000.0, 0.0152], [122947000.0, 0.0152], [122944000.0, 0.003], [122940000.0, 0.0]], "asks": [[122970000.0, 0.1378], [122980000.0, 0.0004], [122994000.0, 0.0023], [123000000.0, 0.1049], [123001000.0, 0.0001], [123003000.0, 0.0081], [123004000.0, 0.0001], [123005000.0, 0.0081], [123006000.0, 0.0081], [123007000.0, 0.0082]]},
{"timestamp": "1743933522548", "bids": [[122968000.0, 0.0], [122960000.0, 0.1376], [122956000.0, 0.0], [122953000.0, 0.0156], [122950000.0, 0.0061], [122949000.0, 0.0002], [122948000.0, 0.0152], [122947000.0, 0.0152], [122944000.0, 0.003], [122940000.0, 0.0]], "asks": [[122970000.0, 0.1378], [122980000.0, 0.0004], [122994000.0, 0.0023], [123000000.0, 0.1049], [123001000.0, 0.0001], [123003000.0, 0.0081], [123004000.0, 0.0001], [123005000.0, 0.0081], [123006000.0, 0.0081], [123007000.0, 0.0082]]},
{"timestamp": "1743933523051", "bids": [[122968000.0, 0.0], [122960000.0, 0.1376], [122956000.0, 0.0], [122953000.0, 0.0156], [122950000.0, 0.0061], [122949000.0, 0.0002], [122948000.0, 0.0152], [122947000.0, 0.0152], [122944000.0, 0.003], [122940000.0, 0.0]], "asks": [[122970000.0, 0.1378], [122980000.0, 0.0004], [122994000.0, 0.0023], [123000000.0, 0.1049], [123001000.0, 0.0001], [123003000.0, 0.0081], [123004000.0, 0.0001], [123005000.0, 0.0081], [123006000.0, 0.0081], [123007000.0, 0.0082]]},
{"timestamp": "1743933523575", "bids": [[122968000.0, 0.0], [122960000.0, 0.1376], [122956000.0, 0.0], [122953000.0, 0.0156], [122950000.0, 0.0061], [122949000.0, 0.0002], [122948000.0, 0.0152], [122947000.0, 0.0152], [122944000.0, 0.003], [122940000.0, 0.0]], "asks": [[122970000.0, 0.1378], [122980000.0, 0.0004], [122994000.0, 0.0023], [123000000.0, 0.1049], [123001000.0, 0.0001], [123003000.0, 0.0081], [123004000.0, 0.0001], [123005000.0, 0.0081], [123006000.0, 0.0081], [123007000.0, 0.0082]]},
{"timestamp": "1743933524086", "bids": [[122968000.0, 0.0], [122960000.0, 0.1376], [122956000.0, 0.0], [122953000.0, 0.0156], [122950000.0, 0.0061], [122949000.0, 0.0002], [122948000.0, 0.0152], [122947000.0, 0.0152], [122944000.0, 0.003], [122940000.0, 0.0]], "asks": [[122970000.0, 0.1378], [122980000.0, 0.0004], [122994000.0, 0.0023], [123000000.0, 0.1049], [123001000.0, 0.0001], [123003000.0, 0.0081], [123004000.0, 0.0001], [123005000.0, 0.0081], [123006000.0, 0.0081], [123007000.0, 0.0082]]},
{"timestamp": "1743933524541", "bids": [[122968000.0, 0.0], [122960000.0, 0.1376], [122956000.0, 0.0], [122953000.0, 0.0156], [122950000.0, 0.0061], [122949000.0, 0.0002], [122948000.0, 0.0152], [122947000.0, 0.0152], [122944000.0, 0.003], [122940000.0, 0.0]], "asks": [[122970000.0, 0.1378], [122980000.0, 0.0004], [122994000.0, 0.0023], [123000000.0, 0.1049], [123001000.0, 0.0001], [123003000.0, 0.0081], [123004000.0, 0.0001], [123005000.0, 0.0081], [123006000.0, 0.0081], [123007000.0, 0.0082]]},
{"timestamp": "1743933525108", "bids": [[122968000.0, 0.0], [122960000.0, 0.1376], [122956000.0, 0.0], [122953000.0, 0.0156], [122950000.0, 0.0061], [122949000.0, 0.0002], [122948000.0, 0.0152], [122947000.0, 0.0152], [122944000.0, 0.003], [122940000.0, 0.0]], "asks": [[122970000.0, 0.1378], [122980000.0, 0.0004], [122994000.0, 0.0023], [123000000.0, 0.1049], [123001000.0, 0.0001], [123003000.0, 0.0081], [123004000.0, 0.0001], [123005000.0, 0.0081], [123006000.0, 0.0081], [123007000.0, 0.0082]]},
{"timestamp": "1743933525643", "bids": [[122968000.0, 0.0], [122960000.0, 0.1376], [122956000.0, 0.0], [122953000.0, 0.0156], [122950000.0, 0.0061], [122949000.0, 0.0002], [122948000.0, 0.0152], [122947000.0, 0.0152], [122944000.0, 0.003], [122940000.0, 0.0]], "asks": [[122970000.0, 0.1378], [122980000.0, 0.0004], [122994000.0, 0.0023], [123000000.0, 0.1049], [123001000.0, 0.0001], [123003000.0, 0.0081], [123004000.0, 0.0001], [123005000.0, 0.0081], [123006000.0, 0.0081], [123007000.0, 0.0082]]},
{"timestamp": "1743933526072", "bids": [[122968000.0, 0.0], [122960000.0, 0.1376], [122956000.0, 0.0], [122953000.0, 0.0156], [122950000.0, 0.0061], [122949000.0, 0.0002], [122948000.0, 0.0152], [122947000.0, 0.0152], [122944000.0, 0.003], [122940000.0, 0.0]], "asks": [[122970000.0, 0.1378], [122980000.0, 0.0004], [122994000.0, 0.0023], [123000000.0, 0.1049], [123001000.0, 0.0001], [123003000.0, 0.0081], [123004000.0, 0.0001], [123005000.0, 0.0081], [123006000.0, 0.0081], [123007000.0, 0.0082]]},
{"timestamp": "1743933526591", "bids": [[122968000.0, 0.0], [122960000.0, 0.1376], [122956000.0, 0.0], [122953000.0, 0.0156], [122950000.0, 0.0061], [122949000.0, 0.0002], [122948000.0, 0.0152], [122947000.0, 0.0152], [122944000.0, 0.003], [122940000.0, 0.0]], "asks": [[122970000.0, 0.1378], [122980000.0, 0.0004], [122994000.0, 0.0023], [123000000.0, 0.1049], [123001000.0, 0.0001], [123003000.0, 0.0081], [123004000.0, 0.0001], [123005000.0, 0.0081], [123006000.0, 0.0081], [123007000.0, 0.0082]]},
{"timestamp": "1743933527079", "bids": [[122968000.0, 0.0], [122960000.0, 0.1376], [122956000.0, 0.0], [122953000.0, 0.0156], [122950000.0, 0.0061], [122949000.0, 0.0002], [122948000.0, 0.0152], [122947000.0, 0.0152], [122944000.0, 0.003], [122940000.0, 0.0]], "asks": [[122970000.0, 0.1378], [122980000.0, 0.0004], [122994000.0, 0.0023], [123000000.0, 0.1049], [123001000.0, 0.0001], [123003000.0, 0.0081], [123004000.0, 0.0001], [123005000.0, 0.0081], [123006000.0, 0.0081], [123007000.0, 0.0082]]},
{"timestamp": "1743933527585", "bids": [[122968000.0, 0.0], [122960000.0, 0.1377], [122956000.0, 0.0], [122953000.0, 0.0156], [122950000.0, 0.0061], [122949000.0, 0.0002], [122948000.0, 0.0152], [122947000.0, 0.0152], [122944000.0, 0.003], [122940000.0, 0.0]], "asks": [[122970000.0, 0.1378], [122980000.0, 0.0004], [122994000.0, 0.0023], [123000000.0, 0.1049], [123001000.0, 0.0001], [123003000.0, 0.0081], [123004000.0, 0.0001], [123005000.0, 0.0081], [123006000.0, 0.0081], [123007000.0, 0.0082]]},
{"timestamp": "1743933528104", "bids": [[122968000.0, 0.0], [122960000.0, 0.1377], [122956000.0, 0.0], [122953000.0, 0.0156], [122950000.0, 0.0061], [122949000.0, 0.0002], [122948000.0, 0.0152], [122947000.0, 0.0152], [122944000.0, 0.003], [122940000.0, 0.0]], "asks": [[122970000.0, 0.1378], [122980000.0, 0.0004], [122994000.0, 0.0023], [123000000.0, 0.1049], [123001000.0, 0.0001], [123003000.0, 0.0081], [123004000.0, 0.0001], [123005000.0, 0.0081], [123006000.0, 0.0081], [123007000.0, 0.0082]]},
{"timestamp": "1743933528614", "bids": [[122968000.0, 0.0], [122960000.0, 0.1377], [122956000.0, 0.0], [122953000.0, 0.0156], [122950000.0, 0.0061], [122949000.0, 0.0002], [122948000.0, 0.0152], [122947000.0, 0.0152], [122944000.0, 0.003], [122940000.0, 0.0]], "asks": [[122970000.0, 0.1378], [122980000.0, 0.0004], [122994000.0, 0.0023], [123000000.0, 0.1049], [123001000.0, 0.0001], [123003000.0, 0.0081], [123004000.0, 0.0001], [123005000.0, 0.0081], [123006000.0, 0.0081], [123007000.0, 0.0082]]},
{"timestamp": "1743933529143", "bids": [[122968000.0, 0.0], [122960000.0, 0.1377], [122956000.0, 0.0], [122953000.0, 0.0156], [122950000.0, 0.0061], [122949000.0, 0.0002], [122948000.0, 0.0152], [122947000.0, 0.0152], [122944000.0, 0.003], [122940000.0, 0.0]], "asks": [[122970000.0, 0.1378], [122980000.0, 0.0004], [122994000.0, 0.0023], [123000000.0, 0.1049], [123001000.0, 0.0001], [123003000.0, 0.0081], [123004000.0, 0.0001], [123005000.0, 0.0081], [123006000.0, 0.0081], [123007000.0, 0.0082]]},
{"timestamp": "1743933529659", "bids": [[122968000.0, 0.0], [122960000.0, 0.1377], [122956000.0, 0.0], [122953000.0, 0.0156], [122950000.0, 0.0061], [122949000.0, 0.0002], [122948000.0, 0.0152], [122947000.0, 0.0152], [122944000.0, 0.003], [122940000.0, 0.0]], "asks": [[122970000.0, 0.1378], [122980000.0, 0.0004], [122994000.0, 0.0023], [123000000.0, 0.1049], [123001000.0, 0.0001], [123003000.0, 0.0081], [123004000.0, 0.0001], [123005000.0, 0.0081], [123006000.0, 0.0081], [123007000.0, 0.0082]]},
{"timestamp": "1743933530164", "bids": [[122968000.0, 0.0], [122960000.0, 0.1377], [122956000.0, 0.0], [122953000.0, 0.0156], [122950000.0, 0.0061], [122949000.0, 0.0002], [122948000.0, 0.0152], [122947000.0, 0.0152], [122944000.0, 0.003], [122940000.0, 0.0]], "asks": [[122970000.0, 0.1378], [122980000.0, 0.0004], [122994000.0, 0.0023], [123000000.0, 0.1049], [123001000.0, 0.0001], [123003000.0, 0.0081], [123004000.0, 0.0001], [123005000.0, 0.0081], [123006000.0, 0.0081], [123007000.0, 0.0082]]},
{"timestamp": "1743933530685", "bids": [[122968000.0, 0.0], [122960000.0, 0.1377], [122956000.0, 0.0], [122953000.0, 0.0156], [122950000.0, 0.0061], [122949000.0, 0.0002], [122948000.0, 0.0152], [122947000.0, 0.0152], [122944000.0, 0.003], [122940000.0, 0.0]], "asks": [[122970000.0, 0.1378], [122980000.0, 0.0004], [122994000.0, 0.0023], [123000000.0, 0.1049], [123001000.0, 0.0001], [123003000.0, 0.0081], [123004000.0, 0.0001], [123005000.0, 0.0081], [123006000.0, 0.0081], [123007000.0, 0.0082]]},
{"timestamp": "1743933531148", "bids": [[122968000.0, 0.0], [122960000.0, 0.1377], [122956000.0, 0.0], [122953000.0, 0.0156], [122950000.0, 0.0061], [122949000.0, 0.0002], [122948000.0, 0.0152], [122947000.0, 0.0152], [122944000.0, 0.003], [122940000.0, 0.0]], "asks": [[122970000.0, 0.1378], [122980000.0, 0.0004], [122994000.0, 0.0023], [123000000.0, 0.1049], [123001000.0, 0.0001], [123003000.0, 0.0081], [123004000.0, 0.0001], [123005000.0, 0.0081], [123006000.0, 0.0081], [123007000.0, 0.0082]]},
{"timestamp": "1743933531663", "bids": [[122968000.0, 0.0], [122960000.0, 0.1377], [122956000.0, 0.0], [122953000.0, 0.0156], [122950000.0, 0.0061], [122949000.0, 0.0002], [122948000.0, 0.0152], [122947000.0, 0.0152], [122944000.0, 0.003], [122940000.0, 0.0]], "asks": [[122970000.0, 0.1378], [122980000.0, 0.0004], [122994000.0, 0.0023], [123000000.0, 0.1049], [123001000.0, 0.0001], [123003000.0, 0.0081], [123004000.0, 0.0001], [123005000.0, 0.0081], [123006000.0, 0.0081], [123007000.0, 0.0082]]},
{"timestamp": "1743933532181", "bids": [[122968000.0, 0.0], [122960000.0, 0.1377], [122956000.0, 0.0], [122953000.0, 0.0156], [122950000.0, 0.0061], [122949000.0, 0.0002], [122948000.0, 0.0152], [122947000.0, 0.0152], [122944000.0, 0.003], [122940000.0, 0.0]], "asks": [[122970000.0, 0.1378], [122980000.0, 0.0004], [122994000.0, 0.0023], [123000000.0, 0.1049], [123001000.0, 0.0001], [123003000.0, 0.0081], [123004000.0, 0.0001], [123005000.0, 0.0081], [123006000.0, 0.0081], [123007000.0, 0.0082]]},
{"timestamp": "1743933532710", "bids": [[122968000.0, 0.0], [122960000.0, 0.1377], [122956000.0, 0.0], [122953000.0, 0.0156], [122950000.0, 0.0061], [122949000.0, 0.0002], [122948000.0, 0.0152], [122947000.0, 0.0152], [122944000.0, 0.003], [122940000.0, 0.0]], "asks": [[122970000.0, 0.1378], [122980000.0, 0.0004], [122994000.0, 0.0023], [123000000.0, 0.1049], [123001000.0, 0.0001], [123003000.0, 0.0081], [123004000.0, 0.0001], [123005000.0, 0.0081], [123006000.0, 0.0081], [123007000.0, 0.0082]]},
{"timestamp": "1743933533205", "bids": [[122966000.0, 0.0002], [122960000.0, 0.1328], [122956000.0, 0.0001], [122953000.0, 0.0156], [122950000.0, 0.0061], [122949000.0, 0.0002], [122948000.0, 0.0152], [122947000.0, 0.0152], [122944000.0, 0.003], [122940000.0, 0.0]], "asks": [[122970000.0, 0.1378], [122980000.0, 0.0004], [122994000.0, 0.0023], [123000000.0, 0.1049], [123001000.0, 0.0001], [123003000.0, 0.0081], [123004000.0, 0.0001], [123005000.0, 0.0081], [123006000.0, 0.0081], [123007000.0, 0.0082]]},
{"timestamp": "1743933533734", "bids": [[122966000.0, 0.0002], [122960000.0, 0.1328], [122956000.0, 0.0001], [122953000.0, 0.0156], [122950000.0, 0.0061], [122949000.0, 0.0002], [122948000.0, 0.0152], [122947000.0, 0.0152], [122944000.0, 0.003], [122940000.0, 0.0]], "asks": [[122970000.0, 0.1378], [122980000.0, 0.0004], [122994000.0, 0.0023], [123000000.0, 0.1049], [123001000.0, 0.0001], [123003000.0, 0.0081], [123004000.0, 0.0001], [123005000.0, 0.0081], [123006000.0, 0.0081], [123007000.0, 0.0082]]},
{"timestamp": "1743933534227", "bids": [[122966000.0, 0.0002], [122960000.0, 0.1328], [122956000.0, 0.0001], [122953000.0, 0.0156], [122950000.0, 0.0061], [122949000.0, 0.0002], [122948000.0, 0.0152], [122947000.0, 0.0152], [122944000.0, 0.003], [122940000.0, 0.0]], "asks": [[122970000.0, 0.1378], [122980000.0, 0.0004], [122994000.0, 0.0023], [123000000.0, 0.1049], [123001000.0, 0.0001], [123003000.0, 0.0081], [123004000.0, 0.0001], [123005000.0, 0.0081], [123006000.0, 0.0081], [123007000.0, 0.0082]]},
{"timestamp": "1743933534811", "bids": [[122966000.0, 0.0002], [122960000.0, 0.1328], [122956000.0, 0.0001], [122953000.0, 0.0156], [122950000.0, 0.0061], [122949000.0, 0.0002], [122948000.0, 0.0152], [122947000.0, 0.0152], [122944000.0, 0.003], [122940000.0, 0.0]], "asks": [[122970000.0, 0.1378], [122980000.0, 0.0004], [122994000.0, 0.0023], [123000000.0, 0.1049], [123001000.0, 0.0001], [123003000.0, 0.0081], [123004000.0, 0.0001], [123005000.0, 0.0081], [123006000.0, 0.0081], [123007000.0, 0.0082]]},
{"timestamp": "1743933535317", "bids": [[122966000.0, 0.0002], [122960000.0, 0.1328], [122956000.0, 0.0001], [122953000.0, 0.0156], [122950000.0, 0.0061], [122949000.0, 0.0002], [122948000.0, 0.0152], [122947000.0, 0.0152], [122944000.0, 0.003], [122940000.0, 0.0]], "asks": [[122970000.0, 0.1378], [122980000.0, 0.0004], [122994000.0, 0.0023], [123000000.0, 0.1049], [123001000.0, 0.0001], [123003000.0, 0.0081], [123004000.0, 0.0001], [123005000.0, 0.0081], [123006000.0, 0.0081], [123007000.0, 0.0082]]},
{"timestamp": "1743933535792", "bids": [[122966000.0, 0.0002], [122960000.0, 0.1328], [122956000.0, 0.0001], [122953000.0, 0.0156], [122950000.0, 0.0061], [122949000.0, 0.0002], [122948000.0, 0.0152], [122947000.0, 0.0152], [122944000.0, 0.003], [122940000.0, 0.0]], "asks": [[122970000.0, 0.1378], [122980000.0, 0.0004], [122994000.0, 0.0023], [123000000.0, 0.1049], [123001000.0, 0.0001], [123003000.0, 0.0081], [123004000.0, 0.0001], [123005000.0, 0.0081], [123006000.0, 0.0081], [123007000.0, 0.0082]]},
{"timestamp": "1743933536341", "bids": [[122966000.0, 0.0002], [122960000.0, 0.1328], [122956000.0, 0.0001], [122953000.0, 0.0156], [122950000.0, 0.0061], [122949000.0, 0.0002], [122948000.0, 0.0152], [122947000.0, 0.0152], [122944000.0, 0.003], [122940000.0, 0.0]], "asks": [[122970000.0, 0.1378], [122980000.0, 0.0004], [122994000.0, 0.0023], [123000000.0, 0.1049], [123001000.0, 0.0001], [123003000.0, 0.0081], [123004000.0, 0.0001], [123005000.0, 0.0081], [123006000.0, 0.0081], [123007000.0, 0.0082]]},
{"timestamp": "1743933536787", "bids": [[122966000.0, 0.0002], [122960000.0, 0.1328], [122956000.0, 0.0001], [122953000.0, 0.0156], [122950000.0, 0.0061], [122949000.0, 0.0002], [122948000.0, 0.0152], [122947000.0, 0.0152], [122944000.0, 0.003], [122940000.0, 0.0]], "asks": [[122970000.0, 0.1378], [122980000.0, 0.0004], [122994000.0, 0.0023], [123000000.0, 0.1049], [123001000.0, 0.0001], [123003000.0, 0.0081], [123004000.0, 0.0001], [123005000.0, 0.0081], [123006000.0, 0.0081], [123007000.0, 0.0082]]},
{"timestamp": "1743933537659", "bids": [[122966000.0, 0.0002], [122960000.0, 0.1328], [122956000.0, 0.0001], [122953000.0, 0.0156], [122950000.0, 0.0061], [122949000.0, 0.0002], [122948000.0, 0.0152], [122947000.0, 0.0152], [122944000.0, 0.003], [122940000.0, 0.0]], "asks": [[122970000.0, 0.1378], [122980000.0, 0.0004], [122994000.0, 0.0023], [123000000.0, 0.1049], [123001000.0, 0.0001], [123003000.0, 0.0081], [123004000.0, 0.0001], [123005000.0, 0.0081], [123006000.0, 0.0081], [123007000.0, 0.0082]]},
{"timestamp": "1743933537898", "bids": [[122966000.0, 0.0002], [122960000.0, 0.1328], [122956000.0, 0.0001], [122953000.0, 0.0156], [122950000.0, 0.0061], [122949000.0, 0.0002], [122948000.0, 0.0152], [122947000.0, 0.0152], [122944000.0, 0.003], [122940000.0, 0.0]], "asks": [[122970000.0, 0.1378], [122980000.0, 0.0004], [122994000.0, 0.0023], [123000000.0, 0.1049], [123001000.0, 0.0001], [123003000.0, 0.0081], [123004000.0, 0.0001], [123005000.0, 0.0081], [123006000.0, 0.0081], [123007000.0, 0.0082]]},
{"timestamp": "1743933538339", "bids": [[122966000.0, 0.0002], [122960000.0, 0.1328], [122956000.0, 0.0001], [122953000.0, 0.0156], [122950000.0, 0.0061], [122949000.0, 0.0002], [122948000.0, 0.0152], [122947000.0, 0.0152], [122944000.0, 0.003], [122940000.0, 0.0]], "asks": [[122970000.0, 0.1378], [122980000.0, 0.0004], [122996000.0, 0.0023], [123000000.0, 0.1049], [123001000.0, 0.0001], [123003000.0, 0.0081], [123004000.0, 0.0001], [123005000.0, 0.0081], [123006000.0, 0.0081], [123007000.0, 0.0082]]},
{"timestamp": "1743933538917", "bids": [[122966000.0, 0.0002], [122960000.0, 0.1328], [122956000.0, 0.0001], [122953000.0, 0.0156], [122950000.0, 0.0061], [122949000.0, 0.0002], [122948000.0, 0.0152], [122947000.0, 0.0152], [122944000.0, 0.003], [122940000.0, 0.0]], "asks": [[122970000.0, 0.1378], [122980000.0, 0.0004], [122996000.0, 0.0023], [123000000.0, 0.1049], [123001000.0, 0.0001], [123003000.0, 0.0081], [123004000.0, 0.0001], [123005000.0, 0.0081], [123006000.0, 0.0081], [123007000.0, 0.0082]]},
{"timestamp": "1743933539332", "bids": [[122966000.0, 0.0002], [122960000.0, 0.1328], [122956000.0, 0.0001], [122953000.0, 0.0156], [122950000.0, 0.0061], [122949000.0, 0.0002], [122948000.0, 0.0152], [122947000.0, 0.0152], [122944000.0, 0.003], [122940000.0, 0.0]], "asks": [[122970000.0, 0.1378], [122980000.0, 0.0004], [122996000.0, 0.0023], [123000000.0, 0.1049], [123001000.0, 0.0001], [123003000.0, 0.0081], [123004000.0, 0.0001], [123005000.0, 0.0081], [123006000.0, 0.0081], [123007000.0, 0.0082]]},
{"timestamp": "1743933539868", "bids": [[122967000.0, 0.0618], [122966000.0, 0.0002], [122960000.0, 0.1328], [122956000.0, 0.0001], [122953000.0, 0.0269], [122950000.0, 0.0061], [122949000.0, 0.0002], [122947000.0, 0.0152], [122944000.0, 0.003], [122940000.0, 0.0]], "asks": [[122970000.0, 0.1378], [122980000.0, 0.0004], [122996000.0, 0.0023], [123000000.0, 0.1049], [123001000.0, 0.0001], [123003000.0, 0.0081], [123004000.0, 0.0001], [123005000.0, 0.0081], [123006000.0, 0.0081], [123007000.0, 0.0082]]},
