[
{"timestamp": "1743936599698", "bids": [[122683000.0, 0.0045], [122673000.0, 0.1109], [122672000.0, 0.0006], [122671000.0, 0.0283], [122667000.0, 0.0202], [122666000.0, 0.0034], [122665000.0, 0.015], [122664000.0, 0.025], [122661000.0, 0.0068], [122659000.0, 0.0202]], "asks": [[122687000.0, 0.0073], [122688000.0, 0.0009], [122690000.0, 0.0002], [122691000.0, 0.0], [122692000.0, 0.0008], [122694000.0, 0.0], [122695000.0, 0.0], [122696000.0, 0.0049], [122697000.0, 0.0047], [122698000.0, 0.0025]]},
{"timestamp": "1743936600130", "bids": [[122683000.0, 0.0045], [122673000.0, 0.1109], [122672000.0, 0.0006], [122671000.0, 0.0283], [122667000.0, 0.0202], [122666000.0, 0.0034], [122665000.0, 0.015], [122664000.0, 0.025], [122661000.0, 0.0068], [122659000.0, 0.0202]], "asks": [[122686000.0, 0.1362], [122687000.0, 0.0073], [122688000.0, 0.0009], [122690000.0, 0.0002], [122691000.0, 0.0], [122692000.0, 0.0008], [122694000.0, 0.0], [122695000.0, 0.0], [122696000.0, 0.0049], [122697000.0, 0.0047]]},
{"timestamp": "1743936600675", "bids": [[122683000.0, 0.0045], [122673000.0, 0.1109], [122672000.0, 0.0006], [122671000.0, 0.0283], [122667000.0, 0.0202], [122666000.0, 0.0034], [122665000.0, 0.015], [122661000.0, 0.0068], [122659000.0, 0.0202], [122644000.0, 0.0159]], "asks": [[122686000.0, 0.16], [122687000.0, 0.0073], [122688000.0, 0.0009], [122690000.0, 0.0002], [122691000.0, 0.0], [122692000.0, 0.0008], [122694000.0, 0.0], [122695000.0, 0.0], [122696000.0, 0.0049], [122697000.0, 0.0047]]},
{"timestamp": "1743936601137", "bids": [[122683000.0, 0.0045], [122673000.0, 0.1109], [122672000.0, 0.0006], [122671000.0, 0.0283], [122667000.0, 0.0202], [122661000.0, 0.0068], [122659000.0, 0.0202], [122655000.0, 0.0034], [122646000.0, 0.0003], [122645000.0, 0.0251]], "asks": [[122687000.0, 0.0073], [122688000.0, 0.0009], [122690000.0, 0.0002], [122691000.0, 0.0], [122692000.0, 0.0008], [122694000.0, 0.0], [122695000.0, 0.0], [122696000.0, 0.0049], [122697000.0, 0.0047], [122698000.0, 0.0025]]},
{"timestamp": "1743936601648", "bids": [[122683000.0, 0.0045], [122673000.0, 0.1109], [122672000.0, 0.0006], [122671000.0, 0.0283], [122667000.0, 0.0202], [122661000.0, 0.0068], [122659000.0, 0.0202], [122655000.0, 0.0034], [122654000.0, 0.015], [122646000.0, 0.0003]], "asks": [[122715000.0, 0.0082], [122716000.0, 0.0001], [122717000.0, 0.0017], [122720000.0, 0.0009], [122721000.0, 0.0954], [122722000.0, 0.0244], [122723000.0, 0.0064], [122724000.0, 0.0], [122725000.0, 0.0193], [122726000.0, 0.0003]]},
{"timestamp": "1743936602179", "bids": [[122683000.0, 0.0045], [122673000.0, 0.1109], [122672000.0, 0.0006], [122671000.0, 0.0283], [122667000.0, 0.0202], [122661000.0, 0.0068], [122659000.0, 0.0202], [122655000.0, 0.0034], [122654000.0, 0.015], [122646000.0, 0.0003]], "asks": [[122715000.0, 0.0082], [122716000.0, 0.0001], [122717000.0, 0.0017], [122720000.0, 0.203], [122721000.0, 0.0119], [122722000.0, 0.0267], [122723000.0, 0.0064], [122724000.0, 0.0], [122725000.0, 0.0193], [122726000.0, 0.0003]]},
{"timestamp": "1743936602693", "bids": [[122683000.0, 0.0045], [122673000.0, 0.1109], [122672000.0, 0.0006], [122671000.0, 0.0283], [122667000.0, 0.0202], [122661000.0, 0.0068], [122659000.0, 0.0202], [122655000.0, 0.0034], [122654000.0, 0.015], [122646000.0, 0.0003]], "asks": [[122715000.0, 0.0082], [122716000.0, 0.0001], [122717000.0, 0.0017], [122719000.0, 0.1288], [122720000.0, 0.0009], [122721000.0, 0.0119], [122722000.0, 0.0267], [122723000.0, 0.0064], [122724000.0, 0.0], [122725000.0, 0.0193]]},
{"timestamp": "1743936603424", "bids": [[122683000.0, 0.0045], [122673000.0, 0.1109], [122672000.0, 0.0006], [122671000.0, 0.0283], [122667000.0, 0.0202], [122661000.0, 0.0068], [122659000.0, 0.0202], [122655000.0, 0.0034], [122654000.0, 0.015], [122646000.0, 0.0003]], "asks": [[122715000.0, 0.0082], [122716000.0, 0.0001], [122717000.0, 0.0017], [122720000.0, 0.0009], [122721000.0, 0.0119], [122722000.0, 0.0267], [122723000.0, 0.0064], [122724000.0, 0.0], [122725000.0, 0.0193], [122726000.0, 0.0003]]},
{"timestamp": "1743936603689", "bids": [[122690000.0, 0.0], [122683000.0, 0.0045], [122673000.0, 0.1109], [122672000.0, 0.0006], [122671000.0, 0.0283], [122667000.0, 0.0202], [122661000.0, 0.0068], [122659000.0, 0.0202], [122655000.0, 0.0034], [122654000.0, 0.015]], "asks": [[122715000.0, 0.0082], [122716000.0, 0.0001], [122717000.0, 0.0017], [122720000.0, 0.0009], [122721000.0, 0.0119], [122722000.0, 0.0267], [122723000.0, 0.0064], [122724000.0, 0.1288], [122725000.0, 0.0193], [122726000.0, 0.0003]]},
{"timestamp": "1743936604217", "bids": [[122690000.0, 0.0], [122683000.0, 0.0045], [122673000.0, 0.1109], [122672000.0, 0.0006], [122671000.0, 0.0283], [122667000.0, 0.0202], [122661000.0, 0.0068], [122659000.0, 0.0202], [122655000.0, 0.0034], [122654000.0, 0.015]], "asks": [[122714000.0, 0.16], [122715000.0, 0.0082], [122716000.0, 0.0001], [122717000.0, 0.0017], [122720000.0, 0.0727], [122721000.0, 0.0119], [122722000.0, 0.0267], [122723000.0, 0.0064], [122724000.0, 0.0], [122725000.0, 0.0193]]},
{"timestamp": "1743936604704", "bids": [[122690000.0, 0.0], [122683000.0, 0.0045], [122673000.0, 0.1109], [122672000.0, 0.0006], [122671000.0, 0.0283], [122667000.0, 0.0202], [122661000.0, 0.0068], [122659000.0, 0.0202], [122655000.0, 0.0034], [122654000.0, 0.015]], "asks": [[122714000.0, 0.16], [122715000.0, 0.0082], [122716000.0, 0.0001], [122717000.0, 0.0017], [122720000.0, 0.0727], [122721000.0, 0.1407], [122722000.0, 0.0244], [122723000.0, 0.0064], [122724000.0, 0.0], [122725000.0, 0.0]]},
{"timestamp": "1743936605236", "bids": [[122690000.0, 0.0], [122683000.0, 0.0045], [122673000.0, 0.1109], [122672000.0, 0.0006], [122671000.0, 0.0283], [122667000.0, 0.0202], [122661000.0, 0.0068], [122659000.0, 0.0202], [122640000.0, 0.0203], [122639000.0, 0.0]], "asks": [[122713000.0, 0.1481], [122714000.0, 0.2318], [122715000.0, 0.0082], [122716000.0, 0.0001], [122717000.0, 0.0217], [122720000.0, 0.0008], [122721000.0, 0.0002], [122722000.0, 0.011], [122723000.0, 0.0064], [122724000.0, 0.0]]},
{"timestamp": "1743936605763", "bids": [[122690000.0, 0.0], [122683000.0, 0.0045], [122673000.0, 0.1109], [122672000.0, 0.0006], [122671000.0, 0.0283], [122667000.0, 0.0202], [122661000.0, 0.0068], [122659000.0, 0.0202], [122643000.0, 0.0001], [122640000.0, 0.0203]], "asks": [[122698000.0, 0.0193], [122701000.0, 0.0237], [122704000.0, 0.027], [122713000.0, 0.1485], [122714000.0, 0.0718], [122715000.0, 0.0082], [122716000.0, 0.0001], [122717000.0, 0.0217], [122720000.0, 0.0008], [122721000.0, 0.0002]]},
{"timestamp": "1743936606255", "bids": [[122673000.0, 0.1109], [122672000.0, 0.0006], [122671000.0, 0.0283], [122667000.0, 0.0202], [122661000.0, 0.0068], [122659000.0, 0.0202], [122643000.0, 0.0001], [122640000.0, 0.0203], [122639000.0, 0.0], [122637000.0, 0.0001]], "asks": [[122679000.0, 0.0001], [122682000.0, 0.011], [122689000.0, 0.0247], [122692000.0, 0.0369], [122698000.0, 0.036], [122700000.0, 0.0001], [122701000.0, 0.0237], [122704000.0, 0.027], [122713000.0, 0.2203], [122715000.0, 0.0082]]},
{"timestamp": "1743936606746", "bids": [[122673000.0, 0.1109], [122672000.0, 0.0006], [122671000.0, 0.0283], [122667000.0, 0.0202], [122661000.0, 0.0068], [122659000.0, 0.0202], [122643000.0, 0.0001], [122640000.0, 0.0203], [122639000.0, 0.0], [122637000.0, 0.0001]], "asks": [[122679000.0, 0.0001], [122681000.0, 0.0117], [122682000.0, 0.011], [122689000.0, 0.0524], [122692000.0, 0.0369], [122697000.0, 0.0718], [122698000.0, 0.036], [122700000.0, 0.0001], [122701000.0, 0.0237], [122704000.0, 0.027]]},
{"timestamp": "1743936607284", "bids": [[122673000.0, 0.1109], [122672000.0, 0.0006], [122671000.0, 0.0283], [122667000.0, 0.0202], [122661000.0, 0.0068], [122659000.0, 0.0202], [122643000.0, 0.0001], [122640000.0, 0.0203], [122639000.0, 0.0], [122637000.0, 0.0001]], "asks": [[122679000.0, 0.0001], [122681000.0, 0.0117], [122682000.0, 0.011], [122687000.0, 0.0718], [122688000.0, 0.1287], [122689000.0, 0.0524], [122691000.0, 0.0718], [122692000.0, 0.0369], [122698000.0, 0.036], [122700000.0, 0.0001]]},
{"timestamp": "1743936607779", "bids": [[122673000.0, 0.109], [122672000.0, 0.0006], [122671000.0, 0.0283], [122667000.0, 0.0202], [122661000.0, 0.0068], [122659000.0, 0.0202], [122643000.0, 0.0001], [122640000.0, 0.0203], [122639000.0, 0.0], [122637000.0, 0.0001]], "asks": [[122679000.0, 0.0001], [122681000.0, 0.0117], [122682000.0, 0.011], [122686000.0, 0.1287], [122687000.0, 0.0718], [122689000.0, 0.0524], [122692000.0, 0.0369], [122698000.0, 0.036], [122700000.0, 0.0001], [122701000.0, 0.0237]]},
{"timestamp": "1743936608282", "bids": [[122673000.0, 0.109], [122672000.0, 0.0006], [122671000.0, 0.0283], [122667000.0, 0.0202], [122661000.0, 0.0068], [122659000.0, 0.0202], [122643000.0, 0.0001], [122640000.0, 0.0203], [122639000.0, 0.0], [122637000.0, 0.0001]], "asks": [[122679000.0, 0.0001], [122681000.0, 0.0117], [122682000.0, 0.011], [122686000.0, 0.1287], [122689000.0, 0.0524], [122692000.0, 0.0369], [122698000.0, 0.036], [122700000.0, 0.0001], [122701000.0, 0.0237], [122704000.0, 0.027]]},
{"timestamp": "1743936608795", "bids": [[122673000.0, 0.109], [122672000.0, 0.0006], [122671000.0, 0.0283], [122667000.0, 0.0202], [122661000.0, 0.0068], [122659000.0, 0.0202], [122643000.0, 0.0001], [122640000.0, 0.0203], [122639000.0, 0.0], [122637000.0, 0.0001]], "asks": [[122679000.0, 0.0001], [122681000.0, 0.0117], [122682000.0, 0.011], [122688000.0, 0.1288], [122689000.0, 0.0524], [122692000.0, 0.0369], [122698000.0, 0.036], [122700000.0, 0.0001], [122701000.0, 0.0237], [122704000.0, 0.027]]},
{"timestamp": "1743936609311", "bids": [[122673000.0, 0.109], [122672000.0, 0.0006], [122671000.0, 0.0283], [122667000.0, 0.0202], [122661000.0, 0.0068], [122659000.0, 0.0202], [122643000.0, 0.0001], [122640000.0, 0.0203], [122639000.0, 0.0], [122637000.0, 0.0001]], "asks": [[122679000.0, 0.0001], [122681000.0, 0.0117], [122682000.0, 0.011], [122689000.0, 0.0524], [122692000.0, 0.0369], [122697000.0, 0.1288], [122698000.0, 0.036], [122700000.0, 0.0001], [122701000.0, 0.0237], [122704000.0, 0.027]]},
{"timestamp": "1743936609814", "bids": [[122673000.0, 0.109], [122672000.0, 0.0006], [122671000.0, 0.0283], [122667000.0, 0.0202], [122661000.0, 0.0068], [122659000.0, 0.0202], [122643000.0, 0.0001], [122640000.0, 0.0203], [122639000.0, 0.0], [122637000.0, 0.0001]], "asks": [[122679000.0, 0.0001], [122681000.0, 0.0117], [122682000.0, 0.011], [122689000.0, 0.0524], [122692000.0, 0.0369], [122696000.0, 0.0719], [122698000.0, 0.036], [122700000.0, 0.0001], [122701000.0, 0.0237], [122704000.0, 0.027]]},
{"timestamp": "1743936610364", "bids": [[122673000.0, 0.109], [122672000.0, 0.0006], [122671000.0, 0.0283], [122667000.0, 0.0202], [122661000.0, 0.0068], [122659000.0, 0.0202], [122643000.0, 0.0001], [122640000.0, 0.0203], [122639000.0, 0.0], [122637000.0, 0.0001]], "asks": [[122679000.0, 0.0001], [122681000.0, 0.0117], [122682000.0, 0.011], [122689000.0, 0.0524], [122692000.0, 0.0369], [122697000.0, 0.0719], [122698000.0, 0.036], [122700000.0, 0.0001], [122701000.0, 0.0237], [122704000.0, 0.027]]},
{"timestamp": "1743936610837", "bids": [[122673000.0, 0.109], [122672000.0, 0.0006], [122671000.0, 0.0283], [122667000.0, 0.0202], [122661000.0, 0.0068], [122659000.0, 0.0202], [122643000.0, 0.0001], [122640000.0, 0.0203], [122639000.0, 0.0], [122637000.0, 0.0001]], "asks": [[122679000.0, 0.0001], [122681000.0, 0.0117], [122682000.0, 0.011], [122689000.0, 0.0524], [122691000.0, 0.1288], [122692000.0, 0.0369], [122698000.0, 0.036], [122700000.0, 0.072], [122701000.0, 0.0237], [122704000.0, 0.027]]},
{"timestamp": "1743936611373", "bids": [[122673000.0, 0.109], [122672000.0, 0.0006], [122671000.0, 0.0283], [122667000.0, 0.0202], [122661000.0, 0.0068], [122659000.0, 0.0202], [122643000.0, 0.0001], [122640000.0, 0.0203], [122639000.0, 0.0], [122637000.0, 0.0001]], "asks": [[122679000.0, 0.0001], [122681000.0, 0.0117], [122682000.0, 0.011], [122689000.0, 0.0524], [122692000.0, 0.0369], [122698000.0, 0.036], [122700000.0, 0.1289], [122701000.0, 0.0237], [122704000.0, 0.027], [122708000.0, 0.0117]]},
{"timestamp": "1743936611861", "bids": [[122673000.0, 0.109], [122672000.0, 0.0006], [122671000.0, 0.0283], [122667000.0, 0.0202], [122661000.0, 0.0068], [122659000.0, 0.0202], [122643000.0, 0.0001], [122640000.0, 0.0203], [122639000.0, 0.0], [122637000.0, 0.0001]], "asks": [[122679000.0, 0.0001], [122681000.0, 0.0117], [122682000.0, 0.011], [122689000.0, 0.0524], [122692000.0, 0.0369], [122698000.0, 0.036], [122700000.0, 0.0001], [122701000.0, 0.0237], [122704000.0, 0.027], [122713000.0, 0.0023]]},
{"timestamp": "1743936612374", "bids": [[122673000.0, 0.109], [122672000.0, 0.0005], [122671000.0, 0.0283], [122667000.0, 0.0202], [122661000.0, 0.0068], [122659000.0, 0.0202], [122643000.0, 0.0001], [122640000.0, 0.0203], [122639000.0, 0.0], [122637000.0, 0.0001]], "asks": [[122679000.0, 0.0001], [122681000.0, 0.0117], [122682000.0, 0.011], [122689000.0, 0.0524], [122692000.0, 0.0369], [122698000.0, 0.036], [122700000.0, 0.1289], [122701000.0, 0.0237], [122704000.0, 0.027], [122713000.0, 0.0023]]},
{"timestamp": "1743936612881", "bids": [[122673000.0, 0.109], [122672000.0, 0.0005], [122671000.0, 0.0283], [122667000.0, 0.0202], [122661000.0, 0.0068], [122659000.0, 0.0202], [122643000.0, 0.0001], [122640000.0, 0.0203], [122639000.0, 0.0], [122637000.0, 0.0001]], "asks": [[122679000.0, 0.0001], [122681000.0, 0.0117], [122682000.0, 0.011], [122689000.0, 0.0524], [122692000.0, 0.0369], [122698000.0, 0.036], [122700000.0, 0.1289], [122701000.0, 0.0237], [122704000.0, 0.027], [122713000.0, 0.0023]]},
{"timestamp": "1743936613424", "bids": [[122673000.0, 0.109], [122672000.0, 0.0005], [122671000.0, 0.0283], [122667000.0, 0.0202], [122661000.0, 0.0068], [122659000.0, 0.0202], [122643000.0, 0.0001], [122640000.0, 0.0203], [122639000.0, 0.0], [122637000.0, 0.0001]], "asks": [[122679000.0, 0.0001], [122681000.0, 0.0117], [122682000.0, 0.011], [122689000.0, 0.0524], [122692000.0, 0.0369], [122698000.0, 0.036], [122700000.0, 0.0001], [122701000.0, 0.0237], [122704000.0, 0.027], [122715000.0, 0.0105]]},
{"timestamp": "1743936613905", "bids": [[122673000.0, 0.109], [122672000.0, 0.0005], [122671000.0, 0.0283], [122667000.0, 0.0202], [122661000.0, 0.0068], [122659000.0, 0.0202], [122643000.0, 0.0001], [122640000.0, 0.0203], [122639000.0, 0.0], [122637000.0, 0.0001]], "asks": [[122679000.0, 0.0001], [122681000.0, 0.0117], [122682000.0, 0.011], [122689000.0, 0.0524], [122692000.0, 0.0369], [122698000.0, 0.036], [122700000.0, 0.0001], [122701000.0, 0.0237], [122704000.0, 0.027], [122715000.0, 0.0105]]},
{"timestamp": "1743936614421", "bids": [[122673000.0, 0.109], [122672000.0, 0.0005], [122671000.0, 0.0283], [122667000.0, 0.0202], [122661000.0, 0.0068], [122659000.0, 0.0202], [122643000.0, 0.0001], [122640000.0, 0.0203], [122639000.0, 0.0], [122637000.0, 0.0001]], "asks": [[122679000.0, 0.0001], [122681000.0, 0.0117], [122682000.0, 0.011], [122689000.0, 0.0524], [122692000.0, 0.0369], [122698000.0, 0.036], [122700000.0, 0.0001], [122701000.0, 0.0237], [122704000.0, 0.027], [122715000.0, 0.0105]]},
{"timestamp": "1743936614931", "bids": [[122673000.0, 0.109], [122672000.0, 0.0005], [122671000.0, 0.0283], [122667000.0, 0.0202], [122661000.0, 0.0068], [122659000.0, 0.0202], [122643000.0, 0.0001], [122640000.0, 0.0203], [122639000.0, 0.0], [122637000.0, 0.0001]], "asks": [[122679000.0, 0.0001], [122681000.0, 0.0117], [122682000.0, 0.011], [122689000.0, 0.0524], [122692000.0, 0.0369], [122698000.0, 0.036], [122700000.0, 0.0001], [122701000.0, 0.0237], [122704000.0, 0.027], [122715000.0, 0.0105]]},
{"timestamp": "1743936615474", "bids": [[122673000.0, 0.109], [122672000.0, 0.0005], [122671000.0, 0.0283], [122667000.0, 0.0202], [122661000.0, 0.0068], [122659000.0, 0.0202], [122643000.0, 0.0001], [122640000.0, 0.0203], [122639000.0, 0.0], [122637000.0, 0.0001]], "asks": [[122679000.0, 0.0001], [122681000.0, 0.0117], [122682000.0, 0.011], [122689000.0, 0.0524], [122692000.0, 0.0369], [122697000.0, 0.1288], [122698000.0, 0.036], [122700000.0, 0.0001], [122701000.0, 0.0237], [122704000.0, 0.027]]},
{"timestamp": "1743936615982", "bids": [[122673000.0, 0.109], [122672000.0, 0.0005], [122671000.0, 0.0283], [122667000.0, 0.0202], [122661000.0, 0.0068], [122659000.0, 0.0202], [122643000.0, 0.0001], [122640000.0, 0.0203], [122639000.0, 0.0], [122637000.0, 0.0001]], "asks": [[122679000.0, 0.0001], [122681000.0, 0.0117], [122682000.0, 0.011], [122689000.0, 0.0524], [122692000.0, 0.0369], [122697000.0, 0.1288], [122698000.0, 0.036], [122700000.0, 0.0001], [122701000.0, 0.0237], [122704000.0, 0.027]]},
{"timestamp": "1743936616469", "bids": [[122673000.0, 0.109], [122672000.0, 0.0005], [122671000.0, 0.0283], [122667000.0, 0.0202], [122661000.0, 0.0068], [122659000.0, 0.0202], [122643000.0, 0.0001], [122640000.0, 0.0203], [122639000.0, 0.0], [122637000.0, 0.0001]], "asks": [[122679000.0, 0.0001], [122681000.0, 0.0117], [122682000.0, 0.011], [122689000.0, 0.0524], [122692000.0, 0.0369], [122698000.0, 0.036], [122700000.0, 0.0001], [122701000.0, 0.0237], [122704000.0, 0.027], [122715000.0, 0.0105]]},
{"timestamp": "1743936616982", "bids": [[122673000.0, 0.109], [122672000.0, 0.0005], [122671000.0, 0.0283], [122667000.0, 0.0202], [122661000.0, 0.0068], [122659000.0, 0.0202], [122643000.0, 0.0001], [122640000.0, 0.0203], [122639000.0, 0.0], [122637000.0, 0.0001]], "asks": [[122679000.0, 0.0001], [122681000.0, 0.0117], [122682000.0, 0.011], [122689000.0, 0.0524], [122692000.0, 0.0369], [122697000.0, 0.1288], [122698000.0, 0.036], [122700000.0, 0.0001], [122701000.0, 0.0237], [122704000.0, 0.027]]},
{"timestamp": "1743936617493", "bids": [[122673000.0, 0.109], [122672000.0, 0.0005], [122671000.0, 0.0283], [122667000.0, 0.0202], [122661000.0, 0.0068], [122659000.0, 0.0202], [122643000.0, 0.0001], [122640000.0, 0.0203], [122639000.0, 0.0], [122637000.0, 0.0001]], "asks": [[122679000.0, 0.0001], [122681000.0, 0.0117], [122682000.0, 0.011], [122689000.0, 0.0524], [122692000.0, 0.0369], [122697000.0, 0.1288], [122698000.0, 0.036], [122700000.0, 0.0001], [122701000.0, 0.0237], [122704000.0, 0.027]]},
{"timestamp": "1743936618037", "bids": [[122673000.0, 0.109], [122672000.0, 0.0005], [122671000.0, 0.0283], [122667000.0, 0.0202], [122661000.0, 0.0068], [122659000.0, 0.0202], [122643000.0, 0.0001], [122640000.0, 0.0203], [122639000.0, 0.0], [122637000.0, 0.0001]], "asks": [[122679000.0, 0.0001], [122681000.0, 0.0117], [122682000.0, 0.011], [122689000.0, 0.0524], [122692000.0, 0.0369], [122697000.0, 0.1288], [122698000.0, 0.036], [122700000.0, 0.0001], [122701000.0, 0.0237], [122704000.0, 0.027]]},
{"timestamp": "1743936618534", "bids": [[122673000.0, 0.109], [122672000.0, 0.0005], [122671000.0, 0.0283], [122670000.0, 0.0], [122667000.0, 0.0202], [122661000.0, 0.0068], [122659000.0, 0.0202], [122643000.0, 0.0001], [122640000.0, 0.0203], [122639000.0, 0.0]], "asks": [[122679000.0, 0.0001], [122681000.0, 0.0117], [122682000.0, 0.011], [122689000.0, 0.0524], [122692000.0, 0.0369], [122697000.0, 0.1288], [122698000.0, 0.036], [122700000.0, 0.0001], [122701000.0, 0.0237], [122704000.0, 0.027]]},
{"timestamp": "1743936619037", "bids": [[122673000.0, 0.109], [122672000.0, 0.0005], [122671000.0, 0.0283], [122670000.0, 0.0], [122667000.0, 0.0202], [122661000.0, 0.0068], [122659000.0, 0.0202], [122643000.0, 0.0001], [122640000.0, 0.0203], [122639000.0, 0.0]], "asks": [[122679000.0, 0.0001], [122681000.0, 0.0117], [122682000.0, 0.011], [122689000.0, 0.0524], [122692000.0, 0.0369], [122698000.0, 0.036], [122700000.0, 0.1289], [122701000.0, 0.0237], [122704000.0, 0.027], [122715000.0, 0.0105]]},
{"timestamp": "1743936619537", "bids": [[122673000.0, 0.109], [122672000.0, 0.0005], [122671000.0, 0.0283], [122670000.0, 0.0], [122667000.0, 0.0202], [122661000.0, 0.0068], [122659000.0, 0.0202], [122643000.0, 0.0001], [122640000.0, 0.0203], [122639000.0, 0.0]], "asks": [[122679000.0, 0.0001], [122681000.0, 0.0117], [122682000.0, 0.011], [122689000.0, 0.0524], [122692000.0, 0.0369], [122698000.0, 0.036], [122700000.0, 0.1289], [122701000.0, 0.0237], [122704000.0, 0.027], [122715000.0, 0.0105]]},
{"timestamp": "1743936620051", "bids": [[122673000.0, 0.109], [122672000.0, 0.0005], [122671000.0, 0.0283], [122670000.0, 0.0], [122667000.0, 0.0202], [122661000.0, 0.0068], [122659000.0, 0.0202], [122643000.0, 0.0001], [122640000.0, 0.0203], [122639000.0, 0.0]], "asks": [[122679000.0, 0.0001], [122681000.0, 0.0117], [122682000.0, 0.011], [122689000.0, 0.0524], [122692000.0, 0.0369], [122698000.0, 0.036], [122700000.0, 0.1289], [122701000.0, 0.0237], [122704000.0, 0.027], [122715000.0, 0.0105]]},
{"timestamp": "1743936620565", "bids": [[122673000.0, 0.109], [122672000.0, 0.0005], [122671000.0, 0.0283], [122670000.0, 0.0], [122667000.0, 0.0202], [122661000.0, 0.0068], [122659000.0, 0.0202], [122643000.0, 0.0001], [122640000.0, 0.0203], [122639000.0, 0.0]], "asks": [[122679000.0, 0.0001], [122681000.0, 0.0117], [122682000.0, 0.011], [122689000.0, 0.0524], [122692000.0, 0.0369], [122697000.0, 0.1288], [122698000.0, 0.036], [122700000.0, 0.0001], [122701000.0, 0.0237], [122704000.0, 0.027]]},
{"timestamp": "1743936621067", "bids": [[122673000.0, 0.109], [122672000.0, 0.0005], [122671000.0, 0.0283], [122670000.0, 0.0], [122667000.0, 0.0202], [122661000.0, 0.0068], [122659000.0, 0.0202], [122643000.0, 0.0001], [122640000.0, 0.0203], [122639000.0, 0.0]], "asks": [[122679000.0, 0.0001], [122681000.0, 0.0117], [122682000.0, 0.011], [122689000.0, 0.0524], [122692000.0, 0.0369], [122698000.0, 0.036], [122700000.0, 0.1289], [122701000.0, 0.0237], [122704000.0, 0.027], [122715000.0, 0.0082]]},
{"timestamp": "1743936621595", "bids": [[122673000.0, 0.109], [122672000.0, 0.0005], [122671000.0, 0.0283], [122670000.0, 0.0], [122667000.0, 0.0202], [122661000.0, 0.0068], [122659000.0, 0.0202], [122643000.0, 0.0001], [122640000.0, 0.0203], [122639000.0, 0.0]], "asks": [[122679000.0, 0.0001], [122681000.0, 0.0117], [122682000.0, 0.011], [122689000.0, 0.0524], [122692000.0, 0.0369], [122697000.0, 0.1288], [122698000.0, 0.036], [122700000.0, 0.0001], [122701000.0, 0.0237], [122704000.0, 0.027]]},
{"timestamp": "1743936622116", "bids": [[122673000.0, 0.1063], [122672000.0, 0.0005], [122671000.0, 0.0284], [122670000.0, 0.0], [122667000.0, 0.0202], [122661000.0, 0.0068], [122659000.0, 0.0202], [122643000.0, 0.0001], [122640000.0, 0.0203], [122639000.0, 0.0]], "asks": [[122679000.0, 0.0001], [122681000.0, 0.0117], [122682000.0, 0.011], [122689000.0, 0.0524], [122692000.0, 0.0369], [122697000.0, 0.1288], [122698000.0, 0.036], [122700000.0, 0.0001], [122701000.0, 0.0237], [122704000.0, 0.027]]},
{"timestamp": "1743936622610", "bids": [[122673000.0, 0.1063], [122672000.0, 0.0005], [122671000.0, 0.0284], [122670000.0, 0.0], [122667000.0, 0.0202], [122661000.0, 0.0068], [122659000.0, 0.0202], [122643000.0, 0.0001], [122640000.0, 0.0203], [122639000.0, 0.0]], "asks": [[122679000.0, 0.0001], [122681000.0, 0.0117], [122682000.0, 0.011], [122689000.0, 0.0524], [122692000.0, 0.0369], [122697000.0, 0.1288], [122698000.0, 0.036], [122700000.0, 0.0001], [122701000.0, 0.0237], [122704000.0, 0.027]]},
{"timestamp": "1743936623131", "bids": [[122673000.0, 0.1063], [122672000.0, 0.0005], [122671000.0, 0.0284], [122670000.0, 0.0], [122667000.0, 0.0202], [122661000.0, 0.0068], [122659000.0, 0.0202], [122643000.0, 0.0001], [122640000.0, 0.0203], [122639000.0, 0.0]], "asks": [[122679000.0, 0.0001], [122681000.0, 0.0117], [122682000.0, 0.011], [122689000.0, 0.0524], [122692000.0, 0.0369], [122698000.0, 0.036], [122700000.0, 0.1289], [122701000.0, 0.0237], [122704000.0, 0.027], [122715000.0, 0.0082]]},
{"timestamp": "1743936623623", "bids": [[122673000.0, 0.1063], [122672000.0, 0.0005], [122671000.0, 0.0284], [122670000.0, 0.0], [122667000.0, 0.0202], [122661000.0, 0.0068], [122659000.0, 0.0202], [122643000.0, 0.0001], [122640000.0, 0.0203], [122639000.0, 0.0]], "asks": [[122681000.0, 0.0113], [122682000.0, 0.011], [122689000.0, 0.0524], [122692000.0, 0.0369], [122697000.0, 0.1288], [122698000.0, 0.036], [122700000.0, 0.0001], [122701000.0, 0.0237], [122704000.0, 0.027], [122715000.0, 0.0082]]},
{"timestamp": "1743936624143", "bids": [[122673000.0, 0.1044], [122672000.0, 0.0005], [122671000.0, 0.0284], [122670000.0, 0.0], [122667000.0, 0.0202], [122661000.0, 0.0068], [122659000.0, 0.0202], [122643000.0, 0.0001], [122640000.0, 0.0203], [122639000.0, 0.0]], "asks": [[122680000.0, 0.1296], [122681000.0, 0.0095], [122682000.0, 0.011], [122689000.0, 0.0524], [122692000.0, 0.016], [122698000.0, 0.036], [122700000.0, 0.0001], [122704000.0, 0.027], [122715000.0, 0.0082], [122716000.0, 0.0001]]},
{"timestamp": "1743936624659", "bids": [[122673000.0, 0.1044], [122672000.0, 0.0005], [122671000.0, 0.0284], [122670000.0, 0.0], [122667000.0, 0.0202], [122661000.0, 0.0068], [122659000.0, 0.0202], [122643000.0, 0.0001], [122640000.0, 0.0203], [122639000.0, 0.0]], "asks": [[122680000.0, 0.1793], [122681000.0, 0.0095], [122696000.0, 0.0719], [122700000.0, 0.1288], [122703000.0, 0.0362], [122715000.0, 0.0082], [122716000.0, 0.0001], [122717000.0, 0.0017], [122720000.0, 0.0008], [122721000.0, 0.0002]]},
{"timestamp": "1743936625168", "bids": [[122673000.0, 0.1044], [122672000.0, 0.0005], [122671000.0, 0.0284], [122670000.0, 0.0], [122667000.0, 0.0202], [122661000.0, 0.0068], [122659000.0, 0.0202], [122640000.0, 0.0203], [122639000.0, 0.0], [122628000.0, 0.0]], "asks": [[122680000.0, 0.1793], [122696000.0, 0.0719], [122700000.0, 0.1288], [122703000.0, 0.0362], [122715000.0, 0.0082], [122716000.0, 0.0001], [122717000.0, 0.0017], [122720000.0, 0.0008], [122721000.0, 0.0002], [122722000.0, 0.0133]]},
{"timestamp": "1743936625687", "bids": [[122673000.0, 0.0304], [122672000.0, 0.0005], [122671000.0, 0.0284], [122670000.0, 0.0], [122667000.0, 0.0202], [122661000.0, 0.0068], [122659000.0, 0.0202], [122640000.0, 0.0203], [122639000.0, 0.0], [122628000.0, 0.0]], "asks": [[122675000.0, 0.0237], [122695000.0, 0.1287], [122699000.0, 0.0718], [122715000.0, 0.0082], [122716000.0, 0.0001], [122717000.0, 0.0017], [122720000.0, 0.0008], [122721000.0, 0.0002], [122722000.0, 0.0133], [122723000.0, 0.004]]},
{"timestamp": "1743936626170", "bids": [[122673000.0, 0.0304], [122672000.0, 0.0005], [122671000.0, 0.0284], [122670000.0, 0.0], [122667000.0, 0.0202], [122661000.0, 0.0068], [122659000.0, 0.0202], [122640000.0, 0.0203], [122639000.0, 0.0], [122628000.0, 0.0]], "asks": [[122675000.0, 0.0237], [122698000.0, 0.1288], [122715000.0, 0.0082], [122716000.0, 0.0001], [122717000.0, 0.0017], [122719000.0, 0.0304], [122720000.0, 0.0008], [122721000.0, 0.0002], [122722000.0, 0.0133], [122723000.0, 0.004]]},
{"timestamp": "1743936626687", "bids": [[122673000.0, 0.0304], [122672000.0, 0.0005], [122671000.0, 0.0284], [122670000.0, 0.0], [122667000.0, 0.0202], [122661000.0, 0.0068], [122659000.0, 0.0202], [122640000.0, 0.0203], [122639000.0, 0.0], [122628000.0, 0.0]], "asks": [[122675000.0, 0.0237], [122696000.0, 0.1285], [122714000.0, 0.0717], [122715000.0, 0.0082], [122716000.0, 0.0001], [122717000.0, 0.0017], [122719000.0, 0.0304], [122720000.0, 0.0008], [122721000.0, 0.0002], [122722000.0, 0.0133]]},
{"timestamp": "1743936627241", "bids": [[122673000.0, 0.0304], [122672000.0, 0.0005], [122671000.0, 0.0284], [122670000.0, 0.0], [122667000.0, 0.0202], [122661000.0, 0.0068], [122659000.0, 0.0202], [122641000.0, 0.1519], [122640000.0, 0.0203], [122639000.0, 0.0]], "asks": [[122675000.0, 0.0237], [122715000.0, 0.0082], [122716000.0, 0.0001], [122717000.0, 0.0017], [122718000.0, 0.1285], [122720000.0, 0.0008], [122721000.0, 0.0025], [122722000.0, 0.011], [122723000.0, 0.004], [122724000.0, 0.0]]},
{"timestamp": "1743936627778", "bids": [[122673000.0, 0.0304], [122672000.0, 0.0005], [122671000.0, 0.0284], [122670000.0, 0.0], [122667000.0, 0.0202], [122661000.0, 0.0068], [122659000.0, 0.0202], [122640000.0, 0.0203], [122639000.0, 0.0], [122628000.0, 0.0]], "asks": [[122675000.0, 0.0237], [122713000.0, 0.1285], [122714000.0, 0.0717], [122715000.0, 0.0082], [122716000.0, 0.0001], [122717000.0, 0.0017], [122720000.0, 0.0312], [122721000.0, 0.0025], [122722000.0, 0.011], [122723000.0, 0.004]]},
{"timestamp": "1743936628222", "bids": [[122673000.0, 0.0304], [122672000.0, 0.0005], [122671000.0, 0.0284], [122670000.0, 0.0], [122667000.0, 0.0202], [122661000.0, 0.0068], [122659000.0, 0.0202], [122640000.0, 0.0203], [122639000.0, 0.0], [122636000.0, 0.003]], "asks": [[122675000.0, 0.0237], [122713000.0, 0.1285], [122715000.0, 0.0082], [122716000.0, 0.0001], [122717000.0, 0.0017], [122720000.0, 0.0312], [122721000.0, 0.0025], [122722000.0, 0.011], [122723000.0, 0.004], [122724000.0, 0.0]]},
{"timestamp": "1743936628736", "bids": [[122673000.0, 0.0304], [122672000.0, 0.0005], [122671000.0, 0.0284], [122670000.0, 0.0], [122667000.0, 0.0202], [122661000.0, 0.0068], [122659000.0, 0.0202], [122640000.0, 0.0203], [122639000.0, 0.0], [122636000.0, 0.003]], "asks": [[122675000.0, 0.0237], [122710000.0, 0.0716], [122715000.0, 0.0082], [122716000.0, 0.0001], [122717000.0, 0.0017], [122719000.0, 0.1284], [122720000.0, 0.0312], [122721000.0, 0.0025], [122722000.0, 0.011], [122723000.0, 0.004]]},
{"timestamp": "1743936629298", "bids": [[122673000.0, 0.0304], [122672000.0, 0.0005], [122671000.0, 0.012], [122670000.0, 0.0], [122667000.0, 0.0202], [122661000.0, 0.0068], [122659000.0, 0.0202], [122640000.0, 0.0203], [122639000.0, 0.0], [122636000.0, 0.003]], "asks": [[122675000.0, 0.0237], [122711000.0, 0.1284], [122714000.0, 0.0716], [122715000.0, 0.0082], [122716000.0, 0.0001], [122717000.0, 0.0017], [122720000.0, 0.0312], [122721000.0, 0.0025], [122722000.0, 0.011], [122723000.0, 0.004]]},
{"timestamp": "1743936629827", "bids": [[122673000.0, 0.0304], [122672000.0, 0.0005], [122671000.0, 0.012], [122670000.0, 0.0], [122667000.0, 0.0202], [122661000.0, 0.0068], [122659000.0, 0.0202], [122640000.0, 0.0204], [122639000.0, 0.0], [122636000.0, 0.003]], "asks": [[122675000.0, 0.0237], [122713000.0, 0.1284], [122714000.0, 0.0716], [122715000.0, 0.0082], [122716000.0, 0.0001], [122717000.0, 0.0017], [122720000.0, 0.0312], [122721000.0, 0.0025], [122722000.0, 0.011], [122723000.0, 0.004]]},
{"timestamp": "1743936630269", "bids": [[122673000.0, 0.0304], [122672000.0, 0.0005], [122671000.0, 0.012], [122670000.0, 0.0], [122667000.0, 0.0202], [122661000.0, 0.0068], [122659000.0, 0.0202], [122640000.0, 0.0204], [122639000.0, 0.0], [122636000.0, 0.003]], "asks": [[122675000.0, 0.0237], [122707000.0, 0.1284], [122712000.0, 0.0716], [122715000.0, 0.0082], [122716000.0, 0.0001], [122717000.0, 0.0017], [122720000.0, 0.0312], [122721000.0, 0.0025], [122722000.0, 0.011], [122723000.0, 0.004]]},
{"timestamp": "1743936630831", "bids": [[122673000.0, 0.0304], [122672000.0, 0.0005], [122671000.0, 0.012], [122670000.0, 0.0], [122667000.0, 0.0202], [122661000.0, 0.0068], [122659000.0, 0.0202], [122640000.0, 0.0204], [122639000.0, 0.0], [122636000.0, 0.003]], "asks": [[122675000.0, 0.0237], [122706000.0, 0.0716], [122711000.0, 0.1284], [122715000.0, 0.0082], [122716000.0, 0.0001], [122717000.0, 0.0017], [122720000.0, 0.0312], [122721000.0, 0.0025], [122722000.0, 0.011], [122723000.0, 0.004]]},
{"timestamp": "1743936631305", "bids": [[122673000.0, 0.0304], [122672000.0, 0.0005], [122671000.0, 0.012], [122670000.0, 0.0], [122667000.0, 0.0202], [122661000.0, 0.0068], [122659000.0, 0.0202], [122640000.0, 0.0204], [122639000.0, 0.0], [122636000.0, 0.003]], "asks": [[122675000.0, 0.0212], [122705000.0, 0.1284], [122710000.0, 0.0716], [122715000.0, 0.0082], [122716000.0, 0.0001], [122717000.0, 0.0017], [122719000.0, 0.0023], [122720000.0, 0.0312], [122721000.0, 0.0002], [122722000.0, 0.011]]},
{"timestamp": "1743936631796", "bids": [[122673000.0, 0.0099], [122672000.0, 0.0005], [122671000.0, 0.012], [122670000.0, 0.0], [122667000.0, 0.0202], [122661000.0, 0.0068], [122659000.0, 0.0202], [122640000.0, 0.0204], [122639000.0, 0.0], [122636000.0, 0.003]], "asks": [[122675000.0, 0.0212], [122709000.0, 0.1284], [122710000.0, 0.0716], [122715000.0, 0.0082], [122716000.0, 0.0001], [122717000.0, 0.0017], [122719000.0, 0.0023], [122720000.0, 0.0008], [122721000.0, 0.0002], [122722000.0, 0.011]]},
{"timestamp": "1743936632322", "bids": [[122673000.0, 0.0054], [122672000.0, 0.0005], [122671000.0, 0.012], [122670000.0, 0.0], [122667000.0, 0.0202], [122661000.0, 0.0068], [122659000.0, 0.0202], [122640000.0, 0.0204], [122639000.0, 0.0], [122636000.0, 0.003]], "asks": [[122675000.0, 0.0212], [122708000.0, 0.0716], [122711000.0, 0.1285], [122715000.0, 0.0202], [122716000.0, 0.0001], [122717000.0, 0.0017], [122719000.0, 0.0023], [122720000.0, 0.0008], [122721000.0, 0.0002], [122722000.0, 0.011]]},
{"timestamp": "1743936632833", "bids": [[122673000.0, 0.0054], [122672000.0, 0.0005], [122671000.0, 0.012], [122670000.0, 0.0], [122667000.0, 0.0202], [122661000.0, 0.0068], [122659000.0, 0.0202], [122640000.0, 0.0204], [122639000.0, 0.0], [122636000.0, 0.003]], "asks": [[122675000.0, 0.0212], [122710000.0, 0.0699], [122714000.0, 0.1285], [122715000.0, 0.0202], [122716000.0, 0.0001], [122717000.0, 0.0017], [122719000.0, 0.0023], [122720000.0, 0.0008], [122721000.0, 0.0002], [122722000.0, 0.011]]},
{"timestamp": "1743936633345", "bids": [[122673000.0, 0.0052], [122672000.0, 0.0005], [122671000.0, 0.012], [122670000.0, 0.0], [122667000.0, 0.0202], [122661000.0, 0.0068], [122659000.0, 0.0202], [122640000.0, 0.0204], [122639000.0, 0.0], [122636000.0, 0.003]], "asks": [[122675000.0, 0.0212], [122709000.0, 0.1285], [122713000.0, 0.0699], [122715000.0, 0.0202], [122716000.0, 0.0001], [122717000.0, 0.0017], [122719000.0, 0.0023], [122720000.0, 0.0008], [122721000.0, 0.0002], [122722000.0, 0.011]]},
{"timestamp": "1743936633834", "bids": [[122673000.0, 0.003], [122672000.0, 0.0005], [122671000.0, 0.012], [122670000.0, 0.0], [122667000.0, 0.0202], [122661000.0, 0.0068], [122659000.0, 0.0202], [122640000.0, 0.0204], [122639000.0, 0.0], [122636000.0, 0.003]], "asks": [[122675000.0, 0.0212], [122711000.0, 0.0699], [122712000.0, 0.1285], [122715000.0, 0.0202], [122716000.0, 0.0001], [122717000.0, 0.0017], [122719000.0, 0.0023], [122720000.0, 0.0008], [122721000.0, 0.0002], [122722000.0, 0.011]]},
{"timestamp": "1743936634348", "bids": [[122673000.0, 0.003], [122672000.0, 0.0005], [122671000.0, 0.012], [122670000.0, 0.0], [122667000.0, 0.0202], [122661000.0, 0.0068], [122659000.0, 0.0202], [122640000.0, 0.0204], [122639000.0, 0.0], [122636000.0, 0.003]], "asks": [[122675000.0, 0.0212], [122710000.0, 0.1285], [122711000.0, 0.0699], [122715000.0, 0.0202], [122716000.0, 0.0001], [122717000.0, 0.0017], [122718000.0, 0.0023], [122720000.0, 0.0008], [122721000.0, 0.0002], [122722000.0, 0.011]]},
{"timestamp": "1743936634860", "bids": [[122673000.0, 0.0027], [122672000.0, 0.0005], [122671000.0, 0.012], [122670000.0, 0.0], [122667000.0, 0.0202], [122661000.0, 0.0068], [122659000.0, 0.0202], [122640000.0, 0.0204], [122639000.0, 0.0], [122636000.0, 0.003]], "asks": [[122675000.0, 0.0212], [122709000.0, 0.0699], [122710000.0, 0.1285], [122715000.0, 0.0202], [122716000.0, 0.0001], [122717000.0, 0.0017], [122718000.0, 0.0023], [122720000.0, 0.0008], [122721000.0, 0.0002], [122722000.0, 0.011]]},
{"timestamp": "1743936635416", "bids": [[122673000.0, 0.0027], [122672000.0, 0.0005], [122671000.0, 0.012], [122670000.0, 0.0], [122667000.0, 0.0202], [122661000.0, 0.0068], [122659000.0, 0.0202], [122640000.0, 0.0204], [122639000.0, 0.0], [122636000.0, 0.003]], "asks": [[122675000.0, 0.0212], [122708000.0, 0.1285], [122709000.0, 0.0699], [122715000.0, 0.0202], [122716000.0, 0.0001], [122717000.0, 0.0017], [122718000.0, 0.0023], [122720000.0, 0.0008], [122721000.0, 0.0002], [122722000.0, 0.011]]},
{"timestamp": "1743936635913", "bids": [[122673000.0, 0.0027], [122672000.0, 0.0005], [122671000.0, 0.012], [122670000.0, 0.0], [122667000.0, 0.0202], [122661000.0, 0.0068], [122659000.0, 0.0202], [122640000.0, 0.0204], [122639000.0, 0.0], [122636000.0, 0.003]], "asks": [[122675000.0, 0.0212], [122708000.0, 0.1285], [122715000.0, 0.0202], [122716000.0, 0.0001], [122717000.0, 0.0017], [122718000.0, 0.0023], [122720000.0, 0.0008], [122721000.0, 0.0002], [122722000.0, 0.011], [122723000.0, 0.004]]},
{"timestamp": "1743936636408", "bids": [[122673000.0, 0.0027], [122672000.0, 0.0005], [122671000.0, 0.012], [122670000.0, 0.0], [122667000.0, 0.0202], [122661000.0, 0.0068], [122659000.0, 0.0202], [122640000.0, 0.0204], [122639000.0, 0.0], [122636000.0, 0.003]], "asks": [[122675000.0, 0.0212], [122707000.0, 0.0699], [122714000.0, 0.1285], [122715000.0, 0.0202], [122716000.0, 0.0001], [122717000.0, 0.0017], [122718000.0, 0.0023], [122720000.0, 0.0008], [122721000.0, 0.0002], [122722000.0, 0.011]]},
{"timestamp": "1743936636955", "bids": [[122673000.0, 0.0043], [122672000.0, 0.0005], [122671000.0, 0.012], [122670000.0, 0.0], [122667000.0, 0.0202], [122661000.0, 0.0068], [122659000.0, 0.0202], [122640000.0, 0.0204], [122639000.0, 0.0], [122636000.0, 0.003]], "asks": [[122675000.0, 0.0212], [122701000.0, 0.1285], [122705000.0, 0.0699], [122715000.0, 0.0202], [122716000.0, 0.0001], [122717000.0, 0.0017], [122718000.0, 0.0023], [122720000.0, 0.0008], [122721000.0, 0.0002], [122722000.0, 0.011]]},
{"timestamp": "1743936637477", "bids": [[122673000.0, 0.0043], [122672000.0, 0.0005], [122671000.0, 0.012], [122670000.0, 0.0], [122667000.0, 0.0202], [122661000.0, 0.0068], [122659000.0, 0.0202], [122640000.0, 0.0204], [122639000.0, 0.0], [122636000.0, 0.003]], "asks": [[122675000.0, 0.0212], [122700000.0, 0.0699], [122715000.0, 0.0202], [122716000.0, 0.0001], [122717000.0, 0.0017], [122718000.0, 0.0023], [122720000.0, 0.0008], [122721000.0, 0.0002], [122722000.0, 0.011], [122723000.0, 0.004]]},
{"timestamp": "1743936637930", "bids": [[122673000.0, 0.0043], [122672000.0, 0.0005], [122671000.0, 0.012], [122670000.0, 0.0], [122667000.0, 0.0202], [122661000.0, 0.0068], [122659000.0, 0.0202], [122640000.0, 0.0204], [122639000.0, 0.0], [122636000.0, 0.003]], "asks": [[122675000.0, 0.0212], [122699000.0, 0.1285], [122711000.0, 0.0699], [122715000.0, 0.0202], [122716000.0, 0.0001], [122717000.0, 0.0017], [122718000.0, 0.0023], [122720000.0, 0.0008], [122721000.0, 0.0002], [122722000.0, 0.011]]},
{"timestamp": "1743936638442", "bids": [[122673000.0, 0.0043], [122672000.0, 0.0005], [122671000.0, 0.012], [122670000.0, 0.0], [122667000.0, 0.0202], [122661000.0, 0.0068], [122659000.0, 0.0202], [122640000.0, 0.0204], [122639000.0, 0.0], [122636000.0, 0.003]], "asks": [[122675000.0, 0.0212], [122698000.0, 0.0699], [122702000.0, 0.1285], [122715000.0, 0.0202], [122716000.0, 0.0001], [122717000.0, 0.0017], [122718000.0, 0.0023], [122720000.0, 0.0008], [122721000.0, 0.0002], [122722000.0, 0.011]]},
{"timestamp": "1743936638995", "bids": [[122673000.0, 0.0043], [122672000.0, 0.0005], [122671000.0, 0.012], [122670000.0, 0.0], [122667000.0, 0.0202], [122661000.0, 0.0068], [122659000.0, 0.0202], [122640000.0, 0.0204], [122639000.0, 0.0], [122636000.0, 0.003]], "asks": [[122675000.0, 0.0212], [122701000.0, 0.0699], [122708000.0, 0.1285], [122715000.0, 0.0202], [122716000.0, 0.0001], [122717000.0, 0.0017], [122718000.0, 0.0023], [122720000.0, 0.0008], [122721000.0, 0.0002], [122722000.0, 0.011]]},
{"timestamp": "1743936639459", "bids": [[122673000.0, 0.0043], [122672000.0, 0.0005], [122671000.0, 0.012], [122670000.0, 0.0], [122667000.0, 0.0202], [122661000.0, 0.0068], [122659000.0, 0.0202], [122640000.0, 0.0204], [122639000.0, 0.0], [122636000.0, 0.003]], "asks": [[122675000.0, 0.0212], [122700000.0, 0.1285], [122707000.0, 0.0699], [122715000.0, 0.0202], [122716000.0, 0.0001], [122717000.0, 0.0017], [122718000.0, 0.0023], [122720000.0, 0.0008], [122721000.0, 0.0002], [122722000.0, 0.011]]},
{"timestamp": "1743936639993", "bids": [[122673000.0, 0.0043], [122672000.0, 0.0005], [122671000.0, 0.012], [122670000.0, 0.0], [122667000.0, 0.0202], [122661000.0, 0.0068], [122659000.0, 0.0202], [122640000.0, 0.0204], [122639000.0, 0.0], [122636000.0, 0.003]], "asks": [[122675000.0, 0.0212], [122695000.0, 0.1285], [122699000.0, 0.0699], [122715000.0, 0.0202], [122716000.0, 0.0001], [122717000.0, 0.0017], [122718000.0, 0.0023], [122720000.0, 0.0008], [122721000.0, 0.0002], [122722000.0, 0.011]]},
{"timestamp": "1743936640504", "bids": [[122673000.0, 0.0043], [122672000.0, 0.0005], [122671000.0, 0.012], [122670000.0, 0.0], [122667000.0, 0.0202], [122661000.0, 0.0068], [122659000.0, 0.0202], [122640000.0, 0.0204], [122639000.0, 0.0], [122636000.0, 0.003]], "asks": [[122675000.0, 0.0212], [122705000.0, 0.0699], [122715000.0, 0.0202], [122716000.0, 0.0001], [122717000.0, 0.0017], [122718000.0, 0.0023], [122720000.0, 0.0008], [122721000.0, 0.0002], [122722000.0, 0.011], [122723000.0, 0.004]]},
{"timestamp": "1743936641011", "bids": [[122673000.0, 0.0043], [122672000.0, 0.0005], [122671000.0, 0.012], [122670000.0, 0.0], [122667000.0, 0.0202], [122661000.0, 0.0068], [122659000.0, 0.0202], [122640000.0, 0.0204], [122639000.0, 0.0], [122636000.0, 0.003]], "asks": [[122675000.0, 0.0212], [122704000.0, 0.1285], [122714000.0, 0.0699], [122715000.0, 0.0202], [122716000.0, 0.0001], [122717000.0, 0.004], [122718000.0, 0.0023], [122720000.0, 0.0008], [122721000.0, 0.0002], [122722000.0, 0.011]]},
{"timestamp": "1743936641525", "bids": [[122673000.0, 0.0039], [122672000.0, 0.0005], [122671000.0, 0.012], [122670000.0, 0.0], [122667000.0, 0.0202], [122661000.0, 0.0068], [122659000.0, 0.0202], [122640000.0, 0.0204], [122639000.0, 0.0], [122636000.0, 0.003]], "asks": [[122675000.0, 0.0212], [122703000.0, 0.0699], [122704000.0, 0.1285], [122715000.0, 0.0202], [122716000.0, 0.0001], [122717000.0, 0.004], [122720000.0, 0.0008], [122721000.0, 0.0002], [122722000.0, 0.011], [122723000.0, 0.004]]},
{"timestamp": "1743936642041", "bids": [[122673000.0, 0.0039], [122672000.0, 0.0005], [122671000.0, 0.012], [122670000.0, 0.0], [122667000.0, 0.0202], [122661000.0, 0.0068], [122659000.0, 0.0202], [122640000.0, 0.0204], [122639000.0, 0.0], [122636000.0, 0.003]], "asks": [[122675000.0, 0.0212], [122702000.0, 0.1285], [122712000.0, 0.0699], [122715000.0, 0.0202], [122716000.0, 0.0001], [122717000.0, 0.004], [122720000.0, 0.0008], [122721000.0, 0.0002], [122722000.0, 0.011], [122723000.0, 0.004]]},
{"timestamp": "1743936642540", "bids": [[122673000.0, 0.0039], [122672000.0, 0.0005], [122671000.0, 0.012], [122670000.0, 0.0], [122667000.0, 0.0202], [122661000.0, 0.0068], [122659000.0, 0.0202], [122640000.0, 0.0204], [122639000.0, 0.0], [122636000.0, 0.003]], "asks": [[122675000.0, 0.0212], [122701000.0, 0.0699], [122711000.0, 0.1285], [122715000.0, 0.0202], [122716000.0, 0.0001], [122717000.0, 0.004], [122720000.0, 0.0008], [122721000.0, 0.0002], [122722000.0, 0.011], [122723000.0, 0.004]]},
{"timestamp": "1743936643025", "bids": [[122673000.0, 0.0039], [122672000.0, 0.0005], [122671000.0, 0.012], [122670000.0, 0.0], [122667000.0, 0.0202], [122661000.0, 0.0068], [122659000.0, 0.0202], [122640000.0, 0.0204], [122639000.0, 0.0], [122636000.0, 0.003]], "asks": [[122675000.0, 0.0212], [122700000.0, 0.1285], [122710000.0, 0.0699], [122715000.0, 0.0202], [122716000.0, 0.0001], [122717000.0, 0.004], [122720000.0, 0.0008], [122721000.0, 0.0002], [122722000.0, 0.011], [122723000.0, 0.004]]},
{"timestamp": "1743936643561", "bids": [[122673000.0, 0.0039], [122672000.0, 0.0005], [122671000.0, 0.012], [122670000.0, 0.0], [122667000.0, 0.0202], [122661000.0, 0.0068], [122659000.0, 0.0202], [122640000.0, 0.0204], [122639000.0, 0.0], [122636000.0, 0.003]], "asks": [[122675000.0, 0.0212], [122698000.0, 0.1285], [122708000.0, 0.0699], [122715000.0, 0.0202], [122716000.0, 0.0001], [122717000.0, 0.004], [122720000.0, 0.0008], [122721000.0, 0.0002], [122722000.0, 0.011], [122723000.0, 0.004]]},
{"timestamp": "1743936644057", "bids": [[122673000.0, 0.0039], [122672000.0, 0.0005], [122671000.0, 0.012], [122670000.0, 0.0], [122667000.0, 0.0202], [122661000.0, 0.0068], [122659000.0, 0.0202], [122640000.0, 0.0204], [122639000.0, 0.0], [122636000.0, 0.003]], "asks": [[122675000.0, 0.0212], [122697000.0, 0.0699], [122707000.0, 0.1285], [122715000.0, 0.0202], [122716000.0, 0.0001], [122717000.0, 0.004], [122720000.0, 0.0008], [122721000.0, 0.0002], [122722000.0, 0.011], [122723000.0, 0.004]]},
{"timestamp": "1743936644587", "bids": [[122673000.0, 0.0039], [122672000.0, 0.0005], [122671000.0, 0.012], [122670000.0, 0.0], [122667000.0, 0.0202], [122661000.0, 0.0068], [122659000.0, 0.0202], [122640000.0, 0.0204], [122639000.0, 0.0], [122636000.0, 0.003]], "asks": [[122675000.0, 0.0196], [122696000.0, 0.1285], [122706000.0, 0.0699], [122715000.0, 0.0202], [122716000.0, 0.0001], [122717000.0, 0.004], [122720000.0, 0.0008], [122721000.0, 0.0002], [122722000.0, 0.011], [122723000.0, 0.004]]},
{"timestamp": "1743936645081", "bids": [[122673000.0, 0.0039], [122672000.0, 0.0005], [122671000.0, 0.012], [122670000.0, 0.0], [122667000.0, 0.0202], [122661000.0, 0.0068], [122659000.0, 0.0202], [122640000.0, 0.0204], [122639000.0, 0.0], [122636000.0, 0.003]], "asks": [[122675000.0, 0.0196], [122705000.0, 0.1285], [122714000.0, 0.0699], [122715000.0, 0.0202], [122716000.0, 0.0001], [122717000.0, 0.004], [122720000.0, 0.0008], [122721000.0, 0.0002], [122722000.0, 0.011], [122723000.0, 0.004]]},
{"timestamp": "1743936645585", "bids": [[122673000.0, 0.0039], [122672000.0, 0.0005], [122671000.0, 0.012], [122670000.0, 0.0], [122667000.0, 0.0202], [122661000.0, 0.0068], [122659000.0, 0.0202], [122640000.0, 0.0204], [122639000.0, 0.0], [122636000.0, 0.003]], "asks": [[122675000.0, 0.0196], [122703000.0, 0.1285], [122712000.0, 0.0699], [122715000.0, 0.0202], [122716000.0, 0.0001], [122717000.0, 0.004], [122720000.0, 0.0008], [122721000.0, 0.0002], [122722000.0, 0.011], [122723000.0, 0.004]]},
{"timestamp": "1743936646095", "bids": [[122673000.0, 0.0039], [122672000.0, 0.0005], [122671000.0, 0.012], [122670000.0, 0.0], [122667000.0, 0.0202], [122661000.0, 0.0068], [122659000.0, 0.0202], [122640000.0, 0.0204], [122639000.0, 0.0], [122636000.0, 0.003]], "asks": [[122675000.0, 0.0196], [122702000.0, 0.0699], [122711000.0, 0.1285], [122715000.0, 0.0202], [122716000.0, 0.0001], [122717000.0, 0.004], [122720000.0, 0.0008], [122721000.0, 0.0002], [122722000.0, 0.011], [122723000.0, 0.004]]},
{"timestamp": "1743936646630", "bids": [[122673000.0, 0.0039], [122672000.0, 0.0005], [122671000.0, 0.012], [122670000.0, 0.0], [122667000.0, 0.0202], [122661000.0, 0.0068], [122659000.0, 0.0202], [122640000.0, 0.0204], [122639000.0, 0.0], [122636000.0, 0.003]], "asks": [[122675000.0, 0.0196], [122701000.0, 0.1285], [122710000.0, 0.0699], [122715000.0, 0.0202], [122716000.0, 0.0001], [122717000.0, 0.004], [122720000.0, 0.0008], [122721000.0, 0.0002], [122722000.0, 0.011], [122723000.0, 0.004]]},
{"timestamp": "1743936647136", "bids": [[122673000.0, 0.0039], [122672000.0, 0.0005], [122671000.0, 0.012], [122670000.0, 0.0], [122667000.0, 0.0202], [122661000.0, 0.0068], [122659000.0, 0.0202], [122640000.0, 0.0204], [122639000.0, 0.0], [122636000.0, 0.003]], "asks": [[122675000.0, 0.0196], [122699000.0, 0.1285], [122708000.0, 0.0699], [122715000.0, 0.0202], [122716000.0, 0.0001], [122717000.0, 0.004], [122720000.0, 0.0008], [122721000.0, 0.0002], [122722000.0, 0.011], [122723000.0, 0.004]]},
{"timestamp": "1743936647633", "bids": [[122673000.0, 0.0039], [122672000.0, 0.0005], [122671000.0, 0.012], [122670000.0, 0.0], [122667000.0, 0.0202], [122661000.0, 0.0068], [122659000.0, 0.0202], [122640000.0, 0.0204], [122639000.0, 0.0], [122636000.0, 0.003]], "asks": [[122675000.0, 0.0196], [122698000.0, 0.0699], [122707000.0, 0.1285], [122715000.0, 0.0202], [122716000.0, 0.0001], [122717000.0, 0.004], [122720000.0, 0.0008], [122721000.0, 0.0002], [122722000.0, 0.011], [122723000.0, 0.004]]},
{"timestamp": "1743936648174", "bids": [[122673000.0, 0.0038], [122672000.0, 0.0005], [122671000.0, 0.012], [122670000.0, 0.0], [122667000.0, 0.0202], [122661000.0, 0.0068], [122659000.0, 0.0202], [122640000.0, 0.0204], [122639000.0, 0.0], [122636000.0, 0.003]], "asks": [[122675000.0, 0.0196], [122697000.0, 0.1285], [122706000.0, 0.0699], [122715000.0, 0.0202], [122716000.0, 0.0001], [122717000.0, 0.004], [122720000.0, 0.0008], [122721000.0, 0.0002], [122722000.0, 0.011], [122723000.0, 0.004]]},
{"timestamp": "1743936648659", "bids": [[122673000.0, 0.0038], [122672000.0, 0.0005], [122671000.0, 0.012], [122670000.0, 0.0], [122667000.0, 0.0202], [122661000.0, 0.0068], [122659000.0, 0.0202], [122640000.0, 0.0204], [122639000.0, 0.0], [122636000.0, 0.003]], "asks": [[122675000.0, 0.0196], [122696000.0, 0.0699], [122712000.0, 0.1285], [122715000.0, 0.0202], [122716000.0, 0.0001], [122717000.0, 0.004], [122720000.0, 0.0008], [122721000.0, 0.0002], [122722000.0, 0.011], [122723000.0, 0.004]]},
{"timestamp": "1743936649193", "bids": [[122673000.0, 0.0038], [122672000.0, 0.0005], [122671000.0, 0.012], [122670000.0, 0.0], [122667000.0, 0.0202], [122661000.0, 0.0068], [122659000.0, 0.0202], [122640000.0, 0.0204], [122639000.0, 0.0], [122636000.0, 0.003]], "asks": [[122675000.0, 0.0196], [122695000.0, 0.1285], [122704000.0, 0.0699], [122715000.0, 0.0082], [122716000.0, 0.0001], [122717000.0, 0.004], [122720000.0, 0.0008], [122721000.0, 0.0002], [122722000.0, 0.011], [122723000.0, 0.004]]},
{"timestamp": "1743936649713", "bids": [[122673000.0, 0.0038], [122672000.0, 0.0005], [122671000.0, 0.012], [122670000.0, 0.0], [122667000.0, 0.0202], [122661000.0, 0.0068], [122659000.0, 0.0202], [122641000.0, 0.152], [122640000.0, 0.0204], [122639000.0, 0.0]], "asks": [[122675000.0, 0.0196], [122703000.0, 0.1285], [122711000.0, 0.0699], [122715000.0, 0.0082], [122716000.0, 0.0001], [122717000.0, 0.004], [122719000.0, 0.012], [122720000.0, 0.0008], [122721000.0, 0.0002], [122722000.0, 0.011]]},
{"timestamp": "1743936650190", "bids": [[122659000.0, 0.0202], [122641000.0, 0.152], [122640000.0, 0.0204], [122639000.0, 0.0], [122636000.0, 0.003], [122628000.0, 0.0], [122615000.0, 0.0], [122614000.0, 0.0016], [122612000.0, 0.0], [122611000.0, 0.0024]], "asks": [[122661000.0, 0.0155], [122667000.0, 0.0167], [122671000.0, 0.0247], [122673000.0, 0.0244], [122675000.0, 0.0196], [122703000.0, 0.1285], [122711000.0, 0.0699], [122715000.0, 0.0082], [122716000.0, 0.0001], [122717000.0, 0.004]]},
{"timestamp": "1743936650756", "bids": [[122659000.0, 0.0202], [122641000.0, 0.152], [122640000.0, 0.0204], [122639000.0, 0.0], [122636000.0, 0.003], [122628000.0, 0.0], [122615000.0, 0.0], [122614000.0, 0.0016], [122612000.0, 0.0], [122611000.0, 0.0024]], "asks": [[122661000.0, 0.0155], [122667000.0, 0.0167], [122669000.0, 0.0001], [122671000.0, 0.0247], [122673000.0, 0.0244], [122711000.0, 0.0699], [122714000.0, 0.0699], [122715000.0, 0.0082], [122716000.0, 0.0001], [122717000.0, 0.004]]},
{"timestamp": "1743936651234", "bids": [[122659000.0, 0.0202], [122640000.0, 0.0204], [122639000.0, 0.0], [122636000.0, 0.003], [122628000.0, 0.0], [122615000.0, 0.0], [122614000.0, 0.0016], [122612000.0, 0.0], [122611000.0, 0.018], [122609000.0, 0.0962]], "asks": [[122661000.0, 0.0155], [122667000.0, 0.0167], [122669000.0, 0.0001], [122671000.0, 0.0247], [122673000.0, 0.026], [122710000.0, 0.1285], [122714000.0, 0.0699], [122715000.0, 0.0082], [122716000.0, 0.0001], [122717000.0, 0.004]]},
{"timestamp": "1743936651748", "bids": [[122659000.0, 0.0202], [122640000.0, 0.0204], [122639000.0, 0.0], [122636000.0, 0.003], [122628000.0, 0.0], [122615000.0, 0.0], [122614000.0, 0.0016], [122612000.0, 0.2454], [122611000.0, 0.018], [122610000.0, 0.151]], "asks": [[122661000.0, 0.0155], [122667000.0, 0.0167], [122669000.0, 0.0001], [122671000.0, 0.0247], [122673000.0, 0.026], [122693000.0, 0.0197], [122713000.0, 0.1276], [122715000.0, 0.0082], [122716000.0, 0.0001], [122717000.0, 0.004]]},
{"timestamp": "1743936652238", "bids": [[122659000.0, 0.0202], [122640000.0, 0.0204], [122639000.0, 0.0], [122636000.0, 0.003], [122628000.0, 0.0], [122615000.0, 0.0], [122614000.0, 0.0016], [122613000.0, 0.0944], [122612000.0, 0.151], [122611000.0, 0.018]], "asks": [[122661000.0, 0.0155], [122667000.0, 0.0167], [122669000.0, 0.0001], [122671000.0, 0.0247], [122673000.0, 0.026], [122692000.0, 0.0694], [122693000.0, 0.0197], [122713000.0, 0.1276], [122715000.0, 0.0082], [122716000.0, 0.0001]]},
{"timestamp": "1743936652750", "bids": [[122659000.0, 0.0202], [122640000.0, 0.0204], [122639000.0, 0.0], [122636000.0, 0.003], [122628000.0, 0.0], [122615000.0, 0.0], [122614000.0, 0.1526], [122613000.0, 0.0944], [122612000.0, 0.0], [122611000.0, 0.018]], "asks": [[122661000.0, 0.0155], [122667000.0, 0.0167], [122669000.0, 0.0001], [122671000.0, 0.0247], [122673000.0, 0.026], [122691000.0, 0.1276], [122692000.0, 0.0694], [122693000.0, 0.0197], [122702000.0, 0.0023], [122715000.0, 0.0082]]},
{"timestamp": "1743936653262", "bids": [[122659000.0, 0.0202], [122640000.0, 0.0204], [122639000.0, 0.0], [122636000.0, 0.003], [122628000.0, 0.0], [122615000.0, 0.0944], [122614000.0, 0.1526], [122612000.0, 0.0], [122611000.0, 0.018], [122609000.0, 0.0012]], "asks": [[122661000.0, 0.0155], [122667000.0, 0.0167], [122669000.0, 0.0001], [122671000.0, 0.0247], [122673000.0, 0.026], [122691000.0, 0.1276], [122693000.0, 0.0197], [122702000.0, 0.0023], [122715000.0, 0.0082], [122716000.0, 0.0001]]},
{"timestamp": "1743936653797", "bids": [[122659000.0, 0.0202], [122640000.0, 0.0204], [122639000.0, 0.0], [122636000.0, 0.003], [122628000.0, 0.0], [122616000.0, 0.151], [122615000.0, 0.0944], [122614000.0, 0.0016], [122612000.0, 0.0], [122611000.0, 0.018]], "asks": [[122661000.0, 0.0155], [122667000.0, 0.0167], [122669000.0, 0.0001], [122671000.0, 0.0247], [122673000.0, 0.026], [122692000.0, 0.1276], [122693000.0, 0.0197], [122702000.0, 0.0023], [122715000.0, 0.0082], [122716000.0, 0.0001]]},
{"timestamp": "1743936654285", "bids": [[122659000.0, 0.0202], [122640000.0, 0.0204], [122639000.0, 0.0], [122636000.0, 0.003], [122628000.0, 0.0], [122617000.0, 0.0944], [122616000.0, 0.151], [122615000.0, 0.0], [122614000.0, 0.0016], [122612000.0, 0.0]], "asks": [[122661000.0, 0.0155], [122667000.0, 0.0167], [122669000.0, 0.0001], [122671000.0, 0.0247], [122673000.0, 0.026], [122692000.0, 0.1276], [122693000.0, 0.0197], [122702000.0, 0.0024], [122715000.0, 0.0082], [122716000.0, 0.0001]]},
{"timestamp": "1743936654821", "bids": [[122659000.0, 0.0202], [122640000.0, 0.0204], [122639000.0, 0.0], [122636000.0, 0.003], [122628000.0, 0.0], [122619000.0, 0.0944], [122618000.0, 0.151], [122615000.0, 0.0], [122614000.0, 0.0016], [122612000.0, 0.0]], "asks": [[122661000.0, 0.0155], [122667000.0, 0.0167], [122669000.0, 0.0001], [122671000.0, 0.0247], [122673000.0, 0.026], [122692000.0, 0.1276], [122693000.0, 0.0197], [122702000.0, 0.0024], [122715000.0, 0.0082], [122716000.0, 0.0001]]},
{"timestamp": "1743936655328", "bids": [[122659000.0, 0.0202], [122640000.0, 0.0204], [122639000.0, 0.0], [122636000.0, 0.003], [122628000.0, 0.0], [122620000.0, 0.151], [122619000.0, 0.0944], [122615000.0, 0.0], [122614000.0, 0.0016], [122612000.0, 0.0]], "asks": [[122661000.0, 0.0155], [122667000.0, 0.0167], [122669000.0, 0.0001], [122671000.0, 0.0247], [122673000.0, 0.026], [122692000.0, 0.1276], [122693000.0, 0.0197], [122702000.0, 0.0024], [122715000.0, 0.0082], [122716000.0, 0.0001]]},
{"timestamp": "1743936655855", "bids": [[122659000.0, 0.0202], [122640000.0, 0.0204], [122639000.0, 0.0], [122636000.0, 0.003], [122628000.0, 0.0], [122621000.0, 0.0944], [122620000.0, 0.151], [122615000.0, 0.0], [122614000.0, 0.0016], [122612000.0, 0.0]], "asks": [[122661000.0, 0.0155], [122667000.0, 0.0167], [122669000.0, 0.0001], [122671000.0, 0.0247], [122673000.0, 0.026], [122692000.0, 0.1276], [122693000.0, 0.0197], [122701000.0, 0.0023], [122702000.0, 0.0], [122715000.0, 0.0082]]},
{"timestamp": "1743936656334", "bids": [[122659000.0, 0.0202], [122640000.0, 0.0204], [122639000.0, 0.0], [122636000.0, 0.003], [122628000.0, 0.0], [122622000.0, 0.151], [122621000.0, 0.0944], [122615000.0, 0.0], [122614000.0, 0.0016], [122612000.0, 0.0]], "asks": [[122661000.0, 0.0155], [122667000.0, 0.0167], [122669000.0, 0.0001], [122671000.0, 0.0247], [122673000.0, 0.026], [122692000.0, 0.1276], [122693000.0, 0.0197], [122701000.0, 0.0023], [122702000.0, 0.0], [122715000.0, 0.0082]]},
{"timestamp": "1743936656858", "bids": [[122659000.0, 0.0202], [122640000.0, 0.0204], [122639000.0, 0.0], [122636000.0, 0.003], [122628000.0, 0.0], [122624000.0, 0.151], [122623000.0, 0.0944], [122615000.0, 0.0], [122614000.0, 0.0016], [122612000.0, 0.0]], "asks": [[122661000.0, 0.0155], [122667000.0, 0.0167], [122669000.0, 0.0001], [122671000.0, 0.0247], [122673000.0, 0.026], [122692000.0, 0.1276], [122693000.0, 0.0197], [122701000.0, 0.0023], [122702000.0, 0.0], [122715000.0, 0.0082]]},
{"timestamp": "1743936657396", "bids": [[122659000.0, 0.0202], [122640000.0, 0.0204], [122639000.0, 0.0], [122636000.0, 0.003], [122628000.0, 0.0], [122624000.0, 0.151], [122615000.0, 0.0], [122614000.0, 0.0016], [122612000.0, 0.0], [122611000.0, 0.018]], "asks": [[122661000.0, 0.0155], [122667000.0, 0.0167], [122669000.0, 0.0001], [122671000.0, 0.0247], [122673000.0, 0.026], [122691000.0, 0.0694], [122692000.0, 0.1276], [122693000.0, 0.0197], [122701000.0, 0.0023], [122702000.0, 0.0]]},
{"timestamp": "1743936657885", "bids": [[122659000.0, 0.0202], [122640000.0, 0.0204], [122639000.0, 0.0], [122636000.0, 0.003], [122628000.0, 0.0], [122615000.0, 0.0], [122614000.0, 0.0016], [122612000.0, 0.151], [122611000.0, 0.018], [122609000.0, 0.0012]], "asks": [[122661000.0, 0.0155], [122667000.0, 0.0167], [122669000.0, 0.0001], [122671000.0, 0.0247], [122673000.0, 0.026], [122690000.0, 0.1276], [122691000.0, 0.0694], [122693000.0, 0.0197], [122701000.0, 0.0023], [122702000.0, 0.0]]},
{"timestamp": "1743936658425", "bids": [[122659000.0, 0.0202], [122640000.0, 0.0204], [122639000.0, 0.0], [122636000.0, 0.003], [122628000.0, 0.0], [122615000.0, 0.0], [122614000.0, 0.1526], [122613000.0, 0.0944], [122612000.0, 0.0], [122611000.0, 0.018]], "asks": [[122661000.0, 0.0155], [122667000.0, 0.0167], [122669000.0, 0.0001], [122671000.0, 0.0247], [122673000.0, 0.026], [122688000.0, 0.1276], [122689000.0, 0.0694], [122693000.0, 0.0197], [122701000.0, 0.0023], [122702000.0, 0.0]]},
{"timestamp": "1743936658926", "bids": [[122659000.0, 0.0202], [122640000.0, 0.0204], [122639000.0, 0.0], [122636000.0, 0.003], [122628000.0, 0.0], [122615000.0, 0.0944], [122614000.0, 0.1526], [122612000.0, 0.0], [122611000.0, 0.018], [122609000.0, 0.0012]], "asks": [[122661000.0, 0.0155], [122667000.0, 0.0167], [122669000.0, 0.0001], [122671000.0, 0.0247], [122673000.0, 0.026], [122688000.0, 0.1276], [122693000.0, 0.0197], [122701000.0, 0.0023], [122702000.0, 0.0], [122715000.0, 0.0082]]},
{"timestamp": "1743936659435", "bids": [[122659000.0, 0.0202], [122640000.0, 0.0204], [122639000.0, 0.0], [122636000.0, 0.003], [122628000.0, 0.0], [122616000.0, 0.151], [122615000.0, 0.0944], [122614000.0, 0.0016], [122612000.0, 0.0], [122611000.0, 0.018]], "asks": [[122661000.0, 0.0155], [122667000.0, 0.0167], [122669000.0, 0.0001], [122671000.0, 0.0247], [122673000.0, 0.026], [122692000.0, 0.1276], [122693000.0, 0.0197], [122701000.0, 0.0023], [122702000.0, 0.0], [122715000.0, 0.0082]]}
]