{"timestamp": "1743771415640", "bids": [[122461000.0, 0.0111], [122460000.0, 0.0026], [122456000.0, 0.0059], [122454000.0, 0.0226], [122453000.0, 0.0094], [122444000.0, 0.0825], [122443000.0, 0.0323], [122442000.0, 0.0556], [122436000.0, 0.0114], [122431000.0, 0.025]], "asks": [[122485000.0, 0.0001], [122486000.0, 0.0002], [122488000.0, 0.0008], [122489000.0, 0.0], [122491000.0, 0.0003], [122492000.0, 0.0008], [122494000.0, 0.0008], [122495000.0, 0.0001], [122497000.0, 0.0096], [122499000.0, 0.0037]]},
{"timestamp": "1743771416136", "bids": [[122461000.0, 0.0111], [122460000.0, 0.0026], [122456000.0, 0.0059], [122454000.0, 0.0226], [122453000.0, 0.0094], [122444000.0, 0.0825], [122443000.0, 0.0323], [122442000.0, 0.0556], [122436000.0, 0.0114], [122431000.0, 0.025]], "asks": [[122485000.0, 0.0001], [122486000.0, 0.0002], [122488000.0, 0.0008], [122489000.0, 0.0], [122491000.0, 0.0003], [122492000.0, 0.0008], [122494000.0, 0.0008], [122495000.0, 0.0001], [122497000.0, 0.0096], [122499000.0, 0.0037]]},
{"timestamp": "1743771416639", "bids": [[122461000.0, 0.0111], [122456000.0, 0.0059], [122454000.0, 0.105], [122453000.0, 0.0094], [122443000.0, 0.0323], [122442000.0, 0.0556], [122436000.0, 0.0114], [122431000.0, 0.0002], [122426000.0, 0.0574], [122425000.0, 0.003]], "asks": [[122485000.0, 0.0001], [122486000.0, 0.0002], [122488000.0, 0.0008], [122489000.0, 0.0], [122491000.0, 0.0003], [122492000.0, 0.0008], [122494000.0, 0.0008], [122495000.0, 0.0001], [122497000.0, 0.0096], [122499000.0, 0.0037]]},
{"timestamp": "1743771417133", "bids": [[122462000.0, 0.1559], [122461000.0, 0.0111], [122457000.0, 0.0825], [122456000.0, 0.0059], [122454000.0, 0.0225], [122453000.0, 0.0094], [122442000.0, 0.0112], [122435000.0, 0.1065], [122433000.0, 0.0362], [122426000.0, 0.0002]], "asks": [[122485000.0, 0.0001], [122486000.0, 0.0002], [122488000.0, 0.0008], [122489000.0, 0.0], [122491000.0, 0.0003], [122492000.0, 0.0008], [122494000.0, 0.0008], [122495000.0, 0.0001], [122497000.0, 0.0096], [122499000.0, 0.0037]]},
{"timestamp": "1743771417636", "bids": [[122472000.0, 0.0026], [122466000.0, 0.0226], [122462000.0, 0.1507], [122461000.0, 0.0111], [122458000.0, 0.0116], [122457000.0, 0.0825], [122456000.0, 0.0059], [122454000.0, 0.0225], [122453000.0, 0.0246], [122447000.0, 0.0522]], "asks": [[122485000.0, 0.0001], [122486000.0, 0.0002], [122488000.0, 0.0008], [122489000.0, 0.0], [122491000.0, 0.0003], [122492000.0, 0.0008], [122494000.0, 0.0008], [122495000.0, 0.0001], [122497000.0, 0.0096], [122499000.0, 0.0037]]},
{"timestamp": "1743771418137", "bids": [[122472000.0, 0.0223], [122466000.0, 0.0226], [122463000.0, 0.1044], [122462000.0, 0.0086], [122461000.0, 0.0434], [122458000.0, 0.0116], [122456000.0, 0.0059], [122455000.0, 0.0002], [122454000.0, 0.0225], [122453000.0, 0.0828]], "asks": [[122485000.0, 0.0001], [122486000.0, 0.0002], [122488000.0, 0.0008], [122489000.0, 0.0], [122491000.0, 0.0003], [122492000.0, 0.0008], [122494000.0, 0.0008], [122495000.0, 0.0001], [122497000.0, 0.0096], [122499000.0, 0.0037]]},
{"timestamp": "1743771418637", "bids": [[122491000.0, 0.0077], [122453000.0, 0.0714], [122451000.0, 0.057], [122447000.0, 0.0258], [122441000.0, 0.0001], [122437000.0, 0.0002], [122429000.0, 0.0253], [122425000.0, 0.003], [122421000.0, 0.0415], [122420000.0, 0.0]], "asks": [[122492000.0, 0.0008], [122494000.0, 0.0008], [122495000.0, 0.0001], [122497000.0, 0.0096], [122499000.0, 0.0037], [122500000.0, 0.0238], [122502000.0, 0.0], [122504000.0, 0.0002], [122505000.0, 0.0081], [122506000.0, 0.0013]]},
{"timestamp": "1743771419138", "bids": [[122491000.0, 0.0077], [122486000.0, 0.0026], [122480000.0, 0.0112], [122467000.0, 0.0001], [122459000.0, 0.0825], [122453000.0, 0.0714], [122451000.0, 0.0572], [122447000.0, 0.0258], [122441000.0, 0.0001], [122429000.0, 0.0253]], "asks": [[122492000.0, 0.0008], [122494000.0, 0.0008], [122495000.0, 0.0001], [122497000.0, 0.0096], [122499000.0, 0.0037], [122500000.0, 0.0238], [122502000.0, 0.0], [122504000.0, 0.0002], [122505000.0, 0.0081], [122506000.0, 0.0013]]},
{"timestamp": "1743771419637", "bids": [[122491000.0, 0.0073], [122486000.0, 0.0026], [122480000.0, 0.0112], [122457000.0, 0.0248], [122453000.0, 0.0437], [122451000.0, 0.0574], [122447000.0, 0.0258], [122429000.0, 0.0253], [122425000.0, 0.003], [122422000.0, 0.0163]], "asks": [[122492000.0, 0.0008], [122494000.0, 0.0008], [122495000.0, 0.0001], [122497000.0, 0.0096], [122499000.0, 0.0037], [122500000.0, 0.0238], [122502000.0, 0.0], [122504000.0, 0.0002], [122505000.0, 0.0081], [122506000.0, 0.0013]]},
{"timestamp": "1743771420132", "bids": [[122478000.0, 0.0227], [122461000.0, 0.0007], [122453000.0, 0.041], [122451000.0, 0.0571], [122447000.0, 0.1064], [122429000.0, 0.0001], [122425000.0, 0.003], [122422000.0, 0.0163], [122421000.0, 0.0415], [122420000.0, 0.0]], "asks": [[122492000.0, 0.0008], [122494000.0, 0.0008], [122495000.0, 0.0001], [122497000.0, 0.0096], [122499000.0, 0.0037], [122500000.0, 0.0238], [122502000.0, 0.0], [122504000.0, 0.0002], [122505000.0, 0.0081], [122506000.0, 0.0013]]},
{"timestamp": "1743771420637", "bids": [[122485000.0, 0.0001], [122478000.0, 0.0339], [122461000.0, 0.0007], [122460000.0, 0.0325], [122459000.0, 0.0264], [122456000.0, 0.0001], [122453000.0, 0.041], [122447000.0, 0.0919], [122440000.0, 0.0002], [122438000.0, 0.0002]], "asks": [[122492000.0, 0.0007], [122494000.0, 0.0008], [122495000.0, 0.0001], [122497000.0, 0.0096], [122499000.0, 0.0037], [122500000.0, 0.0238], [122502000.0, 0.0], [122504000.0, 0.0002], [122505000.0, 0.0081], [122506000.0, 0.0013]]},
{"timestamp": "1743771421136", "bids": [[122489000.0, 0.0074], [122486000.0, 0.0008], [122485000.0, 0.0001], [122478000.0, 0.0338], [122475000.0, 0.0026], [122461000.0, 0.0007], [122460000.0, 0.0325], [122459000.0, 0.0264], [122456000.0, 0.0001], [122453000.0, 0.0587]], "asks": [[122492000.0, 0.0007], [122494000.0, 0.0008], [122495000.0, 0.0001], [122497000.0, 0.0096], [122499000.0, 0.0037], [122500000.0, 0.0238], [122502000.0, 0.0], [122504000.0, 0.0002], [122505000.0, 0.0081], [122506000.0, 0.0013]]},
{"timestamp": "1743771421640", "bids": [[122489000.0, 0.0074], [122486000.0, 0.0008], [122485000.0, 0.0001], [122478000.0, 0.0338], [122475000.0, 0.0026], [122461000.0, 0.0007], [122460000.0, 0.0325], [122459000.0, 0.0264], [122456000.0, 0.0001], [122454000.0, 0.0404]], "asks": [[122492000.0, 0.0007], [122494000.0, 0.0008], [122495000.0, 0.0001], [122497000.0, 0.0096], [122499000.0, 0.0037], [122500000.0, 0.0238], [122502000.0, 0.0], [122504000.0, 0.0002], [122505000.0, 0.0081], [122506000.0, 0.0013]]},
{"timestamp": "1743771422137", "bids": [[122490000.0, 0.1532], [122489000.0, 0.0074], [122486000.0, 0.0008], [122485000.0, 0.0001], [122478000.0, 0.0338], [122461000.0, 0.0007], [122460000.0, 0.0325], [122459000.0, 0.0264], [122454000.0, 0.0404], [122453000.0, 0.0587]], "asks": [[122492000.0, 0.0007], [122494000.0, 0.0008], [122495000.0, 0.0001], [122497000.0, 0.0096], [122499000.0, 0.0037], [122500000.0, 0.0238], [122502000.0, 0.0], [122504000.0, 0.0002], [122505000.0, 0.0081], [122506000.0, 0.0013]]},
{"timestamp": "1743771422638", "bids": [[122489000.0, 0.0074], [122486000.0, 0.0008], [122485000.0, 0.0022], [122484000.0, 0.0026], [122478000.0, 0.0338], [122477000.0, 0.0001], [122470000.0, 0.946], [122465000.0, 0.0001], [122461000.0, 0.0007], [122460000.0, 0.0325]], "asks": [[122492000.0, 0.0007], [122494000.0, 0.0008], [122495000.0, 0.0001], [122497000.0, 0.0096], [122499000.0, 0.0037], [122500000.0, 0.0238], [122502000.0, 0.0], [122504000.0, 0.0002], [122505000.0, 0.0081], [122506000.0, 0.0013]]},
{"timestamp": "1743771423134", "bids": [[122489000.0, 0.0074], [122486000.0, 0.0008], [122485000.0, 0.0022], [122484000.0, 0.0026], [122478000.0, 0.0338], [122477000.0, 0.0001], [122470000.0, 0.946], [122465000.0, 0.0001], [122461000.0, 0.0007], [122460000.0, 0.0325]], "asks": [[122492000.0, 0.0007], [122494000.0, 0.0008], [122495000.0, 0.0001], [122497000.0, 0.0096], [122499000.0, 0.0037], [122500000.0, 0.0238], [122502000.0, 0.0], [122504000.0, 0.0002], [122505000.0, 0.0081], [122506000.0, 0.0013]]},
{"timestamp": "1743771423638", "bids": [[122489000.0, 0.0074], [122486000.0, 0.0008], [122485000.0, 0.0022], [122484000.0, 0.0026], [122478000.0, 0.0338], [122477000.0, 0.0001], [122470000.0, 0.946], [122465000.0, 0.0001], [122461000.0, 0.0007], [122460000.0, 0.0325]], "asks": [[122492000.0, 0.0007], [122494000.0, 0.0008], [122495000.0, 0.0001], [122497000.0, 0.0096], [122499000.0, 0.0037], [122500000.0, 0.0238], [122502000.0, 0.0], [122504000.0, 0.0002], [122505000.0, 0.0081], [122506000.0, 0.0013]]},
{"timestamp": "1743771424148", "bids": [[122489000.0, 0.0074], [122486000.0, 0.0008], [122485000.0, 0.0022], [122484000.0, 0.0026], [122478000.0, 0.0338], [122477000.0, 0.0001], [122470000.0, 0.946], [122465000.0, 0.0001], [122461000.0, 0.0007], [122460000.0, 0.0325]], "asks": [[122492000.0, 0.0007], [122494000.0, 0.0008], [122495000.0, 0.0001], [122497000.0, 0.0096], [122499000.0, 0.0037], [122500000.0, 0.0238], [122502000.0, 0.0], [122504000.0, 0.0002], [122505000.0, 0.0081], [122506000.0, 0.0013]]},
{"timestamp": "1743771424638", "bids": [[122490000.0, 0.1301], [122489000.0, 0.0074], [122486000.0, 0.0008], [122485000.0, 0.0022], [122484000.0, 0.0026], [122478000.0, 0.0338], [122477000.0, 0.0001], [122470000.0, 0.946], [122465000.0, 0.0001], [122461000.0, 0.0007]], "asks": [[122492000.0, 0.0007], [122494000.0, 0.0008], [122495000.0, 0.0001], [122497000.0, 0.0096], [122499000.0, 0.0037], [122500000.0, 0.0238], [122502000.0, 0.0], [122504000.0, 0.0002], [122505000.0, 0.0081], [122506000.0, 0.0013]]},
{"timestamp": "1743771425137", "bids": [[122490000.0, 0.1297], [122489000.0, 0.0074], [122486000.0, 0.0008], [122485000.0, 0.0022], [122479000.0, 0.0404], [122478000.0, 0.0112], [122477000.0, 0.0001], [122470000.0, 0.946], [122461000.0, 0.0007], [122460000.0, 0.0048]], "asks": [[122492000.0, 0.0007], [122494000.0, 0.0008], [122495000.0, 0.0001], [122497000.0, 0.0096], [122499000.0, 0.0037], [122500000.0, 0.0238], [122502000.0, 0.0], [122504000.0, 0.0002], [122505000.0, 0.0081], [122506000.0, 0.0013]]},
{"timestamp": "1743771425637", "bids": [[122489000.0, 0.0074], [122486000.0, 0.0008], [122485000.0, 0.0022], [122479000.0, 0.0404], [122470000.0, 0.946], [122461000.0, 0.0007], [122460000.0, 0.0048], [122453000.0, 0.0225], [122446000.0, 0.0248], [122444000.0, 0.0]], "asks": [[122492000.0, 0.0007], [122494000.0, 0.0008], [122495000.0, 0.0001], [122497000.0, 0.0096], [122499000.0, 0.0037], [122500000.0, 0.0238], [122502000.0, 0.0], [122504000.0, 0.0002], [122505000.0, 0.0081], [122506000.0, 0.0013]]},
{"timestamp": "1743771426138", "bids": [[122486000.0, 0.0008], [122485000.0, 0.0022], [122475000.0, 0.0026], [122471000.0, 0.0404], [122470000.0, 0.946], [122469000.0, 0.0113], [122461000.0, 0.0007], [122460000.0, 0.0048], [122457000.0, 0.0001], [122453000.0, 0.0225]], "asks": [[122492000.0, 0.0012], [122494000.0, 0.0008], [122495000.0, 0.0001], [122497000.0, 0.0096], [122499000.0, 0.0037], [122500000.0, 0.0238], [122502000.0, 0.0], [122504000.0, 0.0002], [122505000.0, 0.0081], [122506000.0, 0.0013]]},
{"timestamp": "1743771426641", "bids": [[122486000.0, 0.0008], [122485000.0, 0.0022], [122475000.0, 0.0026], [122471000.0, 0.0404], [122470000.0, 0.946], [122469000.0, 0.0113], [122461000.0, 0.0007], [122458000.0, 0.0048], [122457000.0, 0.0001], [122453000.0, 0.0225]], "asks": [[122492000.0, 0.0012], [122494000.0, 0.0008], [122495000.0, 0.0001], [122497000.0, 0.0096], [122499000.0, 0.0037], [122500000.0, 0.0238], [122502000.0, 0.0], [122504000.0, 0.0002], [122505000.0, 0.0081], [122506000.0, 0.0013]]},
{"timestamp": "1743771427137", "bids": [[122486000.0, 0.0008], [122485000.0, 0.0022], [122475000.0, 0.0026], [122469000.0, 0.0113], [122461000.0, 0.0007], [122458000.0, 0.0048], [122457000.0, 0.0001], [122454000.0, 0.0842], [122453000.0, 0.0225], [122451000.0, 0.0329]], "asks": [[122492000.0, 0.0012], [122494000.0, 0.0008], [122495000.0, 0.0001], [122497000.0, 0.0096], [122499000.0, 0.0037], [122500000.0, 0.0238], [122502000.0, 0.0], [122504000.0, 0.0002], [122505000.0, 0.0081], [122506000.0, 0.0013]]},
{"timestamp": "1743771427636", "bids": [[122486000.0, 0.0008], [122485000.0, 0.0022], [122475000.0, 0.0026], [122469000.0, 0.0113], [122461000.0, 0.0007], [122457000.0, 0.0001], [122454000.0, 0.0842], [122453000.0, 0.0225], [122451000.0, 0.0329], [122446000.0, 0.0248]], "asks": [[122492000.0, 0.0012], [122494000.0, 0.0008], [122495000.0, 0.0001], [122497000.0, 0.0096], [122499000.0, 0.0037], [122500000.0, 0.0238], [122502000.0, 0.0], [122504000.0, 0.0002], [122505000.0, 0.0081], [122506000.0, 0.0013]]},
{"timestamp": "1743771428138", "bids": [[122486000.0, 0.0008], [122485000.0, 0.0022], [122475000.0, 0.0026], [122469000.0, 0.0113], [122461000.0, 0.0007], [122457000.0, 0.0001], [122454000.0, 0.0842], [122451000.0, 0.0377], [122446000.0, 0.0248], [122445000.0, 0.0258]], "asks": [[122492000.0, 0.0012], [122494000.0, 0.0008], [122495000.0, 0.0001], [122497000.0, 0.0096], [122499000.0, 0.0037], [122500000.0, 0.0238], [122502000.0, 0.0], [122504000.0, 0.0002], [122505000.0, 0.0081], [122506000.0, 0.0013]]},
{"timestamp": "1743771428648", "bids": [[122487000.0, 0.0118], [122486000.0, 0.0008], [122485000.0, 0.0022], [122475000.0, 0.0026], [122469000.0, 0.0113], [122461000.0, 0.0007], [122457000.0, 0.0001], [122452000.0, 0.0842], [122451000.0, 0.0377], [122446000.0, 0.0248]], "asks": [[122491000.0, 0.0364], [122492000.0, 0.0012], [122494000.0, 0.0008], [122495000.0, 0.0001], [122497000.0, 0.0096], [122499000.0, 0.0037], [122500000.0, 0.0238], [122502000.0, 0.0], [122504000.0, 0.0002], [122505000.0, 0.0081]]},
{"timestamp": "1743771429138", "bids": [[122488000.0, 0.0012], [122487000.0, 0.0118], [122486000.0, 0.0008], [122485000.0, 0.0022], [122466000.0, 0.0226], [122461000.0, 0.0007], [122457000.0, 0.0001], [122452000.0, 0.0842], [122451000.0, 0.0048], [122447000.0, 0.0325]], "asks": [[122491000.0, 0.0414], [122492000.0, 0.0012], [122494000.0, 0.0008], [122495000.0, 0.0001], [122497000.0, 0.0096], [122499000.0, 0.0037], [122500000.0, 0.0338], [122502000.0, 0.0], [122504000.0, 0.0002], [122505000.0, 0.0081]]},
{"timestamp": "1743771429640", "bids": [[122488000.0, 0.0012], [122486000.0, 0.0008], [122485000.0, 0.0022], [122471000.0, 0.0074], [122466000.0, 0.0226], [122461000.0, 0.0007], [122453000.0, 0.0048], [122447000.0, 0.1167], [122444000.0, 0.0], [122441000.0, 0.0626]], "asks": [[122492000.0, 0.0012], [122494000.0, 0.0008], [122495000.0, 0.0001], [122497000.0, 0.0096], [122499000.0, 0.0037], [122500000.0, 0.0338], [122502000.0, 0.0], [122504000.0, 0.0002], [122505000.0, 0.0081], [122506000.0, 0.0013]]},
{"timestamp": "1743771430143", "bids": [[122486000.0, 0.0004], [122485000.0, 0.0022], [122466000.0, 0.0226], [122461000.0, 0.0007], [122453000.0, 0.0048], [122447000.0, 0.0325], [122444000.0, 0.0], [122442000.0, 0.0026], [122436000.0, 0.0113], [122432000.0, 0.056]], "asks": [[122490000.0, 0.0002], [122492000.0, 0.0012], [122494000.0, 0.0008], [122495000.0, 0.0001], [122497000.0, 0.0096], [122499000.0, 0.0037], [122500000.0, 0.0338], [122502000.0, 0.0], [122504000.0, 0.0002], [122505000.0, 0.0081]]},
{"timestamp": "1743771430640", "bids": [[122486000.0, 0.0004], [122485000.0, 0.0034], [122461000.0, 0.0007], [122453000.0, 0.0048], [122444000.0, 0.0], [122436000.0, 0.0113], [122429000.0, 0.0001], [122425000.0, 0.003], [122421000.0, 0.0415], [122420000.0, 0.0]], "asks": [[122489000.0, 0.021], [122490000.0, 0.0002], [122492000.0, 0.0012], [122494000.0, 0.0008], [122495000.0, 0.0001], [122497000.0, 0.0096], [122499000.0, 0.0037], [122500000.0, 0.0338], [122502000.0, 0.0], [122504000.0, 0.0002]]},
{"timestamp": "1743771431136", "bids": [[122486000.0, 0.0004], [122485000.0, 0.0034], [122461000.0, 0.0007], [122453000.0, 0.0048], [122444000.0, 0.0], [122429000.0, 0.0001], [122425000.0, 0.003], [122421000.0, 0.0415], [122420000.0, 0.0], [122419000.0, 0.0001]], "asks": [[122489000.0, 0.021], [122492000.0, 0.0012], [122494000.0, 0.0008], [122495000.0, 0.0001], [122497000.0, 0.0096], [122499000.0, 0.0037], [122500000.0, 0.0338], [122502000.0, 0.0], [122504000.0, 0.0002], [122505000.0, 0.0081]]},
{"timestamp": "1743771431639", "bids": [[122486000.0, 0.0004], [122485000.0, 0.0034], [122461000.0, 0.0007], [122455000.0, 0.0095], [122453000.0, 0.0048], [122444000.0, 0.0], [122433000.0, 0.0026], [122432000.0, 0.0074], [122429000.0, 0.0001], [122425000.0, 0.003]], "asks": [[122492000.0, 0.0012], [122494000.0, 0.0008], [122495000.0, 0.0001], [122497000.0, 0.0096], [122499000.0, 0.0037], [122500000.0, 0.0338], [122502000.0, 0.0], [122504000.0, 0.0002], [122505000.0, 0.0081], [122506000.0, 0.0013]]},
{"timestamp": "1743771432142", "bids": [[122487000.0, 0.1172], [122486000.0, 0.0004], [122485000.0, 0.0034], [122461000.0, 0.0007], [122456000.0, 0.0225], [122455000.0, 0.0095], [122453000.0, 0.0048], [122446000.0, 0.0036], [122444000.0, 0.0], [122433000.0, 0.0026]], "asks": [[122492000.0, 0.0012], [122494000.0, 0.0008], [122495000.0, 0.0001], [122497000.0, 0.0096], [122499000.0, 0.0037], [122500000.0, 0.0338], [122502000.0, 0.0], [122504000.0, 0.0002], [122505000.0, 0.0081], [122506000.0, 0.0013]]},
{"timestamp": "1743771432643", "bids": [[122487000.0, 0.1309], [122486000.0, 0.0004], [122485000.0, 0.0034], [122461000.0, 0.0007], [122456000.0, 0.0225], [122455000.0, 0.0095], [122446000.0, 0.0036], [122444000.0, 0.0], [122433000.0, 0.0842], [122429000.0, 0.0001]], "asks": [[122492000.0, 0.0012], [122494000.0, 0.0008], [122495000.0, 0.0001], [122497000.0, 0.0096], [122499000.0, 0.0037], [122500000.0, 0.0338], [122502000.0, 0.0], [122504000.0, 0.0002], [122505000.0, 0.0081], [122506000.0, 0.0013]]},
{"timestamp": "1743771433135", "bids": [[122487000.0, 0.1309], [122486000.0, 0.0004], [122485000.0, 0.0034], [122461000.0, 0.0007], [122455000.0, 0.0095], [122446000.0, 0.0036], [122444000.0, 0.0], [122433000.0, 0.0842], [122430000.0, 0.0339], [122429000.0, 0.0001]], "asks": [[122492000.0, 0.0012], [122494000.0, 0.0008], [122495000.0, 0.0001], [122497000.0, 0.0096], [122499000.0, 0.0037], [122500000.0, 0.0338], [122502000.0, 0.0], [122504000.0, 0.0002], [122505000.0, 0.0081], [122506000.0, 0.0013]]},
{"timestamp": "1743771433641", "bids": [[122486000.0, 0.0004], [122485000.0, 0.0034], [122482000.0, 0.0096], [122449000.0, 0.0026], [122446000.0, 0.0036], [122444000.0, 0.0], [122433000.0, 0.0842], [122431000.0, 0.0001], [122430000.0, 0.0339], [122429000.0, 0.0001]], "asks": [[122491000.0, 0.0023], [122492000.0, 0.0012], [122494000.0, 0.0008], [122495000.0, 0.0001], [122497000.0, 0.0096], [122499000.0, 0.0037], [122500000.0, 0.0338], [122502000.0, 0.0], [122504000.0, 0.0002], [122505000.0, 0.0081]]},
{"timestamp": "1743771434139", "bids": [[122486000.0, 0.0004], [122485000.0, 0.0034], [122482000.0, 0.0096], [122449000.0, 0.0026], [122448000.0, 0.0074], [122446000.0, 0.0036], [122444000.0, 0.0], [122431000.0, 0.0843], [122430000.0, 0.0339], [122429000.0, 0.0001]], "asks": [[122492000.0, 0.0012], [122494000.0, 0.0008], [122495000.0, 0.0001], [122497000.0, 0.0096], [122499000.0, 0.0037], [122500000.0, 0.0338], [122502000.0, 0.0], [122504000.0, 0.0002], [122505000.0, 0.0081], [122506000.0, 0.0013]]},
{"timestamp": "1743771434642", "bids": [[122486000.0, 0.0004], [122485000.0, 0.0034], [122482000.0, 0.0096], [122449000.0, 0.0026], [122448000.0, 0.0074], [122446000.0, 0.0036], [122444000.0, 0.0], [122431000.0, 0.0843], [122430000.0, 0.0339], [122429000.0, 0.0001]], "asks": [[122492000.0, 0.0012], [122494000.0, 0.0008], [122495000.0, 0.0001], [122497000.0, 0.0096], [122499000.0, 0.0037], [122500000.0, 0.0338], [122502000.0, 0.0], [122504000.0, 0.0002], [122505000.0, 0.0081], [122506000.0, 0.0013]]},
{"timestamp": "1743771435139", "bids": [[122486000.0, 0.0004], [122485000.0, 0.0034], [122482000.0, 0.0096], [122449000.0, 0.0026], [122448000.0, 0.0074], [122446000.0, 0.0036], [122444000.0, 0.0], [122431000.0, 0.0843], [122430000.0, 0.0339], [122429000.0, 0.0001]], "asks": [[122492000.0, 0.0012], [122494000.0, 0.0008], [122495000.0, 0.0001], [122497000.0, 0.0096], [122499000.0, 0.0037], [122500000.0, 0.0338], [122502000.0, 0.0], [122504000.0, 0.0002], [122505000.0, 0.0081], [122506000.0, 0.0013]]},
{"timestamp": "1743771435640", "bids": [[122486000.0, 0.0004], [122485000.0, 0.0034], [122482000.0, 0.0046], [122449000.0, 0.0026], [122448000.0, 0.0074], [122446000.0, 0.0036], [122444000.0, 0.0], [122431000.0, 0.0843], [122430000.0, 0.0339], [122429000.0, 0.0001]], "asks": [[122491000.0, 0.0018], [122492000.0, 0.0012], [122494000.0, 0.0008], [122495000.0, 0.0001], [122497000.0, 0.0096], [122499000.0, 0.0037], [122500000.0, 0.0338], [122502000.0, 0.0], [122504000.0, 0.0002], [122505000.0, 0.0081]]},
{"timestamp": "1743771436338", "bids": [[122486000.0, 0.0004], [122485000.0, 0.0034], [122482000.0, 0.0046], [122446000.0, 0.0036], [122444000.0, 0.0], [122430000.0, 0.0113], [122429000.0, 0.0001], [122425000.0, 0.003], [122422000.0, 0.0048], [122421000.0, 0.0842]], "asks": [[122491000.0, 0.0205], [122492000.0, 0.0012], [122494000.0, 0.0008], [122495000.0, 0.0001], [122497000.0, 0.0096], [122499000.0, 0.0037], [122500000.0, 0.0338], [122502000.0, 0.0], [122504000.0, 0.0002], [122505000.0, 0.0081]]},
{"timestamp": "1743771436645", "bids": [[122486000.0, 0.0004], [122485000.0, 0.0034], [122446000.0, 0.0036], [122444000.0, 0.0], [122430000.0, 0.0113], [122429000.0, 0.0001], [122425000.0, 0.003], [122422000.0, 0.0048], [122421000.0, 0.0842], [122420000.0, 0.0]], "asks": [[122491000.0, 0.0187], [122492000.0, 0.0012], [122494000.0, 0.0008], [122495000.0, 0.0001], [122497000.0, 0.0096], [122499000.0, 0.0037], [122500000.0, 0.0338], [122502000.0, 0.0], [122504000.0, 0.0002], [122505000.0, 0.0081]]},
{"timestamp": "1743771437142", "bids": [[122486000.0, 0.0004], [122485000.0, 0.0034], [122447000.0, 0.0122], [122446000.0, 0.0036], [122444000.0, 0.0], [122434000.0, 0.0026], [122433000.0, 0.0074], [122429000.0, 0.0001], [122425000.0, 0.003], [122421000.0, 0.0842]], "asks": [[122491000.0, 0.0002], [122492000.0, 0.0012], [122494000.0, 0.0008], [122495000.0, 0.0001], [122497000.0, 0.0096], [122499000.0, 0.0037], [122500000.0, 0.0338], [122502000.0, 0.0], [122504000.0, 0.0002], [122505000.0, 0.0081]]},
{"timestamp": "1743771437640", "bids": [[122486000.0, 0.0004], [122485000.0, 0.0034], [122447000.0, 0.024], [122446000.0, 0.0036], [122444000.0, 0.0], [122434000.0, 0.0026], [122433000.0, 0.0074], [122429000.0, 0.0001], [122425000.0, 0.003], [122420000.0, 0.0]], "asks": [[122491000.0, 0.0002], [122492000.0, 0.0012], [122494000.0, 0.0008], [122495000.0, 0.0001], [122497000.0, 0.0096], [122499000.0, 0.0037], [122500000.0, 0.0338], [122502000.0, 0.0], [122504000.0, 0.0002], [122505000.0, 0.0081]]},
{"timestamp": "1743771438148", "bids": [[122486000.0, 0.0004], [122485000.0, 0.0034], [122447000.0, 0.024], [122446000.0, 0.0036], [122444000.0, 0.0], [122434000.0, 0.0026], [122433000.0, 0.0074], [122429000.0, 0.0001], [122425000.0, 0.003], [122420000.0, 0.0]], "asks": [[122491000.0, 0.0002], [122492000.0, 0.0012], [122494000.0, 0.0008], [122495000.0, 0.0001], [122497000.0, 0.0096], [122499000.0, 0.0037], [122500000.0, 0.0338], [122502000.0, 0.0], [122504000.0, 0.0002], [122505000.0, 0.0081]]},
{"timestamp": "1743771438646", "bids": [[122486000.0, 0.0004], [122485000.0, 0.0034], [122447000.0, 0.024], [122446000.0, 0.0036], [122444000.0, 0.0], [122434000.0, 0.0026], [122433000.0, 0.0074], [122429000.0, 0.0001], [122425000.0, 0.003], [122420000.0, 0.0]], "asks": [[122491000.0, 0.0002], [122492000.0, 0.0012], [122494000.0, 0.0008], [122495000.0, 0.0001], [122497000.0, 0.0096], [122499000.0, 0.0037], [122500000.0, 0.0338], [122502000.0, 0.0], [122504000.0, 0.0002], [122505000.0, 0.0081]]},
{"timestamp": "1743771439145", "bids": [[122486000.0, 0.0004], [122485000.0, 0.0034], [122447000.0, 0.024], [122446000.0, 0.0036], [122444000.0, 0.0], [122434000.0, 0.0026], [122433000.0, 0.0074], [122429000.0, 0.0001], [122425000.0, 0.003], [122420000.0, 0.0]], "asks": [[122490000.0, 0.0376], [122491000.0, 0.0002], [122492000.0, 0.0012], [122494000.0, 0.0008], [122495000.0, 0.0001], [122497000.0, 0.0096], [122499000.0, 0.0037], [122500000.0, 0.0338], [122502000.0, 0.0], [122504000.0, 0.0002]]},
{"timestamp": "1743771439642", "bids": [[122486000.0, 0.0004], [122485000.0, 0.0034], [122447000.0, 0.024], [122446000.0, 0.0036], [122444000.0, 0.0], [122429000.0, 0.0001], [122426000.0, 0.0227], [122425000.0, 0.003], [122420000.0, 0.0], [122415000.0, 0.0879]], "asks": [[122487000.0, 0.0225], [122489000.0, 0.003], [122490000.0, 0.0376], [122491000.0, 0.0002], [122492000.0, 0.0012], [122494000.0, 0.0008], [122495000.0, 0.0001], [122497000.0, 0.0096], [122499000.0, 0.0037], [122500000.0, 0.0338]]},
{"timestamp": "1743771440145", "bids": [[122486000.0, 0.0014], [122485000.0, 0.0034], [122446000.0, 0.0036], [122444000.0, 0.0], [122429000.0, 0.0001], [122426000.0, 0.0339], [122425000.0, 0.003], [122420000.0, 0.0], [122415000.0, 0.0878], [122412000.0, 0.0118]], "asks": [[122487000.0, 0.0225], [122489000.0, 0.003], [122491000.0, 0.0002], [122492000.0, 0.0012], [122494000.0, 0.0008], [122495000.0, 0.0395], [122497000.0, 0.0096], [122499000.0, 0.0037], [122500000.0, 0.0338], [122502000.0, 0.0]]},
{"timestamp": "1743771440643", "bids": [[122486000.0, 0.0014], [122485000.0, 0.0034], [122446000.0, 0.0036], [122444000.0, 0.0], [122429000.0, 0.0001], [122426000.0, 0.0339], [122425000.0, 0.003], [122420000.0, 0.0], [122415000.0, 0.0036], [122412000.0, 0.0118]], "asks": [[122487000.0, 0.0225], [122491000.0, 0.0002], [122492000.0, 0.0012], [122494000.0, 0.0176], [122495000.0, 0.0641], [122497000.0, 0.0292], [122499000.0, 0.0037], [122500000.0, 0.0338], [122502000.0, 0.0], [122504000.0, 0.0002]]},
{"timestamp": "1743771441141", "bids": [[122486000.0, 0.0014], [122485000.0, 0.0034], [122447000.0, 0.0005], [122446000.0, 0.0036], [122444000.0, 0.0], [122432000.0, 0.0002], [122429000.0, 0.0001], [122426000.0, 0.0112], [122425000.0, 0.003], [122420000.0, 0.0]], "asks": [[122491000.0, 0.0002], [122492000.0, 0.0012], [122494000.0, 0.0008], [122495000.0, 0.0222], [122497000.0, 0.0292], [122499000.0, 0.0037], [122500000.0, 0.0338], [122502000.0, 0.0], [122504000.0, 0.0002], [122505000.0, 0.0081]]},
{"timestamp": "1743771441643", "bids": [[122486000.0, 0.0015], [122485000.0, 0.0034], [122447000.0, 0.0005], [122446000.0, 0.0036], [122444000.0, 0.0], [122432000.0, 0.0002], [122429000.0, 0.0001], [122425000.0, 0.003], [122420000.0, 0.0], [122419000.0, 0.0074]], "asks": [[122491000.0, 0.0002], [122492000.0, 0.0012], [122494000.0, 0.0008], [122495000.0, 0.0001], [122497000.0, 0.0096], [122499000.0, 0.0037], [122500000.0, 0.0339], [122501000.0, 0.0114], [122502000.0, 0.0242], [122504000.0, 0.0002]]},
{"timestamp": "1743771442152", "bids": [[122486000.0, 0.0015], [122485000.0, 0.0034], [122447000.0, 0.0005], [122446000.0, 0.0036], [122444000.0, 0.0], [122432000.0, 0.0002], [122429000.0, 0.0001], [122427000.0, 0.0842], [122425000.0, 0.003], [122420000.0, 0.0]], "asks": [[122491000.0, 0.0002], [122492000.0, 0.0012], [122494000.0, 0.0008], [122495000.0, 0.0001], [122497000.0, 0.0096], [122499000.0, 0.0037], [122500000.0, 0.0877], [122501000.0, 0.0114], [122502000.0, 0.0], [122504000.0, 0.0002]]},
{"timestamp": "1743771442645", "bids": [[122486000.0, 0.0015], [122485000.0, 0.0034], [122446000.0, 0.0036], [122444000.0, 0.0], [122429000.0, 0.0001], [122427000.0, 0.0842], [122425000.0, 0.0056], [122420000.0, 0.0], [122416000.0, 0.0227], [122415000.0, 0.0036]], "asks": [[122491000.0, 0.0002], [122492000.0, 0.0012], [122494000.0, 0.0008], [122495000.0, 0.0001], [122497000.0, 0.0096], [122499000.0, 0.0037], [122500000.0, 0.0703], [122502000.0, 0.0], [122504000.0, 0.0002], [122505000.0, 0.0548]]},
{"timestamp": "1743771443141", "bids": [[122487000.0, 0.1657], [122486000.0, 0.0015], [122485000.0, 0.0034], [122480000.0, 0.0005], [122446000.0, 0.0036], [122444000.0, 0.0], [122429000.0, 0.0001], [122426000.0, 0.0112], [122425000.0, 0.0056], [122420000.0, 0.0842]], "asks": [[122491000.0, 0.0002], [122492000.0, 0.0012], [122494000.0, 0.0008], [122495000.0, 0.0001], [122497000.0, 0.0096], [122499000.0, 0.0037], [122500000.0, 0.0338], [122502000.0, 0.0], [122504000.0, 0.0002], [122505000.0, 0.0327]]},
{"timestamp": "1743771443644", "bids": [[122487000.0, 0.0008], [122486000.0, 0.0015], [122485000.0, 0.0034], [122480000.0, 0.0005], [122446000.0, 0.0036], [122444000.0, 0.0], [122442000.0, 0.0026], [122441000.0, 0.0074], [122431000.0, 0.0842], [122430000.0, 0.0048]], "asks": [[122491000.0, 0.0002], [122492000.0, 0.0012], [122494000.0, 0.0008], [122495000.0, 0.0001], [122497000.0, 0.0096], [122499000.0, 0.0037], [122500000.0, 0.0338], [122502000.0, 0.0], [122504000.0, 0.0002], [122505000.0, 0.0081]]},
{"timestamp": "1743771444159", "bids": [[122487000.0, 0.0008], [122486000.0, 0.0015], [122485000.0, 0.0034], [122480000.0, 0.0005], [122446000.0, 0.0036], [122444000.0, 0.0], [122442000.0, 0.0026], [122441000.0, 0.0074], [122431000.0, 0.0842], [122429000.0, 0.0001]], "asks": [[122491000.0, 0.0002], [122492000.0, 0.0012], [122494000.0, 0.0008], [122495000.0, 0.0001], [122497000.0, 0.0096], [122499000.0, 0.0037], [122500000.0, 0.0338], [122502000.0, 0.0], [122504000.0, 0.0002], [122505000.0, 0.0081]]},
{"timestamp": "1743771444647", "bids": [[122487000.0, 0.0008], [122486000.0, 0.0015], [122485000.0, 0.0034], [122480000.0, 0.0005], [122446000.0, 0.0036], [122444000.0, 0.0], [122442000.0, 0.0026], [122441000.0, 0.0074], [122429000.0, 0.0001], [122427000.0, 0.0048]], "asks": [[122491000.0, 0.0002], [122492000.0, 0.0012], [122494000.0, 0.0008], [122495000.0, 0.0001], [122497000.0, 0.0096], [122499000.0, 0.0037], [122500000.0, 0.0338], [122502000.0, 0.0], [122504000.0, 0.0002], [122505000.0, 0.0081]]},
{"timestamp": "1743771445148", "bids": [[122491000.0, 0.0202], [122487000.0, 0.0008], [122486000.0, 0.0015], [122485000.0, 0.0034], [122480000.0, 0.0005], [122446000.0, 0.0036], [122444000.0, 0.0], [122442000.0, 0.0026], [122441000.0, 0.0074], [122429000.0, 0.0001]], "asks": [[122492000.0, 0.0012], [122494000.0, 0.0008], [122495000.0, 0.0001], [122497000.0, 0.0096], [122499000.0, 0.0037], [122500000.0, 0.0338], [122502000.0, 0.0], [122504000.0, 0.0002], [122505000.0, 0.0081], [122506000.0, 0.0209]]},
{"timestamp": "1743771445644", "bids": [[122491000.0, 0.0202], [122487000.0, 0.0007], [122486000.0, 0.0015], [122485000.0, 0.0034], [122446000.0, 0.0099], [122444000.0, 0.0], [122434000.0, 0.0226], [122429000.0, 0.0001], [122427000.0, 0.089], [122425000.0, 0.003]], "asks": [[122492000.0, 0.0012], [122494000.0, 0.0008], [122495000.0, 0.0001], [122497000.0, 0.0096], [122499000.0, 0.0037], [122500000.0, 0.0338], [122502000.0, 0.0], [122504000.0, 0.0002], [122505000.0, 0.0081], [122506000.0, 0.0013]]},
{"timestamp": "1743771446142", "bids": [[122491000.0, 0.0202], [122487000.0, 0.0007], [122486000.0, 0.0015], [122485000.0, 0.0034], [122446000.0, 0.0099], [122444000.0, 0.0], [122439000.0, 0.0074], [122433000.0, 0.0026], [122429000.0, 0.0001], [122425000.0, 0.003]], "asks": [[122492000.0, 0.0012], [122494000.0, 0.0008], [122495000.0, 0.0001], [122497000.0, 0.0096], [122499000.0, 0.0037], [122500000.0, 0.0338], [122502000.0, 0.0], [122504000.0, 0.0002], [122505000.0, 0.0081], [122506000.0, 0.0013]]},
{"timestamp": "1743771446657", "bids": [[122491000.0, 0.0202], [122487000.0, 0.0007], [122486000.0, 0.0015], [122485000.0, 0.0034], [122446000.0, 0.0099], [122444000.0, 0.0], [122439000.0, 0.0074], [122433000.0, 0.0026], [122429000.0, 0.0001], [122427000.0, 0.0113]], "asks": [[122492000.0, 0.0208], [122494000.0, 0.0008], [122495000.0, 0.0001], [122497000.0, 0.0096], [122499000.0, 0.0037], [122500000.0, 0.0338], [122502000.0, 0.0], [122504000.0, 0.0788], [122505000.0, 0.0081], [122506000.0, 0.0013]]},
{"timestamp": "1743771447144", "bids": [[122491000.0, 0.0202], [122487000.0, 0.0007], [122486000.0, 0.0015], [122485000.0, 0.0034], [122446000.0, 0.0099], [122444000.0, 0.0], [122429000.0, 0.0001], [122427000.0, 0.0113], [122425000.0, 0.003], [122424000.0, 0.0226]], "asks": [[122492000.0, 0.0208], [122494000.0, 0.0008], [122495000.0, 0.0001], [122497000.0, 0.0096], [122499000.0, 0.0037], [122500000.0, 0.0511], [122501000.0, 0.0168], [122502000.0, 0.0], [122504000.0, 0.0788], [122505000.0, 0.0081]]},
{"timestamp": "1743771447643", "bids": [[122491000.0, 0.0202], [122487000.0, 0.0007], [122486000.0, 0.0015], [122485000.0, 0.0034], [122446000.0, 0.0036], [122444000.0, 0.0], [122429000.0, 0.0001], [122425000.0, 0.003], [122424000.0, 0.0226], [122420000.0, 0.0]], "asks": [[122492000.0, 0.0012], [122494000.0, 0.0008], [122495000.0, 0.0001], [122497000.0, 0.0096], [122498000.0, 0.0246], [122499000.0, 0.0037], [122500000.0, 0.0511], [122501000.0, 0.041], [122502000.0, 0.0001], [122504000.0, 0.0002]]},
{"timestamp": "1743771448144", "bids": [[122491000.0, 0.0202], [122487000.0, 0.0007], [122486000.0, 0.0015], [122485000.0, 0.0034], [122446000.0, 0.0036], [122444000.0, 0.0], [122429000.0, 0.0001], [122425000.0, 0.003], [122424000.0, 0.0226], [122420000.0, 0.0]], "asks": [[122492000.0, 0.0012], [122494000.0, 0.0008], [122495000.0, 0.0001], [122497000.0, 0.0096], [122498000.0, 0.0664], [122499000.0, 0.0151], [122500000.0, 0.0511], [122501000.0, 0.041], [122502000.0, 0.0001], [122504000.0, 0.0002]]},
{"timestamp": "1743771448649", "bids": [[122491000.0, 0.0202], [122487000.0, 0.0007], [122486000.0, 0.0015], [122485000.0, 0.0034], [122446000.0, 0.0036], [122444000.0, 0.0], [122429000.0, 0.0001], [122425000.0, 0.0869], [122424000.0, 0.0226], [122420000.0, 0.0]], "asks": [[122492000.0, 0.0012], [122494000.0, 0.0008], [122495000.0, 0.0001], [122497000.0, 0.0096], [122498000.0, 0.0664], [122499000.0, 0.0151], [122500000.0, 0.0511], [122501000.0, 0.041], [122502000.0, 0.0001], [122504000.0, 0.0002]]},
{"timestamp": "1743771449143", "bids": [[122491000.0, 0.0202], [122487000.0, 0.0007], [122486000.0, 0.0015], [122485000.0, 0.0034], [122446000.0, 0.0036], [122444000.0, 0.0], [122429000.0, 0.0001], [122425000.0, 0.003], [122424000.0, 0.0226], [122420000.0, 0.0]], "asks": [[122492000.0, 0.0012], [122494000.0, 0.0008], [122495000.0, 0.0001], [122497000.0, 0.0096], [122498000.0, 0.0664], [122499000.0, 0.0151], [122500000.0, 0.0511], [122501000.0, 0.041], [122502000.0, 0.0001], [122504000.0, 0.0002]]},
{"timestamp": "1743771449646", "bids": [[122491000.0, 0.0202], [122487000.0, 0.0007], [122486000.0, 0.0015], [122485000.0, 0.0034], [122446000.0, 0.0036], [122444000.0, 0.0], [122429000.0, 0.0001], [122425000.0, 0.0869], [122424000.0, 0.0226], [122420000.0, 0.0]], "asks": [[122492000.0, 0.0012], [122494000.0, 0.0008], [122495000.0, 0.0001], [122497000.0, 0.0096], [122498000.0, 0.0664], [122499000.0, 0.0151], [122500000.0, 0.0511], [122501000.0, 0.041], [122502000.0, 0.0001], [122504000.0, 0.0002]]},
{"timestamp": "1743771450140", "bids": [[122491000.0, 0.0202], [122487000.0, 0.0007], [122486000.0, 0.0015], [122485000.0, 0.0034], [122446000.0, 0.0036], [122444000.0, 0.0], [122429000.0, 0.0001], [122425000.0, 0.0869], [122424000.0, 0.0226], [122420000.0, 0.0]], "asks": [[122492000.0, 0.0012], [122494000.0, 0.0008], [122495000.0, 0.0001], [122497000.0, 0.0096], [122498000.0, 0.0664], [122499000.0, 0.0151], [122500000.0, 0.0511], [122501000.0, 0.041], [122502000.0, 0.0001], [122504000.0, 0.0002]]},
{"timestamp": "1743771450646", "bids": [[122491000.0, 0.0202], [122487000.0, 0.0007], [122486000.0, 0.0015], [122485000.0, 0.0034], [122446000.0, 0.0036], [122444000.0, 0.0], [122429000.0, 0.0001], [122425000.0, 0.0869], [122424000.0, 0.0226], [122420000.0, 0.0]], "asks": [[122492000.0, 0.0012], [122494000.0, 0.0008], [122495000.0, 0.0001], [122497000.0, 0.0096], [122498000.0, 0.0664], [122499000.0, 0.0151], [122500000.0, 0.0511], [122501000.0, 0.041], [122502000.0, 0.0001], [122504000.0, 0.0002]]},
{"timestamp": "1743771451145", "bids": [[122491000.0, 0.0202], [122487000.0, 0.0007], [122486000.0, 0.0015], [122485000.0, 0.0034], [122446000.0, 0.0036], [122444000.0, 0.0], [122429000.0, 0.0001], [122425000.0, 0.0869], [122424000.0, 0.0226], [122420000.0, 0.0]], "asks": [[122492000.0, 0.0012], [122494000.0, 0.0008], [122495000.0, 0.0001], [122497000.0, 0.0096], [122498000.0, 0.0664], [122499000.0, 0.0151], [122500000.0, 0.0338], [122501000.0, 0.0168], [122502000.0, 0.0], [122504000.0, 0.0002]]},
{"timestamp": "1743771451653", "bids": [[122491000.0, 0.0202], [122487000.0, 0.0007], [122486000.0, 0.0015], [122485000.0, 0.0034], [122446000.0, 0.0036], [122444000.0, 0.0], [122429000.0, 0.0001], [122425000.0, 0.0869], [122420000.0, 0.0], [122415000.0, 0.0036]], "asks": [[122492000.0, 0.0012], [122494000.0, 0.0008], [122495000.0, 0.0001], [122497000.0, 0.0096], [122499000.0, 0.0037], [122500000.0, 0.0338], [122502000.0, 0.0], [122504000.0, 0.0002], [122505000.0, 0.0081], [122506000.0, 0.0013]]},
{"timestamp": "1743771452143", "bids": [[122491000.0, 0.0202], [122487000.0, 0.0007], [122486000.0, 0.0015], [122485000.0, 0.0034], [122446000.0, 0.0036], [122444000.0, 0.0], [122440000.0, 0.0206], [122429000.0, 0.0001], [122427000.0, 0.0026], [122425000.0, 0.003]], "asks": [[122492000.0, 0.0012], [122494000.0, 0.0008], [122495000.0, 0.0001], [122497000.0, 0.0096], [122499000.0, 0.0037], [122500000.0, 0.0338], [122502000.0, 0.0196], [122504000.0, 0.0002], [122505000.0, 0.0081], [122506000.0, 0.0678]]},
{"timestamp": "1743771452644", "bids": [[122491000.0, 0.0202], [122487000.0, 0.0007], [122486000.0, 0.0015], [122485000.0, 0.0034], [122446000.0, 0.0036], [122444000.0, 0.0], [122440000.0, 0.0206], [122429000.0, 0.0001], [122427000.0, 0.0026], [122425000.0, 0.003]], "asks": [[122492000.0, 0.0012], [122494000.0, 0.0008], [122495000.0, 0.0001], [122497000.0, 0.0096], [122499000.0, 0.0037], [122500000.0, 0.0338], [122502000.0, 0.0196], [122504000.0, 0.0002], [122505000.0, 0.0081], [122506000.0, 0.0678]]},
{"timestamp": "1743771453148", "bids": [[122491000.0, 0.0202], [122487000.0, 0.0007], [122486000.0, 0.0015], [122485000.0, 0.0034], [122446000.0, 0.0036], [122444000.0, 0.0], [122440000.0, 0.0206], [122429000.0, 0.0001], [122427000.0, 0.0026], [122425000.0, 0.003]], "asks": [[122492000.0, 0.0012], [122494000.0, 0.0008], [122495000.0, 0.0001], [122497000.0, 0.0096], [122499000.0, 0.0037], [122500000.0, 0.0338], [122502000.0, 0.0196], [122504000.0, 0.0002], [122505000.0, 0.0081], [122506000.0, 0.0678]]},
{"timestamp": "1743771453650", "bids": [[122491000.0, 0.0202], [122487000.0, 0.0007], [122486000.0, 0.0015], [122485000.0, 0.0034], [122446000.0, 0.0036], [122444000.0, 0.0], [122440000.0, 0.0206], [122429000.0, 0.0001], [122427000.0, 0.0026], [122425000.0, 0.003]], "asks": [[122492000.0, 0.0012], [122494000.0, 0.0008], [122495000.0, 0.0001], [122497000.0, 0.0096], [122499000.0, 0.0037], [122500000.0, 0.0338], [122502000.0, 0.0196], [122504000.0, 0.0002], [122505000.0, 0.0081], [122506000.0, 0.0678]]},
{"timestamp": "1743771454150", "bids": [[122491000.0, 0.0202], [122487000.0, 0.0007], [122486000.0, 0.0015], [122485000.0, 0.0034], [122446000.0, 0.0036], [122444000.0, 0.0], [122440000.0, 0.0206], [122429000.0, 0.0001], [122427000.0, 0.0026], [122425000.0, 0.003]], "asks": [[122492000.0, 0.0012], [122494000.0, 0.0008], [122495000.0, 0.0001], [122497000.0, 0.0096], [122499000.0, 0.0037], [122500000.0, 0.0338], [122502000.0, 0.0196], [122504000.0, 0.0002], [122505000.0, 0.0081], [122506000.0, 0.0678]]},
{"timestamp": "1743771454645", "bids": [[122491000.0, 0.1503], [122487000.0, 0.0007], [122486000.0, 0.0015], [122485000.0, 0.0034], [122446000.0, 0.0036], [122444000.0, 0.0], [122440000.0, 0.0088], [122429000.0, 0.0001], [122427000.0, 0.0026], [122425000.0, 0.003]], "asks": [[122492000.0, 0.0012], [122494000.0, 0.0008], [122495000.0, 0.0001], [122497000.0, 0.0096], [122499000.0, 0.0037], [122500000.0, 0.0338], [122502000.0, 0.0196], [122504000.0, 0.0002], [122505000.0, 0.0081], [122506000.0, 0.021]]},
{"timestamp": "1743771455145", "bids": [[122491000.0, 0.1503], [122487000.0, 0.0007], [122486000.0, 0.0015], [122485000.0, 0.0034], [122475000.0, 0.0029], [122446000.0, 0.0036], [122444000.0, 0.0], [122441000.0, 0.0839], [122440000.0, 0.0088], [122429000.0, 0.0001]], "asks": [[122492000.0, 0.0012], [122494000.0, 0.0008], [122495000.0, 0.0001], [122497000.0, 0.0096], [122499000.0, 0.0037], [122500000.0, 0.0338], [122502000.0, 0.0], [122504000.0, 0.0002], [122505000.0, 0.0081], [122506000.0, 0.0013]]},
{"timestamp": "1743771455659", "bids": [[122491000.0, 0.0531], [122487000.0, 0.0007], [122486000.0, 0.0015], [122485000.0, 0.0034], [122475000.0, 0.0029], [122446000.0, 0.0037], [122444000.0, 0.0], [122441000.0, 0.0839], [122430000.0, 0.0248], [122429000.0, 0.0001]], "asks": [[122492000.0, 0.0012], [122494000.0, 0.0008], [122495000.0, 0.0001], [122497000.0, 0.0096], [122499000.0, 0.0037], [122500000.0, 0.0338], [122502000.0, 0.0], [122504000.0, 0.0002], [122505000.0, 0.0081], [122506000.0, 0.0013]]},
{"timestamp": "1743771456144", "bids": [[122491000.0, 0.0532], [122487000.0, 0.0007], [122486000.0, 0.0015], [122485000.0, 0.0034], [122475000.0, 0.0029], [122446000.0, 0.0037], [122444000.0, 0.0], [122443000.0, 0.0112], [122436000.0, 0.0001], [122430000.0, 0.0248]], "asks": [[122492000.0, 0.0012], [122494000.0, 0.0008], [122495000.0, 0.0001], [122497000.0, 0.0096], [122499000.0, 0.0037], [122500000.0, 0.0338], [122502000.0, 0.0], [122504000.0, 0.0002], [122505000.0, 0.0081], [122506000.0, 0.0013]]},
{"timestamp": "1743771456646", "bids": [[122491000.0, 0.0177], [122487000.0, 0.0007], [122486000.0, 0.0015], [122485000.0, 0.0034], [122475000.0, 0.0029], [122465000.0, 0.0026], [122458000.0, 0.0001], [122455000.0, 0.0116], [122446000.0, 0.0037], [122444000.0, 0.0887]], "asks": [[122492000.0, 0.0012], [122494000.0, 0.0008], [122495000.0, 0.0001], [122497000.0, 0.0096], [122499000.0, 0.0037], [122500000.0, 0.0338], [122502000.0, 0.0], [122504000.0, 0.0002], [122505000.0, 0.0081], [122506000.0, 0.0013]]},
{"timestamp": "1743771457145", "bids": [[122491000.0, 0.0177], [122487000.0, 0.0007], [122486000.0, 0.0015], [122485000.0, 0.0034], [122475000.0, 0.0029], [122458000.0, 0.0001], [122455000.0, 0.0116], [122446000.0, 0.0037], [122444000.0, 0.0048], [122443000.0, 0.0112]], "asks": [[122492000.0, 0.0012], [122494000.0, 0.0008], [122495000.0, 0.0001], [122497000.0, 0.0096], [122499000.0, 0.0037], [122500000.0, 0.0338], [122502000.0, 0.0], [122504000.0, 0.0002], [122505000.0, 0.0081], [122506000.0, 0.0013]]},
{"timestamp": "1743771457860", "bids": [[122491000.0, 0.0177], [122487000.0, 0.0007], [122486000.0, 0.0015], [122485000.0, 0.0034], [122475000.0, 0.0029], [122472000.0, 0.0026], [122465000.0, 0.0226], [122456000.0, 0.0839], [122455000.0, 0.0116], [122446000.0, 0.0036]], "asks": [[122492000.0, 0.0012], [122494000.0, 0.0008], [122495000.0, 0.0001], [122497000.0, 0.0096], [122499000.0, 0.0037], [122500000.0, 0.0338], [122502000.0, 0.0], [122504000.0, 0.0002], [122505000.0, 0.0081], [122506000.0, 0.0013]]},
{"timestamp": "1743771458154", "bids": [[122491000.0, 0.0177], [122487000.0, 0.0007], [122486000.0, 0.0015], [122485000.0, 0.0034], [122475000.0, 0.0029], [122472000.0, 0.0026], [122471000.0, 0.0074], [122466000.0, 0.0001], [122465000.0, 0.0226], [122455000.0, 0.0116]], "asks": [[122492000.0, 0.0012], [122494000.0, 0.0008], [122495000.0, 0.0001], [122497000.0, 0.0096], [122499000.0, 0.0037], [122500000.0, 0.0338], [122502000.0, 0.0], [122504000.0, 0.0002], [122505000.0, 0.0081], [122506000.0, 0.0013]]},
{"timestamp": "1743771458646", "bids": [[122491000.0, 0.0177], [122487000.0, 0.0007], [122486000.0, 0.0015], [122485000.0, 0.0034], [122475000.0, 0.0029], [122471000.0, 0.0074], [122466000.0, 0.0001], [122455000.0, 0.0116], [122450000.0, 0.0001], [122446000.0, 0.0036]], "asks": [[122492000.0, 0.0011], [122494000.0, 0.0008], [122495000.0, 0.0001], [122497000.0, 0.0096], [122499000.0, 0.0037], [122500000.0, 0.0338], [122502000.0, 0.0], [122504000.0, 0.0002], [122505000.0, 0.0081], [122506000.0, 0.0013]]},
{"timestamp": "1743771459147", "bids": [[122491000.0, 0.0177], [122487000.0, 0.0007], [122486000.0, 0.0015], [122485000.0, 0.0034], [122475000.0, 0.0029], [122471000.0, 0.0074], [122468000.0, 0.0026], [122466000.0, 0.0001], [122463000.0, 0.0112], [122455000.0, 0.0116]], "asks": [[122492000.0, 0.0011], [122494000.0, 0.0008], [122495000.0, 0.0001], [122497000.0, 0.0096], [122499000.0, 0.0037], [122500000.0, 0.0338], [122502000.0, 0.0], [122504000.0, 0.0002], [122505000.0, 0.0081], [122506000.0, 0.0013]]},
{"timestamp": "1743771459646", "bids": [[122491000.0, 0.0182], [122487000.0, 0.0007], [122486000.0, 0.0015], [122485000.0, 0.0034], [122475000.0, 0.0029], [122471000.0, 0.0074], [122468000.0, 0.0026], [122466000.0, 0.0001], [122463000.0, 0.0112], [122455000.0, 0.0116]], "asks": [[122492000.0, 0.0011], [122494000.0, 0.0008], [122495000.0, 0.0001], [122497000.0, 0.0096], [122499000.0, 0.0037], [122500000.0, 0.0338], [122502000.0, 0.0], [122504000.0, 0.0002], [122505000.0, 0.0081], [122506000.0, 0.0013]]},
{"timestamp": "1743771460146", "bids": [[122491000.0, 0.0182], [122487000.0, 0.0007], [122486000.0, 0.0015], [122485000.0, 0.0034], [122475000.0, 0.0029], [122471000.0, 0.0074], [122468000.0, 0.0026], [122466000.0, 0.0001], [122463000.0, 0.0112], [122455000.0, 0.0116]], "asks": [[122492000.0, 0.0011], [122494000.0, 0.0008], [122495000.0, 0.0001], [122497000.0, 0.0096], [122499000.0, 0.0037], [122500000.0, 0.0338], [122502000.0, 0.0], [122504000.0, 0.0002], [122505000.0, 0.0081], [122506000.0, 0.0013]]},
{"timestamp": "1743771460651", "bids": [[122491000.0, 0.1746], [122487000.0, 0.0007], [122486000.0, 0.0015], [122485000.0, 0.0034], [122475000.0, 0.0029], [122471000.0, 0.0074], [122468000.0, 0.0026], [122466000.0, 0.0001], [122463000.0, 0.0112], [122455000.0, 0.0116]], "asks": [[122492000.0, 0.001], [122494000.0, 0.0008], [122495000.0, 0.0001], [122497000.0, 0.0096], [122499000.0, 0.0037], [122500000.0, 0.0338], [122502000.0, 0.0], [122504000.0, 0.0002], [122505000.0, 0.0081], [122506000.0, 0.0013]]},
{"timestamp": "1743771461144", "bids": [[122491000.0, 0.0757], [122487000.0, 0.0007], [122486000.0, 0.0015], [122485000.0, 0.0034], [122475000.0, 0.0029], [122471000.0, 0.0074], [122468000.0, 0.0026], [122466000.0, 0.0001], [122463000.0, 0.0112], [122450000.0, 0.0001]], "asks": [[122492000.0, 0.0013], [122494000.0, 0.0008], [122495000.0, 0.0001], [122497000.0, 0.0096], [122499000.0, 0.0037], [122500000.0, 0.0338], [122502000.0, 0.0], [122504000.0, 0.0002], [122505000.0, 0.0081], [122506000.0, 0.0013]]},
{"timestamp": "1743771461645", "bids": [[122487000.0, 0.0007], [122486000.0, 0.0015], [122485000.0, 0.0034], [122475000.0, 0.0029], [122471000.0, 0.0074], [122466000.0, 0.0001], [122463000.0, 0.0112], [122450000.0, 0.0001], [122446000.0, 0.0036], [122444000.0, 0.0]], "asks": [[122492000.0, 0.0209], [122494000.0, 0.0008], [122495000.0, 0.0001], [122497000.0, 0.0096], [122499000.0, 0.0037], [122500000.0, 0.0338], [122502000.0, 0.0], [122504000.0, 0.0002], [122505000.0, 0.0081], [122506000.0, 0.0013]]},
{"timestamp": "1743771462148", "bids": [[122487000.0, 0.0007], [122486000.0, 0.0015], [122485000.0, 0.0034], [122475000.0, 0.0029], [122461000.0, 0.0226], [122446000.0, 0.0036], [122444000.0, 0.0], [122438000.0, 0.0061], [122431000.0, 0.0362], [122429000.0, 0.0001]], "asks": [[122492000.0, 0.0269], [122494000.0, 0.0008], [122495000.0, 0.0001], [122497000.0, 0.0096], [122499000.0, 0.0037], [122500000.0, 0.0338], [122502000.0, 0.0], [122504000.0, 0.0002], [122505000.0, 0.0081], [122506000.0, 0.0013]]},
{"timestamp": "1743771462650", "bids": [[122491000.0, 0.0152], [122488000.0, 0.0786], [122487000.0, 0.0007], [122486000.0, 0.0015], [122485000.0, 0.0034], [122475000.0, 0.0029], [122461000.0, 0.0226], [122451000.0, 0.0026], [122446000.0, 0.0036], [122444000.0, 0.0]], "asks": [[122492000.0, 0.0071], [122494000.0, 0.0008], [122495000.0, 0.0001], [122497000.0, 0.0096], [122499000.0, 0.0037], [122500000.0, 0.0338], [122502000.0, 0.0], [122504000.0, 0.0002], [122505000.0, 0.0081], [122506000.0, 0.0013]]},
{"timestamp": "1743771463147", "bids": [[122491000.0, 0.0023], [122487000.0, 0.0007], [122486000.0, 0.0015], [122485000.0, 0.0034], [122475000.0, 0.0029], [122461000.0, 0.0226], [122451000.0, 0.0026], [122446000.0, 0.0036], [122444000.0, 0.0], [122441000.0, 0.0071]], "asks": [[122492000.0, 0.001], [122494000.0, 0.0008], [122495000.0, 0.0001], [122497000.0, 0.0096], [122499000.0, 0.0037], [122500000.0, 0.0338], [122502000.0, 0.0], [122504000.0, 0.0002], [122505000.0, 0.0081], [122506000.0, 0.0013]]},
{"timestamp": "1743771463653", "bids": [[122494000.0, 0.0017], [122491000.0, 0.0023], [122487000.0, 0.0007], [122486000.0, 0.0015], [122485000.0, 0.0034], [122475000.0, 0.0029], [122461000.0, 0.0226], [122451000.0, 0.0026], [122446000.0, 0.0036], [122444000.0, 0.0]], "asks": [[122495000.0, 0.0001], [122497000.0, 0.0096], [122499000.0, 0.0037], [122500000.0, 0.0338], [122502000.0, 0.0], [122504000.0, 0.0002], [122505000.0, 0.0081], [122506000.0, 0.0013], [122507000.0, 0.0053], [122508000.0, 0.0]]},
{"timestamp": "1743771464163", "bids": [[122494000.0, 0.0017], [122491000.0, 0.0027], [122487000.0, 0.0007], [122486000.0, 0.0015], [122485000.0, 0.0034], [122475000.0, 0.0029], [122451000.0, 0.0039], [122446000.0, 0.0036], [122444000.0, 0.0], [122442000.0, 0.0841]], "asks": [[122495000.0, 0.0001], [122497000.0, 0.0096], [122499000.0, 0.0037], [122500000.0, 0.0338], [122502000.0, 0.0], [122504000.0, 0.0002], [122505000.0, 0.0081], [122506000.0, 0.0013], [122507000.0, 0.0053], [122508000.0, 0.0]]},
{"timestamp": "1743771464651", "bids": [[122494000.0, 0.1521], [122491000.0, 0.0027], [122487000.0, 0.0007], [122486000.0, 0.0015], [122485000.0, 0.0034], [122475000.0, 0.0029], [122462000.0, 0.0841], [122455000.0, 0.0], [122454000.0, 0.0074], [122451000.0, 0.0013]], "asks": [[122495000.0, 0.0001], [122497000.0, 0.0096], [122499000.0, 0.0037], [122500000.0, 0.0338], [122502000.0, 0.0], [122504000.0, 0.0002], [122505000.0, 0.0081], [122506000.0, 0.0013], [122507000.0, 0.0053], [122508000.0, 0.0]]},
{"timestamp": "1743771465151", "bids": [[122494000.0, 0.0017], [122491000.0, 0.0023], [122487000.0, 0.0007], [122486000.0, 0.0015], [122485000.0, 0.0034], [122475000.0, 0.0029], [122462000.0, 0.1067], [122455000.0, 0.0], [122454000.0, 0.0074], [122451000.0, 0.0013]], "asks": [[122495000.0, 0.0001], [122497000.0, 0.0096], [122499000.0, 0.0037], [122500000.0, 0.0338], [122502000.0, 0.0], [122504000.0, 0.0002], [122505000.0, 0.0081], [122506000.0, 0.0013], [122507000.0, 0.0053], [122508000.0, 0.0]]},
{"timestamp": "1743771465650", "bids": [[122494000.0, 0.0017], [122491000.0, 0.0023], [122487000.0, 0.0007], [122486000.0, 0.0015], [122485000.0, 0.0034], [122475000.0, 0.0029], [122468000.0, 0.0026], [122462000.0, 0.0226], [122455000.0, 0.0], [122454000.0, 0.0074]], "asks": [[122495000.0, 0.0001], [122497000.0, 0.0096], [122499000.0, 0.0037], [122500000.0, 0.0338], [122502000.0, 0.0], [122504000.0, 0.0002], [122505000.0, 0.0081], [122506000.0, 0.0013], [122507000.0, 0.0053], [122508000.0, 0.0]]},
{"timestamp": "1743771466148", "bids": [[122494000.0, 0.0017], [122491000.0, 0.0023], [122487000.0, 0.0007], [122486000.0, 0.0015], [122485000.0, 0.0034], [122475000.0, 0.0029], [122468000.0, 0.0026], [122462000.0, 0.0226], [122455000.0, 0.0], [122454000.0, 0.0074]], "asks": [[122495000.0, 0.0001], [122497000.0, 0.0096], [122499000.0, 0.0037], [122500000.0, 0.0338], [122502000.0, 0.0], [122504000.0, 0.0002], [122505000.0, 0.0081], [122506000.0, 0.0013], [122507000.0, 0.0053], [122508000.0, 0.0]]},
{"timestamp": "1743771466656", "bids": [[122494000.0, 0.0017], [122491000.0, 0.0023], [122487000.0, 0.0007], [122486000.0, 0.0015], [122485000.0, 0.0034], [122475000.0, 0.0029], [122468000.0, 0.0026], [122462000.0, 0.0226], [122455000.0, 0.0], [122454000.0, 0.0074]], "asks": [[122495000.0, 0.0001], [122497000.0, 0.0096], [122499000.0, 0.0037], [122500000.0, 0.0338], [122502000.0, 0.0], [122504000.0, 0.0002], [122505000.0, 0.0081], [122506000.0, 0.0013], [122507000.0, 0.0053], [122508000.0, 0.0]]},
{"timestamp": "1743771467150", "bids": [[122494000.0, 0.0017], [122492000.0, 0.0], [122491000.0, 0.0023], [122487000.0, 0.0007], [122486000.0, 0.0015], [122485000.0, 0.0034], [122475000.0, 0.0029], [122468000.0, 0.0026], [122462000.0, 0.0226], [122455000.0, 0.0]], "asks": [[122495000.0, 0.0001], [122497000.0, 0.0096], [122499000.0, 0.0037], [122500000.0, 0.0338], [122502000.0, 0.0], [122504000.0, 0.0002], [122505000.0, 0.0081], [122506000.0, 0.0013], [122507000.0, 0.0053], [122508000.0, 0.0]]},
{"timestamp": "1743771467647", "bids": [[122494000.0, 0.0017], [122492000.0, 0.0], [122491000.0, 0.0023], [122487000.0, 0.0007], [122486000.0, 0.0015], [122485000.0, 0.0034], [122475000.0, 0.0029], [122468000.0, 0.0026], [122462000.0, 0.0226], [122455000.0, 0.0]], "asks": [[122497000.0, 0.0094], [122499000.0, 0.0037], [122500000.0, 0.0338], [122502000.0, 0.0], [122504000.0, 0.0002], [122505000.0, 0.0081], [122506000.0, 0.0013], [122507000.0, 0.0053], [122508000.0, 0.0], [122509000.0, 0.0016]]},
{"timestamp": "1743771468146", "bids": [[122494000.0, 0.0017], [122492000.0, 0.0], [122491000.0, 0.0023], [122487000.0, 0.0007], [122486000.0, 0.0015], [122485000.0, 0.0034], [122475000.0, 0.0029], [122468000.0, 0.0026], [122462000.0, 0.0226], [122455000.0, 0.0]], "asks": [[122497000.0, 0.0094], [122499000.0, 0.0037], [122500000.0, 0.0338], [122502000.0, 0.0], [122504000.0, 0.0002], [122505000.0, 0.0081], [122506000.0, 0.0013], [122507000.0, 0.0053], [122508000.0, 0.0], [122509000.0, 0.0016]]},
{"timestamp": "1743771468646", "bids": [[122494000.0, 0.0017], [122492000.0, 0.0], [122491000.0, 0.0023], [122487000.0, 0.0007], [122486000.0, 0.0015], [122485000.0, 0.0034], [122475000.0, 0.0029], [122468000.0, 0.0026], [122455000.0, 0.0], [122454000.0, 0.0074]], "asks": [[122496000.0, 0.006], [122497000.0, 0.0094], [122499000.0, 0.0037], [122500000.0, 0.0338], [122502000.0, 0.0], [122504000.0, 0.0002], [122505000.0, 0.0081], [122506000.0, 0.0013], [122507000.0, 0.0053], [122508000.0, 0.0]]},
{"timestamp": "1743771469149", "bids": [[122494000.0, 0.0017], [122492000.0, 0.0], [122491000.0, 0.0023], [122487000.0, 0.0007], [122486000.0, 0.0015], [122485000.0, 0.0034], [122475000.0, 0.0029], [122467000.0, 0.0001], [122455000.0, 0.0], [122446000.0, 0.0036]], "asks": [[122496000.0, 0.0256], [122497000.0, 0.0094], [122499000.0, 0.0037], [122500000.0, 0.0338], [122502000.0, 0.0], [122504000.0, 0.0002], [122505000.0, 0.0081], [122506000.0, 0.0013], [122507000.0, 0.0053], [122508000.0, 0.0]]},
{"timestamp": "1743771469657", "bids": [[122494000.0, 0.0017], [122492000.0, 0.0], [122491000.0, 0.0023], [122487000.0, 0.0007], [122486000.0, 0.0015], [122485000.0, 0.0034], [122475000.0, 0.0029], [122467000.0, 0.0001], [122455000.0, 0.0], [122451000.0, 0.0026]], "asks": [[122497000.0, 0.0094], [122499000.0, 0.0037], [122500000.0, 0.0338], [122502000.0, 0.0], [122504000.0, 0.0002], [122505000.0, 0.0081], [122506000.0, 0.0013], [122507000.0, 0.0053], [122508000.0, 0.0], [122509000.0, 0.0016]]},
{"timestamp": "1743771470157", "bids": [[122494000.0, 0.0017], [122492000.0, 0.0], [122491000.0, 0.0023], [122487000.0, 0.0007], [122486000.0, 0.0015], [122485000.0, 0.0034], [122475000.0, 0.0029], [122467000.0, 0.0001], [122455000.0, 0.0], [122451000.0, 0.0026]], "asks": [[122497000.0, 0.0094], [122499000.0, 0.0037], [122500000.0, 0.0338], [122502000.0, 0.0], [122504000.0, 0.0002], [122505000.0, 0.0081], [122506000.0, 0.0013], [122507000.0, 0.0053], [122508000.0, 0.0], [122509000.0, 0.0016]]},
{"timestamp": "1743771470648", "bids": [[122494000.0, 0.0017], [122492000.0, 0.0], [122491000.0, 0.0023], [122487000.0, 0.0007], [122486000.0, 0.0015], [122485000.0, 0.0034], [122475000.0, 0.0029], [122467000.0, 0.0001], [122455000.0, 0.0], [122451000.0, 0.0026]], "asks": [[122497000.0, 0.0094], [122499000.0, 0.0037], [122500000.0, 0.0338], [122502000.0, 0.0], [122504000.0, 0.0002], [122505000.0, 0.0081], [122506000.0, 0.0013], [122507000.0, 0.0053], [122508000.0, 0.0], [122509000.0, 0.0016]]},
{"timestamp": "1743771471149", "bids": [[122495000.0, 0.1605], [122494000.0, 0.0017], [122492000.0, 0.0], [122491000.0, 0.0023], [122487000.0, 0.0007], [122486000.0, 0.0015], [122485000.0, 0.0034], [122475000.0, 0.0029], [122455000.0, 0.0], [122451000.0, 0.0026]], "asks": [[122497000.0, 0.0093], [122499000.0, 0.0037], [122500000.0, 0.0338], [122502000.0, 0.0], [122504000.0, 0.0002], [122505000.0, 0.0081], [122506000.0, 0.0013], [122507000.0, 0.0053], [122508000.0, 0.0], [122509000.0, 0.0016]]},
{"timestamp": "1743771471649", "bids": [[122495000.0, 0.0102], [122494000.0, 0.0017], [122492000.0, 0.0], [122491000.0, 0.0023], [122487000.0, 0.0007], [122486000.0, 0.0015], [122485000.0, 0.0034], [122475000.0, 0.0029], [122455000.0, 0.0], [122451000.0, 0.0026]], "asks": [[122497000.0, 0.0093], [122499000.0, 0.0037], [122500000.0, 0.0338], [122502000.0, 0.0], [122504000.0, 0.0002], [122505000.0, 0.0081], [122506000.0, 0.0013], [122507000.0, 0.0053], [122508000.0, 0.0], [122509000.0, 0.0016]]},
{"timestamp": "1743771472151", "bids": [[122495000.0, 0.0096], [122494000.0, 0.0017], [122492000.0, 0.0], [122491000.0, 0.0023], [122487000.0, 0.0007], [122486000.0, 0.0015], [122485000.0, 0.0034], [122475000.0, 0.0029], [122455000.0, 0.0], [122451000.0, 0.0026]], "asks": [[122497000.0, 0.0093], [122499000.0, 0.0037], [122500000.0, 0.0338], [122502000.0, 0.0], [122504000.0, 0.0002], [122505000.0, 0.0081], [122506000.0, 0.0013], [122507000.0, 0.0053], [122508000.0, 0.0], [122509000.0, 0.0016]]},
{"timestamp": "1743771472647", "bids": [[122495000.0, 0.0096], [122494000.0, 0.0017], [122492000.0, 0.0], [122491000.0, 0.0023], [122487000.0, 0.0007], [122486000.0, 0.0015], [122485000.0, 0.0034], [122475000.0, 0.0029], [122455000.0, 0.0], [122451000.0, 0.0026]], "asks": [[122497000.0, 0.0093], [122499000.0, 0.0037], [122500000.0, 0.0338], [122502000.0, 0.0], [122504000.0, 0.0002], [122505000.0, 0.0081], [122506000.0, 0.0013], [122507000.0, 0.0053], [122508000.0, 0.0], [122509000.0, 0.0016]]},
{"timestamp": "1743771473147", "bids": [[122495000.0, 0.0096], [122494000.0, 0.0017], [122492000.0, 0.0], [122491000.0, 0.0023], [122487000.0, 0.0007], [122486000.0, 0.0015], [122485000.0, 0.0034], [122475000.0, 0.0029], [122455000.0, 0.0], [122451000.0, 0.0026]], "asks": [[122497000.0, 0.0093], [122499000.0, 0.0037], [122500000.0, 0.0338], [122502000.0, 0.0], [122504000.0, 0.0002], [122505000.0, 0.0081], [122506000.0, 0.0013], [122507000.0, 0.0053], [122508000.0, 0.0], [122509000.0, 0.0016]]},
{"timestamp": "1743771473650", "bids": [[122495000.0, 0.0096], [122494000.0, 0.0017], [122492000.0, 0.0], [122491000.0, 0.0023], [122487000.0, 0.0007], [122486000.0, 0.0015], [122485000.0, 0.0034], [122475000.0, 0.0029], [122455000.0, 0.0], [122453000.0, 0.0096]], "asks": [[122497000.0, 0.0093], [122499000.0, 0.0037], [122500000.0, 0.0338], [122502000.0, 0.0], [122504000.0, 0.0002], [122505000.0, 0.0081], [122506000.0, 0.0013], [122507000.0, 0.0053], [122508000.0, 0.0], [122509000.0, 0.0016]]},
{"timestamp": "1743771474152", "bids": [[122495000.0, 0.0096], [122494000.0, 0.0017], [122492000.0, 0.0], [122491000.0, 0.0023], [122487000.0, 0.0007], [122486000.0, 0.0015], [122485000.0, 0.0034], [122475000.0, 0.0029], [122455000.0, 0.0074], [122453000.0, 0.0096]], "asks": [[122497000.0, 0.0093], [122499000.0, 0.0037], [122500000.0, 0.0338], [122502000.0, 0.0], [122504000.0, 0.0002], [122505000.0, 0.0081], [122506000.0, 0.0013], [122507000.0, 0.0053], [122508000.0, 0.0], [122509000.0, 0.0016]]},
{"timestamp": "1743771474648", "bids": [[122495000.0, 0.0096], [122494000.0, 0.0017], [122492000.0, 0.0], [122491000.0, 0.0023], [122487000.0, 0.0007], [122486000.0, 0.0015], [122485000.0, 0.0034], [122475000.0, 0.0029], [122464000.0, 0.0026], [122458000.0, 0.0226]], "asks": [[122496000.0, 0.0057], [122497000.0, 0.0093], [122499000.0, 0.0037], [122500000.0, 0.0338], [122502000.0, 0.0], [122504000.0, 0.0002], [122505000.0, 0.0081], [122506000.0, 0.0013], [122507000.0, 0.0053], [122508000.0, 0.0]]},
{"timestamp": "1743771475150", "bids": [[122495000.0, 0.0096], [122494000.0, 0.0017], [122492000.0, 0.0], [122491000.0, 0.0023], [122487000.0, 0.0007], [122486000.0, 0.0015], [122485000.0, 0.0034], [122475000.0, 0.0029], [122464000.0, 0.0026], [122455000.0, 0.0074]], "asks": [[122497000.0, 0.0093], [122499000.0, 0.0037], [122500000.0, 0.0338], [122502000.0, 0.0], [122504000.0, 0.0002], [122505000.0, 0.0081], [122506000.0, 0.0013], [122507000.0, 0.0053], [122508000.0, 0.0], [122509000.0, 0.0016]]},
{"timestamp": "1743771475650", "bids": [[122495000.0, 0.0096], [122494000.0, 0.0017], [122492000.0, 0.0], [122491000.0, 0.0023], [122487000.0, 0.0007], [122486000.0, 0.0015], [122485000.0, 0.0034], [122475000.0, 0.0029], [122455000.0, 0.0], [122453000.0, 0.0096]], "asks": [[122497000.0, 0.0093], [122499000.0, 0.0037], [122500000.0, 0.0338], [122502000.0, 0.0], [122504000.0, 0.0002], [122505000.0, 0.0081], [122506000.0, 0.0013], [122507000.0, 0.0053], [122508000.0, 0.0], [122509000.0, 0.0016]]},
{"timestamp": "1743771476160", "bids": [[122475000.0, 0.0029], [122455000.0, 0.0], [122453000.0, 0.0096], [122446000.0, 0.0036], [122444000.0, 0.0], [122440000.0, 0.1069], [122429000.0, 0.0001], [122425000.0, 0.003], [122421000.0, 0.0329], [122420000.0, 0.0]], "asks": [[122481000.0, 0.2463], [122489000.0, 0.0001], [122496000.0, 0.0254], [122497000.0, 0.0093], [122499000.0, 0.0037], [122500000.0, 0.0338], [122502000.0, 0.0], [122504000.0, 0.0002], [122505000.0, 0.0081], [122506000.0, 0.0013]]},
{"timestamp": "1743771476652", "bids": [[122455000.0, 0.0], [122453000.0, 0.0096], [122446000.0, 0.0036], [122444000.0, 0.0], [122440000.0, 0.0843], [122430000.0, 0.0001], [122429000.0, 0.0001], [122425000.0, 0.003], [122421000.0, 0.0329], [122420000.0, 0.0]], "asks": [[122481000.0, 0.2463], [122483000.0, 0.0197], [122489000.0, 0.0001], [122492000.0, 0.0144], [122494000.0, 0.0113], [122496000.0, 0.0254], [122497000.0, 0.0093], [122499000.0, 0.0037], [122500000.0, 0.0338], [122502000.0, 0.0]]},
{"timestamp": "1743771477157", "bids": [[122455000.0, 0.0], [122453000.0, 0.0096], [122446000.0, 0.0036], [122444000.0, 0.0], [122430000.0, 0.0001], [122429000.0, 0.0001], [122425000.0, 0.003], [122420000.0, 0.0], [122419000.0, 0.0325], [122417000.0, 0.0843]], "asks": [[122467000.0, 0.0246], [122483000.0, 0.0325], [122489000.0, 0.0002], [122492000.0, 0.0144], [122494000.0, 0.0113], [122497000.0, 0.0259], [122499000.0, 0.0037], [122500000.0, 0.0338], [122502000.0, 0.0251], [122504000.0, 0.0002]]},
{"timestamp": "1743771477649", "bids": [[122444000.0, 0.0], [122430000.0, 0.0001], [122429000.0, 0.0001], [122425000.0, 0.003], [122420000.0, 0.0], [122415000.0, 0.0036], [122414000.0, 0.0074], [122410000.0, 0.0061], [122407000.0, 0.0], [122404000.0, 0.0358]], "asks": [[122445000.0, 0.0183], [122466000.0, 0.0002], [122467000.0, 0.0246], [122480000.0, 0.0148], [122483000.0, 0.045], [122489000.0, 0.0002], [122492000.0, 0.0144], [122495000.0, 0.0003], [122497000.0, 0.0259], [122499000.0, 0.0037]]},
{"timestamp": "1743771478155", "bids": [[122444000.0, 0.0], [122429000.0, 0.0001], [122425000.0, 0.003], [122420000.0, 0.0], [122415000.0, 0.0036], [122414000.0, 0.0074], [122407000.0, 0.0], [122402000.0, 0.0], [122400000.0, 0.1], [122385000.0, 0.0016]], "asks": [[122445000.0, 0.0183], [122463000.0, 0.0173], [122466000.0, 0.0062], [122480000.0, 0.0148], [122482000.0, 0.1347], [122483000.0, 0.0322], [122484000.0, 0.0222], [122489000.0, 0.0002], [122490000.0, 0.0176], [122491000.0, 0.0167]]},
{"timestamp": "1743771478651", "bids": [[122429000.0, 0.0001], [122425000.0, 0.003], [122420000.0, 0.0], [122415000.0, 0.0036], [122407000.0, 0.0], [122402000.0, 0.0], [122400000.0, 0.1], [122387000.0, 0.0], [122385000.0, 0.0016], [122379000.0, 0.0226]], "asks": [[122440000.0, 0.0196], [122458000.0, 0.0268], [122459000.0, 0.0126], [122462000.0, 0.0791], [122463000.0, 0.0173], [122464000.0, 0.0271], [122466000.0, 0.0791], [122474000.0, 0.0182], [122477000.0, 0.0104], [122479000.0, 0.0185]]},
{"timestamp": "1743771479177", "bids": [[122429000.0, 0.0001], [122425000.0, 0.003], [122420000.0, 0.0], [122415000.0, 0.0036], [122407000.0, 0.0], [122402000.0, 0.0], [122400000.0, 0.1], [122387000.0, 0.0], [122385000.0, 0.0016], [122379000.0, 0.0226]], "asks": [[122440000.0, 0.0626], [122455000.0, 0.0], [122456000.0, 0.0128], [122458000.0, 0.0268], [122459000.0, 0.0126], [122462000.0, 0.0939], [122463000.0, 0.0173], [122464000.0, 0.0271], [122470000.0, 0.0166], [122474000.0, 0.0182]]},
{"timestamp": "1743771479647", "bids": [[122429000.0, 0.0001], [122425000.0, 0.003], [122420000.0, 0.0], [122415000.0, 0.0036], [122407000.0, 0.0], [122402000.0, 0.0], [122400000.0, 0.1], [122387000.0, 0.0], [122385000.0, 0.0016], [122379000.0, 0.0226]], "asks": [[122440000.0, 0.0577], [122455000.0, 0.0], [122456000.0, 0.0128], [122458000.0, 0.0268], [122459000.0, 0.0126], [122461000.0, 0.079], [122462000.0, 0.0148], [122463000.0, 0.0173], [122464000.0, 0.0271], [122470000.0, 0.0166]]},
{"timestamp": "1743771480148", "bids": [[122429000.0, 0.0001], [122425000.0, 0.003], [122420000.0, 0.0], [122415000.0, 0.0036], [122407000.0, 0.0], [122402000.0, 0.0], [122400000.0, 0.1], [122387000.0, 0.0], [122385000.0, 0.0016], [122379000.0, 0.0226]], "asks": [[122440000.0, 0.0577], [122455000.0, 0.0], [122456000.0, 0.0128], [122457000.0, 0.079], [122458000.0, 0.0268], [122459000.0, 0.0126], [122462000.0, 0.0148], [122463000.0, 0.0173], [122464000.0, 0.0271], [122470000.0, 0.0166]]},
{"timestamp": "1743771480649", "bids": [[122425000.0, 0.003], [122420000.0, 0.0], [122415000.0, 0.0036], [122407000.0, 0.0], [122402000.0, 0.0], [122400000.0, 0.1], [122387000.0, 0.0], [122385000.0, 0.0016], [122377000.0, 0.0002], [122375000.0, 0.0052]], "asks": [[122428000.0, 0.2463], [122439000.0, 0.0058], [122440000.0, 0.0147], [122455000.0, 0.0791], [122456000.0, 0.0128], [122458000.0, 0.0268], [122462000.0, 0.079], [122464000.0, 0.0271], [122470000.0, 0.0166], [122474000.0, 0.0182]]},
{"timestamp": "1743771481151", "bids": [[122425000.0, 0.003], [122420000.0, 0.0], [122415000.0, 0.0036], [122407000.0, 0.0], [122402000.0, 0.0], [122400000.0, 0.1], [122387000.0, 0.0], [122385000.0, 0.0016], [122377000.0, 0.0002], [122375000.0, 0.0052]], "asks": [[122428000.0, 0.2463], [122439000.0, 0.0058], [122448000.0, 0.0166], [122455000.0, 0.0791], [122456000.0, 0.0128], [122458000.0, 0.0124], [122459000.0, 0.0177], [122463000.0, 0.0831], [122473000.0, 0.0213], [122477000.0, 0.0104]]},
{"timestamp": "1743771481649", "bids": [[122415000.0, 0.0036], [122407000.0, 0.0], [122402000.0, 0.0], [122400000.0, 0.1], [122387000.0, 0.0], [122385000.0, 0.0016], [122377000.0, 0.0002], [122375000.0, 0.0052], [122372000.0, 0.0008], [122371000.0, 0.0]], "asks": [[122427000.0, 0.0177], [122429000.0, 0.0002], [122431000.0, 0.0168], [122433000.0, 0.0001], [122434000.0, 0.0114], [122436000.0, 0.0242], [122439000.0, 0.0058], [122448000.0, 0.0166], [122450000.0, 0.0171], [122454000.0, 0.0506]]},
{"timestamp": "1743771482151", "bids": [[122407000.0, 0.0], [122402000.0, 0.0], [122400000.0, 0.1], [122387000.0, 0.0], [122385000.0, 0.0016], [122377000.0, 0.0002], [122375000.0, 0.0052], [122372000.0, 0.0008], [122371000.0, 0.0], [122370000.0, 0.0]], "asks": [[122412000.0, 0.0209], [122424000.0, 0.0144], [122427000.0, 0.1524], [122429000.0, 0.0002], [122431000.0, 0.0168], [122433000.0, 0.0001], [122434000.0, 0.0114], [122435000.0, 0.0182], [122436000.0, 0.0242], [122437000.0, 0.0271]]},
{"timestamp": "1743771482648", "bids": [[122407000.0, 0.0], [122402000.0, 0.0], [122400000.0, 0.1], [122387000.0, 0.0], [122385000.0, 0.0016], [122377000.0, 0.0002], [122375000.0, 0.0052], [122372000.0, 0.0008], [122371000.0, 0.0], [122370000.0, 0.0]], "asks": [[122411000.0, 0.2521], [122412000.0, 0.0209], [122413000.0, 0.0173], [122419000.0, 0.2243], [122420000.0, 0.0147], [122423000.0, 0.0128], [122424000.0, 0.0144], [122427000.0, 0.1347], [122429000.0, 0.0002], [122431000.0, 0.0377]]},
{"timestamp": "1743771483152", "bids": [[122407000.0, 0.0], [122402000.0, 0.0], [122400000.0, 0.1], [122387000.0, 0.0], [122385000.0, 0.0016], [122377000.0, 0.0002], [122375000.0, 0.0052], [122372000.0, 0.0008], [122371000.0, 0.0], [122370000.0, 0.0]], "asks": [[122411000.0, 0.0849], [122413000.0, 0.0242], [122419000.0, 0.0896], [122423000.0, 0.0128], [122426000.0, 0.0166], [122427000.0, 0.1347], [122429000.0, 0.0002], [122435000.0, 0.0248], [122437000.0, 0.0166], [122441000.0, 0.0253]]},
{"timestamp": "1743771483656", "bids": [[122387000.0, 0.0], [122385000.0, 0.0016], [122377000.0, 0.0002], [122375000.0, 0.0052], [122372000.0, 0.0008], [122371000.0, 0.0], [122370000.0, 0.0], [122367000.0, 0.0], [122366000.0, 0.0025], [122363000.0, 0.0004]], "asks": [[122397000.0, 0.1461], [122413000.0, 0.0242], [122419000.0, 0.0104], [122426000.0, 0.0166], [122429000.0, 0.0252], [122431000.0, 0.0177], [122435000.0, 0.0849], [122441000.0, 0.0253], [122451000.0, 0.0168], [122452000.0, 0.0213]]},
{"timestamp": "1743771484158", "bids": [[122387000.0, 0.0], [122385000.0, 0.0016], [122377000.0, 0.0002], [122375000.0, 0.0052], [122372000.0, 0.0008], [122371000.0, 0.0], [122370000.0, 0.0], [122367000.0, 0.0], [122366000.0, 0.0025], [122363000.0, 0.0004]], "asks": [[122397000.0, 0.1461], [122408000.0, 0.0173], [122409000.0, 0.021], [122418000.0, 0.1346], [122419000.0, 0.0104], [122424000.0, 0.0144], [122426000.0, 0.0166], [122427000.0, 0.0182], [122429000.0, 0.0252], [122431000.0, 0.0547]]},
{"timestamp": "1743771484654", "bids": [[122387000.0, 0.0], [122385000.0, 0.0016], [122377000.0, 0.0002], [122375000.0, 0.0052], [122372000.0, 0.0008], [122371000.0, 0.0], [122370000.0, 0.0], [122367000.0, 0.0], [122366000.0, 0.0025], [122363000.0, 0.0004]], "asks": [[122396000.0, 0.0791], [122405000.0, 0.0168], [122407000.0, 0.0147], [122408000.0, 0.0483], [122409000.0, 0.021], [122412000.0, 0.0058], [122418000.0, 0.1346], [122419000.0, 0.0104], [122422000.0, 0.0791], [122424000.0, 0.0144]]},
{"timestamp": "1743771485155", "bids": [[122377000.0, 0.0002], [122375000.0, 0.0052], [122372000.0, 0.0008], [122371000.0, 0.0], [122370000.0, 0.0], [122367000.0, 0.0], [122366000.0, 0.0025], [122363000.0, 0.0004], [122360000.0, 0.0051], [122358000.0, 0.0001]], "asks": [[122396000.0, 0.0791], [122405000.0, 0.0168], [122407000.0, 0.0147], [122408000.0, 0.0483], [122409000.0, 0.0001], [122418000.0, 0.0126], [122419000.0, 0.0104], [122424000.0, 0.0271], [122426000.0, 0.0166], [122427000.0, 0.0182]]},
{"timestamp": "1743771485652", "bids": [[122378000.0, 0.0044], [122377000.0, 0.0002], [122375000.0, 0.0052], [122372000.0, 0.0008], [122371000.0, 0.0], [122370000.0, 0.0], [122367000.0, 0.0], [122366000.0, 0.0025], [122363000.0, 0.0004], [122360000.0, 0.0051]], "asks": [[122405000.0, 0.0168], [122407000.0, 0.0147], [122408000.0, 0.031], [122418000.0, 0.0927], [122419000.0, 0.0104], [122423000.0, 0.0144], [122424000.0, 0.0148], [122427000.0, 0.0182], [122428000.0, 0.0153], [122429000.0, 0.0126]]},
{"timestamp": "1743771486434", "bids": [[122378000.0, 0.0044], [122377000.0, 0.0002], [122375000.0, 0.0052], [122372000.0, 0.0008], [122371000.0, 0.0], [122370000.0, 0.0], [122367000.0, 0.0], [122366000.0, 0.0025], [122363000.0, 0.0004], [122360000.0, 0.0051]], "asks": [[122402000.0, 0.0001], [122405000.0, 0.0451], [122406000.0, 0.0173], [122408000.0, 0.0196], [122418000.0, 0.0799], [122423000.0, 0.0965], [122428000.0, 0.0177], [122429000.0, 0.0002], [122430000.0, 0.0222], [122432000.0, 0.0578]]},
{"timestamp": "1743771486656", "bids": [[122378000.0, 0.0044], [122377000.0, 0.0002], [122375000.0, 0.0052], [122372000.0, 0.0008], [122371000.0, 0.0], [122370000.0, 0.0], [122367000.0, 0.0], [122366000.0, 0.0025], [122363000.0, 0.0004], [122360000.0, 0.0051]], "asks": [[122402000.0, 0.0001], [122405000.0, 0.0209], [122406000.0, 0.0173], [122418000.0, 0.0799], [122423000.0, 0.0965], [122428000.0, 0.0177], [122429000.0, 0.0002], [122430000.0, 0.0222], [122432000.0, 0.0578], [122433000.0, 0.0253]]},
{"timestamp": "1743771487159", "bids": [[122378000.0, 0.0044], [122377000.0, 0.0002], [122375000.0, 0.0052], [122372000.0, 0.0008], [122371000.0, 0.0], [122370000.0, 0.0], [122367000.0, 0.0], [122366000.0, 0.0025], [122363000.0, 0.0004], [122360000.0, 0.0051]], "asks": [[122402000.0, 0.0001], [122406000.0, 0.0173], [122421000.0, 0.0168], [122423000.0, 0.1112], [122424000.0, 0.0114], [122428000.0, 0.0177], [122429000.0, 0.0002], [122430000.0, 0.0222], [122432000.0, 0.0578], [122433000.0, 0.0253]]},
{"timestamp": "1743771487659", "bids": [[122378000.0, 0.0044], [122377000.0, 0.0002], [122375000.0, 0.0052], [122372000.0, 0.0008], [122371000.0, 0.0], [122370000.0, 0.0], [122367000.0, 0.0], [122366000.0, 0.0025], [122363000.0, 0.0187], [122360000.0, 0.0051]], "asks": [[122421000.0, 0.0168], [122422000.0, 0.0799], [122423000.0, 0.0147], [122424000.0, 0.0114], [122429000.0, 0.0002], [122437000.0, 0.0182], [122438000.0, 0.0242], [122439000.0, 0.0128], [122440000.0, 0.0144], [122444000.0, 0.0444]]},
{"timestamp": "1743771488155", "bids": [[122378000.0, 0.0044], [122377000.0, 0.0002], [122375000.0, 0.0052], [122372000.0, 0.0008], [122371000.0, 0.0], [122370000.0, 0.0], [122367000.0, 0.0], [122366000.0, 0.0025], [122363000.0, 0.0187], [122360000.0, 0.0051]], "asks": [[122401000.0, 0.0058], [122422000.0, 0.0799], [122429000.0, 0.0002], [122431000.0, 0.0173], [122436000.0, 0.1568], [122438000.0, 0.0242], [122440000.0, 0.0144], [122441000.0, 0.0196], [122442000.0, 0.0126], [122445000.0, 0.014]]},
{"timestamp": "1743771488667", "bids": [[122377000.0, 0.0002], [122375000.0, 0.0052], [122372000.0, 0.0008], [122371000.0, 0.0], [122370000.0, 0.0], [122367000.0, 0.0], [122366000.0, 0.0025], [122363000.0, 0.0187], [122360000.0, 0.0051], [122358000.0, 0.0075]], "asks": [[122401000.0, 0.0058], [122420000.0, 0.0976], [122429000.0, 0.0002], [122431000.0, 0.0173], [122433000.0, 0.0001], [122436000.0, 0.1568], [122441000.0, 0.0196], [122442000.0, 0.0126], [122445000.0, 0.014], [122449000.0, 0.0166]]},
{"timestamp": "1743771489156", "bids": [[122377000.0, 0.0002], [122375000.0, 0.0052], [122372000.0, 0.0008], [122371000.0, 0.0], [122370000.0, 0.0], [122367000.0, 0.0], [122366000.0, 0.0025], [122363000.0, 0.0004], [122360000.0, 0.0051], [122358000.0, 0.0001]], "asks": [[122409000.0, 0.0114], [122419000.0, 0.0128], [122420000.0, 0.2335], [122423000.0, 0.0182], [122429000.0, 0.0184], [122430000.0, 0.0468], [122431000.0, 0.0173], [122433000.0, 0.0177], [122438000.0, 0.0164], [122439000.0, 0.017]]},
{"timestamp": "1743771489655", "bids": [[122377000.0, 0.0002], [122375000.0, 0.0052], [122372000.0, 0.0008], [122371000.0, 0.0], [122370000.0, 0.0], [122367000.0, 0.0], [122366000.0, 0.0025], [122363000.0, 0.0004], [122360000.0, 0.0051], [122358000.0, 0.0001]], "asks": [[122378000.0, 0.0002], [122401000.0, 0.0168], [122402000.0, 0.0389], [122409000.0, 0.0114], [122417000.0, 0.0144], [122418000.0, 0.0183], [122421000.0, 0.0171], [122423000.0, 0.0182], [122424000.0, 0.0271], [122426000.0, 0.0179]]},
{"timestamp": "1743771490154", "bids": [[122377000.0, 0.0034], [122375000.0, 0.0052], [122372000.0, 0.0008], [122371000.0, 0.0], [122370000.0, 0.0], [122367000.0, 0.0], [122366000.0, 0.0025], [122363000.0, 0.0004], [122360000.0, 0.0051], [122358000.0, 0.0001]], "asks": [[122378000.0, 0.0002], [122399000.0, 0.0209], [122401000.0, 0.0168], [122402000.0, 0.0389], [122409000.0, 0.0114], [122416000.0, 0.0128], [122417000.0, 0.0144], [122418000.0, 0.0126], [122420000.0, 0.1359], [122421000.0, 0.0319]]},
{"timestamp": "1743771490655", "bids": [[122377000.0, 0.0152], [122375000.0, 0.0052], [122372000.0, 0.0008], [122371000.0, 0.0], [122370000.0, 0.0], [122367000.0, 0.0], [122366000.0, 0.0025], [122363000.0, 0.0004], [122360000.0, 0.0051], [122358000.0, 0.0001]], "asks": [[122378000.0, 0.0002], [122399000.0, 0.0209], [122401000.0, 0.0168], [122402000.0, 0.0389], [122409000.0, 0.0114], [122416000.0, 0.1487], [122417000.0, 0.0144], [122418000.0, 0.0126], [122421000.0, 0.0319], [122423000.0, 0.0182]]},
{"timestamp": "1743771491152", "bids": [[122377000.0, 0.0152], [122375000.0, 0.0052], [122372000.0, 0.0008], [122371000.0, 0.0], [122370000.0, 0.0], [122367000.0, 0.0], [122366000.0, 0.0025], [122363000.0, 0.0004], [122360000.0, 0.0051], [122358000.0, 0.0001]], "asks": [[122378000.0, 0.0002], [122399000.0, 0.0209], [122401000.0, 0.0967], [122402000.0, 0.0389], [122409000.0, 0.0114], [122416000.0, 0.0128], [122417000.0, 0.0144], [122421000.0, 0.0319], [122423000.0, 0.0182], [122426000.0, 0.0179]]},
{"timestamp": "1743771491658", "bids": [[122377000.0, 0.0152], [122375000.0, 0.0052], [122372000.0, 0.0008], [122371000.0, 0.0], [122370000.0, 0.0], [122367000.0, 0.0], [122366000.0, 0.0025], [122363000.0, 0.0004], [122360000.0, 0.0051], [122358000.0, 0.0001]], "asks": [[122378000.0, 0.0002], [122401000.0, 0.0967], [122402000.0, 0.0242], [122412000.0, 0.0173], [122417000.0, 0.0144], [122421000.0, 0.0148], [122423000.0, 0.0182], [122429000.0, 0.0002], [122430000.0, 0.029], [122431000.0, 0.0167]]},
{"timestamp": "1743771492151", "bids": [[122377000.0, 0.0152], [122375000.0, 0.0052], [122372000.0, 0.0008], [122371000.0, 0.0], [122370000.0, 0.0], [122367000.0, 0.0], [122366000.0, 0.0025], [122363000.0, 0.0004], [122360000.0, 0.0051], [122358000.0, 0.0001]], "asks": [[122378000.0, 0.0002], [122408000.0, 0.0799], [122412000.0, 0.0173], [122416000.0, 0.0196], [122427000.0, 0.0565], [122429000.0, 0.0002], [122434000.0, 0.0171], [122436000.0, 0.0248], [122438000.0, 0.0526], [122442000.0, 0.026]]},
{"timestamp": "1743771492655", "bids": [[122377000.0, 0.0152], [122375000.0, 0.0052], [122372000.0, 0.0008], [122371000.0, 0.0], [122370000.0, 0.0], [122367000.0, 0.0], [122366000.0, 0.0025], [122363000.0, 0.0004], [122360000.0, 0.0051], [122358000.0, 0.0001]], "asks": [[122378000.0, 0.0002], [122411000.0, 0.0799], [122412000.0, 0.0173], [122413000.0, 0.0168], [122414000.0, 0.0357], [122415000.0, 0.0114], [122416000.0, 0.0196], [122423000.0, 0.0104], [122426000.0, 0.1359], [122427000.0, 0.0565]]},
{"timestamp": "1743771493156", "bids": [[122377000.0, 0.0152], [122375000.0, 0.0052], [122372000.0, 0.0008], [122371000.0, 0.0], [122370000.0, 0.0], [122367000.0, 0.0], [122366000.0, 0.0025], [122363000.0, 0.0004], [122360000.0, 0.0051], [122358000.0, 0.0001]], "asks": [[122378000.0, 0.0001], [122411000.0, 0.0799], [122412000.0, 0.0173], [122413000.0, 0.0168], [122414000.0, 0.0356], [122426000.0, 0.1359], [122429000.0, 0.0002], [122430000.0, 0.0128], [122432000.0, 0.0144], [122435000.0, 0.0148]]},
{"timestamp": "1743771493652", "bids": [[122377000.0, 0.0152], [122375000.0, 0.0052], [122372000.0, 0.0008], [122371000.0, 0.0], [122370000.0, 0.0], [122367000.0, 0.0], [122366000.0, 0.0025], [122363000.0, 0.0004], [122360000.0, 0.0051], [122358000.0, 0.0001]], "asks": [[122378000.0, 0.0001], [122414000.0, 0.0147], [122420000.0, 0.0209], [122421000.0, 0.0799], [122422000.0, 0.0242], [122429000.0, 0.0002], [122435000.0, 0.0182], [122436000.0, 0.0128], [122439000.0, 0.0126], [122442000.0, 0.0446]]},
{"timestamp": "1743771494158", "bids": [[122377000.0, 0.0152], [122375000.0, 0.0052], [122372000.0, 0.0008], [122371000.0, 0.0], [122370000.0, 0.0], [122367000.0, 0.0], [122366000.0, 0.0025], [122363000.0, 0.0004], [122360000.0, 0.0051], [122358000.0, 0.0001]], "asks": [[122378000.0, 0.0001], [122414000.0, 0.0147], [122420000.0, 0.0209], [122421000.0, 0.0799], [122422000.0, 0.0242], [122429000.0, 0.0002], [122435000.0, 0.0182], [122436000.0, 0.0128], [122439000.0, 0.0126], [122442000.0, 0.0594]]},
{"timestamp": "1743771494653", "bids": [[122377000.0, 0.0002], [122375000.0, 0.0052], [122372000.0, 0.0008], [122371000.0, 0.0], [122370000.0, 0.0], [122367000.0, 0.0], [122366000.0, 0.0025], [122363000.0, 0.0004], [122360000.0, 0.0051], [122358000.0, 0.0001]], "asks": [[122378000.0, 0.0236], [122414000.0, 0.0147], [122419000.0, 0.2158], [122420000.0, 0.0209], [122429000.0, 0.0002], [122430000.0, 0.0177], [122436000.0, 0.0128], [122438000.0, 0.0144], [122442000.0, 0.0594], [122445000.0, 0.0036]]},
{"timestamp": "1743771495157", "bids": [[122377000.0, 0.0002], [122375000.0, 0.0052], [122372000.0, 0.0008], [122371000.0, 0.0], [122370000.0, 0.0], [122367000.0, 0.0], [122366000.0, 0.0025], [122363000.0, 0.0004], [122360000.0, 0.0051], [122358000.0, 0.0001]], "asks": [[122378000.0, 0.0236], [122407000.0, 0.0173], [122409000.0, 0.0001], [122413000.0, 0.0799], [122419000.0, 0.1359], [122425000.0, 0.0166], [122429000.0, 0.0002], [122430000.0, 0.0344], [122431000.0, 0.0546], [122433000.0, 0.0248]]},
{"timestamp": "1743771495662", "bids": [[122363000.0, 0.0004], [122360000.0, 0.0051], [122358000.0, 0.0001], [122357000.0, 0.0009], [122352000.0, 0.0], [122350000.0, 0.0062], [122346000.0, 0.002], [122345000.0, 0.0002], [122344000.0, 0.0003], [122337000.0, 0.0]], "asks": [[122366000.0, 0.1352], [122378000.0, 0.0003], [122383000.0, 0.0242], [122398000.0, 0.0182], [122403000.0, 0.0126], [122405000.0, 0.033], [122406000.0, 0.0799], [122407000.0, 0.0173], [122408000.0, 0.0439], [122409000.0, 0.0001]]},
{"timestamp": "1743771496155", "bids": [[122363000.0, 0.0004], [122360000.0, 0.0051], [122358000.0, 0.0001], [122357000.0, 0.0009], [122352000.0, 0.0], [122350000.0, 0.0062], [122346000.0, 0.002], [122345000.0, 0.0002], [122344000.0, 0.0003], [122337000.0, 0.0]], "asks": [[122365000.0, 0.0057], [122378000.0, 0.0357], [122383000.0, 0.0242], [122395000.0, 0.0128], [122396000.0, 0.0144], [122398000.0, 0.0182], [122400000.0, 0.0148], [122402000.0, 0.0124], [122405000.0, 0.033], [122406000.0, 0.1121]]},
{"timestamp": "1743771496660", "bids": [[122363000.0, 0.0004], [122360000.0, 0.0051], [122358000.0, 0.0001], [122357000.0, 0.0009], [122352000.0, 0.0], [122350000.0, 0.0062], [122346000.0, 0.002], [122345000.0, 0.0002], [122344000.0, 0.0003], [122337000.0, 0.0]], "asks": [[122365000.0, 0.0057], [122377000.0, 0.0766], [122378000.0, 0.0357], [122383000.0, 0.0242], [122395000.0, 0.1483], [122396000.0, 0.0144], [122397000.0, 0.0126], [122398000.0, 0.0182], [122400000.0, 0.0148], [122402000.0, 0.0395]]},
{"timestamp": "1743771497153", "bids": [[122352000.0, 0.0], [122350000.0, 0.0062], [122346000.0, 0.002], [122345000.0, 0.0002], [122344000.0, 0.0003], [122337000.0, 0.0], [122335000.0, 0.0019], [122334000.0, 0.0], [122333000.0, 0.0], [122331000.0, 0.0042]], "asks": [[122377000.0, 0.0766], [122378000.0, 0.0357], [122383000.0, 0.0242], [122396000.0, 0.0144], [122397000.0, 0.0126], [122398000.0, 0.0182], [122400000.0, 0.0148], [122402000.0, 0.0395], [122405000.0, 0.033], [122406000.0, 0.0322]]},
{"timestamp": "1743771497659", "bids": [[122352000.0, 0.0], [122350000.0, 0.0062], [122346000.0, 0.002], [122345000.0, 0.0002], [122344000.0, 0.0003], [122337000.0, 0.0], [122335000.0, 0.0019], [122334000.0, 0.0], [122333000.0, 0.0], [122331000.0, 0.0042]], "asks": [[122378000.0, 0.0357], [122383000.0, 0.0242], [122393000.0, 0.0128], [122395000.0, 0.0764], [122396000.0, 0.0144], [122397000.0, 0.1476], [122398000.0, 0.0182], [122399000.0, 0.0324], [122400000.0, 0.0148], [122402000.0, 0.0395]]},
{"timestamp": "1743771498158", "bids": [[122352000.0, 0.0], [122350000.0, 0.0062], [122346000.0, 0.002], [122345000.0, 0.0002], [122344000.0, 0.0003], [122337000.0, 0.0], [122335000.0, 0.0019], [122334000.0, 0.0], [122333000.0, 0.0], [122331000.0, 0.0042]], "asks": [[122378000.0, 0.0357], [122383000.0, 0.0242], [122392000.0, 0.0764], [122393000.0, 0.0128], [122396000.0, 0.0144], [122397000.0, 0.0126], [122398000.0, 0.0182], [122399000.0, 0.0324], [122400000.0, 0.0148], [122402000.0, 0.0395]]},
{"timestamp": "1743771498658", "bids": [[122352000.0, 0.0], [122350000.0, 0.0062], [122346000.0, 0.002], [122345000.0, 0.0002], [122344000.0, 0.0003], [122337000.0, 0.0], [122335000.0, 0.0019], [122334000.0, 0.0], [122333000.0, 0.0], [122331000.0, 0.0042]], "asks": [[122378000.0, 0.0357], [122382000.0, 0.0764], [122383000.0, 0.0242], [122393000.0, 0.0128], [122396000.0, 0.0144], [122397000.0, 0.0126], [122398000.0, 0.0182], [122399000.0, 0.0324], [122400000.0, 0.0148], [122402000.0, 0.0395]]},
{"timestamp": "1743771499163", "bids": [[122352000.0, 0.0], [122350000.0, 0.0062], [122346000.0, 0.002], [122345000.0, 0.0002], [122344000.0, 0.0003], [122337000.0, 0.0], [122335000.0, 0.0019], [122334000.0, 0.0], [122333000.0, 0.0], [122331000.0, 0.0042]], "asks": [[122378000.0, 0.0357], [122398000.0, 0.0182], [122402000.0, 0.0124], [122406000.0, 0.0544], [122408000.0, 0.0248], [122414000.0, 0.036], [122421000.0, 0.0168], [122429000.0, 0.0188], [122436000.0, 0.017], [122441000.0, 0.0239]]},
{"timestamp": "1743771499657", "bids": [[122353000.0, 0.1406], [122352000.0, 0.0], [122350000.0, 0.0062], [122346000.0, 0.002], [122345000.0, 0.0002], [122344000.0, 0.0003], [122337000.0, 0.0], [122335000.0, 0.0019], [122334000.0, 0.0], [122333000.0, 0.0]], "asks": [[122378000.0, 0.0001], [122392000.0, 0.0764], [122399000.0, 0.0166], [122402000.0, 0.0242], [122404000.0, 0.0177], [122406000.0, 0.0222], [122408000.0, 0.0248], [122410000.0, 0.0255], [122414000.0, 0.0253], [122421000.0, 0.0294]]},
{"timestamp": "1743771500155", "bids": [[122353000.0, 0.1408], [122352000.0, 0.0], [122350000.0, 0.0062], [122346000.0, 0.002], [122345000.0, 0.0002], [122344000.0, 0.0003], [122337000.0, 0.0], [122335000.0, 0.0019], [122334000.0, 0.0], [122333000.0, 0.0]], "asks": [[122378000.0, 0.0001], [122399000.0, 0.0166], [122400000.0, 0.0341], [122402000.0, 0.0243], [122403000.0, 0.0114], [122404000.0, 0.0177], [122406000.0, 0.0], [122407000.0, 0.0764], [122408000.0, 0.0248], [122410000.0, 0.0255]]},
{"timestamp": "1743771500659", "bids": [[122353000.0, 0.0002], [122352000.0, 0.0], [122350000.0, 0.0062], [122346000.0, 0.002], [122345000.0, 0.0002], [122344000.0, 0.0003], [122337000.0, 0.0074], [122335000.0, 0.0019], [122334000.0, 0.0], [122333000.0, 0.0]], "asks": [[122378000.0, 0.0001], [122399000.0, 0.0166], [122400000.0, 0.0341], [122402000.0, 0.0243], [122403000.0, 0.0114], [122404000.0, 0.0177], [122405000.0, 0.135], [122406000.0, 0.0], [122407000.0, 0.0764], [122408000.0, 0.0248]]},
{"timestamp": "1743771501155", "bids": [[122357000.0, 0.0008], [122354000.0, 0.001], [122353000.0, 0.0002], [122352000.0, 0.0], [122350000.0, 0.0062], [122346000.0, 0.002], [122345000.0, 0.0002], [122344000.0, 0.0003], [122337000.0, 0.0074], [122335000.0, 0.0045]], "asks": [[122378000.0, 0.0001], [122398000.0, 0.0764], [122399000.0, 0.0166], [122400000.0, 0.0341], [122402000.0, 0.0243], [122403000.0, 0.0114], [122404000.0, 0.0177], [122406000.0, 0.0], [122408000.0, 0.0248], [122410000.0, 0.0255]]},
{"timestamp": "1743771501666", "bids": [[122357000.0, 0.0008], [122354000.0, 0.001], [122353000.0, 0.0002], [122352000.0, 0.0], [122350000.0, 0.0062], [122346000.0, 0.002], [122345000.0, 0.0002], [122344000.0, 0.0003], [122341000.0, 0.022], [122337000.0, 0.0074]], "asks": [[122378000.0, 0.0001], [122398000.0, 0.0764], [122399000.0, 0.0166], [122400000.0, 0.0341], [122402000.0, 0.0243], [122403000.0, 0.0114], [122404000.0, 0.0177], [122406000.0, 0.0], [122408000.0, 0.0248], [122410000.0, 0.0255]]},
{"timestamp": "1743771502162", "bids": [[122357000.0, 0.0008], [122354000.0, 0.001], [122353000.0, 0.0002], [122352000.0, 0.0], [122350000.0, 0.0062], [122346000.0, 0.002], [122345000.0, 0.0002], [122344000.0, 0.0003], [122341000.0, 0.022], [122337000.0, 0.0123]], "asks": [[122378000.0, 0.0001], [122398000.0, 0.0764], [122399000.0, 0.0166], [122400000.0, 0.0341], [122402000.0, 0.0243], [122403000.0, 0.0114], [122404000.0, 0.0177], [122406000.0, 0.0], [122408000.0, 0.0248], [122410000.0, 0.0255]]},
{"timestamp": "1743771502658", "bids": [[122357000.0, 0.0008], [122354000.0, 0.001], [122353000.0, 0.0002], [122352000.0, 0.0], [122350000.0, 0.0062], [122346000.0, 0.002], [122345000.0, 0.0002], [122344000.0, 0.0003], [122341000.0, 0.022], [122337000.0, 0.0123]], "asks": [[122378000.0, 0.0001], [122399000.0, 0.093], [122400000.0, 0.0341], [122402000.0, 0.0243], [122403000.0, 0.0114], [122404000.0, 0.0177], [122406000.0, 0.0], [122408000.0, 0.0248], [122410000.0, 0.0255], [122414000.0, 0.0357]]},
{"timestamp": "1743771503162", "bids": [[122358000.0, 0.1529], [122357000.0, 0.0008], [122354000.0, 0.001], [122353000.0, 0.0002], [122352000.0, 0.0], [122350000.0, 0.0062], [122346000.0, 0.002], [122345000.0, 0.0002], [122344000.0, 0.0003], [122341000.0, 0.022]], "asks": [[122378000.0, 0.0001], [122398000.0, 0.0764], [122400000.0, 0.0168], [122403000.0, 0.0114], [122406000.0, 0.0], [122414000.0, 0.0104], [122415000.0, 0.0209], [122417000.0, 0.0007], [122419000.0, 0.0196], [122422000.0, 0.0182]]},
{"timestamp": "1743771503657", "bids": [[122358000.0, 0.1023], [122357000.0, 0.0008], [122354000.0, 0.001], [122353000.0, 0.0002], [122352000.0, 0.0], [122350000.0, 0.0062], [122346000.0, 0.002], [122345000.0, 0.0002], [122344000.0, 0.0003], [122337000.0, 0.0152]], "asks": [[122378000.0, 0.0001], [122406000.0, 0.0], [122407000.0, 0.0764], [122421000.0, 0.0173], [122429000.0, 0.0002], [122435000.0, 0.0182], [122438000.0, 0.0388], [122442000.0, 0.0124], [122443000.0, 0.0177], [122445000.0, 0.0036]]},
{"timestamp": "1743771504169", "bids": [[122357000.0, 0.0008], [122354000.0, 0.001], [122353000.0, 0.0002], [122352000.0, 0.0], [122350000.0, 0.0078], [122349000.0, 0.022], [122346000.0, 0.002], [122345000.0, 0.0002], [122344000.0, 0.0003], [122343000.0, 0.0026]], "asks": [[122378000.0, 0.0001], [122406000.0, 0.0], [122414000.0, 0.135], [122421000.0, 0.0173], [122423000.0, 0.0001], [122424000.0, 0.0114], [122425000.0, 0.0242], [122429000.0, 0.0002], [122430000.0, 0.135], [122435000.0, 0.0182]]},
{"timestamp": "1743771504664", "bids": [[122357000.0, 0.0024], [122354000.0, 0.001], [122353000.0, 0.0002], [122352000.0, 0.0], [122350000.0, 0.0078], [122349000.0, 0.022], [122346000.0, 0.002], [122345000.0, 0.0076], [122344000.0, 0.0003], [122343000.0, 0.0026]], "asks": [[122378000.0, 0.0], [122406000.0, 0.0], [122413000.0, 0.0764], [122421000.0, 0.0173], [122423000.0, 0.0357], [122424000.0, 0.0114], [122425000.0, 0.0242], [122427000.0, 0.0196], [122429000.0, 0.0002], [122430000.0, 0.135]]},
{"timestamp": "1743771505161", "bids": [[122357000.0, 0.0024], [122354000.0, 0.001], [122353000.0, 0.0002], [122352000.0, 0.0], [122351000.0, 0.0048], [122350000.0, 0.0078], [122349000.0, 0.022], [122346000.0, 0.002], [122345000.0, 0.0076], [122344000.0, 0.0003]], "asks": [[122378000.0, 0.0001], [122406000.0, 0.0], [122421000.0, 0.0173], [122423000.0, 0.0357], [122424000.0, 0.0114], [122425000.0, 0.0242], [122427000.0, 0.0196], [122429000.0, 0.0002], [122435000.0, 0.0182], [122438000.0, 0.0388]]},
{"timestamp": "1743771505660", "bids": [[122357000.0, 0.0024], [122354000.0, 0.001], [122353000.0, 0.0002], [122352000.0, 0.0], [122351000.0, 0.0048], [122350000.0, 0.0078], [122349000.0, 0.022], [122346000.0, 0.002], [122345000.0, 0.0076], [122344000.0, 0.0003]], "asks": [[122378000.0, 0.0001], [122406000.0, 0.0], [122420000.0, 0.0764], [122421000.0, 0.0173], [122423000.0, 0.0357], [122424000.0, 0.0114], [122425000.0, 0.0242], [122427000.0, 0.0196], [122429000.0, 0.0002], [122434000.0, 0.135]]},
{"timestamp": "1743771506158", "bids": [[122357000.0, 0.0024], [122354000.0, 0.001], [122353000.0, 0.0002], [122352000.0, 0.0], [122350000.0, 0.0078], [122346000.0, 0.002], [122345000.0, 0.0076], [122344000.0, 0.0003], [122343000.0, 0.0026], [122337000.0, 0.0112]], "asks": [[122377000.0, 0.0234], [122378000.0, 0.0001], [122406000.0, 0.0], [122419000.0, 0.135], [122420000.0, 0.0764], [122421000.0, 0.0173], [122423000.0, 0.0357], [122424000.0, 0.0114], [122425000.0, 0.0242], [122426000.0, 0.135]]},
{"timestamp": "1743771506660", "bids": [[122357000.0, 0.0024], [122354000.0, 0.001], [122353000.0, 0.0002], [122352000.0, 0.0], [122350000.0, 0.0078], [122346000.0, 0.002], [122345000.0, 0.0076], [122344000.0, 0.0003], [122343000.0, 0.0026], [122337000.0, 0.0112]], "asks": [[122377000.0, 0.0234], [122378000.0, 0.0001], [122406000.0, 0.0], [122419000.0, 0.135], [122420000.0, 0.0764], [122426000.0, 0.135], [122427000.0, 0.0196], [122429000.0, 0.0002], [122438000.0, 0.0222], [122439000.0, 0.0128]]},
{"timestamp": "1743771507159", "bids": [[122357000.0, 0.0024], [122354000.0, 0.001], [122353000.0, 0.0002], [122352000.0, 0.0], [122350000.0, 0.0078], [122346000.0, 0.002], [122345000.0, 0.0002], [122344000.0, 0.0003], [122337000.0, 0.0], [122336000.0, 0.022]], "asks": [[122378000.0, 0.0001], [122405000.0, 0.021], [122406000.0, 0.0], [122408000.0, 0.0173], [122412000.0, 0.0242], [122415000.0, 0.0168], [122416000.0, 0.0147], [122418000.0, 0.0764], [122419000.0, 0.135], [122424000.0, 0.0126]]},
{"timestamp": "1743771507660", "bids": [[122357000.0, 0.0024], [122354000.0, 0.001], [122353000.0, 0.0002], [122352000.0, 0.0], [122350000.0, 0.0078], [122346000.0, 0.002], [122345000.0, 0.0002], [122344000.0, 0.0003], [122337000.0, 0.0], [122335000.0, 0.0019]], "asks": [[122378000.0, 0.0001], [122405000.0, 0.021], [122406000.0, 0.0], [122407000.0, 0.031], [122408000.0, 0.0173], [122412000.0, 0.0242], [122416000.0, 0.0147], [122418000.0, 0.0764], [122419000.0, 0.1478], [122420000.0, 0.0326]]},
{"timestamp": "1743771508156", "bids": [[122357000.0, 0.0024], [122354000.0, 0.001], [122353000.0, 0.0002], [122352000.0, 0.0], [122350000.0, 0.0078], [122346000.0, 0.002], [122345000.0, 0.0002], [122344000.0, 0.0003], [122337000.0, 0.0], [122335000.0, 0.0019]], "asks": [[122378000.0, 0.0], [122405000.0, 0.0001], [122406000.0, 0.0], [122407000.0, 0.031], [122408000.0, 0.0173], [122412000.0, 0.0242], [122416000.0, 0.0147], [122419000.0, 0.0128], [122420000.0, 0.0326], [122424000.0, 0.0272]]},
{"timestamp": "1743771508661", "bids": [[122357000.0, 0.0024], [122354000.0, 0.001], [122353000.0, 0.0002], [122352000.0, 0.0], [122350000.0, 0.0078], [122346000.0, 0.002], [122345000.0, 0.0002], [122344000.0, 0.0003], [122337000.0, 0.0], [122335000.0, 0.0019]], "asks": [[122378000.0, 0.0], [122402000.0, 0.0209], [122405000.0, 0.0001], [122406000.0, 0.0764], [122407000.0, 0.031], [122408000.0, 0.0173], [122412000.0, 0.0242], [122416000.0, 0.0147], [122419000.0, 0.0128], [122420000.0, 0.0326]]},
{"timestamp": "1743771509160", "bids": [[122357000.0, 0.0024], [122354000.0, 0.001], [122353000.0, 0.0002], [122352000.0, 0.0], [122350000.0, 0.0078], [122346000.0, 0.002], [122345000.0, 0.0002], [122344000.0, 0.0003], [122337000.0, 0.0], [122335000.0, 0.0019]], "asks": [[122378000.0, 0.0], [122402000.0, 0.0209], [122405000.0, 0.0001], [122406000.0, 0.0764], [122407000.0, 0.031], [122408000.0, 0.0173], [122412000.0, 0.0242], [122416000.0, 0.0147], [122419000.0, 0.0128], [122420000.0, 0.0326]]},
{"timestamp": "1743771509659", "bids": [[122357000.0, 0.0023], [122354000.0, 0.001], [122353000.0, 0.0002], [122352000.0, 0.0], [122350000.0, 0.0078], [122346000.0, 0.002], [122345000.0, 0.0002], [122344000.0, 0.0003], [122337000.0, 0.0], [122335000.0, 0.0019]], "asks": [[122402000.0, 0.0209], [122405000.0, 0.0001], [122406000.0, 0.0764], [122407000.0, 0.031], [122408000.0, 0.0173], [122412000.0, 0.0242], [122416000.0, 0.0147], [122419000.0, 0.0128], [122420000.0, 0.0326], [122421000.0, 0.0126]]},
{"timestamp": "1743771510166", "bids": [[122357000.0, 0.0024], [122354000.0, 0.001], [122353000.0, 0.0002], [122352000.0, 0.0], [122350000.0, 0.0078], [122346000.0, 0.002], [122345000.0, 0.0002], [122344000.0, 0.0003], [122337000.0, 0.0], [122335000.0, 0.0019]], "asks": [[122401000.0, 0.0763], [122402000.0, 0.0209], [122405000.0, 0.0001], [122406000.0, 0.0], [122407000.0, 0.031], [122408000.0, 0.0173], [122412000.0, 0.0242], [122415000.0, 0.135], [122416000.0, 0.0147], [122419000.0, 0.0128]]},
{"timestamp": "1743771510673", "bids": [[122357000.0, 0.0024], [122354000.0, 0.001], [122353000.0, 0.0002], [122352000.0, 0.0], [122350000.0, 0.0078], [122346000.0, 0.002], [122345000.0, 0.0002], [122344000.0, 0.0003], [122337000.0, 0.0], [122335000.0, 0.0019]], "asks": [[122399000.0, 0.0168], [122401000.0, 0.0763], [122402000.0, 0.0209], [122406000.0, 0.0], [122416000.0, 0.0147], [122419000.0, 0.135], [122421000.0, 0.0126], [122422000.0, 0.0177], [122424000.0, 0.0179], [122425000.0, 0.0248]]},
{"timestamp": "1743771511160", "bids": [[122357000.0, 0.0024], [122354000.0, 0.001], [122353000.0, 0.0002], [122352000.0, 0.0], [122350000.0, 0.0078], [122346000.0, 0.002], [122345000.0, 0.0002], [122344000.0, 0.0003], [122337000.0, 0.0], [122335000.0, 0.0019]], "asks": [[122399000.0, 0.0167], [122401000.0, 0.0001], [122402000.0, 0.0209], [122406000.0, 0.0], [122415000.0, 0.135], [122417000.0, 0.0128], [122418000.0, 0.0144], [122419000.0, 0.135], [122421000.0, 0.0126], [122422000.0, 0.0449]]},
{"timestamp": "1743771511658", "bids": [[122357000.0, 0.0024], [122352000.0, 0.0], [122350000.0, 0.0078], [122346000.0, 0.002], [122345000.0, 0.0002], [122344000.0, 0.0003], [122337000.0, 0.0], [122335000.0, 0.0019], [122334000.0, 0.0], [122333000.0, 0.0]], "asks": [[122398000.0, 0.082], [122399000.0, 0.0167], [122406000.0, 0.0], [122415000.0, 0.135], [122418000.0, 0.0144], [122422000.0, 0.0124], [122424000.0, 0.0179], [122425000.0, 0.0271], [122429000.0, 0.0002], [122431000.0, 0.0336]]},
{"timestamp": "1743771512163", "bids": [[122357000.0, 0.0024], [122352000.0, 0.0], [122350000.0, 0.0078], [122346000.0, 0.002], [122345000.0, 0.0002], [122344000.0, 0.0003], [122337000.0, 0.0], [122335000.0, 0.0019], [122334000.0, 0.0], [122333000.0, 0.0]], "asks": [[122391000.0, 0.0173], [122394000.0, 0.0262], [122396000.0, 0.0242], [122398000.0, 0.0998], [122406000.0, 0.0], [122407000.0, 0.0182], [122409000.0, 0.0166], [122415000.0, 0.1572], [122416000.0, 0.0171], [122417000.0, 0.1931]]},
{"timestamp": "1743771512661", "bids": [[122357000.0, 0.0024], [122352000.0, 0.0], [122350000.0, 0.0078], [122346000.0, 0.002], [122345000.0, 0.0002], [122344000.0, 0.0003], [122337000.0, 0.0], [122335000.0, 0.0019], [122334000.0, 0.0], [122333000.0, 0.0]], "asks": [[122373000.0, 0.0001], [122388000.0, 0.0126], [122390000.0, 0.0764], [122391000.0, 0.0271], [122393000.0, 0.0324], [122394000.0, 0.0262], [122396000.0, 0.0242], [122401000.0, 0.0196], [122402000.0, 0.0248], [122403000.0, 0.0233]]},
{"timestamp": "1743771513169", "bids": [[122357000.0, 0.0024], [122352000.0, 0.0], [122350000.0, 0.0078], [122346000.0, 0.002], [122345000.0, 0.0002], [122344000.0, 0.0003], [122337000.0, 0.0], [122335000.0, 0.0019], [122334000.0, 0.0], [122333000.0, 0.0]], "asks": [[122365000.0, 0.0166], [122366000.0, 0.0209], [122373000.0, 0.0001], [122382000.0, 0.0128], [122384000.0, 0.0144], [122388000.0, 0.025], [122390000.0, 0.0764], [122391000.0, 0.0271], [122393000.0, 0.0324], [122394000.0, 0.0293]]},
{"timestamp": "1743771513661", "bids": [[122357000.0, 0.0024], [122352000.0, 0.0], [122350000.0, 0.0078], [122346000.0, 0.002], [122345000.0, 0.0002], [122344000.0, 0.0003], [122337000.0, 0.0], [122335000.0, 0.0019], [122334000.0, 0.0], [122333000.0, 0.0]], "asks": [[122365000.0, 0.0166], [122372000.0, 0.0056], [122373000.0, 0.0001], [122385000.0, 0.0148], [122387000.0, 0.0764], [122388000.0, 0.0124], [122393000.0, 0.0324], [122394000.0, 0.0345], [122397000.0, 0.135], [122399000.0, 0.0164]]},
{"timestamp": "1743771514160", "bids": [[122357000.0, 0.0024], [122352000.0, 0.0], [122350000.0, 0.0078], [122346000.0, 0.002], [122345000.0, 0.0002], [122344000.0, 0.0003], [122337000.0, 0.0], [122335000.0, 0.0019], [122334000.0, 0.0], [122333000.0, 0.0]], "asks": [[122365000.0, 0.0339], [122381000.0, 0.0764], [122382000.0, 0.0166], [122385000.0, 0.0148], [122388000.0, 0.0124], [122389000.0, 0.0222], [122391000.0, 0.0849], [122393000.0, 0.0255], [122397000.0, 0.0253], [122406000.0, 0.0]]},
{"timestamp": "1743771514665", "bids": [[122357000.0, 0.0024], [122352000.0, 0.0], [122350000.0, 0.0078], [122346000.0, 0.002], [122345000.0, 0.0002], [122344000.0, 0.0003], [122337000.0, 0.0], [122335000.0, 0.0019], [122334000.0, 0.0], [122333000.0, 0.0]], "asks": [[122365000.0, 0.0339], [122368000.0, 0.0114], [122369000.0, 0.0242], [122381000.0, 0.0946], [122382000.0, 0.0166], [122385000.0, 0.0276], [122387000.0, 0.0326], [122388000.0, 0.0741], [122389000.0, 0.0222], [122390000.0, 0.0171]]},
{"timestamp": "1743771515160", "bids": [[122357000.0, 0.0024], [122352000.0, 0.0], [122350000.0, 0.0078], [122346000.0, 0.002], [122345000.0, 0.0002], [122344000.0, 0.0003], [122337000.0, 0.0], [122335000.0, 0.0019], [122334000.0, 0.0], [122333000.0, 0.0]], "asks": [[122369000.0, 0.021], [122381000.0, 0.0182], [122384000.0, 0.0764], [122385000.0, 0.0128], [122387000.0, 0.0326], [122388000.0, 0.0491], [122390000.0, 0.0348], [122391000.0, 0.0176], [122392000.0, 0.0179], [122394000.0, 0.0209]]},
{"timestamp": "1743771515661", "bids": [[122358000.0, 0.0994], [122357000.0, 0.0024], [122352000.0, 0.0], [122350000.0, 0.0078], [122346000.0, 0.002], [122345000.0, 0.0002], [122344000.0, 0.0003], [122337000.0, 0.0], [122335000.0, 0.0019], [122334000.0, 0.0]], "asks": [[122369000.0, 0.021], [122378000.0, 0.0147], [122380000.0, 0.0196], [122384000.0, 0.0764], [122386000.0, 0.0764], [122387000.0, 0.0182], [122388000.0, 0.0104], [122390000.0, 0.0348], [122392000.0, 0.0179], [122396000.0, 0.033]]},
{"timestamp": "1743771516161", "bids": [[122358000.0, 0.1642], [122357000.0, 0.0024], [122352000.0, 0.0], [122350000.0, 0.0078], [122346000.0, 0.002], [122345000.0, 0.0002], [122344000.0, 0.0003], [122337000.0, 0.0], [122335000.0, 0.0019], [122334000.0, 0.0]], "asks": [[122377000.0, 0.0166], [122378000.0, 0.0147], [122380000.0, 0.0196], [122386000.0, 0.0764], [122388000.0, 0.0104], [122392000.0, 0.0179], [122399000.0, 0.017], [122400000.0, 0.0124], [122406000.0, 0.0], [122409000.0, 0.0496]]},
{"timestamp": "1743771516664", "bids": [[122359000.0, 0.0005], [122358000.0, 0.0036], [122357000.0, 0.0024], [122352000.0, 0.0], [122350000.0, 0.0078], [122346000.0, 0.002], [122345000.0, 0.0002], [122344000.0, 0.0003], [122337000.0, 0.0], [122335000.0, 0.0019]], "asks": [[122377000.0, 0.0166], [122378000.0, 0.0147], [122380000.0, 0.0196], [122388000.0, 0.0104], [122392000.0, 0.0179], [122394000.0, 0.0209], [122399000.0, 0.017], [122400000.0, 0.0124], [122406000.0, 0.0], [122408000.0, 0.0764]]},
{"timestamp": "1743771517162", "bids": [[122359000.0, 0.001], [122358000.0, 0.0036], [122357000.0, 0.0024], [122352000.0, 0.0], [122350000.0, 0.0078], [122346000.0, 0.002], [122345000.0, 0.0002], [122344000.0, 0.0003], [122337000.0, 0.0], [122335000.0, 0.0019]], "asks": [[122394000.0, 0.0209], [122395000.0, 0.0173], [122397000.0, 0.0001], [122398000.0, 0.0114], [122400000.0, 0.0242], [122406000.0, 0.0], [122408000.0, 0.0764], [122411000.0, 0.0144], [122412000.0, 0.0182], [122413000.0, 0.0166]]},
{"timestamp": "1743771517668", "bids": [[122391000.0, 0.0001], [122359000.0, 0.0005], [122358000.0, 0.0036], [122357000.0, 0.0024], [122352000.0, 0.0], [122350000.0, 0.0078], [122346000.0, 0.002], [122345000.0, 0.0002], [122344000.0, 0.0003], [122337000.0, 0.0]], "asks": [[122395000.0, 0.0173], [122397000.0, 0.0001], [122398000.0, 0.028], [122399000.0, 0.0147], [122400000.0, 0.0242], [122404000.0, 0.0196], [122406000.0, 0.0], [122409000.0, 0.0764], [122412000.0, 0.0182], [122413000.0, 0.0166]]},
{"timestamp": "1743771518162", "bids": [[122391000.0, 0.0001], [122359000.0, 0.0005], [122358000.0, 0.0036], [122357000.0, 0.0024], [122352000.0, 0.0], [122350000.0, 0.0078], [122346000.0, 0.002], [122345000.0, 0.0002], [122344000.0, 0.0003], [122337000.0, 0.0]], "asks": [[122395000.0, 0.0172], [122397000.0, 0.0001], [122398000.0, 0.028], [122399000.0, 0.0356], [122400000.0, 0.0242], [122404000.0, 0.0196], [122406000.0, 0.0], [122409000.0, 0.0764], [122412000.0, 0.0286], [122413000.0, 0.0166]]},
{"timestamp": "1743771518660", "bids": [[122357000.0, 0.0024], [122352000.0, 0.0], [122350000.0, 0.0078], [122346000.0, 0.002], [122345000.0, 0.0002], [122344000.0, 0.0003], [122337000.0, 0.0], [122335000.0, 0.0019], [122334000.0, 0.0], [122333000.0, 0.0]], "asks": [[122394000.0, 0.0056], [122395000.0, 0.0172], [122397000.0, 0.0001], [122398000.0, 0.1044], [122399000.0, 0.0356], [122400000.0, 0.0242], [122404000.0, 0.0196], [122406000.0, 0.0], [122412000.0, 0.0286], [122413000.0, 0.0166]]},
{"timestamp": "1743771519162", "bids": [[122357000.0, 0.0024], [122352000.0, 0.0], [122350000.0, 0.0078], [122346000.0, 0.002], [122345000.0, 0.0002], [122344000.0, 0.0003], [122337000.0, 0.0], [122335000.0, 0.0019], [122334000.0, 0.0], [122333000.0, 0.0]], "asks": [[122394000.0, 0.082], [122395000.0, 0.0172], [122397000.0, 0.0001], [122398000.0, 0.028], [122399000.0, 0.0356], [122400000.0, 0.0242], [122404000.0, 0.0196], [122406000.0, 0.0], [122412000.0, 0.0286], [122413000.0, 0.0166]]},
{"timestamp": "1743771519662", "bids": [[122357000.0, 0.0024], [122352000.0, 0.0], [122350000.0, 0.0078], [122346000.0, 0.002], [122345000.0, 0.0002], [122344000.0, 0.0003], [122337000.0, 0.0], [122335000.0, 0.0019], [122334000.0, 0.0], [122333000.0, 0.0]], "asks": [[122393000.0, 0.0177], [122394000.0, 0.0764], [122397000.0, 0.0001], [122398000.0, 0.028], [122399000.0, 0.0356], [122404000.0, 0.0196], [122406000.0, 0.0], [122412000.0, 0.0104], [122416000.0, 0.0128], [122417000.0, 0.0144]]},
{"timestamp": "1743771520167", "bids": [[122357000.0, 0.0024], [122352000.0, 0.0], [122350000.0, 0.0078], [122346000.0, 0.002], [122345000.0, 0.0002], [122344000.0, 0.0003], [122337000.0, 0.0], [122335000.0, 0.0019], [122334000.0, 0.0], [122333000.0, 0.0]], "asks": [[122393000.0, 0.0177], [122406000.0, 0.0], [122415000.0, 0.0222], [122416000.0, 0.0128], [122418000.0, 0.033], [122421000.0, 0.0016], [122423000.0, 0.0179], [122429000.0, 0.0002], [122430000.0, 0.0166], [122431000.0, 0.0007]]},
{"timestamp": "1743771520664", "bids": [[122357000.0, 0.0024], [122352000.0, 0.0], [122350000.0, 0.0078], [122346000.0, 0.002], [122345000.0, 0.0002], [122344000.0, 0.0003], [122337000.0, 0.0], [122335000.0, 0.0019], [122334000.0, 0.0], [122333000.0, 0.0]], "asks": [[122384000.0, 0.0172], [122386000.0, 0.021], [122388000.0, 0.0242], [122392000.0, 0.0147], [122397000.0, 0.0196], [122401000.0, 0.0182], [122402000.0, 0.0166], [122405000.0, 0.0126], [122406000.0, 0.0], [122407000.0, 0.0359]]},
{"timestamp": "1743771521163", "bids": [[122382000.0, 0.0002], [122357000.0, 0.0024], [122352000.0, 0.0], [122350000.0, 0.0078], [122346000.0, 0.002], [122345000.0, 0.0002], [122344000.0, 0.0003], [122337000.0, 0.0], [122335000.0, 0.0019], [122334000.0, 0.0]], "asks": [[122384000.0, 0.0171], [122386000.0, 0.021], [122387000.0, 0.0114], [122388000.0, 0.0242], [122391000.0, 0.0166], [122392000.0, 0.0147], [122396000.0, 0.0764], [122397000.0, 0.0196], [122398000.0, 0.0104], [122401000.0, 0.0182]]},
{"timestamp": "1743771521664", "bids": [[122382000.0, 0.0002], [122358000.0, 0.1508], [122357000.0, 0.0024], [122352000.0, 0.0], [122350000.0, 0.0078], [122346000.0, 0.002], [122345000.0, 0.0002], [122344000.0, 0.0003], [122337000.0, 0.0], [122335000.0, 0.0019]], "asks": [[122386000.0, 0.0209], [122387000.0, 0.0114], [122391000.0, 0.0166], [122392000.0, 0.0147], [122397000.0, 0.0196], [122398000.0, 0.0104], [122400000.0, 0.0764], [122401000.0, 0.0182], [122402000.0, 0.0128], [122404000.0, 0.0144]]},
{"timestamp": "1743771522167", "bids": [[122383000.0, 0.0022], [122382000.0, 0.0002], [122358000.0, 0.1508], [122357000.0, 0.0024], [122352000.0, 0.0], [122350000.0, 0.0078], [122346000.0, 0.002], [122345000.0, 0.0002], [122344000.0, 0.0003], [122337000.0, 0.0]], "asks": [[122391000.0, 0.0166], [122392000.0, 0.0147], [122397000.0, 0.0196], [122400000.0, 0.0764], [122406000.0, 0.0], [122415000.0, 0.0124], [122421000.0, 0.0016], [122422000.0, 0.0185], [122429000.0, 0.0002], [122443000.0, 0.0]]},
{"timestamp": "1743771522661", "bids": [[122382000.0, 0.0002], [122379000.0, 0.006], [122357000.0, 0.0024], [122352000.0, 0.0], [122350000.0, 0.0078], [122346000.0, 0.002], [122345000.0, 0.0002], [122344000.0, 0.0003], [122341000.0, 0.0225], [122337000.0, 0.0]], "asks": [[122400000.0, 0.0764], [122406000.0, 0.0], [122409000.0, 0.0171], [122411000.0, 0.0001], [122414000.0, 0.0242], [122421000.0, 0.0016], [122422000.0, 0.0179], [122423000.0, 0.0104], [122429000.0, 0.0146], [122430000.0, 0.0374]]},
{"timestamp": "1743771523165", "bids": [[122382000.0, 0.0002], [122379000.0, 0.006], [122357000.0, 0.0024], [122352000.0, 0.0], [122350000.0, 0.0078], [122346000.0, 0.002], [122345000.0, 0.0002], [122344000.0, 0.0003], [122341000.0, 0.0225], [122338000.0, 0.0222]], "asks": [[122406000.0, 0.0], [122409000.0, 0.0171], [122411000.0, 0.021], [122414000.0, 0.0242], [122421000.0, 0.078], [122422000.0, 0.0179], [122423000.0, 0.0104], [122427000.0, 0.0128], [122429000.0, 0.0146], [122430000.0, 0.0374]]},
{"timestamp": "1743771523664", "bids": [[122382000.0, 0.0002], [122379000.0, 0.006], [122357000.0, 0.0024], [122352000.0, 0.0], [122350000.0, 0.0078], [122346000.0, 0.002], [122345000.0, 0.0002], [122344000.0, 0.0003], [122338000.0, 0.0222], [122337000.0, 0.0]], "asks": [[122406000.0, 0.0], [122409000.0, 0.0171], [122411000.0, 0.021], [122414000.0, 0.0242], [122421000.0, 0.078], [122422000.0, 0.0179], [122423000.0, 0.0104], [122427000.0, 0.0128], [122429000.0, 0.0146], [122430000.0, 0.0374]]},
{"timestamp": "1743771524185", "bids": [[122382000.0, 0.0002], [122379000.0, 0.006], [122357000.0, 0.0024], [122352000.0, 0.0], [122350000.0, 0.0078], [122346000.0, 0.002], [122345000.0, 0.0002], [122344000.0, 0.0003], [122338000.0, 0.0222], [122337000.0, 0.0]], "asks": [[122406000.0, 0.0], [122409000.0, 0.0171], [122411000.0, 0.021], [122414000.0, 0.0242], [122421000.0, 0.078], [122422000.0, 0.0179], [122423000.0, 0.0104], [122427000.0, 0.0128], [122429000.0, 0.0146], [122430000.0, 0.0374]]},
{"timestamp": "1743771524665", "bids": [[122382000.0, 0.0002], [122379000.0, 0.006], [122357000.0, 0.0024], [122352000.0, 0.0], [122350000.0, 0.0078], [122346000.0, 0.002], [122345000.0, 0.0002], [122344000.0, 0.0003], [122338000.0, 0.0222], [122337000.0, 0.0]], "asks": [[122406000.0, 0.0], [122409000.0, 0.0171], [122411000.0, 0.021], [122413000.0, 0.0764], [122414000.0, 0.0242], [122421000.0, 0.0016], [122422000.0, 0.0179], [122423000.0, 0.0104], [122427000.0, 0.0128], [122429000.0, 0.0146]]},
{"timestamp": "1743771525164", "bids": [[122382000.0, 0.0002], [122379000.0, 0.006], [122357000.0, 0.0024], [122352000.0, 0.0], [122350000.0, 0.0078], [122346000.0, 0.002], [122345000.0, 0.0002], [122344000.0, 0.0003], [122338000.0, 0.0222], [122337000.0, 0.0]], "asks": [[122406000.0, 0.0], [122409000.0, 0.0171], [122411000.0, 0.021], [122414000.0, 0.0242], [122421000.0, 0.078], [122422000.0, 0.0179], [122423000.0, 0.0104], [122427000.0, 0.0128], [122429000.0, 0.0146], [122430000.0, 0.0374]]},
{"timestamp": "1743771525668", "bids": [[122382000.0, 0.0002], [122379000.0, 0.0016], [122357000.0, 0.0024], [122352000.0, 0.0], [122350000.0, 0.0078], [122346000.0, 0.002], [122345000.0, 0.0002], [122344000.0, 0.0003], [122338000.0, 0.0222], [122337000.0, 0.0]], "asks": [[122405000.0, 0.0056], [122406000.0, 0.0], [122411000.0, 0.0209], [122421000.0, 0.078], [122422000.0, 0.0179], [122423000.0, 0.0104], [122427000.0, 0.0128], [122429000.0, 0.0002], [122430000.0, 0.0374], [122432000.0, 0.0359]]},
{"timestamp": "1743771526167", "bids": [[122382000.0, 0.0002], [122379000.0, 0.0016], [122357000.0, 0.0024], [122352000.0, 0.0], [122350000.0, 0.0078], [122346000.0, 0.002], [122345000.0, 0.0002], [122344000.0, 0.0003], [122337000.0, 0.0], [122335000.0, 0.0019]], "asks": [[122405000.0, 0.0056], [122406000.0, 0.0], [122408000.0, 0.0764], [122420000.0, 0.135], [122421000.0, 0.0182], [122429000.0, 0.0002], [122430000.0, 0.0248], [122436000.0, 0.0253], [122443000.0, 0.0], [122445000.0, 0.0036]]},
{"timestamp": "1743771526666", "bids": [[122382000.0, 0.0002], [122357000.0, 0.0024], [122352000.0, 0.0], [122350000.0, 0.0078], [122346000.0, 0.002], [122345000.0, 0.0002], [122344000.0, 0.0003], [122340000.0, 0.0001], [122337000.0, 0.0], [122335000.0, 0.0019]], "asks": [[122402000.0, 0.0242], [122404000.0, 0.0166], [122405000.0, 0.0234], [122406000.0, 0.0171], [122408000.0, 0.0147], [122409000.0, 0.0114], [122410000.0, 0.0196], [122417000.0, 0.0144], [122420000.0, 0.1532], [122421000.0, 0.0946]]},
{"timestamp": "1743771527167", "bids": [[122382000.0, 0.0002], [122357000.0, 0.0024], [122352000.0, 0.0], [122350000.0, 0.0078], [122346000.0, 0.002], [122345000.0, 0.0002], [122344000.0, 0.0003], [122340000.0, 0.0001], [122337000.0, 0.0], [122335000.0, 0.0019]], "asks": [[122388000.0, 0.0209], [122399000.0, 0.0001], [122402000.0, 0.0242], [122404000.0, 0.0166], [122406000.0, 0.0171], [122407000.0, 0.0126], [122408000.0, 0.0147], [122409000.0, 0.0114], [122410000.0, 0.0196], [122415000.0, 0.0148]]},
{"timestamp": "1743771527668", "bids": [[122357000.0, 0.0024], [122352000.0, 0.0], [122350000.0, 0.0078], [122346000.0, 0.002], [122345000.0, 0.0002], [122344000.0, 0.0003], [122337000.0, 0.0], [122335000.0, 0.0019], [122334000.0, 0.0], [122333000.0, 0.0]], "asks": [[122388000.0, 0.0209], [122399000.0, 0.0001], [122401000.0, 0.0764], [122402000.0, 0.0242], [122403000.0, 0.0182], [122406000.0, 0.0171], [122407000.0, 0.0126], [122412000.0, 0.0104], [122413000.0, 0.0271], [122416000.0, 0.0322]]},
{"timestamp": "1743771528165", "bids": [[122357000.0, 0.0024], [122352000.0, 0.0], [122350000.0, 0.0078], [122346000.0, 0.002], [122345000.0, 0.0002], [122344000.0, 0.0003], [122337000.0, 0.0], [122335000.0, 0.0019], [122334000.0, 0.0], [122333000.0, 0.0]], "asks": [[122388000.0, 0.0209], [122399000.0, 0.0001], [122402000.0, 0.0242], [122403000.0, 0.0182], [122404000.0, 0.0128], [122406000.0, 0.0315], [122407000.0, 0.0126], [122412000.0, 0.0104], [122413000.0, 0.0271], [122416000.0, 0.0322]]},
{"timestamp": "1743771528667", "bids": [[122357000.0, 0.0024], [122352000.0, 0.0], [122350000.0, 0.0078], [122346000.0, 0.002], [122345000.0, 0.0002], [122344000.0, 0.0003], [122337000.0, 0.0], [122335000.0, 0.0019], [122334000.0, 0.0], [122333000.0, 0.0]], "asks": [[122388000.0, 0.0149], [122399000.0, 0.0001], [122401000.0, 0.0764], [122402000.0, 0.0242], [122403000.0, 0.0182], [122404000.0, 0.0128], [122406000.0, 0.0315], [122407000.0, 0.0126], [122410000.0, 0.0148], [122412000.0, 0.1454]]},
{"timestamp": "1743771529167", "bids": [[122358000.0, 0.0159], [122357000.0, 0.0024], [122352000.0, 0.0], [122350000.0, 0.0078], [122346000.0, 0.002], [122345000.0, 0.0002], [122344000.0, 0.0003], [122337000.0, 0.0], [122335000.0, 0.0019], [122334000.0, 0.0]], "asks": [[122388000.0, 0.0149], [122401000.0, 0.0764], [122406000.0, 0.0144], [122417000.0, 0.0248], [122419000.0, 0.0496], [122420000.0, 0.0182], [122421000.0, 0.0187], [122423000.0, 0.035], [122424000.0, 0.0349], [122429000.0, 0.0002]]},
{"timestamp": "1743771529664", "bids": [[122358000.0, 0.0159], [122357000.0, 0.0024], [122352000.0, 0.0], [122350000.0, 0.0078], [122346000.0, 0.002], [122345000.0, 0.0002], [122344000.0, 0.0003], [122337000.0, 0.0], [122335000.0, 0.0019], [122334000.0, 0.0]], "asks": [[122388000.0, 0.0149], [122401000.0, 0.0764], [122406000.0, 0.0144], [122409000.0, 0.0166], [122417000.0, 0.0248], [122421000.0, 0.0016], [122424000.0, 0.0417], [122429000.0, 0.0002], [122432000.0, 0.0213], [122438000.0, 0.0186]]},
{"timestamp": "1743771530168", "bids": [[122359000.0, 0.0019], [122358000.0, 0.0136], [122357000.0, 0.0024], [122352000.0, 0.0], [122350000.0, 0.0078], [122346000.0, 0.002], [122345000.0, 0.0002], [122344000.0, 0.0003], [122341000.0, 0.0225], [122337000.0, 0.0]], "asks": [[122392000.0, 0.0166], [122393000.0, 0.0147], [122394000.0, 0.0114], [122397000.0, 0.0196], [122402000.0, 0.0242], [122403000.0, 0.0172], [122405000.0, 0.0764], [122406000.0, 0.0], [122415000.0, 0.0167], [122416000.0, 0.0128]]},
{"timestamp": "1743771530667", "bids": [[122358000.0, 0.0136], [122357000.0, 0.0024], [122352000.0, 0.0], [122350000.0, 0.0078], [122346000.0, 0.002], [122345000.0, 0.0002], [122344000.0, 0.0003], [122337000.0, 0.0], [122335000.0, 0.0019], [122334000.0, 0.0222]], "asks": [[122392000.0, 0.0166], [122393000.0, 0.0147], [122394000.0, 0.0114], [122397000.0, 0.0196], [122402000.0, 0.0242], [122403000.0, 0.0172], [122406000.0, 0.0], [122414000.0, 0.0764], [122415000.0, 0.0167], [122417000.0, 0.0404]]},
{"timestamp": "1743771531163", "bids": [[122375000.0, 0.0002], [122358000.0, 0.0136], [122357000.0, 0.0024], [122352000.0, 0.0], [122350000.0, 0.0078], [122346000.0, 0.002], [122345000.0, 0.0002], [122344000.0, 0.0003], [122337000.0, 0.0], [122335000.0, 0.0019]], "asks": [[122392000.0, 0.0166], [122393000.0, 0.0147], [122394000.0, 0.0114], [122397000.0, 0.0196], [122402000.0, 0.0242], [122403000.0, 0.0172], [122406000.0, 0.0], [122408000.0, 0.0149], [122414000.0, 0.0764], [122415000.0, 0.0167]]},
{"timestamp": "1743771531671", "bids": [[122375000.0, 0.0002], [122358000.0, 0.0136], [122357000.0, 0.0024], [122352000.0, 0.0], [122350000.0, 0.0078], [122346000.0, 0.002], [122345000.0, 0.0002], [122344000.0, 0.0003], [122337000.0, 0.0], [122335000.0, 0.0019]], "asks": [[122392000.0, 0.0166], [122393000.0, 0.0147], [122394000.0, 0.0114], [122397000.0, 0.0196], [122402000.0, 0.0242], [122403000.0, 0.0172], [122406000.0, 0.0], [122408000.0, 0.0149], [122415000.0, 0.0167], [122417000.0, 0.0404]]},
{"timestamp": "1743771532174", "bids": [[122375000.0, 0.0002], [122359000.0, 0.0239], [122358000.0, 0.0143], [122357000.0, 0.0024], [122352000.0, 0.0], [122350000.0, 0.0078], [122346000.0, 0.002], [122345000.0, 0.0002], [122344000.0, 0.0003], [122337000.0, 0.0]], "asks": [[122392000.0, 0.0166], [122393000.0, 0.0147], [122394000.0, 0.0114], [122397000.0, 0.0196], [122401000.0, 0.0056], [122402000.0, 0.0242], [122403000.0, 0.0172], [122406000.0, 0.0], [122408000.0, 0.0149], [122414000.0, 0.0764]]},
{"timestamp": "1743771532669", "bids": [[122375000.0, 0.0002], [122358000.0, 0.0625], [122357000.0, 0.0024], [122352000.0, 0.0], [122350000.0, 0.0078], [122346000.0, 0.002], [122345000.0, 0.0002], [122344000.0, 0.0003], [122337000.0, 0.0], [122335000.0, 0.0019]], "asks": [[122392000.0, 0.0166], [122393000.0, 0.0147], [122394000.0, 0.0114], [122397000.0, 0.0196], [122402000.0, 0.0242], [122403000.0, 0.0172], [122406000.0, 0.0], [122408000.0, 0.0149], [122415000.0, 0.0167], [122417000.0, 0.0404]]},
{"timestamp": "1743771533171", "bids": [[122375000.0, 0.0002], [122359000.0, 0.0254], [122358000.0, 0.069], [122357000.0, 0.0024], [122352000.0, 0.0], [122350000.0, 0.0078], [122346000.0, 0.002], [122345000.0, 0.0002], [122344000.0, 0.0003], [122337000.0, 0.0]], "asks": [[122392000.0, 0.0166], [122393000.0, 0.0147], [122394000.0, 0.0114], [122397000.0, 0.0196], [122402000.0, 0.0242], [122403000.0, 0.0172], [122406000.0, 0.0], [122408000.0, 0.0149], [122415000.0, 0.0167], [122417000.0, 0.0182]]},
{"timestamp": "1743771533665", "bids": [[122375000.0, 0.0002], [122359000.0, 0.0254], [122358000.0, 0.069], [122357000.0, 0.0024], [122352000.0, 0.0], [122350000.0, 0.0078], [122346000.0, 0.002], [122345000.0, 0.0002], [122344000.0, 0.0003], [122337000.0, 0.0]], "asks": [[122392000.0, 0.0166], [122393000.0, 0.0147], [122397000.0, 0.0196], [122406000.0, 0.0], [122421000.0, 0.0016], [122424000.0, 0.0128], [122425000.0, 0.0166], [122429000.0, 0.0002], [122434000.0, 0.0248], [122443000.0, 0.0]]},
{"timestamp": "1743771534170", "bids": [[122388000.0, 0.0], [122384000.0, 0.0], [122375000.0, 0.0002], [122357000.0, 0.0024], [122352000.0, 0.0], [122350000.0, 0.0078], [122348000.0, 0.0222], [122346000.0, 0.002], [122345000.0, 0.0002], [122344000.0, 0.0003]], "asks": [[122406000.0, 0.0], [122420000.0, 0.0171], [122421000.0, 0.0166], [122423000.0, 0.0114], [122425000.0, 0.0166], [122429000.0, 0.0002], [122434000.0, 0.0248], [122436000.0, 0.0182], [122439000.0, 0.0144], [122440000.0, 0.016]]},
{"timestamp": "1743771534672", "bids": [[122389000.0, 0.0842], [122388000.0, 0.0], [122384000.0, 0.0], [122375000.0, 0.0002], [122357000.0, 0.0024], [122352000.0, 0.0], [122350000.0, 0.0078], [122348000.0, 0.0222], [122346000.0, 0.002], [122345000.0, 0.0002]], "asks": [[122406000.0, 0.0], [122420000.0, 0.0166], [122421000.0, 0.0312], [122423000.0, 0.0114], [122426000.0, 0.0196], [122429000.0, 0.0002], [122433000.0, 0.0763], [122434000.0, 0.0104], [122436000.0, 0.0182], [122438000.0, 0.0128]]},
{"timestamp": "1743771535174", "bids": [[122389000.0, 0.153], [122388000.0, 0.0], [122384000.0, 0.0], [122375000.0, 0.0002], [122360000.0, 0.0002], [122357000.0, 0.0024], [122352000.0, 0.0], [122350000.0, 0.0078], [122346000.0, 0.002], [122345000.0, 0.0002]], "asks": [[122406000.0, 0.0], [122420000.0, 0.0166], [122421000.0, 0.0312], [122423000.0, 0.0114], [122426000.0, 0.0196], [122429000.0, 0.0002], [122431000.0, 0.0242], [122434000.0, 0.0104], [122435000.0, 0.0764], [122438000.0, 0.0128]]},
{"timestamp": "1743771535671", "bids": [[122388000.0, 0.0], [122384000.0, 0.0], [122375000.0, 0.0002], [122360000.0, 0.0002], [122357000.0, 0.0024], [122352000.0, 0.0049], [122350000.0, 0.0078], [122346000.0, 0.002], [122345000.0, 0.0002], [122344000.0, 0.0003]], "asks": [[122406000.0, 0.0], [122421000.0, 0.0163], [122429000.0, 0.0002], [122431000.0, 0.0242], [122432000.0, 0.0171], [122434000.0, 0.0105], [122435000.0, 0.0764], [122443000.0, 0.0124], [122445000.0, 0.0036], [122446000.0, 0.0016]]},
{"timestamp": "1743771536180", "bids": [[122390000.0, 0.0026], [122388000.0, 0.0], [122384000.0, 0.0], [122375000.0, 0.0002], [122360000.0, 0.0222], [122357000.0, 0.0024], [122352000.0, 0.0049], [122350000.0, 0.0078], [122346000.0, 0.002], [122345000.0, 0.0002]], "asks": [[122406000.0, 0.0], [122421000.0, 0.0016], [122429000.0, 0.0002], [122432000.0, 0.0171], [122434000.0, 0.0001], [122435000.0, 0.0764], [122443000.0, 0.0], [122445000.0, 0.0036], [122446000.0, 0.0016], [122449000.0, 0.0946]]},
{"timestamp": "1743771536668", "bids": [[122390000.0, 0.0041], [122388000.0, 0.0], [122384000.0, 0.0], [122375000.0, 0.0002], [122368000.0, 0.0026], [122360000.0, 0.0222], [122359000.0, 0.0074], [122357000.0, 0.0024], [122352000.0, 0.0049], [122351000.0, 0.005]], "asks": [[122406000.0, 0.0], [122421000.0, 0.0016], [122429000.0, 0.0002], [122438000.0, 0.0114], [122443000.0, 0.0], [122445000.0, 0.0036], [122446000.0, 0.0165], [122449000.0, 0.0946], [122453000.0, 0.0166], [122456000.0, 0.0617]]},
{"timestamp": "1743771537171", "bids": [[122390000.0, 0.0015], [122389000.0, 0.0022], [122388000.0, 0.0], [122384000.0, 0.0], [122375000.0, 0.0002], [122368000.0, 0.0026], [122360000.0, 0.006], [122359000.0, 0.0074], [122357000.0, 0.0024], [122354000.0, 0.0329]], "asks": [[122406000.0, 0.0], [122421000.0, 0.0016], [122429000.0, 0.0002], [122438000.0, 0.0114], [122443000.0, 0.0], [122445000.0, 0.0202], [122446000.0, 0.0165], [122447000.0, 0.0196], [122453000.0, 0.0166], [122457000.0, 0.0359]]},
{"timestamp": "1743771537668", "bids": [[122388000.0, 0.0], [122384000.0, 0.022], [122375000.0, 0.0002], [122360000.0, 0.0097], [122359000.0, 0.0074], [122357000.0, 0.0024], [122354000.0, 0.0329], [122352000.0, 0.0], [122351000.0, 0.1256], [122350000.0, 0.0078]], "asks": [[122406000.0, 0.0], [122421000.0, 0.0016], [122429000.0, 0.0002], [122438000.0, 0.0114], [122443000.0, 0.0], [122445000.0, 0.0966], [122446000.0, 0.0016], [122447000.0, 0.0196], [122457000.0, 0.0182], [122458000.0, 0.0147]]},
{"timestamp": "1743771538168", "bids": [[122388000.0, 0.0], [122386000.0, 0.0002], [122384000.0, 0.022], [122375000.0, 0.0002], [122369000.0, 0.0226], [122360000.0, 0.0037], [122357000.0, 0.0024], [122352000.0, 0.0], [122351000.0, 0.1094], [122350000.0, 0.0078]], "asks": [[122406000.0, 0.0], [122421000.0, 0.0016], [122429000.0, 0.0002], [122437000.0, 0.0764], [122443000.0, 0.0], [122445000.0, 0.08], [122446000.0, 0.0016], [122452000.0, 0.0148], [122453000.0, 0.0171], [122455000.0, 0.0001]]},
{"timestamp": "1743771538666", "bids": [[122388000.0, 0.0], [122386000.0, 0.0002], [122384000.0, 0.0], [122381000.0, 0.0002], [122375000.0, 0.0002], [122357000.0, 0.0024], [122352000.0, 0.0], [122351000.0, 0.0326], [122350000.0, 0.0078], [122348000.0, 0.0135]], "asks": [[122406000.0, 0.0], [122421000.0, 0.0016], [122425000.0, 0.0166], [122429000.0, 0.0002], [122431000.0, 0.0149], [122432000.0, 0.0114], [122437000.0, 0.0764], [122442000.0, 0.0294], [122443000.0, 0.0], [122444000.0, 0.0144]]},
{"timestamp": "1743771539172", "bids": [[122388000.0, 0.0], [122386000.0, 0.0002], [122384000.0, 0.0], [122375000.0, 0.0002], [122357000.0, 0.0024], [122352000.0, 0.0], [122351000.0, 0.0326], [122350000.0, 0.0078], [122348000.0, 0.0294], [122346000.0, 0.002]], "asks": [[122406000.0, 0.0], [122421000.0, 0.0016], [122425000.0, 0.0166], [122426000.0, 0.0147], [122429000.0, 0.0002], [122430000.0, 0.096], [122432000.0, 0.0114], [122434000.0, 0.0104], [122442000.0, 0.0294], [122443000.0, 0.0]]},
{"timestamp": "1743771539670", "bids": [[122388000.0, 0.0], [122386000.0, 0.0002], [122384000.0, 0.0], [122375000.0, 0.0002], [122357000.0, 0.0024], [122352000.0, 0.0], [122351000.0, 0.0326], [122350000.0, 0.0078], [122348000.0, 0.0294], [122346000.0, 0.002]], "asks": [[122406000.0, 0.0], [122421000.0, 0.0016], [122422000.0, 0.0149], [122424000.0, 0.0764], [122425000.0, 0.0166], [122426000.0, 0.0147], [122429000.0, 0.0002], [122430000.0, 0.0196], [122432000.0, 0.0114], [122434000.0, 0.0104]]},
{"timestamp": "1743771540169", "bids": [[122386000.0, 0.0002], [122384000.0, 0.0], [122375000.0, 0.0002], [122357000.0, 0.0024], [122352000.0, 0.0], [122351000.0, 0.0326], [122350000.0, 0.0078], [122348000.0, 0.0294], [122346000.0, 0.002], [122345000.0, 0.0364]], "asks": [[122388000.0, 0.0816], [122406000.0, 0.0], [122421000.0, 0.0016], [122422000.0, 0.0149], [122424000.0, 0.0764], [122425000.0, 0.0166], [122426000.0, 0.0147], [122429000.0, 0.0002], [122430000.0, 0.0196], [122432000.0, 0.0114]]},
{"timestamp": "1743771540664", "bids": [[122386000.0, 0.0002], [122384000.0, 0.0], [122375000.0, 0.0002], [122357000.0, 0.0024], [122352000.0, 0.0], [122351000.0, 0.0326], [122350000.0, 0.0078], [122348000.0, 0.0294], [122346000.0, 0.002], [122345000.0, 0.0364]], "asks": [[122388000.0, 0.0816], [122406000.0, 0.0], [122421000.0, 0.0779], [122422000.0, 0.0149], [122425000.0, 0.0166], [122426000.0, 0.0147], [122429000.0, 0.0002], [122430000.0, 0.0196], [122432000.0, 0.0114], [122434000.0, 0.0104]]},
{"timestamp": "1743771541174", "bids": [[122357000.0, 0.0024], [122352000.0, 0.0], [122351000.0, 0.0326], [122350000.0, 0.0078], [122348000.0, 0.0294], [122346000.0, 0.002], [122345000.0, 0.0364], [122344000.0, 0.0003], [122342000.0, 0.0026], [122340000.0, 0.0112]], "asks": [[122375000.0, 0.1276], [122387000.0, 0.0234], [122388000.0, 0.0816], [122406000.0, 0.0], [122421000.0, 0.0016], [122422000.0, 0.0149], [122425000.0, 0.0166], [122426000.0, 0.0147], [122429000.0, 0.0765], [122430000.0, 0.0196]]},
{"timestamp": "1743771541668", "bids": [[122357000.0, 0.0024], [122352000.0, 0.0], [122350000.0, 0.0078], [122348000.0, 0.0074], [122346000.0, 0.002], [122345000.0, 0.0002], [122344000.0, 0.0003], [122340000.0, 0.0112], [122337000.0, 0.0], [122336000.0, 0.005]], "asks": [[122375000.0, 0.1276], [122387000.0, 0.0234], [122388000.0, 0.0816], [122406000.0, 0.0], [122421000.0, 0.0779], [122425000.0, 0.0166], [122426000.0, 0.0147], [122429000.0, 0.0002], [122434000.0, 0.0104], [122438000.0, 0.035]]},
{"timestamp": "1743771542167", "bids": [[122357000.0, 0.0024], [122352000.0, 0.0], [122350000.0, 0.0078], [122346000.0, 0.002], [122345000.0, 0.0002], [122344000.0, 0.0003], [122337000.0, 0.0], [122335000.0, 0.0019], [122334000.0, 0.0], [122333000.0, 0.0]], "asks": [[122387000.0, 0.0234], [122388000.0, 0.0816], [122406000.0, 0.0], [122418000.0, 0.0242], [122421000.0, 0.0779], [122426000.0, 0.0147], [122429000.0, 0.0002], [122438000.0, 0.0222], [122440000.0, 0.033], [122442000.0, 0.0255]]},
{"timestamp": "1743771542669", "bids": [[122357000.0, 0.0024], [122352000.0, 0.0], [122350000.0, 0.0078], [122347000.0, 0.0002], [122346000.0, 0.002], [122345000.0, 0.0002], [122344000.0, 0.0003], [122337000.0, 0.0], [122335000.0, 0.0019], [122334000.0, 0.0]], "asks": [[122388000.0, 0.0816], [122399000.0, 0.0171], [122401000.0, 0.015], [122403000.0, 0.0114], [122406000.0, 0.0], [122413000.0, 0.0002], [122416000.0, 0.0182], [122418000.0, 0.0242], [122421000.0, 0.0945], [122422000.0, 0.0177]]},
{"timestamp": "1743771543178", "bids": [[122357000.0, 0.0024], [122352000.0, 0.0], [122350000.0, 0.0078], [122346000.0, 0.002], [122345000.0, 0.0002], [122344000.0, 0.0003], [122337000.0, 0.0], [122335000.0, 0.0019], [122334000.0, 0.0], [122333000.0, 0.0]], "asks": [[122388000.0, 0.0816], [122396000.0, 0.0166], [122399000.0, 0.0171], [122401000.0, 0.0001], [122403000.0, 0.0114], [122405000.0, 0.0196], [122406000.0, 0.0], [122410000.0, 0.0128], [122411000.0, 0.0144], [122412000.0, 0.0126]]},
{"timestamp": "1743771543674", "bids": [[122358000.0, 0.153], [122357000.0, 0.0024], [122352000.0, 0.0], [122350000.0, 0.0078], [122346000.0, 0.002], [122345000.0, 0.0002], [122344000.0, 0.0003], [122337000.0, 0.0], [122335000.0, 0.0019], [122334000.0, 0.0]], "asks": [[122388000.0, 0.0816], [122396000.0, 0.0166], [122401000.0, 0.0001], [122405000.0, 0.0196], [122406000.0, 0.0], [122410000.0, 0.0128], [122411000.0, 0.0144], [122413000.0, 0.0106], [122414000.0, 0.0182], [122415000.0, 0.0277]]},
{"timestamp": "1743771544187", "bids": [[122358000.0, 0.153], [122357000.0, 0.0024], [122352000.0, 0.0], [122350000.0, 0.0078], [122346000.0, 0.002], [122345000.0, 0.0002], [122344000.0, 0.0003], [122337000.0, 0.0], [122335000.0, 0.0019], [122334000.0, 0.0]], "asks": [[122388000.0, 0.0816], [122399000.0, 0.0242], [122403000.0, 0.0147], [122406000.0, 0.0], [122411000.0, 0.0149], [122415000.0, 0.0124], [122417000.0, 0.0171], [122421000.0, 0.0225], [122424000.0, 0.0327], [122426000.0, 0.0222]]},
{"timestamp": "1743771544669", "bids": [[122357000.0, 0.0024], [122352000.0, 0.0], [122350000.0, 0.0078], [122346000.0, 0.002], [122345000.0, 0.0002], [122344000.0, 0.0003], [122338000.0, 0.0222], [122337000.0, 0.0], [122335000.0, 0.0019], [122334000.0, 0.0]], "asks": [[122387000.0, 0.0056], [122388000.0, 0.0506], [122399000.0, 0.0242], [122403000.0, 0.0147], [122406000.0, 0.0], [122411000.0, 0.0149], [122415000.0, 0.0124], [122417000.0, 0.0171], [122421000.0, 0.0225], [122426000.0, 0.0222]]},
{"timestamp": "1743771545177", "bids": [[122357000.0, 0.0024], [122352000.0, 0.0], [122350000.0, 0.0078], [122346000.0, 0.002], [122345000.0, 0.0002], [122344000.0, 0.0003], [122341000.0, 0.022], [122338000.0, 0.0102], [122337000.0, 0.0], [122335000.0, 0.0019]], "asks": [[122387000.0, 0.0177], [122388000.0, 0.0506], [122399000.0, 0.0242], [122403000.0, 0.0147], [122406000.0, 0.0], [122415000.0, 0.0124], [122417000.0, 0.0171], [122421000.0, 0.0225], [122426000.0, 0.0222], [122428000.0, 0.033]]},
{"timestamp": "1743771545668", "bids": [[122357000.0, 0.0024], [122352000.0, 0.0], [122350000.0, 0.0078], [122346000.0, 0.002], [122345000.0, 0.0002], [122344000.0, 0.0003], [122338000.0, 0.0102], [122337000.0, 0.0], [122335000.0, 0.0019], [122334000.0, 0.0]], "asks": [[122387000.0, 0.0221], [122388000.0, 0.0506], [122396000.0, 0.0149], [122399000.0, 0.0242], [122403000.0, 0.0147], [122406000.0, 0.0], [122414000.0, 0.0766], [122415000.0, 0.025], [122417000.0, 0.0171], [122418000.0, 0.0148]]},
{"timestamp": "1743771546174", "bids": [[122357000.0, 0.0024], [122352000.0, 0.0], [122350000.0, 0.0078], [122346000.0, 0.002], [122345000.0, 0.0002], [122344000.0, 0.0003], [122338000.0, 0.0102], [122337000.0, 0.0], [122335000.0, 0.0019], [122334000.0, 0.0]], "asks": [[122387000.0, 0.0043], [122388000.0, 0.0506], [122396000.0, 0.0149], [122402000.0, 0.0173], [122406000.0, 0.0], [122413000.0, 0.0114], [122414000.0, 0.0766], [122415000.0, 0.0126], [122418000.0, 0.0148], [122419000.0, 0.0436]]},
{"timestamp": "1743771546671", "bids": [[122357000.0, 0.0024], [122352000.0, 0.0], [122350000.0, 0.0078], [122346000.0, 0.002], [122345000.0, 0.0002], [122344000.0, 0.0003], [122337000.0, 0.0], [122335000.0, 0.0019], [122334000.0, 0.0], [122333000.0, 0.0]], "asks": [[122388000.0, 0.0506], [122399000.0, 0.0242], [122402000.0, 0.0222], [122404000.0, 0.0001], [122406000.0, 0.0], [122407000.0, 0.0144], [122413000.0, 0.147], [122414000.0, 0.1037], [122421000.0, 0.0016], [122422000.0, 0.0443]]},
{"timestamp": "1743771547175", "bids": [[122357000.0, 0.0024], [122352000.0, 0.0], [122350000.0, 0.0078], [122346000.0, 0.002], [122345000.0, 0.0002], [122344000.0, 0.0003], [122337000.0, 0.0], [122335000.0, 0.0019], [122334000.0, 0.0], [122333000.0, 0.0]], "asks": [[122388000.0, 0.0506], [122390000.0, 0.0147], [122395000.0, 0.0766], [122399000.0, 0.0242], [122400000.0, 0.0196], [122401000.0, 0.0209], [122402000.0, 0.0222], [122403000.0, 0.0166], [122404000.0, 0.0001], [122406000.0, 0.0128]]},
{"timestamp": "1743771547673", "bids": [[122357000.0, 0.0024], [122352000.0, 0.0], [122350000.0, 0.0078], [122346000.0, 0.002], [122345000.0, 0.0002], [122344000.0, 0.0003], [122337000.0, 0.0], [122335000.0, 0.0019], [122334000.0, 0.0], [122333000.0, 0.0]], "asks": [[122387000.0, 0.0043], [122388000.0, 0.0506], [122390000.0, 0.0296], [122398000.0, 0.0766], [122399000.0, 0.0242], [122400000.0, 0.0196], [122401000.0, 0.0209], [122402000.0, 0.0222], [122403000.0, 0.0166], [122404000.0, 0.0001]]},
{"timestamp": "1743771548176", "bids": [[122325000.0, 0.0011], [122321000.0, 0.0], [122320000.0, 0.0001], [122319000.0, 0.0024], [122316000.0, 0.0231], [122314000.0, 0.0008], [122313000.0, 0.0003], [122310000.0, 0.0118], [122308000.0, 0.0365], [122304000.0, 0.0136]], "asks": [[122388000.0, 0.0506], [122390000.0, 0.0296], [122398000.0, 0.0766], [122399000.0, 0.0242], [122400000.0, 0.0196], [122401000.0, 0.0209], [122402000.0, 0.0222], [122403000.0, 0.0166], [122404000.0, 0.0001], [122406000.0, 0.0128]]},
{"timestamp": "1743771548668", "bids": [[122325000.0, 0.0011], [122321000.0, 0.0], [122320000.0, 0.0001], [122319000.0, 0.0024], [122316000.0, 0.0231], [122314000.0, 0.0008], [122313000.0, 0.0003], [122310000.0, 0.0092], [122308000.0, 0.0039], [122304000.0, 0.0136]], "asks": [[122386000.0, 0.035], [122388000.0, 0.0506], [122397000.0, 0.1347], [122398000.0, 0.0766], [122403000.0, 0.0166], [122406000.0, 0.0128], [122407000.0, 0.0144], [122409000.0, 0.0126], [122413000.0, 0.0433], [122414000.0, 0.033]]},
{"timestamp": "1743771549174", "bids": [[122325000.0, 0.0011], [122321000.0, 0.0], [122320000.0, 0.0001], [122319000.0, 0.0024], [122316000.0, 0.0011], [122314000.0, 0.0008], [122313000.0, 0.0003], [122310000.0, 0.0092], [122308000.0, 0.0039], [122304000.0, 0.0024]], "asks": [[122386000.0, 0.0339], [122387000.0, 0.0762], [122388000.0, 0.0506], [122397000.0, 0.1347], [122404000.0, 0.0166], [122406000.0, 0.0], [122409000.0, 0.0177], [122413000.0, 0.0248], [122415000.0, 0.0255], [122417000.0, 0.0124]]},
{"timestamp": "1743771549667", "bids": [[122325000.0, 0.0011], [122321000.0, 0.0], [122320000.0, 0.0001], [122319000.0, 0.0024], [122316000.0, 0.0009], [122314000.0, 0.0008], [122313000.0, 0.0003], [122310000.0, 0.0092], [122308000.0, 0.0039], [122304000.0, 0.0024]], "asks": [[122374000.0, 0.0261], [122375000.0, 0.0114], [122376000.0, 0.0196], [122377000.0, 0.0242], [122380000.0, 0.0222], [122385000.0, 0.0209], [122386000.0, 0.0173], [122387000.0, 0.0805], [122388000.0, 0.0556], [122389000.0, 0.0182]]},
{"timestamp": "1743771550173", "bids": [[122325000.0, 0.0011], [122321000.0, 0.0], [122320000.0, 0.0001], [122319000.0, 0.0024], [122316000.0, 0.0009], [122314000.0, 0.0008], [122313000.0, 0.0003], [122310000.0, 0.0092], [122308000.0, 0.0039], [122304000.0, 0.0249]], "asks": [[122373000.0, 0.0166], [122374000.0, 0.0261], [122375000.0, 0.0114], [122376000.0, 0.0196], [122377000.0, 0.0242], [122380000.0, 0.0222], [122385000.0, 0.0971], [122386000.0, 0.0173], [122388000.0, 0.0556], [122389000.0, 0.0182]]},
{"timestamp": "1743771550672", "bids": [[122325000.0, 0.0011], [122321000.0, 0.0], [122320000.0, 0.0001], [122319000.0, 0.0024], [122316000.0, 0.0009], [122314000.0, 0.0008], [122313000.0, 0.0003], [122310000.0, 0.0092], [122308000.0, 0.0039], [122304000.0, 0.0249]], "asks": [[122373000.0, 0.0166], [122374000.0, 0.026], [122375000.0, 0.0114], [122376000.0, 0.0196], [122377000.0, 0.0242], [122385000.0, 0.0209], [122388000.0, 0.0556], [122389000.0, 0.0182], [122390000.0, 0.0128], [122392000.0, 0.0374]]},
{"timestamp": "1743771551173", "bids": [[122326000.0, 0.1363], [122325000.0, 0.0011], [122324000.0, 0.022], [122321000.0, 0.0], [122320000.0, 0.0001], [122319000.0, 0.0024], [122316000.0, 0.0009], [122314000.0, 0.0008], [122313000.0, 0.0003], [122310000.0, 0.0092]], "asks": [[122374000.0, 0.0113], [122388000.0, 0.0556], [122397000.0, 0.0185], [122401000.0, 0.0171], [122405000.0, 0.0166], [122406000.0, 0.0], [122407000.0, 0.0179], [122408000.0, 0.033], [122409000.0, 0.0239], [122421000.0, 0.0016]]},
{"timestamp": "1743771551669", "bids": [[122326000.0, 0.1363], [122325000.0, 0.0011], [122324000.0, 0.022], [122321000.0, 0.0], [122320000.0, 0.0001], [122319000.0, 0.0024], [122316000.0, 0.0009], [122314000.0, 0.0008], [122313000.0, 0.0003], [122310000.0, 0.0092]], "asks": [[122372000.0, 0.0043], [122385000.0, 0.0124], [122388000.0, 0.0306], [122396000.0, 0.0277], [122397000.0, 0.0001], [122399000.0, 0.0114], [122400000.0, 0.0242], [122401000.0, 0.0171], [122403000.0, 0.0222], [122406000.0, 0.0]]},
{"timestamp": "1743771552172", "bids": [[122325000.0, 0.0011], [122321000.0, 0.0], [122320000.0, 0.0001], [122319000.0, 0.0024], [122316000.0, 0.0009], [122314000.0, 0.0008], [122313000.0, 0.0003], [122310000.0, 0.0317], [122308000.0, 0.0065], [122307000.0, 0.0002]], "asks": [[122372000.0, 0.0043], [122376000.0, 0.0196], [122385000.0, 0.0124], [122387000.0, 0.0166], [122388000.0, 0.0453], [122396000.0, 0.0277], [122397000.0, 0.0001], [122399000.0, 0.0323], [122400000.0, 0.1004], [122401000.0, 0.0171]]},
{"timestamp": "1743771552668", "bids": [[122325000.0, 0.0011], [122321000.0, 0.0], [122320000.0, 0.0001], [122319000.0, 0.0024], [122316000.0, 0.0009], [122314000.0, 0.0228], [122313000.0, 0.0003], [122310000.0, 0.0317], [122309000.0, 0.0048], [122308000.0, 0.0065]], "asks": [[122376000.0, 0.0196], [122385000.0, 0.0124], [122387000.0, 0.0166], [122388000.0, 0.0591], [122395000.0, 0.0761], [122396000.0, 0.0277], [122397000.0, 0.0001], [122399000.0, 0.0323], [122400000.0, 0.0242], [122401000.0, 0.0171]]},
{"timestamp": "1743771553173", "bids": [[122325000.0, 0.0011], [122321000.0, 0.0], [122320000.0, 0.0001], [122319000.0, 0.0024], [122316000.0, 0.0009], [122314000.0, 0.0228], [122313000.0, 0.0003], [122310000.0, 0.0317], [122309000.0, 0.0048], [122308000.0, 0.0065]], "asks": [[122376000.0, 0.0196], [122385000.0, 0.0124], [122387000.0, 0.0166], [122388000.0, 0.0591], [122396000.0, 0.0277], [122397000.0, 0.0001], [122399000.0, 0.0323], [122400000.0, 0.0242], [122401000.0, 0.0171], [122403000.0, 0.0404]]},
{"timestamp": "1743771553674", "bids": [[122325000.0, 0.0011], [122321000.0, 0.0], [122320000.0, 0.0001], [122319000.0, 0.0024], [122316000.0, 0.0009], [122314000.0, 0.0228], [122313000.0, 0.0003], [122310000.0, 0.0317], [122308000.0, 0.0065], [122307000.0, 0.0002]], "asks": [[122376000.0, 0.0196], [122385000.0, 0.0124], [122387000.0, 0.0166], [122388000.0, 0.0591], [122395000.0, 0.0761], [122396000.0, 0.0277], [122397000.0, 0.0001], [122399000.0, 0.0323], [122400000.0, 0.0242], [122401000.0, 0.0171]]},
{"timestamp": "1743771554175", "bids": [[122325000.0, 0.0011], [122321000.0, 0.0], [122320000.0, 0.0001], [122319000.0, 0.0024], [122316000.0, 0.0009], [122314000.0, 0.0228], [122313000.0, 0.0003], [122310000.0, 0.0317], [122308000.0, 0.0065], [122307000.0, 0.005]], "asks": [[122376000.0, 0.0196], [122384000.0, 0.0761], [122385000.0, 0.0124], [122387000.0, 0.0166], [122388000.0, 0.0591], [122396000.0, 0.0277], [122397000.0, 0.0001], [122399000.0, 0.0323], [122400000.0, 0.0242], [122401000.0, 0.0171]]},
{"timestamp": "1743771554674", "bids": [[122310000.0, 0.0062], [122308000.0, 0.0065], [122307000.0, 0.005], [122304000.0, 0.0024], [122302000.0, 0.0338], [122301000.0, 0.0026], [122300000.0, 0.0349], [122298000.0, 0.0097], [122297000.0, 0.0], [122296000.0, 0.0016]], "asks": [[122376000.0, 0.0196], [122384000.0, 0.0761], [122385000.0, 0.0124], [122387000.0, 0.0166], [122388000.0, 0.0591], [122396000.0, 0.0277], [122397000.0, 0.0001], [122399000.0, 0.0323], [122400000.0, 0.0242], [122401000.0, 0.0171]]},
{"timestamp": "1743771555173", "bids": [[122310000.0, 0.0062], [122308000.0, 0.0065], [122307000.0, 0.0002], [122304000.0, 0.0249], [122302000.0, 0.0112], [122301000.0, 0.0026], [122300000.0, 0.0349], [122298000.0, 0.0097], [122297000.0, 0.0], [122296000.0, 0.0016]], "asks": [[122375000.0, 0.021], [122376000.0, 0.0196], [122384000.0, 0.0761], [122385000.0, 0.0124], [122388000.0, 0.0591], [122396000.0, 0.0104], [122404000.0, 0.0128], [122406000.0, 0.0], [122407000.0, 0.0179], [122408000.0, 0.033]]},
{"timestamp": "1743771555672", "bids": [[122312000.0, 0.0001], [122310000.0, 0.0062], [122308000.0, 0.0039], [122304000.0, 0.0249], [122301000.0, 0.0026], [122300000.0, 0.0349], [122299000.0, 0.0226], [122298000.0, 0.0097], [122297000.0, 0.0], [122296000.0, 0.0857]], "asks": [[122375000.0, 0.021], [122385000.0, 0.027], [122386000.0, 0.0761], [122388000.0, 0.0444], [122396000.0, 0.0104], [122403000.0, 0.0144], [122406000.0, 0.0], [122407000.0, 0.0377], [122412000.0, 0.0271], [122417000.0, 0.0007]]},
{"timestamp": "1743771556176", "bids": [[122310000.0, 0.0127], [122308000.0, 0.0039], [122305000.0, 0.0843], [122304000.0, 0.0249], [122301000.0, 0.0026], [122300000.0, 0.0349], [122298000.0, 0.0097], [122297000.0, 0.0], [122296000.0, 0.0016], [122295000.0, 0.0091]], "asks": [[122357000.0, 0.0001], [122385000.0, 0.027], [122386000.0, 0.0173], [122387000.0, 0.0166], [122388000.0, 0.0445], [122389000.0, 0.0114], [122390000.0, 0.0242], [122394000.0, 0.0222], [122399000.0, 0.0209], [122403000.0, 0.0326]]},
{"timestamp": "1743771556671", "bids": [[122316000.0, 0.0002], [122313000.0, 0.1021], [122310000.0, 0.0153], [122308000.0, 0.0039], [122305000.0, 0.0843], [122304000.0, 0.0249], [122302000.0, 0.0112], [122301000.0, 0.0026], [122300000.0, 0.0349], [122298000.0, 0.0097]], "asks": [[122376000.0, 0.0196], [122385000.0, 0.005], [122387000.0, 0.0166], [122388000.0, 0.0591], [122389000.0, 0.0114], [122393000.0, 0.0124], [122399000.0, 0.0209], [122403000.0, 0.0182], [122406000.0, 0.0358], [122407000.0, 0.0762]]},
{"timestamp": "1743771557173", "bids": [[122323000.0, 0.0001], [122316000.0, 0.0002], [122313000.0, 0.1554], [122311000.0, 0.0226], [122310000.0, 0.0088], [122308000.0, 0.0039], [122304000.0, 0.0249], [122302000.0, 0.0112], [122301000.0, 0.0869], [122300000.0, 0.0349]], "asks": [[122376000.0, 0.0196], [122388000.0, 0.0591], [122389000.0, 0.0114], [122393000.0, 0.0886], [122399000.0, 0.0209], [122403000.0, 0.0182], [122406000.0, 0.0104], [122407000.0, 0.0762], [122410000.0, 0.0556], [122412000.0, 0.0176]]},
{"timestamp": "1743771557673", "bids": [[122323000.0, 0.0005], [122317000.0, 0.0026], [122316000.0, 0.0002], [122311000.0, 0.0226], [122310000.0, 0.0424], [122308000.0, 0.0039], [122304000.0, 0.0249], [122301000.0, 0.0026], [122300000.0, 0.0349], [122298000.0, 0.0343]], "asks": [[122376000.0, 0.0196], [122388000.0, 0.0444], [122396000.0, 0.0266], [122406000.0, 0.0104], [122413000.0, 0.0128], [122414000.0, 0.0144], [122415000.0, 0.0126], [122418000.0, 0.033], [122419000.0, 0.0436], [122421000.0, 0.0287]]},
{"timestamp": "1743771558175", "bids": [[122324000.0, 0.0584], [122323000.0, 0.0005], [122317000.0, 0.0026], [122314000.0, 0.0843], [122310000.0, 0.0424], [122308000.0, 0.0039], [122304000.0, 0.0249], [122301000.0, 0.0026], [122300000.0, 0.0597], [122298000.0, 0.0343]], "asks": [[122388000.0, 0.0444], [122396000.0, 0.005], [122403000.0, 0.0242], [122405000.0, 0.0762], [122406000.0, 0.0326], [122413000.0, 0.089], [122414000.0, 0.0144], [122419000.0, 0.0185], [122421000.0, 0.0193], [122422000.0, 0.0148]]},
{"timestamp": "1743771558676", "bids": [[122324000.0, 0.0584], [122314000.0, 0.0843], [122310000.0, 0.0424], [122308000.0, 0.0039], [122306000.0, 0.0074], [122304000.0, 0.0249], [122303000.0, 0.0016], [122301000.0, 0.0026], [122300000.0, 0.0597], [122298000.0, 0.0303]], "asks": [[122388000.0, 0.0134], [122398000.0, 0.0173], [122400000.0, 0.0001], [122401000.0, 0.0114], [122403000.0, 0.0242], [122405000.0, 0.0762], [122406000.0, 0.0222], [122411000.0, 0.0209], [122413000.0, 0.0762], [122415000.0, 0.0182]]},
{"timestamp": "1743771559177", "bids": [[122341000.0, 0.0004], [122329000.0, 0.0226], [122317000.0, 0.004], [122314000.0, 0.0955], [122311000.0, 0.0329], [122310000.0, 0.0424], [122308000.0, 0.0039], [122306000.0, 0.0075], [122304000.0, 0.0249], [122301000.0, 0.0277]], "asks": [[122388000.0, 0.0134], [122398000.0, 0.0173], [122399000.0, 0.0166], [122400000.0, 0.0148], [122401000.0, 0.0114], [122403000.0, 0.0242], [122405000.0, 0.0886], [122406000.0, 0.0222], [122411000.0, 0.0209], [122413000.0, 0.0762]]},
{"timestamp": "1743771559674", "bids": [[122341000.0, 0.0007], [122335000.0, 0.0026], [122329000.0, 0.0226], [122327000.0, 0.0173], [122317000.0, 0.0246], [122314000.0, 0.0112], [122311000.0, 0.0329], [122310000.0, 0.0062], [122308000.0, 0.0039], [122307000.0, 0.0846]], "asks": [[122388000.0, 0.0134], [122398000.0, 0.0173], [122399000.0, 0.0166], [122400000.0, 0.0914], [122401000.0, 0.0114], [122403000.0, 0.0438], [122405000.0, 0.0124], [122406000.0, 0.0222], [122411000.0, 0.0209], [122414000.0, 0.0266]]},
{"timestamp": "1743771560175", "bids": [[122341000.0, 0.0007], [122335000.0, 0.0026], [122329000.0, 0.0226], [122327000.0, 0.0173], [122317000.0, 0.0245], [122314000.0, 0.0112], [122311000.0, 0.0329], [122310000.0, 0.0062], [122308000.0, 0.0039], [122307000.0, 0.0846]], "asks": [[122388000.0, 0.0134], [122397000.0, 0.0766], [122398000.0, 0.0173], [122399000.0, 0.0166], [122400000.0, 0.0148], [122401000.0, 0.0114], [122403000.0, 0.0438], [122405000.0, 0.0124], [122406000.0, 0.0222], [122411000.0, 0.0209]]},
{"timestamp": "1743771560672", "bids": [[122341000.0, 0.0007], [122327000.0, 0.0173], [122317000.0, 0.004], [122314000.0, 0.0112], [122311000.0, 0.0329], [122310000.0, 0.0062], [122308000.0, 0.0039], [122306000.0, 0.0323], [122304000.0, 0.0249], [122301000.0, 0.0026]], "asks": [[122387000.0, 0.0043], [122388000.0, 0.0134], [122397000.0, 0.0766], [122399000.0, 0.0166], [122400000.0, 0.0147], [122403000.0, 0.0196], [122406000.0, 0.0], [122411000.0, 0.0209], [122414000.0, 0.0266], [122418000.0, 0.023]]},
{"timestamp": "1743771561176", "bids": [[122318000.0, 0.0226], [122310000.0, 0.0062], [122308000.0, 0.0039], [122306000.0, 0.0001], [122304000.0, 0.0249], [122301000.0, 0.0026], [122300000.0, 0.0349], [122298000.0, 0.0097], [122297000.0, 0.0], [122296000.0, 0.0016]], "asks": [[122387000.0, 0.0801], [122388000.0, 0.0134], [122406000.0, 0.0], [122418000.0, 0.0166], [122421000.0, 0.0016], [122424000.0, 0.0148], [122427000.0, 0.033], [122428000.0, 0.0213], [122429000.0, 0.0002], [122437000.0, 0.0]]},
{"timestamp": "1743771561673", "bids": [[122342000.0, 0.1529], [122329000.0, 0.0003], [122323000.0, 0.0026], [122319000.0, 0.0112], [122315000.0, 0.0846], [122308000.0, 0.0017], [122304000.0, 0.0495], [122301000.0, 0.0026], [122300000.0, 0.0349], [122298000.0, 0.0097]], "asks": [[122388000.0, 0.0134], [122402000.0, 0.0001], [122406000.0, 0.0], [122408000.0, 0.0124], [122413000.0, 0.1354], [122414000.0, 0.0104], [122418000.0, 0.0166], [122420000.0, 0.0144], [122421000.0, 0.0142], [122423000.0, 0.0177]]},
{"timestamp": "1743771562173", "bids": [[122343000.0, 0.004], [122342000.0, 0.0369], [122329000.0, 0.0007], [122323000.0, 0.0026], [122319000.0, 0.0112], [122308000.0, 0.0017], [122304000.0, 0.0454], [122301000.0, 0.0026], [122300000.0, 0.0349], [122298000.0, 0.0097]], "asks": [[122386000.0, 0.0202], [122387000.0, 0.0764], [122388000.0, 0.0134], [122402000.0, 0.0198], [122406000.0, 0.0], [122408000.0, 0.0124], [122413000.0, 0.1354], [122414000.0, 0.0104], [122418000.0, 0.0294], [122420000.0, 0.0144]]},
{"timestamp": "1743771562678", "bids": [[122343000.0, 0.0114], [122340000.0, 0.004], [122338000.0, 0.0011], [122329000.0, 0.0005], [122319000.0, 0.0112], [122308000.0, 0.0017], [122304000.0, 0.0024], [122301000.0, 0.0388], [122300000.0, 0.0349], [122298000.0, 0.0097]], "asks": [[122369000.0, 0.0], [122386000.0, 0.0202], [122387000.0, 0.0764], [122388000.0, 0.0134], [122402000.0, 0.0001], [122403000.0, 0.0226], [122405000.0, 0.0173], [122406000.0, 0.0], [122408000.0, 0.0242], [122412000.0, 0.0222]]},
{"timestamp": "1743771563185", "bids": [[122343000.0, 0.011], [122340000.0, 0.004], [122338000.0, 0.0011], [122329000.0, 0.0005], [122319000.0, 0.0112], [122308000.0, 0.0346], [122305000.0, 0.0326], [122304000.0, 0.0024], [122301000.0, 0.0388], [122300000.0, 0.108]], "asks": [[122369000.0, 0.0], [122388000.0, 0.0134], [122401000.0, 0.2117], [122403000.0, 0.0226], [122405000.0, 0.0173], [122406000.0, 0.0], [122407000.0, 0.0114], [122408000.0, 0.0242], [122410000.0, 0.0166], [122412000.0, 0.0222]]},
{"timestamp": "1743771563674", "bids": [[122343000.0, 0.0063], [122340000.0, 0.004], [122338000.0, 0.0011], [122329000.0, 0.0001], [122321000.0, 0.0112], [122313000.0, 0.0026], [122312000.0, 0.0074], [122310000.0, 0.0], [122308000.0, 0.0346], [122305000.0, 0.0326]], "asks": [[122368000.0, 0.0001], [122369000.0, 0.0], [122388000.0, 0.0134], [122400000.0, 0.0196], [122401000.0, 0.2117], [122403000.0, 0.0226], [122405000.0, 0.0173], [122406000.0, 0.0], [122407000.0, 0.0114], [122410000.0, 0.0166]]},
{"timestamp": "1743771564200", "bids": [[122344000.0, 0.0666], [122343000.0, 0.0006], [122341000.0, 0.0225], [122321000.0, 0.0112], [122319000.0, 0.0002], [122314000.0, 0.0001], [122313000.0, 0.0026], [122312000.0, 0.0074], [122310000.0, 0.0], [122308000.0, 0.0346]], "asks": [[122368000.0, 0.0001], [122369000.0, 0.0], [122388000.0, 0.0134], [122395000.0, 0.0197], [122400000.0, 0.0196], [122401000.0, 0.2117], [122406000.0, 0.0], [122407000.0, 0.0114], [122410000.0, 0.0166], [122414000.0, 0.0171]]},
{"timestamp": "1743771564675", "bids": [[122344000.0, 0.1136], [122341000.0, 0.0225], [122321000.0, 0.0112], [122319000.0, 0.0002], [122316000.0, 0.0247], [122314000.0, 0.0001], [122313000.0, 0.0026], [122312000.0, 0.0074], [122310000.0, 0.0], [122308000.0, 0.0346]], "asks": [[122368000.0, 0.0001], [122369000.0, 0.0], [122388000.0, 0.0134], [122395000.0, 0.0197], [122400000.0, 0.0196], [122401000.0, 0.2117], [122406000.0, 0.0766], [122407000.0, 0.0114], [122410000.0, 0.0166], [122414000.0, 0.0338]]},
{"timestamp": "1743771565179", "bids": [[122344000.0, 0.1094], [122341000.0, 0.0225], [122338000.0, 0.0002], [122321000.0, 0.0112], [122319000.0, 0.0002], [122316000.0, 0.0247], [122314000.0, 0.0001], [122313000.0, 0.0026], [122312000.0, 0.0074], [122310000.0, 0.0]], "asks": [[122388000.0, 0.0116], [122395000.0, 0.0197], [122396000.0, 0.0016], [122406000.0, 0.0766], [122414000.0, 0.0338], [122415000.0, 0.0104], [122416000.0, 0.0179], [122417000.0, 0.0124], [122421000.0, 0.0338], [122423000.0, 0.017]]},
{"timestamp": "1743771565677", "bids": [[122368000.0, 0.0001], [122357000.0, 0.0362], [122345000.0, 0.0098], [122344000.0, 0.0986], [122338000.0, 0.0002], [122316000.0, 0.0247], [122310000.0, 0.0], [122308000.0, 0.0017], [122306000.0, 0.0845], [122304000.0, 0.025]], "asks": [[122396000.0, 0.0015], [122406000.0, 0.0766], [122414000.0, 0.0167], [122415000.0, 0.0104], [122416000.0, 0.0179], [122417000.0, 0.0124], [122421000.0, 0.0338], [122423000.0, 0.017], [122429000.0, 0.0002], [122431000.0, 0.0001]]},
{"timestamp": "1743771566191", "bids": [[122369000.0, 0.0], [122368000.0, 0.0001], [122357000.0, 0.0362], [122351000.0, 0.0004], [122345000.0, 0.0131], [122344000.0, 0.0517], [122338000.0, 0.0002], [122310000.0, 0.0], [122308000.0, 0.0017], [122306000.0, 0.0845]], "asks": [[122396000.0, 0.0015], [122406000.0, 0.0766], [122417000.0, 0.0124], [122418000.0, 0.0], [122421000.0, 0.0016], [122429000.0, 0.0005], [122431000.0, 0.0001], [122432000.0, 0.0008], [122436000.0, 0.0], [122437000.0, 0.0]]},
{"timestamp": "1743771566682", "bids": [[122412000.0, 0.0038], [122362000.0, 0.0329], [122361000.0, 0.0326], [122357000.0, 0.0322], [122351000.0, 0.0004], [122345000.0, 0.0976], [122344000.0, 0.0142], [122338000.0, 0.0002], [122310000.0, 0.0], [122308000.0, 0.0017]], "asks": [[122418000.0, 0.0], [122421000.0, 0.0016], [122429000.0, 0.0005], [122430000.0, 0.0], [122431000.0, 0.0001], [122432000.0, 0.0008], [122436000.0, 0.0], [122437000.0, 0.0], [122442000.0, 0.0001], [122443000.0, 0.0]]},
{"timestamp": "1743771567188", "bids": [[122412000.0, 0.0038], [122386000.0, 0.0026], [122382000.0, 0.0306], [122373000.0, 0.0074], [122369000.0, 0.0028], [122367000.0, 0.0244], [122366000.0, 0.0225], [122362000.0, 0.0329], [122361000.0, 0.0326], [122359000.0, 0.0246]], "asks": [[122445000.0, 0.0023], [122446000.0, 0.0016], [122447000.0, 0.0041], [122448000.0, 0.0002], [122450000.0, 0.0032], [122453000.0, 0.0215], [122455000.0, 0.0], [122459000.0, 0.0], [122460000.0, 0.0003], [122463000.0, 0.0016]]},
{"timestamp": "1743771567676", "bids": [[122412000.0, 0.0038], [122397000.0, 0.0002], [122386000.0, 0.0074], [122382000.0, 0.0306], [122373000.0, 0.0074], [122372000.0, 0.0001], [122370000.0, 0.0078], [122369000.0, 0.0027], [122367000.0, 0.0244], [122366000.0, 0.0225]], "asks": [[122445000.0, 0.0022], [122446000.0, 0.0016], [122447000.0, 0.0041], [122448000.0, 0.0002], [122450000.0, 0.0032], [122453000.0, 0.0215], [122455000.0, 0.0], [122459000.0, 0.0], [122460000.0, 0.0003], [122463000.0, 0.0016]]},
{"timestamp": "1743771568175", "bids": [[122412000.0, 0.0038], [122397000.0, 0.0002], [122386000.0, 0.0048], [122382000.0, 0.0306], [122373000.0, 0.0074], [122372000.0, 0.0001], [122370000.0, 0.0078], [122367000.0, 0.0013], [122363000.0, 0.0844], [122362000.0, 0.0003]], "asks": [[122445000.0, 0.0022], [122446000.0, 0.0016], [122447000.0, 0.0041], [122448000.0, 0.0002], [122450000.0, 0.0032], [122453000.0, 0.0019], [122455000.0, 0.0], [122459000.0, 0.0], [122460000.0, 0.0003], [122463000.0, 0.0016]]},
{"timestamp": "1743771568677", "bids": [[122412000.0, 0.0038], [122397000.0, 0.0002], [122386000.0, 0.0048], [122383000.0, 0.0844], [122382000.0, 0.0306], [122373000.0, 0.0074], [122367000.0, 0.0013], [122362000.0, 0.0002], [122361000.0, 0.0001], [122358000.0, 0.0322]], "asks": [[122445000.0, 0.0022], [122446000.0, 0.0016], [122447000.0, 0.0041], [122448000.0, 0.0002], [122450000.0, 0.0032], [122453000.0, 0.0019], [122455000.0, 0.0], [122459000.0, 0.0], [122460000.0, 0.0008], [122463000.0, 0.0016]]},
{"timestamp": "1743771569184", "bids": [[122383000.0, 0.0622], [122367000.0, 0.0013], [122361000.0, 0.033], [122356000.0, 0.0026], [122351000.0, 0.0004], [122345000.0, 0.0059], [122344000.0, 0.0001], [122343000.0, 0.0225], [122340000.0, 0.0251], [122337000.0, 0.0243]], "asks": [[122445000.0, 0.0022], [122446000.0, 0.0016], [122447000.0, 0.0041], [122448000.0, 0.0002], [122449000.0, 0.0196], [122450000.0, 0.0032], [122453000.0, 0.0019], [122455000.0, 0.0], [122458000.0, 0.0251], [122459000.0, 0.0]]},
{"timestamp": "1743771569680", "bids": [[122367000.0, 0.0013], [122361000.0, 0.0329], [122359000.0, 0.0844], [122356000.0, 0.0026], [122351000.0, 0.0004], [122345000.0, 0.0059], [122343000.0, 0.0225], [122340000.0, 0.0326], [122337000.0, 0.0245], [122329000.0, 0.0717]], "asks": [[122445000.0, 0.0022], [122446000.0, 0.0016], [122447000.0, 0.0041], [122448000.0, 0.0002], [122449000.0, 0.0196], [122450000.0, 0.0214], [122453000.0, 0.0249], [122454000.0, 0.0126], [122455000.0, 0.0], [122457000.0, 0.0148]]},
{"timestamp": "1743771570188", "bids": [[122367000.0, 0.0013], [122361000.0, 0.0329], [122356000.0, 0.0026], [122352000.0, 0.0048], [122351000.0, 0.0004], [122344000.0, 0.0832], [122343000.0, 0.0225], [122340000.0, 0.0326], [122337000.0, 0.0246], [122329000.0, 0.0717]], "asks": [[122435000.0, 0.0221], [122445000.0, 0.0022], [122446000.0, 0.0016], [122447000.0, 0.0041], [122448000.0, 0.0848], [122449000.0, 0.0196], [122450000.0, 0.0214], [122452000.0, 0.0128], [122453000.0, 0.0393], [122454000.0, 0.0126]]},
{"timestamp": "1743771570676", "bids": [[122367000.0, 0.0013], [122361000.0, 0.0329], [122356000.0, 0.0026], [122351000.0, 0.0004], [122344000.0, 0.0832], [122343000.0, 0.0225], [122340000.0, 0.0326], [122337000.0, 0.0246], [122329000.0, 0.0717], [122327000.0, 0.0249]], "asks": [[122435000.0, 0.0221], [122445000.0, 0.0022], [122446000.0, 0.0016], [122447000.0, 0.0041], [122448000.0, 0.0848], [122449000.0, 0.0196], [122450000.0, 0.0214], [122452000.0, 0.0128], [122453000.0, 0.0393], [122454000.0, 0.0126]]},
{"timestamp": "1743771571187", "bids": [[122367000.0, 0.0013], [122361000.0, 0.0329], [122356000.0, 0.0026], [122351000.0, 0.0004], [122347000.0, 0.0842], [122346000.0, 0.0221], [122343000.0, 0.0225], [122340000.0, 0.0326], [122337000.0, 0.0246], [122329000.0, 0.0717]], "asks": [[122435000.0, 0.0221], [122445000.0, 0.0022], [122446000.0, 0.0016], [122447000.0, 0.0041], [122448000.0, 0.0848], [122449000.0, 0.0196], [122450000.0, 0.0214], [122452000.0, 0.0128], [122453000.0, 0.0393], [122454000.0, 0.0126]]},
{"timestamp": "1743771571681", "bids": [[122387000.0, 0.0024], [122367000.0, 0.0013], [122361000.0, 0.0329], [122356000.0, 0.0026], [122351000.0, 0.0004], [122346000.0, 0.0221], [122344000.0, 0.0842], [122343000.0, 0.0225], [122340000.0, 0.0326], [122337000.0, 0.0246]], "asks": [[122434000.0, 0.0202], [122435000.0, 0.0221], [122445000.0, 0.0022], [122446000.0, 0.0016], [122447000.0, 0.0041], [122448000.0, 0.0848], [122449000.0, 0.1549], [122450000.0, 0.0214], [122452000.0, 0.0128], [122453000.0, 0.0393]]},
{"timestamp": "1743771572188", "bids": [[122387000.0, 0.0024], [122367000.0, 0.0013], [122356000.0, 0.0026], [122344000.0, 0.0842], [122343000.0, 0.0225], [122337000.0, 0.0246], [122333000.0, 0.0], [122329000.0, 0.0717], [122327000.0, 0.0246], [122321000.0, 0.0323]], "asks": [[122427000.0, 0.0173], [122434000.0, 0.0202], [122435000.0, 0.0222], [122445000.0, 0.0188], [122446000.0, 0.0016], [122447000.0, 0.0041], [122448000.0, 0.0002], [122450000.0, 0.0209], [122452000.0, 0.0128], [122453000.0, 0.0019]]},
{"timestamp": "1743771572684", "bids": [[122387000.0, 0.0024], [122367000.0, 0.0013], [122344000.0, 0.0306], [122343000.0, 0.0225], [122341000.0, 0.0842], [122338000.0, 0.0221], [122337000.0, 0.0243], [122335000.0, 0.0074], [122333000.0, 0.0], [122329000.0, 0.0717]], "asks": [[122427000.0, 0.0212], [122428000.0, 0.0168], [122429000.0, 0.0006], [122431000.0, 0.0114], [122434000.0, 0.1012], [122435000.0, 0.0222], [122441000.0, 0.0209], [122445000.0, 0.0188], [122446000.0, 0.0016], [122447000.0, 0.0041]]},
{"timestamp": "1743771573183", "bids": [[122387000.0, 0.0024], [122367000.0, 0.0013], [122350000.0, 0.0026], [122344000.0, 0.0306], [122343000.0, 0.0225], [122339000.0, 0.0842], [122335000.0, 0.0074], [122333000.0, 0.0], [122331000.0, 0.0245], [122329000.0, 0.0717]], "asks": [[122422000.0, 0.004], [122427000.0, 0.0212], [122428000.0, 0.0168], [122429000.0, 0.0226], [122431000.0, 0.0114], [122433000.0, 0.0846], [122434000.0, 0.0124], [122435000.0, 0.0222], [122441000.0, 0.0209], [122442000.0, 0.0104]]},
{"timestamp": "1743771573681", "bids": [[122387000.0, 0.0024], [122367000.0, 0.0013], [122350000.0, 0.0026], [122346000.0, 0.0048], [122344000.0, 0.0306], [122335000.0, 0.0074], [122333000.0, 0.0], [122332000.0, 0.0842], [122331000.0, 0.0246], [122329000.0, 0.0717]], "asks": [[122422000.0, 0.004], [122427000.0, 0.0212], [122428000.0, 0.0168], [122429000.0, 0.0226], [122431000.0, 0.0114], [122433000.0, 0.0846], [122434000.0, 0.0124], [122435000.0, 0.0222], [122441000.0, 0.0209], [122442000.0, 0.0104]]},
{"timestamp": "1743771574180", "bids": [[122387000.0, 0.0024], [122367000.0, 0.0013], [122346000.0, 0.0048], [122344000.0, 0.0306], [122335000.0, 0.0074], [122333000.0, 0.0], [122332000.0, 0.0842], [122331000.0, 0.0245], [122329000.0, 0.0717], [122325000.0, 0.0329]], "asks": [[122418000.0, 0.0226], [122420000.0, 0.0242], [122422000.0, 0.004], [122430000.0, 0.0846], [122432000.0, 0.0182], [122438000.0, 0.0182], [122445000.0, 0.0022], [122446000.0, 0.0016], [122447000.0, 0.0193], [122448000.0, 0.0255]]},
{"timestamp": "1743771574683", "bids": [[122387000.0, 0.0024], [122367000.0, 0.0013], [122342000.0, 0.0225], [122338000.0, 0.0026], [122333000.0, 0.0], [122332000.0, 0.0842], [122329000.0, 0.0717], [122320000.0, 0.0001], [122310000.0, 0.0016], [122309000.0, 0.0001]], "asks": [[122406000.0, 0.0196], [122418000.0, 0.0447], [122420000.0, 0.0242], [122422000.0, 0.0044], [122423000.0, 0.0124], [122430000.0, 0.0104], [122432000.0, 0.0182], [122433000.0, 0.0846], [122434000.0, 0.0128], [122436000.0, 0.023]]},
{"timestamp": "1743771575186", "bids": [[122387000.0, 0.0024], [122367000.0, 0.0013], [122342000.0, 0.0225], [122338000.0, 0.0026], [122337000.0, 0.0048], [122333000.0, 0.0], [122332000.0, 0.0194], [122329000.0, 0.0717], [122320000.0, 0.0245], [122310000.0, 0.0016]], "asks": [[122406000.0, 0.0196], [122418000.0, 0.0447], [122419000.0, 0.0846], [122420000.0, 0.0242], [122422000.0, 0.0044], [122423000.0, 0.0124], [122430000.0, 0.0104], [122432000.0, 0.0182], [122434000.0, 0.0128], [122435000.0, 0.0144]]},
{"timestamp": "1743771575682", "bids": [[122387000.0, 0.0024], [122367000.0, 0.0013], [122342000.0, 0.0225], [122338000.0, 0.0026], [122337000.0, 0.0048], [122333000.0, 0.0], [122332000.0, 0.0194], [122330000.0, 0.0842], [122329000.0, 0.0717], [122320000.0, 0.0246]], "asks": [[122406000.0, 0.0196], [122418000.0, 0.0447], [122420000.0, 0.0242], [122422000.0, 0.0044], [122423000.0, 0.0124], [122429000.0, 0.0846], [122430000.0, 0.0104], [122432000.0, 0.0182], [122434000.0, 0.0128], [122435000.0, 0.0144]]},
{"timestamp": "1743771576182", "bids": [[122387000.0, 0.0024], [122367000.0, 0.0013], [122342000.0, 0.0225], [122338000.0, 0.0026], [122333000.0, 0.0], [122332000.0, 0.0194], [122329000.0, 0.0717], [122321000.0, 0.0842], [122320000.0, 0.0246], [122313000.0, 0.0003]], "asks": [[122405000.0, 0.0035], [122406000.0, 0.0196], [122418000.0, 0.0447], [122419000.0, 0.0846], [122420000.0, 0.0242], [122422000.0, 0.0044], [122423000.0, 0.0124], [122430000.0, 0.0104], [122432000.0, 0.0182], [122434000.0, 0.0128]]},
{"timestamp": "1743771576678", "bids": [[122387000.0, 0.0024], [122367000.0, 0.0013], [122342000.0, 0.0225], [122338000.0, 0.0026], [122333000.0, 0.0842], [122332000.0, 0.0194], [122329000.0, 0.0717], [122327000.0, 0.0225], [122320000.0, 0.0246], [122313000.0, 0.0003]], "asks": [[122405000.0, 0.0035], [122406000.0, 0.0196], [122418000.0, 0.0447], [122420000.0, 0.0242], [122422000.0, 0.0044], [122423000.0, 0.0124], [122430000.0, 0.0104], [122432000.0, 0.0182], [122434000.0, 0.0128], [122435000.0, 0.0144]]},
{"timestamp": "1743771577192", "bids": [[122387000.0, 0.0024], [122367000.0, 0.0013], [122342000.0, 0.0225], [122338000.0, 0.0026], [122333000.0, 0.0], [122332000.0, 0.0194], [122330000.0, 0.0842], [122329000.0, 0.0717], [122327000.0, 0.0225], [122320000.0, 0.0246]], "asks": [[122406000.0, 0.0196], [122418000.0, 0.0447], [122420000.0, 0.0242], [122422000.0, 0.0044], [122423000.0, 0.0124], [122429000.0, 0.0846], [122430000.0, 0.0104], [122432000.0, 0.0182], [122434000.0, 0.0128], [122435000.0, 0.0144]]},
{"timestamp": "1743771577685", "bids": [[122387000.0, 0.0024], [122367000.0, 0.0013], [122342000.0, 0.0225], [122338000.0, 0.0026], [122336000.0, 0.0225], [122333000.0, 0.0842], [122332000.0, 0.0194], [122329000.0, 0.0717], [122320000.0, 0.0246], [122313000.0, 0.0003]], "asks": [[122406000.0, 0.0196], [122418000.0, 0.0226], [122420000.0, 0.0242], [122422000.0, 0.0044], [122423000.0, 0.0124], [122430000.0, 0.0104], [122432000.0, 0.0182], [122434000.0, 0.0128], [122436000.0, 0.023], [122437000.0, 0.0126]]},
{"timestamp": "1743771578180", "bids": [[122387000.0, 0.0024], [122367000.0, 0.0013], [122343000.0, 0.0842], [122342000.0, 0.0225], [122336000.0, 0.0225], [122333000.0, 0.0], [122332000.0, 0.0194], [122329000.0, 0.0717], [122320000.0, 0.0245], [122314000.0, 0.0322]], "asks": [[122406000.0, 0.0196], [122418000.0, 0.0226], [122419000.0, 0.0001], [122422000.0, 0.004], [122423000.0, 0.0297], [122425000.0, 0.0222], [122432000.0, 0.0182], [122434000.0, 0.0128], [122435000.0, 0.0166], [122436000.0, 0.023]]},
{"timestamp": "1743771578679", "bids": [[122387000.0, 0.0024], [122367000.0, 0.0013], [122346000.0, 0.0026], [122342000.0, 0.0225], [122339000.0, 0.0112], [122337000.0, 0.0842], [122336000.0, 0.0225], [122333000.0, 0.0], [122329000.0, 0.0717], [122328000.0, 0.0001]], "asks": [[122419000.0, 0.0004], [122420000.0, 0.0114], [122422000.0, 0.0079], [122423000.0, 0.0341], [122426000.0, 0.0447], [122428000.0, 0.0242], [122430000.0, 0.0209], [122431000.0, 0.0846], [122435000.0, 0.0166], [122440000.0, 0.052]]},
{"timestamp": "1743771579182", "bids": [[122387000.0, 0.0024], [122367000.0, 0.0013], [122346000.0, 0.0026], [122344000.0, 0.0048], [122343000.0, 0.0842], [122342000.0, 0.0225], [122339000.0, 0.0112], [122334000.0, 0.0], [122333000.0, 0.0], [122329000.0, 0.0717]], "asks": [[122420000.0, 0.0112], [122422000.0, 0.0079], [122423000.0, 0.0341], [122426000.0, 0.0447], [122430000.0, 0.0209], [122435000.0, 0.0166], [122438000.0, 0.0104], [122439000.0, 0.0846], [122440000.0, 0.0702], [122441000.0, 0.0236]]},
{"timestamp": "1743771579684", "bids": [[122387000.0, 0.0024], [122367000.0, 0.0013], [122346000.0, 0.0026], [122344000.0, 0.0048], [122342000.0, 0.0225], [122340000.0, 0.0842], [122339000.0, 0.0112], [122334000.0, 0.0], [122333000.0, 0.0], [122329000.0, 0.0717]], "asks": [[122420000.0, 0.0112], [122422000.0, 0.004], [122426000.0, 0.0221], [122435000.0, 0.0222], [122439000.0, 0.0846], [122441000.0, 0.0236], [122442000.0, 0.0179], [122445000.0, 0.0022], [122446000.0, 0.0016], [122447000.0, 0.0197]]},
{"timestamp": "1743771580186", "bids": [[122387000.0, 0.0024], [122367000.0, 0.0013], [122344000.0, 0.0246], [122343000.0, 0.0842], [122342000.0, 0.0225], [122337000.0, 0.0002], [122334000.0, 0.0], [122333000.0, 0.0], [122331000.0, 0.0246], [122329000.0, 0.0717]], "asks": [[122417000.0, 0.0196], [122422000.0, 0.004], [122427000.0, 0.0039], [122429000.0, 0.0222], [122432000.0, 0.0242], [122434000.0, 0.0124], [122435000.0, 0.0222], [122445000.0, 0.0022], [122446000.0, 0.099], [122447000.0, 0.0193]]},
{"timestamp": "1743771580684", "bids": [[122387000.0, 0.0024], [122367000.0, 0.0013], [122350000.0, 0.0026], [122344000.0, 0.0246], [122343000.0, 0.0842], [122342000.0, 0.0225], [122337000.0, 0.0002], [122334000.0, 0.0], [122333000.0, 0.0], [122331000.0, 0.0246]], "asks": [[122417000.0, 0.0196], [122422000.0, 0.004], [122427000.0, 0.0039], [122429000.0, 0.0222], [122432000.0, 0.0242], [122434000.0, 0.097], [122435000.0, 0.0222], [122445000.0, 0.0022], [122446000.0, 0.0144], [122447000.0, 0.0193]]},
{"timestamp": "1743771581184", "bids": [[122387000.0, 0.0024], [122367000.0, 0.0013], [122350000.0, 0.0026], [122344000.0, 0.0246], [122337000.0, 0.0002], [122334000.0, 0.0], [122333000.0, 0.0], [122332000.0, 0.0842], [122331000.0, 0.0246], [122329000.0, 0.0717]], "asks": [[122417000.0, 0.0195], [122422000.0, 0.004], [122427000.0, 0.0039], [122428000.0, 0.0846], [122429000.0, 0.0222], [122432000.0, 0.0242], [122434000.0, 0.0124], [122435000.0, 0.0222], [122445000.0, 0.0022], [122446000.0, 0.0144]]},
{"timestamp": "1743771581682", "bids": [[122387000.0, 0.0024], [122367000.0, 0.0013], [122350000.0, 0.0026], [122344000.0, 0.0198], [122337000.0, 0.0002], [122334000.0, 0.0], [122333000.0, 0.0], [122332000.0, 0.0842], [122331000.0, 0.0246], [122329000.0, 0.0717]], "asks": [[122417000.0, 0.0195], [122422000.0, 0.004], [122427000.0, 0.0039], [122428000.0, 0.0846], [122429000.0, 0.0222], [122432000.0, 0.0242], [122434000.0, 0.0124], [122435000.0, 0.0222], [122445000.0, 0.0022], [122446000.0, 0.0144]]},
{"timestamp": "1743771582195", "bids": [[122387000.0, 0.0024], [122367000.0, 0.0013], [122341000.0, 0.0274], [122339000.0, 0.0112], [122334000.0, 0.0], [122333000.0, 0.0], [122332000.0, 0.0842], [122329000.0, 0.0717], [122326000.0, 0.0001], [122320000.0, 0.0655]], "asks": [[122422000.0, 0.004], [122423000.0, 0.0341], [122424000.0, 0.0226], [122428000.0, 0.0846], [122430000.0, 0.0008], [122432000.0, 0.0024], [122436000.0, 0.0209], [122439000.0, 0.0182], [122440000.0, 0.0166], [122445000.0, 0.0204]]},
{"timestamp": "1743771582684", "bids": [[122388000.0, 0.1135], [122387000.0, 0.0024], [122367000.0, 0.0013], [122345000.0, 0.0026], [122341000.0, 0.0274], [122339000.0, 0.031], [122334000.0, 0.0], [122333000.0, 0.0], [122332000.0, 0.0842], [122330000.0, 0.0074]], "asks": [[122412000.0, 0.0195], [122422000.0, 0.004], [122423000.0, 0.0341], [122424000.0, 0.0226], [122426000.0, 0.0113], [122430000.0, 0.0132], [122432000.0, 0.0024], [122436000.0, 0.0209], [122437000.0, 0.0104], [122439000.0, 0.0182]]},
{"timestamp": "1743771583194", "bids": [[122388000.0, 0.1289], [122387000.0, 0.0024], [122367000.0, 0.0013], [122345000.0, 0.0026], [122341000.0, 0.0274], [122339000.0, 0.0198], [122334000.0, 0.0], [122333000.0, 0.0], [122332000.0, 0.0842], [122331000.0, 0.0243]], "asks": [[122412000.0, 0.0195], [122422000.0, 0.004], [122426000.0, 0.0113], [122429000.0, 0.0221], [122430000.0, 0.0132], [122431000.0, 0.0242], [122432000.0, 0.0024], [122435000.0, 0.0222], [122437000.0, 0.0104], [122441000.0, 0.0128]]},
{"timestamp": "1743771583684", "bids": [[122387000.0, 0.0024], [122367000.0, 0.0013], [122341000.0, 0.0274], [122339000.0, 0.0198], [122337000.0, 0.0002], [122334000.0, 0.0], [122333000.0, 0.0], [122331000.0, 0.0244], [122330000.0, 0.0916], [122329000.0, 0.0717]], "asks": [[122412000.0, 0.0195], [122422000.0, 0.0886], [122426000.0, 0.0113], [122427000.0, 0.0039], [122429000.0, 0.1068], [122430000.0, 0.0132], [122431000.0, 0.0242], [122432000.0, 0.0024], [122435000.0, 0.0222], [122437000.0, 0.0104]]},
{"timestamp": "1743771584204", "bids": [[122387000.0, 0.0024], [122367000.0, 0.0013], [122350000.0, 0.0026], [122342000.0, 0.0842], [122341000.0, 0.0225], [122339000.0, 0.0198], [122337000.0, 0.0002], [122334000.0, 0.0], [122333000.0, 0.0], [122331000.0, 0.0246]], "asks": [[122412000.0, 0.0195], [122422000.0, 0.004], [122426000.0, 0.0113], [122427000.0, 0.0039], [122429000.0, 0.0222], [122430000.0, 0.0132], [122431000.0, 0.0242], [122432000.0, 0.0024], [122435000.0, 0.0222], [122437000.0, 0.0104]]},
{"timestamp": "1743771584688", "bids": [[122387000.0, 0.0024], [122367000.0, 0.0013], [122350000.0, 0.0026], [122345000.0, 0.0048], [122341000.0, 0.0225], [122340000.0, 0.0842], [122339000.0, 0.0198], [122337000.0, 0.0002], [122334000.0, 0.0], [122333000.0, 0.0]], "asks": [[122412000.0, 0.0192], [122422000.0, 0.004], [122426000.0, 0.0113], [122427000.0, 0.0039], [122429000.0, 0.1068], [122430000.0, 0.0132], [122431000.0, 0.0242], [122432000.0, 0.0024], [122435000.0, 0.0222], [122437000.0, 0.0104]]},
{"timestamp": "1743771585184", "bids": [[122387000.0, 0.0024], [122367000.0, 0.0013], [122350000.0, 0.0026], [122345000.0, 0.0048], [122341000.0, 0.0225], [122339000.0, 0.0198], [122337000.0, 0.0002], [122334000.0, 0.0], [122333000.0, 0.0], [122332000.0, 0.0842]], "asks": [[122412000.0, 0.0192], [122422000.0, 0.004], [122426000.0, 0.0113], [122427000.0, 0.0039], [122428000.0, 0.0846], [122429000.0, 0.0222], [122430000.0, 0.0132], [122431000.0, 0.0242], [122432000.0, 0.0024], [122435000.0, 0.0222]]},
{"timestamp": "1743771585690", "bids": [[122387000.0, 0.0024], [122367000.0, 0.0013], [122342000.0, 0.0842], [122341000.0, 0.0225], [122339000.0, 0.0198], [122337000.0, 0.0002], [122334000.0, 0.0], [122333000.0, 0.0], [122331000.0, 0.0246], [122330000.0, 0.0074]], "asks": [[122412000.0, 0.0192], [122422000.0, 0.004], [122426000.0, 0.0113], [122427000.0, 0.0039], [122429000.0, 0.0222], [122430000.0, 0.0132], [122431000.0, 0.0242], [122432000.0, 0.0024], [122435000.0, 0.0222], [122437000.0, 0.0104]]},
{"timestamp": "1743771586181", "bids": [[122387000.0, 0.0024], [122367000.0, 0.0013], [122351000.0, 0.0048], [122342000.0, 0.0842], [122341000.0, 0.0225], [122337000.0, 0.0002], [122334000.0, 0.0], [122333000.0, 0.0], [122331000.0, 0.0244], [122330000.0, 0.0074]], "asks": [[122422000.0, 0.004], [122426000.0, 0.0113], [122430000.0, 0.0181], [122432000.0, 0.0024], [122444000.0, 0.0846], [122445000.0, 0.0138], [122446000.0, 0.0016], [122447000.0, 0.0193], [122448000.0, 0.0168], [122450000.0, 0.0032]]},
{"timestamp": "1743771586685", "bids": [[122387000.0, 0.0024], [122367000.0, 0.0013], [122353000.0, 0.0026], [122351000.0, 0.0048], [122347000.0, 0.0112], [122342000.0, 0.0842], [122341000.0, 0.0225], [122334000.0, 0.0], [122333000.0, 0.0], [122328000.0, 0.0655]], "asks": [[122399000.0, 0.0002], [122412000.0, 0.0], [122422000.0, 0.004], [122426000.0, 0.0113], [122430000.0, 0.0181], [122431000.0, 0.0168], [122432000.0, 0.025], [122435000.0, 0.0242], [122444000.0, 0.0209], [122445000.0, 0.0984]]},
{"timestamp": "1743771587188", "bids": [[122388000.0, 0.1675], [122387000.0, 0.0024], [122376000.0, 0.0198], [122367000.0, 0.0013], [122362000.0, 0.0246], [122359000.0, 0.0002], [122353000.0, 0.0277], [122351000.0, 0.0048], [122347000.0, 0.0112], [122342000.0, 0.0842]], "asks": [[122399000.0, 0.0002], [122412000.0, 0.0], [122420000.0, 0.0193], [122422000.0, 0.004], [122430000.0, 0.0008], [122432000.0, 0.025], [122435000.0, 0.0242], [122437000.0, 0.0124], [122444000.0, 0.0209], [122445000.0, 0.0984]]},
{"timestamp": "1743771587685", "bids": [[122388000.0, 0.1724], [122387000.0, 0.0024], [122378000.0, 0.0245], [122376000.0, 0.0198], [122373000.0, 0.0075], [122367000.0, 0.0013], [122362000.0, 0.0246], [122348000.0, 0.0842], [122347000.0, 0.0061], [122344000.0, 0.0002]], "asks": [[122399000.0, 0.0002], [122412000.0, 0.0], [122420000.0, 0.0193], [122422000.0, 0.004], [122430000.0, 0.0008], [122432000.0, 0.0024], [122437000.0, 0.0124], [122445000.0, 0.0138], [122446000.0, 0.0016], [122447000.0, 0.0088]]},
{"timestamp": "1743771588186", "bids": [[122393000.0, 0.0026], [122388000.0, 0.0076], [122387000.0, 0.0024], [122379000.0, 0.0002], [122378000.0, 0.0245], [122373000.0, 0.0316], [122367000.0, 0.0013], [122362000.0, 0.0001], [122357000.0, 0.0469], [122348000.0, 0.0842]], "asks": [[122399000.0, 0.0002], [122412000.0, 0.0], [122422000.0, 0.004], [122430000.0, 0.0008], [122432000.0, 0.0024], [122445000.0, 0.0138], [122446000.0, 0.0016], [122447000.0, 0.0049], [122448000.0, 0.0002], [122450000.0, 0.0032]]},
{"timestamp": "1743771588684", "bids": [[122393000.0, 0.0026], [122388000.0, 0.0269], [122387000.0, 0.0136], [122379000.0, 0.0002], [122378000.0, 0.0245], [122373000.0, 0.0074], [122369000.0, 0.0655], [122367000.0, 0.0013], [122366000.0, 0.0002], [122363000.0, 0.0322]], "asks": [[122399000.0, 0.0002], [122412000.0, 0.0], [122422000.0, 0.004], [122430000.0, 0.0008], [122432000.0, 0.0024], [122445000.0, 0.0138], [122446000.0, 0.0016], [122447000.0, 0.0049], [122448000.0, 0.0002], [122450000.0, 0.0032]]},
{"timestamp": "1743771589189", "bids": [[122388000.0, 0.0076], [122387000.0, 0.0136], [122379000.0, 0.0002], [122378000.0, 0.0245], [122376000.0, 0.0245], [122373000.0, 0.0074], [122371000.0, 0.0082], [122369000.0, 0.0655], [122367000.0, 0.0013], [122366000.0, 0.0247]], "asks": [[122399000.0, 0.0002], [122412000.0, 0.0], [122422000.0, 0.004], [122430000.0, 0.0008], [122432000.0, 0.0024], [122445000.0, 0.0138], [122446000.0, 0.0016], [122447000.0, 0.0049], [122448000.0, 0.0002], [122450000.0, 0.0032]]},
{"timestamp": "1743771589686", "bids": [[122395000.0, 0.0023], [122388000.0, 0.0124], [122387000.0, 0.0136], [122379000.0, 0.0002], [122378000.0, 0.0245], [122376000.0, 0.0245], [122373000.0, 0.0074], [122371000.0, 0.0082], [122369000.0, 0.0655], [122367000.0, 0.0013]], "asks": [[122450000.0, 0.0022], [122453000.0, 0.0019], [122455000.0, 0.0], [122459000.0, 0.0], [122460000.0, 0.0003], [122461000.0, 0.0833], [122462000.0, 0.0193], [122463000.0, 0.0016], [122468000.0, 0.002], [122470000.0, 0.0]]},
{"timestamp": "1743771590188", "bids": [[122395000.0, 0.0023], [122388000.0, 0.0124], [122387000.0, 0.0136], [122379000.0, 0.0848], [122378000.0, 0.0245], [122376000.0, 0.0245], [122373000.0, 0.0074], [122369000.0, 0.0655], [122367000.0, 0.0013], [122366000.0, 0.0249]], "asks": [[122450000.0, 0.0022], [122453000.0, 0.0019], [122455000.0, 0.0], [122459000.0, 0.0], [122460000.0, 0.0003], [122462000.0, 0.0193], [122463000.0, 0.0016], [122468000.0, 0.002], [122470000.0, 0.0], [122471000.0, 0.1022]]},
{"timestamp": "1743771590682", "bids": [[122395000.0, 0.0023], [122387000.0, 0.0136], [122379000.0, 0.0002], [122376000.0, 0.0245], [122373000.0, 0.0074], [122370000.0, 0.0845], [122369000.0, 0.0655], [122367000.0, 0.0013], [122366000.0, 0.0249], [122363000.0, 0.0322]], "asks": [[122450000.0, 0.0022], [122453000.0, 0.0019], [122455000.0, 0.0], [122459000.0, 0.0], [122460000.0, 0.0003], [122462000.0, 0.0193], [122463000.0, 0.0016], [122468000.0, 0.002], [122470000.0, 0.0833], [122471000.0, 0.0189]]},
{"timestamp": "1743771591186", "bids": [[122395000.0, 0.0023], [122388000.0, 0.0048], [122387000.0, 0.0024], [122379000.0, 0.0002], [122376000.0, 0.0002], [122373000.0, 0.0074], [122367000.0, 0.0858], [122366000.0, 0.0247], [122360000.0, 0.0323], [122351000.0, 0.0255]], "asks": [[122450000.0, 0.0022], [122453000.0, 0.0019], [122455000.0, 0.0], [122459000.0, 0.0], [122460000.0, 0.0003], [122461000.0, 0.0833], [122463000.0, 0.0016], [122468000.0, 0.002], [122470000.0, 0.0833], [122471000.0, 0.0016]]},
{"timestamp": "1743771591683", "bids": [[122388000.0, 0.0048], [122387000.0, 0.0024], [122381000.0, 0.0198], [122378000.0, 0.0225], [122373000.0, 0.0074], [122367000.0, 0.0858], [122358000.0, 0.0002], [122352000.0, 0.0251], [122350000.0, 0.0361], [122347000.0, 0.0119]], "asks": [[122450000.0, 0.0022], [122453000.0, 0.0019], [122455000.0, 0.0], [122459000.0, 0.0], [122460000.0, 0.0003], [122461000.0, 0.0833], [122463000.0, 0.0016], [122464000.0, 0.0039], [122466000.0, 0.0222], [122468000.0, 0.002]]},
{"timestamp": "1743771592183", "bids": [[122387000.0, 0.0047], [122381000.0, 0.0198], [122378000.0, 0.0225], [122373000.0, 0.0074], [122368000.0, 0.0246], [122367000.0, 0.0013], [122358000.0, 0.0248], [122353000.0, 0.0845], [122352000.0, 0.0251], [122350000.0, 0.0361]], "asks": [[122450000.0, 0.0022], [122453000.0, 0.0019], [122454000.0, 0.0193], [122455000.0, 0.0], [122459000.0, 0.0], [122460000.0, 0.0003], [122463000.0, 0.0016], [122464000.0, 0.0039], [122465000.0, 0.0833], [122466000.0, 0.0222]]},
{"timestamp": "1743771592683", "bids": [[122395000.0, 0.0], [122387000.0, 0.0048], [122382000.0, 0.0048], [122381000.0, 0.0198], [122378000.0, 0.0225], [122373000.0, 0.0074], [122370000.0, 0.0], [122368000.0, 0.0246], [122367000.0, 0.0013], [122359000.0, 0.0845]], "asks": [[122450000.0, 0.0022], [122453000.0, 0.0019], [122454000.0, 0.0193], [122455000.0, 0.0], [122459000.0, 0.0], [122460000.0, 0.0003], [122463000.0, 0.0016], [122464000.0, 0.0039], [122465000.0, 0.0833], [122466000.0, 0.0222]]},
{"timestamp": "1743771593188", "bids": [[122395000.0, 0.0], [122387000.0, 0.0048], [122381000.0, 0.0198], [122378000.0, 0.0225], [122373000.0, 0.0074], [122370000.0, 0.0], [122368000.0, 0.0246], [122367000.0, 0.0013], [122359000.0, 0.0845], [122358000.0, 0.0249]], "asks": [[122450000.0, 0.0022], [122453000.0, 0.0019], [122454000.0, 0.0193], [122455000.0, 0.0], [122459000.0, 0.0], [122460000.0, 0.0003], [122463000.0, 0.0016], [122464000.0, 0.0039], [122465000.0, 0.0833], [122466000.0, 0.0222]]},
{"timestamp": "1743771593687", "bids": [[122395000.0, 0.0], [122387000.0, 0.0048], [122377000.0, 0.0048], [122373000.0, 0.0074], [122370000.0, 0.0], [122367000.0, 0.0013], [122359000.0, 0.0845], [122358000.0, 0.0248], [122352000.0, 0.0323], [122347000.0, 0.0119]], "asks": [[122450000.0, 0.0022], [122453000.0, 0.0019], [122455000.0, 0.0], [122459000.0, 0.0], [122460000.0, 0.0176], [122463000.0, 0.0016], [122464000.0, 0.0242], [122465000.0, 0.0833], [122468000.0, 0.002], [122470000.0, 0.0]]},
{"timestamp": "1743771594383", "bids": [[122395000.0, 0.0], [122387000.0, 0.0024], [122377000.0, 0.0048], [122376000.0, 0.0112], [122370000.0, 0.02], [122367000.0, 0.0013], [122359000.0, 0.0845], [122358000.0, 0.09], [122352000.0, 0.0322], [122347000.0, 0.012]], "asks": [[122450000.0, 0.0215], [122453000.0, 0.0019], [122454000.0, 0.0039], [122455000.0, 0.0], [122456000.0, 0.0221], [122459000.0, 0.0833], [122460000.0, 0.0176], [122461000.0, 0.0168], [122462000.0, 0.0227], [122463000.0, 0.0129]]},
{"timestamp": "1743771594686", "bids": [[122395000.0, 0.0], [122387000.0, 0.0024], [122376000.0, 0.0112], [122370000.0, 0.0221], [122367000.0, 0.0013], [122359000.0, 0.0845], [122358000.0, 0.0899], [122352000.0, 0.0322], [122347000.0, 0.012], [122345000.0, 0.0707]], "asks": [[122449000.0, 0.0202], [122450000.0, 0.0215], [122453000.0, 0.0019], [122454000.0, 0.0039], [122455000.0, 0.0], [122456000.0, 0.0221], [122459000.0, 0.0833], [122460000.0, 0.0176], [122461000.0, 0.0168], [122462000.0, 0.0227]]},
{"timestamp": "1743771595189", "bids": [[122395000.0, 0.0], [122387000.0, 0.0024], [122379000.0, 0.0225], [122370000.0, 0.0221], [122367000.0, 0.0013], [122365000.0, 0.0048], [122362000.0, 0.0074], [122358000.0, 0.0244], [122353000.0, 0.0845], [122352000.0, 0.0001]], "asks": [[122448000.0, 0.0832], [122449000.0, 0.0202], [122450000.0, 0.0022], [122453000.0, 0.0019], [122455000.0, 0.0], [122459000.0, 0.0], [122460000.0, 0.0003], [122463000.0, 0.0016], [122468000.0, 0.0268], [122469000.0, 0.0126]]},
{"timestamp": "1743771595690", "bids": [[122395000.0, 0.0], [122387000.0, 0.0024], [122370000.0, 0.0222], [122367000.0, 0.0013], [122365000.0, 0.0048], [122363000.0, 0.0845], [122362000.0, 0.0074], [122357000.0, 0.0002], [122353000.0, 0.0845], [122352000.0, 0.0002]], "asks": [[122449000.0, 0.0221], [122450000.0, 0.0022], [122453000.0, 0.0019], [122455000.0, 0.0], [122459000.0, 0.0], [122460000.0, 0.0003], [122463000.0, 0.0016], [122467000.0, 0.0832], [122468000.0, 0.0268], [122469000.0, 0.0126]]},
{"timestamp": "1743771596187", "bids": [[122395000.0, 0.0], [122387000.0, 0.0024], [122370000.0, 0.0222], [122367000.0, 0.0013], [122365000.0, 0.0048], [122363000.0, 0.0845], [122362000.0, 0.0074], [122357000.0, 0.0002], [122352000.0, 0.0245], [122347000.0, 0.0119]], "asks": [[122449000.0, 0.0221], [122450000.0, 0.0022], [122453000.0, 0.0019], [122455000.0, 0.0], [122459000.0, 0.0], [122460000.0, 0.0003], [122463000.0, 0.0016], [122466000.0, 0.0128], [122467000.0, 0.0832], [122468000.0, 0.0268]]},
{"timestamp": "1743771596686", "bids": [[122395000.0, 0.0], [122387000.0, 0.0024], [122370000.0, 0.0222], [122367000.0, 0.0013], [122365000.0, 0.0048], [122363000.0, 0.0845], [122362000.0, 0.0074], [122357000.0, 0.0002], [122352000.0, 0.0246], [122347000.0, 0.0119]], "asks": [[122449000.0, 0.0221], [122450000.0, 0.0022], [122453000.0, 0.0019], [122455000.0, 0.0], [122459000.0, 0.0], [122460000.0, 0.0003], [122463000.0, 0.0016], [122465000.0, 0.0832], [122466000.0, 0.0128], [122468000.0, 0.0268]]},
{"timestamp": "1743771597188", "bids": [[122396000.0, 0.0846], [122395000.0, 0.0], [122387000.0, 0.0024], [122378000.0, 0.0225], [122371000.0, 0.0845], [122370000.0, 0.0244], [122367000.0, 0.0013], [122352000.0, 0.0246], [122349000.0, 0.0322], [122347000.0, 0.0119]], "asks": [[122450000.0, 0.0022], [122453000.0, 0.0019], [122455000.0, 0.0], [122457000.0, 0.0173], [122459000.0, 0.0], [122460000.0, 0.0003], [122461000.0, 0.0242], [122463000.0, 0.0016], [122465000.0, 0.0832], [122466000.0, 0.0128]]},
{"timestamp": "1743771597690", "bids": [[122396000.0, 0.137], [122395000.0, 0.0], [122387000.0, 0.0024], [122378000.0, 0.0225], [122371000.0, 0.0845], [122370000.0, 0.0221], [122367000.0, 0.0013], [122355000.0, 0.0326], [122352000.0, 0.0245], [122349000.0, 0.0322]], "asks": [[122450000.0, 0.0022], [122453000.0, 0.0019], [122455000.0, 0.0], [122457000.0, 0.0212], [122458000.0, 0.0168], [122459000.0, 0.0227], [122460000.0, 0.0003], [122461000.0, 0.0463], [122463000.0, 0.0016], [122465000.0, 0.0222]]},
{"timestamp": "1743771598187", "bids": [[122396000.0, 0.137], [122395000.0, 0.0], [122388000.0, 0.0001], [122387000.0, 0.0024], [122378000.0, 0.0225], [122374000.0, 0.0122], [122373000.0, 0.031], [122371000.0, 0.0845], [122370000.0, 0.0221], [122367000.0, 0.0013]], "asks": [[122439000.0, 0.0193], [122450000.0, 0.0022], [122452000.0, 0.0113], [122453000.0, 0.0019], [122455000.0, 0.0], [122457000.0, 0.0039], [122458000.0, 0.0168], [122459000.0, 0.0227], [122460000.0, 0.0003], [122461000.0, 0.0221]]},
{"timestamp": "1743771598716", "bids": [[122395000.0, 0.0], [122390000.0, 0.0023], [122388000.0, 0.0001], [122387000.0, 0.0024], [122384000.0, 0.0063], [122378000.0, 0.0225], [122374000.0, 0.0196], [122373000.0, 0.031], [122372000.0, 0.0244], [122370000.0, 0.0]], "asks": [[122439000.0, 0.0193], [122450000.0, 0.0022], [122452000.0, 0.0113], [122453000.0, 0.0019], [122455000.0, 0.0], [122459000.0, 0.0], [122460000.0, 0.0003], [122463000.0, 0.0016], [122468000.0, 0.002], [122469000.0, 0.0833]]},
{"timestamp": "1743771599192", "bids": [[122396000.0, 0.1561], [122395000.0, 0.0], [122390000.0, 0.0023], [122388000.0, 0.0048], [122387000.0, 0.0024], [122384000.0, 0.0063], [122379000.0, 0.0845], [122378000.0, 0.0225], [122374000.0, 0.0196], [122373000.0, 0.0198]], "asks": [[122439000.0, 0.0193], [122450000.0, 0.0022], [122452000.0, 0.0113], [122453000.0, 0.0019], [122455000.0, 0.0], [122459000.0, 0.0], [122460000.0, 0.0003], [122463000.0, 0.0016], [122468000.0, 0.002], [122470000.0, 0.0221]]},
{"timestamp": "1743771599692", "bids": [[122396000.0, 0.1596], [122395000.0, 0.0], [122390000.0, 0.0023], [122388000.0, 0.0048], [122387000.0, 0.0024], [122384000.0, 0.0063], [122379000.0, 0.0845], [122378000.0, 0.0225], [122374000.0, 0.0122], [122372000.0, 0.0244]], "asks": [[122450000.0, 0.0022], [122453000.0, 0.0019], [122455000.0, 0.0], [122459000.0, 0.0], [122460000.0, 0.0003], [122463000.0, 0.0016], [122468000.0, 0.002], [122469000.0, 0.0832], [122470000.0, 0.0394], [122471000.0, 0.0016]]}
]