[{"timestamp": "1743771208877", "bids": [[122433000.0, 0.0027], [122430000.0, 0.0124], [122426000.0, 0.0254], [122425000.0, 0.0004], [122423000.0, 0.077], [122422000.0, 0.0322], [122421000.0, 0.0001], [122416000.0, 0.0251], [122415000.0, 0.0036], [122412000.0, 0.0706]], "asks": [[122449000.0, 0.0049], [122451000.0, 0.0304], [122452000.0, 0.006], [122453000.0, 0.0038], [122454000.0, 0.0013], [122455000.0, 0.0], [122456000.0, 0.0043], [122457000.0, 0.004], [122458000.0, 0.0032], [122459000.0, 0.0]]},
{"timestamp": "1743771209353", "bids": [[122433000.0, 0.0027], [122430000.0, 0.0124], [122426000.0, 0.0254], [122425000.0, 0.0004], [122423000.0, 0.077], [122422000.0, 0.0322], [122421000.0, 0.0001], [122416000.0, 0.0251], [122415000.0, 0.0036], [122412000.0, 0.0706]], "asks": [[122449000.0, 0.0049], [122451000.0, 0.0304], [122452000.0, 0.006], [122453000.0, 0.0038], [122454000.0, 0.0013], [122455000.0, 0.0], [122456000.0, 0.0043], [122457000.0, 0.004], [122458000.0, 0.0032], [122459000.0, 0.0]]},
{"timestamp": "1743771209846", "bids": [[122441000.0, 0.0225], [122434000.0, 0.0078], [122433000.0, 0.0027], [122430000.0, 0.0124], [122426000.0, 0.0254], [122425000.0, 0.0004], [122422000.0, 0.0322], [122421000.0, 0.0001], [122417000.0, 0.077], [122416000.0, 0.0251]], "asks": [[122449000.0, 0.0049], [122451000.0, 0.0304], [122452000.0, 0.006], [122453000.0, 0.0038], [122454000.0, 0.0013], [122455000.0, 0.0], [122456000.0, 0.0043], [122457000.0, 0.004], [122458000.0, 0.0032], [122459000.0, 0.0]]},
{"timestamp": "1743771210344", "bids": [[122441000.0, 0.0225], [122434000.0, 0.0078], [122433000.0, 0.0027], [122430000.0, 0.0124], [122426000.0, 0.0001], [122425000.0, 0.0004], [122421000.0, 0.0001], [122416000.0, 0.0251], [122415000.0, 0.0036], [122412000.0, 0.0448]], "asks": [[122449000.0, 0.0049], [122451000.0, 0.0304], [122452000.0, 0.006], [122453000.0, 0.0038], [122454000.0, 0.0013], [122455000.0, 0.0], [122456000.0, 0.0043], [122457000.0, 0.004], [122458000.0, 0.0032], [122459000.0, 0.0]]},
{"timestamp": "1743771210846", "bids": [[122441000.0, 0.0225], [122434000.0, 0.0078], [122430000.0, 0.0123], [122426000.0, 0.0254], [122425000.0, 0.0004], [122423000.0, 0.1099], [122416000.0, 0.0246], [122415000.0, 0.0036], [122410000.0, 0.0563], [122409000.0, 0.0]], "asks": [[122449000.0, 0.0049], [122451000.0, 0.0304], [122452000.0, 0.006], [122453000.0, 0.0038], [122454000.0, 0.0013], [122455000.0, 0.0], [122456000.0, 0.0043], [122457000.0, 0.004], [122458000.0, 0.0032], [122459000.0, 0.0]]},
{"timestamp": "1743771211355", "bids": [[122441000.0, 0.0207], [122437000.0, 0.0027], [122431000.0, 0.0253], [122430000.0, 0.0123], [122426000.0, 0.0254], [122425000.0, 0.0004], [122423000.0, 0.1099], [122420000.0, 0.0001], [122417000.0, 0.0772], [122415000.0, 0.0285]], "asks": [[122449000.0, 0.0049], [122451000.0, 0.0304], [122452000.0, 0.006], [122453000.0, 0.0038], [122454000.0, 0.0013], [122455000.0, 0.0], [122456000.0, 0.0043], [122457000.0, 0.004], [122458000.0, 0.0032], [122459000.0, 0.0]]},
{"timestamp": "1743771211845", "bids": [[122441000.0, 0.0207], [122437000.0, 0.0027], [122431000.0, 0.0253], [122430000.0, 0.0123], [122426000.0, 0.0254], [122425000.0, 0.0004], [122423000.0, 0.0329], [122420000.0, 0.0249], [122417000.0, 0.0002], [122415000.0, 0.06]], "asks": [[122449000.0, 0.0049], [122451000.0, 0.0304], [122452000.0, 0.006], [122453000.0, 0.0038], [122454000.0, 0.0013], [122455000.0, 0.0], [122456000.0, 0.0043], [122457000.0, 0.004], [122458000.0, 0.0032], [122459000.0, 0.0]]},
{"timestamp": "1743771212350", "bids": [[122441000.0, 0.0207], [122440000.0, 0.0006], [122437000.0, 0.0027], [122431000.0, 0.0253], [122430000.0, 0.0123], [122426000.0, 0.0254], [122425000.0, 0.0004], [122423000.0, 0.0329], [122420000.0, 0.025], [122417000.0, 0.0002]], "asks": [[122449000.0, 0.0049], [122451000.0, 0.0304], [122452000.0, 0.006], [122453000.0, 0.0038], [122454000.0, 0.0013], [122455000.0, 0.0], [122456000.0, 0.0043], [122457000.0, 0.004], [122458000.0, 0.0032], [122459000.0, 0.0]]},
{"timestamp": "1743771212847", "bids": [[122441000.0, 0.0207], [122440000.0, 0.0006], [122437000.0, 0.0027], [122431000.0, 0.0253], [122430000.0, 0.0123], [122426000.0, 0.0254], [122425000.0, 0.0004], [122423000.0, 0.0329], [122420000.0, 0.025], [122417000.0, 0.0002]], "asks": [[122449000.0, 0.0049], [122451000.0, 0.0304], [122452000.0, 0.006], [122453000.0, 0.0038], [122454000.0, 0.0013], [122455000.0, 0.0], [122456000.0, 0.0043], [122457000.0, 0.004], [122458000.0, 0.0032], [122459000.0, 0.0]]},
{"timestamp": "1743771213352", "bids": [[122441000.0, 0.0207], [122440000.0, 0.0006], [122437000.0, 0.0027], [122431000.0, 0.0253], [122430000.0, 0.0123], [122426000.0, 0.0254], [122425000.0, 0.0004], [122424000.0, 0.077], [122423000.0, 0.0329], [122420000.0, 0.025]], "asks": [[122449000.0, 0.0249], [122451000.0, 0.0304], [122452000.0, 0.006], [122453000.0, 0.0038], [122454000.0, 0.0013], [122455000.0, 0.0], [122456000.0, 0.0043], [122457000.0, 0.004], [122458000.0, 0.0032], [122459000.0, 0.0]]},
{"timestamp": "1743771213848", "bids": [[122441000.0, 0.0207], [122440000.0, 0.0006], [122437000.0, 0.0027], [122431000.0, 0.0253], [122430000.0, 0.0123], [122426000.0, 0.0254], [122425000.0, 0.0004], [122423000.0, 0.0329], [122420000.0, 0.025], [122417000.0, 0.0002]], "asks": [[122449000.0, 0.0249], [122451000.0, 0.0304], [122452000.0, 0.006], [122453000.0, 0.0038], [122454000.0, 0.0013], [122455000.0, 0.0], [122456000.0, 0.0043], [122457000.0, 0.004], [122458000.0, 0.0032], [122459000.0, 0.0]]},
{"timestamp": "1743771214346", "bids": [[122441000.0, 0.0207], [122440000.0, 0.0006], [122437000.0, 0.0027], [122431000.0, 0.0001], [122430000.0, 0.0123], [122426000.0, 0.0254], [122425000.0, 0.0004], [122424000.0, 0.077], [122423000.0, 0.0329], [122422000.0, 0.0362]], "asks": [[122449000.0, 0.0249], [122451000.0, 0.0304], [122452000.0, 0.006], [122453000.0, 0.0038], [122454000.0, 0.0013], [122455000.0, 0.0], [122456000.0, 0.0043], [122457000.0, 0.004], [122458000.0, 0.0032], [122459000.0, 0.0]]},
{"timestamp": "1743771214851", "bids": [[122446000.0, 0.0001], [122441000.0, 0.0207], [122440000.0, 0.0006], [122436000.0, 0.0001], [122430000.0, 0.0445], [122428000.0, 0.0445], [122427000.0, 0.0324], [122425000.0, 0.0004], [122422000.0, 0.0362], [122421000.0, 0.077]], "asks": [[122449000.0, 0.0249], [122451000.0, 0.0304], [122452000.0, 0.006], [122453000.0, 0.0038], [122454000.0, 0.0013], [122455000.0, 0.0], [122456000.0, 0.0043], [122457000.0, 0.004], [122458000.0, 0.0032], [122459000.0, 0.0]]},
{"timestamp": "1743771215350", "bids": [[122446000.0, 0.0001], [122442000.0, 0.0384], [122441000.0, 0.0207], [122440000.0, 0.0006], [122438000.0, 0.0313], [122436000.0, 0.0001], [122435000.0, 0.0002], [122430000.0, 0.0445], [122428000.0, 0.0445], [122427000.0, 0.0324]], "asks": [[122451000.0, 0.0], [122452000.0, 0.006], [122453000.0, 0.0038], [122454000.0, 0.0013], [122455000.0, 0.0], [122456000.0, 0.0043], [122457000.0, 0.004], [122458000.0, 0.0032], [122459000.0, 0.0], [122460000.0, 0.0033]]},
{"timestamp": "1743771215847", "bids": [[122450000.0, 0.0329], [122449000.0, 0.0078], [122445000.0, 0.0249], [122442000.0, 0.0191], [122441000.0, 0.021], [122440000.0, 0.0253], [122438000.0, 0.0565], [122436000.0, 0.0001], [122435000.0, 0.0002], [122434000.0, 0.024]], "asks": [[122452000.0, 0.0033], [122453000.0, 0.0038], [122454000.0, 0.0013], [122455000.0, 0.0], [122456000.0, 0.0043], [122457000.0, 0.004], [122458000.0, 0.0032], [122459000.0, 0.0], [122460000.0, 0.0033], [122462000.0, 0.0008]]},
{"timestamp": "1743771216346", "bids": [[122462000.0, 1.1436], [122459000.0, 0.0254], [122452000.0, 0.0007], [122450000.0, 0.0691], [122449000.0, 0.0078], [122447000.0, 0.0258], [122446000.0, 0.0002], [122445000.0, 0.0248], [122441000.0, 0.021], [122440000.0, 0.0253]], "asks": [[122463000.0, 0.0017], [122464000.0, 0.004], [122465000.0, 0.0002], [122466000.0, 0.0], [122468000.0, 0.0028], [122470000.0, 0.0], [122471000.0, 0.0032], [122472000.0, 0.0051], [122473000.0, 0.0001], [122474000.0, 0.0011]]},
{"timestamp": "1743771216847", "bids": [[122460000.0, 0.0446], [122459000.0, 0.0255], [122452000.0, 0.0561], [122450000.0, 0.0362], [122449000.0, 0.0078], [122448000.0, 0.0145], [122447000.0, 0.0258], [122446000.0, 0.0002], [122445000.0, 0.0248], [122443000.0, 0.0777]], "asks": [[122463000.0, 0.0015], [122464000.0, 0.004], [122465000.0, 0.0002], [122466000.0, 0.0], [122468000.0, 0.0028], [122470000.0, 0.0], [122471000.0, 0.0032], [122472000.0, 0.0051], [122473000.0, 0.0001], [122474000.0, 0.0011]]},
{"timestamp": "1743771217345", "bids": [[122462000.0, 0.0252], [122460000.0, 0.0001], [122459000.0, 0.0254], [122456000.0, 0.0261], [122455000.0, 0.0315], [122452000.0, 0.0561], [122450000.0, 0.0619], [122447000.0, 0.0258], [122444000.0, 0.0002], [122443000.0, 0.0777]], "asks": [[122463000.0, 0.0015], [122464000.0, 0.004], [122465000.0, 0.0002], [122466000.0, 0.0], [122468000.0, 0.0028], [122470000.0, 0.0], [122471000.0, 0.0032], [122472000.0, 0.0051], [122473000.0, 0.0001], [122474000.0, 0.0011]]},
{"timestamp": "1743771217853", "bids": [[122462000.0, 0.0252], [122460000.0, 0.0001], [122459000.0, 0.0254], [122458000.0, 0.0322], [122456000.0, 0.059], [122455000.0, 0.0636], [122452000.0, 0.0561], [122451000.0, 0.0248], [122450000.0, 0.0619], [122448000.0, 0.0004]], "asks": [[122463000.0, 0.0015], [122464000.0, 0.004], [122465000.0, 0.0002], [122466000.0, 0.0], [122468000.0, 0.0028], [122470000.0, 0.0], [122471000.0, 0.0032], [122472000.0, 0.0051], [122473000.0, 0.0001], [122474000.0, 0.0011]]},
{"timestamp": "1743771218349", "bids": [[122462000.0, 0.0228], [122459000.0, 0.0254], [122458000.0, 0.0322], [122456000.0, 0.059], [122455000.0, 0.0323], [122452000.0, 0.0561], [122451000.0, 0.0248], [122448000.0, 0.0004], [122446000.0, 0.0249], [122445000.0, 0.0001]], "asks": [[122463000.0, 0.0015], [122464000.0, 0.004], [122465000.0, 0.0002], [122466000.0, 0.0], [122468000.0, 0.0028], [122470000.0, 0.0], [122471000.0, 0.0032], [122472000.0, 0.0051], [122473000.0, 0.0001], [122474000.0, 0.0011]]},
{"timestamp": "1743771218852", "bids": [[122459000.0, 0.0254], [122451000.0, 0.0248], [122450000.0, 0.0445], [122446000.0, 0.0001], [122445000.0, 0.0001], [122444000.0, 0.0362], [122440000.0, 0.0006], [122438000.0, 0.0145], [122434000.0, 0.024], [122430000.0, 0.0123]], "asks": [[122463000.0, 0.0015], [122464000.0, 0.004], [122465000.0, 0.0002], [122466000.0, 0.0], [122468000.0, 0.0028], [122470000.0, 0.0], [122471000.0, 0.0032], [122472000.0, 0.0051], [122473000.0, 0.0001], [122474000.0, 0.0011]]},
{"timestamp": "1743771219609", "bids": [[122450000.0, 0.0654], [122445000.0, 0.025], [122441000.0, 0.0257], [122440000.0, 0.057], [122438000.0, 0.0002], [122430000.0, 0.0123], [122425000.0, 0.0004], [122415000.0, 0.0036], [122409000.0, 0.0], [122407000.0, 0.0]], "asks": [[122463000.0, 0.0014], [122464000.0, 0.004], [122465000.0, 0.0002], [122466000.0, 0.0], [122468000.0, 0.0028], [122470000.0, 0.0], [122471000.0, 0.0032], [122472000.0, 0.0051], [122473000.0, 0.0001], [122474000.0, 0.0011]]},
{"timestamp": "1743771219849", "bids": [[122445000.0, 0.025], [122441000.0, 0.0257], [122440000.0, 0.057], [122438000.0, 0.0258], [122430000.0, 0.0123], [122429000.0, 0.0252], [122425000.0, 0.0004], [122415000.0, 0.0036], [122409000.0, 0.0], [122407000.0, 0.0]], "asks": [[122463000.0, 0.0014], [122464000.0, 0.004], [122465000.0, 0.0002], [122466000.0, 0.0], [122468000.0, 0.0028], [122470000.0, 0.0], [122471000.0, 0.0032], [122472000.0, 0.0051], [122473000.0, 0.0001], [122474000.0, 0.0011]]},
{"timestamp": "1743771220350", "bids": [[122453000.0, 0.0228], [122451000.0, 0.0254], [122447000.0, 0.0322], [122446000.0, 0.0323], [122445000.0, 0.0001], [122440000.0, 0.0319], [122438000.0, 0.0522], [122435000.0, 0.0918], [122430000.0, 0.0123], [122429000.0, 0.0252]], "asks": [[122463000.0, 0.0014], [122464000.0, 0.004], [122465000.0, 0.0002], [122466000.0, 0.0], [122468000.0, 0.0028], [122470000.0, 0.0], [122471000.0, 0.0032], [122472000.0, 0.0051], [122473000.0, 0.0001], [122474000.0, 0.0011]]},
{"timestamp": "1743771220849", "bids": [[122453000.0, 0.0228], [122451000.0, 0.0254], [122447000.0, 0.0322], [122446000.0, 0.0323], [122440000.0, 0.0006], [122439000.0, 0.0445], [122438000.0, 0.0523], [122435000.0, 0.0358], [122432000.0, 0.0362], [122430000.0, 0.0124]], "asks": [[122462000.0, 0.1583], [122463000.0, 0.0014], [122464000.0, 0.004], [122465000.0, 0.0002], [122466000.0, 0.0], [122468000.0, 0.0028], [122470000.0, 0.0], [122471000.0, 0.0032], [122472000.0, 0.0051], [122473000.0, 0.0001]]},
{"timestamp": "1743771221345", "bids": [[122451000.0, 0.0254], [122447000.0, 0.0322], [122440000.0, 0.0006], [122439000.0, 0.0654], [122438000.0, 0.0001], [122430000.0, 0.0381], [122425000.0, 0.0004], [122424000.0, 0.025], [122420000.0, 0.0248], [122415000.0, 0.0036]], "asks": [[122462000.0, 0.1583], [122463000.0, 0.0014], [122464000.0, 0.004], [122465000.0, 0.0002], [122466000.0, 0.0], [122468000.0, 0.0028], [122470000.0, 0.0], [122471000.0, 0.0032], [122472000.0, 0.0051], [122473000.0, 0.0001]]},
{"timestamp": "1743771221848", "bids": [[122440000.0, 0.0006], [122439000.0, 0.0654], [122430000.0, 0.0381], [122425000.0, 0.0004], [122424000.0, 0.025], [122420000.0, 0.0248], [122419000.0, 0.0316], [122415000.0, 0.0036], [122409000.0, 0.0], [122407000.0, 0.0]], "asks": [[122463000.0, 0.0014], [122464000.0, 0.004], [122465000.0, 0.0002], [122466000.0, 0.0], [122468000.0, 0.0028], [122470000.0, 0.0], [122471000.0, 0.0032], [122472000.0, 0.0051], [122473000.0, 0.0001], [122474000.0, 0.0011]]},
{"timestamp": "1743771222347", "bids": [[122440000.0, 0.0006], [122439000.0, 0.0654], [122430000.0, 0.0381], [122425000.0, 0.0004], [122424000.0, 0.025], [122420000.0, 0.0248], [122419000.0, 0.0316], [122415000.0, 0.0036], [122409000.0, 0.0], [122407000.0, 0.0]], "asks": [[122463000.0, 0.0014], [122464000.0, 0.004], [122465000.0, 0.0002], [122466000.0, 0.0], [122468000.0, 0.0028], [122470000.0, 0.0], [122471000.0, 0.0032], [122472000.0, 0.0051], [122473000.0, 0.0001], [122474000.0, 0.0011]]},
{"timestamp": "1743771222847", "bids": [[122441000.0, 0.0078], [122440000.0, 0.0006], [122430000.0, 0.038], [122429000.0, 0.0362], [122426000.0, 0.0258], [122425000.0, 0.0781], [122420000.0, 0.0248], [122419000.0, 0.0435], [122415000.0, 0.0036], [122409000.0, 0.0]], "asks": [[122463000.0, 0.0014], [122464000.0, 0.004], [122465000.0, 0.0002], [122466000.0, 0.0], [122468000.0, 0.0028], [122470000.0, 0.0], [122471000.0, 0.0032], [122472000.0, 0.0051], [122473000.0, 0.0001], [122474000.0, 0.0011]]},
{"timestamp": "1743771223345", "bids": [[122441000.0, 0.0426], [122440000.0, 0.0329], [122438000.0, 0.0254], [122437000.0, 0.0322], [122434000.0, 0.0001], [122430000.0, 0.0123], [122429000.0, 0.0362], [122428000.0, 0.0708], [122426000.0, 0.0258], [122425000.0, 0.0781]], "asks": [[122463000.0, 0.0014], [122464000.0, 0.004], [122465000.0, 0.0002], [122466000.0, 0.0], [122468000.0, 0.0028], [122470000.0, 0.0], [122471000.0, 0.0032], [122472000.0, 0.0051], [122473000.0, 0.0001], [122474000.0, 0.0011]]},
{"timestamp": "1743771223849", "bids": [[122463000.0, 0.001], [122445000.0, 0.025], [122442000.0, 0.0103], [122441000.0, 0.0228], [122440000.0, 0.0329], [122438000.0, 0.0254], [122437000.0, 0.0322], [122434000.0, 0.0003], [122432000.0, 0.0001], [122431000.0, 0.0777]], "asks": [[122464000.0, 0.004], [122465000.0, 0.0002], [122466000.0, 0.0], [122468000.0, 0.0028], [122470000.0, 0.0], [122471000.0, 0.0032], [122472000.0, 0.0051], [122473000.0, 0.0001], [122474000.0, 0.0011], [122475000.0, 0.0001]]},
{"timestamp": "1743771224344", "bids": [[122463000.0, 0.001], [122452000.0, 0.0248], [122450000.0, 0.0329], [122445000.0, 0.0475], [122444000.0, 0.0325], [122442000.0, 0.0295], [122441000.0, 0.0228], [122440000.0, 0.0006], [122438000.0, 0.0254], [122434000.0, 0.0002]], "asks": [[122464000.0, 0.004], [122465000.0, 0.0002], [122466000.0, 0.0], [122468000.0, 0.0028], [122470000.0, 0.0], [122471000.0, 0.0032], [122472000.0, 0.0051], [122473000.0, 0.0001], [122474000.0, 0.0011], [122475000.0, 0.0001]]},
{"timestamp": "1743771224851", "bids": [[122477000.0, 1.1222], [122465000.0, 0.0001], [122464000.0, 0.0312], [122463000.0, 0.0024], [122452000.0, 0.0248], [122450000.0, 0.0329], [122446000.0, 0.0129], [122445000.0, 0.0225], [122444000.0, 0.0325], [122442000.0, 0.1089]], "asks": [[122479000.0, 0.0014], [122480000.0, 0.001], [122482000.0, 0.0006], [122484000.0, 0.0031], [122485000.0, 0.0004], [122486000.0, 0.0043], [122487000.0, 0.0004], [122488000.0, 0.0016], [122489000.0, 0.0001], [122490000.0, 0.0008]]},
{"timestamp": "1743771225351", "bids": [[122484000.0, 0.029], [122482000.0, 0.0088], [122481000.0, 0.0323], [122477000.0, 1.1224], [122476000.0, 0.0362], [122472000.0, 0.0258], [122470000.0, 0.1064], [122465000.0, 0.0003], [122464000.0, 0.0579], [122463000.0, 0.0081]], "asks": [[122497000.0, 0.0064], [122498000.0, 0.0011], [122499000.0, 0.0183], [122500000.0, 0.0198], [122502000.0, 0.0], [122503000.0, 0.0028], [122504000.0, 0.001], [122505000.0, 0.0094], [122506000.0, 0.0167], [122507000.0, 0.0053]]},
{"timestamp": "1743771225855", "bids": [[122495000.0, 0.0204], [122493000.0, 0.0253], [122485000.0, 0.025], [122484000.0, 0.029], [122482000.0, 0.0088], [122481000.0, 0.0585], [122479000.0, 0.0002], [122478000.0, 0.088], [122477000.0, 0.0002], [122476000.0, 0.0362]], "asks": [[122497000.0, 0.0064], [122498000.0, 0.0011], [122499000.0, 0.0183], [122500000.0, 0.0198], [122502000.0, 0.0], [122503000.0, 0.0028], [122504000.0, 0.001], [122505000.0, 0.0094], [122506000.0, 0.0167], [122507000.0, 0.0053]]},
{"timestamp": "1743771226345", "bids": [[122495000.0, 0.0204], [122493000.0, 0.0253], [122485000.0, 0.025], [122484000.0, 0.029], [122482000.0, 0.0088], [122481000.0, 0.0585], [122479000.0, 0.0249], [122478000.0, 0.088], [122477000.0, 0.0002], [122476000.0, 0.0362]], "asks": [[122497000.0, 0.0064], [122498000.0, 0.0011], [122499000.0, 0.0183], [122500000.0, 0.0198], [122502000.0, 0.0], [122503000.0, 0.0028], [122504000.0, 0.001], [122505000.0, 0.0094], [122506000.0, 0.0167], [122507000.0, 0.0053]]},
{"timestamp": "1743771226860", "bids": [[122495000.0, 0.0204], [122493000.0, 0.0253], [122485000.0, 0.025], [122484000.0, 0.029], [122482000.0, 0.0088], [122481000.0, 0.0585], [122479000.0, 0.0524], [122478000.0, 0.0103], [122477000.0, 0.0002], [122476000.0, 0.0362]], "asks": [[122497000.0, 0.0064], [122498000.0, 0.0011], [122499000.0, 0.0183], [122500000.0, 0.0198], [122502000.0, 0.0], [122503000.0, 0.0028], [122504000.0, 0.001], [122505000.0, 0.0094], [122506000.0, 0.0167], [122507000.0, 0.0053]]},
{"timestamp": "1743771227349", "bids": [[122495000.0, 0.0203], [122493000.0, 0.0253], [122485000.0, 0.025], [122484000.0, 0.029], [122482000.0, 0.0088], [122481000.0, 0.0585], [122479000.0, 0.0524], [122477000.0, 0.0002], [122476000.0, 0.0362], [122472000.0, 0.0258]], "asks": [[122497000.0, 0.0064], [122498000.0, 0.0011], [122499000.0, 0.0183], [122500000.0, 0.0198], [122502000.0, 0.0], [122503000.0, 0.0028], [122504000.0, 0.001], [122505000.0, 0.0094], [122506000.0, 0.0167], [122507000.0, 0.0053]]},
{"timestamp": "1743771227846", "bids": [[122484000.0, 0.029], [122483000.0, 0.0325], [122482000.0, 0.0088], [122481000.0, 0.0323], [122479000.0, 0.0249], [122476000.0, 0.0362], [122470000.0, 0.1064], [122464000.0, 0.0252], [122453000.0, 0.0122], [122440000.0, 0.0231]], "asks": [[122497000.0, 0.0063], [122498000.0, 0.0011], [122499000.0, 0.0183], [122500000.0, 0.0198], [122502000.0, 0.0], [122503000.0, 0.0028], [122504000.0, 0.001], [122505000.0, 0.0094], [122506000.0, 0.0167], [122507000.0, 0.0053]]},
{"timestamp": "1743771228397", "bids": [[122486000.0, 0.0001], [122484000.0, 0.0619], [122483000.0, 0.0325], [122482000.0, 0.0088], [122481000.0, 0.0323], [122478000.0, 0.025], [122476000.0, 0.0362], [122474000.0, 0.0259], [122473000.0, 0.0275], [122470000.0, 0.1064]], "asks": [[122497000.0, 0.0063], [122498000.0, 0.0011], [122499000.0, 0.0183], [122500000.0, 0.0198], [122502000.0, 0.0], [122503000.0, 0.0028], [122504000.0, 0.001], [122505000.0, 0.0094], [122506000.0, 0.0167], [122507000.0, 0.0053]]},
{"timestamp": "1743771228848", "bids": [[122486000.0, 0.0001], [122484000.0, 0.029], [122482000.0, 0.0088], [122478000.0, 0.025], [122473000.0, 0.0273], [122453000.0, 0.0122], [122445000.0, 0.0225], [122440000.0, 0.0006], [122434000.0, 0.0118], [122430000.0, 0.0123]], "asks": [[122497000.0, 0.0063], [122498000.0, 0.0011], [122499000.0, 0.0183], [122500000.0, 0.0198], [122502000.0, 0.0], [122503000.0, 0.0028], [122504000.0, 0.001], [122505000.0, 0.0094], [122506000.0, 0.0167], [122507000.0, 0.0053]]},
{"timestamp": "1743771229351", "bids": [[122487000.0, 0.0078], [122486000.0, 0.0204], [122471000.0, 0.052], [122470000.0, 0.0248], [122467000.0, 0.0002], [122463000.0, 0.0118], [122453000.0, 0.0122], [122445000.0, 0.0225], [122440000.0, 0.0006], [122430000.0, 0.0123]], "asks": [[122497000.0, 0.0063], [122498000.0, 0.0011], [122499000.0, 0.0183], [122500000.0, 0.0198], [122502000.0, 0.0], [122503000.0, 0.0028], [122504000.0, 0.001], [122505000.0, 0.0094], [122506000.0, 0.0167], [122507000.0, 0.0053]]},
{"timestamp": "1743771229853", "bids": [[122487000.0, 0.0076], [122483000.0, 0.0341], [122476000.0, 0.0362], [122471000.0, 0.0262], [122470000.0, 0.0953], [122469000.0, 0.0002], [122467000.0, 0.0002], [122464000.0, 0.0252], [122463000.0, 0.0118], [122454000.0, 0.0772]], "asks": [[122497000.0, 0.0063], [122498000.0, 0.0011], [122499000.0, 0.0183], [122500000.0, 0.0198], [122502000.0, 0.0], [122503000.0, 0.0028], [122504000.0, 0.001], [122505000.0, 0.0094], [122506000.0, 0.0167], [122507000.0, 0.0053]]},
{"timestamp": "1743771230345", "bids": [[122486000.0, 0.0291], [122483000.0, 0.0995], [122482000.0, 0.0323], [122479000.0, 0.025], [122476000.0, 0.0362], [122474000.0, 0.0261], [122471000.0, 0.0262], [122470000.0, 0.1063], [122469000.0, 0.0002], [122464000.0, 0.1024]], "asks": [[122497000.0, 0.0063], [122498000.0, 0.0011], [122499000.0, 0.0183], [122500000.0, 0.0198], [122502000.0, 0.0], [122503000.0, 0.0028], [122504000.0, 0.001], [122505000.0, 0.0094], [122506000.0, 0.0167], [122507000.0, 0.0053]]},
{"timestamp": "1743771230851", "bids": [[122490000.0, 0.0204], [122488000.0, 0.0064], [122486000.0, 0.0291], [122483000.0, 0.0907], [122482000.0, 0.0323], [122481000.0, 0.0258], [122479000.0, 0.0523], [122474000.0, 0.0261], [122472000.0, 0.0001], [122470000.0, 0.0358]], "asks": [[122497000.0, 0.0063], [122498000.0, 0.0011], [122499000.0, 0.0183], [122500000.0, 0.0198], [122502000.0, 0.0], [122503000.0, 0.0028], [122504000.0, 0.001], [122505000.0, 0.0094], [122506000.0, 0.0167], [122507000.0, 0.0053]]},
{"timestamp": "1743771231349", "bids": [[122490000.0, 0.0204], [122488000.0, 0.0001], [122487000.0, 0.0261], [122486000.0, 0.0247], [122481000.0, 0.0258], [122479000.0, 0.0637], [122476000.0, 0.0001], [122472000.0, 0.0001], [122467000.0, 0.0252], [122463000.0, 0.0118]], "asks": [[122493000.0, 0.5749], [122497000.0, 0.0063], [122498000.0, 0.0011], [122499000.0, 0.0183], [122500000.0, 0.0198], [122502000.0, 0.0], [122503000.0, 0.0028], [122504000.0, 0.001], [122505000.0, 0.0094], [122506000.0, 0.0167]]},
{"timestamp": "1743771231852", "bids": [[122490000.0, 0.0204], [122488000.0, 0.0001], [122487000.0, 0.0261], [122486000.0, 0.0417], [122479000.0, 0.0364], [122476000.0, 0.0001], [122473000.0, 0.0559], [122467000.0, 0.0252], [122440000.0, 0.0231], [122431000.0, 0.0183]], "asks": [[122493000.0, 0.5749], [122497000.0, 0.0063], [122498000.0, 0.0011], [122499000.0, 0.0183], [122500000.0, 0.0198], [122502000.0, 0.0], [122503000.0, 0.0028], [122504000.0, 0.001], [122505000.0, 0.0094], [122506000.0, 0.0167]]},
{"timestamp": "1743771232353", "bids": [[122488000.0, 0.0252], [122486000.0, 0.0417], [122479000.0, 0.0364], [122477000.0, 0.0003], [122473000.0, 0.0559], [122472000.0, 0.0436], [122471000.0, 0.0325], [122470000.0, 0.0323], [122467000.0, 0.0252], [122466000.0, 0.025]], "asks": [[122492000.0, 0.1102], [122493000.0, 0.5749], [122497000.0, 0.0063], [122498000.0, 0.0011], [122499000.0, 0.0183], [122500000.0, 0.0198], [122502000.0, 0.0], [122503000.0, 0.0028], [122504000.0, 0.001], [122505000.0, 0.0094]]},
{"timestamp": "1743771232851", "bids": [[122488000.0, 0.0252], [122477000.0, 0.0003], [122472000.0, 0.0291], [122471000.0, 0.0325], [122470000.0, 0.0323], [122463000.0, 0.0], [122462000.0, 0.0257], [122461000.0, 0.0247], [122460000.0, 0.0258], [122440000.0, 0.0006]], "asks": [[122492000.0, 0.1583], [122493000.0, 0.5749], [122497000.0, 0.0063], [122498000.0, 0.0011], [122499000.0, 0.0183], [122500000.0, 0.0198], [122502000.0, 0.0], [122503000.0, 0.0028], [122504000.0, 0.001], [122505000.0, 0.0094]]},
{"timestamp": "1743771233351", "bids": [[122488000.0, 0.022], [122475000.0, 0.0204], [122474000.0, 0.0001], [122463000.0, 0.0], [122461000.0, 0.0247], [122460000.0, 0.0258], [122456000.0, 0.0001], [122455000.0, 0.0261], [122454000.0, 0.0275], [122442000.0, 0.0225]], "asks": [[122493000.0, 0.5749], [122497000.0, 0.0063], [122498000.0, 0.0011], [122499000.0, 0.0183], [122500000.0, 0.0198], [122502000.0, 0.0], [122503000.0, 0.0028], [122504000.0, 0.001], [122505000.0, 0.0094], [122506000.0, 0.0167]]},
{"timestamp": "1743771233854", "bids": [[122475000.0, 0.0204], [122474000.0, 0.0001], [122467000.0, 0.0001], [122464000.0, 0.0329], [122463000.0, 0.0], [122460000.0, 0.0258], [122459000.0, 0.025], [122456000.0, 0.0001], [122455000.0, 0.0261], [122454000.0, 0.0523]], "asks": [[122493000.0, 0.5749], [122497000.0, 0.0063], [122498000.0, 0.0011], [122499000.0, 0.0183], [122500000.0, 0.0198], [122502000.0, 0.0], [122503000.0, 0.0028], [122504000.0, 0.001], [122505000.0, 0.0094], [122506000.0, 0.0167]]},
{"timestamp": "1743771234351", "bids": [[122475000.0, 0.0204], [122474000.0, 0.0001], [122467000.0, 0.0001], [122464000.0, 0.0329], [122463000.0, 0.0], [122460000.0, 0.0258], [122459000.0, 0.025], [122456000.0, 0.0001], [122455000.0, 0.0261], [122454000.0, 0.0524]], "asks": [[122493000.0, 0.5749], [122497000.0, 0.0063], [122498000.0, 0.0011], [122499000.0, 0.0183], [122500000.0, 0.0198], [122502000.0, 0.0], [122503000.0, 0.0028], [122504000.0, 0.001], [122505000.0, 0.0094], [122506000.0, 0.0167]]},
{"timestamp": "1743771235049", "bids": [[122476000.0, 0.0078], [122475000.0, 0.0204], [122474000.0, 0.0001], [122467000.0, 0.0001], [122464000.0, 0.0329], [122463000.0, 0.0], [122461000.0, 0.0772], [122460000.0, 0.0258], [122456000.0, 0.0001], [122455000.0, 0.0261]], "asks": [[122493000.0, 0.5749], [122497000.0, 0.0063], [122498000.0, 0.0011], [122499000.0, 0.0183], [122500000.0, 0.0398], [122502000.0, 0.0], [122503000.0, 0.0028], [122504000.0, 0.001], [122505000.0, 0.0094], [122506000.0, 0.0167]]},
{"timestamp": "1743771235357", "bids": [[122476000.0, 0.0078], [122475000.0, 0.0204], [122474000.0, 0.0001], [122463000.0, 0.0], [122461000.0, 0.0772], [122460000.0, 0.0258], [122456000.0, 0.0001], [122455000.0, 0.0406], [122454000.0, 0.0524], [122446000.0, 0.0036]], "asks": [[122493000.0, 0.5749], [122497000.0, 0.0063], [122498000.0, 0.0011], [122499000.0, 0.0183], [122500000.0, 0.0398], [122502000.0, 0.0], [122503000.0, 0.0028], [122504000.0, 0.001], [122505000.0, 0.0094], [122506000.0, 0.0167]]},
{"timestamp": "1743771235852", "bids": [[122476000.0, 0.0068], [122475000.0, 0.0204], [122469000.0, 0.0291], [122468000.0, 0.0742], [122467000.0, 0.0323], [122463000.0, 0.025], [122462000.0, 0.0362], [122461000.0, 0.0772], [122460000.0, 0.0258], [122459000.0, 0.0257]], "asks": [[122493000.0, 0.5749], [122497000.0, 0.0063], [122498000.0, 0.0011], [122499000.0, 0.0183], [122500000.0, 0.0398], [122502000.0, 0.0], [122503000.0, 0.0028], [122504000.0, 0.001], [122505000.0, 0.0094], [122506000.0, 0.0167]]},
{"timestamp": "1743771236350", "bids": [[122475000.0, 0.0204], [122471000.0, 0.0221], [122469000.0, 0.0291], [122468000.0, 0.0742], [122467000.0, 0.0323], [122463000.0, 0.025], [122460000.0, 0.0258], [122459000.0, 0.0261], [122458000.0, 0.0001], [122456000.0, 0.0001]], "asks": [[122492000.0, 0.155], [122493000.0, 0.5749], [122497000.0, 0.0063], [122498000.0, 0.0011], [122499000.0, 0.0183], [122500000.0, 0.0398], [122502000.0, 0.0], [122503000.0, 0.0028], [122504000.0, 0.001], [122505000.0, 0.0094]]},
{"timestamp": "1743771236855", "bids": [[122471000.0, 0.0221], [122469000.0, 0.0291], [122468000.0, 0.0329], [122463000.0, 0.0], [122459000.0, 0.0004], [122458000.0, 0.0001], [122446000.0, 0.0036], [122444000.0, 0.0], [122440000.0, 0.0254], [122430000.0, 0.0115]], "asks": [[122492000.0, 0.1583], [122493000.0, 0.5749], [122497000.0, 0.0063], [122498000.0, 0.0011], [122499000.0, 0.0183], [122500000.0, 0.0398], [122502000.0, 0.0], [122503000.0, 0.0028], [122504000.0, 0.001], [122505000.0, 0.0094]]},
{"timestamp": "1743771237356", "bids": [[122455000.0, 0.0252], [122454000.0, 0.0001], [122449000.0, 0.0558], [122446000.0, 0.0036], [122444000.0, 0.0], [122440000.0, 0.0254], [122430000.0, 0.0115], [122425000.0, 0.0004], [122423000.0, 0.0362], [122421000.0, 0.0001]], "asks": [[122474000.0, 0.7538], [122491000.0, 0.0003], [122492000.0, 0.0032], [122493000.0, 0.5749], [122497000.0, 0.0063], [122498000.0, 0.0011], [122499000.0, 0.0183], [122500000.0, 0.0398], [122502000.0, 0.0], [122503000.0, 0.0028]]},
{"timestamp": "1743771237851", "bids": [[122455000.0, 0.0252], [122454000.0, 0.0001], [122449000.0, 0.0558], [122446000.0, 0.0036], [122444000.0, 0.0], [122440000.0, 0.0254], [122430000.0, 0.0115], [122429000.0, 0.0413], [122428000.0, 0.0323], [122425000.0, 0.0004]], "asks": [[122474000.0, 0.7538], [122491000.0, 0.0003], [122493000.0, 0.5749], [122497000.0, 0.0063], [122498000.0, 0.0011], [122499000.0, 0.0183], [122500000.0, 0.0398], [122502000.0, 0.0], [122503000.0, 0.0028], [122504000.0, 0.001]]},
{"timestamp": "1743771238355", "bids": [[122455000.0, 0.0252], [122454000.0, 0.0001], [122449000.0, 0.0558], [122446000.0, 0.0036], [122444000.0, 0.0], [122440000.0, 0.0006], [122433000.0, 0.0221], [122430000.0, 0.0115], [122429000.0, 0.0413], [122428000.0, 0.0323]], "asks": [[122493000.0, 0.5749], [122497000.0, 0.0063], [122498000.0, 0.0011], [122499000.0, 0.0183], [122500000.0, 0.0398], [122502000.0, 0.0], [122503000.0, 0.0028], [122504000.0, 0.001], [122505000.0, 0.0094], [122506000.0, 0.0167]]},
{"timestamp": "1743771238853", "bids": [[122455000.0, 0.0252], [122454000.0, 0.0001], [122449000.0, 0.0558], [122446000.0, 0.0036], [122444000.0, 0.0], [122440000.0, 0.0006], [122431000.0, 0.0772], [122430000.0, 0.0115], [122425000.0, 0.0004], [122424000.0, 0.025]], "asks": [[122493000.0, 0.5749], [122497000.0, 0.0063], [122498000.0, 0.0011], [122499000.0, 0.0183], [122500000.0, 0.0398], [122502000.0, 0.0], [122503000.0, 0.0028], [122504000.0, 0.001], [122505000.0, 0.0094], [122506000.0, 0.0167]]},
{"timestamp": "1743771239353", "bids": [[122446000.0, 0.0036], [122444000.0, 0.0], [122440000.0, 0.0006], [122437000.0, 0.0204], [122434000.0, 0.0772], [122433000.0, 0.0653], [122431000.0, 0.0587], [122430000.0, 0.0363], [122425000.0, 0.0004], [122419000.0, 0.0504]], "asks": [[122493000.0, 0.5749], [122497000.0, 0.0063], [122498000.0, 0.0011], [122499000.0, 0.0183], [122500000.0, 0.0398], [122502000.0, 0.0], [122503000.0, 0.0028], [122504000.0, 0.001], [122505000.0, 0.0094], [122506000.0, 0.0167]]},
{"timestamp": "1743771239856", "bids": [[122446000.0, 0.0036], [122444000.0, 0.0], [122440000.0, 0.0419], [122439000.0, 0.0323], [122437000.0, 0.0204], [122435000.0, 0.0471], [122433000.0, 0.0653], [122431000.0, 0.1616], [122430000.0, 0.0638], [122427000.0, 0.0558]], "asks": [[122493000.0, 0.5749], [122497000.0, 0.0063], [122498000.0, 0.0011], [122499000.0, 0.0183], [122500000.0, 0.0398], [122502000.0, 0.0], [122503000.0, 0.0028], [122504000.0, 0.001], [122505000.0, 0.0094], [122506000.0, 0.0167]]},
{"timestamp": "1743771240362", "bids": [[122447000.0, 0.0331], [122446000.0, 0.0036], [122444000.0, 0.0], [122443000.0, 0.0001], [122440000.0, 0.0556], [122439000.0, 0.0323], [122437000.0, 0.0204], [122435000.0, 0.0471], [122433000.0, 0.0291], [122431000.0, 0.1358]], "asks": [[122493000.0, 0.5749], [122497000.0, 0.0063], [122498000.0, 0.0011], [122499000.0, 0.0183], [122500000.0, 0.0398], [122502000.0, 0.0], [122503000.0, 0.0028], [122504000.0, 0.001], [122505000.0, 0.0094], [122506000.0, 0.0167]]},
{"timestamp": "1743771240853", "bids": [[122447000.0, 0.0344], [122446000.0, 0.0036], [122444000.0, 0.0], [122440000.0, 0.0231], [122436000.0, 0.0772], [122435000.0, 0.0221], [122433000.0, 0.0291], [122431000.0, 0.1358], [122430000.0, 0.0388], [122425000.0, 0.0004]], "asks": [[122493000.0, 0.5749], [122497000.0, 0.0063], [122498000.0, 0.0011], [122499000.0, 0.0183], [122500000.0, 0.0398], [122502000.0, 0.0], [122503000.0, 0.0028], [122504000.0, 0.001], [122505000.0, 0.0094], [122506000.0, 0.0167]]},
{"timestamp": "1743771241353", "bids": [[122479000.0, 0.0204], [122473000.0, 0.0088], [122467000.0, 0.0362], [122465000.0, 0.0258], [122464000.0, 0.0002], [122461000.0, 0.106], [122455000.0, 0.0252], [122446000.0, 0.0036], [122444000.0, 0.0], [122440000.0, 0.0006]], "asks": [[122493000.0, 0.5749], [122497000.0, 0.0063], [122498000.0, 0.0011], [122499000.0, 0.0183], [122500000.0, 0.0398], [122502000.0, 0.0], [122503000.0, 0.0028], [122504000.0, 0.001], [122505000.0, 0.0094], [122506000.0, 0.0167]]},
{"timestamp": "1743771241858", "bids": [[122479000.0, 0.0204], [122477000.0, 0.0001], [122469000.0, 0.025], [122467000.0, 0.0362], [122464000.0, 0.0002], [122463000.0, 0.0248], [122461000.0, 0.0915], [122455000.0, 0.0252], [122446000.0, 0.0036], [122444000.0, 0.0]], "asks": [[122492000.0, 0.1163], [122497000.0, 0.0063], [122498000.0, 0.0011], [122499000.0, 0.0183], [122500000.0, 0.0398], [122502000.0, 0.0], [122503000.0, 0.0028], [122504000.0, 0.001], [122505000.0, 0.0094], [122506000.0, 0.0167]]},
{"timestamp": "1743771242360", "bids": [[122479000.0, 0.0204], [122477000.0, 0.0001], [122469000.0, 0.025], [122467000.0, 0.0291], [122465000.0, 0.0329], [122464000.0, 0.0323], [122463000.0, 0.0248], [122461000.0, 0.0915], [122457000.0, 0.0257], [122453000.0, 0.0005]], "asks": [[122492000.0, 0.16], [122497000.0, 0.0063], [122498000.0, 0.0011], [122499000.0, 0.0183], [122500000.0, 0.0398], [122502000.0, 0.0], [122503000.0, 0.0028], [122504000.0, 0.001], [122505000.0, 0.0094], [122506000.0, 0.0167]]},
{"timestamp": "1743771242855", "bids": [[122467000.0, 0.0291], [122465000.0, 0.0654], [122464000.0, 0.0323], [122463000.0, 0.0247], [122457000.0, 0.0257], [122456000.0, 0.0088], [122453000.0, 0.0005], [122447000.0, 0.0258], [122446000.0, 0.0309], [122444000.0, 0.0]], "asks": [[122492000.0, 0.0328], [122497000.0, 0.0063], [122498000.0, 0.0011], [122499000.0, 0.0183], [122500000.0, 0.0398], [122502000.0, 0.0], [122503000.0, 0.0028], [122504000.0, 0.001], [122505000.0, 0.0094], [122506000.0, 0.0167]]},
{"timestamp": "1743771243354", "bids": [[122467000.0, 0.0291], [122465000.0, 0.0654], [122464000.0, 0.0323], [122460000.0, 0.0221], [122457000.0, 0.0257], [122453000.0, 0.0005], [122451000.0, 0.025], [122447000.0, 0.0253], [122446000.0, 0.0311], [122444000.0, 0.0]], "asks": [[122491000.0, 0.0006], [122497000.0, 0.0063], [122498000.0, 0.0011], [122499000.0, 0.0183], [122500000.0, 0.0398], [122502000.0, 0.0], [122503000.0, 0.0028], [122504000.0, 0.001], [122505000.0, 0.0094], [122506000.0, 0.0167]]},
{"timestamp": "1743771243853", "bids": [[122451000.0, 0.025], [122447000.0, 0.0615], [122446000.0, 0.0311], [122444000.0, 0.0], [122441000.0, 0.0358], [122440000.0, 0.0006], [122435000.0, 0.0252], [122431000.0, 0.0247], [122430000.0, 0.0115], [122425000.0, 0.0004]], "asks": [[122491000.0, 0.0006], [122497000.0, 0.0063], [122498000.0, 0.0011], [122499000.0, 0.0183], [122500000.0, 0.0398], [122502000.0, 0.0], [122503000.0, 0.0028], [122504000.0, 0.001], [122505000.0, 0.0094], [122506000.0, 0.0167]]},
{"timestamp": "1743771244355", "bids": [[122459000.0, 0.0204], [122457000.0, 0.0001], [122454000.0, 0.0413], [122447000.0, 0.0615], [122446000.0, 0.0568], [122445000.0, 0.0001], [122444000.0, 0.0], [122442000.0, 0.0007], [122441000.0, 0.1139], [122440000.0, 0.0006]], "asks": [[122490000.0, 0.1206], [122496000.0, 0.014], [122497000.0, 0.0063], [122498000.0, 0.0011], [122499000.0, 0.0183], [122500000.0, 0.0398], [122502000.0, 0.0], [122503000.0, 0.0028], [122504000.0, 0.001], [122505000.0, 0.0094]]},
{"timestamp": "1743771244856", "bids": [[122459000.0, 0.0204], [122458000.0, 0.0221], [122457000.0, 0.0001], [122456000.0, 0.0291], [122454000.0, 0.1065], [122450000.0, 0.025], [122447000.0, 0.0615], [122446000.0, 0.0568], [122445000.0, 0.0001], [122444000.0, 0.0]], "asks": [[122497000.0, 0.0063], [122498000.0, 0.0011], [122499000.0, 0.0183], [122500000.0, 0.0398], [122502000.0, 0.0], [122503000.0, 0.0028], [122504000.0, 0.001], [122505000.0, 0.0094], [122506000.0, 0.0167], [122507000.0, 0.0053]]},
{"timestamp": "1743771245353", "bids": [[122459000.0, 0.0204], [122458000.0, 0.0221], [122457000.0, 0.0001], [122456000.0, 0.0291], [122454000.0, 0.1065], [122447000.0, 0.0615], [122446000.0, 0.0293], [122444000.0, 0.0], [122442000.0, 0.0007], [122441000.0, 0.0914]], "asks": [[122497000.0, 0.0063], [122498000.0, 0.0011], [122499000.0, 0.0183], [122500000.0, 0.0398], [122502000.0, 0.0], [122503000.0, 0.0028], [122504000.0, 0.001], [122505000.0, 0.0094], [122506000.0, 0.0167], [122507000.0, 0.0053]]},
{"timestamp": "1743771245852", "bids": [[122460000.0, 0.0072], [122459000.0, 0.0204], [122458000.0, 0.0221], [122457000.0, 0.0001], [122456000.0, 0.0291], [122454000.0, 0.1065], [122447000.0, 0.0615], [122446000.0, 0.0301], [122444000.0, 0.0], [122442000.0, 0.0007]], "asks": [[122532000.0, 0.0352], [122534000.0, 0.0001], [122535000.0, 0.0001], [122536000.0, 0.027], [122538000.0, 0.0062], [122539000.0, 0.0012], [122540000.0, 0.0032], [122541000.0, 0.0004], [122543000.0, 0.0058], [122544000.0, 0.0086]]},
{"timestamp": "1743771246355", "bids": [[122459000.0, 0.0204], [122458000.0, 0.0221], [122457000.0, 0.0773], [122456000.0, 0.0291], [122455000.0, 0.0772], [122454000.0, 0.1065], [122447000.0, 0.0615], [122446000.0, 0.0301], [122444000.0, 0.0], [122442000.0, 0.0007]], "asks": [[122532000.0, 0.0352], [122534000.0, 0.0001], [122535000.0, 0.0001], [122536000.0, 0.027], [122538000.0, 0.0062], [122539000.0, 0.0012], [122540000.0, 0.0032], [122541000.0, 0.0004], [122543000.0, 0.0058], [122544000.0, 0.0086]]},
{"timestamp": "1743771246855", "bids": [[122459000.0, 0.0204], [122458000.0, 0.0221], [122457000.0, 0.0773], [122456000.0, 0.0291], [122454000.0, 0.1065], [122447000.0, 0.0615], [122446000.0, 0.0301], [122444000.0, 0.0], [122442000.0, 0.0007], [122441000.0, 0.0914]], "asks": [[122532000.0, 0.0352], [122534000.0, 0.0001], [122535000.0, 0.0001], [122536000.0, 0.027], [122538000.0, 0.0062], [122539000.0, 0.0012], [122540000.0, 0.0032], [122541000.0, 0.0004], [122543000.0, 0.0058], [122544000.0, 0.0086]]},
{"timestamp": "1743771247452", "bids": [[122460000.0, 0.0962], [122459000.0, 0.0204], [122458000.0, 0.0221], [122457000.0, 0.0001], [122456000.0, 0.0291], [122455000.0, 0.0771], [122454000.0, 0.0977], [122447000.0, 0.0253], [122446000.0, 0.0301], [122444000.0, 0.0]], "asks": [[122532000.0, 0.0132], [122534000.0, 0.0001], [122535000.0, 0.0001], [122536000.0, 0.027], [122538000.0, 0.0062], [122539000.0, 0.0012], [122540000.0, 0.0032], [122541000.0, 0.0004], [122543000.0, 0.0058], [122544000.0, 0.0086]]},
{"timestamp": "1743771247856", "bids": [[122460000.0, 0.0191], [122458000.0, 0.0221], [122457000.0, 0.0001], [122455000.0, 0.0771], [122454000.0, 0.0323], [122447000.0, 0.0253], [122446000.0, 0.0044], [122444000.0, 0.0], [122441000.0, 0.0358], [122440000.0, 0.0231]], "asks": [[122534000.0, 0.0001], [122535000.0, 0.0001], [122536000.0, 0.027], [122538000.0, 0.0062], [122539000.0, 0.0012], [122540000.0, 0.0032], [122541000.0, 0.0004], [122543000.0, 0.0058], [122544000.0, 0.0086], [122545000.0, 0.0008]]},
{"timestamp": "1743771248376", "bids": [[122446000.0, 0.002], [122444000.0, 0.0], [122442000.0, 0.0115], [122441000.0, 0.0358], [122440000.0, 0.0006], [122431000.0, 0.025], [122430000.0, 0.0115], [122429000.0, 0.0362], [122426000.0, 0.0002], [122425000.0, 0.0004]], "asks": [[122447000.0, 0.4425], [122531000.0, 0.16], [122534000.0, 0.0001], [122535000.0, 0.0115], [122536000.0, 0.027], [122538000.0, 0.0062], [122539000.0, 0.0012], [122540000.0, 0.0032], [122541000.0, 0.0004], [122542000.0, 0.0242]]},
{"timestamp": "1743771248857", "bids": [[122446000.0, 0.002], [122444000.0, 0.0], [122442000.0, 0.0319], [122441000.0, 0.0291], [122440000.0, 0.0231], [122436000.0, 0.0088], [122431000.0, 0.0251], [122430000.0, 0.0444], [122429000.0, 0.0362], [122426000.0, 0.03]], "asks": [[122447000.0, 0.3654], [122531000.0, 0.16], [122534000.0, 0.0001], [122535000.0, 0.0115], [122536000.0, 0.027], [122538000.0, 0.0062], [122539000.0, 0.0012], [122540000.0, 0.0384], [122541000.0, 0.0004], [122542000.0, 0.0242]]},
{"timestamp": "1743771255855", "bids": [[122446000.0, 1.0016], [122444000.0, 0.0], [122440000.0, 0.0006], [122430000.0, 0.0115], [122425000.0, 0.0], [122415000.0, 0.0036], [122410000.0, 0.0016], [122409000.0, 0.0], [122407000.0, 0.0], [122396000.0, 0.0]], "asks": [[122447000.0, 0.2642], [122453000.0, 0.054], [122486000.0, 0.0168], [122487000.0, 0.022], [122495000.0, 0.0001], [122502000.0, 0.0048], [122508000.0, 0.0181], [122514000.0, 0.0174], [122515000.0, 0.0118], [122518000.0, 0.0253]]},
{"timestamp": "1743771256365", "bids": [[122446000.0, 1.0016], [122444000.0, 0.0], [122440000.0, 0.0006], [122430000.0, 0.0115], [122425000.0, 0.0], [122415000.0, 0.0036], [122410000.0, 0.0016], [122409000.0, 0.0017], [122407000.0, 0.0], [122396000.0, 0.0]], "asks": [[122447000.0, 0.2606], [122453000.0, 0.054], [122487000.0, 0.0665], [122495000.0, 0.0001], [122499000.0, 0.0217], [122502000.0, 0.0183], [122503000.0, 0.0129], [122505000.0, 0.0144], [122510000.0, 0.0171], [122511000.0, 0.0271]]},
{"timestamp": "1743771256855", "bids": [[122446000.0, 1.0016], [122444000.0, 0.0], [122440000.0, 0.0006], [122430000.0, 0.0115], [122425000.0, 0.0], [122415000.0, 0.0036], [122410000.0, 0.0016], [122409000.0, 0.0017], [122407000.0, 0.0], [122396000.0, 0.0]], "asks": [[122447000.0, 0.2606], [122453000.0, 0.054], [122490000.0, 0.0173], [122491000.0, 0.0227], [122494000.0, 0.0242], [122495000.0, 0.0001], [122503000.0, 0.0129], [122507000.0, 0.0166], [122511000.0, 0.0199], [122512000.0, 0.0399]]},
{"timestamp": "1743771257357", "bids": [[122446000.0, 1.0016], [122444000.0, 0.0], [122440000.0, 0.0006], [122430000.0, 0.0115], [122425000.0, 0.0], [122415000.0, 0.0036], [122410000.0, 0.0016], [122409000.0, 0.0017], [122407000.0, 0.0], [122396000.0, 0.0]], "asks": [[122447000.0, 0.2569], [122453000.0, 0.054], [122490000.0, 0.0173], [122491000.0, 0.0227], [122492000.0, 0.0467], [122493000.0, 0.0282], [122494000.0, 0.0506], [122495000.0, 0.0199], [122507000.0, 0.0383], [122509000.0, 0.0129]]},
{"timestamp": "1743771257856", "bids": [[122446000.0, 1.0016], [122444000.0, 0.0], [122440000.0, 0.0006], [122430000.0, 0.0115], [122425000.0, 0.0], [122415000.0, 0.0036], [122410000.0, 0.0016], [122409000.0, 0.0017], [122407000.0, 0.0], [122400000.0, 0.0016]], "asks": [[122447000.0, 0.2569], [122453000.0, 0.054], [122490000.0, 0.0173], [122491000.0, 0.0227], [122492000.0, 0.0467], [122493000.0, 0.0282], [122494000.0, 0.0506], [122495000.0, 0.0199], [122507000.0, 0.0383], [122509000.0, 0.0129]]},
{"timestamp": "1743771258357", "bids": [[122446000.0, 1.0016], [122444000.0, 0.0], [122440000.0, 0.0006], [122430000.0, 0.0115], [122425000.0, 0.0], [122415000.0, 0.0036], [122410000.0, 0.0016], [122409000.0, 0.0017], [122407000.0, 0.0], [122400000.0, 0.0098]], "asks": [[122447000.0, 0.2982], [122453000.0, 0.054], [122490000.0, 0.0173], [122491000.0, 0.0227], [122492000.0, 0.022], [122493000.0, 0.0282], [122494000.0, 0.0506], [122495000.0, 0.0199], [122507000.0, 0.0383], [122509000.0, 0.0129]]},
{"timestamp": "1743771258859", "bids": [[122446000.0, 1.0016], [122444000.0, 0.0], [122440000.0, 0.0006], [122430000.0, 0.0115], [122425000.0, 0.0], [122415000.0, 0.0036], [122410000.0, 0.0016], [122409000.0, 0.0017], [122407000.0, 0.0], [122400000.0, 0.0098]], "asks": [[122447000.0, 0.3743], [122453000.0, 0.054], [122491000.0, 0.0227], [122492000.0, 0.022], [122493000.0, 0.0282], [122494000.0, 0.0264], [122495000.0, 0.0001], [122507000.0, 0.0217], [122509000.0, 0.0129], [122511000.0, 0.0488]]},
{"timestamp": "1743771259361", "bids": [[122446000.0, 1.0016], [122444000.0, 0.0], [122440000.0, 0.0006], [122430000.0, 0.0115], [122425000.0, 0.0], [122415000.0, 0.0036], [122410000.0, 0.0016], [122409000.0, 0.0017], [122407000.0, 0.0], [122400000.0, 0.0098]], "asks": [[122447000.0, 0.3843], [122453000.0, 0.054], [122495000.0, 0.0001], [122511000.0, 0.0362], [122520000.0, 0.0013], [122529000.0, 0.0225], [122532000.0, 0.02], [122534000.0, 0.0001], [122535000.0, 0.0001], [122536000.0, 0.027]]},
{"timestamp": "1743771259865", "bids": [[122446000.0, 1.0016], [122444000.0, 0.0], [122440000.0, 0.0006], [122430000.0, 0.0115], [122425000.0, 0.0], [122415000.0, 0.0036], [122410000.0, 0.0016], [122409000.0, 0.0017], [122407000.0, 0.0], [122400000.0, 0.0098]], "asks": [[122447000.0, 0.2588], [122453000.0, 0.054], [122460000.0, 0.0242], [122462000.0, 0.0173], [122464000.0, 0.0247], [122465000.0, 0.0198], [122479000.0, 0.0174], [122485000.0, 0.0181], [122486000.0, 0.0295], [122488000.0, 0.0166]]},
{"timestamp": "1743771260356", "bids": [[122446000.0, 1.0016], [122444000.0, 0.0], [122440000.0, 0.0006], [122430000.0, 0.0115], [122425000.0, 0.0], [122415000.0, 0.0036], [122410000.0, 0.0016], [122409000.0, 0.0017], [122407000.0, 0.0], [122400000.0, 0.0098]], "asks": [[122447000.0, 0.2487], [122453000.0, 0.054], [122454000.0, 0.022], [122455000.0, 0.0114], [122460000.0, 0.0242], [122462000.0, 0.0173], [122464000.0, 0.0247], [122465000.0, 0.0198], [122469000.0, 0.0217], [122472000.0, 0.0327]]},
{"timestamp": "1743771261054", "bids": [[122446000.0, 1.0016], [122444000.0, 0.0], [122430000.0, 0.0115], [122425000.0, 0.0], [122415000.0, 0.0882], [122410000.0, 0.0016], [122409000.0, 0.0017], [122407000.0, 0.0], [122400000.0, 0.0098], [122396000.0, 0.0]], "asks": [[122447000.0, 0.2325], [122453000.0, 0.054], [122455000.0, 0.0114], [122456000.0, 0.0168], [122457000.0, 0.0491], [122462000.0, 0.0173], [122464000.0, 0.0247], [122469000.0, 0.0217], [122472000.0, 0.0183], [122476000.0, 0.0171]]},
{"timestamp": "1743771261358", "bids": [[122446000.0, 1.0016], [122444000.0, 0.0], [122430000.0, 0.0115], [122425000.0, 0.0], [122415000.0, 0.0882], [122410000.0, 0.0016], [122409000.0, 0.0017], [122407000.0, 0.0], [122400000.0, 0.0098], [122396000.0, 0.0]], "asks": [[122447000.0, 0.2325], [122453000.0, 0.054], [122455000.0, 0.0114], [122456000.0, 0.0168], [122457000.0, 0.0491], [122462000.0, 0.0173], [122463000.0, 0.022], [122464000.0, 0.0247], [122469000.0, 0.0217], [122472000.0, 0.0183]]},
{"timestamp": "1743771261853", "bids": [[122446000.0, 1.0016], [122444000.0, 0.0], [122430000.0, 0.0115], [122425000.0, 0.0], [122415000.0, 0.0882], [122410000.0, 0.0016], [122409000.0, 0.0017], [122407000.0, 0.0], [122400000.0, 0.0098], [122396000.0, 0.0]], "asks": [[122447000.0, 0.2325], [122453000.0, 0.054], [122455000.0, 0.0114], [122456000.0, 0.0168], [122457000.0, 0.0491], [122462000.0, 0.0173], [122463000.0, 0.022], [122464000.0, 0.0247], [122469000.0, 0.0217], [122472000.0, 0.0183]]},
{"timestamp": "1743771262363", "bids": [[122446000.0, 1.0016], [122444000.0, 0.0], [122430000.0, 0.0115], [122428000.0, 0.0016], [122425000.0, 0.0], [122415000.0, 0.0882], [122410000.0, 0.0016], [122409000.0, 0.0017], [122408000.0, 0.0225], [122407000.0, 0.0]], "asks": [[122447000.0, 0.2325], [122453000.0, 0.054], [122455000.0, 0.0114], [122456000.0, 0.0168], [122457000.0, 0.0491], [122462000.0, 0.0173], [122463000.0, 0.022], [122464000.0, 0.0247], [122469000.0, 0.0217], [122472000.0, 0.0183]]},
{"timestamp": "1743771262861", "bids": [[122446000.0, 1.0016], [122444000.0, 0.0], [122430000.0, 0.0115], [122428000.0, 0.0016], [122425000.0, 0.0], [122415000.0, 0.0882], [122410000.0, 0.0016], [122409000.0, 0.0017], [122408000.0, 0.0225], [122407000.0, 0.0]], "asks": [[122447000.0, 0.2325], [122453000.0, 0.054], [122455000.0, 0.0114], [122456000.0, 0.0168], [122457000.0, 0.0491], [122462000.0, 0.0173], [122463000.0, 0.022], [122464000.0, 0.0247], [122469000.0, 0.0217], [122472000.0, 0.0183]]},
{"timestamp": "1743771263360", "bids": [[122446000.0, 1.0016], [122444000.0, 0.0], [122430000.0, 0.0115], [122428000.0, 0.0016], [122425000.0, 0.0], [122415000.0, 0.0882], [122410000.0, 0.0016], [122409000.0, 0.0017], [122408000.0, 0.0225], [122407000.0, 0.0]], "asks": [[122447000.0, 0.2325], [122453000.0, 0.054], [122455000.0, 0.0114], [122456000.0, 0.0168], [122457000.0, 0.0491], [122462000.0, 0.0173], [122463000.0, 0.022], [122464000.0, 0.0247], [122469000.0, 0.0217], [122472000.0, 0.0183]]},
{"timestamp": "1743771263861", "bids": [[122446000.0, 1.0016], [122444000.0, 0.0], [122430000.0, 0.0115], [122428000.0, 0.0016], [122425000.0, 0.0], [122415000.0, 0.0882], [122410000.0, 0.0016], [122409000.0, 0.0017], [122407000.0, 0.0], [122400000.0, 0.0098]], "asks": [[122447000.0, 0.2325], [122453000.0, 0.054], [122455000.0, 0.0114], [122456000.0, 0.0168], [122457000.0, 0.0491], [122462000.0, 0.0173], [122463000.0, 0.022], [122464000.0, 0.0247], [122469000.0, 0.0217], [122472000.0, 0.0183]]},
{"timestamp": "1743771264355", "bids": [[122446000.0, 1.0016], [122444000.0, 0.0], [122430000.0, 0.0115], [122428000.0, 0.0016], [122425000.0, 0.0], [122415000.0, 0.0882], [122410000.0, 0.0016], [122409000.0, 0.0017], [122407000.0, 0.0], [122400000.0, 0.0098]], "asks": [[122447000.0, 0.2325], [122453000.0, 0.054], [122455000.0, 0.0114], [122456000.0, 0.0168], [122457000.0, 0.0491], [122462000.0, 0.0173], [122463000.0, 0.022], [122464000.0, 0.0247], [122469000.0, 0.0217], [122472000.0, 0.0183]]},
{"timestamp": "1743771264862", "bids": [[122446000.0, 1.0016], [122444000.0, 0.0], [122430000.0, 0.0115], [122428000.0, 0.0016], [122425000.0, 0.0], [122415000.0, 0.0882], [122410000.0, 0.0016], [122409000.0, 0.0017], [122407000.0, 0.0], [122400000.0, 0.0098]], "asks": [[122447000.0, 0.2325], [122453000.0, 0.054], [122455000.0, 0.0114], [122456000.0, 0.0168], [122457000.0, 0.0491], [122462000.0, 0.0173], [122463000.0, 0.022], [122464000.0, 0.0247], [122469000.0, 0.0217], [122472000.0, 0.0183]]},
{"timestamp": "1743771265358", "bids": [[122446000.0, 1.0016], [122444000.0, 0.0], [122430000.0, 0.0115], [122428000.0, 0.0016], [122425000.0, 0.0], [122415000.0, 0.0882], [122410000.0, 0.0016], [122409000.0, 0.0017], [122407000.0, 0.0], [122400000.0, 0.0098]], "asks": [[122447000.0, 0.2324], [122453000.0, 0.054], [122455000.0, 0.0114], [122456000.0, 0.0168], [122457000.0, 0.0491], [122462000.0, 0.0173], [122463000.0, 0.022], [122464000.0, 0.0247], [122469000.0, 0.0217], [122472000.0, 0.0183]]},
{"timestamp": "1743771265863", "bids": [[122446000.0, 1.0016], [122444000.0, 0.0], [122430000.0, 0.0115], [122428000.0, 0.0016], [122425000.0, 0.0], [122415000.0, 0.0882], [122410000.0, 0.0016], [122409000.0, 0.0017], [122407000.0, 0.0], [122400000.0, 0.0098]], "asks": [[122447000.0, 0.2324], [122453000.0, 0.054], [122455000.0, 0.0114], [122456000.0, 0.0168], [122457000.0, 0.0491], [122462000.0, 0.0173], [122463000.0, 0.022], [122464000.0, 0.0247], [122469000.0, 0.0217], [122472000.0, 0.0183]]},
{"timestamp": "1743771266354", "bids": [[122446000.0, 1.0016], [122444000.0, 0.0], [122430000.0, 0.0115], [122428000.0, 0.0016], [122425000.0, 0.0], [122415000.0, 0.0882], [122410000.0, 0.0016], [122409000.0, 0.0017], [122407000.0, 0.0], [122400000.0, 0.0098]], "asks": [[122447000.0, 0.2299], [122453000.0, 0.054], [122455000.0, 0.0114], [122462000.0, 0.0173], [122464000.0, 0.0247], [122476000.0, 0.0171], [122481000.0, 0.031], [122482000.0, 0.0126], [122485000.0, 0.0181], [122486000.0, 0.0167]]},
{"timestamp": "1743771266862", "bids": [[122446000.0, 1.0209], [122444000.0, 0.0], [122430000.0, 0.0115], [122428000.0, 0.0016], [122425000.0, 0.0], [122415000.0, 0.0882], [122410000.0, 0.0016], [122409000.0, 0.0017], [122407000.0, 0.0], [122400000.0, 0.0098]], "asks": [[122447000.0, 0.2299], [122453000.0, 0.054], [122465000.0, 0.0425], [122468000.0, 0.0242], [122478000.0, 0.0217], [122481000.0, 0.0166], [122482000.0, 0.0168], [122485000.0, 0.0199], [122486000.0, 0.0399], [122487000.0, 0.0153]]},
{"timestamp": "1743771267359", "bids": [[122446000.0, 1.0209], [122444000.0, 0.0], [122430000.0, 0.0115], [122428000.0, 0.0016], [122425000.0, 0.0], [122415000.0, 0.0882], [122410000.0, 0.0016], [122409000.0, 0.0017], [122407000.0, 0.0], [122400000.0, 0.0098]], "asks": [[122447000.0, 0.2299], [122453000.0, 0.054], [122465000.0, 0.0425], [122468000.0, 0.0506], [122478000.0, 0.0217], [122481000.0, 0.0166], [122482000.0, 0.0168], [122484000.0, 0.022], [122485000.0, 0.0313], [122486000.0, 0.0399]]},
{"timestamp": "1743771267865", "bids": [[122446000.0, 1.0016], [122444000.0, 0.0], [122430000.0, 0.0115], [122428000.0, 0.0016], [122425000.0, 0.0], [122415000.0, 0.0882], [122410000.0, 0.0016], [122409000.0, 0.0021], [122407000.0, 0.0], [122400000.0, 0.0098]], "asks": [[122447000.0, 0.2298], [122453000.0, 0.054], [122485000.0, 0.0287], [122487000.0, 0.0247], [122495000.0, 0.0001], [122498000.0, 0.0183], [122504000.0, 0.0144], [122505000.0, 0.0171], [122507000.0, 0.093], [122508000.0, 0.0167]]},
{"timestamp": "1743771268373", "bids": [[122446000.0, 0.0016], [122444000.0, 0.0], [122430000.0, 0.0115], [122428000.0, 0.0016], [122425000.0, 0.0], [122415000.0, 0.0882], [122410000.0, 0.0016], [122409000.0, 0.0021], [122407000.0, 0.0], [122400000.0, 0.0107]], "asks": [[122447000.0, 0.2298], [122453000.0, 0.054], [122485000.0, 0.0287], [122487000.0, 0.0467], [122495000.0, 0.0001], [122498000.0, 0.0183], [122503000.0, 0.0129], [122504000.0, 0.0144], [122505000.0, 0.0171], [122506000.0, 0.0126]]},
{"timestamp": "1743771268859", "bids": [[122446000.0, 0.0031], [122444000.0, 0.0], [122430000.0, 0.0115], [122428000.0, 0.0016], [122425000.0, 0.0], [122415000.0, 0.0882], [122410000.0, 0.0016], [122409000.0, 0.0021], [122407000.0, 0.0], [122402000.0, 0.0225]], "asks": [[122447000.0, 0.2298], [122453000.0, 0.054], [122485000.0, 0.0114], [122495000.0, 0.0001], [122498000.0, 0.041], [122503000.0, 0.0129], [122504000.0, 0.0144], [122507000.0, 0.0036], [122508000.0, 0.0174], [122513000.0, 0.0222]]},
{"timestamp": "1743771269358", "bids": [[122446000.0, 0.0129], [122444000.0, 0.0], [122430000.0, 0.0115], [122428000.0, 0.0016], [122425000.0, 0.0], [122424000.0, 0.0], [122415000.0, 0.0882], [122410000.0, 0.0016], [122409000.0, 0.0021], [122407000.0, 0.0]], "asks": [[122447000.0, 0.2298], [122453000.0, 0.054], [122495000.0, 0.0001], [122496000.0, 0.0173], [122497000.0, 0.0168], [122498000.0, 0.0645], [122500000.0, 0.0242], [122507000.0, 0.0036], [122509000.0, 0.0115], [122510000.0, 0.0217]]},
{"timestamp": "1743771269869", "bids": [[122446000.0, 0.0016], [122444000.0, 0.0], [122430000.0, 0.0115], [122428000.0, 0.0016], [122425000.0, 0.0], [122424000.0, 0.0], [122415000.0, 0.0882], [122410000.0, 0.0016], [122409000.0, 0.0021], [122407000.0, 0.0]], "asks": [[122447000.0, 0.2298], [122453000.0, 0.054], [122492000.0, 0.0008], [122495000.0, 0.0001], [122496000.0, 0.0173], [122497000.0, 0.0168], [122498000.0, 0.0892], [122500000.0, 0.0242], [122501000.0, 0.0264], [122507000.0, 0.0036]]},
{"timestamp": "1743771270356", "bids": [[122446000.0, 0.0016], [122444000.0, 0.0], [122430000.0, 0.0115], [122428000.0, 0.0016], [122425000.0, 0.0], [122424000.0, 0.0], [122415000.0, 0.0882], [122410000.0, 0.0016], [122409000.0, 0.0021], [122408000.0, 0.0]], "asks": [[122447000.0, 0.2298], [122453000.0, 0.054], [122492000.0, 0.0008], [122495000.0, 0.0001], [122498000.0, 0.0418], [122501000.0, 0.0264], [122507000.0, 0.0036], [122513000.0, 0.0222], [122517000.0, 0.0], [122520000.0, 0.0013]]},
{"timestamp": "1743771270869", "bids": [[122446000.0, 0.0016], [122444000.0, 0.0], [122430000.0, 0.0115], [122428000.0, 0.0016], [122425000.0, 0.0041], [122424000.0, 0.0], [122415000.0, 0.0882], [122410000.0, 0.0016], [122409000.0, 0.0021], [122408000.0, 0.0]], "asks": [[122447000.0, 0.2298], [122453000.0, 0.054], [122485000.0, 0.0341], [122486000.0, 0.0247], [122487000.0, 0.022], [122492000.0, 0.0008], [122494000.0, 0.0114], [122495000.0, 0.0001], [122500000.0, 0.0115], [122507000.0, 0.0219]]},
{"timestamp": "1743771271364", "bids": [[122446000.0, 0.0016], [122444000.0, 0.0], [122430000.0, 0.0115], [122428000.0, 0.0016], [122425000.0, 0.0041], [122424000.0, 0.0], [122415000.0, 0.0882], [122410000.0, 0.0016], [122409000.0, 0.0021], [122408000.0, 0.0]], "asks": [[122447000.0, 0.2437], [122453000.0, 0.054], [122485000.0, 0.0341], [122486000.0, 0.0247], [122487000.0, 0.0645], [122488000.0, 0.0264], [122489000.0, 0.0242], [122492000.0, 0.0008], [122494000.0, 0.0114], [122495000.0, 0.0001]]},
{"timestamp": "1743771272059", "bids": [[122446000.0, 0.0016], [122444000.0, 0.0], [122430000.0, 0.0115], [122428000.0, 0.0016], [122425000.0, 0.0041], [122424000.0, 0.0], [122415000.0, 0.0882], [122410000.0, 0.0016], [122409000.0, 0.0021], [122408000.0, 0.0]], "asks": [[122447000.0, 0.3977], [122453000.0, 0.054], [122486000.0, 0.0247], [122487000.0, 0.0115], [122488000.0, 0.0264], [122492000.0, 0.0008], [122494000.0, 0.0114], [122495000.0, 0.0001], [122504000.0, 0.0222], [122505000.0, 0.0126]]},
{"timestamp": "1743771272360", "bids": [[122446000.0, 0.0016], [122444000.0, 0.0], [122430000.0, 0.0115], [122428000.0, 0.0016], [122425000.0, 0.0041], [122424000.0, 0.0], [122415000.0, 0.0882], [122410000.0, 0.0016], [122409000.0, 0.0021], [122408000.0, 0.0]], "asks": [[122447000.0, 0.3983], [122453000.0, 0.054], [122474000.0, 0.0242], [122487000.0, 0.0115], [122488000.0, 0.0129], [122490000.0, 0.0144], [122492000.0, 0.0207], [122493000.0, 0.0181], [122495000.0, 0.0001], [122504000.0, 0.0222]]},
{"timestamp": "1743771272865", "bids": [[122446000.0, 0.0016], [122444000.0, 0.0], [122430000.0, 0.0115], [122428000.0, 0.0016], [122425000.0, 0.0041], [122424000.0, 0.0], [122415000.0, 0.0882], [122410000.0, 0.0016], [122409000.0, 0.0021], [122408000.0, 0.0]], "asks": [[122447000.0, 0.2298], [122453000.0, 0.054], [122472000.0, 0.0665], [122474000.0, 0.0506], [122484000.0, 0.0217], [122488000.0, 0.0129], [122490000.0, 0.0144], [122491000.0, 0.0126], [122492000.0, 0.0207], [122493000.0, 0.0679]]},
{"timestamp": "1743771273356", "bids": [[122446000.0, 0.0016], [122444000.0, 0.0], [122430000.0, 0.0115], [122428000.0, 0.0016], [122425000.0, 0.0041], [122424000.0, 0.0], [122415000.0, 0.0882], [122410000.0, 0.0016], [122409000.0, 0.0021], [122408000.0, 0.0]], "asks": [[122447000.0, 0.2295], [122453000.0, 0.054], [122472000.0, 0.0665], [122474000.0, 0.0506], [122484000.0, 0.0217], [122488000.0, 0.0129], [122490000.0, 0.0259], [122491000.0, 0.0126], [122492000.0, 0.0207], [122493000.0, 0.0679]]},
{"timestamp": "1743771273864", "bids": [[122446000.0, 0.0016], [122444000.0, 0.0], [122430000.0, 0.0115], [122428000.0, 0.0016], [122425000.0, 0.0041], [122424000.0, 0.0], [122415000.0, 0.0882], [122410000.0, 0.0016], [122409000.0, 0.0021], [122408000.0, 0.0]], "asks": [[122447000.0, 0.2295], [122453000.0, 0.054], [122472000.0, 0.0665], [122474000.0, 0.0506], [122480000.0, 0.0008], [122484000.0, 0.0217], [122488000.0, 0.0129], [122490000.0, 0.0259], [122491000.0, 0.0126], [122492000.0, 0.0207]]},
{"timestamp": "1743771274359", "bids": [[122446000.0, 0.0016], [122444000.0, 0.0], [122430000.0, 0.0115], [122428000.0, 0.0016], [122425000.0, 0.0041], [122424000.0, 0.0], [122415000.0, 0.0882], [122410000.0, 0.0016], [122409000.0, 0.0021], [122408000.0, 0.0]], "asks": [[122447000.0, 0.2295], [122453000.0, 0.054], [122472000.0, 0.0665], [122474000.0, 0.0506], [122480000.0, 0.0008], [122484000.0, 0.0217], [122488000.0, 0.0129], [122490000.0, 0.0259], [122491000.0, 0.0126], [122492000.0, 0.0207]]},
{"timestamp": "1743771274866", "bids": [[122446000.0, 0.0016], [122444000.0, 0.0], [122430000.0, 0.0115], [122428000.0, 0.0016], [122425000.0, 0.0041], [122424000.0, 0.0], [122415000.0, 0.0882], [122410000.0, 0.0016], [122409000.0, 0.0021], [122408000.0, 0.0]], "asks": [[122447000.0, 0.3873], [122453000.0, 0.054], [122472000.0, 0.0665], [122474000.0, 0.0506], [122480000.0, 0.0008], [122484000.0, 0.0217], [122486000.0, 0.0115], [122488000.0, 0.0129], [122490000.0, 0.0144], [122491000.0, 0.0126]]},
{"timestamp": "1743771275365", "bids": [[122446000.0, 0.0016], [122444000.0, 0.0], [122430000.0, 0.0115], [122428000.0, 0.0016], [122425000.0, 0.0041], [122424000.0, 0.0], [122415000.0, 0.0882], [122410000.0, 0.0016], [122409000.0, 0.0021], [122408000.0, 0.0]], "asks": [[122447000.0, 0.2295], [122453000.0, 0.054], [122472000.0, 0.0665], [122474000.0, 0.0506], [122480000.0, 0.0008], [122484000.0, 0.0217], [122486000.0, 0.0115], [122488000.0, 0.0129], [122490000.0, 0.0144], [122491000.0, 0.0126]]},
{"timestamp": "1743771275863", "bids": [[122447000.0, 0.7704], [122446000.0, 0.0016], [122444000.0, 0.0], [122434000.0, 0.0007], [122430000.0, 0.0115], [122428000.0, 0.0016], [122425000.0, 0.0041], [122424000.0, 0.0], [122415000.0, 0.0882], [122410000.0, 0.0016]], "asks": [[122453000.0, 0.054], [122472000.0, 0.0759], [122473000.0, 0.0227], [122480000.0, 0.0008], [122486000.0, 0.0115], [122489000.0, 0.0166], [122490000.0, 0.0144], [122492000.0, 0.0207], [122493000.0, 0.0181], [122494000.0, 0.0177]]},
{"timestamp": "1743771276358", "bids": [[122447000.0, 0.771], [122446000.0, 0.0209], [122444000.0, 0.0], [122434000.0, 0.0007], [122430000.0, 0.0115], [122428000.0, 0.0016], [122425000.0, 0.0041], [122424000.0, 0.0], [122415000.0, 0.0882], [122410000.0, 0.0016]], "asks": [[122453000.0, 0.054], [122475000.0, 0.0114], [122480000.0, 0.0008], [122483000.0, 0.0242], [122486000.0, 0.0217], [122488000.0, 0.0183], [122491000.0, 0.0129], [122492000.0, 0.0008], [122495000.0, 0.0168], [122497000.0, 0.0179]]},
{"timestamp": "1743771276863", "bids": [[122447000.0, 0.771], [122446000.0, 0.0016], [122444000.0, 0.0], [122434000.0, 0.0007], [122430000.0, 0.0115], [122428000.0, 0.0016], [122425000.0, 0.0041], [122424000.0, 0.0], [122415000.0, 0.0882], [122410000.0, 0.0016]], "asks": [[122453000.0, 0.054], [122475000.0, 0.0114], [122476000.0, 0.0264], [122480000.0, 0.0008], [122483000.0, 0.0242], [122485000.0, 0.0796], [122486000.0, 0.0217], [122488000.0, 0.0183], [122492000.0, 0.0008], [122494000.0, 0.0467]]},
{"timestamp": "1743771277421", "bids": [[122447000.0, 0.771], [122446000.0, 0.0016], [122444000.0, 0.0], [122434000.0, 0.0007], [122430000.0, 0.0115], [122428000.0, 0.0016], [122425000.0, 0.0041], [122424000.0, 0.0], [122415000.0, 0.0882], [122410000.0, 0.0016]], "asks": [[122453000.0, 0.054], [122475000.0, 0.0114], [122476000.0, 0.0264], [122480000.0, 0.0008], [122483000.0, 0.0242], [122485000.0, 0.0796], [122486000.0, 0.0217], [122488000.0, 0.0183], [122492000.0, 0.0008], [122494000.0, 0.0467]]},
{"timestamp": "1743771277869", "bids": [[122447000.0, 0.771], [122446000.0, 0.0016], [122444000.0, 0.0], [122434000.0, 0.0007], [122430000.0, 0.0115], [122428000.0, 0.0016], [122425000.0, 0.0041], [122424000.0, 0.0], [122415000.0, 0.0882], [122410000.0, 0.0016]], "asks": [[122453000.0, 0.054], [122475000.0, 0.0114], [122476000.0, 0.0264], [122480000.0, 0.0008], [122483000.0, 0.0242], [122486000.0, 0.0217], [122488000.0, 0.0183], [122492000.0, 0.0008], [122494000.0, 0.0467], [122495000.0, 0.0001]]},
{"timestamp": "1743771278360", "bids": [[122447000.0, 0.771], [122446000.0, 0.0016], [122444000.0, 0.0], [122434000.0, 0.0007], [122430000.0, 0.0115], [122428000.0, 0.0016], [122425000.0, 0.0041], [122424000.0, 0.0], [122415000.0, 0.0882], [122410000.0, 0.0016]], "asks": [[122453000.0, 0.054], [122475000.0, 0.0114], [122476000.0, 0.0264], [122480000.0, 0.0008], [122483000.0, 0.0242], [122485000.0, 0.0796], [122486000.0, 0.0217], [122488000.0, 0.0183], [122492000.0, 0.0008], [122494000.0, 0.0467]]},
{"timestamp": "1743771278866", "bids": [[122447000.0, 0.771], [122446000.0, 0.0016], [122444000.0, 0.0], [122434000.0, 0.0007], [122430000.0, 0.0115], [122428000.0, 0.0016], [122425000.0, 0.0041], [122424000.0, 0.0], [122415000.0, 0.0882], [122410000.0, 0.0016]], "asks": [[122453000.0, 0.054], [122475000.0, 0.0114], [122476000.0, 0.0264], [122480000.0, 0.0008], [122483000.0, 0.0242], [122485000.0, 0.0796], [122486000.0, 0.0217], [122488000.0, 0.0183], [122492000.0, 0.0008], [122494000.0, 0.0467]]},
{"timestamp": "1743771279363", "bids": [[122447000.0, 0.7464], [122446000.0, 0.0016], [122444000.0, 0.0], [122434000.0, 0.0007], [122430000.0, 0.0115], [122428000.0, 0.0016], [122425000.0, 0.0041], [122424000.0, 0.0], [122415000.0, 0.0882], [122410000.0, 0.0016]], "asks": [[122453000.0, 0.0539], [122475000.0, 0.0114], [122476000.0, 0.0264], [122480000.0, 0.0008], [122483000.0, 0.0242], [122486000.0, 0.0217], [122488000.0, 0.0183], [122492000.0, 0.0008], [122494000.0, 0.0467], [122495000.0, 0.0001]]},
{"timestamp": "1743771279867", "bids": [[122447000.0, 0.7505], [122446000.0, 0.0016], [122444000.0, 0.0], [122434000.0, 0.0007], [122430000.0, 0.0115], [122428000.0, 0.0016], [122425000.0, 0.0041], [122424000.0, 0.0], [122415000.0, 0.0882], [122410000.0, 0.0016]], "asks": [[122453000.0, 0.0539], [122475000.0, 0.0114], [122476000.0, 0.0264], [122480000.0, 0.0008], [122483000.0, 0.0242], [122485000.0, 0.0798], [122486000.0, 0.0217], [122488000.0, 0.0183], [122492000.0, 0.0008], [122494000.0, 0.0467]]},
{"timestamp": "1743771280367", "bids": [[122447000.0, 0.7505], [122446000.0, 0.0016], [122444000.0, 0.0], [122434000.0, 0.0007], [122430000.0, 0.0115], [122428000.0, 0.0016], [122425000.0, 0.0041], [122424000.0, 0.0], [122415000.0, 0.0882], [122410000.0, 0.0016]], "asks": [[122453000.0, 0.0539], [122475000.0, 0.0114], [122476000.0, 0.0264], [122480000.0, 0.0008], [122483000.0, 0.0242], [122486000.0, 0.0217], [122488000.0, 0.0183], [122492000.0, 0.0008], [122494000.0, 0.0467], [122495000.0, 0.0001]]},
{"timestamp": "1743771280868", "bids": [[122447000.0, 0.751], [122446000.0, 0.0016], [122444000.0, 0.0], [122434000.0, 0.0007], [122430000.0, 0.0115], [122428000.0, 0.0016], [122425000.0, 0.0041], [122424000.0, 0.0], [122415000.0, 0.0882], [122410000.0, 0.0016]], "asks": [[122453000.0, 0.0539], [122475000.0, 0.0114], [122476000.0, 0.0264], [122480000.0, 0.0008], [122482000.0, 0.0798], [122483000.0, 0.0242], [122486000.0, 0.0217], [122488000.0, 0.0183], [122492000.0, 0.0008], [122494000.0, 0.0467]]},
{"timestamp": "1743771281367", "bids": [[122447000.0, 0.751], [122446000.0, 0.0016], [122444000.0, 0.0], [122434000.0, 0.0007], [122430000.0, 0.0115], [122428000.0, 0.0016], [122425000.0, 0.0041], [122424000.0, 0.0], [122415000.0, 0.0882], [122410000.0, 0.0016]], "asks": [[122452000.0, 0.1678], [122453000.0, 0.0539], [122474000.0, 0.0798], [122475000.0, 0.0114], [122476000.0, 0.0264], [122480000.0, 0.0008], [122487000.0, 0.0227], [122492000.0, 0.0008], [122494000.0, 0.0247], [122495000.0, 0.0001]]},
{"timestamp": "1743771281868", "bids": [[122447000.0, 0.751], [122446000.0, 0.0016], [122444000.0, 0.0], [122434000.0, 0.0007], [122430000.0, 0.0115], [122428000.0, 0.0016], [122425000.0, 0.0041], [122424000.0, 0.0], [122415000.0, 0.0882], [122410000.0, 0.0016]], "asks": [[122452000.0, 0.1678], [122453000.0, 0.0539], [122480000.0, 0.0176], [122485000.0, 0.0173], [122487000.0, 0.0425], [122492000.0, 0.0008], [122495000.0, 0.0001], [122497000.0, 0.0166], [122499000.0, 0.0362], [122501000.0, 0.0199]]},
{"timestamp": "1743771282365", "bids": [[122447000.0, 0.751], [122446000.0, 0.0016], [122444000.0, 0.0], [122434000.0, 0.0007], [122430000.0, 0.0115], [122428000.0, 0.0016], [122425000.0, 0.0041], [122424000.0, 0.0], [122415000.0, 0.0882], [122410000.0, 0.0016]], "asks": [[122453000.0, 0.0539], [122480000.0, 0.0008], [122481000.0, 0.0467], [122484000.0, 0.0242], [122487000.0, 0.0425], [122492000.0, 0.0008], [122494000.0, 0.0217], [122495000.0, 0.0001], [122499000.0, 0.0362], [122500000.0, 0.0126]]},
{"timestamp": "1743771282867", "bids": [[122447000.0, 0.751], [122446000.0, 0.0016], [122444000.0, 0.0], [122434000.0, 0.0007], [122430000.0, 0.0115], [122428000.0, 0.0016], [122425000.0, 0.0041], [122424000.0, 0.0], [122415000.0, 0.0882], [122410000.0, 0.0016]], "asks": [[122453000.0, 0.0539], [122480000.0, 0.0008], [122484000.0, 0.0798], [122485000.0, 0.0282], [122486000.0, 0.0798], [122487000.0, 0.0418], [122489000.0, 0.0264], [122492000.0, 0.0008], [122494000.0, 0.0217], [122495000.0, 0.0001]]},
{"timestamp": "1743771283366", "bids": [[122447000.0, 0.751], [122446000.0, 0.0016], [122444000.0, 0.0], [122434000.0, 0.0007], [122430000.0, 0.0115], [122428000.0, 0.0016], [122425000.0, 0.0041], [122424000.0, 0.0], [122415000.0, 0.0882], [122410000.0, 0.0016]], "asks": [[122453000.0, 0.0539], [122480000.0, 0.0008], [122485000.0, 0.0282], [122486000.0, 0.0798], [122487000.0, 0.0665], [122489000.0, 0.0264], [122492000.0, 0.0008], [122494000.0, 0.0217], [122495000.0, 0.0001], [122498000.0, 0.0183]]},
{"timestamp": "1743771283865", "bids": [[122447000.0, 0.751], [122446000.0, 0.0016], [122444000.0, 0.0], [122434000.0, 0.0007], [122430000.0, 0.0115], [122428000.0, 0.0016], [122425000.0, 0.0041], [122424000.0, 0.0], [122415000.0, 0.0882], [122410000.0, 0.0016]], "asks": [[122452000.0, 0.1335], [122453000.0, 0.0539], [122480000.0, 0.0008], [122484000.0, 0.0798], [122485000.0, 0.0282], [122487000.0, 0.0665], [122489000.0, 0.0264], [122492000.0, 0.0008], [122494000.0, 0.0217], [122495000.0, 0.0001]]},
{"timestamp": "1743771284364", "bids": [[122447000.0, 0.751], [122446000.0, 0.0388], [122444000.0, 0.0], [122434000.0, 0.0007], [122430000.0, 0.0115], [122428000.0, 0.0016], [122425000.0, 0.0041], [122424000.0, 0.0], [122415000.0, 0.0882], [122410000.0, 0.0016]], "asks": [[122453000.0, 0.0539], [122480000.0, 0.0008], [122485000.0, 0.0282], [122487000.0, 0.0665], [122489000.0, 0.0264], [122492000.0, 0.0008], [122494000.0, 0.0217], [122495000.0, 0.0001], [122498000.0, 0.0183], [122499000.0, 0.0362]]},
{"timestamp": "1743771284869", "bids": [[122447000.0, 0.751], [122446000.0, 0.0388], [122444000.0, 0.0], [122434000.0, 0.0007], [122430000.0, 0.0115], [122428000.0, 0.0016], [122425000.0, 0.0041], [122424000.0, 0.0], [122415000.0, 0.0882], [122410000.0, 0.0016]], "asks": [[122453000.0, 0.0539], [122480000.0, 0.0008], [122484000.0, 0.0798], [122485000.0, 0.0282], [122487000.0, 0.0665], [122489000.0, 0.0264], [122492000.0, 0.0008], [122494000.0, 0.0217], [122495000.0, 0.0001], [122498000.0, 0.0183]]},
{"timestamp": "1743771285361", "bids": [[122447000.0, 0.751], [122446000.0, 0.0388], [122444000.0, 0.0], [122434000.0, 0.0007], [122430000.0, 0.0115], [122428000.0, 0.0016], [122425000.0, 0.0041], [122424000.0, 0.0], [122415000.0, 0.0882], [122410000.0, 0.0016]], "asks": [[122452000.0, 0.1055], [122453000.0, 0.0539], [122478000.0, 0.04], [122480000.0, 0.0008], [122484000.0, 0.0798], [122487000.0, 0.022], [122492000.0, 0.0008], [122495000.0, 0.0001], [122499000.0, 0.0362], [122501000.0, 0.0166]]},
{"timestamp": "1743771285862", "bids": [[122447000.0, 0.731], [122446000.0, 0.0388], [122444000.0, 0.0], [122434000.0, 0.0007], [122430000.0, 0.0115], [122428000.0, 0.0016], [122425000.0, 0.0041], [122424000.0, 0.0], [122415000.0, 0.0882], [122410000.0, 0.0016]], "asks": [[122452000.0, 0.1684], [122453000.0, 0.0539], [122468000.0, 0.0168], [122469000.0, 0.0247], [122478000.0, 0.04], [122480000.0, 0.0008], [122484000.0, 0.0798], [122485000.0, 0.0129], [122486000.0, 0.0242], [122489000.0, 0.0199]]},
{"timestamp": "1743771286361", "bids": [[122447000.0, 0.731], [122446000.0, 0.0388], [122444000.0, 0.0], [122434000.0, 0.0007], [122430000.0, 0.0115], [122428000.0, 0.0016], [122425000.0, 0.0041], [122424000.0, 0.0], [122415000.0, 0.0882], [122410000.0, 0.0016]], "asks": [[122452000.0, 0.0491], [122453000.0, 0.0539], [122468000.0, 0.0168], [122469000.0, 0.0445], [122470000.0, 0.0114], [122478000.0, 0.0173], [122480000.0, 0.0008], [122484000.0, 0.0183], [122485000.0, 0.0129], [122486000.0, 0.104]]},
{"timestamp": "1743771286868", "bids": [[122447000.0, 0.7312], [122446000.0, 0.0388], [122444000.0, 0.0], [122434000.0, 0.0007], [122430000.0, 0.0115], [122428000.0, 0.0016], [122425000.0, 0.0041], [122424000.0, 0.0], [122415000.0, 0.0882], [122410000.0, 0.0016]], "asks": [[122453000.0, 0.0539], [122467000.0, 0.022], [122468000.0, 0.0168], [122469000.0, 0.0462], [122470000.0, 0.0114], [122478000.0, 0.0173], [122479000.0, 0.0217], [122480000.0, 0.0008], [122484000.0, 0.0327], [122485000.0, 0.0362]]},
{"timestamp": "1743771287364", "bids": [[122447000.0, 0.7312], [122446000.0, 0.0388], [122444000.0, 0.0], [122434000.0, 0.0007], [122430000.0, 0.0115], [122428000.0, 0.0016], [122425000.0, 0.0041], [122424000.0, 0.0], [122415000.0, 0.0882], [122410000.0, 0.0016]], "asks": [[122453000.0, 0.0539], [122466000.0, 0.0247], [122467000.0, 0.022], [122468000.0, 0.0168], [122469000.0, 0.0462], [122470000.0, 0.0114], [122478000.0, 0.0173], [122479000.0, 0.0217], [122480000.0, 0.0008], [122483000.0, 0.0129]]},
{"timestamp": "1743771287869", "bids": [[122447000.0, 0.7312], [122446000.0, 0.0388], [122444000.0, 0.0], [122434000.0, 0.0007], [122430000.0, 0.0115], [122428000.0, 0.0016], [122425000.0, 0.0041], [122424000.0, 0.0], [122415000.0, 0.0882], [122410000.0, 0.0016]], "asks": [[122453000.0, 0.0539], [122466000.0, 0.0247], [122467000.0, 0.022], [122468000.0, 0.0168], [122469000.0, 0.0462], [122470000.0, 0.0114], [122478000.0, 0.0173], [122479000.0, 0.0217], [122480000.0, 0.0008], [122483000.0, 0.0129]]},
{"timestamp": "1743771288370", "bids": [[122447000.0, 0.7312], [122446000.0, 0.0388], [122444000.0, 0.0], [122434000.0, 0.0007], [122430000.0, 0.0115], [122428000.0, 0.0016], [122425000.0, 0.0041], [122424000.0, 0.0], [122415000.0, 0.0882], [122410000.0, 0.0016]], "asks": [[122453000.0, 0.0539], [122466000.0, 0.0247], [122467000.0, 0.022], [122468000.0, 0.0168], [122469000.0, 0.0462], [122470000.0, 0.0114], [122478000.0, 0.0173], [122479000.0, 0.0217], [122480000.0, 0.0008], [122483000.0, 0.0129]]},
{"timestamp": "1743771288867", "bids": [[122447000.0, 0.7312], [122446000.0, 0.0388], [122444000.0, 0.0], [122434000.0, 0.0007], [122430000.0, 0.0115], [122428000.0, 0.0016], [122425000.0, 0.0041], [122424000.0, 0.0], [122415000.0, 0.0882], [122410000.0, 0.0016]], "asks": [[122453000.0, 0.0539], [122466000.0, 0.0247], [122467000.0, 0.022], [122468000.0, 0.0168], [122469000.0, 0.0462], [122470000.0, 0.0114], [122478000.0, 0.0173], [122479000.0, 0.0217], [122480000.0, 0.0008], [122483000.0, 0.0129]]},
{"timestamp": "1743771289360", "bids": [[122447000.0, 0.7312], [122446000.0, 0.0388], [122444000.0, 0.0], [122434000.0, 0.0007], [122430000.0, 0.0115], [122428000.0, 0.0016], [122425000.0, 0.0041], [122424000.0, 0.0], [122415000.0, 0.0882], [122410000.0, 0.0016]], "asks": [[122453000.0, 0.0539], [122466000.0, 0.0247], [122467000.0, 0.022], [122468000.0, 0.0168], [122469000.0, 0.0462], [122470000.0, 0.0114], [122478000.0, 0.0173], [122479000.0, 0.0217], [122480000.0, 0.0008], [122483000.0, 0.0129]]},
{"timestamp": "1743771289866", "bids": [[122447000.0, 0.7312], [122446000.0, 0.0388], [122444000.0, 0.0], [122434000.0, 0.0007], [122430000.0, 0.0115], [122428000.0, 0.0016], [122425000.0, 0.0041], [122424000.0, 0.0], [122415000.0, 0.0882], [122410000.0, 0.0016]], "asks": [[122453000.0, 0.0539], [122466000.0, 0.0247], [122467000.0, 0.022], [122468000.0, 0.0168], [122469000.0, 0.0462], [122470000.0, 0.0114], [122478000.0, 0.0173], [122479000.0, 0.0217], [122480000.0, 0.0008], [122483000.0, 0.0129]]},
{"timestamp": "1743771290368", "bids": [[122447000.0, 0.7312], [122446000.0, 0.0388], [122444000.0, 0.0], [122434000.0, 0.0007], [122430000.0, 0.0115], [122428000.0, 0.0016], [122425000.0, 0.0041], [122424000.0, 0.0], [122415000.0, 0.0882], [122410000.0, 0.0016]], "asks": [[122453000.0, 0.0539], [122466000.0, 0.0247], [122467000.0, 0.022], [122468000.0, 0.0168], [122469000.0, 0.0462], [122470000.0, 0.0114], [122478000.0, 0.0173], [122479000.0, 0.0217], [122480000.0, 0.0008], [122483000.0, 0.0129]]},
{"timestamp": "1743771290868", "bids": [[122448000.0, 0.0001], [122447000.0, 0.7312], [122446000.0, 0.0388], [122444000.0, 0.0], [122434000.0, 0.0007], [122430000.0, 0.0115], [122428000.0, 0.0016], [122425000.0, 0.0041], [122424000.0, 0.0], [122415000.0, 0.0882]], "asks": [[122453000.0, 0.0539], [122466000.0, 0.0247], [122468000.0, 0.0168], [122469000.0, 0.0462], [122470000.0, 0.0114], [122479000.0, 0.0217], [122480000.0, 0.0008], [122483000.0, 0.0129], [122484000.0, 0.0327], [122485000.0, 0.0126]]},
{"timestamp": "1743771291372", "bids": [[122448000.0, 0.0193], [122447000.0, 0.7312], [122446000.0, 0.0388], [122444000.0, 0.0], [122434000.0, 0.0007], [122430000.0, 0.0115], [122428000.0, 0.0016], [122425000.0, 0.0041], [122424000.0, 0.0], [122415000.0, 0.0882]], "asks": [[122453000.0, 0.0539], [122474000.0, 0.0227], [122480000.0, 0.0008], [122483000.0, 0.0129], [122484000.0, 0.0183], [122488000.0, 0.0362], [122490000.0, 0.0347], [122492000.0, 0.0008], [122495000.0, 0.0178], [122498000.0, 0.0176]]},
{"timestamp": "1743771291867", "bids": [[122452000.0, 0.0], [122447000.0, 0.7312], [122446000.0, 0.0388], [122444000.0, 0.0], [122434000.0, 0.0007], [122430000.0, 0.0115], [122428000.0, 0.0016], [122425000.0, 0.0041], [122424000.0, 0.0], [122415000.0, 0.0882]], "asks": [[122453000.0, 0.0539], [122474000.0, 0.04], [122475000.0, 0.0168], [122476000.0, 0.0467], [122478000.0, 0.0242], [122480000.0, 0.0008], [122487000.0, 0.0799], [122490000.0, 0.0166], [122492000.0, 0.0008], [122495000.0, 0.0304]]},
{"timestamp": "1743771292364", "bids": [[122447000.0, 0.7312], [122446000.0, 0.0388], [122444000.0, 0.0], [122434000.0, 0.0007], [122430000.0, 0.0115], [122428000.0, 0.0016], [122425000.0, 0.0041], [122424000.0, 0.0], [122415000.0, 0.0882], [122410000.0, 0.0016]], "asks": [[122453000.0, 0.0568], [122476000.0, 0.0198], [122477000.0, 0.0114], [122478000.0, 0.0264], [122480000.0, 0.0008], [122487000.0, 0.0799], [122488000.0, 0.0217], [122489000.0, 0.0799], [122492000.0, 0.0008], [122494000.0, 0.0144]]},
{"timestamp": "1743771292870", "bids": [[122447000.0, 0.7311], [122446000.0, 0.0388], [122444000.0, 0.0], [122434000.0, 0.0007], [122430000.0, 0.0115], [122428000.0, 0.0016], [122425000.0, 0.0041], [122424000.0, 0.0], [122415000.0, 0.0882], [122410000.0, 0.0016]], "asks": [[122453000.0, 0.0467], [122476000.0, 0.0198], [122477000.0, 0.0114], [122478000.0, 0.0264], [122479000.0, 0.0467], [122480000.0, 0.0008], [122488000.0, 0.0217], [122492000.0, 0.0008], [122493000.0, 0.0183], [122495000.0, 0.013]]},
{"timestamp": "1743771293367", "bids": [[122447000.0, 0.7311], [122446000.0, 0.0388], [122444000.0, 0.0], [122434000.0, 0.0007], [122433000.0, 0.004], [122430000.0, 0.0115], [122428000.0, 0.0016], [122425000.0, 0.0041], [122424000.0, 0.0], [122415000.0, 0.0882]], "asks": [[122452000.0, 0.0107], [122453000.0, 0.0467], [122476000.0, 0.0198], [122477000.0, 0.0919], [122478000.0, 0.0264], [122479000.0, 0.0467], [122480000.0, 0.0008], [122488000.0, 0.0217], [122492000.0, 0.037], [122495000.0, 0.013]]},
{"timestamp": "1743771293872", "bids": [[122447000.0, 0.7311], [122446000.0, 0.0388], [122444000.0, 0.0], [122434000.0, 0.0007], [122433000.0, 0.004], [122430000.0, 0.0115], [122428000.0, 0.0016], [122425000.0, 0.0041], [122424000.0, 0.0], [122415000.0, 0.0882]], "asks": [[122452000.0, 0.0109], [122453000.0, 0.0467], [122467000.0, 0.0173], [122468000.0, 0.041], [122469000.0, 0.0227], [122475000.0, 0.0805], [122477000.0, 0.0805], [122480000.0, 0.0008], [122481000.0, 0.0144], [122482000.0, 0.0166]]},
{"timestamp": "1743771294369", "bids": [[122447000.0, 0.7311], [122446000.0, 0.038], [122444000.0, 0.0], [122434000.0, 0.0007], [122433000.0, 0.004], [122430000.0, 0.0115], [122428000.0, 0.0016], [122425000.0, 0.0041], [122424000.0, 0.0], [122415000.0, 0.0882]], "asks": [[122453000.0, 0.0467], [122467000.0, 0.0173], [122468000.0, 0.041], [122469000.0, 0.0227], [122473000.0, 0.0183], [122475000.0, 0.0805], [122477000.0, 0.0805], [122478000.0, 0.0126], [122479000.0, 0.0181], [122480000.0, 0.0008]]},
{"timestamp": "1743771294865", "bids": [[122447000.0, 0.7311], [122446000.0, 0.038], [122444000.0, 0.0], [122434000.0, 0.0007], [122433000.0, 0.004], [122430000.0, 0.0115], [122428000.0, 0.0016], [122425000.0, 0.0041], [122424000.0, 0.0], [122415000.0, 0.0882]], "asks": [[122453000.0, 0.0467], [122459000.0, 0.0665], [122460000.0, 0.0114], [122461000.0, 0.0264], [122467000.0, 0.0173], [122468000.0, 0.041], [122469000.0, 0.0227], [122471000.0, 0.0217], [122473000.0, 0.0183], [122475000.0, 0.0129]]},
{"timestamp": "1743771295373", "bids": [[122447000.0, 0.7311], [122446000.0, 0.038], [122444000.0, 0.0], [122434000.0, 0.0007], [122433000.0, 0.004], [122430000.0, 0.0115], [122428000.0, 0.0016], [122425000.0, 0.0041], [122424000.0, 0.0], [122415000.0, 0.0882]], "asks": [[122453000.0, 0.0467], [122459000.0, 0.0665], [122460000.0, 0.0114], [122461000.0, 0.0264], [122467000.0, 0.0173], [122468000.0, 0.041], [122469000.0, 0.0227], [122471000.0, 0.0217], [122473000.0, 0.0183], [122475000.0, 0.0129]]},
{"timestamp": "1743771295868", "bids": [[122447000.0, 0.7311], [122446000.0, 0.038], [122444000.0, 0.0], [122434000.0, 0.0007], [122433000.0, 0.004], [122430000.0, 0.0115], [122428000.0, 0.0016], [122425000.0, 0.0041], [122424000.0, 0.0], [122419000.0, 0.0002]], "asks": [[122453000.0, 0.0467], [122459000.0, 0.0665], [122460000.0, 0.0114], [122461000.0, 0.0264], [122467000.0, 0.0173], [122468000.0, 0.041], [122469000.0, 0.0227], [122471000.0, 0.0217], [122473000.0, 0.0183], [122475000.0, 0.0129]]},
{"timestamp": "1743771296364", "bids": [[122447000.0, 0.7304], [122446000.0, 0.038], [122444000.0, 0.0], [122434000.0, 0.0007], [122433000.0, 0.004], [122430000.0, 0.0115], [122428000.0, 0.0016], [122425000.0, 0.0041], [122424000.0, 0.0], [122419000.0, 0.0002]], "asks": [[122453000.0, 0.0467], [122459000.0, 0.0665], [122460000.0, 0.0114], [122461000.0, 0.0264], [122467000.0, 0.0173], [122468000.0, 0.041], [122469000.0, 0.0227], [122471000.0, 0.0217], [122473000.0, 0.0183], [122475000.0, 0.0129]]},
{"timestamp": "1743771296873", "bids": [[122447000.0, 0.7304], [122446000.0, 0.038], [122444000.0, 0.0], [122434000.0, 0.0007], [122433000.0, 0.004], [122430000.0, 0.0115], [122428000.0, 0.0016], [122425000.0, 0.0041], [122424000.0, 0.0], [122419000.0, 0.0002]], "asks": [[122453000.0, 0.0467], [122459000.0, 0.0665], [122460000.0, 0.0114], [122461000.0, 0.0264], [122467000.0, 0.0173], [122468000.0, 0.041], [122469000.0, 0.0227], [122471000.0, 0.0217], [122473000.0, 0.0183], [122475000.0, 0.0129]]},
{"timestamp": "1743771297366", "bids": [[122447000.0, 0.7304], [122446000.0, 0.038], [122444000.0, 0.0], [122434000.0, 0.0007], [122433000.0, 0.004], [122430000.0, 0.0115], [122428000.0, 0.0016], [122425000.0, 0.0041], [122424000.0, 0.0], [122419000.0, 0.0002]], "asks": [[122453000.0, 0.0467], [122459000.0, 0.0665], [122460000.0, 0.0114], [122461000.0, 0.0264], [122467000.0, 0.0173], [122468000.0, 0.041], [122469000.0, 0.0227], [122471000.0, 0.0217], [122473000.0, 0.0183], [122475000.0, 0.0129]]},
{"timestamp": "1743771297868", "bids": [[122447000.0, 0.7304], [122446000.0, 0.038], [122444000.0, 0.0], [122434000.0, 0.0007], [122433000.0, 0.004], [122430000.0, 0.0115], [122428000.0, 0.0016], [122425000.0, 0.0041], [122424000.0, 0.0], [122419000.0, 0.0002]], "asks": [[122453000.0, 0.0467], [122459000.0, 0.0665], [122460000.0, 0.0114], [122461000.0, 0.0264], [122467000.0, 0.0173], [122468000.0, 0.041], [122469000.0, 0.0227], [122471000.0, 0.0217], [122473000.0, 0.0183], [122475000.0, 0.0129]]},
{"timestamp": "1743771298368", "bids": [[122447000.0, 0.7304], [122446000.0, 0.038], [122444000.0, 0.0], [122434000.0, 0.0007], [122433000.0, 0.004], [122430000.0, 0.0115], [122428000.0, 0.0016], [122425000.0, 0.0041], [122424000.0, 0.0], [122419000.0, 0.0002]], "asks": [[122453000.0, 0.0467], [122459000.0, 0.0665], [122460000.0, 0.0114], [122461000.0, 0.0264], [122467000.0, 0.0173], [122468000.0, 0.041], [122469000.0, 0.0227], [122471000.0, 0.0217], [122473000.0, 0.0183], [122475000.0, 0.0129]]},
{"timestamp": "1743771298868", "bids": [[122447000.0, 0.7304], [122446000.0, 0.038], [122444000.0, 0.0], [122434000.0, 0.0007], [122433000.0, 0.004], [122430000.0, 0.0115], [122428000.0, 0.0016], [122425000.0, 0.0041], [122424000.0, 0.0], [122419000.0, 0.0002]], "asks": [[122453000.0, 0.0463], [122459000.0, 0.0665], [122460000.0, 0.0114], [122461000.0, 0.0264], [122467000.0, 0.0173], [122468000.0, 0.041], [122469000.0, 0.0227], [122471000.0, 0.0217], [122473000.0, 0.0183], [122475000.0, 0.0129]]},
{"timestamp": "1743771299370", "bids": [[122447000.0, 0.7304], [122446000.0, 0.038], [122444000.0, 0.0], [122434000.0, 0.0007], [122433000.0, 0.004], [122430000.0, 0.0115], [122428000.0, 0.0016], [122425000.0, 0.0041], [122424000.0, 0.0], [122419000.0, 0.0002]], "asks": [[122453000.0, 0.0463], [122459000.0, 0.0665], [122460000.0, 0.0114], [122461000.0, 0.0264], [122467000.0, 0.0173], [122468000.0, 0.041], [122469000.0, 0.0227], [122471000.0, 0.0217], [122472000.0, 0.0362], [122473000.0, 0.0183]]},
{"timestamp": "1743771299874", "bids": [[122447000.0, 0.7304], [122446000.0, 0.038], [122444000.0, 0.0], [122434000.0, 0.0007], [122433000.0, 0.004], [122430000.0, 0.0115], [122428000.0, 0.0016], [122425000.0, 0.0041], [122424000.0, 0.0], [122419000.0, 0.0002]], "asks": [[122453000.0, 0.0463], [122459000.0, 0.0445], [122460000.0, 0.0114], [122461000.0, 0.0264], [122468000.0, 0.0242], [122471000.0, 0.0217], [122472000.0, 0.0362], [122473000.0, 0.0183], [122475000.0, 0.0129], [122476000.0, 0.0144]]},
{"timestamp": "1743771300365", "bids": [[122447000.0, 0.7136], [122446000.0, 0.038], [122444000.0, 0.0], [122434000.0, 0.0007], [122433000.0, 0.004], [122430000.0, 0.0115], [122428000.0, 0.0016], [122425000.0, 0.0041], [122424000.0, 0.0], [122419000.0, 0.0002]], "asks": [[122448000.0, 0.0227], [122452000.0, 0.0022], [122453000.0, 0.0463], [122469000.0, 0.0358], [122470000.0, 0.0174], [122476000.0, 0.0167], [122479000.0, 0.033], [122480000.0, 0.0008], [122481000.0, 0.0255], [122491000.0, 0.0225]]},
{"timestamp": "1743771300871", "bids": [[122447000.0, 0.6963], [122446000.0, 0.038], [122444000.0, 0.0], [122434000.0, 0.0007], [122433000.0, 0.004], [122430000.0, 0.0115], [122428000.0, 0.0016], [122425000.0, 0.0041], [122424000.0, 0.0], [122419000.0, 0.0002]], "asks": [[122448000.0, 0.0694], [122451000.0, 0.0242], [122452000.0, 0.0015], [122453000.0, 0.0463], [122460000.0, 0.0217], [122463000.0, 0.0183], [122464000.0, 0.0166], [122467000.0, 0.0126], [122468000.0, 0.0199], [122469000.0, 0.058]]},
{"timestamp": "1743771301366", "bids": [[122447000.0, 0.6963], [122446000.0, 0.038], [122444000.0, 0.0], [122434000.0, 0.0007], [122433000.0, 0.004], [122430000.0, 0.0115], [122428000.0, 0.0016], [122425000.0, 0.0041], [122424000.0, 0.0], [122419000.0, 0.0002]], "asks": [[122449000.0, 0.0114], [122453000.0, 0.0463], [122460000.0, 0.0217], [122463000.0, 0.1351], [122464000.0, 0.0129], [122466000.0, 0.0144], [122468000.0, 0.0199], [122469000.0, 0.0181], [122470000.0, 0.0324], [122471000.0, 0.1155]]},
{"timestamp": "1743771301886", "bids": [[122447000.0, 0.6765], [122446000.0, 0.038], [122444000.0, 0.0], [122434000.0, 0.0007], [122433000.0, 0.004], [122430000.0, 0.0115], [122428000.0, 0.0016], [122425000.0, 0.0041], [122424000.0, 0.0], [122419000.0, 0.0002]], "asks": [[122448000.0, 0.0116], [122449000.0, 0.0114], [122451000.0, 0.0264], [122453000.0, 0.0463], [122463000.0, 0.1168], [122464000.0, 0.0129], [122466000.0, 0.0144], [122470000.0, 0.0153], [122471000.0, 0.035], [122479000.0, 0.016]]},
{"timestamp": "1743771302375", "bids": [[122447000.0, 0.6303], [122446000.0, 0.038], [122444000.0, 0.0], [122434000.0, 0.0007], [122433000.0, 0.004], [122430000.0, 0.0115], [122428000.0, 0.0016], [122425000.0, 0.0041], [122424000.0, 0.0], [122419000.0, 0.0002]], "asks": [[122448000.0, 0.0116], [122449000.0, 0.0114], [122451000.0, 0.0264], [122453000.0, 0.0629], [122454000.0, 0.0126], [122456000.0, 0.0174], [122458000.0, 0.0399], [122462000.0, 0.0578], [122463000.0, 0.1168], [122464000.0, 0.0129]]},
{"timestamp": "1743771302872", "bids": [[122447000.0, 0.5613], [122446000.0, 0.038], [122444000.0, 0.0], [122434000.0, 0.0007], [122433000.0, 0.004], [122430000.0, 0.0115], [122428000.0, 0.0016], [122425000.0, 0.0041], [122424000.0, 0.0], [122419000.0, 0.0002]], "asks": [[122451000.0, 0.0144], [122453000.0, 0.0828], [122456000.0, 0.0341], [122458000.0, 0.067], [122459000.0, 0.0385], [122461000.0, 0.0322], [122462000.0, 0.1639], [122464000.0, 0.0166], [122465000.0, 0.0827], [122466000.0, 0.0406]]},
{"timestamp": "1743771303365", "bids": [[122447000.0, 0.5192], [122446000.0, 0.038], [122444000.0, 0.0], [122434000.0, 0.0007], [122433000.0, 0.004], [122430000.0, 0.0115], [122428000.0, 0.0016], [122425000.0, 0.0041], [122424000.0, 0.0], [122419000.0, 0.0002]], "asks": [[122450000.0, 0.0129], [122451000.0, 0.0144], [122453000.0, 0.0629], [122456000.0, 0.0167], [122457000.0, 0.0362], [122458000.0, 0.0448], [122459000.0, 0.0209], [122464000.0, 0.0166], [122465000.0, 0.0827], [122466000.0, 0.0406]]},
{"timestamp": "1743771303866", "bids": [[122447000.0, 0.4704], [122446000.0, 0.038], [122444000.0, 0.0], [122434000.0, 0.0007], [122433000.0, 0.004], [122430000.0, 0.0115], [122428000.0, 0.0016], [122425000.0, 0.0041], [122424000.0, 0.0], [122419000.0, 0.0002]], "asks": [[122449000.0, 0.0251], [122450000.0, 0.0996], [122451000.0, 0.0144], [122453000.0, 0.0629], [122457000.0, 0.0362], [122458000.0, 0.0177], [122462000.0, 0.0233], [122464000.0, 0.0166], [122469000.0, 0.0185], [122480000.0, 0.0008]]},
{"timestamp": "1743771304365", "bids": [[122425000.0, 0.0041], [122424000.0, 0.0], [122419000.0, 0.0002], [122415000.0, 0.0882], [122410000.0, 0.0016], [122409000.0, 0.0021], [122408000.0, 0.0], [122407000.0, 0.0], [122406000.0, 0.0003], [122404000.0, 0.0]], "asks": [[122428000.0, 0.0026], [122432000.0, 0.033], [122434000.0, 0.0342], [122437000.0, 0.2934], [122439000.0, 0.0253], [122441000.0, 0.0327], [122443000.0, 0.0183], [122449000.0, 0.0251], [122450000.0, 0.1191], [122451000.0, 0.035]]},
{"timestamp": "1743771304869", "bids": [[122419000.0, 0.0002], [122415000.0, 0.0882], [122410000.0, 0.0016], [122409000.0, 0.0021], [122408000.0, 0.0], [122407000.0, 0.0], [122406000.0, 0.0003], [122404000.0, 0.0], [122400000.0, 0.0189], [122396000.0, 0.0002]], "asks": [[122423000.0, 0.0282], [122428000.0, 0.0231], [122429000.0, 0.0167], [122431000.0, 0.0264], [122432000.0, 0.0849], [122434000.0, 0.0551], [122436000.0, 0.0322], [122437000.0, 0.0255], [122438000.0, 0.05], [122439000.0, 0.042]]},
{"timestamp": "1743771305369", "bids": [[122419000.0, 0.0002], [122415000.0, 0.0882], [122410000.0, 0.0016], [122409000.0, 0.0021], [122408000.0, 0.0], [122407000.0, 0.0], [122406000.0, 0.0003], [122404000.0, 0.0], [122400000.0, 0.0189], [122396000.0, 0.0002]], "asks": [[122422000.0, 0.0964], [122423000.0, 0.0282], [122424000.0, 0.0144], [122427000.0, 0.1505], [122428000.0, 0.0231], [122429000.0, 0.0167], [122431000.0, 0.1603], [122432000.0, 0.0578], [122434000.0, 0.0385], [122436000.0, 0.0488]]},
{"timestamp": "1743771305873", "bids": [[122400000.0, 0.0002], [122396000.0, 0.0002], [122394000.0, 0.0], [122392000.0, 0.0008], [122391000.0, 0.0008], [122390000.0, 0.0], [122388000.0, 0.0001], [122387000.0, 0.0016], [122385000.0, 0.0032], [122384000.0, 0.0013]], "asks": [[122410000.0, 0.2612], [122421000.0, 0.0015], [122422000.0, 0.0129], [122423000.0, 0.1619], [122424000.0, 0.0144], [122427000.0, 0.0166], [122428000.0, 0.0231], [122429000.0, 0.0167], [122430000.0, 0.0271], [122431000.0, 0.0264]]},
{"timestamp": "1743771306367", "bids": [[122400000.0, 0.0002], [122396000.0, 0.0002], [122394000.0, 0.0], [122392000.0, 0.0008], [122391000.0, 0.0008], [122390000.0, 0.0], [122388000.0, 0.0001], [122387000.0, 0.0016], [122385000.0, 0.0032], [122384000.0, 0.0013]], "asks": [[122409000.0, 0.14], [122410000.0, 0.005], [122421000.0, 0.0008], [122422000.0, 0.0129], [122423000.0, 0.1619], [122424000.0, 0.0144], [122427000.0, 0.0166], [122428000.0, 0.0231], [122429000.0, 0.0167], [122431000.0, 0.0264]]},
{"timestamp": "1743771306875", "bids": [[122400000.0, 0.0002], [122396000.0, 0.0002], [122394000.0, 0.0], [122392000.0, 0.0008], [122391000.0, 0.0008], [122390000.0, 0.0], [122388000.0, 0.0001], [122387000.0, 0.0016], [122385000.0, 0.0032], [122384000.0, 0.0013]], "asks": [[122408000.0, 0.0526], [122409000.0, 0.14], [122410000.0, 0.005], [122420000.0, 0.0166], [122421000.0, 0.0526], [122423000.0, 0.1619], [122424000.0, 0.0177], [122428000.0, 0.0009], [122429000.0, 0.0167], [122431000.0, 0.0264]]},
{"timestamp": "1743771307371", "bids": [[122396000.0, 0.0002], [122394000.0, 0.0], [122392000.0, 0.0008], [122391000.0, 0.0008], [122390000.0, 0.0], [122388000.0, 0.0001], [122387000.0, 0.0016], [122385000.0, 0.0032], [122384000.0, 0.0013], [122382000.0, 0.0002]], "asks": [[122409000.0, 0.135], [122420000.0, 0.0166], [122421000.0, 0.0526], [122423000.0, 0.0282], [122424000.0, 0.0177], [122425000.0, 0.0166], [122428000.0, 0.0271], [122434000.0, 0.0493], [122435000.0, 0.0239], [122436000.0, 0.0185]]},
{"timestamp": "1743771307867", "bids": [[122396000.0, 0.0002], [122394000.0, 0.0], [122392000.0, 0.0008], [122391000.0, 0.0008], [122390000.0, 0.0], [122388000.0, 0.0001], [122387000.0, 0.0016], [122385000.0, 0.0032], [122384000.0, 0.0013], [122382000.0, 0.0002]], "asks": [[122419000.0, 0.0526], [122420000.0, 0.0295], [122421000.0, 0.0144], [122423000.0, 0.0282], [122424000.0, 0.0177], [122425000.0, 0.0166], [122428000.0, 0.0271], [122434000.0, 0.0493], [122435000.0, 0.0239], [122436000.0, 0.0185]]},
{"timestamp": "1743771308443", "bids": [[122396000.0, 0.0002], [122394000.0, 0.0], [122392000.0, 0.0016], [122391000.0, 0.0008], [122390000.0, 0.0004], [122388000.0, 0.0001], [122387000.0, 0.0016], [122385000.0, 0.0032], [122384000.0, 0.0013], [122382000.0, 0.0002]], "asks": [[122420000.0, 0.0295], [122421000.0, 0.0144], [122422000.0, 0.0526], [122423000.0, 0.0282], [122424000.0, 0.0177], [122425000.0, 0.0166], [122428000.0, 0.0271], [122433000.0, 0.1351], [122434000.0, 0.0493], [122435000.0, 0.0239]]},
{"timestamp": "1743771308871", "bids": [[122396000.0, 0.0002], [122394000.0, 0.0], [122392000.0, 0.0016], [122391000.0, 0.0008], [122390000.0, 0.0004], [122388000.0, 0.0001], [122387000.0, 0.0016], [122385000.0, 0.0032], [122384000.0, 0.0013], [122382000.0, 0.0002]], "asks": [[122420000.0, 0.0295], [122421000.0, 0.0144], [122423000.0, 0.0282], [122424000.0, 0.0177], [122425000.0, 0.0166], [122428000.0, 0.0271], [122433000.0, 0.1351], [122434000.0, 0.0493], [122435000.0, 0.0239], [122436000.0, 0.0185]]},
{"timestamp": "1743771309370", "bids": [[122396000.0, 0.0002], [122394000.0, 0.0], [122392000.0, 0.0016], [122391000.0, 0.0008], [122390000.0, 0.0004], [122388000.0, 0.0001], [122387000.0, 0.0016], [122385000.0, 0.0032], [122384000.0, 0.0013], [122382000.0, 0.0002]], "asks": [[122419000.0, 0.0526], [122420000.0, 0.0295], [122421000.0, 0.0144], [122423000.0, 0.0282], [122424000.0, 0.0177], [122425000.0, 0.0166], [122428000.0, 0.0271], [122433000.0, 0.1351], [122434000.0, 0.0493], [122435000.0, 0.0239]]},
{"timestamp": "1743771309867", "bids": [[122396000.0, 0.0002], [122394000.0, 0.0], [122392000.0, 0.0016], [122391000.0, 0.0008], [122390000.0, 0.0004], [122388000.0, 0.0042], [122387000.0, 0.0016], [122385000.0, 0.0032], [122384000.0, 0.0013], [122382000.0, 0.0002]], "asks": [[122420000.0, 0.0295], [122421000.0, 0.0144], [122422000.0, 0.0526], [122423000.0, 0.0282], [122424000.0, 0.0177], [122425000.0, 0.0166], [122428000.0, 0.0271], [122434000.0, 0.0493], [122435000.0, 0.0239], [122436000.0, 0.0185]]},
{"timestamp": "1743771310369", "bids": [[122396000.0, 0.0002], [122394000.0, 0.0], [122392000.0, 0.0016], [122391000.0, 0.0008], [122390000.0, 0.0004], [122388000.0, 0.0042], [122387000.0, 0.0016], [122385000.0, 0.0032], [122384000.0, 0.0013], [122382000.0, 0.0002]], "asks": [[122420000.0, 0.0295], [122421000.0, 0.0144], [122422000.0, 0.0526], [122423000.0, 0.0282], [122424000.0, 0.0177], [122425000.0, 0.0166], [122428000.0, 0.0271], [122434000.0, 0.0493], [122435000.0, 0.0239], [122436000.0, 0.0185]]},
{"timestamp": "1743771310869", "bids": [[122396000.0, 0.0002], [122394000.0, 0.0], [122392000.0, 0.0016], [122391000.0, 0.0008], [122390000.0, 0.0004], [122388000.0, 0.0042], [122387000.0, 0.0016], [122385000.0, 0.0032], [122384000.0, 0.0013], [122382000.0, 0.0002]], "asks": [[122419000.0, 0.1877], [122420000.0, 0.0295], [122421000.0, 0.0144], [122423000.0, 0.0282], [122424000.0, 0.0177], [122425000.0, 0.0166], [122428000.0, 0.0271], [122434000.0, 0.0493], [122435000.0, 0.0239], [122436000.0, 0.0185]]},
{"timestamp": "1743771311375", "bids": [[122396000.0, 0.0002], [122394000.0, 0.0], [122392000.0, 0.0016], [122391000.0, 0.0008], [122390000.0, 0.0004], [122388000.0, 0.0042], [122387000.0, 0.0016], [122385000.0, 0.0032], [122384000.0, 0.0013], [122382000.0, 0.0002]], "asks": [[122418000.0, 0.1868], [122420000.0, 0.0295], [122421000.0, 0.0144], [122423000.0, 0.0282], [122424000.0, 0.0177], [122425000.0, 0.0166], [122428000.0, 0.0271], [122434000.0, 0.0493], [122435000.0, 0.0239], [122436000.0, 0.0185]]},
{"timestamp": "1743771311876", "bids": [[122396000.0, 0.0002], [122394000.0, 0.0], [122392000.0, 0.0016], [122391000.0, 0.0008], [122390000.0, 0.0004], [122388000.0, 0.0042], [122387000.0, 0.0016], [122385000.0, 0.0032], [122384000.0, 0.0013], [122382000.0, 0.0002]], "asks": [[122420000.0, 0.0295], [122421000.0, 0.0144], [122423000.0, 0.0282], [122424000.0, 0.0177], [122425000.0, 0.0166], [122428000.0, 0.0271], [122434000.0, 0.0493], [122435000.0, 0.0239], [122436000.0, 0.0185], [122438000.0, 0.0251]]},
{"timestamp": "1743771312370", "bids": [[122396000.0, 0.001], [122394000.0, 0.0], [122392000.0, 0.0016], [122391000.0, 0.0008], [122390000.0, 0.0004], [122388000.0, 0.0042], [122387000.0, 0.0016], [122385000.0, 0.0032], [122384000.0, 0.0013], [122382000.0, 0.0002]], "asks": [[122420000.0, 0.0295], [122421000.0, 0.0144], [122422000.0, 0.0517], [122423000.0, 0.0282], [122424000.0, 0.0177], [122425000.0, 0.0166], [122428000.0, 0.0271], [122433000.0, 0.1351], [122434000.0, 0.0493], [122435000.0, 0.0239]]},
{"timestamp": "1743771312872", "bids": [[122396000.0, 0.001], [122394000.0, 0.0], [122392000.0, 0.0016], [122391000.0, 0.0008], [122390000.0, 0.0004], [122388000.0, 0.0042], [122387000.0, 0.0016], [122385000.0, 0.0032], [122384000.0, 0.0013], [122382000.0, 0.0002]], "asks": [[122414000.0, 0.0222], [122419000.0, 0.0546], [122420000.0, 0.031], [122421000.0, 0.0898], [122422000.0, 0.1351], [122423000.0, 0.0537], [122428000.0, 0.0253], [122430000.0, 0.0327], [122431000.0, 0.0213], [122437000.0, 0.0186]]},
{"timestamp": "1743771313379", "bids": [[122396000.0, 0.001], [122394000.0, 0.0], [122392000.0, 0.0016], [122391000.0, 0.0008], [122390000.0, 0.0004], [122388000.0, 0.0042], [122387000.0, 0.0016], [122385000.0, 0.0032], [122384000.0, 0.0013], [122382000.0, 0.0002]], "asks": [[122411000.0, 0.0183], [122414000.0, 0.0222], [122418000.0, 0.0491], [122419000.0, 0.1897], [122420000.0, 0.0181], [122421000.0, 0.0754], [122422000.0, 0.038], [122423000.0, 0.0537], [122425000.0, 0.0322], [122427000.0, 0.073]]},
{"timestamp": "1743771313872", "bids": [[122396000.0, 0.001], [122394000.0, 0.0], [122392000.0, 0.0016], [122391000.0, 0.0008], [122390000.0, 0.0004], [122388000.0, 0.0042], [122387000.0, 0.0016], [122385000.0, 0.0032], [122384000.0, 0.0013], [122382000.0, 0.0002]], "asks": [[122398000.0, 0.0264], [122411000.0, 0.0183], [122413000.0, 0.0517], [122414000.0, 0.0222], [122418000.0, 0.0672], [122419000.0, 0.141], [122420000.0, 0.0631], [122421000.0, 0.0754], [122422000.0, 0.038], [122423000.0, 0.0255]]},
{"timestamp": "1743771314379", "bids": [[122396000.0, 0.001], [122394000.0, 0.0], [122392000.0, 0.0016], [122391000.0, 0.0008], [122390000.0, 0.0004], [122388000.0, 0.0042], [122387000.0, 0.0016], [122385000.0, 0.0032], [122384000.0, 0.0013], [122382000.0, 0.0002]], "asks": [[122397000.0, 0.0529], [122398000.0, 0.0264], [122411000.0, 0.0183], [122412000.0, 0.0129], [122413000.0, 0.1351], [122414000.0, 0.0366], [122418000.0, 0.0657], [122419000.0, 0.136], [122420000.0, 0.0631], [122421000.0, 0.0754]]},
{"timestamp": "1743771314874", "bids": [[122382000.0, 0.0002], [122380000.0, 0.0002], [122378000.0, 0.0103], [122377000.0, 0.0068], [122375000.0, 0.0168], [122372000.0, 0.0008], [122371000.0, 0.0123], [122370000.0, 0.0], [122367000.0, 0.0], [122366000.0, 0.0025]], "asks": [[122384000.0, 0.2463], [122397000.0, 0.0012], [122398000.0, 0.0264], [122410000.0, 0.1351], [122411000.0, 0.0183], [122412000.0, 0.0129], [122414000.0, 0.0144], [122418000.0, 0.0657], [122420000.0, 0.0179], [122421000.0, 0.0176]]},
{"timestamp": "1743771315369", "bids": [[122382000.0, 0.0002], [122380000.0, 0.0002], [122378000.0, 0.0103], [122377000.0, 0.0068], [122375000.0, 0.0168], [122372000.0, 0.0008], [122371000.0, 0.0123], [122370000.0, 0.0], [122367000.0, 0.0], [122366000.0, 0.0025]], "asks": [[122397000.0, 0.0003], [122410000.0, 0.1351], [122412000.0, 0.0129], [122413000.0, 0.0177], [122418000.0, 0.0167], [122420000.0, 0.0179], [122427000.0, 0.0166], [122428000.0, 0.0185], [122431000.0, 0.0164], [122432000.0, 0.0048]]},
{"timestamp": "1743771315873", "bids": [[122378000.0, 0.0], [122377000.0, 0.0068], [122375000.0, 0.0168], [122372000.0, 0.0008], [122371000.0, 0.0123], [122370000.0, 0.0], [122367000.0, 0.0], [122366000.0, 0.0025], [122364000.0, 0.0], [122363000.0, 0.0008]], "asks": [[122383000.0, 0.0582], [122397000.0, 0.005], [122405000.0, 0.0009], [122406000.0, 0.0222], [122408000.0, 0.0166], [122409000.0, 0.0181], [122410000.0, 0.1351], [122411000.0, 0.0251], [122413000.0, 0.1202], [122416000.0, 0.0255]]},
{"timestamp": "1743771316376", "bids": [[122377000.0, 0.0068], [122375000.0, 0.0168], [122372000.0, 0.0008], [122371000.0, 0.0123], [122370000.0, 0.0], [122367000.0, 0.0], [122366000.0, 0.0025], [122364000.0, 0.0], [122363000.0, 0.0008], [122360000.0, 0.0018]], "asks": [[122378000.0, 0.0263], [122383000.0, 0.1935], [122390000.0, 0.0129], [122391000.0, 0.0144], [122395000.0, 0.0166], [122396000.0, 0.0003], [122397000.0, 0.005], [122405000.0, 0.0009], [122406000.0, 0.0222], [122409000.0, 0.0181]]},
{"timestamp": "1743771316870", "bids": [[122377000.0, 0.0068], [122375000.0, 0.0168], [122372000.0, 0.0008], [122371000.0, 0.0123], [122370000.0, 0.0], [122367000.0, 0.0], [122366000.0, 0.0025], [122364000.0, 0.0], [122363000.0, 0.0008], [122360000.0, 0.0018]], "asks": [[122378000.0, 0.0263], [122383000.0, 0.1371], [122388000.0, 0.0183], [122390000.0, 0.0129], [122391000.0, 0.0144], [122395000.0, 0.0504], [122396000.0, 0.0212], [122400000.0, 0.0179], [122402000.0, 0.0166], [122404000.0, 0.0345]]},
{"timestamp": "1743771317374", "bids": [[122366000.0, 0.0025], [122364000.0, 0.0], [122363000.0, 0.0008], [122360000.0, 0.0018], [122358000.0, 0.0001], [122357000.0, 0.0006], [122352000.0, 0.0], [122350000.0, 0.0067], [122346000.0, 0.0053], [122345000.0, 0.0115]], "asks": [[122367000.0, 0.0189], [122371000.0, 0.2093], [122378000.0, 0.0263], [122383000.0, 0.1351], [122388000.0, 0.0183], [122390000.0, 0.0129], [122391000.0, 0.0144], [122395000.0, 0.0338], [122396000.0, 0.0209], [122400000.0, 0.0179]]},
{"timestamp": "1743771317870", "bids": [[122366000.0, 0.0025], [122364000.0, 0.0], [122363000.0, 0.0008], [122360000.0, 0.0018], [122358000.0, 0.0001], [122357000.0, 0.0006], [122352000.0, 0.0], [122350000.0, 0.0067], [122346000.0, 0.0053], [122345000.0, 0.0115]], "asks": [[122367000.0, 0.0189], [122371000.0, 0.2093], [122378000.0, 0.0708], [122383000.0, 0.0166], [122386000.0, 0.0181], [122387000.0, 0.0177], [122390000.0, 0.0377], [122391000.0, 0.0144], [122393000.0, 0.0255], [122395000.0, 0.0591]]},
{"timestamp": "1743771318378", "bids": [[122366000.0, 0.0025], [122364000.0, 0.0], [122363000.0, 0.0008], [122360000.0, 0.0018], [122358000.0, 0.0001], [122357000.0, 0.0006], [122352000.0, 0.0], [122350000.0, 0.0067], [122346000.0, 0.0053], [122345000.0, 0.0115]], "asks": [[122367000.0, 0.0636], [122371000.0, 0.2315], [122378000.0, 0.184], [122382000.0, 0.0168], [122383000.0, 0.0166], [122386000.0, 0.0181], [122387000.0, 0.0177], [122389000.0, 0.033], [122390000.0, 0.0248], [122393000.0, 0.0255]]},
{"timestamp": "1743771318873", "bids": [[122352000.0, 0.0], [122350000.0, 0.0067], [122346000.0, 0.0053], [122345000.0, 0.0115], [122344000.0, 0.0003], [122341000.0, 0.0002], [122337000.0, 0.0], [122335000.0, 0.0016], [122334000.0, 0.0], [122333000.0, 0.0]], "asks": [[122356000.0, 0.0102], [122357000.0, 0.0058], [122361000.0, 0.03], [122367000.0, 0.0785], [122368000.0, 0.0322], [122370000.0, 0.017], [122371000.0, 0.0223], [122374000.0, 0.0251], [122378000.0, 0.1839], [122379000.0, 0.0327]]},
{"timestamp": "1743771319376", "bids": [[122335000.0, 0.0016], [122334000.0, 0.0], [122333000.0, 0.0], [122332000.0, 0.0005], [122331000.0, 0.0019], [122329000.0, 0.0], [122328000.0, 0.0017], [122326000.0, 0.0003], [122325000.0, 0.0049], [122321000.0, 0.0]], "asks": [[122337000.0, 0.0021], [122352000.0, 0.0182], [122355000.0, 0.0144], [122356000.0, 0.0102], [122357000.0, 0.0058], [122359000.0, 0.0338], [122361000.0, 0.0509], [122362000.0, 0.0171], [122367000.0, 0.0741], [122368000.0, 0.0322]]},
{"timestamp": "1743771319871", "bids": [[122335000.0, 0.0016], [122334000.0, 0.0], [122333000.0, 0.0], [122332000.0, 0.0005], [122331000.0, 0.0019], [122329000.0, 0.0], [122328000.0, 0.0017], [122326000.0, 0.0003], [122325000.0, 0.0049], [122321000.0, 0.0]], "asks": [[122346000.0, 0.2093], [122347000.0, 0.0189], [122350000.0, 0.0125], [122352000.0, 0.015], [122355000.0, 0.0144], [122356000.0, 0.0102], [122357000.0, 0.0058], [122359000.0, 0.0338], [122361000.0, 0.0541], [122362000.0, 0.0171]]},
{"timestamp": "1743771320376", "bids": [[122335000.0, 0.0016], [122334000.0, 0.0], [122333000.0, 0.0], [122332000.0, 0.0005], [122331000.0, 0.0019], [122329000.0, 0.0], [122328000.0, 0.0017], [122326000.0, 0.0003], [122325000.0, 0.0049], [122321000.0, 0.0]], "asks": [[122347000.0, 0.0189], [122350000.0, 0.0125], [122352000.0, 0.015], [122355000.0, 0.0145], [122359000.0, 0.0338], [122361000.0, 0.0633], [122362000.0, 0.0171], [122363000.0, 0.0255], [122367000.0, 0.0572], [122369000.0, 0.1317]]},
{"timestamp": "1743771320872", "bids": [[122335000.0, 0.0016], [122334000.0, 0.0], [122333000.0, 0.0], [122332000.0, 0.0005], [122331000.0, 0.0019], [122329000.0, 0.0], [122328000.0, 0.0017], [122326000.0, 0.0003], [122325000.0, 0.0049], [122321000.0, 0.0]], "asks": [[122347000.0, 0.0503], [122352000.0, 0.0316], [122355000.0, 0.0144], [122357000.0, 0.0181], [122358000.0, 0.0148], [122359000.0, 0.0338], [122360000.0, 0.0578], [122361000.0, 0.0271], [122362000.0, 0.0171], [122363000.0, 0.0255]]},
{"timestamp": "1743771321387", "bids": [[122335000.0, 0.0016], [122334000.0, 0.0], [122333000.0, 0.0], [122332000.0, 0.0005], [122331000.0, 0.0019], [122329000.0, 0.0], [122328000.0, 0.0017], [122326000.0, 0.0003], [122325000.0, 0.0049], [122321000.0, 0.0]], "asks": [[122345000.0, 0.1332], [122347000.0, 0.0503], [122352000.0, 0.0418], [122354000.0, 0.1332], [122357000.0, 0.0181], [122358000.0, 0.0148], [122359000.0, 0.0167], [122360000.0, 0.033], [122367000.0, 0.0166], [122369000.0, 0.082]]},
{"timestamp": "1743771321875", "bids": [[122335000.0, 0.0016], [122334000.0, 0.0], [122333000.0, 0.0], [122332000.0, 0.0005], [122331000.0, 0.0019], [122329000.0, 0.0], [122328000.0, 0.0017], [122326000.0, 0.0003], [122325000.0, 0.0049], [122321000.0, 0.0]], "asks": [[122345000.0, 0.1332], [122352000.0, 0.0102], [122354000.0, 0.1773], [122356000.0, 0.0222], [122359000.0, 0.0177], [122360000.0, 0.0153], [122365000.0, 0.0209], [122366000.0, 0.0501], [122369000.0, 0.016], [122371000.0, 0.0007]]},
{"timestamp": "1743771322374", "bids": [[122329000.0, 0.0], [122328000.0, 0.0017], [122326000.0, 0.0003], [122325000.0, 0.0049], [122321000.0, 0.0], [122320000.0, 0.0001], [122319000.0, 0.0024], [122318000.0, 0.0026], [122316000.0, 0.0009], [122314000.0, 0.0008]], "asks": [[122331000.0, 0.1225], [122354000.0, 0.0441], [122356000.0, 0.0663], [122359000.0, 0.0177], [122360000.0, 0.0153], [122365000.0, 0.0209], [122366000.0, 0.0501], [122373000.0, 0.0327], [122377000.0, 0.0213], [122378000.0, 0.0]]},
{"timestamp": "1743771322877", "bids": [[122329000.0, 0.0], [122328000.0, 0.0017], [122326000.0, 0.0003], [122325000.0, 0.0049], [122321000.0, 0.0], [122320000.0, 0.0001], [122319000.0, 0.0024], [122318000.0, 0.0026], [122316000.0, 0.0009], [122314000.0, 0.0008]], "asks": [[122331000.0, 0.1225], [122335000.0, 0.0], [122356000.0, 0.0222], [122359000.0, 0.0177], [122360000.0, 0.0153], [122365000.0, 0.0209], [122366000.0, 0.0501], [122373000.0, 0.0327], [122377000.0, 0.0213], [122378000.0, 0.0]]},
{"timestamp": "1743771323376", "bids": [[122329000.0, 0.0], [122328000.0, 0.0017], [122326000.0, 0.0003], [122325000.0, 0.0049], [122321000.0, 0.0], [122320000.0, 0.0001], [122319000.0, 0.0024], [122318000.0, 0.0026], [122316000.0, 0.0009], [122314000.0, 0.0008]], "asks": [[122331000.0, 0.1225], [122335000.0, 0.0], [122360000.0, 0.0153], [122365000.0, 0.0209], [122373000.0, 0.0327], [122378000.0, 0.0], [122383000.0, 0.015], [122385000.0, 0.0144], [122389000.0, 0.025], [122392000.0, 0.0271]]},
{"timestamp": "1743771323872", "bids": [[122330000.0, 0.1664], [122329000.0, 0.0], [122328000.0, 0.0017], [122326000.0, 0.0003], [122325000.0, 0.0049], [122321000.0, 0.0], [122320000.0, 0.0001], [122319000.0, 0.0024], [122318000.0, 0.0026], [122316000.0, 0.0009]], "asks": [[122331000.0, 0.1162], [122335000.0, 0.0], [122378000.0, 0.0], [122389000.0, 0.0268], [122394000.0, 0.0519], [122396000.0, 0.0171], [122397000.0, 0.033], [122400000.0, 0.0255], [122402000.0, 0.023], [122403000.0, 0.05]]},
{"timestamp": "1743771324375", "bids": [[122330000.0, 0.1346], [122329000.0, 0.0], [122328000.0, 0.0143], [122326000.0, 0.0003], [122325000.0, 0.0049], [122321000.0, 0.0], [122320000.0, 0.0001], [122319000.0, 0.0024], [122316000.0, 0.0182], [122314000.0, 0.0008]], "asks": [[122331000.0, 0.1128], [122335000.0, 0.0], [122352000.0, 0.011], [122378000.0, 0.0], [122389000.0, 0.0166], [122394000.0, 0.0519], [122396000.0, 0.0171], [122397000.0, 0.033], [122400000.0, 0.0255], [122402000.0, 0.0452]]},
{"timestamp": "1743771324873", "bids": [[122329000.0, 0.0], [122328000.0, 0.0143], [122326000.0, 0.0003], [122325000.0, 0.0049], [122321000.0, 0.0719], [122320000.0, 0.0001], [122319000.0, 0.0024], [122316000.0, 0.0182], [122314000.0, 0.0008], [122313000.0, 0.0035]], "asks": [[122331000.0, 0.1068], [122335000.0, 0.0], [122352000.0, 0.011], [122378000.0, 0.0], [122384000.0, 0.1332], [122388000.0, 0.1332], [122389000.0, 0.0166], [122394000.0, 0.0519], [122396000.0, 0.0171], [122397000.0, 0.033]]},
{"timestamp": "1743771325378", "bids": [[122330000.0, 0.0045], [122329000.0, 0.0], [122328000.0, 0.0143], [122326000.0, 0.0003], [122325000.0, 0.0049], [122321000.0, 0.0719], [122320000.0, 0.0001], [122319000.0, 0.0024], [122316000.0, 0.0009], [122314000.0, 0.0234]], "asks": [[122331000.0, 0.1042], [122335000.0, 0.0], [122352000.0, 0.011], [122378000.0, 0.0], [122383000.0, 0.0516], [122388000.0, 0.1848], [122394000.0, 0.0338], [122396000.0, 0.0171], [122399000.0, 0.015], [122400000.0, 0.0102]]},
{"timestamp": "1743771325878", "bids": [[122330000.0, 0.0015], [122329000.0, 0.0], [122328000.0, 0.0017], [122326000.0, 0.0003], [122325000.0, 0.0049], [122321000.0, 0.0719], [122320000.0, 0.0001], [122319000.0, 0.0024], [122316000.0, 0.0009], [122314000.0, 0.0008]], "asks": [[122331000.0, 0.1148], [122335000.0, 0.0], [122352000.0, 0.011], [122378000.0, 0.0], [122383000.0, 0.0516], [122387000.0, 0.1328], [122388000.0, 0.0516], [122394000.0, 0.0338], [122400000.0, 0.0102], [122406000.0, 0.0007]]},
{"timestamp": "1743771326379", "bids": [[122329000.0, 0.0], [122328000.0, 0.0017], [122326000.0, 0.0003], [122325000.0, 0.0049], [122321000.0, 0.0719], [122320000.0, 0.0001], [122319000.0, 0.0024], [122316000.0, 0.0009], [122314000.0, 0.0008], [122313000.0, 0.0003]], "asks": [[122331000.0, 0.1163], [122335000.0, 0.0], [122352000.0, 0.011], [122378000.0, 0.0], [122382000.0, 0.0166], [122383000.0, 0.0516], [122387000.0, 0.1328], [122388000.0, 0.0516], [122389000.0, 0.0251], [122391000.0, 0.0447]]},
{"timestamp": "1743771326876", "bids": [[122329000.0, 0.0], [122328000.0, 0.0017], [122326000.0, 0.0003], [122325000.0, 0.0049], [122321000.0, 0.0719], [122320000.0, 0.0001], [122319000.0, 0.0024], [122316000.0, 0.0009], [122314000.0, 0.0008], [122313000.0, 0.0003]], "asks": [[122331000.0, 0.1057], [122335000.0, 0.0], [122352000.0, 0.011], [122371000.0, 0.0026], [122372000.0, 0.0366], [122375000.0, 0.0177], [122376000.0, 0.0301], [122378000.0, 0.0], [122382000.0, 0.1494], [122383000.0, 0.0697]]},
{"timestamp": "1743771327375", "bids": [[122329000.0, 0.0], [122328000.0, 0.0017], [122326000.0, 0.0003], [122325000.0, 0.0049], [122321000.0, 0.0719], [122320000.0, 0.0001], [122319000.0, 0.0024], [122316000.0, 0.0009], [122314000.0, 0.0008], [122313000.0, 0.0003]], "asks": [[122331000.0, 0.1029], [122335000.0, 0.0], [122352000.0, 0.011], [122371000.0, 0.0128], [122372000.0, 0.0366], [122375000.0, 0.0177], [122376000.0, 0.0301], [122378000.0, 0.0559], [122382000.0, 0.1494], [122383000.0, 0.0697]]},
{"timestamp": "1743771327876", "bids": [[122329000.0, 0.0], [122328000.0, 0.0017], [122326000.0, 0.0003], [122325000.0, 0.0049], [122321000.0, 0.0719], [122320000.0, 0.0001], [122319000.0, 0.0024], [122316000.0, 0.0009], [122314000.0, 0.0008], [122313000.0, 0.0003]], "asks": [[122331000.0, 0.1017], [122335000.0, 0.0], [122352000.0, 0.011], [122370000.0, 0.0513], [122371000.0, 0.1456], [122372000.0, 0.0366], [122375000.0, 0.0177], [122376000.0, 0.0301], [122378000.0, 0.0559], [122379000.0, 0.0271]]},
{"timestamp": "1743771328440", "bids": [[122329000.0, 0.0], [122328000.0, 0.0017], [122326000.0, 0.0003], [122325000.0, 0.0049], [122321000.0, 0.0719], [122320000.0, 0.0001], [122319000.0, 0.0024], [122316000.0, 0.0009], [122314000.0, 0.0008], [122313000.0, 0.0003]], "asks": [[122331000.0, 0.1017], [122335000.0, 0.0], [122352000.0, 0.011], [122370000.0, 0.0513], [122371000.0, 0.0026], [122372000.0, 0.0144], [122376000.0, 0.0301], [122378000.0, 0.0179], [122384000.0, 0.023], [122385000.0, 0.0166]]},
{"timestamp": "1743771328873", "bids": [[122329000.0, 0.0], [122328000.0, 0.0017], [122326000.0, 0.0003], [122325000.0, 0.0049], [122321000.0, 0.0719], [122320000.0, 0.0001], [122319000.0, 0.0024], [122316000.0, 0.0009], [122314000.0, 0.0008], [122313000.0, 0.0003]], "asks": [[122331000.0, 0.1017], [122335000.0, 0.0], [122352000.0, 0.011], [122369000.0, 0.1328], [122371000.0, 0.0512], [122378000.0, 0.0], [122379000.0, 0.0166], [122382000.0, 0.0338], [122388000.0, 0.0424], [122396000.0, 0.0016]]},
{"timestamp": "1743771329380", "bids": [[122329000.0, 0.0], [122328000.0, 0.0017], [122326000.0, 0.0003], [122325000.0, 0.0049], [122321000.0, 0.0719], [122320000.0, 0.0001], [122319000.0, 0.0024], [122316000.0, 0.0009], [122314000.0, 0.0008], [122313000.0, 0.0003]], "asks": [[122330000.0, 0.0014], [122331000.0, 0.1017], [122335000.0, 0.0], [122352000.0, 0.011], [122371000.0, 0.0512], [122375000.0, 0.015], [122378000.0, 0.0], [122379000.0, 0.0166], [122380000.0, 0.0102], [122382000.0, 0.0338]]},
{"timestamp": "1743771329878", "bids": [[122329000.0, 0.0], [122328000.0, 0.0017], [122326000.0, 0.0003], [122325000.0, 0.0049], [122321000.0, 0.0719], [122320000.0, 0.0001], [122319000.0, 0.0024], [122316000.0, 0.0009], [122314000.0, 0.0008], [122313000.0, 0.0003]], "asks": [[122331000.0, 0.0942], [122335000.0, 0.0], [122352000.0, 0.011], [122368000.0, 0.0512], [122369000.0, 0.0], [122374000.0, 0.0026], [122375000.0, 0.015], [122376000.0, 0.0144], [122378000.0, 0.0222], [122380000.0, 0.0148]]},
{"timestamp": "1743771330380", "bids": [[122330000.0, 0.1617], [122329000.0, 0.0], [122328000.0, 0.0017], [122326000.0, 0.0003], [122325000.0, 0.0049], [122321000.0, 0.0719], [122320000.0, 0.0001], [122319000.0, 0.0024], [122316000.0, 0.0009], [122314000.0, 0.0008]], "asks": [[122331000.0, 0.0942], [122335000.0, 0.0], [122352000.0, 0.011], [122369000.0, 0.0], [122374000.0, 0.0538], [122375000.0, 0.015], [122376000.0, 0.0144], [122378000.0, 0.0222], [122381000.0, 0.0181], [122382000.0, 0.0153]]},
{"timestamp": "1743771330876", "bids": [[122330000.0, 0.1756], [122329000.0, 0.0], [122328000.0, 0.0017], [122326000.0, 0.0003], [122325000.0, 0.0049], [122321000.0, 0.0719], [122320000.0, 0.0001], [122319000.0, 0.0024], [122316000.0, 0.0009], [122314000.0, 0.0008]], "asks": [[122331000.0, 0.0942], [122335000.0, 0.0], [122352000.0, 0.011], [122369000.0, 0.0], [122374000.0, 0.0512], [122375000.0, 0.015], [122376000.0, 0.0144], [122378000.0, 0.0166], [122382000.0, 0.0153], [122384000.0, 0.0176]]},
{"timestamp": "1743771331373", "bids": [[122330000.0, 0.0113], [122329000.0, 0.0], [122328000.0, 0.0017], [122326000.0, 0.0003], [122325000.0, 0.0049], [122321000.0, 0.0719], [122320000.0, 0.0001], [122319000.0, 0.0024], [122316000.0, 0.0009], [122314000.0, 0.0008]], "asks": [[122331000.0, 0.0942], [122335000.0, 0.0], [122352000.0, 0.011], [122369000.0, 0.0], [122378000.0, 0.0166], [122383000.0, 0.0338], [122384000.0, 0.0176], [122386000.0, 0.0248], [122395000.0, 0.0327], [122396000.0, 0.0016]]},
{"timestamp": "1743771331881", "bids": [[122330000.0, 0.0061], [122329000.0, 0.0], [122328000.0, 0.0017], [122326000.0, 0.0003], [122325000.0, 0.0049], [122321000.0, 0.0719], [122320000.0, 0.0001], [122319000.0, 0.0024], [122316000.0, 0.0009], [122314000.0, 0.0008]], "asks": [[122331000.0, 0.0849], [122335000.0, 0.0], [122352000.0, 0.011], [122369000.0, 0.0], [122378000.0, 0.0166], [122383000.0, 0.0338], [122386000.0, 0.0248], [122395000.0, 0.0327], [122396000.0, 0.0016], [122397000.0, 0.0102]]},
{"timestamp": "1743771332377", "bids": [[122330000.0, 0.0126], [122329000.0, 0.0], [122328000.0, 0.0017], [122326000.0, 0.0003], [122325000.0, 0.0049], [122321000.0, 0.0719], [122320000.0, 0.0001], [122319000.0, 0.0024], [122316000.0, 0.0009], [122314000.0, 0.0008]], "asks": [[122331000.0, 0.0849], [122335000.0, 0.0], [122352000.0, 0.011], [122369000.0, 0.0], [122378000.0, 0.0], [122396000.0, 0.0016], [122399000.0, 0.0026], [122404000.0, 0.0691], [122406000.0, 0.058], [122407000.0, 0.0434]]},
{"timestamp": "1743771332874", "bids": [[122330000.0, 0.0126], [122329000.0, 0.0], [122328000.0, 0.0017], [122326000.0, 0.0003], [122325000.0, 0.0049], [122321000.0, 0.0719], [122320000.0, 0.0001], [122319000.0, 0.0024], [122316000.0, 0.0009], [122314000.0, 0.0008]], "asks": [[122331000.0, 0.0849], [122335000.0, 0.0], [122369000.0, 0.0], [122378000.0, 0.0], [122394000.0, 0.1832], [122396000.0, 0.0016], [122401000.0, 0.015], [122402000.0, 0.0102], [122403000.0, 0.183], [122404000.0, 0.0543]]},
{"timestamp": "1743771333375", "bids": [[122330000.0, 0.1882], [122329000.0, 0.0], [122328000.0, 0.0017], [122326000.0, 0.0003], [122325000.0, 0.0049], [122321000.0, 0.0719], [122320000.0, 0.0001], [122319000.0, 0.0024], [122316000.0, 0.0009], [122314000.0, 0.0008]], "asks": [[122331000.0, 0.0848], [122335000.0, 0.0], [122369000.0, 0.0], [122378000.0, 0.0], [122394000.0, 0.1832], [122396000.0, 0.0016], [122401000.0, 0.015], [122402000.0, 0.0102], [122403000.0, 0.0509], [122404000.0, 0.0321]]},
{"timestamp": "1743771333877", "bids": [[122330000.0, 0.1882], [122329000.0, 0.0], [122328000.0, 0.0111], [122326000.0, 0.0003], [122325000.0, 0.0049], [122321000.0, 0.0719], [122320000.0, 0.0001], [122319000.0, 0.0024], [122316000.0, 0.0009], [122314000.0, 0.0008]], "asks": [[122331000.0, 0.0848], [122335000.0, 0.0], [122369000.0, 0.0], [122378000.0, 0.0], [122394000.0, 0.1832], [122396000.0, 0.0016], [122403000.0, 0.0509], [122406000.0, 0.0396], [122411000.0, 0.0271], [122413000.0, 0.0497]]},
{"timestamp": "1743771334378", "bids": [[122330000.0, 0.019], [122329000.0, 0.0], [122328000.0, 0.0111], [122326000.0, 0.0003], [122325000.0, 0.0049], [122321000.0, 0.0719], [122320000.0, 0.0001], [122319000.0, 0.0024], [122316000.0, 0.0009], [122314000.0, 0.0008]], "asks": [[122331000.0, 0.0846], [122335000.0, 0.0], [122369000.0, 0.0], [122378000.0, 0.0], [122396000.0, 0.0016], [122406000.0, 0.0166], [122412000.0, 0.0338], [122414000.0, 0.0424], [122421000.0, 0.0016], [122423000.0, 0.0327]]},
{"timestamp": "1743771334878", "bids": [[122330000.0, 0.0154], [122329000.0, 0.0], [122328000.0, 0.0111], [122327000.0, 0.0198], [122326000.0, 0.0003], [122325000.0, 0.0463], [122321000.0, 0.0719], [122320000.0, 0.0001], [122319000.0, 0.0024], [122316000.0, 0.0249]], "asks": [[122331000.0, 0.0073], [122335000.0, 0.0], [122369000.0, 0.0], [122378000.0, 0.0], [122393000.0, 0.1321], [122396000.0, 0.0016], [122406000.0, 0.0], [122412000.0, 0.0338], [122421000.0, 0.0016], [122424000.0, 0.015]]},
{"timestamp": "1743771335379", "bids": [[122341000.0, 0.0009], [122340000.0, 0.0219], [122331000.0, 0.025], [122330000.0, 0.0188], [122329000.0, 0.0], [122328000.0, 0.0111], [122327000.0, 0.0198], [122326000.0, 0.0003], [122325000.0, 0.0463], [122323000.0, 0.0005]], "asks": [[122369000.0, 0.0], [122378000.0, 0.0], [122393000.0, 0.1321], [122396000.0, 0.0016], [122405000.0, 0.0509], [122406000.0, 0.0], [122411000.0, 0.1321], [122421000.0, 0.0016], [122424000.0, 0.015], [122430000.0, 0.0102]]},
{"timestamp": "1743771336073", "bids": [[122354000.0, 0.0225], [122341000.0, 0.0035], [122340000.0, 0.0219], [122335000.0, 0.0227], [122331000.0, 0.009], [122330000.0, 0.0435], [122329000.0, 0.0073], [122328000.0, 0.0111], [122326000.0, 0.0003], [122325000.0, 0.0265]], "asks": [[122369000.0, 0.0], [122378000.0, 0.0], [122396000.0, 0.0016], [122406000.0, 0.0], [122421000.0, 0.0016], [122423000.0, 0.0242], [122425000.0, 0.0168], [122430000.0, 0.0173], [122432000.0, 0.0334], [122434000.0, 0.0559]]},
{"timestamp": "1743771336383", "bids": [[122354000.0, 0.0225], [122341000.0, 0.0062], [122340000.0, 0.0219], [122335000.0, 0.0227], [122331000.0, 0.009], [122330000.0, 0.0427], [122329000.0, 0.0073], [122328000.0, 0.0111], [122326000.0, 0.0003], [122325000.0, 0.0265]], "asks": [[122369000.0, 0.0], [122378000.0, 0.0], [122396000.0, 0.0016], [122406000.0, 0.0], [122421000.0, 0.0016], [122423000.0, 0.0242], [122425000.0, 0.0168], [122430000.0, 0.0173], [122432000.0, 0.0335], [122434000.0, 0.0559]]},
{"timestamp": "1743771336878", "bids": [[122354000.0, 0.0225], [122342000.0, 0.1529], [122341000.0, 0.0027], [122335000.0, 0.0227], [122334000.0, 0.0241], [122331000.0, 0.009], [122330000.0, 0.0313], [122329000.0, 0.0073], [122328000.0, 0.0111], [122326000.0, 0.0003]], "asks": [[122369000.0, 0.0], [122378000.0, 0.0], [122396000.0, 0.0016], [122406000.0, 0.0], [122421000.0, 0.0016], [122423000.0, 0.0242], [122425000.0, 0.0168], [122430000.0, 0.0173], [122432000.0, 0.0335], [122434000.0, 0.0559]]},
{"timestamp": "1743771337381", "bids": [[122359000.0, 0.0219], [122354000.0, 0.0225], [122353000.0, 0.0026], [122343000.0, 0.0822], [122336000.0, 0.0822], [122334000.0, 0.0241], [122331000.0, 0.002], [122329000.0, 0.0073], [122328000.0, 0.0017], [122326000.0, 0.0003]], "asks": [[122396000.0, 0.0001], [122406000.0, 0.0], [122421000.0, 0.0016], [122434000.0, 0.0559], [122437000.0, 0.0], [122440000.0, 0.023], [122441000.0, 0.0827], [122442000.0, 0.0236], [122443000.0, 0.0239], [122444000.0, 0.0141]]},
{"timestamp": "1743771337943", "bids": [[122376000.0, 0.0032], [122355000.0, 0.0198], [122354000.0, 0.0225], [122353000.0, 0.0026], [122351000.0, 0.0198], [122343000.0, 0.0822], [122336000.0, 0.0822], [122333000.0, 0.0329], [122331000.0, 0.002], [122329000.0, 0.0073]], "asks": [[122396000.0, 0.0001], [122406000.0, 0.0], [122421000.0, 0.0016], [122435000.0, 0.0173], [122437000.0, 0.0], [122439000.0, 0.0242], [122443000.0, 0.0], [122445000.0, 0.0036], [122446000.0, 0.0016], [122447000.0, 0.004]]},
{"timestamp": "1743771338385", "bids": [[122376000.0, 0.0032], [122360000.0, 0.1877], [122355000.0, 0.0198], [122354000.0, 0.0225], [122351000.0, 0.0425], [122343000.0, 0.0822], [122333000.0, 0.0329], [122331000.0, 0.002], [122329000.0, 0.0073], [122328000.0, 0.0017]], "asks": [[122396000.0, 0.0001], [122406000.0, 0.0], [122421000.0, 0.0016], [122435000.0, 0.0173], [122437000.0, 0.0], [122439000.0, 0.0242], [122443000.0, 0.0], [122445000.0, 0.0036], [122446000.0, 0.0016], [122447000.0, 0.004]]},
{"timestamp": "1743771338882", "bids": [[122376000.0, 0.0032], [122360000.0, 0.1877], [122358000.0, 0.0246], [122357000.0, 0.0216], [122354000.0, 0.0225], [122351000.0, 0.0425], [122345000.0, 0.0114], [122343000.0, 0.0822], [122339000.0, 0.0323], [122333000.0, 0.0655]], "asks": [[122396000.0, 0.0001], [122406000.0, 0.0], [122421000.0, 0.0016], [122435000.0, 0.0173], [122437000.0, 0.0], [122439000.0, 0.0242], [122441000.0, 0.0168], [122443000.0, 0.0], [122445000.0, 0.0036], [122446000.0, 0.0016]]},
{"timestamp": "1743771339380", "bids": [[122389000.0, 0.0026], [122383000.0, 0.0219], [122377000.0, 0.0088], [122370000.0, 0.0043], [122360000.0, 0.05], [122358000.0, 0.0246], [122357000.0, 0.0216], [122355000.0, 0.0323], [122354000.0, 0.0225], [122348000.0, 0.0248]], "asks": [[122396000.0, 0.0001], [122406000.0, 0.0], [122421000.0, 0.0016], [122437000.0, 0.0], [122441000.0, 0.0168], [122443000.0, 0.0], [122445000.0, 0.0036], [122446000.0, 0.0016], [122447000.0, 0.004], [122448000.0, 0.0002]]},
{"timestamp": "1743771339878", "bids": [[122406000.0, 0.0006], [122390000.0, 0.0027], [122389000.0, 0.0026], [122384000.0, 0.0002], [122370000.0, 0.0043], [122361000.0, 0.0822], [122360000.0, 0.0125], [122357000.0, 0.0216], [122355000.0, 0.0574], [122354000.0, 0.0225]], "asks": [[122421000.0, 0.0016], [122437000.0, 0.0], [122441000.0, 0.0168], [122443000.0, 0.0], [122445000.0, 0.0036], [122446000.0, 0.0016], [122447000.0, 0.004], [122448000.0, 0.0002], [122453000.0, 0.0471], [122459000.0, 0.0153]]},
{"timestamp": "1743771340379", "bids": [[122406000.0, 0.0033], [122395000.0, 0.0219], [122390000.0, 0.0136], [122389000.0, 0.0026], [122384000.0, 0.0002], [122371000.0, 0.0246], [122370000.0, 0.0043], [122369000.0, 0.0048], [122360000.0, 0.025], [122357000.0, 0.0216]], "asks": [[122421000.0, 0.0015], [122437000.0, 0.0], [122441000.0, 0.0168], [122443000.0, 0.0], [122445000.0, 0.0036], [122446000.0, 0.0016], [122447000.0, 0.004], [122448000.0, 0.0002], [122453000.0, 0.0471], [122459000.0, 0.0153]]},
{"timestamp": "1743771340884", "bids": [[122406000.0, 0.0027], [122395000.0, 0.0219], [122389000.0, 0.0026], [122372000.0, 0.0822], [122371000.0, 0.0246], [122370000.0, 0.0822], [122369000.0, 0.0048], [122360000.0, 0.0251], [122357000.0, 0.0216], [122355000.0, 0.0574]], "asks": [[122421000.0, 0.0015], [122437000.0, 0.0], [122441000.0, 0.0168], [122443000.0, 0.0], [122445000.0, 0.0036], [122446000.0, 0.0016], [122447000.0, 0.004], [122448000.0, 0.0002], [122450000.0, 0.0016], [122453000.0, 0.0471]]},
{"timestamp": "1743771341381", "bids": [[122395000.0, 0.0219], [122389000.0, 0.0026], [122372000.0, 0.0822], [122371000.0, 0.0246], [122370000.0, 0.0822], [122360000.0, 0.0002], [122357000.0, 0.0216], [122355000.0, 0.0323], [122345000.0, 0.0114], [122331000.0, 0.0278]], "asks": [[122421000.0, 0.0015], [122437000.0, 0.0], [122443000.0, 0.0], [122445000.0, 0.0036], [122446000.0, 0.0016], [122447000.0, 0.004], [122448000.0, 0.0002], [122450000.0, 0.0016], [122453000.0, 0.0471], [122459000.0, 0.0153]]},
{"timestamp": "1743771341881", "bids": [[122404000.0, 0.0032], [122382000.0, 0.0198], [122378000.0, 0.0425], [122372000.0, 0.0822], [122370000.0, 0.0822], [122360000.0, 0.0329], [122355000.0, 0.0323], [122354000.0, 0.0362], [122352000.0, 0.0522], [122348000.0, 0.0146]], "asks": [[122421000.0, 0.0015], [122437000.0, 0.0], [122443000.0, 0.0], [122445000.0, 0.0036], [122446000.0, 0.0016], [122447000.0, 0.004], [122448000.0, 0.0002], [122450000.0, 0.0016], [122453000.0, 0.0471], [122459000.0, 0.0]]},
{"timestamp": "1743771342378", "bids": [[122404000.0, 0.0032], [122396000.0, 0.0], [122378000.0, 0.0425], [122372000.0, 0.0822], [122361000.0, 0.0216], [122360000.0, 0.0329], [122354000.0, 0.0362], [122352000.0, 0.0522], [122348000.0, 0.0146], [122342000.0, 0.1139]], "asks": [[122421000.0, 0.0015], [122437000.0, 0.0], [122443000.0, 0.0059], [122445000.0, 0.0036], [122446000.0, 0.0184], [122447000.0, 0.004], [122448000.0, 0.0002], [122450000.0, 0.0016], [122453000.0, 0.0471], [122459000.0, 0.0]]},
{"timestamp": "1743771342883", "bids": [[122405000.0, 0.1842], [122404000.0, 0.0032], [122396000.0, 0.0], [122384000.0, 0.0225], [122378000.0, 0.0425], [122369000.0, 0.0161], [122363000.0, 0.0026], [122361000.0, 0.1035], [122360000.0, 0.0329], [122354000.0, 0.0476]], "asks": [[122421000.0, 0.0015], [122437000.0, 0.0], [122443000.0, 0.0059], [122445000.0, 0.0036], [122446000.0, 0.0184], [122447000.0, 0.004], [122448000.0, 0.0002], [122450000.0, 0.0016], [122453000.0, 0.0471], [122455000.0, 0.0]]},
{"timestamp": "1743771343381", "bids": [[122405000.0, 0.1842], [122404000.0, 0.0032], [122396000.0, 0.0], [122394000.0, 0.0122], [122384000.0, 0.0225], [122378000.0, 0.0198], [122374000.0, 0.0198], [122369000.0, 0.0161], [122363000.0, 0.0026], [122361000.0, 0.0819]], "asks": [[122421000.0, 0.0015], [122437000.0, 0.0], [122443000.0, 0.0059], [122445000.0, 0.0036], [122446000.0, 0.0016], [122447000.0, 0.004], [122448000.0, 0.0002], [122450000.0, 0.0016], [122453000.0, 0.0471], [122455000.0, 0.0]]},
{"timestamp": "1743771343879", "bids": [[122405000.0, 0.0615], [122396000.0, 0.0], [122394000.0, 0.0122], [122386000.0, 0.0059], [122384000.0, 0.0225], [122374000.0, 0.0198], [122371000.0, 0.0251], [122344000.0, 0.0225], [122331000.0, 0.0021], [122330000.0, 0.0561]], "asks": [[122421000.0, 0.0015], [122437000.0, 0.0], [122443000.0, 0.0], [122445000.0, 0.0036], [122446000.0, 0.0016], [122447000.0, 0.004], [122448000.0, 0.0002], [122450000.0, 0.0016], [122453000.0, 0.0471], [122455000.0, 0.0]]},
{"timestamp": "1743771344383", "bids": [[122399000.0, 0.0161], [122396000.0, 0.0], [122393000.0, 0.0026], [122387000.0, 0.0425], [122381000.0, 0.0114], [122375000.0, 0.0246], [122374000.0, 0.0198], [122371000.0, 0.0251], [122369000.0, 0.0655], [122368000.0, 0.0362]], "asks": [[122421000.0, 0.0015], [122437000.0, 0.0], [122443000.0, 0.0], [122445000.0, 0.0036], [122446000.0, 0.0016], [122447000.0, 0.004], [122448000.0, 0.0002], [122450000.0, 0.0016], [122453000.0, 0.0471], [122455000.0, 0.0]]},
{"timestamp": "1743771344879", "bids": [[122399000.0, 0.0161], [122396000.0, 0.0], [122393000.0, 0.0026], [122387000.0, 0.0425], [122381000.0, 0.0114], [122375000.0, 0.1065], [122374000.0, 0.0198], [122373000.0, 0.0048], [122372000.0, 0.0819], [122369000.0, 0.0655]], "asks": [[122421000.0, 0.0015], [122437000.0, 0.0], [122443000.0, 0.0], [122445000.0, 0.0036], [122446000.0, 0.0016], [122447000.0, 0.004], [122448000.0, 0.0002], [122450000.0, 0.0016], [122453000.0, 0.0482], [122455000.0, 0.0]]},
{"timestamp": "1743771345385", "bids": [[122399000.0, 0.0161], [122396000.0, 0.0], [122393000.0, 0.0026], [122387000.0, 0.0425], [122381000.0, 0.0114], [122375000.0, 0.1065], [122374000.0, 0.0198], [122373000.0, 0.0048], [122372000.0, 0.0819], [122369000.0, 0.0655]], "asks": [[122421000.0, 0.0015], [122437000.0, 0.0], [122443000.0, 0.0], [122445000.0, 0.0036], [122446000.0, 0.0016], [122447000.0, 0.004], [122448000.0, 0.0002], [122450000.0, 0.0016], [122453000.0, 0.0482], [122455000.0, 0.0]]},
{"timestamp": "1743771345884", "bids": [[122399000.0, 0.0161], [122396000.0, 0.0], [122393000.0, 0.0026], [122387000.0, 0.0425], [122381000.0, 0.0114], [122376000.0, 0.0819], [122375000.0, 0.0246], [122374000.0, 0.0198], [122369000.0, 0.0655], [122368000.0, 0.0362]], "asks": [[122421000.0, 0.0015], [122437000.0, 0.0], [122443000.0, 0.0], [122445000.0, 0.0036], [122446000.0, 0.0016], [122447000.0, 0.004], [122448000.0, 0.0002], [122450000.0, 0.0016], [122453000.0, 0.0482], [122455000.0, 0.0]]},
{"timestamp": "1743771346381", "bids": [[122399000.0, 0.0161], [122396000.0, 0.0], [122393000.0, 0.0026], [122387000.0, 0.0198], [122381000.0, 0.0114], [122376000.0, 0.0819], [122375000.0, 0.0246], [122373000.0, 0.0048], [122369000.0, 0.0655], [122364000.0, 0.0251]], "asks": [[122421000.0, 0.0015], [122437000.0, 0.0], [122443000.0, 0.0], [122445000.0, 0.0036], [122446000.0, 0.0016], [122447000.0, 0.004], [122448000.0, 0.0002], [122450000.0, 0.0016], [122453000.0, 0.0482], [122455000.0, 0.0]]},
{"timestamp": "1743771346883", "bids": [[122411000.0, 0.0032], [122396000.0, 0.0], [122393000.0, 0.0026], [122385000.0, 0.0216], [122376000.0, 0.0819], [122373000.0, 0.0048], [122364000.0, 0.0249], [122354000.0, 0.0002], [122335000.0, 0.0003], [122331000.0, 0.0021]], "asks": [[122421000.0, 0.0015], [122437000.0, 0.0], [122443000.0, 0.0], [122445000.0, 0.0036], [122446000.0, 0.0016], [122447000.0, 0.004], [122448000.0, 0.0002], [122450000.0, 0.0016], [122453000.0, 0.0482], [122455000.0, 0.0]]},
{"timestamp": "1743771347381", "bids": [[122411000.0, 0.0032], [122385000.0, 0.0216], [122379000.0, 0.0198], [122375000.0, 0.0227], [122373000.0, 0.0048], [122367000.0, 0.0323], [122359000.0, 0.0264], [122354000.0, 0.0361], [122345000.0, 0.0508], [122341000.0, 0.0799]], "asks": [[122421000.0, 0.0014], [122437000.0, 0.0], [122443000.0, 0.0], [122445000.0, 0.0036], [122446000.0, 0.0016], [122447000.0, 0.004], [122448000.0, 0.0002], [122450000.0, 0.0016], [122452000.0, 0.079], [122453000.0, 0.0482]]},
{"timestamp": "1743771347883", "bids": [[122411000.0, 0.0032], [122385000.0, 0.0216], [122382000.0, 0.0161], [122379000.0, 0.0198], [122375000.0, 0.0227], [122367000.0, 0.0323], [122360000.0, 0.0819], [122359000.0, 0.0264], [122357000.0, 0.0246], [122354000.0, 0.0409]], "asks": [[122421000.0, 0.0014], [122437000.0, 0.0], [122443000.0, 0.0], [122445000.0, 0.0036], [122446000.0, 0.0016], [122447000.0, 0.004], [122448000.0, 0.0002], [122450000.0, 0.0016], [122452000.0, 0.079], [122453000.0, 0.0482]]},
{"timestamp": "1743771348391", "bids": [[122411000.0, 0.0032], [122360000.0, 0.0819], [122357000.0, 0.0246], [122354000.0, 0.0048], [122346000.0, 0.025], [122341000.0, 0.0574], [122335000.0, 0.0003], [122331000.0, 0.0021], [122329000.0, 0.0], [122328000.0, 0.0017]], "asks": [[122420000.0, 0.0107], [122421000.0, 0.0014], [122437000.0, 0.0], [122443000.0, 0.0], [122445000.0, 0.0036], [122446000.0, 0.0016], [122447000.0, 0.004], [122448000.0, 0.0002], [122450000.0, 0.0016], [122452000.0, 0.079]]},
{"timestamp": "1743771348879", "bids": [[122412000.0, 0.1563], [122368000.0, 0.0819], [122366000.0, 0.0198], [122361000.0, 0.0198], [122360000.0, 0.0933], [122354000.0, 0.0048], [122341000.0, 0.0225], [122340000.0, 0.0257], [122336000.0, 0.0561], [122335000.0, 0.0003]], "asks": [[122420000.0, 0.0107], [122421000.0, 0.0014], [122437000.0, 0.0], [122441000.0, 0.0173], [122443000.0, 0.0], [122445000.0, 0.0036], [122446000.0, 0.0258], [122447000.0, 0.004], [122448000.0, 0.0002], [122450000.0, 0.0016]]},
{"timestamp": "1743771349383", "bids": [[122412000.0, 0.1563], [122375000.0, 0.0161], [122368000.0, 0.0819], [122366000.0, 0.0224], [122361000.0, 0.0198], [122360000.0, 0.0114], [122358000.0, 0.0443], [122354000.0, 0.0048], [122341000.0, 0.0225], [122340000.0, 0.0257]], "asks": [[122421000.0, 0.0014], [122437000.0, 0.0], [122441000.0, 0.0173], [122443000.0, 0.0], [122445000.0, 0.0036], [122446000.0, 0.0258], [122447000.0, 0.004], [122448000.0, 0.0002], [122450000.0, 0.0016], [122451000.0, 0.0168]]},
{"timestamp": "1743771349882", "bids": [[122386000.0, 0.0032], [122375000.0, 0.0161], [122360000.0, 0.0114], [122358000.0, 0.0216], [122354000.0, 0.0048], [122351000.0, 0.0246], [122342000.0, 0.0329], [122340000.0, 0.0248], [122339000.0, 0.0649], [122335000.0, 0.0577]], "asks": [[122421000.0, 0.0014], [122437000.0, 0.0], [122443000.0, 0.0], [122445000.0, 0.0036], [122446000.0, 0.0016], [122447000.0, 0.004], [122448000.0, 0.0002], [122449000.0, 0.0059], [122450000.0, 0.0016], [122453000.0, 0.0482]]},
{"timestamp": "1743771350388", "bids": [[122366000.0, 0.0198], [122360000.0, 0.0114], [122354000.0, 0.0048], [122351000.0, 0.0246], [122343000.0, 0.0002], [122340000.0, 0.0505], [122335000.0, 0.0887], [122331000.0, 0.0021], [122329000.0, 0.0], [122328000.0, 0.0017]], "asks": [[122421000.0, 0.0014], [122437000.0, 0.0], [122443000.0, 0.0], [122445000.0, 0.0036], [122446000.0, 0.0016], [122447000.0, 0.004], [122448000.0, 0.0002], [122449000.0, 0.0059], [122450000.0, 0.0016], [122451000.0, 0.0168]]},
{"timestamp": "1743771350883", "bids": [[122374000.0, 0.0026], [122368000.0, 0.0227], [122366000.0, 0.0198], [122359000.0, 0.0819], [122346000.0, 0.0362], [122343000.0, 0.0002], [122342000.0, 0.0258], [122341000.0, 0.0225], [122340000.0, 0.0259], [122335000.0, 0.0564]], "asks": [[122421000.0, 0.0014], [122437000.0, 0.0], [122443000.0, 0.0], [122445000.0, 0.0036], [122446000.0, 0.0016], [122447000.0, 0.004], [122448000.0, 0.0002], [122450000.0, 0.0016], [122451000.0, 0.0168], [122452000.0, 0.079]]},
{"timestamp": "1743771351382", "bids": [[122393000.0, 0.0032], [122383000.0, 0.0161], [122370000.0, 0.0216], [122366000.0, 0.0198], [122358000.0, 0.0246], [122355000.0, 0.0048], [122352000.0, 0.0649], [122349000.0, 0.0329], [122348000.0, 0.0001], [122344000.0, 0.0264]], "asks": [[122411000.0, 0.0001], [122421000.0, 0.0014], [122437000.0, 0.0], [122443000.0, 0.0], [122445000.0, 0.0036], [122446000.0, 0.0016], [122447000.0, 0.004], [122448000.0, 0.0002], [122449000.0, 0.0059], [122450000.0, 0.0806]]},
{"timestamp": "1743771351880", "bids": [[122393000.0, 0.0032], [122370000.0, 0.0026], [122360000.0, 0.0114], [122355000.0, 0.0048], [122352000.0, 0.0323], [122348000.0, 0.0001], [122341000.0, 0.0247], [122335000.0, 0.0326], [122331000.0, 0.0022], [122329000.0, 0.0]], "asks": [[122410000.0, 0.0107], [122411000.0, 0.0001], [122421000.0, 0.0014], [122437000.0, 0.0], [122443000.0, 0.0], [122445000.0, 0.0036], [122446000.0, 0.0016], [122447000.0, 0.004], [122448000.0, 0.0002], [122449000.0, 0.0059]]},
{"timestamp": "1743771352381", "bids": [[122370000.0, 0.0026], [122364000.0, 0.0198], [122361000.0, 0.0227], [122360000.0, 0.0114], [122339000.0, 0.0326], [122338000.0, 0.0258], [122335000.0, 0.0005], [122333000.0, 0.0362], [122331000.0, 0.0022], [122329000.0, 0.0251]], "asks": [[122410000.0, 0.0107], [122411000.0, 0.0001], [122421000.0, 0.0014], [122437000.0, 0.0], [122441000.0, 0.0173], [122443000.0, 0.0], [122445000.0, 0.0036], [122446000.0, 0.1048], [122447000.0, 0.004], [122448000.0, 0.0002]]},
{"timestamp": "1743771352884", "bids": [[122383000.0, 0.0032], [122371000.0, 0.1563], [122370000.0, 0.0161], [122364000.0, 0.0224], [122361000.0, 0.0227], [122360000.0, 0.0114], [122358000.0, 0.0414], [122349000.0, 0.0225], [122345000.0, 0.0246], [122340000.0, 0.0819]], "asks": [[122411000.0, 0.0], [122421000.0, 0.0014], [122437000.0, 0.0], [122440000.0, 0.079], [122441000.0, 0.0173], [122442000.0, 0.0168], [122443000.0, 0.0059], [122445000.0, 0.0036], [122446000.0, 0.0258], [122447000.0, 0.004]]},
{"timestamp": "1743771353387", "bids": [[122383000.0, 0.0032], [122371000.0, 0.0139], [122370000.0, 0.0161], [122364000.0, 0.0224], [122361000.0, 0.0227], [122360000.0, 0.0114], [122358000.0, 0.0414], [122345000.0, 0.0246], [122339000.0, 0.0655], [122338000.0, 0.0258]], "asks": [[122411000.0, 0.0], [122421000.0, 0.0014], [122437000.0, 0.0], [122441000.0, 0.0173], [122442000.0, 0.0168], [122443000.0, 0.0059], [122445000.0, 0.0036], [122446000.0, 0.0258], [122447000.0, 0.004], [122448000.0, 0.0002]]},
{"timestamp": "1743771353887", "bids": [[122383000.0, 0.0032], [122370000.0, 0.0161], [122364000.0, 0.0224], [122361000.0, 0.0227], [122360000.0, 0.0114], [122358000.0, 0.0414], [122346000.0, 0.0819], [122345000.0, 0.0246], [122339000.0, 0.0655], [122338000.0, 0.0258]], "asks": [[122411000.0, 0.0], [122421000.0, 0.0014], [122437000.0, 0.0], [122441000.0, 0.0173], [122442000.0, 0.0168], [122443000.0, 0.0059], [122445000.0, 0.0826], [122446000.0, 0.0258], [122447000.0, 0.004], [122448000.0, 0.0002]]},
{"timestamp": "1743771354384", "bids": [[122383000.0, 0.0032], [122370000.0, 0.0161], [122364000.0, 0.0224], [122361000.0, 0.0227], [122360000.0, 0.0114], [122358000.0, 0.0414], [122346000.0, 0.0867], [122345000.0, 0.0246], [122339000.0, 0.0655], [122338000.0, 0.0258]], "asks": [[122411000.0, 0.0], [122421000.0, 0.0014], [122437000.0, 0.0], [122440000.0, 0.079], [122441000.0, 0.0173], [122442000.0, 0.0168], [122443000.0, 0.0059], [122445000.0, 0.0036], [122446000.0, 0.0258], [122447000.0, 0.004]]},
{"timestamp": "1743771354883", "bids": [[122383000.0, 0.0032], [122370000.0, 0.0161], [122364000.0, 0.0224], [122361000.0, 0.0227], [122360000.0, 0.0114], [122358000.0, 0.0414], [122346000.0, 0.0867], [122345000.0, 0.0246], [122339000.0, 0.0655], [122338000.0, 0.0258]], "asks": [[122411000.0, 0.0], [122421000.0, 0.0014], [122437000.0, 0.0], [122441000.0, 0.0173], [122442000.0, 0.0168], [122443000.0, 0.0059], [122445000.0, 0.0036], [122446000.0, 0.0258], [122447000.0, 0.004], [122448000.0, 0.0002]]},
{"timestamp": "1743771355383", "bids": [[122384000.0, 0.0671], [122383000.0, 0.0032], [122370000.0, 0.0161], [122364000.0, 0.0224], [122361000.0, 0.0227], [122360000.0, 0.0114], [122358000.0, 0.0414], [122346000.0, 0.0819], [122345000.0, 0.0246], [122341000.0, 0.0225]], "asks": [[122411000.0, 0.0], [122421000.0, 0.0014], [122437000.0, 0.0], [122441000.0, 0.0963], [122442000.0, 0.0168], [122443000.0, 0.0059], [122445000.0, 0.0036], [122446000.0, 0.0258], [122447000.0, 0.004], [122448000.0, 0.0002]]},
{"timestamp": "1743771355883", "bids": [[122384000.0, 0.1755], [122370000.0, 0.0161], [122364000.0, 0.0224], [122361000.0, 0.0227], [122358000.0, 0.0198], [122346000.0, 0.0819], [122341000.0, 0.0225], [122338000.0, 0.0258], [122335000.0, 0.0253], [122332000.0, 0.0521]], "asks": [[122411000.0, 0.0], [122421000.0, 0.0014], [122437000.0, 0.0], [122443000.0, 0.0], [122444000.0, 0.079], [122445000.0, 0.0036], [122446000.0, 0.0016], [122447000.0, 0.004], [122448000.0, 0.0002], [122450000.0, 0.0016]]},
{"timestamp": "1743771356381", "bids": [[122369000.0, 0.0026], [122364000.0, 0.0198], [122361000.0, 0.0227], [122356000.0, 0.0048], [122350000.0, 0.0246], [122344000.0, 0.0652], [122342000.0, 0.0122], [122335000.0, 0.0003], [122331000.0, 0.0729], [122329000.0, 0.0]], "asks": [[122411000.0, 0.0], [122421000.0, 0.0014], [122437000.0, 0.0], [122443000.0, 0.0], [122445000.0, 0.0036], [122446000.0, 0.0016], [122447000.0, 0.004], [122448000.0, 0.0061], [122450000.0, 0.0016], [122452000.0, 0.079]]},
{"timestamp": "1743771356883", "bids": [[122375000.0, 0.0161], [122369000.0, 0.0026], [122364000.0, 0.0198], [122361000.0, 0.0227], [122351000.0, 0.0819], [122350000.0, 0.0246], [122344000.0, 0.0652], [122340000.0, 0.025], [122335000.0, 0.0003], [122334000.0, 0.0574]], "asks": [[122411000.0, 0.0], [122421000.0, 0.0014], [122437000.0, 0.0], [122443000.0, 0.0], [122445000.0, 0.0036], [122446000.0, 0.0016], [122447000.0, 0.004], [122448000.0, 0.0061], [122450000.0, 0.0016], [122452000.0, 0.079]]},
{"timestamp": "1743771357385", "bids": [[122375000.0, 0.0161], [122369000.0, 0.0026], [122364000.0, 0.0198], [122361000.0, 0.0227], [122351000.0, 0.0819], [122350000.0, 0.0246], [122348000.0, 0.0048], [122344000.0, 0.0652], [122340000.0, 0.0251], [122335000.0, 0.0003]], "asks": [[122411000.0, 0.0], [122421000.0, 0.0014], [122437000.0, 0.0], [122443000.0, 0.0], [122445000.0, 0.0036], [122446000.0, 0.0016], [122447000.0, 0.083], [122448000.0, 0.0061], [122450000.0, 0.0016], [122453000.0, 0.0482]]},
{"timestamp": "1743771357882", "bids": [[122375000.0, 0.0161], [122369000.0, 0.0026], [122365000.0, 0.0819], [122364000.0, 0.0198], [122361000.0, 0.0227], [122350000.0, 0.0246], [122348000.0, 0.0048], [122344000.0, 0.0652], [122341000.0, 0.0225], [122340000.0, 0.0251]], "asks": [[122411000.0, 0.0], [122421000.0, 0.0014], [122437000.0, 0.0], [122443000.0, 0.0], [122445000.0, 0.0036], [122446000.0, 0.0016], [122447000.0, 0.004], [122448000.0, 0.0061], [122450000.0, 0.0016], [122453000.0, 0.0482]]},
{"timestamp": "1743771358386", "bids": [[122376000.0, 0.1563], [122364000.0, 0.0198], [122351000.0, 0.0819], [122341000.0, 0.0225], [122340000.0, 0.0248], [122335000.0, 0.0003], [122334000.0, 0.0323], [122331000.0, 0.0022], [122329000.0, 0.0], [122328000.0, 0.0017]], "asks": [[122411000.0, 0.0], [122421000.0, 0.0014], [122437000.0, 0.0], [122443000.0, 0.0], [122445000.0, 0.0036], [122446000.0, 0.0016], [122447000.0, 0.004], [122448000.0, 0.0061], [122450000.0, 0.0016], [122452000.0, 0.079]]},
{"timestamp": "1743771358883", "bids": [[122376000.0, 0.1563], [122369000.0, 0.0216], [122363000.0, 0.0002], [122362000.0, 0.0819], [122350000.0, 0.0326], [122344000.0, 0.0362], [122343000.0, 0.0258], [122341000.0, 0.0225], [122338000.0, 0.0359], [122335000.0, 0.0003]], "asks": [[122411000.0, 0.0], [122421000.0, 0.0014], [122437000.0, 0.0], [122443000.0, 0.0], [122445000.0, 0.0036], [122446000.0, 0.0016], [122447000.0, 0.004], [122448000.0, 0.0002], [122450000.0, 0.0016], [122452000.0, 0.0173]]},
{"timestamp": "1743771359384", "bids": [[122394000.0, 0.0032], [122391000.0, 0.0161], [122385000.0, 0.0026], [122379000.0, 0.0227], [122377000.0, 0.0016], [122369000.0, 0.0414], [122367000.0, 0.0294], [122363000.0, 0.0091], [122362000.0, 0.0933], [122361000.0, 0.0323]], "asks": [[122411000.0, 0.0], [122421000.0, 0.0014], [122437000.0, 0.0], [122443000.0, 0.0], [122445000.0, 0.0036], [122446000.0, 0.0016], [122447000.0, 0.004], [122448000.0, 0.0002], [122450000.0, 0.0016], [122452000.0, 0.0173]]},
{"timestamp": "1743771359882", "bids": [[122394000.0, 0.0032], [122391000.0, 0.0161], [122385000.0, 0.0026], [122382000.0, 0.0198], [122379000.0, 0.0227], [122377000.0, 0.0297], [122369000.0, 0.0414], [122367000.0, 0.0294], [122364000.0, 0.0248], [122363000.0, 0.0091]], "asks": [[122411000.0, 0.0], [122421000.0, 0.0014], [122437000.0, 0.0], [122443000.0, 0.0], [122445000.0, 0.0036], [122446000.0, 0.0016], [122447000.0, 0.004], [122448000.0, 0.0002], [122450000.0, 0.0016], [122453000.0, 0.0482]]},
{"timestamp": "1743771360385", "bids": [[122385000.0, 0.0026], [122382000.0, 0.0198], [122380000.0, 0.0819], [122377000.0, 0.0059], [122373000.0, 0.0001], [122367000.0, 0.0048], [122364000.0, 0.0248], [122361000.0, 0.0652], [122359000.0, 0.0323], [122343000.0, 0.0264]], "asks": [[122411000.0, 0.0], [122421000.0, 0.0014], [122437000.0, 0.0], [122443000.0, 0.0], [122445000.0, 0.0036], [122446000.0, 0.0016], [122447000.0, 0.004], [122448000.0, 0.0002], [122450000.0, 0.0016], [122453000.0, 0.0482]]},
{"timestamp": "1743771360892", "bids": [[122395000.0, 0.0118], [122383000.0, 0.0819], [122380000.0, 0.0819], [122378000.0, 0.0326], [122373000.0, 0.0001], [122370000.0, 0.0258], [122369000.0, 0.0362], [122367000.0, 0.0048], [122365000.0, 0.0359], [122363000.0, 0.0002]], "asks": [[122411000.0, 0.0], [122421000.0, 0.0014], [122437000.0, 0.0], [122443000.0, 0.0], [122445000.0, 0.0036], [122446000.0, 0.0016], [122447000.0, 0.004], [122448000.0, 0.0002], [122450000.0, 0.0016], [122453000.0, 0.0482]]},
{"timestamp": "1743771361388", "bids": [[122425000.0, 0.0137], [122401000.0, 0.0443], [122400000.0, 0.0246], [122395000.0, 0.0118], [122392000.0, 0.1535], [122389000.0, 0.0002], [122386000.0, 0.0122], [122383000.0, 0.0819], [122381000.0, 0.0225], [122380000.0, 0.0819]], "asks": [[122437000.0, 0.0], [122443000.0, 0.0], [122445000.0, 0.0036], [122446000.0, 0.0016], [122447000.0, 0.004], [122448000.0, 0.0002], [122450000.0, 0.0016], [122453000.0, 0.0482], [122455000.0, 0.0], [122459000.0, 0.0]]},
{"timestamp": "1743771361886", "bids": [[122425000.0, 0.0137], [122405000.0, 0.0198], [122401000.0, 0.0641], [122400000.0, 0.0246], [122395000.0, 0.0232], [122394000.0, 0.0323], [122392000.0, 0.1535], [122389000.0, 0.0002], [122386000.0, 0.0386], [122383000.0, 0.0819]], "asks": [[122437000.0, 0.0], [122443000.0, 0.0], [122445000.0, 0.0036], [122446000.0, 0.0016], [122447000.0, 0.004], [122448000.0, 0.0002], [122450000.0, 0.0016], [122453000.0, 0.0482], [122455000.0, 0.0], [122459000.0, 0.0]]},
{"timestamp": "1743771362412", "bids": [[122427000.0, 0.0032], [122425000.0, 0.0137], [122418000.0, 0.0026], [122406000.0, 0.0819], [122405000.0, 0.0198], [122401000.0, 0.0641], [122400000.0, 0.0246], [122396000.0, 0.0056], [122395000.0, 0.0232], [122394000.0, 0.0652]], "asks": [[122437000.0, 0.0], [122443000.0, 0.0], [122445000.0, 0.0036], [122446000.0, 0.0016], [122447000.0, 0.004], [122448000.0, 0.0002], [122450000.0, 0.0016], [122453000.0, 0.0482], [122455000.0, 0.0], [122459000.0, 0.0]]},
{"timestamp": "1743771362884", "bids": [[122425000.0, 0.0137], [122406000.0, 0.0819], [122405000.0, 0.0198], [122395000.0, 0.0118], [122394000.0, 0.0652], [122389000.0, 0.0251], [122386000.0, 0.0122], [122370000.0, 0.0258], [122341000.0, 0.0225], [122335000.0, 0.0003]], "asks": [[122437000.0, 0.0], [122443000.0, 0.0], [122445000.0, 0.0036], [122446000.0, 0.0016], [122447000.0, 0.004], [122448000.0, 0.0002], [122450000.0, 0.0016], [122453000.0, 0.0482], [122455000.0, 0.0], [122459000.0, 0.0]]},
{"timestamp": "1743771363391", "bids": [[122406000.0, 0.0819], [122395000.0, 0.0118], [122394000.0, 0.0294], [122389000.0, 0.0001], [122386000.0, 0.0122], [122382000.0, 0.0362], [122380000.0, 0.0002], [122378000.0, 0.0251], [122375000.0, 0.0707], [122370000.0, 0.0]], "asks": [[122437000.0, 0.0], [122443000.0, 0.0], [122445000.0, 0.0036], [122446000.0, 0.0016], [122447000.0, 0.004], [122448000.0, 0.0002], [122450000.0, 0.0016], [122453000.0, 0.0482], [122455000.0, 0.0], [122459000.0, 0.0]]},
{"timestamp": "1743771363887", "bids": [[122432000.0, 0.0032], [122407000.0, 0.0198], [122406000.0, 0.1233], [122405000.0, 0.0227], [122403000.0, 0.0026], [122394000.0, 0.0294], [122380000.0, 0.0259], [122377000.0, 0.0522], [122375000.0, 0.1066], [122370000.0, 0.0]], "asks": [[122437000.0, 0.0], [122443000.0, 0.0], [122445000.0, 0.0036], [122446000.0, 0.0016], [122447000.0, 0.004], [122448000.0, 0.0002], [122450000.0, 0.0016], [122453000.0, 0.0482], [122455000.0, 0.0], [122459000.0, 0.0]]},
{"timestamp": "1743771364389", "bids": [[122432000.0, 0.0032], [122425000.0, 0.0024], [122407000.0, 0.0198], [122406000.0, 0.1233], [122402000.0, 0.0138], [122397000.0, 0.0114], [122385000.0, 0.0326], [122380000.0, 0.0257], [122377000.0, 0.0845], [122375000.0, 0.0359]], "asks": [[122437000.0, 0.0], [122443000.0, 0.0], [122445000.0, 0.0036], [122446000.0, 0.0016], [122447000.0, 0.004], [122448000.0, 0.0002], [122450000.0, 0.0016], [122453000.0, 0.0482], [122455000.0, 0.0], [122459000.0, 0.0]]},
{"timestamp": "1743771364892", "bids": [[122425000.0, 0.0024], [122407000.0, 0.0198], [122406000.0, 0.0819], [122402000.0, 0.0138], [122397000.0, 0.0114], [122385000.0, 0.0326], [122377000.0, 0.0845], [122372000.0, 0.0377], [122370000.0, 0.0], [122367000.0, 0.05]], "asks": [[122437000.0, 0.0], [122443000.0, 0.0], [122445000.0, 0.0036], [122446000.0, 0.0016], [122447000.0, 0.004], [122448000.0, 0.0002], [122450000.0, 0.0016], [122453000.0, 0.0482], [122455000.0, 0.0], [122459000.0, 0.0]]},
{"timestamp": "1743771365391", "bids": [[122425000.0, 0.0024], [122397000.0, 0.0114], [122386000.0, 0.0819], [122385000.0, 0.0326], [122377000.0, 0.0323], [122372000.0, 0.0377], [122370000.0, 0.0], [122367000.0, 0.0252], [122362000.0, 0.0227], [122361000.0, 0.0002]], "asks": [[122436000.0, 0.0107], [122437000.0, 0.0], [122443000.0, 0.0], [122445000.0, 0.0036], [122446000.0, 0.0016], [122447000.0, 0.004], [122448000.0, 0.0002], [122450000.0, 0.0016], [122453000.0, 0.0482], [122455000.0, 0.0]]},
{"timestamp": "1743771365886", "bids": [[122425000.0, 0.0024], [122397000.0, 0.0114], [122386000.0, 0.0819], [122385000.0, 0.0326], [122377000.0, 0.0323], [122372000.0, 0.0329], [122370000.0, 0.0], [122369000.0, 0.0138], [122367000.0, 0.045], [122362000.0, 0.0198]], "asks": [[122436000.0, 0.0107], [122437000.0, 0.0], [122442000.0, 0.0082], [122443000.0, 0.0], [122444000.0, 0.0242], [122445000.0, 0.0036], [122446000.0, 0.0184], [122447000.0, 0.004], [122448000.0, 0.0002], [122450000.0, 0.0016]]},
{"timestamp": "1743771366390", "bids": [[122425000.0, 0.0024], [122382000.0, 0.0032], [122370000.0, 0.0], [122369000.0, 0.0138], [122367000.0, 0.0198], [122362000.0, 0.0224], [122358000.0, 0.0107], [122344000.0, 0.0246], [122338000.0, 0.0522], [122335000.0, 0.0003]], "asks": [[122437000.0, 0.0], [122442000.0, 0.0082], [122443000.0, 0.0], [122444000.0, 0.0242], [122445000.0, 0.0036], [122446000.0, 0.0184], [122447000.0, 0.004], [122448000.0, 0.0002], [122450000.0, 0.0016], [122453000.0, 0.0482]]},
{"timestamp": "1743771366888", "bids": [[122425000.0, 0.0024], [122370000.0, 0.0819], [122358000.0, 0.0107], [122351000.0, 0.0227], [122344000.0, 0.0246], [122335000.0, 0.0003], [122333000.0, 0.0247], [122331000.0, 0.0024], [122329000.0, 0.0], [122328000.0, 0.034]], "asks": [[122437000.0, 0.0], [122443000.0, 0.0], [122445000.0, 0.0036], [122446000.0, 0.0016], [122447000.0, 0.004], [122448000.0, 0.0002], [122450000.0, 0.0016], [122452000.0, 0.0166], [122453000.0, 0.0482], [122455000.0, 0.0]]},
{"timestamp": "1743771367388", "bids": [[122425000.0, 0.0024], [122421000.0, 0.001], [122370000.0, 0.0], [122368000.0, 0.0819], [122358000.0, 0.0107], [122353000.0, 0.0026], [122351000.0, 0.0443], [122340000.0, 0.0323], [122335000.0, 0.0003], [122333000.0, 0.0247]], "asks": [[122432000.0, 0.0082], [122434000.0, 0.0173], [122437000.0, 0.0], [122439000.0, 0.0242], [122443000.0, 0.0], [122445000.0, 0.0036], [122446000.0, 0.0016], [122447000.0, 0.004], [122448000.0, 0.0002], [122450000.0, 0.0016]]},
{"timestamp": "1743771367886", "bids": [[122425000.0, 0.0024], [122421000.0, 0.001], [122370000.0, 0.0], [122361000.0, 0.0032], [122359000.0, 0.0819], [122357000.0, 0.0198], [122348000.0, 0.0138], [122346000.0, 0.0198], [122344000.0, 0.0114], [122335000.0, 0.0003]], "asks": [[122431000.0, 0.0168], [122437000.0, 0.0], [122438000.0, 0.0128], [122439000.0, 0.0386], [122443000.0, 0.0148], [122445000.0, 0.0036], [122446000.0, 0.0016], [122447000.0, 0.004], [122448000.0, 0.0002], [122450000.0, 0.0016]]},
{"timestamp": "1743771368398", "bids": [[122378000.0, 0.0], [122370000.0, 0.0], [122361000.0, 0.0032], [122358000.0, 0.0819], [122357000.0, 0.0198], [122348000.0, 0.0138], [122346000.0, 0.0198], [122344000.0, 0.0114], [122343000.0, 0.0048], [122342000.0, 0.0026]], "asks": [[122421000.0, 0.0047], [122431000.0, 0.0218], [122437000.0, 0.0], [122438000.0, 0.0128], [122439000.0, 0.0386], [122440000.0, 0.0126], [122443000.0, 0.0148], [122445000.0, 0.0036], [122446000.0, 0.0016], [122447000.0, 0.004]]},
{"timestamp": "1743771368889", "bids": [[122378000.0, 0.0], [122370000.0, 0.0], [122361000.0, 0.0032], [122358000.0, 0.0819], [122357000.0, 0.0198], [122348000.0, 0.0172], [122346000.0, 0.0198], [122344000.0, 0.0114], [122343000.0, 0.0048], [122342000.0, 0.0026]], "asks": [[122421000.0, 0.0047], [122431000.0, 0.0168], [122437000.0, 0.0], [122438000.0, 0.0128], [122439000.0, 0.0386], [122440000.0, 0.0126], [122443000.0, 0.0148], [122445000.0, 0.0036], [122446000.0, 0.0287], [122447000.0, 0.004]]},
{"timestamp": "1743771369402", "bids": [[122378000.0, 0.0], [122370000.0, 0.0], [122361000.0, 0.0032], [122358000.0, 0.0819], [122357000.0, 0.0198], [122348000.0, 0.0272], [122346000.0, 0.0246], [122344000.0, 0.0114], [122342000.0, 0.0026], [122335000.0, 0.0003]], "asks": [[122421000.0, 0.0047], [122431000.0, 0.0168], [122437000.0, 0.0], [122438000.0, 0.0128], [122439000.0, 0.0386], [122440000.0, 0.0126], [122443000.0, 0.0148], [122445000.0, 0.0036], [122446000.0, 0.0287], [122447000.0, 0.004]]},
{"timestamp": "1743771369892", "bids": [[122378000.0, 0.0], [122370000.0, 0.0], [122361000.0, 0.0032], [122360000.0, 0.0016], [122358000.0, 0.0819], [122357000.0, 0.0198], [122348000.0, 0.0272], [122346000.0, 0.0246], [122344000.0, 0.0114], [122342000.0, 0.0026]], "asks": [[122421000.0, 0.0047], [122431000.0, 0.0168], [122437000.0, 0.0], [122438000.0, 0.0128], [122439000.0, 0.0386], [122440000.0, 0.0126], [122443000.0, 0.0148], [122445000.0, 0.0036], [122446000.0, 0.0287], [122447000.0, 0.004]]},
{"timestamp": "1743771370385", "bids": [[122378000.0, 0.0], [122370000.0, 0.0], [122361000.0, 0.0032], [122360000.0, 0.0016], [122358000.0, 0.0819], [122357000.0, 0.0198], [122348000.0, 0.0272], [122346000.0, 0.0298], [122344000.0, 0.0114], [122342000.0, 0.0026]], "asks": [[122421000.0, 0.0047], [122431000.0, 0.0168], [122437000.0, 0.0], [122438000.0, 0.0128], [122439000.0, 0.0386], [122440000.0, 0.0126], [122443000.0, 0.0148], [122445000.0, 0.0036], [122446000.0, 0.0287], [122447000.0, 0.004]]},
{"timestamp": "1743771370891", "bids": [[122379000.0, 0.1563], [122378000.0, 0.0], [122370000.0, 0.0], [122361000.0, 0.0032], [122360000.0, 0.0016], [122358000.0, 0.0819], [122357000.0, 0.0198], [122348000.0, 0.0238], [122346000.0, 0.0298], [122344000.0, 0.0114]], "asks": [[122421000.0, 0.0047], [122431000.0, 0.0168], [122437000.0, 0.0], [122438000.0, 0.0128], [122439000.0, 0.0242], [122443000.0, 0.0148], [122445000.0, 0.0036], [122446000.0, 0.0016], [122447000.0, 0.004], [122448000.0, 0.0002]]},
{"timestamp": "1743771371391", "bids": [[122379000.0, 0.1563], [122378000.0, 0.0], [122370000.0, 0.0], [122363000.0, 0.0034], [122360000.0, 0.0016], [122350000.0, 0.0443], [122348000.0, 0.01], [122346000.0, 0.01], [122344000.0, 0.0114], [122343000.0, 0.0048]], "asks": [[122437000.0, 0.0], [122443000.0, 0.0], [122445000.0, 0.0036], [122446000.0, 0.0016], [122447000.0, 0.004], [122448000.0, 0.0002], [122450000.0, 0.0016], [122451000.0, 0.015], [122452000.0, 0.0166], [122453000.0, 0.0737]]},
{"timestamp": "1743771372087", "bids": [[122378000.0, 0.0], [122370000.0, 0.0], [122363000.0, 0.0034], [122360000.0, 0.0214], [122350000.0, 0.0414], [122348000.0, 0.0238], [122346000.0, 0.01], [122344000.0, 0.0114], [122342000.0, 0.0026], [122340000.0, 0.0323]], "asks": [[122423000.0, 0.01], [122433000.0, 0.0168], [122437000.0, 0.0], [122438000.0, 0.0128], [122443000.0, 0.0], [122445000.0, 0.0036], [122446000.0, 0.0016], [122447000.0, 0.004], [122448000.0, 0.0002], [122450000.0, 0.0796]]},
{"timestamp": "1743771372390", "bids": [[122378000.0, 0.0], [122370000.0, 0.0], [122363000.0, 0.0034], [122360000.0, 0.0214], [122350000.0, 0.0414], [122348000.0, 0.0238], [122346000.0, 0.01], [122342000.0, 0.0026], [122335000.0, 0.0019], [122333000.0, 0.0]], "asks": [[122411000.0, 0.0048], [122423000.0, 0.01], [122424000.0, 0.0242], [122432000.0, 0.0148], [122433000.0, 0.0168], [122437000.0, 0.0166], [122438000.0, 0.0128], [122443000.0, 0.0], [122445000.0, 0.0036], [122446000.0, 0.0016]]},
{"timestamp": "1743771372892", "bids": [[122378000.0, 0.0], [122374000.0, 0.0032], [122370000.0, 0.0], [122360000.0, 0.0214], [122350000.0, 0.0198], [122348000.0, 0.0238], [122346000.0, 0.01], [122342000.0, 0.0026], [122340000.0, 0.01], [122335000.0, 0.0019]], "asks": [[122409000.0, 0.0173], [122411000.0, 0.0048], [122423000.0, 0.0065], [122424000.0, 0.0242], [122432000.0, 0.0148], [122433000.0, 0.0168], [122435000.0, 0.0754], [122436000.0, 0.0228], [122437000.0, 0.0379], [122438000.0, 0.0353]]},
{"timestamp": "1743771373391", "bids": [[122378000.0, 0.0], [122370000.0, 0.0111], [122360000.0, 0.0016], [122340000.0, 0.01], [122335000.0, 0.0019], [122333000.0, 0.0], [122331000.0, 0.0023], [122329000.0, 0.0], [122328000.0, 0.0017], [122326000.0, 0.0003]], "asks": [[122404000.0, 0.0358], [122405000.0, 0.0171], [122406000.0, 0.0179], [122407000.0, 0.0271], [122409000.0, 0.0173], [122411000.0, 0.0198], [122415000.0, 0.0167], [122417000.0, 0.0141], [122419000.0, 0.0171], [122420000.0, 0.04]]},
{"timestamp": "1743771373891", "bids": [[122378000.0, 0.0], [122370000.0, 0.0111], [122360000.0, 0.0016], [122335000.0, 0.0019], [122333000.0, 0.0], [122331000.0, 0.0023], [122330000.0, 0.0034], [122329000.0, 0.0], [122328000.0, 0.0017], [122326000.0, 0.0003]], "asks": [[122403000.0, 0.005], [122404000.0, 0.0358], [122405000.0, 0.0171], [122406000.0, 0.0179], [122407000.0, 0.0271], [122408000.0, 0.0035], [122411000.0, 0.015], [122415000.0, 0.0167], [122417000.0, 0.0141], [122419000.0, 0.0331]]},
{"timestamp": "1743771374394", "bids": [[122378000.0, 0.0], [122370000.0, 0.0111], [122360000.0, 0.0016], [122335000.0, 0.0019], [122333000.0, 0.0], [122331000.0, 0.0023], [122330000.0, 0.0034], [122329000.0, 0.0198], [122328000.0, 0.0017], [122327000.0, 0.0138]], "asks": [[122402000.0, 0.0168], [122403000.0, 0.005], [122405000.0, 0.0171], [122408000.0, 0.0035], [122417000.0, 0.0128], [122418000.0, 0.078], [122419000.0, 0.016], [122421000.0, 0.0144], [122423000.0, 0.0453], [122424000.0, 0.0168]]},
{"timestamp": "1743771374889", "bids": [[122378000.0, 0.0], [122370000.0, 0.0111], [122360000.0, 0.0016], [122341000.0, 0.0032], [122335000.0, 0.0019], [122333000.0, 0.0], [122331000.0, 0.0023], [122330000.0, 0.0034], [122329000.0, 0.0198], [122328000.0, 0.0017]], "asks": [[122392000.0, 0.0173], [122397000.0, 0.0242], [122401000.0, 0.0048], [122402000.0, 0.0168], [122410000.0, 0.0166], [122417000.0, 0.0128], [122418000.0, 0.078], [122419000.0, 0.0552], [122421000.0, 0.0144], [122422000.0, 0.0148]]},
{"timestamp": "1743771375390", "bids": [[122378000.0, 0.0], [122370000.0, 0.0111], [122360000.0, 0.0016], [122341000.0, 0.0032], [122335000.0, 0.0019], [122333000.0, 0.0], [122331000.0, 0.0023], [122329000.0, 0.0], [122328000.0, 0.0836], [122326000.0, 0.0003]], "asks": [[122392000.0, 0.0173], [122397000.0, 0.0242], [122401000.0, 0.0048], [122409000.0, 0.015], [122410000.0, 0.0166], [122415000.0, 0.0177], [122418000.0, 0.0171], [122419000.0, 0.1025], [122420000.0, 0.0126], [122421000.0, 0.0255]]},
{"timestamp": "1743771375890", "bids": [[122378000.0, 0.0], [122370000.0, 0.0111], [122360000.0, 0.0016], [122341000.0, 0.0032], [122335000.0, 0.0019], [122333000.0, 0.0], [122331000.0, 0.0023], [122329000.0, 0.0], [122328000.0, 0.0836], [122326000.0, 0.0003]], "asks": [[122420000.0, 0.0126], [122421000.0, 0.0181], [122422000.0, 0.0171], [122424000.0, 0.0179], [122430000.0, 0.0164], [122431000.0, 0.033], [122432000.0, 0.0167], [122433000.0, 0.0236], [122434000.0, 0.0475], [122437000.0, 0.0]]},
{"timestamp": "1743771376394", "bids": [[122379000.0, 0.091], [122378000.0, 0.0], [122370000.0, 0.0111], [122360000.0, 0.0016], [122335000.0, 0.0019], [122334000.0, 0.0172], [122333000.0, 0.0198], [122331000.0, 0.0023], [122329000.0, 0.0], [122328000.0, 0.0017]], "asks": [[122402000.0, 0.0168], [122414000.0, 0.078], [122421000.0, 0.0156], [122422000.0, 0.0171], [122424000.0, 0.0307], [122425000.0, 0.0464], [122431000.0, 0.033], [122432000.0, 0.0167], [122433000.0, 0.0222], [122434000.0, 0.0805]]},
{"timestamp": "1743771376891", "bids": [[122379000.0, 0.1782], [122378000.0, 0.0], [122370000.0, 0.0111], [122360000.0, 0.0016], [122341000.0, 0.0245], [122335000.0, 0.0019], [122334000.0, 0.0172], [122333000.0, 0.0198], [122331000.0, 0.0023], [122330000.0, 0.0248]], "asks": [[122402000.0, 0.0168], [122414000.0, 0.1022], [122424000.0, 0.0128], [122425000.0, 0.0464], [122433000.0, 0.0372], [122434000.0, 0.0337], [122435000.0, 0.0239], [122436000.0, 0.0248], [122437000.0, 0.0173], [122438000.0, 0.0255]]},
{"timestamp": "1743771377391", "bids": [[122384000.0, 0.0025], [122380000.0, 0.002], [122379000.0, 0.0058], [122378000.0, 0.0], [122370000.0, 0.0111], [122360000.0, 0.0016], [122359000.0, 0.0026], [122350000.0, 0.0058], [122348000.0, 0.0001], [122341000.0, 0.0245]], "asks": [[122402000.0, 0.0168], [122414000.0, 0.0242], [122425000.0, 0.032], [122433000.0, 0.0372], [122434000.0, 0.0337], [122435000.0, 0.0239], [122436000.0, 0.0248], [122437000.0, 0.0173], [122438000.0, 0.0255], [122439000.0, 0.0048]]},
{"timestamp": "1743771377890", "bids": [[122384000.0, 0.0025], [122380000.0, 0.0027], [122379000.0, 0.0032], [122378000.0, 0.0], [122370000.0, 0.0111], [122360000.0, 0.0232], [122359000.0, 0.0026], [122356000.0, 0.0362], [122350000.0, 0.0058], [122349000.0, 0.0323]], "asks": [[122433000.0, 0.015], [122437000.0, 0.0], [122443000.0, 0.0], [122445000.0, 0.0036], [122446000.0, 0.0016], [122447000.0, 0.004], [122448000.0, 0.0002], [122450000.0, 0.0016], [122453000.0, 0.0482], [122455000.0, 0.0]]},
{"timestamp": "1743771378392", "bids": [[122360000.0, 0.0111], [122356000.0, 0.0362], [122350000.0, 0.0058], [122349000.0, 0.0323], [122342000.0, 0.1149], [122341000.0, 0.0777], [122335000.0, 0.0019], [122333000.0, 0.0], [122331000.0, 0.0023], [122330000.0, 0.0002]], "asks": [[122437000.0, 0.0], [122443000.0, 0.0], [122445000.0, 0.0036], [122446000.0, 0.0016], [122447000.0, 0.004], [122448000.0, 0.0002], [122450000.0, 0.0016], [122452000.0, 0.0048], [122453000.0, 0.0482], [122455000.0, 0.0]]},
{"timestamp": "1743771378892", "bids": [[122378000.0, 0.0001], [122372000.0, 0.0026], [122371000.0, 0.0819], [122360000.0, 0.0111], [122354000.0, 0.0294], [122350000.0, 0.0058], [122349000.0, 0.0323], [122348000.0, 0.0001], [122343000.0, 0.0249], [122342000.0, 0.033]], "asks": [[122437000.0, 0.0], [122443000.0, 0.0], [122445000.0, 0.0036], [122446000.0, 0.0016], [122447000.0, 0.004], [122448000.0, 0.0002], [122450000.0, 0.0016], [122452000.0, 0.0048], [122453000.0, 0.0482], [122455000.0, 0.0]]},
{"timestamp": "1743771379392", "bids": [[122378000.0, 0.0001], [122375000.0, 0.0198], [122364000.0, 0.0227], [122361000.0, 0.0817], [122358000.0, 0.0114], [122354000.0, 0.0293], [122343000.0, 0.0247], [122342000.0, 0.033], [122341000.0, 0.0256], [122339000.0, 0.0362]], "asks": [[122436000.0, 0.0172], [122437000.0, 0.0], [122443000.0, 0.0], [122444000.0, 0.0173], [122445000.0, 0.0036], [122446000.0, 0.0016], [122447000.0, 0.004], [122448000.0, 0.0244], [122450000.0, 0.0016], [122452000.0, 0.0048]]},
{"timestamp": "1743771379890", "bids": [[122395000.0, 0.0025], [122375000.0, 0.0198], [122364000.0, 0.0425], [122358000.0, 0.0114], [122357000.0, 0.0026], [122355000.0, 0.0817], [122354000.0, 0.0048], [122346000.0, 0.0326], [122345000.0, 0.0002], [122339000.0, 0.0362]], "asks": [[122436000.0, 0.0172], [122437000.0, 0.0], [122443000.0, 0.0], [122444000.0, 0.0173], [122445000.0, 0.0036], [122446000.0, 0.0016], [122447000.0, 0.004], [122448000.0, 0.0412], [122450000.0, 0.0016], [122453000.0, 0.0482]]},
{"timestamp": "1743771380396", "bids": [[122395000.0, 0.0025], [122375000.0, 0.0198], [122364000.0, 0.0425], [122363000.0, 0.0001], [122358000.0, 0.0114], [122357000.0, 0.0026], [122355000.0, 0.0817], [122351000.0, 0.0112], [122346000.0, 0.0326], [122345000.0, 0.0002]], "asks": [[122436000.0, 0.022], [122437000.0, 0.0], [122443000.0, 0.0], [122444000.0, 0.0173], [122445000.0, 0.0036], [122446000.0, 0.0016], [122447000.0, 0.004], [122448000.0, 0.0412], [122450000.0, 0.0016], [122453000.0, 0.061]]},
{"timestamp": "1743771380909", "bids": [[122396000.0, 0.1563], [122395000.0, 0.0025], [122378000.0, 0.0007], [122375000.0, 0.0198], [122365000.0, 0.0817], [122364000.0, 0.0425], [122363000.0, 0.0001], [122358000.0, 0.0114], [122357000.0, 0.0026], [122351000.0, 0.0112]], "asks": [[122436000.0, 0.0172], [122437000.0, 0.0], [122443000.0, 0.0], [122444000.0, 0.0173], [122445000.0, 0.0036], [122446000.0, 0.0016], [122447000.0, 0.004], [122448000.0, 0.0412], [122450000.0, 0.0016], [122453000.0, 0.061]]},
{"timestamp": "1743771381392", "bids": [[122396000.0, 0.1563], [122395000.0, 0.0025], [122378000.0, 0.0007], [122376000.0, 0.0817], [122367000.0, 0.0122], [122357000.0, 0.0026], [122346000.0, 0.0326], [122345000.0, 0.0002], [122341000.0, 0.0225], [122340000.0, 0.0323]], "asks": [[122436000.0, 0.0172], [122437000.0, 0.0], [122443000.0, 0.0], [122445000.0, 0.0036], [122446000.0, 0.0016], [122447000.0, 0.004], [122448000.0, 0.0002], [122450000.0, 0.0016], [122453000.0, 0.0482], [122454000.0, 0.0144]]},
{"timestamp": "1743771381890", "bids": [[122397000.0, 0.0001], [122396000.0, 0.0982], [122378000.0, 0.0007], [122376000.0, 0.0817], [122367000.0, 0.0122], [122363000.0, 0.0251], [122345000.0, 0.0002], [122341000.0, 0.0225], [122338000.0, 0.0172], [122336000.0, 0.0001]], "asks": [[122437000.0, 0.0], [122443000.0, 0.0], [122445000.0, 0.0036], [122446000.0, 0.0016], [122447000.0, 0.004], [122448000.0, 0.0002], [122450000.0, 0.0016], [122453000.0, 0.0482], [122455000.0, 0.0], [122459000.0, 0.0]]},
{"timestamp": "1743771382395", "bids": [[122403000.0, 0.0001], [122397000.0, 0.0843], [122391000.0, 0.0206], [122379000.0, 0.0246], [122378000.0, 0.0007], [122373000.0, 0.0329], [122368000.0, 0.0248], [122367000.0, 0.0484], [122363000.0, 0.0251], [122360000.0, 0.0706]], "asks": [[122435000.0, 0.0048], [122437000.0, 0.0], [122443000.0, 0.0], [122445000.0, 0.0036], [122446000.0, 0.0016], [122447000.0, 0.004], [122448000.0, 0.0002], [122450000.0, 0.0016], [122453000.0, 0.0482], [122455000.0, 0.0]]},
{"timestamp": "1743771382890", "bids": [[122403000.0, 0.0001], [122397000.0, 0.0026], [122391000.0, 0.0328], [122380000.0, 0.0817], [122379000.0, 0.0246], [122378000.0, 0.0007], [122375000.0, 0.0048], [122373000.0, 0.0329], [122368000.0, 0.025], [122367000.0, 0.0362]], "asks": [[122435000.0, 0.0048], [122437000.0, 0.0], [122443000.0, 0.0], [122445000.0, 0.0036], [122446000.0, 0.0016], [122447000.0, 0.004], [122448000.0, 0.0002], [122450000.0, 0.0016], [122453000.0, 0.0482], [122455000.0, 0.0]]},
{"timestamp": "1743771383397", "bids": [[122403000.0, 0.0001], [122397000.0, 0.0026], [122392000.0, 0.0817], [122391000.0, 0.0328], [122379000.0, 0.0246], [122378000.0, 0.0007], [122375000.0, 0.0048], [122373000.0, 0.0329], [122368000.0, 0.0251], [122367000.0, 0.0362]], "asks": [[122435000.0, 0.0048], [122437000.0, 0.0], [122443000.0, 0.0], [122445000.0, 0.0036], [122446000.0, 0.0016], [122447000.0, 0.004], [122448000.0, 0.0002], [122450000.0, 0.0016], [122453000.0, 0.0482], [122455000.0, 0.0]]},
{"timestamp": "1743771383894", "bids": [[122403000.0, 0.0001], [122397000.0, 0.0026], [122391000.0, 0.0328], [122380000.0, 0.0817], [122379000.0, 0.0246], [122378000.0, 0.0007], [122375000.0, 0.0048], [122373000.0, 0.0329], [122368000.0, 0.0251], [122367000.0, 0.0362]], "asks": [[122435000.0, 0.0048], [122437000.0, 0.0], [122443000.0, 0.0], [122445000.0, 0.0036], [122446000.0, 0.0016], [122447000.0, 0.004], [122448000.0, 0.0002], [122450000.0, 0.0016], [122453000.0, 0.0482], [122455000.0, 0.0]]},
{"timestamp": "1743771384395", "bids": [[122420000.0, 0.0], [122403000.0, 0.0001], [122397000.0, 0.0026], [122392000.0, 0.0817], [122391000.0, 0.0328], [122379000.0, 0.0246], [122378000.0, 0.0007], [122375000.0, 0.0048], [122373000.0, 0.0329], [122368000.0, 0.0251]], "asks": [[122435000.0, 0.0048], [122437000.0, 0.0], [122443000.0, 0.0], [122445000.0, 0.0036], [122446000.0, 0.0016], [122447000.0, 0.004], [122448000.0, 0.0002], [122450000.0, 0.0016], [122453000.0, 0.0482], [122455000.0, 0.0]]},
{"timestamp": "1743771384892", "bids": [[122420000.0, 0.0], [122403000.0, 0.0001], [122397000.0, 0.0026], [122391000.0, 0.0328], [122380000.0, 0.0817], [122379000.0, 0.0246], [122378000.0, 0.0007], [122373000.0, 0.0329], [122369000.0, 0.0048], [122368000.0, 0.0251]], "asks": [[122435000.0, 0.0048], [122437000.0, 0.0], [122443000.0, 0.0], [122445000.0, 0.0036], [122446000.0, 0.0016], [122447000.0, 0.004], [122448000.0, 0.0002], [122450000.0, 0.0016], [122453000.0, 0.0482], [122455000.0, 0.0]]},
{"timestamp": "1743771385395", "bids": [[122420000.0, 0.0], [122403000.0, 0.0001], [122397000.0, 0.0026], [122391000.0, 0.0328], [122379000.0, 0.0246], [122378000.0, 0.0007], [122373000.0, 0.0329], [122369000.0, 0.0048], [122368000.0, 0.0251], [122367000.0, 0.0362]], "asks": [[122435000.0, 0.0048], [122437000.0, 0.0], [122443000.0, 0.0], [122445000.0, 0.0036], [122446000.0, 0.0016], [122447000.0, 0.004], [122448000.0, 0.0002], [122450000.0, 0.0016], [122453000.0, 0.0482], [122455000.0, 0.0]]},
{"timestamp": "1743771385893", "bids": [[122420000.0, 0.0], [122403000.0, 0.0001], [122391000.0, 0.0216], [122378000.0, 0.0007], [122368000.0, 0.0251], [122363000.0, 0.0251], [122360000.0, 0.0024], [122341000.0, 0.0225], [122336000.0, 0.0001], [122335000.0, 0.0019]], "asks": [[122435000.0, 0.0048], [122437000.0, 0.0], [122443000.0, 0.0], [122445000.0, 0.0036], [122446000.0, 0.0016], [122447000.0, 0.004], [122448000.0, 0.0002], [122450000.0, 0.0016], [122453000.0, 0.0482], [122455000.0, 0.0]]},
{"timestamp": "1743771386400", "bids": [[122420000.0, 0.0], [122411000.0, 0.0025], [122403000.0, 0.0001], [122392000.0, 0.1015], [122391000.0, 0.0216], [122381000.0, 0.0425], [122378000.0, 0.0007], [122375000.0, 0.0114], [122370000.0, 0.0323], [122368000.0, 0.025]], "asks": [[122435000.0, 0.0048], [122437000.0, 0.0], [122443000.0, 0.0], [122445000.0, 0.0036], [122446000.0, 0.0016], [122447000.0, 0.004], [122448000.0, 0.0002], [122450000.0, 0.0016], [122453000.0, 0.0482], [122455000.0, 0.0]]},
{"timestamp": "1743771386894", "bids": [[122420000.0, 0.0], [122411000.0, 0.0025], [122392000.0, 0.1015], [122387000.0, 0.0026], [122381000.0, 0.0425], [122380000.0, 0.0817], [122378000.0, 0.0007], [122375000.0, 0.0114], [122370000.0, 0.0323], [122368000.0, 0.0246]], "asks": [[122435000.0, 0.0048], [122437000.0, 0.0], [122443000.0, 0.0], [122445000.0, 0.0036], [122446000.0, 0.0016], [122447000.0, 0.004], [122448000.0, 0.0002], [122450000.0, 0.0016], [122453000.0, 0.0482], [122455000.0, 0.0]]},
{"timestamp": "1743771387398", "bids": [[122420000.0, 0.0], [122411000.0, 0.0025], [122393000.0, 0.0001], [122392000.0, 0.0198], [122387000.0, 0.0026], [122382000.0, 0.0817], [122381000.0, 0.0425], [122378000.0, 0.0007], [122375000.0, 0.0122], [122370000.0, 0.0323]], "asks": [[122435000.0, 0.0048], [122437000.0, 0.0], [122443000.0, 0.0], [122445000.0, 0.0036], [122446000.0, 0.0016], [122447000.0, 0.004], [122448000.0, 0.0002], [122450000.0, 0.0016], [122453000.0, 0.0482], [122455000.0, 0.0]]},
{"timestamp": "1743771387893", "bids": [[122420000.0, 0.0], [122411000.0, 0.0025], [122393000.0, 0.0001], [122392000.0, 0.0198], [122387000.0, 0.0026], [122382000.0, 0.0817], [122381000.0, 0.0425], [122378000.0, 0.0007], [122375000.0, 0.0122], [122370000.0, 0.0323]], "asks": [[122435000.0, 0.0048], [122437000.0, 0.0], [122443000.0, 0.0], [122445000.0, 0.0036], [122446000.0, 0.0016], [122447000.0, 0.004], [122448000.0, 0.0002], [122450000.0, 0.0016], [122453000.0, 0.0482], [122455000.0, 0.0]]},
{"timestamp": "1743771388455", "bids": [[122420000.0, 0.0], [122411000.0, 0.0025], [122393000.0, 0.0818], [122392000.0, 0.0198], [122387000.0, 0.0026], [122381000.0, 0.0425], [122378000.0, 0.0007], [122375000.0, 0.0122], [122370000.0, 0.0323], [122368000.0, 0.0246]], "asks": [[122435000.0, 0.0048], [122437000.0, 0.0], [122443000.0, 0.0], [122445000.0, 0.0036], [122446000.0, 0.0016], [122447000.0, 0.004], [122448000.0, 0.0002], [122450000.0, 0.0016], [122453000.0, 0.0482], [122455000.0, 0.0]]},
{"timestamp": "1743771388895", "bids": [[122420000.0, 0.0], [122411000.0, 0.0025], [122403000.0, 0.0001], [122393000.0, 0.0818], [122392000.0, 0.0198], [122387000.0, 0.0026], [122381000.0, 0.0425], [122378000.0, 0.0007], [122375000.0, 0.0122], [122370000.0, 0.0323]], "asks": [[122435000.0, 0.0048], [122437000.0, 0.0], [122443000.0, 0.0], [122445000.0, 0.0036], [122446000.0, 0.0016], [122447000.0, 0.004], [122448000.0, 0.0002], [122450000.0, 0.0016], [122453000.0, 0.0482], [122455000.0, 0.0]]},
{"timestamp": "1743771389400", "bids": [[122422000.0, 0.0191], [122421000.0, 0.1563], [122420000.0, 0.0], [122411000.0, 0.0025], [122403000.0, 0.0001], [122393000.0, 0.0001], [122392000.0, 0.0198], [122387000.0, 0.0026], [122382000.0, 0.0817], [122381000.0, 0.0425]], "asks": [[122435000.0, 0.0048], [122437000.0, 0.0], [122443000.0, 0.0], [122445000.0, 0.0036], [122446000.0, 0.0016], [122447000.0, 0.004], [122448000.0, 0.0002], [122450000.0, 0.0016], [122453000.0, 0.0482], [122455000.0, 0.0]]},
{"timestamp": "1743771389894", "bids": [[122422000.0, 0.0191], [122421000.0, 0.1563], [122420000.0, 0.0], [122411000.0, 0.0025], [122403000.0, 0.0081], [122387000.0, 0.0026], [122382000.0, 0.0817], [122379000.0, 0.0225], [122378000.0, 0.0007], [122377000.0, 0.0048]], "asks": [[122435000.0, 0.0048], [122437000.0, 0.0], [122443000.0, 0.0], [122445000.0, 0.0036], [122446000.0, 0.0016], [122447000.0, 0.004], [122448000.0, 0.0002], [122450000.0, 0.0016], [122453000.0, 0.0482], [122455000.0, 0.0]]},
{"timestamp": "1743771390397", "bids": [[122422000.0, 0.0191], [122421000.0, 0.0501], [122420000.0, 0.0], [122403000.0, 0.0081], [122393000.0, 0.0817], [122379000.0, 0.0225], [122378000.0, 0.0007], [122377000.0, 0.0048], [122375000.0, 0.0008], [122360000.0, 0.0024]], "asks": [[122435000.0, 0.0048], [122437000.0, 0.0], [122443000.0, 0.0], [122445000.0, 0.0036], [122446000.0, 0.0016], [122447000.0, 0.004], [122448000.0, 0.0002], [122450000.0, 0.0016], [122453000.0, 0.0482], [122455000.0, 0.0]]},
{"timestamp": "1743771390896", "bids": [[122425000.0, 0.0001], [122423000.0, 0.0132], [122420000.0, 0.0], [122412000.0, 0.0425], [122406000.0, 0.0114], [122403000.0, 0.0081], [122400000.0, 0.0246], [122394000.0, 0.0584], [122393000.0, 0.0817], [122391000.0, 0.0112]], "asks": [[122435000.0, 0.0048], [122437000.0, 0.0], [122443000.0, 0.0], [122445000.0, 0.0036], [122446000.0, 0.0016], [122447000.0, 0.004], [122448000.0, 0.0002], [122450000.0, 0.0016], [122453000.0, 0.0482], [122455000.0, 0.0]]},
{"timestamp": "1743771391399", "bids": [[122425000.0, 0.0001], [122424000.0, 0.0181], [122423000.0, 0.0368], [122420000.0, 0.0], [122415000.0, 0.0198], [122412000.0, 0.0425], [122406000.0, 0.0114], [122403000.0, 0.0081], [122400000.0, 0.0246], [122395000.0, 0.0002]], "asks": [[122435000.0, 0.0048], [122437000.0, 0.0], [122443000.0, 0.0], [122445000.0, 0.0036], [122446000.0, 0.0016], [122447000.0, 0.004], [122448000.0, 0.0002], [122450000.0, 0.0016], [122453000.0, 0.0482], [122455000.0, 0.0]]},
{"timestamp": "1743771391898", "bids": [[122425000.0, 0.0001], [122424000.0, 0.0181], [122423000.0, 0.0118], [122420000.0, 0.0], [122417000.0, 0.0112], [122415000.0, 0.0198], [122412000.0, 0.0425], [122406000.0, 0.0114], [122403000.0, 0.0081], [122402000.0, 0.0]], "asks": [[122435000.0, 0.0023], [122437000.0, 0.0], [122443000.0, 0.0], [122445000.0, 0.0036], [122446000.0, 0.0016], [122447000.0, 0.004], [122448000.0, 0.0002], [122450000.0, 0.0016], [122453000.0, 0.0482], [122455000.0, 0.0]]},
{"timestamp": "1743771392395", "bids": [[122424000.0, 0.0026], [122423000.0, 0.0112], [122420000.0, 0.0], [122418000.0, 0.0225], [122417000.0, 0.0112], [122415000.0, 0.0198], [122412000.0, 0.0425], [122407000.0, 0.0817], [122406000.0, 0.0114], [122405000.0, 0.0245]], "asks": [[122435000.0, 0.0023], [122437000.0, 0.0], [122443000.0, 0.0], [122445000.0, 0.0036], [122446000.0, 0.0016], [122447000.0, 0.004], [122448000.0, 0.0002], [122450000.0, 0.0016], [122453000.0, 0.0482], [122455000.0, 0.0]]},
{"timestamp": "1743771392895", "bids": [[122437000.0, 1.6643], [122425000.0, 0.1518], [122424000.0, 0.0026], [122423000.0, 0.0228], [122420000.0, 0.0], [122418000.0, 0.0225], [122415000.0, 0.0198], [122413000.0, 0.0817], [122403000.0, 0.0081], [122402000.0, 0.025]], "asks": [[122445000.0, 0.0031], [122446000.0, 0.0016], [122447000.0, 0.004], [122448000.0, 0.0002], [122450000.0, 0.0016], [122453000.0, 0.0482], [122455000.0, 0.0], [122459000.0, 0.0], [122460000.0, 0.0004], [122463000.0, 0.0016]]},
{"timestamp": "1743771393398", "bids": [[122430000.0, 0.0001], [122425000.0, 0.1518], [122424000.0, 0.0026], [122423000.0, 0.0228], [122420000.0, 0.0], [122418000.0, 0.0225], [122413000.0, 0.0817], [122411000.0, 0.0323], [122403000.0, 0.0596], [122402000.0, 0.025]], "asks": [[122445000.0, 0.003], [122446000.0, 0.0016], [122447000.0, 0.004], [122448000.0, 0.0002], [122450000.0, 0.0016], [122453000.0, 0.0482], [122455000.0, 0.0], [122459000.0, 0.0], [122460000.0, 0.0004], [122463000.0, 0.0016]]},
{"timestamp": "1743771393899", "bids": [[122447000.0, 0.011], [122442000.0, 0.0226], [122440000.0, 0.0112], [122438000.0, 0.0817], [122430000.0, 0.0001], [122429000.0, 0.0114], [122428000.0, 0.0245], [122423000.0, 0.0112], [122422000.0, 0.0654], [122420000.0, 0.0]], "asks": [[122448000.0, 0.0002], [122450000.0, 0.0016], [122453000.0, 0.0482], [122455000.0, 0.0], [122459000.0, 0.0], [122460000.0, 0.0004], [122463000.0, 0.0016], [122468000.0, 0.002], [122470000.0, 0.0], [122471000.0, 0.0016]]},
{"timestamp": "1743771394400", "bids": [[122447000.0, 0.011], [122443000.0, 0.0006], [122440000.0, 0.0112], [122438000.0, 0.0817], [122429000.0, 0.0114], [122428000.0, 0.0245], [122427000.0, 0.0198], [122423000.0, 0.0112], [122422000.0, 0.0654], [122420000.0, 0.0]], "asks": [[122448000.0, 0.0002], [122450000.0, 0.0016], [122453000.0, 0.0482], [122455000.0, 0.0], [122459000.0, 0.0], [122460000.0, 0.0004], [122463000.0, 0.0016], [122468000.0, 0.002], [122470000.0, 0.0], [122471000.0, 0.0016]]},
{"timestamp": "1743771394902", "bids": [[122443000.0, 0.0006], [122430000.0, 0.0026], [122423000.0, 0.0112], [122422000.0, 0.0325], [122420000.0, 0.0], [122416000.0, 0.0225], [122412000.0, 0.0818], [122409000.0, 0.0358], [122403000.0, 0.0001], [122402000.0, 0.0]], "asks": [[122448000.0, 0.0002], [122450000.0, 0.0016], [122453000.0, 0.0482], [122455000.0, 0.0], [122459000.0, 0.0], [122460000.0, 0.0004], [122463000.0, 0.0016], [122468000.0, 0.002], [122470000.0, 0.0], [122471000.0, 0.0016]]},
{"timestamp": "1743771395405", "bids": [[122443000.0, 0.0006], [122430000.0, 0.0026], [122423000.0, 0.0112], [122422000.0, 0.0325], [122420000.0, 0.0], [122417000.0, 0.0817], [122416000.0, 0.0225], [122412000.0, 0.0246], [122409000.0, 0.0358], [122403000.0, 0.0001]], "asks": [[122448000.0, 0.0002], [122450000.0, 0.0016], [122453000.0, 0.0482], [122455000.0, 0.0], [122459000.0, 0.0], [122460000.0, 0.0004], [122463000.0, 0.0016], [122468000.0, 0.002], [122470000.0, 0.0], [122471000.0, 0.0016]]},
{"timestamp": "1743771395899", "bids": [[122444000.0, 0.1562], [122443000.0, 0.0006], [122430000.0, 0.0026], [122425000.0, 0.003], [122423000.0, 0.0112], [122422000.0, 0.0325], [122420000.0, 0.0], [122417000.0, 0.0817], [122416000.0, 0.0225], [122412000.0, 0.0246]], "asks": [[122448000.0, 0.0002], [122450000.0, 0.0016], [122453000.0, 0.0482], [122455000.0, 0.0], [122459000.0, 0.0], [122460000.0, 0.0004], [122463000.0, 0.0016], [122468000.0, 0.002], [122470000.0, 0.0], [122471000.0, 0.0016]]},
{"timestamp": "1743771396399", "bids": [[122443000.0, 0.0006], [122430000.0, 0.0026], [122425000.0, 0.003], [122423000.0, 0.0112], [122422000.0, 0.0325], [122420000.0, 0.0], [122416000.0, 0.0225], [122412000.0, 0.0246], [122409000.0, 0.0358], [122403000.0, 0.0001]], "asks": [[122448000.0, 0.0002], [122450000.0, 0.0016], [122453000.0, 0.0482], [122455000.0, 0.0], [122459000.0, 0.0], [122460000.0, 0.0004], [122463000.0, 0.0016], [122468000.0, 0.002], [122470000.0, 0.0], [122471000.0, 0.0016]]},
{"timestamp": "1743771396899", "bids": [[122443000.0, 0.0006], [122430000.0, 0.0026], [122425000.0, 0.003], [122423000.0, 0.0112], [122422000.0, 0.0325], [122420000.0, 0.0], [122416000.0, 0.0225], [122412000.0, 0.0246], [122409000.0, 0.0358], [122403000.0, 0.0001]], "asks": [[122448000.0, 0.0002], [122450000.0, 0.0016], [122453000.0, 0.0482], [122455000.0, 0.0], [122459000.0, 0.0], [122460000.0, 0.0004], [122463000.0, 0.0016], [122468000.0, 0.002], [122470000.0, 0.0], [122471000.0, 0.0016]]},
{"timestamp": "1743771398629", "bids": [[122443000.0, 0.0006], [122430000.0, 0.0026], [122425000.0, 0.003], [122424000.0, 0.0817], [122423000.0, 0.0112], [122422000.0, 0.0325], [122421000.0, 0.0415], [122420000.0, 0.0], [122412000.0, 0.0246], [122409000.0, 0.0358]], "asks": [[122448000.0, 0.0], [122450000.0, 0.0016], [122453000.0, 0.0482], [122455000.0, 0.0], [122459000.0, 0.0], [122460000.0, 0.0004], [122463000.0, 0.0016], [122468000.0, 0.002], [122470000.0, 0.0], [122471000.0, 0.0016]]},
{"timestamp": "1743771399130", "bids": [[122443000.0, 0.0006], [122425000.0, 0.003], [122423000.0, 0.0929], [122422000.0, 0.0325], [122421000.0, 0.0415], [122420000.0, 0.0], [122403000.0, 0.0001], [122402000.0, 0.0], [122401000.0, 0.0251], [122397000.0, 0.0323]], "asks": [[122447000.0, 0.0005], [122448000.0, 0.0], [122450000.0, 0.0016], [122453000.0, 0.0482], [122455000.0, 0.0], [122459000.0, 0.0], [122460000.0, 0.0004], [122463000.0, 0.0016], [122468000.0, 0.002], [122470000.0, 0.0]]},
{"timestamp": "1743771399644", "bids": [[122443000.0, 0.0006], [122425000.0, 0.003], [122423000.0, 0.0112], [122421000.0, 0.0839], [122420000.0, 0.0], [122413000.0, 0.0817], [122403000.0, 0.0522], [122402000.0, 0.0], [122401000.0, 0.025], [122397000.0, 0.0362]], "asks": [[122447000.0, 0.0005], [122448000.0, 0.0], [122450000.0, 0.0016], [122453000.0, 0.0482], [122455000.0, 0.0], [122459000.0, 0.0], [122460000.0, 0.0004], [122463000.0, 0.0016], [122468000.0, 0.002], [122470000.0, 0.0]]},
{"timestamp": "1743771400133", "bids": [[122443000.0, 0.0006], [122432000.0, 0.0094], [122425000.0, 0.003], [122423000.0, 0.0112], [122421000.0, 0.0725], [122420000.0, 0.0], [122419000.0, 0.0026], [122415000.0, 0.0114], [122411000.0, 0.0323], [122406000.0, 0.0245]], "asks": [[122447000.0, 0.0005], [122448000.0, 0.0], [122450000.0, 0.0016], [122453000.0, 0.0482], [122455000.0, 0.0], [122459000.0, 0.0], [122460000.0, 0.0004], [122463000.0, 0.0016], [122468000.0, 0.002], [122470000.0, 0.0]]},
{"timestamp": "1743771400626", "bids": [[122443000.0, 0.0006], [122425000.0, 0.003], [122423000.0, 0.0112], [122421000.0, 0.0527], [122420000.0, 0.0], [122403000.0, 0.0001], [122402000.0, 0.0817], [122400000.0, 0.0001], [122394000.0, 0.0326], [122390000.0, 0.0001]], "asks": [[122447000.0, 0.0004], [122448000.0, 0.0], [122450000.0, 0.0016], [122453000.0, 0.0482], [122455000.0, 0.0], [122459000.0, 0.0], [122460000.0, 0.0004], [122463000.0, 0.0016], [122468000.0, 0.002], [122470000.0, 0.0]]},
{"timestamp": "1743771401135", "bids": [[122443000.0, 0.0006], [122425000.0, 0.003], [122423000.0, 0.0112], [122421000.0, 0.0415], [122420000.0, 0.0], [122413000.0, 0.0026], [122407000.0, 0.0198], [122403000.0, 0.0001], [122402000.0, 0.0], [122395000.0, 0.0817]], "asks": [[122447000.0, 0.0004], [122448000.0, 0.0], [122450000.0, 0.0016], [122453000.0, 0.0482], [122455000.0, 0.0], [122459000.0, 0.0], [122460000.0, 0.0004], [122463000.0, 0.0016], [122468000.0, 0.002], [122470000.0, 0.0]]},
{"timestamp": "1743771401643", "bids": [[122444000.0, 0.1562], [122443000.0, 0.0006], [122425000.0, 0.003], [122423000.0, 0.0112], [122421000.0, 0.0415], [122420000.0, 0.0], [122417000.0, 0.0094], [122416000.0, 0.0225], [122413000.0, 0.0026], [122408000.0, 0.0817]], "asks": [[122447000.0, 0.0004], [122448000.0, 0.0], [122450000.0, 0.0016], [122453000.0, 0.0482], [122455000.0, 0.0], [122459000.0, 0.0], [122460000.0, 0.0004], [122463000.0, 0.0016], [122468000.0, 0.002], [122470000.0, 0.0]]},
{"timestamp": "1743771402132", "bids": [[122445000.0, 0.0191], [122444000.0, 0.1562], [122443000.0, 0.0006], [122425000.0, 0.003], [122424000.0, 0.0817], [122423000.0, 0.0112], [122421000.0, 0.0415], [122420000.0, 0.0], [122418000.0, 0.0116], [122416000.0, 0.0225]], "asks": [[122447000.0, 0.0004], [122448000.0, 0.0], [122450000.0, 0.0016], [122453000.0, 0.0482], [122455000.0, 0.0], [122459000.0, 0.0], [122460000.0, 0.0004], [122463000.0, 0.0016], [122468000.0, 0.002], [122470000.0, 0.0]]},
{"timestamp": "1743771402631", "bids": [[122445000.0, 0.0191], [122443000.0, 0.0006], [122425000.0, 0.003], [122424000.0, 0.0817], [122423000.0, 0.0112], [122421000.0, 0.0415], [122420000.0, 0.0], [122418000.0, 0.0228], [122416000.0, 0.0225], [122412000.0, 0.034]], "asks": [[122447000.0, 0.0004], [122448000.0, 0.0], [122450000.0, 0.0016], [122453000.0, 0.0482], [122455000.0, 0.0], [122459000.0, 0.0], [122460000.0, 0.0004], [122463000.0, 0.0016], [122468000.0, 0.002], [122470000.0, 0.0]]},
{"timestamp": "1743771403128", "bids": [[122443000.0, 0.0006], [122435000.0, 0.0094], [122430000.0, 0.0026], [122429000.0, 0.0048], [122425000.0, 0.003], [122424000.0, 0.0198], [122423000.0, 0.0112], [122421000.0, 0.0415], [122420000.0, 0.0], [122418000.0, 0.0228]], "asks": [[122447000.0, 0.0002], [122448000.0, 0.0], [122450000.0, 0.0016], [122453000.0, 0.0482], [122455000.0, 0.0], [122459000.0, 0.0], [122460000.0, 0.0004], [122463000.0, 0.0016], [122468000.0, 0.002], [122470000.0, 0.0]]},
{"timestamp": "1743771403636", "bids": [[122443000.0, 0.0006], [122435000.0, 0.0094], [122430000.0, 0.0026], [122429000.0, 0.0048], [122425000.0, 0.003], [122424000.0, 0.0198], [122423000.0, 0.0112], [122422000.0, 0.0817], [122421000.0, 0.0415], [122420000.0, 0.0]], "asks": [[122447000.0, 0.0002], [122448000.0, 0.0], [122450000.0, 0.0016], [122453000.0, 0.0482], [122455000.0, 0.0], [122459000.0, 0.0], [122460000.0, 0.0004], [122463000.0, 0.0016], [122468000.0, 0.002], [122470000.0, 0.0]]},
{"timestamp": "1743771404131", "bids": [[122443000.0, 0.0006], [122435000.0, 0.0094], [122430000.0, 0.0026], [122429000.0, 0.0048], [122425000.0, 0.0847], [122424000.0, 0.0198], [122423000.0, 0.0112], [122421000.0, 0.0415], [122420000.0, 0.0], [122418000.0, 0.0228]], "asks": [[122447000.0, 0.0002], [122448000.0, 0.0], [122450000.0, 0.0016], [122453000.0, 0.0482], [122455000.0, 0.0], [122459000.0, 0.0], [122460000.0, 0.0004], [122463000.0, 0.0016], [122468000.0, 0.002], [122470000.0, 0.0]]},
{"timestamp": "1743771404632", "bids": [[122443000.0, 0.0006], [122435000.0, 0.0094], [122430000.0, 0.0026], [122429000.0, 0.0048], [122425000.0, 0.0847], [122424000.0, 0.0198], [122423000.0, 0.0112], [122421000.0, 0.0415], [122420000.0, 0.0], [122418000.0, 0.0228]], "asks": [[122447000.0, 0.0002], [122448000.0, 0.0], [122450000.0, 0.0016], [122453000.0, 0.0482], [122455000.0, 0.0], [122459000.0, 0.0], [122460000.0, 0.0004], [122463000.0, 0.0016], [122468000.0, 0.002], [122470000.0, 0.0]]},
{"timestamp": "1743771405128", "bids": [[122443000.0, 0.0006], [122435000.0, 0.0094], [122430000.0, 0.0026], [122429000.0, 0.0048], [122425000.0, 0.0847], [122424000.0, 0.0198], [122423000.0, 0.0112], [122421000.0, 0.0415], [122420000.0, 0.0], [122418000.0, 0.0228]], "asks": [[122447000.0, 0.0002], [122448000.0, 0.0], [122450000.0, 0.0016], [122453000.0, 0.0482], [122455000.0, 0.0], [122459000.0, 0.0], [122460000.0, 0.0004], [122463000.0, 0.0016], [122468000.0, 0.002], [122470000.0, 0.0]]},
{"timestamp": "1743771405632", "bids": [[122443000.0, 0.0006], [122435000.0, 0.0094], [122430000.0, 0.0026], [122429000.0, 0.0048], [122425000.0, 0.0847], [122424000.0, 0.0198], [122423000.0, 0.0112], [122421000.0, 0.0415], [122420000.0, 0.0], [122418000.0, 0.0228]], "asks": [[122447000.0, 0.0002], [122448000.0, 0.0], [122450000.0, 0.0016], [122453000.0, 0.0482], [122455000.0, 0.0], [122459000.0, 0.0], [122460000.0, 0.0004], [122463000.0, 0.0016], [122468000.0, 0.002], [122470000.0, 0.0]]},
{"timestamp": "1743771406132", "bids": [[122444000.0, 0.1404], [122443000.0, 0.0006], [122435000.0, 0.0094], [122430000.0, 0.0026], [122429000.0, 0.0048], [122426000.0, 0.0817], [122425000.0, 0.003], [122424000.0, 0.0198], [122423000.0, 0.0112], [122421000.0, 0.0415]], "asks": [[122447000.0, 0.0002], [122448000.0, 0.0], [122450000.0, 0.0016], [122453000.0, 0.0482], [122455000.0, 0.0], [122459000.0, 0.0], [122460000.0, 0.0004], [122463000.0, 0.0016], [122468000.0, 0.002], [122470000.0, 0.0]]},
{"timestamp": "1743771406633", "bids": [[122455000.0, 1.6141], [122445000.0, 0.0113], [122444000.0, 0.1404], [122443000.0, 0.0006], [122435000.0, 0.0094], [122429000.0, 0.0048], [122426000.0, 0.0817], [122425000.0, 0.003], [122423000.0, 0.0112], [122421000.0, 0.0415]], "asks": [[122459000.0, 0.0], [122460000.0, 0.0004], [122463000.0, 0.0016], [122468000.0, 0.002], [122470000.0, 0.0], [122471000.0, 0.0016], [122472000.0, 0.0045], [122473000.0, 0.0001], [122474000.0, 0.0], [122475000.0, 0.0]]},
{"timestamp": "1743771407134", "bids": [[122445000.0, 0.0113], [122444000.0, 0.0275], [122443000.0, 0.0006], [122431000.0, 0.0246], [122429000.0, 0.0048], [122425000.0, 0.003], [122423000.0, 0.0112], [122421000.0, 0.0415], [122420000.0, 0.0], [122418000.0, 0.0116]], "asks": [[122459000.0, 0.0], [122460000.0, 0.0004], [122463000.0, 0.0016], [122468000.0, 0.002], [122470000.0, 0.0], [122471000.0, 0.0016], [122472000.0, 0.0045], [122473000.0, 0.0001], [122474000.0, 0.0], [122475000.0, 0.0]]},
{"timestamp": "1743771407633", "bids": [[122456000.0, 0.0876], [122443000.0, 0.0542], [122437000.0, 0.0114], [122432000.0, 0.1148], [122431000.0, 0.0246], [122429000.0, 0.0048], [122425000.0, 0.0359], [122424000.0, 0.0515], [122421000.0, 0.0415], [122420000.0, 0.0249]], "asks": [[122459000.0, 0.0], [122460000.0, 0.0004], [122463000.0, 0.0016], [122468000.0, 0.002], [122470000.0, 0.0], [122471000.0, 0.0016], [122472000.0, 0.0045], [122473000.0, 0.0001], [122474000.0, 0.0], [122475000.0, 0.0]]},
{"timestamp": "1743771408134", "bids": [[122456000.0, 0.0059], [122454000.0, 0.0094], [122443000.0, 0.0316], [122437000.0, 0.0114], [122433000.0, 0.0825], [122432000.0, 0.0323], [122431000.0, 0.0246], [122425000.0, 0.0359], [122424000.0, 0.0515], [122421000.0, 0.0415]], "asks": [[122459000.0, 0.0], [122460000.0, 0.0004], [122463000.0, 0.0016], [122468000.0, 0.002], [122470000.0, 0.0], [122471000.0, 0.0016], [122472000.0, 0.0045], [122473000.0, 0.0001], [122474000.0, 0.0], [122475000.0, 0.0]]},
{"timestamp": "1743771408636", "bids": [[122456000.0, 0.0059], [122454000.0, 0.0094], [122443000.0, 0.0118], [122433000.0, 0.0825], [122425000.0, 0.003], [122421000.0, 0.0415], [122420000.0, 0.0249], [122418000.0, 0.0116], [122416000.0, 0.0225], [122412000.0, 0.0362]], "asks": [[122459000.0, 0.0], [122460000.0, 0.0004], [122463000.0, 0.0016], [122468000.0, 0.002], [122470000.0, 0.0], [122471000.0, 0.0016], [122472000.0, 0.0045], [122473000.0, 0.0001], [122474000.0, 0.0], [122475000.0, 0.0]]},
{"timestamp": "1743771409138", "bids": [[122456000.0, 0.0059], [122443000.0, 0.0032], [122437000.0, 0.0226], [122433000.0, 0.0825], [122426000.0, 0.0323], [122425000.0, 0.003], [122424000.0, 0.0246], [122422000.0, 0.0048], [122421000.0, 0.0415], [122420000.0, 0.0]], "asks": [[122459000.0, 0.0], [122460000.0, 0.0004], [122463000.0, 0.0016], [122468000.0, 0.002], [122470000.0, 0.0], [122471000.0, 0.0016], [122472000.0, 0.0045], [122473000.0, 0.0001], [122474000.0, 0.0], [122475000.0, 0.0]]},
{"timestamp": "1743771409636", "bids": [[122456000.0, 0.0059], [122443000.0, 0.0032], [122437000.0, 0.0226], [122427000.0, 0.0825], [122426000.0, 0.0323], [122425000.0, 0.003], [122424000.0, 0.0246], [122422000.0, 0.0048], [122421000.0, 0.0415], [122420000.0, 0.0]], "asks": [[122459000.0, 0.0], [122460000.0, 0.0004], [122463000.0, 0.0016], [122468000.0, 0.002], [122470000.0, 0.0], [122471000.0, 0.0016], [122472000.0, 0.0045], [122473000.0, 0.0001], [122474000.0, 0.0], [122475000.0, 0.0]]},
{"timestamp": "1743771410130", "bids": [[122456000.0, 0.0059], [122443000.0, 0.0032], [122437000.0, 0.0226], [122427000.0, 0.0825], [122426000.0, 0.0323], [122425000.0, 0.003], [122424000.0, 0.0246], [122422000.0, 0.0048], [122421000.0, 0.0415], [122420000.0, 0.0]], "asks": [[122459000.0, 0.0], [122460000.0, 0.0004], [122463000.0, 0.0016], [122468000.0, 0.002], [122470000.0, 0.0], [122471000.0, 0.0016], [122472000.0, 0.0045], [122473000.0, 0.0001], [122474000.0, 0.0], [122475000.0, 0.0]]},
{"timestamp": "1743771410635", "bids": [[122456000.0, 0.0059], [122443000.0, 0.0032], [122437000.0, 0.0226], [122427000.0, 0.0825], [122426000.0, 0.0323], [122425000.0, 0.003], [122424000.0, 0.0246], [122422000.0, 0.0048], [122421000.0, 0.0415], [122420000.0, 0.0]], "asks": [[122459000.0, 0.0], [122460000.0, 0.0004], [122463000.0, 0.0016], [122468000.0, 0.002], [122470000.0, 0.0], [122471000.0, 0.0016], [122472000.0, 0.0045], [122473000.0, 0.0001], [122474000.0, 0.0], [122475000.0, 0.0]]},
{"timestamp": "1743771411130", "bids": [[122457000.0, 0.1562], [122456000.0, 0.0059], [122443000.0, 0.0032], [122438000.0, 0.0825], [122437000.0, 0.0226], [122426000.0, 0.0323], [122425000.0, 0.003], [122424000.0, 0.0246], [122421000.0, 0.0415], [122420000.0, 0.0]], "asks": [[122459000.0, 0.0], [122460000.0, 0.0004], [122463000.0, 0.0016], [122468000.0, 0.002], [122470000.0, 0.0], [122471000.0, 0.0016], [122472000.0, 0.0045], [122473000.0, 0.0001], [122474000.0, 0.0], [122475000.0, 0.0]]},
{"timestamp": "1743771411629", "bids": [[122469000.0, 1.6099], [122457000.0, 0.1562], [122456000.0, 0.0059], [122443000.0, 0.0032], [122425000.0, 0.003], [122421000.0, 0.0415], [122420000.0, 0.0], [122418000.0, 0.038], [122416000.0, 0.0273], [122415000.0, 0.0036]], "asks": [[122470000.0, 0.0], [122471000.0, 0.0016], [122472000.0, 0.0045], [122473000.0, 0.0001], [122474000.0, 0.0], [122475000.0, 0.0], [122476000.0, 0.0036], [122480000.0, 0.001], [122482000.0, 0.0002], [122485000.0, 0.0004]]},
{"timestamp": "1743771412135", "bids": [[122456000.0, 0.0059], [122442000.0, 0.0198], [122436000.0, 0.0114], [122425000.0, 0.003], [122424000.0, 0.0325], [122423000.0, 0.0515], [122421000.0, 0.0415], [122420000.0, 0.0], [122418000.0, 0.0116], [122416000.0, 0.0273]], "asks": [[122470000.0, 0.0], [122471000.0, 0.0016], [122472000.0, 0.0045], [122473000.0, 0.0001], [122474000.0, 0.0], [122475000.0, 0.0], [122476000.0, 0.0036], [122480000.0, 0.001], [122482000.0, 0.0002], [122485000.0, 0.0004]]},
{"timestamp": "1743771412633", "bids": [[122469000.0, 0.0216], [122456000.0, 0.0059], [122454000.0, 0.0226], [122453000.0, 0.0094], [122443000.0, 0.0323], [122442000.0, 0.0556], [122436000.0, 0.0114], [122431000.0, 0.0002], [122426000.0, 0.0324], [122425000.0, 0.003]], "asks": [[122485000.0, 0.0002], [122486000.0, 0.0002], [122488000.0, 0.0008], [122489000.0, 0.0], [122491000.0, 0.0003], [122492000.0, 0.0008], [122494000.0, 0.0008], [122495000.0, 0.0001], [122497000.0, 0.0096], [122499000.0, 0.0037]]},
{"timestamp": "1743771413133", "bids": [[122460000.0, 0.0026], [122456000.0, 0.0059], [122454000.0, 0.0226], [122453000.0, 0.0094], [122446000.0, 0.0059], [122443000.0, 0.0323], [122442000.0, 0.0556], [122436000.0, 0.0114], [122431000.0, 0.025], [122426000.0, 0.0573]], "asks": [[122485000.0, 0.0002], [122486000.0, 0.0002], [122488000.0, 0.0008], [122489000.0, 0.0], [122491000.0, 0.0003], [122492000.0, 0.0008], [122494000.0, 0.0008], [122495000.0, 0.0001], [122497000.0, 0.0096], [122499000.0, 0.0037]]},
{"timestamp": "1743771413637", "bids": [[122461000.0, 0.0111], [122460000.0, 0.0026], [122456000.0, 0.0059], [122454000.0, 0.0226], [122453000.0, 0.0094], [122446000.0, 0.0059], [122444000.0, 0.0825], [122443000.0, 0.0323], [122442000.0, 0.0556], [122436000.0, 0.0114]], "asks": [[122485000.0, 0.0002], [122486000.0, 0.0002], [122488000.0, 0.0008], [122489000.0, 0.0], [122491000.0, 0.0003], [122492000.0, 0.0008], [122494000.0, 0.0008], [122495000.0, 0.0001], [122497000.0, 0.0096], [122499000.0, 0.0037]]},
{"timestamp": "1743771414134", "bids": [[122461000.0, 0.0111], [122460000.0, 0.0026], [122456000.0, 0.0059], [122454000.0, 0.0226], [122453000.0, 0.0094], [122446000.0, 0.0059], [122444000.0, 0.0825], [122443000.0, 0.0323], [122442000.0, 0.0556], [122436000.0, 0.0114]], "asks": [[122485000.0, 0.0002], [122486000.0, 0.0002], [122488000.0, 0.0008], [122489000.0, 0.0], [122491000.0, 0.0003], [122492000.0, 0.0008], [122494000.0, 0.0008], [122495000.0, 0.0001], [122497000.0, 0.0096], [122499000.0, 0.0037]]},
{"timestamp": "1743771414634", "bids": [[122461000.0, 0.0111], [122460000.0, 0.0026], [122456000.0, 0.0059], [122454000.0, 0.0226], [122453000.0, 0.0094], [122446000.0, 0.0059], [122444000.0, 0.0825], [122443000.0, 0.0323], [122442000.0, 0.0556], [122436000.0, 0.0114]], "asks": [[122485000.0, 0.0002], [122486000.0, 0.0002], [122488000.0, 0.0008], [122489000.0, 0.0], [122491000.0, 0.0003], [122492000.0, 0.0008], [122494000.0, 0.0008], [122495000.0, 0.0001], [122497000.0, 0.0096], [122499000.0, 0.0037]]},
{"timestamp": "1743771415133", "bids": [[122461000.0, 0.0111], [122460000.0, 0.0026], [122456000.0, 0.0059], [122454000.0, 0.1051], [122453000.0, 0.0094], [122446000.0, 0.0059], [122443000.0, 0.0323], [122442000.0, 0.0556], [122436000.0, 0.0114], [122431000.0, 0.025]], "asks": [[122485000.0, 0.0002], [122486000.0, 0.0002], [122488000.0, 0.0008], [122489000.0, 0.0], [122491000.0, 0.0003], [122492000.0, 0.0008], [122494000.0, 0.0008], [122495000.0, 0.0001], [122497000.0, 0.0096], [122499000.0, 0.0037]]},
