{"timestamp": "1743771600190", "bids": [[122396000.0, 0.1638], [122395000.0, 0.0], [122388000.0, 0.0048], [122387000.0, 0.0024], [122384000.0, 0.0063], [122379000.0, 0.0845], [122378000.0, 0.0225], [122374000.0, 0.0122], [122372000.0, 0.0001], [122370000.0, 0.0]], "asks": [[122450000.0, 0.0022], [122453000.0, 0.0019], [122455000.0, 0.0], [122459000.0, 0.0], [122460000.0, 0.0003], [122463000.0, 0.0016], [122468000.0, 0.002], [122469000.0, 0.0832], [122470000.0, 0.0173], [122471000.0, 0.0184]]},
{"timestamp": "1743771600762", "bids": [[122432000.0, 0.0001], [122426000.0, 0.0225], [122397000.0, 0.0123], [122396000.0, 0.0077], [122395000.0, 0.0], [122388000.0, 0.0048], [122387000.0, 0.0024], [122386000.0, 0.0112], [122384000.0, 0.0063], [122380000.0, 0.0002]], "asks": [[122450000.0, 0.0022], [122453000.0, 0.0019], [122455000.0, 0.0], [122459000.0, 0.0], [122460000.0, 0.0003], [122463000.0, 0.0016], [122468000.0, 0.002], [122469000.0, 0.0832], [122470000.0, 0.0039], [122471000.0, 0.0184]]},
{"timestamp": "1743771601190", "bids": [[122432000.0, 0.0001], [122426000.0, 0.0422], [122423000.0, 0.0001], [122420000.0, 0.0074], [122397000.0, 0.018], [122395000.0, 0.0], [122390000.0, 0.0002], [122387000.0, 0.0024], [122386000.0, 0.0112], [122380000.0, 0.0002]], "asks": [[122450000.0, 0.0022], [122453000.0, 0.0019], [122455000.0, 0.0], [122459000.0, 0.0], [122460000.0, 0.0003], [122463000.0, 0.0016], [122468000.0, 0.002], [122470000.0, 0.0039], [122471000.0, 0.0184], [122472000.0, 0.0272]]},
{"timestamp": "1743771601688", "bids": [[122449000.0, 0.0023], [122433000.0, 0.0175], [122432000.0, 0.0244], [122426000.0, 0.0422], [122423000.0, 0.0001], [122420000.0, 0.0074], [122407000.0, 0.0323], [122406000.0, 0.0563], [122397000.0, 0.0173], [122395000.0, 0.0]], "asks": [[122450000.0, 0.0022], [122453000.0, 0.0019], [122455000.0, 0.0], [122459000.0, 0.0], [122460000.0, 0.0003], [122463000.0, 0.0016], [122468000.0, 0.002], [122470000.0, 0.0], [122471000.0, 0.0016], [122472000.0, 0.0045]]},
{"timestamp": "1743771602190", "bids": [[122449000.0, 0.0023], [122433000.0, 0.046], [122432000.0, 0.0243], [122426000.0, 0.0199], [122423000.0, 0.0001], [122422000.0, 0.0248], [122420000.0, 0.0074], [122407000.0, 0.0323], [122406000.0, 0.0563], [122400000.0, 0.0748]], "asks": [[122450000.0, 0.0022], [122453000.0, 0.0019], [122455000.0, 0.0], [122459000.0, 0.0], [122460000.0, 0.0003], [122463000.0, 0.0016], [122468000.0, 0.002], [122470000.0, 0.0], [122471000.0, 0.0016], [122472000.0, 0.0045]]},
{"timestamp": "1743771602691", "bids": [[122449000.0, 0.0112], [122433000.0, 0.0479], [122432000.0, 0.0243], [122427000.0, 0.0845], [122426000.0, 0.0002], [122422000.0, 0.0248], [122407000.0, 0.0323], [122406000.0, 0.0563], [122400000.0, 0.0963], [122398000.0, 0.0845]], "asks": [[122450000.0, 0.0022], [122453000.0, 0.0019], [122455000.0, 0.0], [122459000.0, 0.0], [122460000.0, 0.0003], [122463000.0, 0.0016], [122468000.0, 0.002], [122470000.0, 0.0], [122471000.0, 0.0016], [122472000.0, 0.0045]]},
{"timestamp": "1743771603190", "bids": [[122463000.0, 1.7592], [122457000.0, 0.0002], [122452000.0, 0.0329], [122450000.0, 0.0322], [122449000.0, 0.0926], [122447000.0, 0.002], [122446000.0, 0.0325], [122438000.0, 0.0358], [122437000.0, 0.0264], [122435000.0, 0.025]], "asks": [[122472000.0, 0.0003], [122473000.0, 0.0001], [122474000.0, 0.0], [122475000.0, 0.0], [122476000.0, 0.0036], [122480000.0, 0.0002], [122482000.0, 0.0002], [122485000.0, 0.0004], [122486000.0, 0.0002], [122488000.0, 0.0008]]},
{"timestamp": "1743771603691", "bids": [[122463000.0, 1.7592], [122457000.0, 0.0002], [122452000.0, 0.0329], [122451000.0, 0.0001], [122450000.0, 0.0322], [122449000.0, 0.1209], [122447000.0, 0.002], [122446000.0, 0.0325], [122438000.0, 0.0358], [122437000.0, 0.0264]], "asks": [[122472000.0, 0.0002], [122473000.0, 0.0001], [122474000.0, 0.0], [122475000.0, 0.0], [122476000.0, 0.0036], [122480000.0, 0.0002], [122482000.0, 0.0002], [122485000.0, 0.0004], [122486000.0, 0.0002], [122488000.0, 0.0008]]},
{"timestamp": "1743771604205", "bids": [[122477000.0, 0.0155], [122468000.0, 0.0074], [122465000.0, 0.0023], [122464000.0, 0.0005], [122452000.0, 0.0329], [122451000.0, 0.0001], [122449000.0, 0.0371], [122446000.0, 0.0243], [122440000.0, 0.0562], [122439000.0, 0.0258]], "asks": [[122480000.0, 0.0002], [122482000.0, 0.0002], [122485000.0, 0.0004], [122486000.0, 0.0002], [122488000.0, 0.0008], [122489000.0, 0.0], [122490000.0, 0.01], [122491000.0, 0.0003], [122492000.0, 0.0], [122493000.0, 0.0042]]},
{"timestamp": "1743771604692", "bids": [[122478000.0, 0.0006], [122477000.0, 0.0155], [122468000.0, 0.0074], [122464000.0, 0.0005], [122459000.0, 0.0112], [122453000.0, 0.0845], [122450000.0, 0.0845], [122449000.0, 0.0333], [122446000.0, 0.0244], [122440000.0, 0.0562]], "asks": [[122480000.0, 0.0002], [122482000.0, 0.0002], [122485000.0, 0.0004], [122486000.0, 0.0002], [122488000.0, 0.0008], [122489000.0, 0.0], [122490000.0, 0.01], [122491000.0, 0.0003], [122492000.0, 0.0], [122493000.0, 0.0042]]},
{"timestamp": "1743771605191", "bids": [[122478000.0, 0.0006], [122477000.0, 0.0155], [122468000.0, 0.0074], [122464000.0, 0.0005], [122459000.0, 0.0112], [122453000.0, 0.0845], [122450000.0, 0.0845], [122449000.0, 0.0333], [122440000.0, 0.0562], [122439000.0, 0.0258]], "asks": [[122480000.0, 0.0002], [122482000.0, 0.0002], [122485000.0, 0.0004], [122486000.0, 0.0002], [122488000.0, 0.0008], [122489000.0, 0.0], [122490000.0, 0.01], [122491000.0, 0.0003], [122492000.0, 0.0], [122493000.0, 0.0042]]},
{"timestamp": "1743771605692", "bids": [[122478000.0, 0.0006], [122477000.0, 0.0155], [122468000.0, 0.0074], [122464000.0, 0.0004], [122459000.0, 0.0112], [122449000.0, 0.0285], [122440000.0, 0.0562], [122439000.0, 0.0258], [122430000.0, 0.0001], [122413000.0, 0.0116]], "asks": [[122480000.0, 0.0002], [122482000.0, 0.0002], [122485000.0, 0.0004], [122486000.0, 0.0002], [122488000.0, 0.0008], [122489000.0, 0.0], [122490000.0, 0.01], [122491000.0, 0.0003], [122492000.0, 0.0], [122493000.0, 0.0042]]},
{"timestamp": "1743771606214", "bids": [[122478000.0, 0.0006], [122464000.0, 0.0004], [122449000.0, 0.0285], [122430000.0, 0.0001], [122413000.0, 0.0116], [122412000.0, 0.0225], [122403000.0, 0.0064], [122400000.0, 0.0326], [122395000.0, 0.0], [122394000.0, 0.0322]], "asks": [[122480000.0, 0.0002], [122482000.0, 0.0002], [122485000.0, 0.0004], [122486000.0, 0.0002], [122488000.0, 0.0008], [122489000.0, 0.0], [122490000.0, 0.01], [122491000.0, 0.0003], [122492000.0, 0.0], [122493000.0, 0.0042]]},
{"timestamp": "1743771606692", "bids": [[122479000.0, 0.1444], [122449000.0, 0.0285], [122438000.0, 0.0048], [122414000.0, 0.0845], [122412000.0, 0.0227], [122410000.0, 0.0023], [122403000.0, 0.0328], [122400000.0, 0.0655], [122395000.0, 0.0], [122388000.0, 0.0506]], "asks": [[122480000.0, 0.0002], [122482000.0, 0.0002], [122485000.0, 0.0004], [122486000.0, 0.0002], [122488000.0, 0.0008], [122489000.0, 0.0], [122490000.0, 0.01], [122491000.0, 0.0003], [122492000.0, 0.0], [122493000.0, 0.0042]]},
{"timestamp": "1743771607190", "bids": [[122479000.0, 0.1331], [122449000.0, 0.0285], [122438000.0, 0.0048], [122414000.0, 0.0845], [122413000.0, 0.0845], [122412000.0, 0.0227], [122410000.0, 0.0023], [122408000.0, 0.0112], [122406000.0, 0.0156], [122404000.0, 0.0074]], "asks": [[122480000.0, 0.0002], [122482000.0, 0.0002], [122485000.0, 0.0004], [122486000.0, 0.0002], [122488000.0, 0.0008], [122489000.0, 0.0], [122490000.0, 0.01], [122491000.0, 0.0003], [122492000.0, 0.0], [122493000.0, 0.0042]]},
{"timestamp": "1743771607697", "bids": [[122468000.0, 0.0189], [122449000.0, 0.0285], [122438000.0, 0.0048], [122428000.0, 0.022], [122413000.0, 0.0845], [122412000.0, 0.0225], [122408000.0, 0.0112], [122406000.0, 0.0156], [122404000.0, 0.0074], [122403000.0, 0.0264]], "asks": [[122485000.0, 0.0001], [122486000.0, 0.0002], [122488000.0, 0.0008], [122489000.0, 0.0], [122490000.0, 0.01], [122491000.0, 0.0003], [122492000.0, 0.0], [122493000.0, 0.0042], [122494000.0, 0.0008], [122497000.0, 0.0212]]},
{"timestamp": "1743771608191", "bids": [[122479000.0, 0.0098], [122468000.0, 0.0189], [122449000.0, 0.0285], [122428000.0, 0.022], [122418000.0, 0.0244], [122417000.0, 0.0005], [122415000.0, 0.0247], [122413000.0, 0.0845], [122412000.0, 0.0225], [122409000.0, 0.0113]], "asks": [[122485000.0, 0.0001], [122486000.0, 0.0002], [122488000.0, 0.0008], [122489000.0, 0.0], [122490000.0, 0.01], [122491000.0, 0.0003], [122492000.0, 0.0], [122493000.0, 0.0042], [122494000.0, 0.0008], [122497000.0, 0.0212]]},
{"timestamp": "1743771608687", "bids": [[122479000.0, 0.002], [122468000.0, 0.0189], [122449000.0, 0.0285], [122444000.0, 0.0116], [122430000.0, 0.0001], [122428000.0, 0.0001], [122418000.0, 0.0244], [122417000.0, 0.0006], [122415000.0, 0.0247], [122412000.0, 0.0472]], "asks": [[122485000.0, 0.0001], [122486000.0, 0.0002], [122488000.0, 0.0008], [122489000.0, 0.0], [122490000.0, 0.01], [122491000.0, 0.0003], [122492000.0, 0.0], [122493000.0, 0.0042], [122494000.0, 0.0008], [122497000.0, 0.0212]]},
{"timestamp": "1743771609191", "bids": [[122473000.0, 0.0048], [122468000.0, 0.0189], [122450000.0, 0.0836], [122449000.0, 0.0285], [122448000.0, 0.0023], [122444000.0, 0.0116], [122440000.0, 0.0112], [122430000.0, 0.0001], [122428000.0, 0.0001], [122417000.0, 0.0006]], "asks": [[122485000.0, 0.0001], [122486000.0, 0.0002], [122488000.0, 0.0008], [122489000.0, 0.0], [122490000.0, 0.01], [122491000.0, 0.0003], [122492000.0, 0.0], [122493000.0, 0.0042], [122494000.0, 0.0008], [122497000.0, 0.0212]]},
{"timestamp": "1743771609694", "bids": [[122473000.0, 0.0048], [122468000.0, 0.0189], [122459000.0, 0.0074], [122450000.0, 0.0836], [122449000.0, 0.0285], [122448000.0, 0.0023], [122445000.0, 0.0156], [122444000.0, 0.0116], [122440000.0, 0.0112], [122430000.0, 0.0001]], "asks": [[122485000.0, 0.0001], [122486000.0, 0.0002], [122488000.0, 0.0008], [122489000.0, 0.0], [122490000.0, 0.01], [122491000.0, 0.0003], [122492000.0, 0.0], [122493000.0, 0.0042], [122494000.0, 0.0008], [122497000.0, 0.0212]]},
{"timestamp": "1743771610190", "bids": [[122468000.0, 0.0189], [122459000.0, 0.0074], [122457000.0, 0.022], [122449000.0, 0.0285], [122445000.0, 0.0992], [122444000.0, 0.0116], [122440000.0, 0.0112], [122433000.0, 0.0245], [122430000.0, 0.0001], [122427000.0, 0.0522]], "asks": [[122485000.0, 0.0001], [122486000.0, 0.0002], [122488000.0, 0.0008], [122489000.0, 0.0], [122490000.0, 0.01], [122491000.0, 0.0003], [122492000.0, 0.0], [122493000.0, 0.0042], [122494000.0, 0.0008], [122497000.0, 0.0212]]},
{"timestamp": "1743771610693", "bids": [[122468000.0, 0.0189], [122467000.0, 0.0048], [122450000.0, 0.0836], [122449000.0, 0.0308], [122433000.0, 0.0245], [122427000.0, 0.0522], [122422000.0, 0.0247], [122417000.0, 0.025], [122415000.0, 0.0036], [122412000.0, 0.0225]], "asks": [[122485000.0, 0.0001], [122486000.0, 0.0002], [122488000.0, 0.0008], [122489000.0, 0.0], [122490000.0, 0.01], [122491000.0, 0.0003], [122492000.0, 0.0], [122493000.0, 0.0042], [122494000.0, 0.0008], [122497000.0, 0.0212]]},
{"timestamp": "1743771611193", "bids": [[122468000.0, 0.0189], [122467000.0, 0.0048], [122449000.0, 0.0285], [122427000.0, 0.0258], [122425000.0, 0.0325], [122417000.0, 0.025], [122415000.0, 0.0036], [122412000.0, 0.0373], [122407000.0, 0.386], [122406000.0, 0.0116]], "asks": [[122485000.0, 0.0001], [122486000.0, 0.0002], [122488000.0, 0.0008], [122489000.0, 0.0], [122490000.0, 0.01], [122491000.0, 0.0003], [122492000.0, 0.0], [122493000.0, 0.0042], [122494000.0, 0.0008], [122497000.0, 0.0212]]},
{"timestamp": "1743771611690", "bids": [[122480000.0, 0.0005], [122468000.0, 0.0189], [122449000.0, 0.0285], [122441000.0, 0.0836], [122437000.0, 0.0114], [122436000.0, 0.022], [122425000.0, 0.0325], [122424000.0, 0.0268], [122416000.0, 0.0322], [122415000.0, 0.0036]], "asks": [[122485000.0, 0.0001], [122486000.0, 0.0002], [122488000.0, 0.0008], [122489000.0, 0.0], [122490000.0, 0.01], [122491000.0, 0.0003], [122492000.0, 0.0], [122493000.0, 0.0042], [122494000.0, 0.0008], [122497000.0, 0.0212]]},
{"timestamp": "1743771612193", "bids": [[122480000.0, 0.0005], [122469000.0, 0.0973], [122468000.0, 0.0189], [122449000.0, 0.0285], [122443000.0, 0.0003], [122439000.0, 0.0074], [122438000.0, 0.0836], [122437000.0, 0.0114], [122425000.0, 0.0325], [122424000.0, 0.0268]], "asks": [[122485000.0, 0.0001], [122486000.0, 0.0002], [122488000.0, 0.0008], [122489000.0, 0.0], [122490000.0, 0.01], [122491000.0, 0.0003], [122492000.0, 0.0], [122493000.0, 0.0042], [122494000.0, 0.0008], [122497000.0, 0.0212]]},
{"timestamp": "1743771612693", "bids": [[122481000.0, 0.0032], [122480000.0, 0.0005], [122469000.0, 0.0973], [122468000.0, 0.0189], [122449000.0, 0.0285], [122448000.0, 0.0023], [122443000.0, 0.0003], [122439000.0, 0.0074], [122438000.0, 0.0836], [122437000.0, 0.0114]], "asks": [[122485000.0, 0.0001], [122486000.0, 0.0002], [122488000.0, 0.0008], [122489000.0, 0.0], [122490000.0, 0.01], [122491000.0, 0.0003], [122492000.0, 0.0], [122493000.0, 0.0042], [122494000.0, 0.0008], [122497000.0, 0.0212]]},
{"timestamp": "1743771613227", "bids": [[122493000.0, 1.748], [122481000.0, 0.0391], [122479000.0, 0.0003], [122470000.0, 0.0836], [122469000.0, 0.0638], [122468000.0, 0.0189], [122449000.0, 0.0285], [122448000.0, 0.0023], [122443000.0, 0.0003], [122431000.0, 0.0004]], "asks": [[122494000.0, 0.0004], [122497000.0, 0.0212], [122499000.0, 0.0055], [122500000.0, 0.0338], [122502000.0, 0.0], [122503000.0, 0.0], [122504000.0, 0.0002], [122505000.0, 0.0081], [122506000.0, 0.0013], [122507000.0, 0.0094]]},
{"timestamp": "1743771613695", "bids": [[122493000.0, 1.748], [122486000.0, 0.022], [122482000.0, 0.004], [122481000.0, 0.0391], [122479000.0, 0.0003], [122470000.0, 0.0896], [122468000.0, 0.0189], [122467000.0, 0.0003], [122455000.0, 0.0325], [122450000.0, 0.0001]], "asks": [[122494000.0, 0.0004], [122497000.0, 0.0212], [122499000.0, 0.0055], [122500000.0, 0.0338], [122502000.0, 0.0], [122503000.0, 0.0], [122504000.0, 0.0002], [122505000.0, 0.0081], [122506000.0, 0.0013], [122507000.0, 0.0053]]},
{"timestamp": "1743771614194", "bids": [[122493000.0, 0.0225], [122486000.0, 0.022], [122482000.0, 0.0075], [122479000.0, 0.0003], [122473000.0, 0.0112], [122470000.0, 0.0896], [122467000.0, 0.0003], [122461000.0, 0.0001], [122455000.0, 0.0325], [122450000.0, 0.0001]], "asks": [[122500000.0, 0.0289], [122502000.0, 0.0], [122503000.0, 0.0], [122504000.0, 0.0002], [122505000.0, 0.0081], [122506000.0, 0.0013], [122507000.0, 0.0053], [122508000.0, 0.0], [122509000.0, 0.0017], [122510000.0, 0.0041]]},
{"timestamp": "1743771614687", "bids": [[122497000.0, 0.0216], [122493000.0, 0.0225], [122490000.0, 0.0074], [122486000.0, 0.022], [122482000.0, 0.004], [122481000.0, 0.0023], [122479000.0, 0.0003], [122476000.0, 0.0156], [122473000.0, 0.0112], [122470000.0, 0.101]], "asks": [[122500000.0, 0.0289], [122502000.0, 0.0], [122503000.0, 0.0], [122504000.0, 0.0002], [122505000.0, 0.0081], [122506000.0, 0.0013], [122507000.0, 0.0053], [122508000.0, 0.0], [122509000.0, 0.0017], [122510000.0, 0.0041]]},
{"timestamp": "1743771615195", "bids": [[122498000.0, 0.0107], [122497000.0, 0.0216], [122493000.0, 0.0225], [122490000.0, 0.0074], [122486000.0, 0.022], [122482000.0, 0.004], [122481000.0, 0.0023], [122476000.0, 0.0156], [122473000.0, 0.0112], [122470000.0, 0.0174]], "asks": [[122500000.0, 0.0037], [122502000.0, 0.0], [122503000.0, 0.0], [122504000.0, 0.0002], [122505000.0, 0.0081], [122506000.0, 0.0013], [122507000.0, 0.0053], [122508000.0, 0.0], [122509000.0, 0.0017], [122510000.0, 0.0041]]},
{"timestamp": "1743771615694", "bids": [[122498000.0, 0.0107], [122493000.0, 0.0225], [122490000.0, 0.0074], [122489000.0, 0.0191], [122482000.0, 0.004], [122481000.0, 0.0023], [122476000.0, 0.0156], [122473000.0, 0.0112], [122470000.0, 0.0174], [122461000.0, 0.0065]], "asks": [[122500000.0, 0.0037], [122502000.0, 0.0], [122503000.0, 0.0], [122504000.0, 0.0002], [122505000.0, 0.0081], [122506000.0, 0.0013], [122507000.0, 0.0053], [122508000.0, 0.0], [122509000.0, 0.0017], [122510000.0, 0.0041]]},
{"timestamp": "1743771616196", "bids": [[122498000.0, 0.0107], [122493000.0, 0.0225], [122489000.0, 0.0191], [122482000.0, 0.004], [122477000.0, 0.0829], [122473000.0, 0.0112], [122470000.0, 0.006], [122451000.0, 0.0002], [122450000.0, 0.0001], [122449000.0, 0.0225]], "asks": [[122500000.0, 0.0037], [122502000.0, 0.0], [122503000.0, 0.0], [122504000.0, 0.0002], [122505000.0, 0.0081], [122506000.0, 0.0013], [122507000.0, 0.0053], [122508000.0, 0.0], [122509000.0, 0.0017], [122510000.0, 0.0041]]},
{"timestamp": "1743771616694", "bids": [[122499000.0, 0.0002], [122498000.0, 0.0107], [122493000.0, 0.0225], [122482000.0, 0.0114], [122479000.0, 0.022], [122477000.0, 0.0829], [122474000.0, 0.0829], [122473000.0, 0.0023], [122460000.0, 0.0114], [122454000.0, 0.0244]], "asks": [[122500000.0, 0.0037], [122502000.0, 0.0], [122503000.0, 0.0], [122504000.0, 0.0002], [122505000.0, 0.0081], [122506000.0, 0.0013], [122507000.0, 0.0053], [122508000.0, 0.0], [122509000.0, 0.0017], [122510000.0, 0.0041]]},
{"timestamp": "1743771617197", "bids": [[122499000.0, 0.0002], [122498000.0, 0.0107], [122493000.0, 0.0225], [122485000.0, 0.1312], [122482000.0, 0.0114], [122479000.0, 0.022], [122473000.0, 0.0023], [122470000.0, 0.0829], [122469000.0, 0.052], [122460000.0, 0.0114]], "asks": [[122500000.0, 0.0037], [122502000.0, 0.0], [122503000.0, 0.0], [122504000.0, 0.0002], [122505000.0, 0.0081], [122506000.0, 0.0013], [122507000.0, 0.0053], [122508000.0, 0.0], [122509000.0, 0.0017], [122510000.0, 0.0041]]},
{"timestamp": "1743771617707", "bids": [[122499000.0, 0.0002], [122498000.0, 0.0107], [122493000.0, 0.0225], [122485000.0, 0.1263], [122482000.0, 0.0114], [122479000.0, 0.022], [122473000.0, 0.0023], [122460000.0, 0.0114], [122454000.0, 0.0245], [122452000.0, 0.0264]], "asks": [[122500000.0, 0.0028], [122502000.0, 0.0], [122503000.0, 0.0], [122504000.0, 0.0002], [122505000.0, 0.0081], [122506000.0, 0.0013], [122507000.0, 0.0053], [122508000.0, 0.0], [122509000.0, 0.0017], [122510000.0, 0.0041]]},
{"timestamp": "1743771618198", "bids": [[122499000.0, 0.0002], [122498000.0, 0.0107], [122493000.0, 0.0225], [122485000.0, 0.1263], [122484000.0, 0.0048], [122482000.0, 0.0114], [122473000.0, 0.0023], [122460000.0, 0.0114], [122454000.0, 0.0245], [122452000.0, 0.0264]], "asks": [[122500000.0, 0.0028], [122502000.0, 0.0], [122503000.0, 0.0], [122504000.0, 0.0002], [122505000.0, 0.0081], [122506000.0, 0.0013], [122507000.0, 0.0053], [122508000.0, 0.0], [122509000.0, 0.0017], [122510000.0, 0.0041]]},
{"timestamp": "1743771618696", "bids": [[122499000.0, 0.0002], [122498000.0, 0.0107], [122493000.0, 0.0225], [122485000.0, 0.1263], [122484000.0, 0.0048], [122482000.0, 0.0114], [122481000.0, 0.022], [122473000.0, 0.0023], [122452000.0, 0.0264], [122449000.0, 0.0225]], "asks": [[122500000.0, 0.0016], [122502000.0, 0.0], [122503000.0, 0.0], [122504000.0, 0.0002], [122505000.0, 0.0081], [122506000.0, 0.0013], [122507000.0, 0.0053], [122508000.0, 0.0], [122509000.0, 0.0017], [122510000.0, 0.0041]]},
{"timestamp": "1743771619195", "bids": [[122499000.0, 0.0939], [122498000.0, 0.0107], [122493000.0, 0.0225], [122486000.0, 0.0829], [122485000.0, 0.1263], [122484000.0, 0.0048], [122482000.0, 0.004], [122481000.0, 0.022], [122474000.0, 0.0268], [122466000.0, 0.0153]], "asks": [[122500000.0, 0.0016], [122502000.0, 0.0], [122503000.0, 0.0], [122504000.0, 0.0002], [122505000.0, 0.0081], [122506000.0, 0.0013], [122507000.0, 0.0053], [122508000.0, 0.0], [122509000.0, 0.0017], [122510000.0, 0.0041]]},
{"timestamp": "1743771619692", "bids": [[122512000.0, 1.7246], [122508000.0, 0.0165], [122499000.0, 0.0399], [122498000.0, 0.0107], [122494000.0, 0.0829], [122493000.0, 0.0225], [122485000.0, 0.1263], [122484000.0, 0.0048], [122482000.0, 0.004], [122481000.0, 0.0023]], "asks": [[122513000.0, 0.0008], [122514000.0, 0.0008], [122515000.0, 0.0005], [122517000.0, 0.0], [122519000.0, 0.0024], [122520000.0, 0.0044], [122522000.0, 0.0127], [122523000.0, 0.0002], [122525000.0, 0.002], [122529000.0, 0.0033]]},
{"timestamp": "1743771630703", "bids": [[122534000.0, 0.1334], [122533000.0, 0.0059], [122532000.0, 0.022], [122531000.0, 0.0225], [122527000.0, 0.0222], [122526000.0, 0.0067], [122520000.0, 0.0268], [122514000.0, 0.0114], [122512000.0, 0.0023], [122508000.0, 0.0001]], "asks": [[122551000.0, 0.0], [122552000.0, 0.0092], [122553000.0, 0.0013], [122554000.0, 0.0147], [122555000.0, 0.0025], [122556000.0, 0.0009], [122557000.0, 0.0034], [122559000.0, 0.0006], [122560000.0, 0.0012], [122561000.0, 0.0001]]},
{"timestamp": "1743771631203", "bids": [[122534000.0, 0.1334], [122533000.0, 0.0059], [122531000.0, 0.0225], [122527000.0, 0.0222], [122526000.0, 0.0044], [122512000.0, 0.0023], [122500000.0, 0.0802], [122496000.0, 0.0002], [122493000.0, 0.0225], [122488000.0, 0.0163]], "asks": [[122551000.0, 0.0], [122552000.0, 0.0092], [122553000.0, 0.0013], [122554000.0, 0.0147], [122555000.0, 0.0025], [122556000.0, 0.0009], [122557000.0, 0.0034], [122559000.0, 0.0006], [122560000.0, 0.0012], [122561000.0, 0.0001]]},
{"timestamp": "1743771635198", "bids": [[122564000.0, 0.0052], [122558000.0, 0.0118], [122552000.0, 0.004], [122549000.0, 0.022], [122548000.0, 0.012], [122543000.0, 0.0023], [122541000.0, 0.0175], [122536000.0, 0.0268], [122535000.0, 0.1263], [122531000.0, 0.0225]], "asks": [[122566000.0, 0.0097], [122567000.0, 0.0009], [122568000.0, 0.0018], [122569000.0, 0.0037], [122570000.0, 0.005], [122571000.0, 0.0012], [122572000.0, 0.0049], [122573000.0, 0.0041], [122574000.0, 0.0021], [122575000.0, 0.0]]},
{"timestamp": "1743771635698", "bids": [[122564000.0, 0.0052], [122558000.0, 0.0118], [122552000.0, 0.0008], [122548000.0, 0.0023], [122543000.0, 0.0023], [122541000.0, 0.0059], [122536000.0, 0.0268], [122535000.0, 0.1263], [122531000.0, 0.0225], [122521000.0, 0.44]], "asks": [[122566000.0, 0.0046], [122567000.0, 0.0009], [122568000.0, 0.0018], [122569000.0, 0.0037], [122570000.0, 0.005], [122571000.0, 0.0012], [122572000.0, 0.0049], [122573000.0, 0.0041], [122574000.0, 0.0021], [122575000.0, 0.0]]},
{"timestamp": "1743771638204", "bids": [[122560000.0, 0.9453], [122552000.0, 0.0008], [122544000.0, 0.0225], [122527000.0, 0.0285], [122521000.0, 0.44], [122493000.0, 0.0225], [122491000.0, 0.0112], [122481000.0, 0.0], [122480000.0, 0.0023], [122477000.0, 0.0042]], "asks": [[122564000.0, 0.0532], [122565000.0, 0.0001], [122566000.0, 0.0046], [122567000.0, 0.0009], [122568000.0, 0.0018], [122569000.0, 0.0037], [122570000.0, 0.005], [122571000.0, 0.0012], [122572000.0, 0.0153], [122573000.0, 0.0041]]},
{"timestamp": "1743771638704", "bids": [[122560000.0, 0.928], [122552000.0, 0.0008], [122550000.0, 0.0048], [122527000.0, 0.0285], [122503000.0, 0.0006], [122493000.0, 0.0225], [122490000.0, 0.022], [122482000.0, 0.0003], [122481000.0, 0.0], [122477000.0, 0.0036]], "asks": [[122562000.0, 0.0039], [122563000.0, 0.0336], [122564000.0, 0.0759], [122565000.0, 0.0001], [122566000.0, 0.0046], [122567000.0, 0.0009], [122568000.0, 0.0018], [122569000.0, 0.0037], [122570000.0, 0.005], [122571000.0, 0.0012]]},
{"timestamp": "1743771639199", "bids": [[122560000.0, 0.928], [122552000.0, 0.0008], [122550000.0, 0.0048], [122527000.0, 0.0285], [122503000.0, 0.0006], [122493000.0, 0.0299], [122490000.0, 0.022], [122481000.0, 0.0], [122480000.0, 0.0157], [122477000.0, 0.0036]], "asks": [[122562000.0, 0.0038], [122563000.0, 0.0504], [122564000.0, 0.0759], [122566000.0, 0.0046], [122567000.0, 0.0009], [122568000.0, 0.0018], [122569000.0, 0.0037], [122570000.0, 0.005], [122571000.0, 0.0012], [122572000.0, 0.0049]]},
{"timestamp": "1743771639708", "bids": [[122560000.0, 0.928], [122552000.0, 0.0008], [122530000.0, 0.0225], [122527000.0, 0.0285], [122503000.0, 0.0006], [122493000.0, 0.0299], [122486000.0, 0.0023], [122482000.0, 0.01], [122481000.0, 0.0], [122480000.0, 0.0269]], "asks": [[122563000.0, 0.0007], [122564000.0, 0.0532], [122566000.0, 0.0046], [122567000.0, 0.0009], [122568000.0, 0.0018], [122569000.0, 0.0037], [122570000.0, 0.005], [122571000.0, 0.0012], [122572000.0, 0.0049], [122573000.0, 0.0041]]},
{"timestamp": "1743771641706", "bids": [[122564000.0, 0.0777], [122560000.0, 0.9279], [122553000.0, 0.0361], [122552000.0, 0.0008], [122540000.0, 0.0056], [122539000.0, 0.0102], [122530000.0, 0.0225], [122527000.0, 0.0285], [122512000.0, 0.44], [122507000.0, 0.0074]], "asks": [[122566000.0, 0.0046], [122567000.0, 0.0009], [122568000.0, 0.0018], [122569000.0, 0.0037], [122570000.0, 0.005], [122571000.0, 0.0012], [122572000.0, 0.0049], [122573000.0, 0.0041], [122574000.0, 0.0021], [122575000.0, 0.0]]},
{"timestamp": "1743771642207", "bids": [[122565000.0, 0.0035], [122564000.0, 0.0777], [122560000.0, 0.9279], [122553000.0, 0.0361], [122552000.0, 0.0008], [122540000.0, 0.0056], [122539000.0, 0.0102], [122530000.0, 0.0225], [122527000.0, 0.0285], [122512000.0, 0.44]], "asks": [[122566000.0, 0.0046], [122567000.0, 0.0009], [122568000.0, 0.0018], [122569000.0, 0.0037], [122570000.0, 0.005], [122571000.0, 0.0012], [122572000.0, 0.0049], [122573000.0, 0.0041], [122574000.0, 0.0021], [122575000.0, 0.0]]},
{"timestamp": "1743771642700", "bids": [[122565000.0, 0.1506], [122564000.0, 0.0777], [122560000.0, 0.9279], [122553000.0, 0.0361], [122552000.0, 0.0008], [122540000.0, 0.0056], [122539000.0, 0.0102], [122530000.0, 0.0225], [122527000.0, 0.0285], [122518000.0, 0.0173]], "asks": [[122569000.0, 0.0002], [122570000.0, 0.005], [122571000.0, 0.0012], [122572000.0, 0.0049], [122573000.0, 0.0041], [122574000.0, 0.0021], [122575000.0, 0.0], [122576000.0, 0.0044], [122578000.0, 0.0018], [122579000.0, 0.0001]]},
{"timestamp": "1743771643206", "bids": [[122565000.0, 0.1305], [122564000.0, 0.0777], [122560000.0, 0.9279], [122553000.0, 0.0361], [122552000.0, 0.0008], [122540000.0, 0.0056], [122539000.0, 0.0102], [122530000.0, 0.0225], [122527000.0, 0.0285], [122518000.0, 0.0173]], "asks": [[122569000.0, 0.0002], [122570000.0, 0.005], [122571000.0, 0.0012], [122572000.0, 0.0049], [122573000.0, 0.0041], [122574000.0, 0.0021], [122575000.0, 0.0], [122576000.0, 0.0044], [122578000.0, 0.0018], [122579000.0, 0.0001]]},
{"timestamp": "1743771643703", "bids": [[122564000.0, 0.0777], [122560000.0, 0.9279], [122552000.0, 0.0008], [122540000.0, 0.0056], [122539000.0, 0.0102], [122530000.0, 0.0225], [122527000.0, 0.0285], [122518000.0, 0.0173], [122515000.0, 0.0074], [122513000.0, 0.016]], "asks": [[122568000.0, 0.0119], [122604000.0, 0.0011], [122605000.0, 0.0001], [122606000.0, 0.0013], [122607000.0, 0.0343], [122608000.0, 0.0542], [122609000.0, 0.0008], [122610000.0, 0.0336], [122611000.0, 0.0], [122612000.0, 0.0338]]},
{"timestamp": "1743771644214", "bids": [[122564000.0, 0.5777], [122560000.0, 0.9279], [122552000.0, 0.0008], [122527000.0, 0.0285], [122515000.0, 0.0074], [122511000.0, 0.0023], [122509000.0, 0.0241], [122493000.0, 0.0225], [122483000.0, 0.0264], [122482000.0, 0.01]], "asks": [[122568000.0, 0.0318], [122600000.0, 0.0166], [122604000.0, 0.0011], [122605000.0, 0.0001], [122606000.0, 0.0013], [122607000.0, 0.0343], [122608000.0, 0.0398], [122609000.0, 0.0008], [122610000.0, 0.0157], [122611000.0, 0.0]]},
{"timestamp": "1743771644701", "bids": [[122564000.0, 0.5777], [122560000.0, 0.9279], [122552000.0, 0.0008], [122527000.0, 0.0285], [122493000.0, 0.0225], [122483000.0, 0.0264], [122482000.0, 0.01], [122481000.0, 0.0], [122477000.0, 0.0036], [122476000.0, 0.0249]], "asks": [[122568000.0, 0.0318], [122585000.0, 0.0128], [122600000.0, 0.0166], [122604000.0, 0.0011], [122605000.0, 0.0178], [122606000.0, 0.0166], [122607000.0, 0.0013], [122608000.0, 0.0326], [122609000.0, 0.0008], [122610000.0, 0.0157]]},
{"timestamp": "1743771648209", "bids": [[122578000.0, 0.0871], [122577000.0, 0.0016], [122567000.0, 0.0225], [122565000.0, 0.0008], [122564000.0, 0.5777], [122560000.0, 0.9279], [122552000.0, 0.0008], [122534000.0, 0.0143], [122530000.0, 0.0225], [122527000.0, 0.0285]], "asks": [[122594000.0, 0.003], [122604000.0, 0.0011], [122605000.0, 0.0001], [122606000.0, 0.0016], [122607000.0, 0.0013], [122608000.0, 0.015], [122609000.0, 0.023], [122610000.0, 0.0157], [122611000.0, 0.0], [122612000.0, 0.0421]]},
{"timestamp": "1743771648703", "bids": [[122599000.0, 1.5678], [122594000.0, 0.0159], [122578000.0, 0.1695], [122577000.0, 0.0016], [122567000.0, 0.0225], [122565000.0, 0.0008], [122564000.0, 0.5777], [122560000.0, 0.9279], [122552000.0, 0.0008], [122534000.0, 0.0143]], "asks": [[122602000.0, 0.0359], [122603000.0, 0.0324], [122604000.0, 0.0011], [122605000.0, 0.0177], [122606000.0, 0.0013], [122607000.0, 0.0013], [122608000.0, 0.0262], [122609000.0, 0.0552], [122610000.0, 0.0157], [122611000.0, 0.0]]},
{"timestamp": "1743771649201", "bids": [[122599000.0, 1.5485], [122594000.0, 0.0159], [122578000.0, 0.0352], [122577000.0, 0.0016], [122567000.0, 0.0225], [122565000.0, 0.0008], [122564000.0, 0.5777], [122562000.0, 0.0235], [122561000.0, 0.0178], [122560000.0, 0.9279]], "asks": [[122602000.0, 0.0002], [122603000.0, 0.0324], [122604000.0, 0.0182], [122605000.0, 0.0177], [122606000.0, 0.0013], [122607000.0, 0.0013], [122608000.0, 0.0262], [122609000.0, 0.0676], [122610000.0, 0.0157], [122611000.0, 0.0]]},
{"timestamp": "1743771649701", "bids": [[122578000.0, 0.0054], [122577000.0, 0.0016], [122567000.0, 0.0225], [122565000.0, 0.0008], [122564000.0, 0.5777], [122562000.0, 0.0235], [122561000.0, 0.0178], [122560000.0, 0.9279], [122553000.0, 0.022], [122552000.0, 0.0156]], "asks": [[122603000.0, 0.0162], [122604000.0, 0.0182], [122605000.0, 0.0177], [122606000.0, 0.0013], [122607000.0, 0.0013], [122608000.0, 0.015], [122609000.0, 0.0454], [122610000.0, 0.0157], [122611000.0, 0.0], [122612000.0, 0.0168]]},
{"timestamp": "1743771650202", "bids": [[122600000.0, 0.0012], [122582000.0, 0.0015], [122577000.0, 0.0016], [122567000.0, 0.0225], [122565000.0, 0.0008], [122564000.0, 0.5777], [122562000.0, 0.0235], [122561000.0, 0.0178], [122560000.0, 0.9279], [122552000.0, 0.0008]], "asks": [[122603000.0, 0.0162], [122604000.0, 0.0182], [122605000.0, 0.0001], [122606000.0, 0.0013], [122607000.0, 0.0013], [122608000.0, 0.015], [122609000.0, 0.0454], [122610000.0, 0.0157], [122611000.0, 0.0], [122612000.0, 0.0168]]},
{"timestamp": "1743771650707", "bids": [[122600000.0, 0.0012], [122582000.0, 0.0015], [122577000.0, 0.0016], [122565000.0, 0.0008], [122564000.0, 0.5777], [122562000.0, 0.0235], [122561000.0, 0.0178], [122560000.0, 0.9279], [122553000.0, 0.0091], [122552000.0, 0.0008]], "asks": [[122603000.0, 0.0162], [122604000.0, 0.0182], [122605000.0, 0.0001], [122606000.0, 0.0013], [122607000.0, 0.0013], [122608000.0, 0.015], [122609000.0, 0.0454], [122610000.0, 0.0157], [122611000.0, 0.0], [122612000.0, 0.0168]]},
{"timestamp": "1743771651204", "bids": [[122565000.0, 0.0151], [122564000.0, 0.5777], [122560000.0, 0.9279], [122558000.0, 0.0182], [122553000.0, 0.0091], [122552000.0, 0.0008], [122542000.0, 0.0173], [122538000.0, 0.0241], [122530000.0, 0.0225], [122527000.0, 0.0285]], "asks": [[122602000.0, 0.0115], [122604000.0, 0.0011], [122605000.0, 0.0001], [122606000.0, 0.0013], [122607000.0, 0.0013], [122608000.0, 0.015], [122609000.0, 0.0008], [122610000.0, 0.0157], [122611000.0, 0.0], [122612000.0, 0.0168]]},
{"timestamp": "1743771651700", "bids": [[122565000.0, 0.0151], [122564000.0, 0.5777], [122560000.0, 0.9279], [122557000.0, 0.0182], [122552000.0, 0.0008], [122550000.0, 0.0182], [122542000.0, 0.0173], [122538000.0, 0.0241], [122532000.0, 0.0009], [122530000.0, 0.0225]], "asks": [[122602000.0, 0.0115], [122604000.0, 0.0011], [122605000.0, 0.0129], [122606000.0, 0.0013], [122607000.0, 0.0157], [122608000.0, 0.015], [122609000.0, 0.0008], [122610000.0, 0.0157], [122611000.0, 0.0], [122612000.0, 0.0168]]},
{"timestamp": "1743771652205", "bids": [[122565000.0, 0.0151], [122564000.0, 0.5777], [122560000.0, 0.9279], [122557000.0, 0.0182], [122552000.0, 0.0008], [122550000.0, 0.0182], [122542000.0, 0.0173], [122538000.0, 0.0241], [122532000.0, 0.0009], [122530000.0, 0.0225]], "asks": [[122604000.0, 0.0011], [122605000.0, 0.0129], [122606000.0, 0.0139], [122607000.0, 0.0157], [122608000.0, 0.032], [122609000.0, 0.0008], [122610000.0, 0.0328], [122611000.0, 0.0], [122612000.0, 0.0168], [122613000.0, 0.0008]]},
{"timestamp": "1743771652706", "bids": [[122565000.0, 0.0008], [122564000.0, 0.5777], [122552000.0, 0.0008], [122533000.0, 0.0129], [122530000.0, 0.0225], [122527000.0, 0.0285], [122521000.0, 0.0235], [122520000.0, 0.0177], [122517000.0, 0.0178], [122516000.0, 0.4566]], "asks": [[122601000.0, 0.0], [122604000.0, 0.0011], [122605000.0, 0.0001], [122606000.0, 0.0139], [122607000.0, 0.0013], [122608000.0, 0.0728], [122609000.0, 0.0008], [122610000.0, 0.0328], [122611000.0, 0.0], [122612000.0, 0.0334]]},
{"timestamp": "1743771661205", "bids": [[122564000.0, 0.1448], [122555000.0, 0.0002], [122552000.0, 0.0008], [122551000.0, 0.0244], [122540000.0, 0.0001], [122539000.0, 0.0036], [122530000.0, 0.0225], [122527000.0, 0.0285], [122520000.0, 0.0001], [122518000.0, 0.0]], "asks": [[122565000.0, 0.0], [122566000.0, 0.0175], [122567000.0, 0.0327], [122570000.0, 0.0213], [122581000.0, 0.0322], [122582000.0, 0.0556], [122583000.0, 0.017], [122584000.0, 0.0186], [122604000.0, 0.0011], [122605000.0, 0.0001]]},
{"timestamp": "1743771661707", "bids": [[122610000.0, 0.6918], [122564000.0, 0.1448], [122555000.0, 0.0002], [122552000.0, 0.0008], [122551000.0, 0.0244], [122540000.0, 0.0001], [122539000.0, 0.0036], [122530000.0, 0.0225], [122527000.0, 0.0285], [122520000.0, 0.0001]], "asks": [[122611000.0, 0.0], [122612000.0, 0.0168], [122613000.0, 0.0008], [122614000.0, 0.0009], [122615000.0, 0.0003], [122616000.0, 0.0005], [122617000.0, 0.0017], [122618000.0, 0.0026], [122619000.0, 0.0013], [122620000.0, 0.0032]]},
{"timestamp": "1743771662209", "bids": [[122610000.0, 0.6262], [122564000.0, 0.1448], [122555000.0, 0.0002], [122552000.0, 0.0008], [122551000.0, 0.0412], [122540000.0, 0.0001], [122539000.0, 0.0036], [122530000.0, 0.0225], [122527000.0, 0.0285], [122520000.0, 0.0001]], "asks": [[122611000.0, 0.0], [122612000.0, 0.0168], [122613000.0, 0.0008], [122614000.0, 0.0009], [122615000.0, 0.0003], [122616000.0, 0.0005], [122617000.0, 0.0017], [122618000.0, 0.0026], [122619000.0, 0.0013], [122620000.0, 0.0032]]},
{"timestamp": "1743771663708", "bids": [[122610000.0, 0.6376], [122564000.0, 0.1448], [122555000.0, 0.017], [122552000.0, 0.0008], [122551000.0, 0.0244], [122540000.0, 0.0001], [122539000.0, 0.0036], [122530000.0, 0.0225], [122527000.0, 0.0285], [122520000.0, 0.0001]], "asks": [[122611000.0, 0.0], [122612000.0, 0.0168], [122613000.0, 0.0008], [122614000.0, 0.0009], [122615000.0, 0.0003], [122616000.0, 0.0005], [122617000.0, 0.0017], [122618000.0, 0.0026], [122619000.0, 0.0013], [122620000.0, 0.0032]]},
{"timestamp": "1743771664220", "bids": [[122610000.0, 0.6376], [122564000.0, 0.1448], [122555000.0, 0.017], [122552000.0, 0.0008], [122551000.0, 0.0244], [122540000.0, 0.0001], [122539000.0, 0.0036], [122530000.0, 0.0225], [122520000.0, 0.0001], [122518000.0, 0.0]], "asks": [[122611000.0, 0.0], [122612000.0, 0.0168], [122613000.0, 0.0008], [122614000.0, 0.0009], [122615000.0, 0.0003], [122616000.0, 0.0005], [122617000.0, 0.0017], [122618000.0, 0.0026], [122619000.0, 0.0013], [122620000.0, 0.0032]]},
{"timestamp": "1743771664713", "bids": [[122610000.0, 0.5418], [122564000.0, 0.1448], [122555000.0, 0.017], [122552000.0, 0.0008], [122551000.0, 0.0244], [122540000.0, 0.0001], [122539000.0, 0.0036], [122530000.0, 0.0225], [122520000.0, 0.0001], [122519000.0, 0.0111]], "asks": [[122611000.0, 0.0], [122612000.0, 0.0168], [122613000.0, 0.0008], [122614000.0, 0.0009], [122615000.0, 0.0003], [122616000.0, 0.0005], [122617000.0, 0.0339], [122618000.0, 0.067], [122619000.0, 0.0013], [122620000.0, 0.0032]]},
{"timestamp": "1743771665712", "bids": [[122610000.0, 0.5376], [122564000.0, 0.1448], [122555000.0, 0.0002], [122552000.0, 0.0008], [122551000.0, 0.0244], [122540000.0, 0.0001], [122539000.0, 0.0036], [122520000.0, 0.0001], [122518000.0, 0.0], [122513000.0, 0.0143]], "asks": [[122611000.0, 0.0079], [122612000.0, 0.0168], [122613000.0, 0.0008], [122614000.0, 0.0009], [122615000.0, 0.0003], [122616000.0, 0.0005], [122617000.0, 0.0017], [122618000.0, 0.0026], [122619000.0, 0.0013], [122620000.0, 0.0032]]},
{"timestamp": "1743771666215", "bids": [[122610000.0, 0.5376], [122594000.0, 0.0008], [122564000.0, 0.1448], [122555000.0, 0.0002], [122552000.0, 0.0008], [122551000.0, 0.0244], [122540000.0, 0.0001], [122539000.0, 0.0036], [122520000.0, 0.0001], [122518000.0, 0.0]], "asks": [[122611000.0, 0.0], [122612000.0, 0.0168], [122613000.0, 0.0008], [122614000.0, 0.0009], [122615000.0, 0.0003], [122616000.0, 0.0005], [122617000.0, 0.0017], [122618000.0, 0.0026], [122619000.0, 0.0013], [122620000.0, 0.0032]]},
{"timestamp": "1743771666711", "bids": [[122610000.0, 0.4277], [122594000.0, 0.0008], [122564000.0, 0.1448], [122555000.0, 0.0002], [122552000.0, 0.0008], [122551000.0, 0.0244], [122540000.0, 0.0001], [122539000.0, 0.0036], [122535000.0, 0.0168], [122520000.0, 0.0001]], "asks": [[122611000.0, 0.0], [122612000.0, 0.0168], [122613000.0, 0.0008], [122614000.0, 0.0009], [122615000.0, 0.0003], [122616000.0, 0.0005], [122617000.0, 0.0017], [122618000.0, 0.0026], [122619000.0, 0.0013], [122620000.0, 0.0032]]},
{"timestamp": "1743771667217", "bids": [[122610000.0, 0.4277], [122594000.0, 0.0008], [122564000.0, 0.1448], [122555000.0, 0.0002], [122552000.0, 0.0008], [122551000.0, 0.0244], [122540000.0, 0.0001], [122539000.0, 0.0036], [122520000.0, 0.0001], [122518000.0, 0.0]], "asks": [[122611000.0, 0.0], [122612000.0, 0.0168], [122613000.0, 0.0008], [122614000.0, 0.0009], [122615000.0, 0.0003], [122616000.0, 0.0005], [122617000.0, 0.0017], [122618000.0, 0.0026], [122619000.0, 0.0013], [122620000.0, 0.0032]]},
{"timestamp": "1743771667716", "bids": [[122610000.0, 0.4276], [122594000.0, 0.0008], [122564000.0, 0.1448], [122555000.0, 0.0002], [122552000.0, 0.0008], [122540000.0, 0.0001], [122539000.0, 0.0036], [122520000.0, 0.0001], [122518000.0, 0.0], [122508000.0, 0.0036]], "asks": [[122611000.0, 0.0079], [122612000.0, 0.0168], [122613000.0, 0.0008], [122614000.0, 0.0009], [122615000.0, 0.0003], [122616000.0, 0.0005], [122617000.0, 0.0017], [122618000.0, 0.0032], [122619000.0, 0.0013], [122620000.0, 0.0032]]},
{"timestamp": "1743771668411", "bids": [[122610000.0, 0.4275], [122594000.0, 0.0008], [122564000.0, 0.1448], [122555000.0, 0.0002], [122552000.0, 0.0008], [122540000.0, 0.0001], [122539000.0, 0.0036], [122530000.0, 0.0168], [122520000.0, 0.0001], [122518000.0, 0.0]], "asks": [[122611000.0, 0.0077], [122612000.0, 0.0168], [122613000.0, 0.0008], [122614000.0, 0.0009], [122615000.0, 0.0003], [122616000.0, 0.0005], [122617000.0, 0.0017], [122618000.0, 0.0032], [122619000.0, 0.0013], [122620000.0, 0.0032]]},
{"timestamp": "1743771668714", "bids": [[122610000.0, 0.4261], [122594000.0, 0.0008], [122564000.0, 0.1448], [122555000.0, 0.0002], [122552000.0, 0.0008], [122540000.0, 0.0001], [122539000.0, 0.0036], [122530000.0, 0.0168], [122520000.0, 0.0001], [122518000.0, 0.0]], "asks": [[122612000.0, 0.0168], [122613000.0, 0.0008], [122614000.0, 0.0009], [122615000.0, 0.0003], [122616000.0, 0.0005], [122617000.0, 0.0017], [122618000.0, 0.0026], [122619000.0, 0.0013], [122620000.0, 0.0032], [122621000.0, 0.0807]]},
{"timestamp": "1743771669219", "bids": [[122610000.0, 0.4261], [122594000.0, 0.0008], [122564000.0, 0.1448], [122555000.0, 0.0002], [122552000.0, 0.0008], [122540000.0, 0.0001], [122539000.0, 0.0036], [122520000.0, 0.0001], [122518000.0, 0.0], [122508000.0, 0.0036]], "asks": [[122612000.0, 0.0168], [122613000.0, 0.0008], [122614000.0, 0.0009], [122615000.0, 0.0003], [122616000.0, 0.0005], [122617000.0, 0.0017], [122618000.0, 0.0026], [122619000.0, 0.0013], [122620000.0, 0.0032], [122621000.0, 0.0807]]},
{"timestamp": "1743771669714", "bids": [[122610000.0, 0.4261], [122594000.0, 0.0008], [122564000.0, 0.1448], [122555000.0, 0.0002], [122552000.0, 0.0008], [122540000.0, 0.0001], [122539000.0, 0.0036], [122520000.0, 0.0001], [122518000.0, 0.0], [122508000.0, 0.0036]], "asks": [[122611000.0, 0.0031], [122612000.0, 0.0168], [122613000.0, 0.0008], [122614000.0, 0.0009], [122615000.0, 0.0003], [122616000.0, 0.0005], [122617000.0, 0.0017], [122618000.0, 0.0026], [122619000.0, 0.0013], [122620000.0, 0.0032]]},
{"timestamp": "1743771670217", "bids": [[122610000.0, 0.4255], [122594000.0, 0.0008], [122564000.0, 0.1448], [122555000.0, 0.0002], [122552000.0, 0.0008], [122540000.0, 0.0001], [122539000.0, 0.0036], [122520000.0, 0.0001], [122519000.0, 0.0168], [122518000.0, 0.0]], "asks": [[122612000.0, 0.0168], [122613000.0, 0.0008], [122614000.0, 0.0009], [122615000.0, 0.0003], [122616000.0, 0.0005], [122617000.0, 0.0017], [122618000.0, 0.0026], [122619000.0, 0.0013], [122620000.0, 0.0922], [122621000.0, 0.0807]]},
{"timestamp": "1743771670713", "bids": [[122610000.0, 0.4255], [122594000.0, 0.0008], [122564000.0, 0.1448], [122555000.0, 0.0002], [122552000.0, 0.0008], [122540000.0, 0.0001], [122539000.0, 0.0036], [122520000.0, 0.0001], [122518000.0, 0.0], [122515000.0, 0.0168]], "asks": [[122612000.0, 0.0168], [122613000.0, 0.0008], [122614000.0, 0.0009], [122615000.0, 0.0003], [122616000.0, 0.0005], [122617000.0, 0.0017], [122618000.0, 0.0026], [122619000.0, 0.0013], [122620000.0, 0.0032], [122621000.0, 0.0807]]},
{"timestamp": "1743771671213", "bids": [[122610000.0, 0.4255], [122594000.0, 0.0008], [122564000.0, 0.1448], [122555000.0, 0.0002], [122552000.0, 0.0008], [122540000.0, 0.0001], [122539000.0, 0.0036], [122520000.0, 0.0001], [122518000.0, 0.0], [122515000.0, 0.0168]], "asks": [[122612000.0, 0.0168], [122613000.0, 0.0008], [122614000.0, 0.0009], [122615000.0, 0.0003], [122616000.0, 0.0005], [122617000.0, 0.0017], [122618000.0, 0.0026], [122619000.0, 0.0013], [122620000.0, 0.0032], [122621000.0, 0.0807]]},
{"timestamp": "1743771671717", "bids": [[122610000.0, 0.4255], [122594000.0, 0.0008], [122564000.0, 0.1448], [122555000.0, 0.0002], [122552000.0, 0.0008], [122540000.0, 0.0001], [122539000.0, 0.0036], [122530000.0, 0.0225], [122520000.0, 0.0001], [122518000.0, 0.0]], "asks": [[122612000.0, 0.0168], [122613000.0, 0.0008], [122614000.0, 0.0009], [122615000.0, 0.0003], [122616000.0, 0.0005], [122617000.0, 0.0017], [122618000.0, 0.0026], [122619000.0, 0.0013], [122620000.0, 0.0032], [122621000.0, 0.0807]]},
{"timestamp": "1743771684239", "bids": [[122612000.0, 0.1307], [122611000.0, 0.01], [122594000.0, 0.0008], [122567000.0, 0.0225], [122566000.0, 0.0002], [122564000.0, 0.1448], [122560000.0, 0.0001], [122555000.0, 0.0002], [122552000.0, 0.0008], [122540000.0, 0.0001]], "asks": [[122615000.0, 0.005], [122616000.0, 0.0005], [122617000.0, 0.0017], [122618000.0, 0.0026], [122619000.0, 0.0013], [122620000.0, 0.0032], [122621000.0, 0.0807], [122622000.0, 0.0154], [122623000.0, 0.0], [122624000.0, 0.0012]]},
{"timestamp": "1743771684723", "bids": [[122612000.0, 0.06], [122611000.0, 0.01], [122594000.0, 0.0008], [122580000.0, 0.0357], [122567000.0, 0.0225], [122566000.0, 0.0002], [122564000.0, 0.1448], [122560000.0, 0.0001], [122555000.0, 0.0002], [122552000.0, 0.0008]], "asks": [[122615000.0, 0.005], [122616000.0, 0.0005], [122617000.0, 0.0017], [122618000.0, 0.0026], [122619000.0, 0.0013], [122620000.0, 0.0032], [122621000.0, 0.0807], [122622000.0, 0.0154], [122623000.0, 0.0], [122624000.0, 0.0012]]},
{"timestamp": "1743771685222", "bids": [[122612000.0, 0.0724], [122611000.0, 0.01], [122594000.0, 0.0008], [122580000.0, 0.0357], [122567000.0, 0.0225], [122566000.0, 0.0002], [122564000.0, 0.1448], [122560000.0, 0.0001], [122555000.0, 0.0002], [122552000.0, 0.0008]], "asks": [[122615000.0, 0.005], [122616000.0, 0.0005], [122617000.0, 0.0017], [122618000.0, 0.0026], [122619000.0, 0.0013], [122620000.0, 0.0032], [122621000.0, 0.0807], [122622000.0, 0.0154], [122623000.0, 0.0], [122624000.0, 0.0012]]},
{"timestamp": "1743771685722", "bids": [[122612000.0, 0.0509], [122611000.0, 0.01], [122594000.0, 0.0008], [122566000.0, 0.0002], [122564000.0, 0.1448], [122560000.0, 0.0001], [122555000.0, 0.0002], [122552000.0, 0.0008], [122545000.0, 0.0128], [122544000.0, 0.0144]], "asks": [[122615000.0, 0.005], [122616000.0, 0.0005], [122617000.0, 0.0017], [122618000.0, 0.0026], [122619000.0, 0.0013], [122620000.0, 0.0032], [122621000.0, 0.0807], [122622000.0, 0.0154], [122623000.0, 0.0], [122624000.0, 0.0012]]},
{"timestamp": "1743771686220", "bids": [[122612000.0, 0.0509], [122611000.0, 0.01], [122594000.0, 0.0008], [122592000.0, 0.005], [122566000.0, 0.0002], [122564000.0, 0.1448], [122560000.0, 0.0001], [122555000.0, 0.0002], [122552000.0, 0.0008], [122545000.0, 0.0128]], "asks": [[122615000.0, 0.005], [122616000.0, 0.0005], [122617000.0, 0.0017], [122618000.0, 0.0026], [122619000.0, 0.0013], [122620000.0, 0.0032], [122621000.0, 0.0807], [122622000.0, 0.0154], [122623000.0, 0.0], [122624000.0, 0.0012]]},
{"timestamp": "1743771686719", "bids": [[122612000.0, 0.0509], [122611000.0, 0.01], [122594000.0, 0.0008], [122592000.0, 0.005], [122567000.0, 0.0225], [122566000.0, 0.0002], [122564000.0, 0.1448], [122560000.0, 0.0001], [122555000.0, 0.0002], [122552000.0, 0.0008]], "asks": [[122615000.0, 0.005], [122616000.0, 0.0005], [122617000.0, 0.0017], [122618000.0, 0.0026], [122619000.0, 0.0013], [122620000.0, 0.0032], [122621000.0, 0.0807], [122622000.0, 0.0154], [122623000.0, 0.0], [122624000.0, 0.0012]]},
{"timestamp": "1743771687219", "bids": [[122620000.0, 0.4118], [122613000.0, 0.1444], [122612000.0, 0.0509], [122611000.0, 0.01], [122594000.0, 0.0008], [122592000.0, 0.005], [122567000.0, 0.0225], [122566000.0, 0.0002], [122564000.0, 0.1448], [122560000.0, 0.0001]], "asks": [[122621000.0, 0.0807], [122622000.0, 0.0154], [122623000.0, 0.0], [122624000.0, 0.0012], [122625000.0, 0.0035], [122626000.0, 0.0085], [122627000.0, 0.0004], [122628000.0, 0.0028], [122629000.0, 0.0013], [122630000.0, 0.0104]]},
{"timestamp": "1743771687722", "bids": [[122620000.0, 0.4118], [122613000.0, 0.1597], [122612000.0, 0.0509], [122611000.0, 0.01], [122594000.0, 0.0008], [122592000.0, 0.005], [122567000.0, 0.0225], [122566000.0, 0.0002], [122565000.0, 0.0651], [122564000.0, 0.1448]], "asks": [[122621000.0, 0.0807], [122622000.0, 0.0154], [122623000.0, 0.0], [122624000.0, 0.0012], [122625000.0, 0.0035], [122626000.0, 0.0085], [122627000.0, 0.0004], [122628000.0, 0.0028], [122629000.0, 0.0013], [122630000.0, 0.0104]]},
{"timestamp": "1743771688221", "bids": [[122620000.0, 0.4316], [122613000.0, 0.1597], [122612000.0, 0.0509], [122611000.0, 0.01], [122594000.0, 0.0008], [122592000.0, 0.005], [122567000.0, 0.0225], [122566000.0, 0.0002], [122565000.0, 0.0651], [122564000.0, 0.1448]], "asks": [[122621000.0, 0.0807], [122622000.0, 0.0154], [122623000.0, 0.0], [122624000.0, 0.0012], [122625000.0, 0.0035], [122626000.0, 0.0085], [122627000.0, 0.0004], [122628000.0, 0.0028], [122629000.0, 0.0013], [122630000.0, 0.0104]]},
{"timestamp": "1743771688721", "bids": [[122620000.0, 0.4323], [122612000.0, 0.0509], [122611000.0, 0.01], [122594000.0, 0.0008], [122592000.0, 0.005], [122571000.0, 0.0143], [122567000.0, 0.0225], [122566000.0, 0.0002], [122565000.0, 0.0652], [122564000.0, 0.1448]], "asks": [[122621000.0, 0.0757], [122622000.0, 0.0154], [122623000.0, 0.0], [122624000.0, 0.0012], [122625000.0, 0.0035], [122626000.0, 0.0085], [122627000.0, 0.0004], [122628000.0, 0.0028], [122629000.0, 0.0013], [122630000.0, 0.0104]]},
{"timestamp": "1743771695723", "bids": [[122654000.0, 0.0041], [122650000.0, 0.0122], [122649000.0, 0.0174], [122648000.0, 0.0021], [122645000.0, 0.0002], [122642000.0, 0.0048], [122641000.0, 0.0851], [122637000.0, 0.0174], [122634000.0, 0.0241], [122633000.0, 0.0002]], "asks": [[122655000.0, 0.0024], [122656000.0, 0.0015], [122658000.0, 0.0005], [122659000.0, 0.0009], [122660000.0, 0.0011], [122662000.0, 0.0037], [122663000.0, 0.0005], [122664000.0, 0.0086], [122665000.0, 0.0], [122666000.0, 0.0016]]},
{"timestamp": "1743771697722", "bids": [[122690000.0, 0.0248], [122687000.0, 0.001], [122686000.0, 0.0177], [122683000.0, 0.0267], [122681000.0, 0.0001], [122673000.0, 0.022], [122672000.0, 0.0101], [122668000.0, 0.0184], [122667000.0, 1.2643], [122659000.0, 0.0167]], "asks": [[122700000.0, 0.7295], [122701000.0, 0.0095], [122702000.0, 0.0095], [122703000.0, 0.0057], [122704000.0, 0.029], [122705000.0, 0.0008], [122706000.0, 0.0002], [122707000.0, 0.0], [122708000.0, 0.0009], [122709000.0, 0.001]]},
{"timestamp": "1743771698225", "bids": [[122698000.0, 0.0002], [122694000.0, 0.0181], [122692000.0, 0.0152], [122690000.0, 0.0248], [122688000.0, 0.0027], [122687000.0, 0.0444], [122686000.0, 0.0177], [122685000.0, 0.0219], [122684000.0, 0.0179], [122683000.0, 0.0267]], "asks": [[122700000.0, 0.7295], [122701000.0, 0.0095], [122702000.0, 0.0095], [122703000.0, 0.0057], [122704000.0, 0.029], [122705000.0, 0.0008], [122706000.0, 0.0002], [122707000.0, 0.0], [122708000.0, 0.0009], [122709000.0, 0.001]]},
{"timestamp": "1743771698723", "bids": [[122698000.0, 0.0002], [122694000.0, 0.0181], [122693000.0, 0.001], [122692000.0, 0.0152], [122690000.0, 0.0248], [122688000.0, 0.0306], [122687000.0, 0.0535], [122686000.0, 0.0385], [122685000.0, 0.0219], [122684000.0, 0.0179]], "asks": [[122700000.0, 0.7295], [122701000.0, 0.0095], [122702000.0, 0.0095], [122703000.0, 0.0057], [122704000.0, 0.029], [122705000.0, 0.0008], [122706000.0, 0.0002], [122707000.0, 0.0], [122708000.0, 0.0009], [122709000.0, 0.001]]},
{"timestamp": "1743771699226", "bids": [[122699000.0, 0.0001], [122698000.0, 0.0002], [122697000.0, 0.0001], [122695000.0, 0.0087], [122694000.0, 0.0181], [122693000.0, 0.001], [122692000.0, 0.0152], [122688000.0, 0.0508], [122687000.0, 0.0761], [122686000.0, 0.0208]], "asks": [[122700000.0, 0.5514], [122701000.0, 0.0095], [122702000.0, 0.0095], [122703000.0, 0.0057], [122704000.0, 0.029], [122705000.0, 0.0008], [122706000.0, 0.0002], [122707000.0, 0.0], [122708000.0, 0.0009], [122709000.0, 0.001]]},
{"timestamp": "1743771699722", "bids": [[122699000.0, 0.0001], [122697000.0, 0.0001], [122695000.0, 0.0252], [122693000.0, 0.001], [122692000.0, 0.0002], [122688000.0, 0.0508], [122687000.0, 0.0491], [122686000.0, 0.0208], [122685000.0, 0.014], [122683000.0, 0.0479]], "asks": [[122700000.0, 0.546], [122701000.0, 0.0095], [122702000.0, 0.0095], [122703000.0, 0.0057], [122704000.0, 0.029], [122705000.0, 0.0008], [122706000.0, 0.0002], [122707000.0, 0.0], [122708000.0, 0.0009], [122709000.0, 0.001]]},
{"timestamp": "1743771700224", "bids": [[122699000.0, 0.0226], [122697000.0, 0.0001], [122695000.0, 0.0252], [122693000.0, 0.001], [122692000.0, 0.0002], [122690000.0, 0.0163], [122688000.0, 0.0481], [122687000.0, 0.0234], [122685000.0, 0.014], [122677000.0, 0.0361]], "asks": [[122700000.0, 0.4337], [122701000.0, 0.0095], [122702000.0, 0.0095], [122703000.0, 0.0057], [122704000.0, 0.029], [122705000.0, 0.0008], [122706000.0, 0.0002], [122707000.0, 0.0], [122708000.0, 0.0009], [122709000.0, 0.001]]},
{"timestamp": "1743771700722", "bids": [[122722000.0, 0.0172], [122711000.0, 0.7438], [122701000.0, 0.0001], [122699000.0, 0.1447], [122696000.0, 0.0252], [122695000.0, 0.0252], [122692000.0, 0.0002], [122691000.0, 0.0167], [122690000.0, 0.0163], [122688000.0, 0.0279]], "asks": [[122723000.0, 0.5464], [122724000.0, 0.0146], [122725000.0, 0.0], [122726000.0, 0.0012], [122727000.0, 0.0016], [122728000.0, 0.0024], [122729000.0, 0.0001], [122730000.0, 0.0047], [122732000.0, 0.0023], [122733000.0, 0.0041]]},
{"timestamp": "1743771701227", "bids": [[122722000.0, 0.0172], [122718000.0, 0.0229], [122717000.0, 0.0167], [122713000.0, 0.023], [122711000.0, 0.7771], [122709000.0, 0.0345], [122706000.0, 0.0123], [122701000.0, 0.0249], [122699000.0, 0.1958], [122696000.0, 0.0252]], "asks": [[122723000.0, 0.4714], [122724000.0, 0.0146], [122725000.0, 0.0], [122726000.0, 0.0012], [122727000.0, 0.0016], [122728000.0, 0.0024], [122729000.0, 0.0001], [122730000.0, 0.0047], [122732000.0, 0.0023], [122733000.0, 0.0041]]},
{"timestamp": "1743771701722", "bids": [[122722000.0, 0.0172], [122718000.0, 0.0229], [122717000.0, 0.0167], [122715000.0, 0.0175], [122713000.0, 0.023], [122712000.0, 0.0036], [122711000.0, 0.0636], [122709000.0, 0.0345], [122706000.0, 0.0123], [122701000.0, 0.0251]], "asks": [[122723000.0, 0.4506], [122724000.0, 0.0146], [122725000.0, 0.0], [122726000.0, 0.0012], [122727000.0, 0.0016], [122728000.0, 0.0024], [122729000.0, 0.0001], [122730000.0, 0.0047], [122732000.0, 0.0023], [122733000.0, 0.0041]]},
{"timestamp": "1743771702224", "bids": [[122722000.0, 0.0018], [122718000.0, 0.0229], [122717000.0, 0.0167], [122715000.0, 0.0337], [122713000.0, 0.023], [122712000.0, 0.0036], [122711000.0, 0.086], [122709000.0, 0.0345], [122708000.0, 0.0227], [122706000.0, 0.0263]], "asks": [[122723000.0, 0.4505], [122724000.0, 0.0146], [122725000.0, 0.0], [122726000.0, 0.0012], [122727000.0, 0.0016], [122728000.0, 0.0024], [122729000.0, 0.0001], [122730000.0, 0.0047], [122732000.0, 0.0023], [122733000.0, 0.0041]]},
{"timestamp": "1743771702731", "bids": [[122722000.0, 0.0018], [122718000.0, 0.0229], [122715000.0, 0.0533], [122714000.0, 0.0001], [122712000.0, 0.0036], [122711000.0, 0.1025], [122710000.0, 0.0292], [122709000.0, 0.017], [122708000.0, 0.0227], [122706000.0, 0.014]], "asks": [[122723000.0, 0.4493], [122724000.0, 0.0146], [122725000.0, 0.0], [122726000.0, 0.0012], [122727000.0, 0.0016], [122728000.0, 0.0024], [122729000.0, 0.0001], [122730000.0, 0.0047], [122732000.0, 0.0023], [122733000.0, 0.0041]]},
{"timestamp": "1743771727734", "bids": [[122823000.0, 0.0042], [122811000.0, 0.0141], [122810000.0, 0.1596], [122801000.0, 0.0001], [122798000.0, 0.0001], [122797000.0, 0.0001], [122793000.0, 0.0229], [122791000.0, 0.0125], [122785000.0, 0.0002], [122782000.0, 0.01]], "asks": [[122824000.0, 0.0016], [122825000.0, 0.011], [122826000.0, 0.0123], [122827000.0, 0.004], [122828000.0, 0.0058], [122829000.0, 0.0], [122830000.0, 0.0045], [122831000.0, 0.0237], [122832000.0, 0.0005], [122833000.0, 0.0006]]},
{"timestamp": "1743771732231", "bids": [[122877000.0, 0.0167], [122876000.0, 0.0003], [122873000.0, 0.0328], [122870000.0, 0.0241], [122868000.0, 0.0001], [122865000.0, 0.0185], [122864000.0, 0.0073], [122863000.0, 0.0169], [122862000.0, 0.0295], [122859000.0, 0.0006]], "asks": [[122880000.0, 0.0363], [122881000.0, 0.0083], [122882000.0, 0.006], [122883000.0, 0.0016], [122884000.0, 0.0028], [122885000.0, 0.0004], [122886000.0, 0.0029], [122887000.0, 0.0013], [122888000.0, 0.0], [122890000.0, 0.0001]]},
{"timestamp": "1743771732738", "bids": [[122877000.0, 0.0167], [122876000.0, 0.0003], [122873000.0, 0.0328], [122870000.0, 0.0241], [122868000.0, 0.0001], [122865000.0, 0.0185], [122864000.0, 0.0073], [122863000.0, 0.0169], [122862000.0, 0.0295], [122859000.0, 0.0006]], "asks": [[122880000.0, 0.0241], [122881000.0, 0.0083], [122882000.0, 0.006], [122883000.0, 0.0016], [122884000.0, 0.0028], [122885000.0, 0.0004], [122886000.0, 0.0029], [122887000.0, 0.0013], [122888000.0, 0.0], [122890000.0, 0.0001]]},
{"timestamp": "1743771733233", "bids": [[122880000.0, 0.199], [122877000.0, 0.0166], [122876000.0, 0.0003], [122873000.0, 0.0328], [122870000.0, 0.0241], [122869000.0, 0.0246], [122868000.0, 0.0001], [122865000.0, 0.0185], [122863000.0, 0.0169], [122862000.0, 0.0003]], "asks": [[122881000.0, 0.0083], [122882000.0, 0.006], [122883000.0, 0.0016], [122884000.0, 0.0028], [122885000.0, 0.0004], [122886000.0, 0.0029], [122887000.0, 0.0013], [122888000.0, 0.0], [122890000.0, 0.0001], [122891000.0, 0.0008]]},
{"timestamp": "1743771733740", "bids": [[122880000.0, 0.199], [122878000.0, 0.0015], [122877000.0, 0.0166], [122876000.0, 0.0003], [122873000.0, 0.0328], [122870000.0, 0.0241], [122869000.0, 0.0246], [122868000.0, 0.0001], [122865000.0, 0.0185], [122863000.0, 0.0169]], "asks": [[122881000.0, 0.0051], [122882000.0, 0.006], [122883000.0, 0.0016], [122884000.0, 0.0028], [122885000.0, 0.0004], [122886000.0, 0.0029], [122887000.0, 0.0013], [122888000.0, 0.0], [122890000.0, 0.0001], [122891000.0, 0.0008]]},
{"timestamp": "1743771734233", "bids": [[122880000.0, 0.199], [122878000.0, 0.0015], [122877000.0, 0.0166], [122876000.0, 0.0003], [122873000.0, 0.0328], [122870000.0, 0.0241], [122869000.0, 0.0246], [122868000.0, 0.0001], [122865000.0, 0.0185], [122863000.0, 0.0169]], "asks": [[122882000.0, 0.0054], [122883000.0, 0.0016], [122884000.0, 0.0028], [122885000.0, 0.0004], [122886000.0, 0.0029], [122887000.0, 0.0013], [122888000.0, 0.0], [122890000.0, 0.0001], [122891000.0, 0.0008], [122892000.0, 0.0001]]},
{"timestamp": "1743771743230", "bids": [[122900000.0, 0.0008], [122899000.0, 0.0017], [122893000.0, 0.004], [122891000.0, 0.0116], [122890000.0, 0.1595], [122887000.0, 0.0002], [122881000.0, 0.0019], [122880000.0, 0.0002], [122879000.0, 0.0321], [122878000.0, 0.0008]], "asks": [[122904000.0, 0.0078], [122905000.0, 0.0027], [122906000.0, 0.0004], [122907000.0, 0.0014], [122909000.0, 0.0018], [122910000.0, 0.0068], [122911000.0, 0.0091], [122912000.0, 0.0001], [122913000.0, 0.0016], [122914000.0, 0.0]]},
{"timestamp": "1743771743738", "bids": [[122900000.0, 0.0008], [122899000.0, 0.0006], [122893000.0, 0.004], [122891000.0, 0.0116], [122890000.0, 0.1595], [122887000.0, 0.0001], [122881000.0, 0.0019], [122880000.0, 0.0002], [122879000.0, 0.0321], [122878000.0, 0.0008]], "asks": [[122904000.0, 0.0078], [122905000.0, 0.0027], [122906000.0, 0.0004], [122907000.0, 0.0014], [122909000.0, 0.0018], [122910000.0, 0.0068], [122911000.0, 0.0091], [122912000.0, 0.0001], [122913000.0, 0.0016], [122914000.0, 0.0]]},
{"timestamp": "1743771746242", "bids": [[122900000.0, 0.0024], [122893000.0, 0.004], [122890000.0, 0.1595], [122881000.0, 0.0019], [122878000.0, 0.0008], [122876000.0, 0.0161], [122869000.0, 0.1316], [122857000.0, 0.0248], [122855000.0, 0.0001], [122848000.0, 0.0001]], "asks": [[122904000.0, 0.0074], [122905000.0, 0.0027], [122906000.0, 0.0004], [122907000.0, 0.0014], [122909000.0, 0.0018], [122910000.0, 0.0093], [122911000.0, 0.0091], [122912000.0, 0.0001], [122913000.0, 0.0016], [122914000.0, 0.0]]},
{"timestamp": "1743771751738", "bids": [[122800000.0, 0.0275], [122791000.0, 0.0077], [122784000.0, 0.0001], [122783000.0, 0.0238], [122782000.0, 0.01], [122781000.0, 0.0008], [122780000.0, 0.0168], [122779000.0, 0.0234], [122778000.0, 0.0], [122776000.0, 0.056]], "asks": [[122833000.0, 0.0178], [122862000.0, 0.0128], [122869000.0, 0.0002], [122877000.0, 0.0187], [122880000.0, 0.0178], [122883000.0, 0.0216], [122884000.0, 0.0222], [122889000.0, 0.0479], [122890000.0, 0.7349], [122891000.0, 0.0143]]},
{"timestamp": "1743771752240", "bids": [[122800000.0, 0.0234], [122791000.0, 0.0077], [122784000.0, 0.0], [122783000.0, 0.0238], [122782000.0, 0.01], [122781000.0, 0.0008], [122780000.0, 0.0168], [122778000.0, 0.0], [122776000.0, 0.0323], [122774000.0, 0.0016]], "asks": [[122833000.0, 0.0178], [122835000.0, 0.0089], [122851000.0, 0.0002], [122852000.0, 0.0001], [122857000.0, 0.0185], [122862000.0, 0.0128], [122863000.0, 0.0013], [122869000.0, 0.0002], [122870000.0, 0.0232], [122876000.0, 0.1004]]},
{"timestamp": "1743771752740", "bids": [[122800000.0, 0.0234], [122791000.0, 0.0077], [122784000.0, 0.0], [122783000.0, 0.0238], [122782000.0, 0.01], [122781000.0, 0.0008], [122780000.0, 0.0166], [122778000.0, 0.0], [122776000.0, 0.0323], [122774000.0, 0.0016]], "asks": [[122833000.0, 0.0179], [122835000.0, 0.0089], [122851000.0, 0.0004], [122852000.0, 0.0002], [122857000.0, 0.0185], [122863000.0, 0.0013], [122869000.0, 0.0002], [122870000.0, 0.0232], [122876000.0, 0.1004], [122877000.0, 0.0187]]},
{"timestamp": "1743771753241", "bids": [[122783000.0, 0.022], [122782000.0, 0.01], [122781000.0, 0.0008], [122780000.0, 0.0166], [122778000.0, 0.0], [122776000.0, 0.0323], [122774000.0, 0.0016], [122770000.0, 0.0001], [122767000.0, 0.0335], [122762000.0, 0.0]], "asks": [[122832000.0, 0.0007], [122833000.0, 0.0179], [122835000.0, 0.0089], [122851000.0, 0.0004], [122852000.0, 0.0126], [122857000.0, 0.0185], [122858000.0, 0.0266], [122861000.0, 0.0845], [122863000.0, 0.0013], [122869000.0, 0.0004]]},
{"timestamp": "1743771753739", "bids": [[122818000.0, 0.0036], [122815000.0, 0.0008], [122793000.0, 0.0225], [122791000.0, 0.0003], [122787000.0, 0.0036], [122783000.0, 0.022], [122782000.0, 0.01], [122781000.0, 0.0005], [122778000.0, 0.0], [122776000.0, 0.0321]], "asks": [[122832000.0, 0.0017], [122833000.0, 0.0179], [122835000.0, 0.0089], [122851000.0, 0.0144], [122852000.0, 0.0002], [122855000.0, 0.0174], [122857000.0, 0.0185], [122858000.0, 0.0005], [122861000.0, 0.0845], [122869000.0, 0.0163]]},
{"timestamp": "1743771754236", "bids": [[122818000.0, 0.0036], [122815000.0, 0.0008], [122793000.0, 0.0225], [122791000.0, 0.0003], [122787000.0, 0.0036], [122782000.0, 0.01], [122781000.0, 0.0005], [122778000.0, 0.0], [122774000.0, 0.0016], [122762000.0, 0.0]], "asks": [[122832000.0, 0.0017], [122833000.0, 0.0177], [122850000.0, 0.0182], [122851000.0, 0.0144], [122852000.0, 0.0167], [122855000.0, 0.0174], [122856000.0, 0.0128], [122857000.0, 0.0362], [122858000.0, 0.0005], [122861000.0, 0.0845]]},
{"timestamp": "1743771754736", "bids": [[122818000.0, 0.0036], [122815000.0, 0.0008], [122793000.0, 0.0225], [122791000.0, 0.0003], [122787000.0, 0.0036], [122782000.0, 0.01], [122781000.0, 0.0005], [122778000.0, 0.0], [122774000.0, 0.0016], [122762000.0, 0.0053]], "asks": [[122832000.0, 0.0017], [122834000.0, 0.0339], [122836000.0, 0.0423], [122850000.0, 0.0182], [122851000.0, 0.0987], [122852000.0, 0.0166], [122856000.0, 0.0128], [122857000.0, 0.053], [122858000.0, 0.0005], [122860000.0, 0.0175]]},
{"timestamp": "1743771755238", "bids": [[122791000.0, 0.0003], [122787000.0, 0.0036], [122782000.0, 0.01], [122781000.0, 0.0005], [122778000.0, 0.0], [122774000.0, 0.0016], [122762000.0, 0.0053], [122761000.0, 0.017], [122760000.0, 0.0009], [122756000.0, 0.0423]], "asks": [[122831000.0, 0.0855], [122834000.0, 0.0339], [122836000.0, 0.0423], [122841000.0, 0.0089], [122848000.0, 0.0124], [122850000.0, 0.0182], [122851000.0, 0.0985], [122852000.0, 0.0166], [122856000.0, 0.0128], [122857000.0, 0.0535]]},
{"timestamp": "1743771755737", "bids": [[122791000.0, 0.0003], [122787000.0, 0.0036], [122782000.0, 0.01], [122781000.0, 0.0005], [122778000.0, 0.0], [122774000.0, 0.0016], [122762000.0, 0.0], [122761000.0, 0.017], [122760000.0, 0.0009], [122759000.0, 0.0001]], "asks": [[122827000.0, 0.0002], [122831000.0, 0.0855], [122834000.0, 0.0167], [122836000.0, 0.0196], [122839000.0, 0.0188], [122841000.0, 0.0089], [122846000.0, 0.0001], [122848000.0, 0.034], [122849000.0, 0.1066], [122854000.0, 0.0208]]},
{"timestamp": "1743771756243", "bids": [[122791000.0, 0.0003], [122787000.0, 0.0036], [122782000.0, 0.01], [122781000.0, 0.0005], [122778000.0, 0.0], [122774000.0, 0.0016], [122762000.0, 0.0], [122761000.0, 0.017], [122760000.0, 0.0009], [122759000.0, 0.0001]], "asks": [[122827000.0, 0.0179], [122839000.0, 0.0188], [122841000.0, 0.0089], [122845000.0, 0.0002], [122846000.0, 0.0001], [122848000.0, 0.0514], [122849000.0, 0.1066], [122850000.0, 0.0185], [122851000.0, 0.0005], [122854000.0, 0.0208]]},
{"timestamp": "1743771756741", "bids": [[122791000.0, 0.0003], [122787000.0, 0.0036], [122782000.0, 0.01], [122781000.0, 0.0005], [122778000.0, 0.0], [122774000.0, 0.0016], [122762000.0, 0.0], [122761000.0, 0.017], [122760000.0, 0.0009], [122759000.0, 0.0001]], "asks": [[122826000.0, 0.0179], [122827000.0, 0.0179], [122835000.0, 0.0844], [122839000.0, 0.0188], [122841000.0, 0.0089], [122843000.0, 0.0128], [122845000.0, 0.0144], [122846000.0, 0.0001], [122848000.0, 0.0514], [122849000.0, 0.1066]]},
{"timestamp": "1743771757244", "bids": [[122791000.0, 0.0003], [122787000.0, 0.0036], [122782000.0, 0.01], [122781000.0, 0.0005], [122778000.0, 0.0], [122774000.0, 0.0016], [122762000.0, 0.0], [122761000.0, 0.017], [122760000.0, 0.0009], [122756000.0, 0.0262]], "asks": [[122824000.0, 0.0227], [122826000.0, 0.0249], [122827000.0, 0.0177], [122835000.0, 0.0844], [122841000.0, 0.0089], [122843000.0, 0.0128], [122845000.0, 0.0321], [122846000.0, 0.0002], [122848000.0, 0.039], [122850000.0, 0.0185]]},
{"timestamp": "1743771757741", "bids": [[122791000.0, 0.0003], [122787000.0, 0.0036], [122782000.0, 0.01], [122781000.0, 0.0005], [122778000.0, 0.0], [122774000.0, 0.0016], [122762000.0, 0.0], [122761000.0, 0.017], [122760000.0, 0.0009], [122756000.0, 0.0262]], "asks": [[122822000.0, 0.0167], [122824000.0, 0.0227], [122826000.0, 0.0249], [122835000.0, 0.0844], [122839000.0, 0.0182], [122840000.0, 0.0166], [122843000.0, 0.0128], [122845000.0, 0.036], [122846000.0, 0.0172], [122848000.0, 0.0266]]},
{"timestamp": "1743771758242", "bids": [[122791000.0, 0.0003], [122787000.0, 0.0036], [122782000.0, 0.01], [122781000.0, 0.0005], [122778000.0, 0.0], [122774000.0, 0.0016], [122762000.0, 0.0], [122761000.0, 0.017], [122760000.0, 0.0009], [122756000.0, 0.0262]], "asks": [[122822000.0, 0.0167], [122823000.0, 0.0167], [122824000.0, 0.0423], [122838000.0, 0.0844], [122839000.0, 0.0182], [122840000.0, 0.0166], [122843000.0, 0.0124], [122845000.0, 0.0358], [122846000.0, 0.0345], [122848000.0, 0.0441]]},
{"timestamp": "1743771758739", "bids": [[122791000.0, 0.0003], [122787000.0, 0.0036], [122782000.0, 0.01], [122781000.0, 0.0005], [122778000.0, 0.0], [122774000.0, 0.0016], [122762000.0, 0.0], [122761000.0, 0.017], [122760000.0, 0.0009], [122756000.0, 0.0262]], "asks": [[122823000.0, 0.0167], [122824000.0, 0.0375], [122829000.0, 0.0188], [122838000.0, 0.0844], [122839000.0, 0.0222], [122842000.0, 0.0216], [122843000.0, 0.0001], [122846000.0, 0.0174], [122847000.0, 0.0185], [122848000.0, 0.0175]]},
{"timestamp": "1743771759239", "bids": [[122761000.0, 0.0045], [122760000.0, 0.0009], [122758000.0, 0.0004], [122756000.0, 0.0036], [122750000.0, 0.0026], [122749000.0, 0.0016], [122748000.0, 0.0], [122747000.0, 0.0002], [122746000.0, 0.0], [122744000.0, 0.0164]], "asks": [[122821000.0, 0.0817], [122824000.0, 0.018], [122828000.0, 0.0089], [122829000.0, 0.0188], [122837000.0, 0.0128], [122839000.0, 0.119], [122842000.0, 0.0216], [122843000.0, 0.0001], [122844000.0, 0.0208], [122847000.0, 0.0185]]},
{"timestamp": "1743771759738", "bids": [[122761000.0, 0.0045], [122760000.0, 0.0009], [122758000.0, 0.0004], [122756000.0, 0.0036], [122750000.0, 0.0024], [122749000.0, 0.0016], [122748000.0, 0.0], [122747000.0, 0.0002], [122746000.0, 0.0], [122744000.0, 0.0004]], "asks": [[122816000.0, 0.0168], [122818000.0, 0.0227], [122821000.0, 0.0817], [122824000.0, 0.0003], [122826000.0, 0.0266], [122828000.0, 0.0089], [122831000.0, 0.0166], [122833000.0, 0.0182], [122836000.0, 0.0002], [122837000.0, 0.0129]]},
{"timestamp": "1743771760240", "bids": [[122761000.0, 0.0045], [122760000.0, 0.0009], [122756000.0, 0.0036], [122750000.0, 0.0024], [122749000.0, 0.0016], [122748000.0, 0.0], [122746000.0, 0.0], [122744000.0, 0.0004], [122741000.0, 0.0165], [122740000.0, 0.0]], "asks": [[122816000.0, 0.0168], [122818000.0, 0.0227], [122820000.0, 0.0124], [122821000.0, 0.0817], [122824000.0, 0.0001], [122826000.0, 0.0266], [122828000.0, 0.0933], [122831000.0, 0.0166], [122833000.0, 0.0182], [122836000.0, 0.0002]]},
{"timestamp": "1743771760738", "bids": [[122761000.0, 0.0002], [122760000.0, 0.0009], [122756000.0, 0.0036], [122750000.0, 0.0024], [122749000.0, 0.0016], [122748000.0, 0.0], [122746000.0, 0.0], [122744000.0, 0.0004], [122741000.0, 0.0226], [122740000.0, 0.0]], "asks": [[122791000.0, 0.0003], [122801000.0, 0.0177], [122816000.0, 0.0164], [122818000.0, 0.0227], [122820000.0, 0.0124], [122823000.0, 0.0174], [122824000.0, 0.0001], [122826000.0, 0.0266], [122828000.0, 0.2281], [122829000.0, 0.0001]]},
{"timestamp": "1743771761246", "bids": [[122760000.0, 0.0003], [122756000.0, 0.0036], [122750000.0, 0.0024], [122749000.0, 0.0016], [122748000.0, 0.0], [122746000.0, 0.0], [122744000.0, 0.0004], [122741000.0, 0.0226], [122740000.0, 0.0], [122739000.0, 0.0074]], "asks": [[122791000.0, 0.0003], [122801000.0, 0.0177], [122820000.0, 0.0124], [122823000.0, 0.0174], [122824000.0, 0.0001], [122828000.0, 0.2192], [122829000.0, 0.0001], [122837000.0, 0.0159], [122838000.0, 0.135], [122840000.0, 0.0195]]},
{"timestamp": "1743771761741", "bids": [[122760000.0, 0.0003], [122756000.0, 0.0036], [122750000.0, 0.0065], [122749000.0, 0.0016], [122748000.0, 0.0], [122746000.0, 0.0], [122744000.0, 0.0004], [122741000.0, 0.0226], [122740000.0, 0.0], [122738000.0, 0.0016]], "asks": [[122791000.0, 0.0003], [122801000.0, 0.0177], [122802000.0, 0.0167], [122803000.0, 0.0196], [122806000.0, 0.0188], [122815000.0, 0.1058], [122820000.0, 0.0124], [122823000.0, 0.0174], [122824000.0, 0.0001], [122825000.0, 0.0152]]},
{"timestamp": "1743771762243", "bids": [[122761000.0, 0.004], [122760000.0, 0.0003], [122756000.0, 0.0037], [122750000.0, 0.0075], [122749000.0, 0.0016], [122748000.0, 0.0], [122746000.0, 0.0], [122744000.0, 0.0004], [122742000.0, 0.0004], [122741000.0, 0.0226]], "asks": [[122791000.0, 0.0003], [122801000.0, 0.0177], [122802000.0, 0.0167], [122803000.0, 0.0196], [122806000.0, 0.0188], [122811000.0, 0.0002], [122815000.0, 0.1058], [122824000.0, 0.0001], [122825000.0, 0.0152], [122826000.0, 0.0583]]},
{"timestamp": "1743771762739", "bids": [[122762000.0, 0.0018], [122761000.0, 0.004], [122760000.0, 0.0003], [122756000.0, 0.0037], [122750000.0, 0.0075], [122749000.0, 0.0016], [122748000.0, 0.0], [122746000.0, 0.0], [122744000.0, 0.0004], [122742000.0, 0.0004]], "asks": [[122791000.0, 0.0003], [122802000.0, 0.0167], [122803000.0, 0.0196], [122806000.0, 0.0188], [122811000.0, 0.0002], [122815000.0, 0.1058], [122824000.0, 0.0001], [122825000.0, 0.0152], [122826000.0, 0.0583], [122827000.0, 0.0355]]},
{"timestamp": "1743771763241", "bids": [[122762000.0, 0.0018], [122761000.0, 0.0057], [122760000.0, 0.0003], [122756000.0, 0.0037], [122754000.0, 0.0016], [122753000.0, 0.0008], [122750000.0, 0.0075], [122749000.0, 0.0016], [122748000.0, 0.0], [122746000.0, 0.0]], "asks": [[122791000.0, 0.0003], [122802000.0, 0.0167], [122803000.0, 0.0196], [122806000.0, 0.0188], [122811000.0, 0.0002], [122815000.0, 0.1058], [122822000.0, 0.0164], [122824000.0, 0.0001], [122825000.0, 0.0152], [122826000.0, 0.0583]]},
{"timestamp": "1743771763741", "bids": [[122760000.0, 0.0003], [122756000.0, 0.0037], [122754000.0, 0.0016], [122753000.0, 0.0008], [122750000.0, 0.0075], [122749000.0, 0.0016], [122748000.0, 0.0], [122746000.0, 0.0], [122744000.0, 0.0004], [122743000.0, 0.0224]], "asks": [[122761000.0, 0.0166], [122791000.0, 0.0003], [122802000.0, 0.0167], [122803000.0, 0.0196], [122819000.0, 0.0842], [122820000.0, 0.0001], [122822000.0, 0.0164], [122824000.0, 0.0001], [122826000.0, 0.0583], [122827000.0, 0.0355]]},
{"timestamp": "1743771764250", "bids": [[122760000.0, 0.0003], [122756000.0, 0.0037], [122754000.0, 0.0016], [122753000.0, 0.0008], [122751000.0, 0.0074], [122750000.0, 0.0075], [122749000.0, 0.0016], [122748000.0, 0.0001], [122746000.0, 0.0], [122744000.0, 0.0004]], "asks": [[122761000.0, 0.0165], [122791000.0, 0.0003], [122819000.0, 0.0842], [122820000.0, 0.0001], [122822000.0, 0.0164], [122824000.0, 0.0001], [122827000.0, 0.0227], [122829000.0, 0.0001], [122831000.0, 0.0089], [122840000.0, 0.0024]]},
{"timestamp": "1743771764742", "bids": [[122763000.0, 0.0425], [122760000.0, 0.0012], [122756000.0, 0.0037], [122754000.0, 0.0016], [122753000.0, 0.0008], [122751000.0, 0.0074], [122750000.0, 0.0076], [122749000.0, 0.0016], [122748000.0, 0.0001], [122746000.0, 0.0]], "asks": [[122791000.0, 0.0003], [122819000.0, 0.0842], [122820000.0, 0.0001], [122824000.0, 0.0001], [122829000.0, 0.0001], [122831000.0, 0.0089], [122840000.0, 0.0024], [122846000.0, 0.0177], [122847000.0, 0.0124], [122848000.0, 0.0208]]},
{"timestamp": "1743771765751", "bids": [[122799000.0, 0.0159], [122788000.0, 0.0166], [122787000.0, 0.0192], [122785000.0, 0.0172], [122781000.0, 0.0321], [122776000.0, 0.0003], [122775000.0, 0.0001], [122770000.0, 0.0005], [122769000.0, 0.0252], [122768000.0, 0.0236]], "asks": [[122820000.0, 0.0001], [122824000.0, 0.0001], [122829000.0, 0.0001], [122840000.0, 0.0024], [122841000.0, 0.0839], [122856000.0, 0.0001], [122857000.0, 0.0001], [122860000.0, 0.0172], [122872000.0, 0.0], [122879000.0, 0.0198]]},
{"timestamp": "1743771766246", "bids": [[122807000.0, 0.0004], [122799000.0, 0.0065], [122797000.0, 0.0041], [122788000.0, 0.0166], [122787000.0, 0.0192], [122785000.0, 0.0172], [122781000.0, 0.0321], [122780000.0, 0.0329], [122776000.0, 0.0003], [122775000.0, 0.0001]], "asks": [[122820000.0, 0.0001], [122824000.0, 0.0001], [122829000.0, 0.0001], [122840000.0, 0.0024], [122841000.0, 0.0839], [122856000.0, 0.0001], [122857000.0, 0.0001], [122860000.0, 0.0001], [122872000.0, 0.0], [122876000.0, 0.0227]]},
{"timestamp": "1743771766743", "bids": [[122787000.0, 0.0129], [122785000.0, 0.0172], [122781000.0, 0.0321], [122780000.0, 0.0329], [122776000.0, 0.0003], [122775000.0, 0.0001], [122773000.0, 0.0004], [122770000.0, 0.0005], [122769000.0, 0.0252], [122767000.0, 0.0325]], "asks": [[122820000.0, 0.0001], [122824000.0, 0.0001], [122829000.0, 0.0001], [122840000.0, 0.0024], [122841000.0, 0.0839], [122856000.0, 0.0001], [122857000.0, 0.0001], [122860000.0, 0.0001], [122869000.0, 0.0164], [122872000.0, 0.0]]},
{"timestamp": "1743771768250", "bids": [[122788000.0, 0.0004], [122781000.0, 0.032], [122780000.0, 0.0329], [122779000.0, 0.0365], [122776000.0, 0.0003], [122775000.0, 0.0001], [122773000.0, 0.0243], [122769000.0, 0.0252], [122767000.0, 0.0325], [122762000.0, 0.0948]], "asks": [[122800000.0, 0.3207], [122824000.0, 0.0001], [122829000.0, 0.0001], [122840000.0, 0.0024], [122856000.0, 0.0001], [122857000.0, 0.0001], [122860000.0, 0.0001], [122869000.0, 0.0164], [122871000.0, 0.0222], [122872000.0, 0.0]]},
{"timestamp": "1743771768744", "bids": [[122788000.0, 0.0004], [122787000.0, 0.0002], [122781000.0, 0.032], [122780000.0, 0.0329], [122779000.0, 0.0366], [122775000.0, 0.0001], [122773000.0, 0.0243], [122762000.0, 0.0758], [122761000.0, 0.0028], [122760000.0, 0.01]], "asks": [[122800000.0, 0.3042], [122824000.0, 0.0001], [122829000.0, 0.0001], [122840000.0, 0.0024], [122856000.0, 0.0001], [122857000.0, 0.0001], [122860000.0, 0.0001], [122871000.0, 0.022], [122872000.0, 0.0], [122875000.0, 0.0167]]},
{"timestamp": "1743771769248", "bids": [[122797000.0, 0.0001], [122793000.0, 0.0335], [122789000.0, 0.0321], [122788000.0, 0.0004], [122787000.0, 0.0171], [122781000.0, 0.0319], [122779000.0, 0.0366], [122773000.0, 0.0242], [122761000.0, 0.0028], [122760000.0, 0.01]], "asks": [[122800000.0, 0.3041], [122824000.0, 0.0001], [122829000.0, 0.0001], [122840000.0, 0.0024], [122856000.0, 0.0001], [122857000.0, 0.0001], [122860000.0, 0.0001], [122872000.0, 0.0], [122880000.0, 0.0024], [122888000.0, 0.0008]]},
{"timestamp": "1743771769745", "bids": [[122797000.0, 0.0001], [122793000.0, 0.0335], [122789000.0, 0.0326], [122788000.0, 0.0004], [122787000.0, 0.0817], [122783000.0, 0.0185], [122781000.0, 0.074], [122778000.0, 0.0028], [122777000.0, 0.0005], [122775000.0, 0.0502]], "asks": [[122800000.0, 0.2743], [122824000.0, 0.0001], [122829000.0, 0.0001], [122840000.0, 0.0024], [122856000.0, 0.0001], [122857000.0, 0.0001], [122860000.0, 0.0001], [122872000.0, 0.0], [122880000.0, 0.0024], [122886000.0, 0.0002]]},
{"timestamp": "1743771770245", "bids": [[122798000.0, 0.0002], [122797000.0, 0.0253], [122796000.0, 0.0001], [122794000.0, 0.0237], [122793000.0, 0.0335], [122789000.0, 0.0326], [122788000.0, 0.0246], [122787000.0, 0.0817], [122783000.0, 0.0185], [122782000.0, 0.0001]], "asks": [[122800000.0, 0.2743], [122824000.0, 0.0001], [122829000.0, 0.0001], [122840000.0, 0.0024], [122856000.0, 0.0001], [122857000.0, 0.0001], [122860000.0, 0.0001], [122872000.0, 0.0], [122880000.0, 0.0024], [122884000.0, 0.0164]]},
{"timestamp": "1743771770743", "bids": [[122798000.0, 0.0002], [122797000.0, 0.0253], [122796000.0, 0.0001], [122794000.0, 0.0365], [122793000.0, 0.0335], [122789000.0, 0.0326], [122788000.0, 0.0247], [122787000.0, 0.0817], [122783000.0, 0.0185], [122782000.0, 0.0001]], "asks": [[122800000.0, 0.1146], [122817000.0, 0.0036], [122824000.0, 0.0001], [122829000.0, 0.0001], [122840000.0, 0.0024], [122848000.0, 0.0036], [122856000.0, 0.0001], [122857000.0, 0.0001], [122860000.0, 0.0001], [122872000.0, 0.0]]},
{"timestamp": "1743771771247", "bids": [[122799000.0, 0.0369], [122798000.0, 0.0002], [122797000.0, 0.0253], [122796000.0, 0.0001], [122794000.0, 0.0365], [122793000.0, 0.0335], [122789000.0, 0.0326], [122788000.0, 0.0247], [122787000.0, 0.0817], [122783000.0, 0.0185]], "asks": [[122800000.0, 0.1146], [122817000.0, 0.0036], [122824000.0, 0.0001], [122829000.0, 0.0001], [122840000.0, 0.0024], [122848000.0, 0.0036], [122856000.0, 0.0001], [122857000.0, 0.0001], [122860000.0, 0.0001], [122872000.0, 0.0]]},
{"timestamp": "1743771771743", "bids": [[122799000.0, 0.0369], [122798000.0, 0.0002], [122797000.0, 0.0253], [122796000.0, 0.0001], [122794000.0, 0.0366], [122793000.0, 0.0335], [122789000.0, 0.0326], [122788000.0, 0.0247], [122787000.0, 0.0817], [122783000.0, 0.0185]], "asks": [[122800000.0, 0.0068], [122817000.0, 0.0036], [122824000.0, 0.0001], [122829000.0, 0.0001], [122840000.0, 0.0024], [122848000.0, 0.0036], [122856000.0, 0.0001], [122857000.0, 0.0001], [122860000.0, 0.0001], [122872000.0, 0.0]]},
{"timestamp": "1743771772244", "bids": [[122798000.0, 0.0002], [122797000.0, 0.0253], [122796000.0, 0.0001], [122794000.0, 0.0366], [122793000.0, 0.0335], [122791000.0, 0.0], [122789000.0, 0.0326], [122788000.0, 0.0247], [122787000.0, 0.0817], [122783000.0, 0.0185]], "asks": [[122800000.0, 0.0068], [122817000.0, 0.0036], [122824000.0, 0.0001], [122829000.0, 0.0001], [122840000.0, 0.0024], [122848000.0, 0.0036], [122856000.0, 0.0001], [122857000.0, 0.0001], [122860000.0, 0.0001], [122872000.0, 0.0]]},
{"timestamp": "1743771772745", "bids": [[122799000.0, 0.02], [122798000.0, 0.0002], [122797000.0, 0.0253], [122794000.0, 0.0365], [122793000.0, 0.0335], [122791000.0, 0.0], [122789000.0, 0.0326], [122788000.0, 0.0247], [122787000.0, 0.0492], [122783000.0, 0.0185]], "asks": [[122800000.0, 0.006], [122817000.0, 0.0036], [122824000.0, 0.0001], [122829000.0, 0.0001], [122840000.0, 0.0024], [122848000.0, 0.0036], [122856000.0, 0.0001], [122857000.0, 0.0001], [122860000.0, 0.0001], [122872000.0, 0.0]]},
{"timestamp": "1743771773248", "bids": [[122802000.0, 0.0268], [122799000.0, 0.0543], [122797000.0, 0.0001], [122794000.0, 0.0129], [122791000.0, 0.0], [122789000.0, 0.0005], [122788000.0, 0.0247], [122787000.0, 0.0492], [122781000.0, 0.0061], [122777000.0, 0.0252]], "asks": [[122817000.0, 0.0036], [122824000.0, 0.0001], [122829000.0, 0.0001], [122840000.0, 0.0024], [122848000.0, 0.0036], [122856000.0, 0.0001], [122857000.0, 0.0001], [122860000.0, 0.0001], [122872000.0, 0.0], [122879000.0, 0.0036]]},
{"timestamp": "1743771773744", "bids": [[122802000.0, 0.0592], [122799000.0, 0.0543], [122798000.0, 0.0185], [122797000.0, 0.0001], [122796000.0, 0.036], [122794000.0, 0.0001], [122792000.0, 0.0028], [122791000.0, 0.0], [122790000.0, 0.0357], [122789000.0, 0.0005]], "asks": [[122817000.0, 0.0036], [122824000.0, 0.0001], [122829000.0, 0.0001], [122840000.0, 0.0024], [122848000.0, 0.0036], [122856000.0, 0.0001], [122857000.0, 0.0001], [122860000.0, 0.0001], [122872000.0, 0.0], [122879000.0, 0.0036]]},
{"timestamp": "1743771774246", "bids": [[122817000.0, 0.0203], [122812000.0, 0.0251], [122806000.0, 0.0328], [122802000.0, 0.066], [122800000.0, 0.0379], [122799000.0, 0.0456], [122798000.0, 0.115], [122796000.0, 0.036], [122792000.0, 0.0278], [122791000.0, 0.0]], "asks": [[122824000.0, 0.0001], [122829000.0, 0.0001], [122840000.0, 0.0024], [122848000.0, 0.0036], [122856000.0, 0.0001], [122857000.0, 0.0001], [122860000.0, 0.0001], [122872000.0, 0.0], [122879000.0, 0.0036], [122880000.0, 0.0024]]},
{"timestamp": "1743771774744", "bids": [[122820000.0, 0.0001], [122817000.0, 0.0203], [122814000.0, 0.0001], [122812000.0, 0.0251], [122810000.0, 0.0246], [122806000.0, 0.0328], [122803000.0, 0.0003], [122802000.0, 0.066], [122800000.0, 0.1123], [122799000.0, 0.0456]], "asks": [[122824000.0, 0.0001], [122829000.0, 0.0001], [122840000.0, 0.0024], [122848000.0, 0.0036], [122856000.0, 0.0001], [122857000.0, 0.0001], [122860000.0, 0.0001], [122872000.0, 0.0], [122879000.0, 0.0036], [122880000.0, 0.0024]]},
{"timestamp": "1743771775247", "bids": [[122849000.0, 0.0178], [122820000.0, 0.0001], [122817000.0, 0.0239], [122814000.0, 0.0001], [122810000.0, 0.0246], [122806000.0, 0.0328], [122804000.0, 0.0003], [122803000.0, 0.0058], [122802000.0, 0.0337], [122800000.0, 0.135]], "asks": [[122856000.0, 0.0001], [122857000.0, 0.0001], [122860000.0, 0.0001], [122872000.0, 0.0], [122879000.0, 0.0036], [122880000.0, 0.0024], [122883000.0, 0.0846], [122884000.0, 0.0001], [122886000.0, 0.0001], [122888000.0, 0.0]]},
{"timestamp": "1743771775740", "bids": [[122858000.0, 0.0126], [122855000.0, 0.0027], [122849000.0, 0.0178], [122847000.0, 0.0001], [122841000.0, 0.0005], [122824000.0, 0.0001], [122820000.0, 0.0001], [122818000.0, 0.0048], [122817000.0, 0.0037], [122816000.0, 0.386]], "asks": [[122860000.0, 0.0001], [122872000.0, 0.0], [122879000.0, 0.0036], [122880000.0, 0.0024], [122883000.0, 0.0846], [122884000.0, 0.0001], [122886000.0, 0.0001], [122888000.0, 0.0], [122890000.0, 0.7349], [122894000.0, 0.0001]]},
{"timestamp": "1743771776446", "bids": [[122858000.0, 0.0126], [122855000.0, 0.0027], [122854000.0, 0.0268], [122851000.0, 0.0001], [122849000.0, 0.0178], [122847000.0, 0.0001], [122841000.0, 0.0006], [122835000.0, 0.0028], [122826000.0, 0.0001], [122824000.0, 0.0001]], "asks": [[122860000.0, 0.0001], [122872000.0, 0.0], [122879000.0, 0.0036], [122880000.0, 0.0024], [122882000.0, 0.0], [122884000.0, 0.0001], [122886000.0, 0.0001], [122888000.0, 0.0], [122890000.0, 0.7349], [122894000.0, 0.0001]]},
{"timestamp": "1743771776744", "bids": [[122858000.0, 0.0126], [122855000.0, 0.0027], [122854000.0, 0.0268], [122851000.0, 0.0001], [122847000.0, 0.0001], [122844000.0, 0.0324], [122841000.0, 0.0006], [122835000.0, 0.0028], [122832000.0, 0.0185], [122831000.0, 0.036]], "asks": [[122860000.0, 0.0001], [122872000.0, 0.0], [122879000.0, 0.0036], [122880000.0, 0.0024], [122882000.0, 0.0], [122884000.0, 0.0001], [122886000.0, 0.0001], [122888000.0, 0.0], [122890000.0, 0.7349], [122894000.0, 0.0001]]},
{"timestamp": "1743771777247", "bids": [[122855000.0, 0.0027], [122854000.0, 0.0518], [122844000.0, 0.0324], [122835000.0, 0.0028], [122832000.0, 0.0185], [122831000.0, 0.036], [122829000.0, 0.0319], [122826000.0, 0.0001], [122825000.0, 0.0001], [122824000.0, 0.1061]], "asks": [[122860000.0, 0.0001], [122872000.0, 0.0], [122879000.0, 0.0036], [122880000.0, 0.0024], [122882000.0, 0.0], [122884000.0, 0.0001], [122886000.0, 0.0001], [122888000.0, 0.0], [122890000.0, 0.7349], [122894000.0, 0.0001]]},
{"timestamp": "1743771777746", "bids": [[122859000.0, 0.0279], [122855000.0, 0.0027], [122854000.0, 0.0518], [122844000.0, 0.0324], [122833000.0, 0.0001], [122832000.0, 0.0185], [122831000.0, 0.036], [122829000.0, 0.0319], [122826000.0, 0.0001], [122825000.0, 0.0001]], "asks": [[122860000.0, 0.0001], [122872000.0, 0.0], [122879000.0, 0.0036], [122880000.0, 0.0024], [122882000.0, 0.0], [122884000.0, 0.0001], [122886000.0, 0.0001], [122888000.0, 0.0], [122890000.0, 0.7349], [122894000.0, 0.0001]]},
{"timestamp": "1743771778248", "bids": [[122859000.0, 0.0279], [122855000.0, 0.0027], [122854000.0, 0.0518], [122845000.0, 0.0202], [122839000.0, 0.0178], [122837000.0, 0.0001], [122834000.0, 0.0109], [122833000.0, 0.0002], [122829000.0, 0.0646], [122826000.0, 0.0321]], "asks": [[122860000.0, 0.0001], [122872000.0, 0.0], [122879000.0, 0.0036], [122880000.0, 0.0024], [122882000.0, 0.0], [122884000.0, 0.0001], [122886000.0, 0.0001], [122888000.0, 0.0], [122890000.0, 0.7349], [122894000.0, 0.0001]]},
{"timestamp": "1743771778744", "bids": [[122859000.0, 0.0318], [122855000.0, 0.0027], [122847000.0, 0.0001], [122845000.0, 0.0202], [122844000.0, 0.0001], [122839000.0, 0.0178], [122837000.0, 0.0001], [122836000.0, 0.0005], [122834000.0, 0.0109], [122833000.0, 0.0002]], "asks": [[122860000.0, 0.0001], [122872000.0, 0.0], [122876000.0, 0.0], [122879000.0, 0.0036], [122880000.0, 0.0024], [122882000.0, 0.0], [122884000.0, 0.0001], [122886000.0, 0.0001], [122888000.0, 0.0], [122890000.0, 0.7349]]},
{"timestamp": "1743771779248", "bids": [[122862000.0, 0.0126], [122859000.0, 0.0103], [122856000.0, 0.0007], [122855000.0, 0.0027], [122847000.0, 0.0002], [122845000.0, 0.0389], [122844000.0, 0.0001], [122839000.0, 0.0178], [122837000.0, 0.0001], [122836000.0, 0.0005]], "asks": [[122879000.0, 0.0031], [122880000.0, 0.0024], [122882000.0, 0.0], [122884000.0, 0.0001], [122886000.0, 0.0001], [122888000.0, 0.0], [122890000.0, 0.7349], [122894000.0, 0.0001], [122896000.0, 0.0017], [122897000.0, 0.0016]]},
{"timestamp": "1743771779748", "bids": [[122862000.0, 0.0126], [122859000.0, 0.0102], [122858000.0, 0.0268], [122856000.0, 0.0251], [122853000.0, 0.0319], [122847000.0, 0.0326], [122845000.0, 0.0187], [122844000.0, 0.0001], [122840000.0, 0.036], [122837000.0, 0.0001]], "asks": [[122879000.0, 0.0031], [122880000.0, 0.0024], [122882000.0, 0.0], [122884000.0, 0.0001], [122886000.0, 0.0001], [122888000.0, 0.0], [122890000.0, 0.7349], [122894000.0, 0.0001], [122896000.0, 0.0017], [122897000.0, 0.0016]]},
{"timestamp": "1743771780250", "bids": [[122868000.0, 0.0001], [122865000.0, 0.0001], [122862000.0, 0.0127], [122861000.0, 0.0319], [122860000.0, 0.0006], [122859000.0, 0.0269], [122858000.0, 0.0268], [122856000.0, 0.0249], [122853000.0, 0.0319], [122851000.0, 0.0321]], "asks": [[122879000.0, 0.0031], [122880000.0, 0.0024], [122882000.0, 0.0], [122884000.0, 0.0001], [122886000.0, 0.0001], [122888000.0, 0.0], [122890000.0, 0.7349], [122894000.0, 0.0001], [122896000.0, 0.0017], [122897000.0, 0.0016]]},
{"timestamp": "1743771801753", "bids": [[122889000.0, 0.0007], [122888000.0, 0.0028], [122887000.0, 0.0022], [122886000.0, 0.0006], [122885000.0, 0.0006], [122884000.0, 0.0104], [122883000.0, 0.0269], [122881000.0, 0.0034], [122880000.0, 0.0007], [122868000.0, 0.0331]], "asks": [[122909000.0, 0.0016], [122910000.0, 0.0093], [122911000.0, 0.0091], [122912000.0, 0.0001], [122913000.0, 0.0016], [122914000.0, 0.0], [122915000.0, 0.0013], [122916000.0, 0.0033], [122917000.0, 0.0007], [122918000.0, 0.0005]]},
{"timestamp": "1743771802264", "bids": [[122901000.0, 0.0001], [122889000.0, 0.0007], [122888000.0, 0.0021], [122884000.0, 0.0068], [122883000.0, 0.0254], [122882000.0, 0.0007], [122881000.0, 0.0066], [122880000.0, 0.0044], [122878000.0, 0.0013], [122877000.0, 0.0021]], "asks": [[122909000.0, 0.0016], [122910000.0, 0.0093], [122911000.0, 0.0091], [122912000.0, 0.0001], [122913000.0, 0.0016], [122914000.0, 0.0], [122915000.0, 0.0013], [122916000.0, 0.0033], [122917000.0, 0.0007], [122918000.0, 0.0005]]},
{"timestamp": "1743771802750", "bids": [[122901000.0, 0.0001], [122888000.0, 0.0006], [122887000.0, 0.0022], [122886000.0, 0.0006], [122884000.0, 0.0068], [122883000.0, 0.0261], [122882000.0, 0.0014], [122881000.0, 0.0044], [122880000.0, 0.0014], [122879000.0, 0.0006]], "asks": [[122909000.0, 0.0016], [122910000.0, 0.0093], [122911000.0, 0.0091], [122912000.0, 0.0001], [122913000.0, 0.0016], [122914000.0, 0.0], [122915000.0, 0.0013], [122916000.0, 0.0033], [122917000.0, 0.0007], [122918000.0, 0.0005]]},
{"timestamp": "1743771803257", "bids": [[122901000.0, 0.0001], [122888000.0, 0.0006], [122887000.0, 0.0044], [122886000.0, 0.0021], [122884000.0, 0.0082], [122883000.0, 0.0274], [122882000.0, 0.0022], [122881000.0, 0.0044], [122880000.0, 0.0035], [122879000.0, 0.0013]], "asks": [[122909000.0, 0.0016], [122910000.0, 0.0093], [122911000.0, 0.0091], [122912000.0, 0.0001], [122913000.0, 0.0016], [122914000.0, 0.0], [122915000.0, 0.0013], [122916000.0, 0.0033], [122917000.0, 0.0007], [122918000.0, 0.0005]]},
{"timestamp": "1743771803757", "bids": [[122888000.0, 0.0006], [122887000.0, 0.0044], [122886000.0, 0.0021], [122884000.0, 0.0082], [122883000.0, 0.0274], [122882000.0, 0.0022], [122881000.0, 0.0044], [122880000.0, 0.0035], [122879000.0, 0.0013], [122878000.0, 0.0054]], "asks": [[122909000.0, 0.0014], [122910000.0, 0.0093], [122911000.0, 0.0091], [122912000.0, 0.0001], [122913000.0, 0.0016], [122914000.0, 0.0], [122915000.0, 0.0013], [122916000.0, 0.0033], [122917000.0, 0.0007], [122918000.0, 0.0005]]},
{"timestamp": "1743771804277", "bids": [[122907000.0, 0.0001], [122884000.0, 0.0083], [122883000.0, 0.0254], [122882000.0, 0.0007], [122881000.0, 0.0015], [122880000.0, 0.0013], [122878000.0, 0.0054], [122877000.0, 0.0014], [122876000.0, 0.0014], [122873000.0, 0.0006]], "asks": [[122909000.0, 0.0014], [122910000.0, 0.0093], [122911000.0, 0.0091], [122912000.0, 0.0001], [122913000.0, 0.0016], [122914000.0, 0.0], [122915000.0, 0.0013], [122916000.0, 0.0033], [122917000.0, 0.0007], [122918000.0, 0.0005]]},
{"timestamp": "1743771804757", "bids": [[122907000.0, 0.0001], [122885000.0, 0.0007], [122884000.0, 0.0104], [122883000.0, 0.0283], [122881000.0, 0.0014], [122880000.0, 0.002], [122879000.0, 0.0013], [122878000.0, 0.0055], [122877000.0, 0.0029], [122876000.0, 0.0014]], "asks": [[122909000.0, 0.0014], [122910000.0, 0.0093], [122911000.0, 0.0091], [122912000.0, 0.0001], [122913000.0, 0.0016], [122914000.0, 0.0], [122915000.0, 0.0013], [122916000.0, 0.0033], [122917000.0, 0.0007], [122918000.0, 0.0005]]},
{"timestamp": "1743771805252", "bids": [[122908000.0, 0.0128], [122907000.0, 0.0001], [122885000.0, 0.0007], [122884000.0, 0.0076], [122883000.0, 0.0172], [122880000.0, 0.0006], [122879000.0, 0.0006], [122877000.0, 0.0007], [122860000.0, 0.0225], [122859000.0, 0.0026]], "asks": [[122909000.0, 0.0014], [122910000.0, 0.0093], [122911000.0, 0.0091], [122912000.0, 0.0001], [122913000.0, 0.0016], [122914000.0, 0.0], [122915000.0, 0.0013], [122916000.0, 0.0033], [122917000.0, 0.0007], [122918000.0, 0.0005]]},
{"timestamp": "1743771805756", "bids": [[122907000.0, 0.0001], [122884000.0, 0.0061], [122883000.0, 0.0165], [122882000.0, 0.0007], [122881000.0, 0.0015], [122880000.0, 0.0014], [122879000.0, 0.0006], [122878000.0, 0.0107], [122877000.0, 0.0014], [122860000.0, 0.0225]], "asks": [[122909000.0, 0.0014], [122910000.0, 0.0093], [122911000.0, 0.0091], [122912000.0, 0.0001], [122913000.0, 0.0016], [122914000.0, 0.0], [122915000.0, 0.0013], [122916000.0, 0.0033], [122917000.0, 0.0007], [122918000.0, 0.0005]]},
{"timestamp": "1743771806254", "bids": [[122908000.0, 0.0279], [122907000.0, 0.0001], [122884000.0, 0.0061], [122883000.0, 0.0165], [122881000.0, 0.0006], [122880000.0, 0.0007], [122877000.0, 0.0007], [122875000.0, 0.0007], [122860000.0, 0.0225], [122859000.0, 0.0026]], "asks": [[122909000.0, 0.0014], [122910000.0, 0.0093], [122911000.0, 0.0091], [122912000.0, 0.0001], [122913000.0, 0.0016], [122914000.0, 0.0], [122915000.0, 0.0013], [122916000.0, 0.0033], [122917000.0, 0.0007], [122918000.0, 0.0005]]},
{"timestamp": "1743771806748", "bids": [[122908000.0, 0.0116], [122907000.0, 0.0001], [122884000.0, 0.0061], [122883000.0, 0.0165], [122881000.0, 0.0006], [122879000.0, 0.0093], [122877000.0, 0.0007], [122875000.0, 0.0014], [122871000.0, 0.0007], [122860000.0, 0.0225]], "asks": [[122909000.0, 0.0014], [122910000.0, 0.0093], [122911000.0, 0.0091], [122912000.0, 0.0001], [122913000.0, 0.0016], [122914000.0, 0.0], [122915000.0, 0.0013], [122916000.0, 0.0033], [122917000.0, 0.0007], [122918000.0, 0.0005]]},
{"timestamp": "1743771807258", "bids": [[122908000.0, 0.0116], [122907000.0, 0.0001], [122895000.0, 0.0163], [122884000.0, 0.0061], [122883000.0, 0.0165], [122879000.0, 0.0093], [122875000.0, 0.0014], [122871000.0, 0.0007], [122860000.0, 0.0225], [122859000.0, 0.0026]], "asks": [[122909000.0, 0.0014], [122910000.0, 0.0093], [122911000.0, 0.0091], [122912000.0, 0.0001], [122913000.0, 0.0016], [122914000.0, 0.0], [122915000.0, 0.0013], [122916000.0, 0.0033], [122917000.0, 0.0007], [122918000.0, 0.0005]]},
{"timestamp": "1743771807751", "bids": [[122908000.0, 0.0116], [122895000.0, 0.0163], [122884000.0, 0.0061], [122883000.0, 0.0165], [122879000.0, 0.0093], [122878000.0, 0.0007], [122875000.0, 0.0007], [122871000.0, 0.0007], [122860000.0, 0.0225], [122859000.0, 0.0026]], "asks": [[122909000.0, 0.0014], [122910000.0, 0.0093], [122911000.0, 0.0091], [122912000.0, 0.0001], [122913000.0, 0.0016], [122914000.0, 0.0], [122915000.0, 0.0013], [122916000.0, 0.0033], [122917000.0, 0.0007], [122918000.0, 0.0005]]},
{"timestamp": "1743771808263", "bids": [[122908000.0, 0.0116], [122895000.0, 0.0163], [122889000.0, 0.0001], [122884000.0, 0.0075], [122883000.0, 0.0173], [122880000.0, 0.0007], [122879000.0, 0.0006], [122878000.0, 0.0045], [122877000.0, 0.0007], [122874000.0, 0.0007]], "asks": [[122909000.0, 0.0014], [122910000.0, 0.0093], [122911000.0, 0.0091], [122912000.0, 0.0001], [122913000.0, 0.0016], [122914000.0, 0.0], [122915000.0, 0.0013], [122916000.0, 0.0033], [122917000.0, 0.0007], [122918000.0, 0.0005]]}
